package com.slugterra.world.greatForge;
import java.util.Random;

import net.minecraft.init.Blocks;
import net.minecraft.world.World;
public class GreatWesternForgeStructure11 {
public boolean generate(World world, Random par2Random, int xco, int yco, int zco) {
      world.setBlock(xco + 20, yco + 20, zco + 50, Blocks.stained_hardened_clay, 4, 1);
      world.setBlock(xco + 21, yco + 20, zco + 50, Blocks.stained_hardened_clay, 4, 1);
      world.setBlock(xco + 23, yco + 20, zco + 50, Blocks.diamond_block, 0, 1);
      world.setBlock(xco + 29, yco + 20, zco + 50, Blocks.diamond_block, 0, 1);
      world.setBlock(xco + 31, yco + 20, zco + 50, Blocks.stained_hardened_clay, 4, 1);
      world.setBlock(xco + 32, yco + 20, zco + 50, Blocks.stained_hardened_clay, 4, 1);
      world.setBlock(xco + 33, yco + 20, zco + 50, Blocks.stained_hardened_clay, 4, 1);
      world.setBlock(xco + 34, yco + 20, zco + 50, Blocks.stained_hardened_clay, 4, 1);
      world.setBlock(xco + 35, yco + 20, zco + 50, Blocks.stained_hardened_clay, 4, 1);
      world.setBlock(xco + 18, yco + 20, zco + 51, Blocks.stained_hardened_clay, 4, 1);
      world.setBlock(xco + 19, yco + 20, zco + 51, Blocks.stained_hardened_clay, 4, 1);
      world.setBlock(xco + 20, yco + 20, zco + 51, Blocks.stained_hardened_clay, 4, 1);
      world.setBlock(xco + 21, yco + 20, zco + 51, Blocks.stained_hardened_clay, 4, 1);
      world.setBlock(xco + 22, yco + 20, zco + 51, Blocks.stained_hardened_clay, 4, 1);
      world.setBlock(xco + 23, yco + 20, zco + 51, Blocks.stained_hardened_clay, 4, 1);
      world.setBlock(xco + 24, yco + 20, zco + 51, Blocks.stained_hardened_clay, 4, 1);
      world.setBlock(xco + 25, yco + 20, zco + 51, Blocks.stained_hardened_clay, 4, 1);
      world.setBlock(xco + 26, yco + 20, zco + 51, Blocks.stained_hardened_clay, 4, 1);
      world.setBlock(xco + 27, yco + 20, zco + 51, Blocks.stained_hardened_clay, 4, 1);
      world.setBlock(xco + 28, yco + 20, zco + 51, Blocks.stained_hardened_clay, 4, 1);
      world.setBlock(xco + 29, yco + 20, zco + 51, Blocks.stained_hardened_clay, 4, 1);
      world.setBlock(xco + 30, yco + 20, zco + 51, Blocks.stained_hardened_clay, 4, 1);
      world.setBlock(xco + 31, yco + 20, zco + 51, Blocks.stained_hardened_clay, 4, 1);
      world.setBlock(xco + 32, yco + 20, zco + 51, Blocks.stained_hardened_clay, 4, 1);
      world.setBlock(xco + 33, yco + 20, zco + 51, Blocks.stained_hardened_clay, 4, 1);
      world.setBlock(xco + 34, yco + 20, zco + 51, Blocks.stained_hardened_clay, 4, 1);
      world.setBlock(xco + 17, yco + 20, zco + 52, Blocks.stained_hardened_clay, 4, 1);
      world.setBlock(xco + 18, yco + 20, zco + 52, Blocks.stained_hardened_clay, 4, 1);
      world.setBlock(xco + 22, yco + 20, zco + 52, Blocks.stained_hardened_clay, 4, 1);
      world.setBlock(xco + 23, yco + 20, zco + 52, Blocks.stained_hardened_clay, 4, 1);
      world.setBlock(xco + 29, yco + 20, zco + 52, Blocks.stained_hardened_clay, 4, 1);
      world.setBlock(xco + 30, yco + 20, zco + 52, Blocks.stained_hardened_clay, 4, 1);
      world.setBlock(xco + 34, yco + 20, zco + 52, Blocks.stained_hardened_clay, 4, 1);
      world.setBlock(xco + 35, yco + 20, zco + 52, Blocks.stained_hardened_clay, 4, 1);
      world.setBlock(xco + 16, yco + 20, zco + 53, Blocks.stained_hardened_clay, 4, 1);
      world.setBlock(xco + 17, yco + 20, zco + 53, Blocks.stained_hardened_clay, 4, 1);
      world.setBlock(xco + 23, yco + 20, zco + 53, Blocks.stained_hardened_clay, 4, 1);
      world.setBlock(xco + 24, yco + 20, zco + 53, Blocks.stained_hardened_clay, 4, 1);
      world.setBlock(xco + 28, yco + 20, zco + 53, Blocks.stained_hardened_clay, 4, 1);
      world.setBlock(xco + 29, yco + 20, zco + 53, Blocks.stained_hardened_clay, 4, 1);
      world.setBlock(xco + 35, yco + 20, zco + 53, Blocks.stained_hardened_clay, 4, 1);
      world.setBlock(xco + 36, yco + 20, zco + 53, Blocks.stained_hardened_clay, 4, 1);
      world.setBlock(xco + 16, yco + 20, zco + 54, Blocks.stained_hardened_clay, 4, 1);
      world.setBlock(xco + 17, yco + 20, zco + 54, Blocks.stained_hardened_clay, 4, 1);
      world.setBlock(xco + 23, yco + 20, zco + 54, Blocks.stained_hardened_clay, 4, 1);
      world.setBlock(xco + 24, yco + 20, zco + 54, Blocks.stained_hardened_clay, 4, 1);
      world.setBlock(xco + 28, yco + 20, zco + 54, Blocks.stained_hardened_clay, 4, 1);
      world.setBlock(xco + 29, yco + 20, zco + 54, Blocks.stained_hardened_clay, 4, 1);
      world.setBlock(xco + 35, yco + 20, zco + 54, Blocks.stained_hardened_clay, 4, 1);
      world.setBlock(xco + 36, yco + 20, zco + 54, Blocks.stained_hardened_clay, 4, 1);
      world.setBlock(xco + 16, yco + 20, zco + 55, Blocks.stained_hardened_clay, 4, 1);
      world.setBlock(xco + 17, yco + 20, zco + 55, Blocks.stained_hardened_clay, 4, 1);
      world.setBlock(xco + 23, yco + 20, zco + 55, Blocks.stained_hardened_clay, 4, 1);
      world.setBlock(xco + 24, yco + 20, zco + 55, Blocks.stained_hardened_clay, 4, 1);
      world.setBlock(xco + 28, yco + 20, zco + 55, Blocks.stained_hardened_clay, 4, 1);
      world.setBlock(xco + 29, yco + 20, zco + 55, Blocks.stained_hardened_clay, 4, 1);
      world.setBlock(xco + 35, yco + 20, zco + 55, Blocks.stained_hardened_clay, 4, 1);
      world.setBlock(xco + 36, yco + 20, zco + 55, Blocks.stained_hardened_clay, 4, 1);
      world.setBlock(xco + 37, yco + 20, zco + 55, Blocks.stained_hardened_clay, 4, 1);
      world.setBlock(xco + 39, yco + 20, zco + 55, Blocks.nether_brick_fence, 0, 1);
      world.setBlock(xco + 40, yco + 20, zco + 55, Blocks.nether_brick_fence, 0, 1);
      world.setBlock(xco + 41, yco + 20, zco + 55, Blocks.nether_brick_fence, 0, 1);
      world.setBlock(xco + 17, yco + 20, zco + 56, Blocks.stained_hardened_clay, 4, 1);
      world.setBlock(xco + 18, yco + 20, zco + 56, Blocks.stained_hardened_clay, 4, 1);
      world.setBlock(xco + 22, yco + 20, zco + 56, Blocks.stained_hardened_clay, 4, 1);
      world.setBlock(xco + 23, yco + 20, zco + 56, Blocks.stained_hardened_clay, 4, 1);
      world.setBlock(xco + 29, yco + 20, zco + 56, Blocks.stained_hardened_clay, 4, 1);
      world.setBlock(xco + 30, yco + 20, zco + 56, Blocks.stained_hardened_clay, 4, 1);
      world.setBlock(xco + 34, yco + 20, zco + 56, Blocks.stained_hardened_clay, 4, 1);
      world.setBlock(xco + 35, yco + 20, zco + 56, Blocks.stained_hardened_clay, 4, 1);
      world.setBlock(xco + 38, yco + 20, zco + 56, Blocks.stained_hardened_clay, 4, 1);
      world.setBlock(xco + 39, yco + 20, zco + 56, Blocks.redstone_block, 0, 1);
      world.setBlock(xco + 40, yco + 20, zco + 56, Blocks.redstone_block, 0, 1);
      world.setBlock(xco + 41, yco + 20, zco + 56, Blocks.nether_brick_fence, 0, 1);
      world.setBlock(xco + 42, yco + 20, zco + 56, Blocks.nether_brick_fence, 0, 1);
      world.setBlock(xco + 18, yco + 20, zco + 57, Blocks.stained_hardened_clay, 4, 1);
      world.setBlock(xco + 19, yco + 20, zco + 57, Blocks.stained_hardened_clay, 4, 1);
      world.setBlock(xco + 20, yco + 20, zco + 57, Blocks.stained_hardened_clay, 4, 1);
      world.setBlock(xco + 21, yco + 20, zco + 57, Blocks.stained_hardened_clay, 4, 1);
      world.setBlock(xco + 22, yco + 20, zco + 57, Blocks.stained_hardened_clay, 4, 1);
      world.setBlock(xco + 30, yco + 20, zco + 57, Blocks.stained_hardened_clay, 4, 1);
      world.setBlock(xco + 31, yco + 20, zco + 57, Blocks.stained_hardened_clay, 4, 1);
      world.setBlock(xco + 32, yco + 20, zco + 57, Blocks.stained_hardened_clay, 4, 1);
      world.setBlock(xco + 33, yco + 20, zco + 57, Blocks.stained_hardened_clay, 4, 1);
      world.setBlock(xco + 34, yco + 20, zco + 57, Blocks.stained_hardened_clay, 4, 1);
      world.setBlock(xco + 39, yco + 20, zco + 57, Blocks.stained_hardened_clay, 4, 1);
      world.setBlock(xco + 41, yco + 20, zco + 57, Blocks.redstone_block, 0, 1);
      world.setBlock(xco + 42, yco + 20, zco + 57, Blocks.nether_brick_fence, 0, 1);
      world.setBlock(xco + 43, yco + 20, zco + 57, Blocks.nether_brick_fence, 0, 1);
      world.setBlock(xco + 19, yco + 20, zco + 58, Blocks.stained_hardened_clay, 4, 1);
      world.setBlock(xco + 20, yco + 20, zco + 58, Blocks.stained_hardened_clay, 4, 1);
      world.setBlock(xco + 21, yco + 20, zco + 58, Blocks.stained_hardened_clay, 4, 1);
      world.setBlock(xco + 31, yco + 20, zco + 58, Blocks.stained_hardened_clay, 4, 1);
      world.setBlock(xco + 32, yco + 20, zco + 58, Blocks.stained_hardened_clay, 4, 1);
      world.setBlock(xco + 33, yco + 20, zco + 58, Blocks.stained_hardened_clay, 4, 1);
      world.setBlock(xco + 40, yco + 20, zco + 58, Blocks.stained_hardened_clay, 4, 1);
      world.setBlock(xco + 42, yco + 20, zco + 58, Blocks.redstone_block, 0, 1);
      world.setBlock(xco + 43, yco + 20, zco + 58, Blocks.nether_brick_fence, 0, 1);
      world.setBlock(xco + 34, yco + 20, zco + 59, Blocks.redstone_block, 0, 1);
      world.setBlock(xco + 35, yco + 20, zco + 59, Blocks.redstone_block, 0, 1);
      world.setBlock(xco + 36, yco + 20, zco + 59, Blocks.redstone_block, 0, 1);
      world.setBlock(xco + 37, yco + 20, zco + 59, Blocks.redstone_block, 0, 1);
      world.setBlock(xco + 41, yco + 20, zco + 59, Blocks.stained_hardened_clay, 4, 1);
      world.setBlock(xco + 42, yco + 20, zco + 59, Blocks.redstone_block, 0, 1);
      world.setBlock(xco + 43, yco + 20, zco + 59, Blocks.nether_brick_fence, 0, 1);
      world.setBlock(xco + 33, yco + 20, zco + 60, Blocks.redstone_block, 0, 1);
      world.setBlock(xco + 38, yco + 20, zco + 60, Blocks.redstone_block, 0, 1);
      world.setBlock(xco + 42, yco + 20, zco + 60, Blocks.stone, 0, 1);
      world.setBlock(xco + 43, yco + 20, zco + 60, Blocks.stone, 0, 1);
      world.setBlock(xco + 44, yco + 20, zco + 60, Blocks.stone, 0, 1);
      world.setBlock(xco + 45, yco + 20, zco + 60, Blocks.stone, 0, 1);
      world.setBlock(xco + 32, yco + 20, zco + 61, Blocks.redstone_block, 0, 1);
      world.setBlock(xco + 39, yco + 20, zco + 61, Blocks.redstone_block, 0, 1);
      world.setBlock(xco + 41, yco + 20, zco + 61, Blocks.stone, 0, 1);
      world.setBlock(xco + 46, yco + 20, zco + 61, Blocks.stone, 0, 1);
      world.setBlock(xco + 32, yco + 20, zco + 62, Blocks.redstone_block, 0, 1);
      world.setBlock(xco + 39, yco + 20, zco + 62, Blocks.redstone_block, 0, 1);
      world.setBlock(xco + 40, yco + 20, zco + 62, Blocks.stone, 0, 1);
      world.setBlock(xco + 47, yco + 20, zco + 62, Blocks.stone, 0, 1);
      world.setBlock(xco + 32, yco + 20, zco + 63, Blocks.redstone_block, 0, 1);
      world.setBlock(xco + 39, yco + 20, zco + 63, Blocks.redstone_block, 0, 1);
      world.setBlock(xco + 40, yco + 20, zco + 63, Blocks.stone, 0, 1);
      world.setBlock(xco + 47, yco + 20, zco + 63, Blocks.stone, 0, 1);
      world.setBlock(xco + 32, yco + 20, zco + 64, Blocks.redstone_block, 0, 1);
      world.setBlock(xco + 39, yco + 20, zco + 64, Blocks.redstone_block, 0, 1);
      world.setBlock(xco + 40, yco + 20, zco + 64, Blocks.stone, 0, 1);
      world.setBlock(xco + 47, yco + 20, zco + 64, Blocks.stone, 0, 1);
      world.setBlock(xco + 33, yco + 20, zco + 65, Blocks.redstone_block, 0, 1);
      world.setBlock(xco + 38, yco + 20, zco + 65, Blocks.redstone_block, 0, 1);
      world.setBlock(xco + 40, yco + 20, zco + 65, Blocks.stone, 0, 1);
      world.setBlock(xco + 47, yco + 20, zco + 65, Blocks.stone, 0, 1);
      world.setBlock(xco + 34, yco + 20, zco + 66, Blocks.redstone_block, 0, 1);
      world.setBlock(xco + 35, yco + 20, zco + 66, Blocks.redstone_block, 0, 1);
      world.setBlock(xco + 36, yco + 20, zco + 66, Blocks.redstone_block, 0, 1);
      world.setBlock(xco + 37, yco + 20, zco + 66, Blocks.redstone_block, 0, 1);
      world.setBlock(xco + 41, yco + 20, zco + 66, Blocks.stone, 0, 1);
      world.setBlock(xco + 46, yco + 20, zco + 66, Blocks.stone, 0, 1);
      world.setBlock(xco + 42, yco + 20, zco + 67, Blocks.stone, 0, 1);
      world.setBlock(xco + 43, yco + 20, zco + 67, Blocks.stone, 0, 1);
      world.setBlock(xco + 44, yco + 20, zco + 67, Blocks.stone, 0, 1);
      world.setBlock(xco + 45, yco + 20, zco + 67, Blocks.stone, 0, 1);
      world.setBlock(xco + 17, yco + 21, zco + 37, Blocks.stained_hardened_clay, 4, 1);
      world.setBlock(xco + 18, yco + 21, zco + 37, Blocks.stained_hardened_clay, 4, 1);
      world.setBlock(xco + 23, yco + 21, zco + 37, Blocks.stained_hardened_clay, 4, 1);
      world.setBlock(xco + 24, yco + 21, zco + 37, Blocks.stained_hardened_clay, 4, 1);
      world.setBlock(xco + 25, yco + 21, zco + 37, Blocks.diamond_block, 0, 1);
      world.setBlock(xco + 26, yco + 21, zco + 37, Blocks.diamond_block, 0, 1);
      world.setBlock(xco + 27, yco + 21, zco + 37, Blocks.diamond_block, 0, 1);
      world.setBlock(xco + 28, yco + 21, zco + 37, Blocks.stained_hardened_clay, 4, 1);
      world.setBlock(xco + 29, yco + 21, zco + 37, Blocks.stained_hardened_clay, 4, 1);
      world.setBlock(xco + 34, yco + 21, zco + 37, Blocks.stained_hardened_clay, 4, 1);
      world.setBlock(xco + 35, yco + 21, zco + 37, Blocks.stained_hardened_clay, 4, 1);
      world.setBlock(xco + 17, yco + 21, zco + 38, Blocks.stained_hardened_clay, 4, 1);
      world.setBlock(xco + 18, yco + 21, zco + 38, Blocks.stained_hardened_clay, 4, 1);
      world.setBlock(xco + 19, yco + 21, zco + 38, Blocks.stained_hardened_clay, 7, 1);
      world.setBlock(xco + 20, yco + 21, zco + 38, Blocks.stained_hardened_clay, 7, 1);
      world.setBlock(xco + 23, yco + 21, zco + 38, Blocks.diamond_block, 0, 1);
      world.setBlock(xco + 29, yco + 21, zco + 38, Blocks.diamond_block, 0, 1);
      world.setBlock(xco + 32, yco + 21, zco + 38, Blocks.stained_hardened_clay, 7, 1);
      world.setBlock(xco + 33, yco + 21, zco + 38, Blocks.stained_hardened_clay, 7, 1);
      world.setBlock(xco + 34, yco + 21, zco + 38, Blocks.stained_hardened_clay, 4, 1);
      world.setBlock(xco + 35, yco + 21, zco + 38, Blocks.stained_hardened_clay, 4, 1);
      world.setBlock(xco + 17, yco + 21, zco + 39, Blocks.stained_hardened_clay, 4, 1);
      world.setBlock(xco + 20, yco + 21, zco + 39, Blocks.stained_hardened_clay, 4, 1);
      world.setBlock(xco + 23, yco + 21, zco + 39, Blocks.diamond_block, 0, 1);
      world.setBlock(xco + 29, yco + 21, zco + 39, Blocks.diamond_block, 0, 1);
      world.setBlock(xco + 32, yco + 21, zco + 39, Blocks.stained_hardened_clay, 4, 1);
      world.setBlock(xco + 35, yco + 21, zco + 39, Blocks.stained_hardened_clay, 4, 1);
      world.setBlock(xco + 17, yco + 21, zco + 40, Blocks.stained_hardened_clay, 4, 1);
      world.setBlock(xco + 20, yco + 21, zco + 40, Blocks.stained_hardened_clay, 4, 1);
      world.setBlock(xco + 23, yco + 21, zco + 40, Blocks.diamond_block, 0, 1);
      world.setBlock(xco + 29, yco + 21, zco + 40, Blocks.diamond_block, 0, 1);
      world.setBlock(xco + 32, yco + 21, zco + 40, Blocks.stained_hardened_clay, 4, 1);
      world.setBlock(xco + 34, yco + 21, zco + 40, Blocks.stained_hardened_clay, 4, 1);
      world.setBlock(xco + 35, yco + 21, zco + 40, Blocks.stained_hardened_clay, 4, 1);
      world.setBlock(xco + 18, yco + 21, zco + 41, Blocks.quartz_block, 0, 1);
      world.setBlock(xco + 20, yco + 21, zco + 41, Blocks.quartz_block, 0, 1);
      world.setBlock(xco + 23, yco + 21, zco + 41, Blocks.stained_hardened_clay, 4, 1);
      world.setBlock(xco + 26, yco + 21, zco + 41, Blocks.stone, 0, 1);
      world.setBlock(xco + 27, yco + 21, zco + 41, Blocks.stone, 0, 1);
      world.setBlock(xco + 29, yco + 21, zco + 41, Blocks.stained_hardened_clay, 4, 1);
      world.setBlock(xco + 32, yco + 21, zco + 41, Blocks.quartz_block, 0, 1);
      world.setBlock(xco + 34, yco + 21, zco + 41, Blocks.quartz_block, 0, 1);
      world.setBlock(xco + 18, yco + 21, zco + 42, Blocks.quartz_block, 0, 1);
      world.setBlock(xco + 20, yco + 21, zco + 42, Blocks.quartz_block, 0, 1);
      world.setBlock(xco + 23, yco + 21, zco + 42, Blocks.stained_hardened_clay, 4, 1);
      world.setBlock(xco + 26, yco + 21, zco + 42, Blocks.stone, 0, 1);
      world.setBlock(xco + 27, yco + 21, zco + 42, Blocks.stone, 0, 1);
      world.setBlock(xco + 29, yco + 21, zco + 42, Blocks.stained_hardened_clay, 4, 1);
      world.setBlock(xco + 32, yco + 21, zco + 42, Blocks.quartz_block, 0, 1);
      world.setBlock(xco + 34, yco + 21, zco + 42, Blocks.quartz_block, 0, 1);
      world.setBlock(xco + 17, yco + 21, zco + 43, Blocks.stained_hardened_clay, 4, 1);
      world.setBlock(xco + 20, yco + 21, zco + 43, Blocks.stained_hardened_clay, 4, 1);
      world.setBlock(xco + 23, yco + 21, zco + 43, Blocks.diamond_block, 0, 1);
      world.setBlock(xco + 29, yco + 21, zco + 43, Blocks.diamond_block, 0, 1);
      world.setBlock(xco + 32, yco + 21, zco + 43, Blocks.stained_hardened_clay, 4, 1);
      world.setBlock(xco + 35, yco + 21, zco + 43, Blocks.stained_hardened_clay, 4, 1);
      world.setBlock(xco + 17, yco + 21, zco + 44, Blocks.stained_hardened_clay, 4, 1);
      world.setBlock(xco + 20, yco + 21, zco + 44, Blocks.stained_hardened_clay, 4, 1);
      world.setBlock(xco + 23, yco + 21, zco + 44, Blocks.diamond_block, 0, 1);
      world.setBlock(xco + 29, yco + 21, zco + 44, Blocks.diamond_block, 0, 1);
      world.setBlock(xco + 32, yco + 21, zco + 44, Blocks.stained_hardened_clay, 4, 1);
      world.setBlock(xco + 35, yco + 21, zco + 44, Blocks.stained_hardened_clay, 4, 1);
      world.setBlock(xco + 17, yco + 21, zco + 45, Blocks.stained_hardened_clay, 4, 1);
      world.setBlock(xco + 20, yco + 21, zco + 45, Blocks.stained_hardened_clay, 4, 1);
      world.setBlock(xco + 23, yco + 21, zco + 45, Blocks.diamond_block, 0, 1);
      world.setBlock(xco + 29, yco + 21, zco + 45, Blocks.diamond_block, 0, 1);
      world.setBlock(xco + 32, yco + 21, zco + 45, Blocks.stained_hardened_clay, 4, 1);
      world.setBlock(xco + 35, yco + 21, zco + 45, Blocks.stained_hardened_clay, 4, 1);
      world.setBlock(xco + 18, yco + 21, zco + 46, Blocks.quartz_block, 0, 1);
      world.setBlock(xco + 19, yco + 21, zco + 46, Blocks.quartz_block, 0, 1);
      world.setBlock(xco + 20, yco + 21, zco + 46, Blocks.quartz_block, 0, 1);
      world.setBlock(xco + 23, yco + 21, zco + 46, Blocks.stained_hardened_clay, 4, 1);
      world.setBlock(xco + 25, yco + 21, zco + 46, Blocks.stone, 0, 1);
      world.setBlock(xco + 26, yco + 21, zco + 46, Blocks.stone, 0, 1);
      world.setBlock(xco + 29, yco + 21, zco + 46, Blocks.stained_hardened_clay, 4, 1);
      world.setBlock(xco + 32, yco + 21, zco + 46, Blocks.quartz_block, 0, 1);
      world.setBlock(xco + 34, yco + 21, zco + 46, Blocks.quartz_block, 0, 1);
      world.setBlock(xco + 18, yco + 21, zco + 47, Blocks.quartz_block, 0, 1);
      world.setBlock(xco + 19, yco + 21, zco + 47, Blocks.quartz_block, 0, 1);
      world.setBlock(xco + 20, yco + 21, zco + 47, Blocks.quartz_block, 0, 1);
      world.setBlock(xco + 23, yco + 21, zco + 47, Blocks.stained_hardened_clay, 4, 1);
      world.setBlock(xco + 25, yco + 21, zco + 47, Blocks.stone, 0, 1);
      world.setBlock(xco + 26, yco + 21, zco + 47, Blocks.stone, 0, 1);
      world.setBlock(xco + 29, yco + 21, zco + 47, Blocks.stained_hardened_clay, 4, 1);
      world.setBlock(xco + 32, yco + 21, zco + 47, Blocks.quartz_block, 0, 1);
      world.setBlock(xco + 34, yco + 21, zco + 47, Blocks.quartz_block, 0, 1);
      world.setBlock(xco + 17, yco + 21, zco + 48, Blocks.stained_hardened_clay, 4, 1);
      world.setBlock(xco + 20, yco + 21, zco + 48, Blocks.stained_hardened_clay, 4, 1);
      world.setBlock(xco + 23, yco + 21, zco + 48, Blocks.diamond_block, 0, 1);
      world.setBlock(xco + 29, yco + 21, zco + 48, Blocks.diamond_block, 0, 1);
      world.setBlock(xco + 32, yco + 21, zco + 48, Blocks.stained_hardened_clay, 4, 1);
      world.setBlock(xco + 35, yco + 21, zco + 48, Blocks.stained_hardened_clay, 4, 1);
      world.setBlock(xco + 17, yco + 21, zco + 49, Blocks.stained_hardened_clay, 4, 1);
      world.setBlock(xco + 20, yco + 21, zco + 49, Blocks.stained_hardened_clay, 4, 1);
      world.setBlock(xco + 23, yco + 21, zco + 49, Blocks.diamond_block, 0, 1);
      world.setBlock(xco + 29, yco + 21, zco + 49, Blocks.diamond_block, 0, 1);
      world.setBlock(xco + 32, yco + 21, zco + 49, Blocks.stained_hardened_clay, 4, 1);
      world.setBlock(xco + 35, yco + 21, zco + 49, Blocks.stained_hardened_clay, 4, 1);
      world.setBlock(xco + 17, yco + 21, zco + 50, Blocks.stained_hardened_clay, 4, 1);
      world.setBlock(xco + 18, yco + 21, zco + 50, Blocks.stained_hardened_clay, 4, 1);
      world.setBlock(xco + 19, yco + 21, zco + 50, Blocks.stained_hardened_clay, 4, 1);
      world.setBlock(xco + 20, yco + 21, zco + 50, Blocks.stained_hardened_clay, 4, 1);
      world.setBlock(xco + 21, yco + 21, zco + 50, Blocks.stained_hardened_clay, 4, 1);
      world.setBlock(xco + 23, yco + 21, zco + 50, Blocks.diamond_block, 0, 1);
      world.setBlock(xco + 29, yco + 21, zco + 50, Blocks.diamond_block, 0, 1);
      world.setBlock(xco + 31, yco + 21, zco + 50, Blocks.stained_hardened_clay, 4, 1);
      world.setBlock(xco + 32, yco + 21, zco + 50, Blocks.stained_hardened_clay, 4, 1);
      world.setBlock(xco + 33, yco + 21, zco + 50, Blocks.stained_hardened_clay, 4, 1);
      world.setBlock(xco + 34, yco + 21, zco + 50, Blocks.stained_hardened_clay, 4, 1);
      world.setBlock(xco + 35, yco + 21, zco + 50, Blocks.stained_hardened_clay, 4, 1);
      world.setBlock(xco + 18, yco + 21, zco + 51, Blocks.stained_hardened_clay, 4, 1);
      world.setBlock(xco + 19, yco + 21, zco + 51, Blocks.stained_hardened_clay, 4, 1);
      world.setBlock(xco + 20, yco + 21, zco + 51, Blocks.stained_hardened_clay, 4, 1);
      world.setBlock(xco + 21, yco + 21, zco + 51, Blocks.stained_hardened_clay, 4, 1);
      world.setBlock(xco + 22, yco + 21, zco + 51, Blocks.stained_hardened_clay, 4, 1);
      world.setBlock(xco + 23, yco + 21, zco + 51, Blocks.stained_hardened_clay, 4, 1);
      world.setBlock(xco + 24, yco + 21, zco + 51, Blocks.stained_hardened_clay, 4, 1);
      world.setBlock(xco + 25, yco + 21, zco + 51, Blocks.stained_hardened_clay, 4, 1);
      world.setBlock(xco + 26, yco + 21, zco + 51, Blocks.stained_hardened_clay, 4, 1);
      world.setBlock(xco + 27, yco + 21, zco + 51, Blocks.stained_hardened_clay, 4, 1);
      world.setBlock(xco + 28, yco + 21, zco + 51, Blocks.stained_hardened_clay, 4, 1);
      world.setBlock(xco + 29, yco + 21, zco + 51, Blocks.stained_hardened_clay, 4, 1);
      world.setBlock(xco + 30, yco + 21, zco + 51, Blocks.stained_hardened_clay, 4, 1);
      world.setBlock(xco + 31, yco + 21, zco + 51, Blocks.stained_hardened_clay, 4, 1);
      world.setBlock(xco + 32, yco + 21, zco + 51, Blocks.stained_hardened_clay, 4, 1);
      world.setBlock(xco + 33, yco + 21, zco + 51, Blocks.stained_hardened_clay, 4, 1);
      world.setBlock(xco + 34, yco + 21, zco + 51, Blocks.stained_hardened_clay, 4, 1);
      world.setBlock(xco + 17, yco + 21, zco + 52, Blocks.stained_hardened_clay, 4, 1);
      world.setBlock(xco + 18, yco + 21, zco + 52, Blocks.stained_hardened_clay, 4, 1);
      world.setBlock(xco + 22, yco + 21, zco + 52, Blocks.stained_hardened_clay, 4, 1);
      world.setBlock(xco + 23, yco + 21, zco + 52, Blocks.stained_hardened_clay, 4, 1);
      world.setBlock(xco + 29, yco + 21, zco + 52, Blocks.stained_hardened_clay, 4, 1);
      world.setBlock(xco + 30, yco + 21, zco + 52, Blocks.stained_hardened_clay, 4, 1);
      world.setBlock(xco + 34, yco + 21, zco + 52, Blocks.stained_hardened_clay, 4, 1);
      world.setBlock(xco + 35, yco + 21, zco + 52, Blocks.stained_hardened_clay, 4, 1);
      world.setBlock(xco + 16, yco + 21, zco + 53, Blocks.stained_hardened_clay, 4, 1);
      world.setBlock(xco + 17, yco + 21, zco + 53, Blocks.stained_hardened_clay, 4, 1);
      world.setBlock(xco + 23, yco + 21, zco + 53, Blocks.stained_hardened_clay, 4, 1);
      world.setBlock(xco + 24, yco + 21, zco + 53, Blocks.stained_hardened_clay, 4, 1);
      world.setBlock(xco + 28, yco + 21, zco + 53, Blocks.stained_hardened_clay, 4, 1);
      world.setBlock(xco + 29, yco + 21, zco + 53, Blocks.stained_hardened_clay, 4, 1);
      world.setBlock(xco + 35, yco + 21, zco + 53, Blocks.stained_hardened_clay, 4, 1);
      world.setBlock(xco + 36, yco + 21, zco + 53, Blocks.stained_hardened_clay, 4, 1);
      world.setBlock(xco + 16, yco + 21, zco + 54, Blocks.stained_hardened_clay, 4, 1);
      world.setBlock(xco + 17, yco + 21, zco + 54, Blocks.stained_hardened_clay, 4, 1);
      world.setBlock(xco + 23, yco + 21, zco + 54, Blocks.stained_hardened_clay, 4, 1);
      world.setBlock(xco + 24, yco + 21, zco + 54, Blocks.stained_hardened_clay, 4, 1);
      world.setBlock(xco + 28, yco + 21, zco + 54, Blocks.stained_hardened_clay, 4, 1);
      world.setBlock(xco + 29, yco + 21, zco + 54, Blocks.stained_hardened_clay, 4, 1);
      world.setBlock(xco + 35, yco + 21, zco + 54, Blocks.stained_hardened_clay, 4, 1);
      world.setBlock(xco + 36, yco + 21, zco + 54, Blocks.stained_hardened_clay, 4, 1);
      world.setBlock(xco + 16, yco + 21, zco + 55, Blocks.stained_hardened_clay, 4, 1);
      world.setBlock(xco + 17, yco + 21, zco + 55, Blocks.stained_hardened_clay, 4, 1);
      world.setBlock(xco + 23, yco + 21, zco + 55, Blocks.stained_hardened_clay, 4, 1);
      world.setBlock(xco + 24, yco + 21, zco + 55, Blocks.stained_hardened_clay, 4, 1);
      world.setBlock(xco + 28, yco + 21, zco + 55, Blocks.stained_hardened_clay, 4, 1);
      world.setBlock(xco + 29, yco + 21, zco + 55, Blocks.stained_hardened_clay, 4, 1);
      world.setBlock(xco + 35, yco + 21, zco + 55, Blocks.stained_hardened_clay, 4, 1);
      world.setBlock(xco + 36, yco + 21, zco + 55, Blocks.stained_hardened_clay, 4, 1);
      world.setBlock(xco + 37, yco + 21, zco + 55, Blocks.stained_hardened_clay, 4, 1);
      world.setBlock(xco + 39, yco + 21, zco + 55, Blocks.nether_brick_fence, 0, 1);
      world.setBlock(xco + 40, yco + 21, zco + 55, Blocks.nether_brick_fence, 0, 1);
      world.setBlock(xco + 41, yco + 21, zco + 55, Blocks.nether_brick_fence, 0, 1);
      world.setBlock(xco + 17, yco + 21, zco + 56, Blocks.stained_hardened_clay, 4, 1);
      world.setBlock(xco + 18, yco + 21, zco + 56, Blocks.stained_hardened_clay, 4, 1);
      world.setBlock(xco + 22, yco + 21, zco + 56, Blocks.stained_hardened_clay, 4, 1);
      world.setBlock(xco + 23, yco + 21, zco + 56, Blocks.stained_hardened_clay, 4, 1);
      world.setBlock(xco + 29, yco + 21, zco + 56, Blocks.stained_hardened_clay, 4, 1);
      world.setBlock(xco + 30, yco + 21, zco + 56, Blocks.stained_hardened_clay, 4, 1);
      world.setBlock(xco + 34, yco + 21, zco + 56, Blocks.stained_hardened_clay, 4, 1);
      world.setBlock(xco + 35, yco + 21, zco + 56, Blocks.stained_hardened_clay, 4, 1);
      world.setBlock(xco + 38, yco + 21, zco + 56, Blocks.stained_hardened_clay, 4, 1);
      world.setBlock(xco + 39, yco + 21, zco + 56, Blocks.redstone_block, 0, 1);
      world.setBlock(xco + 40, yco + 21, zco + 56, Blocks.redstone_block, 0, 1);
      world.setBlock(xco + 41, yco + 21, zco + 56, Blocks.nether_brick_fence, 0, 1);
      world.setBlock(xco + 42, yco + 21, zco + 56, Blocks.nether_brick_fence, 0, 1);
      world.setBlock(xco + 18, yco + 21, zco + 57, Blocks.stained_hardened_clay, 4, 1);
      world.setBlock(xco + 19, yco + 21, zco + 57, Blocks.stained_hardened_clay, 4, 1);
      world.setBlock(xco + 20, yco + 21, zco + 57, Blocks.stained_hardened_clay, 4, 1);
      world.setBlock(xco + 21, yco + 21, zco + 57, Blocks.stained_hardened_clay, 4, 1);
      world.setBlock(xco + 22, yco + 21, zco + 57, Blocks.stained_hardened_clay, 4, 1);
      world.setBlock(xco + 30, yco + 21, zco + 57, Blocks.stained_hardened_clay, 4, 1);
      world.setBlock(xco + 31, yco + 21, zco + 57, Blocks.stained_hardened_clay, 4, 1);
      world.setBlock(xco + 32, yco + 21, zco + 57, Blocks.stained_hardened_clay, 4, 1);
      world.setBlock(xco + 33, yco + 21, zco + 57, Blocks.stained_hardened_clay, 4, 1);
      world.setBlock(xco + 34, yco + 21, zco + 57, Blocks.stained_hardened_clay, 4, 1);
      world.setBlock(xco + 39, yco + 21, zco + 57, Blocks.stained_hardened_clay, 4, 1);
      world.setBlock(xco + 41, yco + 21, zco + 57, Blocks.redstone_block, 0, 1);
      world.setBlock(xco + 42, yco + 21, zco + 57, Blocks.nether_brick_fence, 0, 1);
      world.setBlock(xco + 43, yco + 21, zco + 57, Blocks.nether_brick_fence, 0, 1);
      world.setBlock(xco + 19, yco + 21, zco + 58, Blocks.stained_hardened_clay, 4, 1);
      world.setBlock(xco + 20, yco + 21, zco + 58, Blocks.stained_hardened_clay, 4, 1);
      world.setBlock(xco + 21, yco + 21, zco + 58, Blocks.stained_hardened_clay, 4, 1);
      world.setBlock(xco + 31, yco + 21, zco + 58, Blocks.stained_hardened_clay, 4, 1);
      world.setBlock(xco + 32, yco + 21, zco + 58, Blocks.stained_hardened_clay, 4, 1);
      world.setBlock(xco + 33, yco + 21, zco + 58, Blocks.stained_hardened_clay, 4, 1);
      world.setBlock(xco + 40, yco + 21, zco + 58, Blocks.stained_hardened_clay, 4, 1);
      world.setBlock(xco + 42, yco + 21, zco + 58, Blocks.redstone_block, 0, 1);
      world.setBlock(xco + 43, yco + 21, zco + 58, Blocks.nether_brick_fence, 0, 1);
      world.setBlock(xco + 34, yco + 21, zco + 59, Blocks.wool, 15, 1);
      world.setBlock(xco + 35, yco + 21, zco + 59, Blocks.wool, 15, 1);
      world.setBlock(xco + 36, yco + 21, zco + 59, Blocks.wool, 15, 1);
      world.setBlock(xco + 37, yco + 21, zco + 59, Blocks.wool, 15, 1);
      world.setBlock(xco + 41, yco + 21, zco + 59, Blocks.stained_hardened_clay, 4, 1);
      world.setBlock(xco + 42, yco + 21, zco + 59, Blocks.redstone_block, 0, 1);
      world.setBlock(xco + 43, yco + 21, zco + 59, Blocks.nether_brick_fence, 0, 1);
      world.setBlock(xco + 33, yco + 21, zco + 60, Blocks.wool, 15, 1);
      world.setBlock(xco + 38, yco + 21, zco + 60, Blocks.wool, 15, 1);
      world.setBlock(xco + 42, yco + 21, zco + 60, Blocks.stone, 0, 1);
      world.setBlock(xco + 43, yco + 21, zco + 60, Blocks.stone, 0, 1);
      world.setBlock(xco + 44, yco + 21, zco + 60, Blocks.stone, 0, 1);
      world.setBlock(xco + 45, yco + 21, zco + 60, Blocks.stone, 0, 1);
      world.setBlock(xco + 32, yco + 21, zco + 61, Blocks.wool, 15, 1);
      world.setBlock(xco + 39, yco + 21, zco + 61, Blocks.wool, 15, 1);
      world.setBlock(xco + 41, yco + 21, zco + 61, Blocks.stone, 0, 1);
      world.setBlock(xco + 46, yco + 21, zco + 61, Blocks.stone, 0, 1);
      world.setBlock(xco + 32, yco + 21, zco + 62, Blocks.wool, 15, 1);
      world.setBlock(xco + 39, yco + 21, zco + 62, Blocks.wool, 15, 1);
      world.setBlock(xco + 40, yco + 21, zco + 62, Blocks.stone, 0, 1);
      world.setBlock(xco + 47, yco + 21, zco + 62, Blocks.stone, 0, 1);
      world.setBlock(xco + 32, yco + 21, zco + 63, Blocks.wool, 15, 1);
      world.setBlock(xco + 39, yco + 21, zco + 63, Blocks.wool, 15, 1);
      world.setBlock(xco + 40, yco + 21, zco + 63, Blocks.stone, 0, 1);
      world.setBlock(xco + 47, yco + 21, zco + 63, Blocks.stone, 0, 1);
      world.setBlock(xco + 32, yco + 21, zco + 64, Blocks.wool, 15, 1);
      world.setBlock(xco + 39, yco + 21, zco + 64, Blocks.wool, 15, 1);
      world.setBlock(xco + 40, yco + 21, zco + 64, Blocks.stone, 0, 1);
      world.setBlock(xco + 47, yco + 21, zco + 64, Blocks.stone, 0, 1);
      world.setBlock(xco + 33, yco + 21, zco + 65, Blocks.wool, 15, 1);
      world.setBlock(xco + 38, yco + 21, zco + 65, Blocks.wool, 15, 1);
      world.setBlock(xco + 40, yco + 21, zco + 65, Blocks.stone, 0, 1);
      world.setBlock(xco + 47, yco + 21, zco + 65, Blocks.stone, 0, 1);
      world.setBlock(xco + 34, yco + 21, zco + 66, Blocks.wool, 15, 1);
      world.setBlock(xco + 35, yco + 21, zco + 66, Blocks.wool, 15, 1);
      world.setBlock(xco + 36, yco + 21, zco + 66, Blocks.wool, 15, 1);
      world.setBlock(xco + 37, yco + 21, zco + 66, Blocks.wool, 15, 1);
      world.setBlock(xco + 41, yco + 21, zco + 66, Blocks.stone, 0, 1);
      world.setBlock(xco + 46, yco + 21, zco + 66, Blocks.stone, 0, 1);
      world.setBlock(xco + 42, yco + 21, zco + 67, Blocks.stone, 0, 1);
      world.setBlock(xco + 43, yco + 21, zco + 67, Blocks.stone, 0, 1);
      world.setBlock(xco + 44, yco + 21, zco + 67, Blocks.stone, 0, 1);
      world.setBlock(xco + 45, yco + 21, zco + 67, Blocks.stone, 0, 1);
      world.setBlock(xco + 17, yco + 22, zco + 37, Blocks.stained_hardened_clay, 4, 1);
      world.setBlock(xco + 18, yco + 22, zco + 37, Blocks.stained_hardened_clay, 4, 1);
      world.setBlock(xco + 19, yco + 22, zco + 37, Blocks.stained_hardened_clay, 4, 1);
      world.setBlock(xco + 20, yco + 22, zco + 37, Blocks.stained_hardened_clay, 4, 1);
      world.setBlock(xco + 23, yco + 22, zco + 37, Blocks.stained_hardened_clay, 4, 1);
      world.setBlock(xco + 24, yco + 22, zco + 37, Blocks.diamond_block, 0, 1);
      world.setBlock(xco + 25, yco + 22, zco + 37, Blocks.diamond_block, 0, 1);
      world.setBlock(xco + 26, yco + 22, zco + 37, Blocks.stained_glass, 11, 1);
      world.setBlock(xco + 27, yco + 22, zco + 37, Blocks.diamond_block, 0, 1);
      world.setBlock(xco + 28, yco + 22, zco + 37, Blocks.diamond_block, 0, 1);
      world.setBlock(xco + 29, yco + 22, zco + 37, Blocks.stained_hardened_clay, 4, 1);
      world.setBlock(xco + 32, yco + 22, zco + 37, Blocks.stained_hardened_clay, 4, 1);
      world.setBlock(xco + 33, yco + 22, zco + 37, Blocks.stained_hardened_clay, 4, 1);
      world.setBlock(xco + 34, yco + 22, zco + 37, Blocks.stained_hardened_clay, 4, 1);
      world.setBlock(xco + 35, yco + 22, zco + 37, Blocks.stained_hardened_clay, 4, 1);
      world.setBlock(xco + 17, yco + 22, zco + 38, Blocks.stained_hardened_clay, 4, 1);
      world.setBlock(xco + 18, yco + 22, zco + 38, Blocks.stained_hardened_clay, 4, 1);
      world.setBlock(xco + 19, yco + 22, zco + 38, Blocks.stained_hardened_clay, 4, 1);
      world.setBlock(xco + 20, yco + 22, zco + 38, Blocks.stained_hardened_clay, 4, 1);
      world.setBlock(xco + 23, yco + 22, zco + 38, Blocks.diamond_block, 0, 1);
      world.setBlock(xco + 26, yco + 22, zco + 38, Blocks.glowstone, 0, 1);
      world.setBlock(xco + 29, yco + 22, zco + 38, Blocks.diamond_block, 0, 1);
      world.setBlock(xco + 32, yco + 22, zco + 38, Blocks.stained_hardened_clay, 4, 1);
      world.setBlock(xco + 33, yco + 22, zco + 38, Blocks.stained_hardened_clay, 4, 1);
      world.setBlock(xco + 34, yco + 22, zco + 38, Blocks.stained_hardened_clay, 4, 1);
      world.setBlock(xco + 35, yco + 22, zco + 38, Blocks.stained_hardened_clay, 4, 1);
      world.setBlock(xco + 17, yco + 22, zco + 39, Blocks.stained_hardened_clay, 4, 1);
      world.setBlock(xco + 20, yco + 22, zco + 39, Blocks.stained_hardened_clay, 4, 1);
      world.setBlock(xco + 23, yco + 22, zco + 39, Blocks.diamond_block, 0, 1);
      world.setBlock(xco + 29, yco + 22, zco + 39, Blocks.diamond_block, 0, 1);
      world.setBlock(xco + 32, yco + 22, zco + 39, Blocks.stained_hardened_clay, 4, 1);
      world.setBlock(xco + 35, yco + 22, zco + 39, Blocks.stained_hardened_clay, 4, 1);
      world.setBlock(xco + 17, yco + 22, zco + 40, Blocks.stained_hardened_clay, 4, 1);
      world.setBlock(xco + 20, yco + 22, zco + 40, Blocks.stained_hardened_clay, 4, 1);
      world.setBlock(xco + 23, yco + 22, zco + 40, Blocks.diamond_block, 0, 1);
      world.setBlock(xco + 29, yco + 22, zco + 40, Blocks.diamond_block, 0, 1);
      world.setBlock(xco + 32, yco + 22, zco + 40, Blocks.stained_hardened_clay, 4, 1);
      world.setBlock(xco + 33, yco + 22, zco + 40, Blocks.stained_hardened_clay, 4, 1);
      world.setBlock(xco + 34, yco + 22, zco + 40, Blocks.stained_hardened_clay, 4, 1);
      world.setBlock(xco + 35, yco + 22, zco + 40, Blocks.stained_hardened_clay, 4, 1);
      world.setBlock(xco + 18, yco + 22, zco + 41, Blocks.quartz_block, 0, 1);
      world.setBlock(xco + 19, yco + 22, zco + 41, Blocks.quartz_block, 0, 1);
      world.setBlock(xco + 20, yco + 22, zco + 41, Blocks.quartz_block, 0, 1);
      world.setBlock(xco + 23, yco + 22, zco + 41, Blocks.stained_hardened_clay, 4, 1);
      world.setBlock(xco + 26, yco + 22, zco + 41, Blocks.stone, 0, 1);
      world.setBlock(xco + 27, yco + 22, zco + 41, Blocks.stone, 0, 1);
      world.setBlock(xco + 29, yco + 22, zco + 41, Blocks.stained_hardened_clay, 4, 1);
      world.setBlock(xco + 32, yco + 22, zco + 41, Blocks.quartz_block, 0, 1);
      world.setBlock(xco + 34, yco + 22, zco + 41, Blocks.quartz_block, 0, 1);
      world.setBlock(xco + 18, yco + 22, zco + 42, Blocks.quartz_block, 0, 1);
      world.setBlock(xco + 20, yco + 22, zco + 42, Blocks.quartz_block, 0, 1);
      world.setBlock(xco + 23, yco + 22, zco + 42, Blocks.stained_hardened_clay, 4, 1);
      world.setBlock(xco + 26, yco + 22, zco + 42, Blocks.stone, 0, 1);
      world.setBlock(xco + 27, yco + 22, zco + 42, Blocks.stone, 0, 1);
      world.setBlock(xco + 29, yco + 22, zco + 42, Blocks.stained_hardened_clay, 4, 1);
      world.setBlock(xco + 32, yco + 22, zco + 42, Blocks.quartz_block, 0, 1);
      world.setBlock(xco + 34, yco + 22, zco + 42, Blocks.quartz_block, 0, 1);
      world.setBlock(xco + 17, yco + 22, zco + 43, Blocks.stained_hardened_clay, 4, 1);
      world.setBlock(xco + 18, yco + 22, zco + 43, Blocks.stained_hardened_clay, 4, 1);
      world.setBlock(xco + 20, yco + 22, zco + 43, Blocks.stained_hardened_clay, 4, 1);
      world.setBlock(xco + 23, yco + 22, zco + 43, Blocks.diamond_block, 0, 1);
      world.setBlock(xco + 29, yco + 22, zco + 43, Blocks.diamond_block, 0, 1);
      world.setBlock(xco + 32, yco + 22, zco + 43, Blocks.stained_hardened_clay, 4, 1);
      world.setBlock(xco + 35, yco + 22, zco + 43, Blocks.stained_hardened_clay, 4, 1);
      world.setBlock(xco + 17, yco + 22, zco + 44, Blocks.stained_hardened_clay, 4, 1);
      world.setBlock(xco + 20, yco + 22, zco + 44, Blocks.stained_hardened_clay, 4, 1);
      world.setBlock(xco + 23, yco + 22, zco + 44, Blocks.diamond_block, 0, 1);
      world.setBlock(xco + 29, yco + 22, zco + 44, Blocks.diamond_block, 0, 1);
      world.setBlock(xco + 32, yco + 22, zco + 44, Blocks.stained_hardened_clay, 4, 1);
      world.setBlock(xco + 35, yco + 22, zco + 44, Blocks.stained_hardened_clay, 4, 1);
      world.setBlock(xco + 17, yco + 22, zco + 45, Blocks.stained_hardened_clay, 4, 1);
      world.setBlock(xco + 20, yco + 22, zco + 45, Blocks.stained_hardened_clay, 4, 1);
      world.setBlock(xco + 23, yco + 22, zco + 45, Blocks.diamond_block, 0, 1);
      world.setBlock(xco + 29, yco + 22, zco + 45, Blocks.diamond_block, 0, 1);
      world.setBlock(xco + 32, yco + 22, zco + 45, Blocks.stained_hardened_clay, 4, 1);
      world.setBlock(xco + 35, yco + 22, zco + 45, Blocks.stained_hardened_clay, 4, 1);
      world.setBlock(xco + 18, yco + 22, zco + 46, Blocks.quartz_block, 0, 1);
      world.setBlock(xco + 19, yco + 22, zco + 46, Blocks.quartz_block, 0, 1);
      world.setBlock(xco + 20, yco + 22, zco + 46, Blocks.quartz_block, 0, 1);
      world.setBlock(xco + 23, yco + 22, zco + 46, Blocks.stained_hardened_clay, 4, 1);
      world.setBlock(xco + 25, yco + 22, zco + 46, Blocks.stone, 0, 1);
      world.setBlock(xco + 26, yco + 22, zco + 46, Blocks.stone, 0, 1);
      world.setBlock(xco + 29, yco + 22, zco + 46, Blocks.stained_hardened_clay, 4, 1);
      world.setBlock(xco + 32, yco + 22, zco + 46, Blocks.quartz_block, 0, 1);
      world.setBlock(xco + 33, yco + 22, zco + 46, Blocks.quartz_block, 0, 1);
      world.setBlock(xco + 34, yco + 22, zco + 46, Blocks.quartz_block, 0, 1);
      world.setBlock(xco + 18, yco + 22, zco + 47, Blocks.quartz_block, 0, 1);
      world.setBlock(xco + 19, yco + 22, zco + 47, Blocks.quartz_block, 0, 1);
      world.setBlock(xco + 20, yco + 22, zco + 47, Blocks.quartz_block, 0, 1);
      world.setBlock(xco + 23, yco + 22, zco + 47, Blocks.stained_hardened_clay, 4, 1);
      world.setBlock(xco + 25, yco + 22, zco + 47, Blocks.stone, 0, 1);
      world.setBlock(xco + 26, yco + 22, zco + 47, Blocks.stone, 0, 1);
      world.setBlock(xco + 29, yco + 22, zco + 47, Blocks.stained_hardened_clay, 4, 1);
      world.setBlock(xco + 32, yco + 22, zco + 47, Blocks.quartz_block, 0, 1);
      world.setBlock(xco + 33, yco + 22, zco + 47, Blocks.quartz_block, 0, 1);
      world.setBlock(xco + 34, yco + 22, zco + 47, Blocks.quartz_block, 0, 1);
      world.setBlock(xco + 17, yco + 22, zco + 48, Blocks.stained_hardened_clay, 4, 1);
      world.setBlock(xco + 20, yco + 22, zco + 48, Blocks.stained_hardened_clay, 4, 1);
      world.setBlock(xco + 23, yco + 22, zco + 48, Blocks.diamond_block, 0, 1);
      world.setBlock(xco + 29, yco + 22, zco + 48, Blocks.diamond_block, 0, 1);
      world.setBlock(xco + 32, yco + 22, zco + 48, Blocks.stained_hardened_clay, 4, 1);
      world.setBlock(xco + 34, yco + 22, zco + 48, Blocks.stained_hardened_clay, 4, 1);
      world.setBlock(xco + 35, yco + 22, zco + 48, Blocks.stained_hardened_clay, 4, 1);
      world.setBlock(xco + 17, yco + 22, zco + 49, Blocks.stained_hardened_clay, 4, 1);
      world.setBlock(xco + 20, yco + 22, zco + 49, Blocks.stained_hardened_clay, 4, 1);
      world.setBlock(xco + 23, yco + 22, zco + 49, Blocks.diamond_block, 0, 1);
      world.setBlock(xco + 29, yco + 22, zco + 49, Blocks.diamond_block, 0, 1);
      world.setBlock(xco + 32, yco + 22, zco + 49, Blocks.stained_hardened_clay, 4, 1);
      world.setBlock(xco + 35, yco + 22, zco + 49, Blocks.stained_hardened_clay, 4, 1);
      world.setBlock(xco + 17, yco + 22, zco + 50, Blocks.stained_hardened_clay, 4, 1);
      world.setBlock(xco + 18, yco + 22, zco + 50, Blocks.stained_hardened_clay, 4, 1);
      world.setBlock(xco + 19, yco + 22, zco + 50, Blocks.stained_hardened_clay, 4, 1);
      world.setBlock(xco + 20, yco + 22, zco + 50, Blocks.stained_hardened_clay, 4, 1);
      world.setBlock(xco + 21, yco + 22, zco + 50, Blocks.stained_hardened_clay, 4, 1);
      world.setBlock(xco + 23, yco + 22, zco + 50, Blocks.diamond_block, 0, 1);
      world.setBlock(xco + 29, yco + 22, zco + 50, Blocks.diamond_block, 0, 1);
      world.setBlock(xco + 31, yco + 22, zco + 50, Blocks.stained_hardened_clay, 4, 1);
      world.setBlock(xco + 32, yco + 22, zco + 50, Blocks.stained_hardened_clay, 4, 1);
      world.setBlock(xco + 33, yco + 22, zco + 50, Blocks.stained_hardened_clay, 4, 1);
      world.setBlock(xco + 34, yco + 22, zco + 50, Blocks.stained_hardened_clay, 4, 1);
      world.setBlock(xco + 35, yco + 22, zco + 50, Blocks.stained_hardened_clay, 4, 1);
      world.setBlock(xco + 18, yco + 22, zco + 51, Blocks.stained_hardened_clay, 4, 1);
      world.setBlock(xco + 19, yco + 22, zco + 51, Blocks.stained_hardened_clay, 4, 1);
      world.setBlock(xco + 20, yco + 22, zco + 51, Blocks.stained_hardened_clay, 4, 1);
      world.setBlock(xco + 21, yco + 22, zco + 51, Blocks.stained_hardened_clay, 4, 1);
      world.setBlock(xco + 22, yco + 22, zco + 51, Blocks.stained_hardened_clay, 4, 1);
      world.setBlock(xco + 23, yco + 22, zco + 51, Blocks.stained_hardened_clay, 4, 1);
      world.setBlock(xco + 24, yco + 22, zco + 51, Blocks.stained_hardened_clay, 4, 1);
      world.setBlock(xco + 25, yco + 22, zco + 51, Blocks.stained_hardened_clay, 4, 1);
      world.setBlock(xco + 26, yco + 22, zco + 51, Blocks.stained_hardened_clay, 4, 1);
      world.setBlock(xco + 27, yco + 22, zco + 51, Blocks.stained_hardened_clay, 4, 1);
      world.setBlock(xco + 28, yco + 22, zco + 51, Blocks.stained_hardened_clay, 4, 1);
      world.setBlock(xco + 29, yco + 22, zco + 51, Blocks.stained_hardened_clay, 4, 1);
      world.setBlock(xco + 30, yco + 22, zco + 51, Blocks.stained_hardened_clay, 4, 1);
      world.setBlock(xco + 31, yco + 22, zco + 51, Blocks.stained_hardened_clay, 4, 1);
      world.setBlock(xco + 32, yco + 22, zco + 51, Blocks.stained_hardened_clay, 4, 1);
      world.setBlock(xco + 33, yco + 22, zco + 51, Blocks.stained_hardened_clay, 4, 1);
      world.setBlock(xco + 34, yco + 22, zco + 51, Blocks.stained_hardened_clay, 4, 1);
      world.setBlock(xco + 17, yco + 22, zco + 52, Blocks.stained_hardened_clay, 4, 1);
      world.setBlock(xco + 18, yco + 22, zco + 52, Blocks.stained_hardened_clay, 4, 1);
      world.setBlock(xco + 22, yco + 22, zco + 52, Blocks.stained_hardened_clay, 4, 1);
      world.setBlock(xco + 23, yco + 22, zco + 52, Blocks.stained_hardened_clay, 4, 1);
      world.setBlock(xco + 29, yco + 22, zco + 52, Blocks.stained_hardened_clay, 4, 1);
      world.setBlock(xco + 30, yco + 22, zco + 52, Blocks.stained_hardened_clay, 4, 1);
      world.setBlock(xco + 34, yco + 22, zco + 52, Blocks.stained_hardened_clay, 4, 1);
      world.setBlock(xco + 35, yco + 22, zco + 52, Blocks.stained_hardened_clay, 4, 1);
      world.setBlock(xco + 16, yco + 22, zco + 53, Blocks.stained_hardened_clay, 4, 1);
      world.setBlock(xco + 17, yco + 22, zco + 53, Blocks.stained_hardened_clay, 4, 1);
      world.setBlock(xco + 23, yco + 22, zco + 53, Blocks.stained_hardened_clay, 4, 1);
      world.setBlock(xco + 24, yco + 22, zco + 53, Blocks.stained_hardened_clay, 4, 1);
      world.setBlock(xco + 28, yco + 22, zco + 53, Blocks.stained_hardened_clay, 4, 1);
      world.setBlock(xco + 29, yco + 22, zco + 53, Blocks.stained_hardened_clay, 4, 1);
      world.setBlock(xco + 35, yco + 22, zco + 53, Blocks.stained_hardened_clay, 4, 1);
      world.setBlock(xco + 36, yco + 22, zco + 53, Blocks.stained_hardened_clay, 4, 1);
      world.setBlock(xco + 16, yco + 22, zco + 54, Blocks.stained_hardened_clay, 4, 1);
      world.setBlock(xco + 17, yco + 22, zco + 54, Blocks.stained_hardened_clay, 4, 1);
      world.setBlock(xco + 23, yco + 22, zco + 54, Blocks.stained_hardened_clay, 4, 1);
      world.setBlock(xco + 24, yco + 22, zco + 54, Blocks.stained_hardened_clay, 4, 1);
      world.setBlock(xco + 28, yco + 22, zco + 54, Blocks.stained_hardened_clay, 4, 1);
      world.setBlock(xco + 29, yco + 22, zco + 54, Blocks.stained_hardened_clay, 4, 1);
      world.setBlock(xco + 35, yco + 22, zco + 54, Blocks.stained_hardened_clay, 4, 1);
      world.setBlock(xco + 36, yco + 22, zco + 54, Blocks.stained_hardened_clay, 4, 1);
      world.setBlock(xco + 16, yco + 22, zco + 55, Blocks.stained_hardened_clay, 4, 1);
      world.setBlock(xco + 17, yco + 22, zco + 55, Blocks.stained_hardened_clay, 4, 1);
      world.setBlock(xco + 23, yco + 22, zco + 55, Blocks.stained_hardened_clay, 4, 1);
      world.setBlock(xco + 24, yco + 22, zco + 55, Blocks.stained_hardened_clay, 4, 1);
      world.setBlock(xco + 28, yco + 22, zco + 55, Blocks.stained_hardened_clay, 4, 1);
      world.setBlock(xco + 29, yco + 22, zco + 55, Blocks.stained_hardened_clay, 4, 1);
      world.setBlock(xco + 35, yco + 22, zco + 55, Blocks.stained_hardened_clay, 4, 1);
      world.setBlock(xco + 36, yco + 22, zco + 55, Blocks.stained_hardened_clay, 4, 1);
      world.setBlock(xco + 37, yco + 22, zco + 55, Blocks.stained_hardened_clay, 4, 1);
      world.setBlock(xco + 39, yco + 22, zco + 55, Blocks.nether_brick_fence, 0, 1);
      world.setBlock(xco + 40, yco + 22, zco + 55, Blocks.nether_brick_fence, 0, 1);
      world.setBlock(xco + 41, yco + 22, zco + 55, Blocks.nether_brick_fence, 0, 1);
      world.setBlock(xco + 17, yco + 22, zco + 56, Blocks.stained_hardened_clay, 4, 1);
      world.setBlock(xco + 18, yco + 22, zco + 56, Blocks.stained_hardened_clay, 4, 1);
      world.setBlock(xco + 22, yco + 22, zco + 56, Blocks.stained_hardened_clay, 4, 1);
      world.setBlock(xco + 23, yco + 22, zco + 56, Blocks.stained_hardened_clay, 4, 1);
      world.setBlock(xco + 29, yco + 22, zco + 56, Blocks.stained_hardened_clay, 4, 1);
      world.setBlock(xco + 30, yco + 22, zco + 56, Blocks.stained_hardened_clay, 4, 1);
      world.setBlock(xco + 34, yco + 22, zco + 56, Blocks.stained_hardened_clay, 4, 1);
      world.setBlock(xco + 35, yco + 22, zco + 56, Blocks.stained_hardened_clay, 4, 1);
      world.setBlock(xco + 38, yco + 22, zco + 56, Blocks.stained_hardened_clay, 4, 1);
      world.setBlock(xco + 39, yco + 22, zco + 56, Blocks.redstone_block, 0, 1);
      world.setBlock(xco + 40, yco + 22, zco + 56, Blocks.redstone_block, 0, 1);
      world.setBlock(xco + 41, yco + 22, zco + 56, Blocks.nether_brick_fence, 0, 1);
      world.setBlock(xco + 42, yco + 22, zco + 56, Blocks.nether_brick_fence, 0, 1);
      world.setBlock(xco + 18, yco + 22, zco + 57, Blocks.stained_hardened_clay, 4, 1);
      world.setBlock(xco + 19, yco + 22, zco + 57, Blocks.stained_hardened_clay, 4, 1);
      world.setBlock(xco + 20, yco + 22, zco + 57, Blocks.stained_hardened_clay, 4, 1);
      world.setBlock(xco + 21, yco + 22, zco + 57, Blocks.stained_hardened_clay, 4, 1);
      world.setBlock(xco + 22, yco + 22, zco + 57, Blocks.stained_hardened_clay, 4, 1);
      world.setBlock(xco + 30, yco + 22, zco + 57, Blocks.stained_hardened_clay, 4, 1);
      world.setBlock(xco + 31, yco + 22, zco + 57, Blocks.stained_hardened_clay, 4, 1);
      world.setBlock(xco + 32, yco + 22, zco + 57, Blocks.stained_hardened_clay, 4, 1);
      world.setBlock(xco + 33, yco + 22, zco + 57, Blocks.stained_hardened_clay, 4, 1);
      world.setBlock(xco + 34, yco + 22, zco + 57, Blocks.stained_hardened_clay, 4, 1);
      world.setBlock(xco + 39, yco + 22, zco + 57, Blocks.stained_hardened_clay, 4, 1);
      world.setBlock(xco + 41, yco + 22, zco + 57, Blocks.redstone_block, 0, 1);
      world.setBlock(xco + 42, yco + 22, zco + 57, Blocks.nether_brick_fence, 0, 1);
      world.setBlock(xco + 43, yco + 22, zco + 57, Blocks.nether_brick_fence, 0, 1);
      world.setBlock(xco + 19, yco + 22, zco + 58, Blocks.stained_hardened_clay, 4, 1);
      world.setBlock(xco + 20, yco + 22, zco + 58, Blocks.stained_hardened_clay, 4, 1);
      world.setBlock(xco + 21, yco + 22, zco + 58, Blocks.stained_hardened_clay, 4, 1);
      world.setBlock(xco + 31, yco + 22, zco + 58, Blocks.stained_hardened_clay, 4, 1);
      world.setBlock(xco + 32, yco + 22, zco + 58, Blocks.stained_hardened_clay, 4, 1);
      world.setBlock(xco + 33, yco + 22, zco + 58, Blocks.stained_hardened_clay, 4, 1);
      world.setBlock(xco + 40, yco + 22, zco + 58, Blocks.stained_hardened_clay, 4, 1);
      world.setBlock(xco + 42, yco + 22, zco + 58, Blocks.redstone_block, 0, 1);
      world.setBlock(xco + 43, yco + 22, zco + 58, Blocks.nether_brick_fence, 0, 1);
      world.setBlock(xco + 34, yco + 22, zco + 59, Blocks.redstone_block, 0, 1);
      world.setBlock(xco + 35, yco + 22, zco + 59, Blocks.redstone_block, 0, 1);
      world.setBlock(xco + 36, yco + 22, zco + 59, Blocks.redstone_block, 0, 1);
      world.setBlock(xco + 37, yco + 22, zco + 59, Blocks.redstone_block, 0, 1);
      world.setBlock(xco + 41, yco + 22, zco + 59, Blocks.stained_hardened_clay, 4, 1);
      world.setBlock(xco + 42, yco + 22, zco + 59, Blocks.redstone_block, 0, 1);
      world.setBlock(xco + 43, yco + 22, zco + 59, Blocks.nether_brick_fence, 0, 1);
      world.setBlock(xco + 33, yco + 22, zco + 60, Blocks.redstone_block, 0, 1);
      world.setBlock(xco + 38, yco + 22, zco + 60, Blocks.redstone_block, 0, 1);
      world.setBlock(xco + 42, yco + 22, zco + 60, Blocks.stone, 0, 1);
      world.setBlock(xco + 43, yco + 22, zco + 60, Blocks.stone, 0, 1);
      world.setBlock(xco + 44, yco + 22, zco + 60, Blocks.stone, 0, 1);
      world.setBlock(xco + 45, yco + 22, zco + 60, Blocks.stone, 0, 1);
      world.setBlock(xco + 32, yco + 22, zco + 61, Blocks.redstone_block, 0, 1);
      world.setBlock(xco + 39, yco + 22, zco + 61, Blocks.redstone_block, 0, 1);
      world.setBlock(xco + 41, yco + 22, zco + 61, Blocks.stone, 0, 1);
      world.setBlock(xco + 46, yco + 22, zco + 61, Blocks.stone, 0, 1);
      world.setBlock(xco + 32, yco + 22, zco + 62, Blocks.redstone_block, 0, 1);
      world.setBlock(xco + 39, yco + 22, zco + 62, Blocks.redstone_block, 0, 1);
      world.setBlock(xco + 40, yco + 22, zco + 62, Blocks.stone, 0, 1);
      world.setBlock(xco + 47, yco + 22, zco + 62, Blocks.stone, 0, 1);
      world.setBlock(xco + 32, yco + 22, zco + 63, Blocks.redstone_block, 0, 1);
      world.setBlock(xco + 39, yco + 22, zco + 63, Blocks.redstone_block, 0, 1);
      world.setBlock(xco + 40, yco + 22, zco + 63, Blocks.stone, 0, 1);
      world.setBlock(xco + 47, yco + 22, zco + 63, Blocks.stone, 0, 1);
      world.setBlock(xco + 32, yco + 22, zco + 64, Blocks.redstone_block, 0, 1);
      world.setBlock(xco + 39, yco + 22, zco + 64, Blocks.redstone_block, 0, 1);
      world.setBlock(xco + 40, yco + 22, zco + 64, Blocks.stone, 0, 1);
      world.setBlock(xco + 47, yco + 22, zco + 64, Blocks.stone, 0, 1);
      world.setBlock(xco + 33, yco + 22, zco + 65, Blocks.redstone_block, 0, 1);
      world.setBlock(xco + 38, yco + 22, zco + 65, Blocks.redstone_block, 0, 1);
      world.setBlock(xco + 40, yco + 22, zco + 65, Blocks.stone, 0, 1);
      world.setBlock(xco + 47, yco + 22, zco + 65, Blocks.stone, 0, 1);
      world.setBlock(xco + 34, yco + 22, zco + 66, Blocks.redstone_block, 0, 1);
      world.setBlock(xco + 35, yco + 22, zco + 66, Blocks.redstone_block, 0, 1);
      world.setBlock(xco + 36, yco + 22, zco + 66, Blocks.redstone_block, 0, 1);
      world.setBlock(xco + 37, yco + 22, zco + 66, Blocks.redstone_block, 0, 1);
      world.setBlock(xco + 41, yco + 22, zco + 66, Blocks.stone, 0, 1);
      world.setBlock(xco + 46, yco + 22, zco + 66, Blocks.stone, 0, 1);
      world.setBlock(xco + 42, yco + 22, zco + 67, Blocks.stone, 0, 1);
      world.setBlock(xco + 43, yco + 22, zco + 67, Blocks.stone, 0, 1);
      world.setBlock(xco + 44, yco + 22, zco + 67, Blocks.stone, 0, 1);
      world.setBlock(xco + 45, yco + 22, zco + 67, Blocks.stone, 0, 1);
      world.setBlock(xco + 18, yco + 23, zco + 37, Blocks.stained_hardened_clay, 4, 1);
      world.setBlock(xco + 19, yco + 23, zco + 37, Blocks.stained_hardened_clay, 4, 1);
      world.setBlock(xco + 20, yco + 23, zco + 37, Blocks.stained_hardened_clay, 4, 1);
      world.setBlock(xco + 23, yco + 23, zco + 37, Blocks.stained_hardened_clay, 4, 1);
      world.setBlock(xco + 24, yco + 23, zco + 37, Blocks.stained_hardened_clay, 4, 1);
      world.setBlock(xco + 25, yco + 23, zco + 37, Blocks.diamond_block, 0, 1);
      world.setBlock(xco + 26, yco + 23, zco + 37, Blocks.diamond_block, 0, 1);
      world.setBlock(xco + 27, yco + 23, zco + 37, Blocks.diamond_block, 0, 1);
      world.setBlock(xco + 28, yco + 23, zco + 37, Blocks.stained_hardened_clay, 4, 1);
      world.setBlock(xco + 29, yco + 23, zco + 37, Blocks.stained_hardened_clay, 4, 1);
      world.setBlock(xco + 32, yco + 23, zco + 37, Blocks.stained_hardened_clay, 4, 1);
      world.setBlock(xco + 33, yco + 23, zco + 37, Blocks.stained_hardened_clay, 4, 1);
      world.setBlock(xco + 34, yco + 23, zco + 37, Blocks.stained_hardened_clay, 4, 1);
      world.setBlock(xco + 18, yco + 23, zco + 38, Blocks.stained_hardened_clay, 4, 1);
      world.setBlock(xco + 19, yco + 23, zco + 38, Blocks.stained_hardened_clay, 4, 1);
      world.setBlock(xco + 20, yco + 23, zco + 38, Blocks.stained_hardened_clay, 4, 1);
      world.setBlock(xco + 23, yco + 23, zco + 38, Blocks.diamond_block, 0, 1);
      world.setBlock(xco + 29, yco + 23, zco + 38, Blocks.diamond_block, 0, 1);
      world.setBlock(xco + 32, yco + 23, zco + 38, Blocks.stained_hardened_clay, 4, 1);
      world.setBlock(xco + 33, yco + 23, zco + 38, Blocks.stained_hardened_clay, 4, 1);
      world.setBlock(xco + 34, yco + 23, zco + 38, Blocks.stained_hardened_clay, 4, 1);
      world.setBlock(xco + 18, yco + 23, zco + 39, Blocks.stained_hardened_clay, 4, 1);
      world.setBlock(xco + 20, yco + 23, zco + 39, Blocks.stained_hardened_clay, 4, 1);
      world.setBlock(xco + 23, yco + 23, zco + 39, Blocks.diamond_block, 0, 1);
      world.setBlock(xco + 29, yco + 23, zco + 39, Blocks.diamond_block, 0, 1);
      world.setBlock(xco + 32, yco + 23, zco + 39, Blocks.stained_hardened_clay, 4, 1);
      world.setBlock(xco + 34, yco + 23, zco + 39, Blocks.stained_hardened_clay, 4, 1);
      world.setBlock(xco + 18, yco + 23, zco + 40, Blocks.stained_hardened_clay, 4, 1);
      world.setBlock(xco + 20, yco + 23, zco + 40, Blocks.stained_hardened_clay, 4, 1);
      world.setBlock(xco + 23, yco + 23, zco + 40, Blocks.diamond_block, 0, 1);
      world.setBlock(xco + 29, yco + 23, zco + 40, Blocks.diamond_block, 0, 1);
      world.setBlock(xco + 32, yco + 23, zco + 40, Blocks.stained_hardened_clay, 4, 1);
      world.setBlock(xco + 33, yco + 23, zco + 40, Blocks.stained_hardened_clay, 4, 1);
      world.setBlock(xco + 34, yco + 23, zco + 40, Blocks.stained_hardened_clay, 4, 1);
      world.setBlock(xco + 19, yco + 23, zco + 41, Blocks.quartz_block, 0, 1);
      world.setBlock(xco + 20, yco + 23, zco + 41, Blocks.quartz_block, 0, 1);
      world.setBlock(xco + 23, yco + 23, zco + 41, Blocks.stained_hardened_clay, 4, 1);
      world.setBlock(xco + 26, yco + 23, zco + 41, Blocks.stone, 0, 1);
      world.setBlock(xco + 27, yco + 23, zco + 41, Blocks.stone, 0, 1);
      world.setBlock(xco + 29, yco + 23, zco + 41, Blocks.stained_hardened_clay, 4, 1);
      world.setBlock(xco + 32, yco + 23, zco + 41, Blocks.quartz_block, 0, 1);
      world.setBlock(xco + 33, yco + 23, zco + 41, Blocks.quartz_block, 0, 1);
      world.setBlock(xco + 19, yco + 23, zco + 42, Blocks.quartz_block, 0, 1);
      world.setBlock(xco + 20, yco + 23, zco + 42, Blocks.quartz_block, 0, 1);
      world.setBlock(xco + 23, yco + 23, zco + 42, Blocks.stained_hardened_clay, 4, 1);
      world.setBlock(xco + 26, yco + 23, zco + 42, Blocks.stone, 0, 1);
      world.setBlock(xco + 27, yco + 23, zco + 42, Blocks.stone, 0, 1);
      world.setBlock(xco + 29, yco + 23, zco + 42, Blocks.stained_hardened_clay, 4, 1);
      world.setBlock(xco + 32, yco + 23, zco + 42, Blocks.quartz_block, 0, 1);
      world.setBlock(xco + 33, yco + 23, zco + 42, Blocks.quartz_block, 0, 1);
      world.setBlock(xco + 18, yco + 23, zco + 43, Blocks.stained_hardened_clay, 4, 1);
      world.setBlock(xco + 20, yco + 23, zco + 43, Blocks.stained_hardened_clay, 4, 1);
      world.setBlock(xco + 23, yco + 23, zco + 43, Blocks.diamond_block, 0, 1);
      world.setBlock(xco + 29, yco + 23, zco + 43, Blocks.diamond_block, 0, 1);
      world.setBlock(xco + 32, yco + 23, zco + 43, Blocks.stained_hardened_clay, 4, 1);
      world.setBlock(xco + 34, yco + 23, zco + 43, Blocks.stained_hardened_clay, 4, 1);
      world.setBlock(xco + 18, yco + 23, zco + 44, Blocks.stained_hardened_clay, 4, 1);
      world.setBlock(xco + 20, yco + 23, zco + 44, Blocks.stained_hardened_clay, 4, 1);
      world.setBlock(xco + 23, yco + 23, zco + 44, Blocks.diamond_block, 0, 1);
      world.setBlock(xco + 29, yco + 23, zco + 44, Blocks.diamond_block, 0, 1);
      world.setBlock(xco + 32, yco + 23, zco + 44, Blocks.stained_hardened_clay, 4, 1);
      world.setBlock(xco + 34, yco + 23, zco + 44, Blocks.stained_hardened_clay, 4, 1);
      world.setBlock(xco + 18, yco + 23, zco + 45, Blocks.stained_hardened_clay, 4, 1);
      world.setBlock(xco + 20, yco + 23, zco + 45, Blocks.stained_hardened_clay, 4, 1);
      world.setBlock(xco + 23, yco + 23, zco + 45, Blocks.diamond_block, 0, 1);
      world.setBlock(xco + 29, yco + 23, zco + 45, Blocks.diamond_block, 0, 1);
      world.setBlock(xco + 32, yco + 23, zco + 45, Blocks.stained_hardened_clay, 4, 1);
      world.setBlock(xco + 34, yco + 23, zco + 45, Blocks.stained_hardened_clay, 4, 1);
      world.setBlock(xco + 19, yco + 23, zco + 46, Blocks.quartz_block, 0, 1);
      world.setBlock(xco + 20, yco + 23, zco + 46, Blocks.quartz_block, 0, 1);
      world.setBlock(xco + 23, yco + 23, zco + 46, Blocks.stained_hardened_clay, 4, 1);
      world.setBlock(xco + 25, yco + 23, zco + 46, Blocks.stone, 0, 1);
      world.setBlock(xco + 26, yco + 23, zco + 46, Blocks.stone, 0, 1);
      world.setBlock(xco + 29, yco + 23, zco + 46, Blocks.stained_hardened_clay, 4, 1);
      world.setBlock(xco + 32, yco + 23, zco + 46, Blocks.quartz_block, 0, 1);
      world.setBlock(xco + 33, yco + 23, zco + 46, Blocks.quartz_block, 0, 1);
      world.setBlock(xco + 19, yco + 23, zco + 47, Blocks.quartz_block, 0, 1);
      world.setBlock(xco + 20, yco + 23, zco + 47, Blocks.quartz_block, 0, 1);
      world.setBlock(xco + 23, yco + 23, zco + 47, Blocks.stained_hardened_clay, 4, 1);
      world.setBlock(xco + 25, yco + 23, zco + 47, Blocks.stone, 0, 1);
      world.setBlock(xco + 26, yco + 23, zco + 47, Blocks.stone, 0, 1);
      world.setBlock(xco + 29, yco + 23, zco + 47, Blocks.stained_hardened_clay, 4, 1);
      world.setBlock(xco + 32, yco + 23, zco + 47, Blocks.quartz_block, 0, 1);
      world.setBlock(xco + 33, yco + 23, zco + 47, Blocks.quartz_block, 0, 1);
      world.setBlock(xco + 18, yco + 23, zco + 48, Blocks.stained_hardened_clay, 4, 1);
      world.setBlock(xco + 20, yco + 23, zco + 48, Blocks.stained_hardened_clay, 4, 1);
      world.setBlock(xco + 23, yco + 23, zco + 48, Blocks.diamond_block, 0, 1);
      world.setBlock(xco + 29, yco + 23, zco + 48, Blocks.diamond_block, 0, 1);
      world.setBlock(xco + 32, yco + 23, zco + 48, Blocks.stained_hardened_clay, 4, 1);
      world.setBlock(xco + 34, yco + 23, zco + 48, Blocks.stained_hardened_clay, 4, 1);
      world.setBlock(xco + 18, yco + 23, zco + 49, Blocks.stained_hardened_clay, 4, 1);
      world.setBlock(xco + 20, yco + 23, zco + 49, Blocks.stained_hardened_clay, 4, 1);
      world.setBlock(xco + 23, yco + 23, zco + 49, Blocks.diamond_block, 0, 1);
      world.setBlock(xco + 29, yco + 23, zco + 49, Blocks.diamond_block, 0, 1);
      world.setBlock(xco + 32, yco + 23, zco + 49, Blocks.stained_hardened_clay, 4, 1);
      world.setBlock(xco + 34, yco + 23, zco + 49, Blocks.stained_hardened_clay, 4, 1);
      world.setBlock(xco + 18, yco + 23, zco + 50, Blocks.stained_hardened_clay, 4, 1);
      world.setBlock(xco + 19, yco + 23, zco + 50, Blocks.stained_hardened_clay, 4, 1);
      world.setBlock(xco + 20, yco + 23, zco + 50, Blocks.stained_hardened_clay, 4, 1);
      world.setBlock(xco + 21, yco + 23, zco + 50, Blocks.stained_hardened_clay, 4, 1);
      world.setBlock(xco + 23, yco + 23, zco + 50, Blocks.diamond_block, 0, 1);
      world.setBlock(xco + 29, yco + 23, zco + 50, Blocks.diamond_block, 0, 1);
      world.setBlock(xco + 31, yco + 23, zco + 50, Blocks.stained_hardened_clay, 4, 1);
      world.setBlock(xco + 32, yco + 23, zco + 50, Blocks.stained_hardened_clay, 4, 1);
      world.setBlock(xco + 33, yco + 23, zco + 50, Blocks.stained_hardened_clay, 4, 1);
      world.setBlock(xco + 34, yco + 23, zco + 50, Blocks.stained_hardened_clay, 4, 1);
      world.setBlock(xco + 18, yco + 23, zco + 51, Blocks.stained_hardened_clay, 4, 1);
      world.setBlock(xco + 19, yco + 23, zco + 51, Blocks.stained_hardened_clay, 4, 1);
      world.setBlock(xco + 20, yco + 23, zco + 51, Blocks.stained_hardened_clay, 4, 1);
      world.setBlock(xco + 21, yco + 23, zco + 51, Blocks.stained_hardened_clay, 4, 1);
      world.setBlock(xco + 22, yco + 23, zco + 51, Blocks.stained_hardened_clay, 4, 1);
      world.setBlock(xco + 23, yco + 23, zco + 51, Blocks.stained_hardened_clay, 4, 1);
      world.setBlock(xco + 24, yco + 23, zco + 51, Blocks.stained_hardened_clay, 4, 1);
      world.setBlock(xco + 25, yco + 23, zco + 51, Blocks.stained_hardened_clay, 4, 1);
      world.setBlock(xco + 26, yco + 23, zco + 51, Blocks.stained_hardened_clay, 4, 1);
      world.setBlock(xco + 27, yco + 23, zco + 51, Blocks.stained_hardened_clay, 4, 1);
      world.setBlock(xco + 28, yco + 23, zco + 51, Blocks.stained_hardened_clay, 4, 1);
      world.setBlock(xco + 29, yco + 23, zco + 51, Blocks.stained_hardened_clay, 4, 1);
      world.setBlock(xco + 30, yco + 23, zco + 51, Blocks.stained_hardened_clay, 4, 1);
      world.setBlock(xco + 31, yco + 23, zco + 51, Blocks.stained_hardened_clay, 4, 1);
      world.setBlock(xco + 32, yco + 23, zco + 51, Blocks.stained_hardened_clay, 4, 1);
      world.setBlock(xco + 33, yco + 23, zco + 51, Blocks.stained_hardened_clay, 4, 1);
      world.setBlock(xco + 34, yco + 23, zco + 51, Blocks.stained_hardened_clay, 4, 1);
      world.setBlock(xco + 17, yco + 23, zco + 52, Blocks.stained_hardened_clay, 4, 1);
      world.setBlock(xco + 18, yco + 23, zco + 52, Blocks.stained_hardened_clay, 4, 1);
      world.setBlock(xco + 22, yco + 23, zco + 52, Blocks.stained_hardened_clay, 4, 1);
      world.setBlock(xco + 23, yco + 23, zco + 52, Blocks.stained_hardened_clay, 4, 1);
      world.setBlock(xco + 29, yco + 23, zco + 52, Blocks.stained_hardened_clay, 4, 1);
      world.setBlock(xco + 30, yco + 23, zco + 52, Blocks.stained_hardened_clay, 4, 1);
      world.setBlock(xco + 34, yco + 23, zco + 52, Blocks.stained_hardened_clay, 4, 1);
      world.setBlock(xco + 35, yco + 23, zco + 52, Blocks.stained_hardened_clay, 4, 1);
      world.setBlock(xco + 16, yco + 23, zco + 53, Blocks.stained_hardened_clay, 4, 1);
      world.setBlock(xco + 17, yco + 23, zco + 53, Blocks.stained_hardened_clay, 4, 1);
      world.setBlock(xco + 23, yco + 23, zco + 53, Blocks.stained_hardened_clay, 4, 1);
      world.setBlock(xco + 24, yco + 23, zco + 53, Blocks.stained_hardened_clay, 4, 1);
      world.setBlock(xco + 28, yco + 23, zco + 53, Blocks.stained_hardened_clay, 4, 1);
      world.setBlock(xco + 29, yco + 23, zco + 53, Blocks.stained_hardened_clay, 4, 1);
      world.setBlock(xco + 35, yco + 23, zco + 53, Blocks.stained_hardened_clay, 4, 1);
      world.setBlock(xco + 36, yco + 23, zco + 53, Blocks.stained_hardened_clay, 4, 1);
      world.setBlock(xco + 16, yco + 23, zco + 54, Blocks.stained_hardened_clay, 4, 1);
      world.setBlock(xco + 17, yco + 23, zco + 54, Blocks.stained_hardened_clay, 4, 1);
      world.setBlock(xco + 23, yco + 23, zco + 54, Blocks.stained_hardened_clay, 4, 1);
      world.setBlock(xco + 24, yco + 23, zco + 54, Blocks.stained_hardened_clay, 4, 1);
      world.setBlock(xco + 28, yco + 23, zco + 54, Blocks.stained_hardened_clay, 4, 1);
      world.setBlock(xco + 29, yco + 23, zco + 54, Blocks.stained_hardened_clay, 4, 1);
      world.setBlock(xco + 35, yco + 23, zco + 54, Blocks.stained_hardened_clay, 4, 1);
      world.setBlock(xco + 36, yco + 23, zco + 54, Blocks.wool, 15, 1);
      world.setBlock(xco + 16, yco + 23, zco + 55, Blocks.stained_hardened_clay, 4, 1);
      world.setBlock(xco + 17, yco + 23, zco + 55, Blocks.stained_hardened_clay, 4, 1);
      world.setBlock(xco + 23, yco + 23, zco + 55, Blocks.stained_hardened_clay, 4, 1);
      world.setBlock(xco + 24, yco + 23, zco + 55, Blocks.stained_hardened_clay, 4, 1);
      world.setBlock(xco + 28, yco + 23, zco + 55, Blocks.stained_hardened_clay, 4, 1);
      world.setBlock(xco + 29, yco + 23, zco + 55, Blocks.stained_hardened_clay, 4, 1);
      world.setBlock(xco + 35, yco + 23, zco + 55, Blocks.stained_hardened_clay, 4, 1);
      world.setBlock(xco + 36, yco + 23, zco + 55, Blocks.stained_hardened_clay, 4, 1);
      world.setBlock(xco + 37, yco + 23, zco + 55, Blocks.stained_hardened_clay, 4, 1);
      world.setBlock(xco + 39, yco + 23, zco + 55, Blocks.nether_brick_fence, 0, 1);
      world.setBlock(xco + 40, yco + 23, zco + 55, Blocks.nether_brick_fence, 0, 1);
      world.setBlock(xco + 41, yco + 23, zco + 55, Blocks.nether_brick_fence, 0, 1);
      world.setBlock(xco + 17, yco + 23, zco + 56, Blocks.stained_hardened_clay, 4, 1);
      world.setBlock(xco + 18, yco + 23, zco + 56, Blocks.stained_hardened_clay, 4, 1);
      world.setBlock(xco + 22, yco + 23, zco + 56, Blocks.stained_hardened_clay, 4, 1);
      world.setBlock(xco + 23, yco + 23, zco + 56, Blocks.stained_hardened_clay, 4, 1);
      world.setBlock(xco + 29, yco + 23, zco + 56, Blocks.stained_hardened_clay, 4, 1);
      world.setBlock(xco + 30, yco + 23, zco + 56, Blocks.stained_hardened_clay, 4, 1);
      world.setBlock(xco + 34, yco + 23, zco + 56, Blocks.stained_hardened_clay, 4, 1);
      world.setBlock(xco + 35, yco + 23, zco + 56, Blocks.stained_hardened_clay, 4, 1);
      world.setBlock(xco + 38, yco + 23, zco + 56, Blocks.stained_hardened_clay, 4, 1);
      world.setBlock(xco + 39, yco + 23, zco + 56, Blocks.redstone_block, 0, 1);
      world.setBlock(xco + 40, yco + 23, zco + 56, Blocks.redstone_block, 0, 1);
      world.setBlock(xco + 41, yco + 23, zco + 56, Blocks.nether_brick_fence, 0, 1);
      world.setBlock(xco + 42, yco + 23, zco + 56, Blocks.nether_brick_fence, 0, 1);
      world.setBlock(xco + 18, yco + 23, zco + 57, Blocks.stained_hardened_clay, 4, 1);
      world.setBlock(xco + 19, yco + 23, zco + 57, Blocks.stained_hardened_clay, 4, 1);
      world.setBlock(xco + 20, yco + 23, zco + 57, Blocks.stained_hardened_clay, 4, 1);
      world.setBlock(xco + 21, yco + 23, zco + 57, Blocks.stained_hardened_clay, 4, 1);
      world.setBlock(xco + 22, yco + 23, zco + 57, Blocks.stained_hardened_clay, 4, 1);
      world.setBlock(xco + 30, yco + 23, zco + 57, Blocks.stained_hardened_clay, 4, 1);
      world.setBlock(xco + 31, yco + 23, zco + 57, Blocks.stained_hardened_clay, 4, 1);
      world.setBlock(xco + 32, yco + 23, zco + 57, Blocks.stained_hardened_clay, 4, 1);
      world.setBlock(xco + 33, yco + 23, zco + 57, Blocks.stained_hardened_clay, 4, 1);
      world.setBlock(xco + 34, yco + 23, zco + 57, Blocks.stained_hardened_clay, 4, 1);
      world.setBlock(xco + 39, yco + 23, zco + 57, Blocks.stained_hardened_clay, 4, 1);
      world.setBlock(xco + 41, yco + 23, zco + 57, Blocks.redstone_block, 0, 1);
      world.setBlock(xco + 42, yco + 23, zco + 57, Blocks.nether_brick_fence, 0, 1);
      world.setBlock(xco + 43, yco + 23, zco + 57, Blocks.nether_brick_fence, 0, 1);
      world.setBlock(xco + 19, yco + 23, zco + 58, Blocks.stained_hardened_clay, 4, 1);
      world.setBlock(xco + 20, yco + 23, zco + 58, Blocks.stained_hardened_clay, 4, 1);
      world.setBlock(xco + 21, yco + 23, zco + 58, Blocks.stained_hardened_clay, 4, 1);
      world.setBlock(xco + 31, yco + 23, zco + 58, Blocks.stained_hardened_clay, 4, 1);
      world.setBlock(xco + 32, yco + 23, zco + 58, Blocks.stained_hardened_clay, 4, 1);
      world.setBlock(xco + 33, yco + 23, zco + 58, Blocks.stained_hardened_clay, 4, 1);
      world.setBlock(xco + 40, yco + 23, zco + 58, Blocks.stained_hardened_clay, 4, 1);
      world.setBlock(xco + 42, yco + 23, zco + 58, Blocks.redstone_block, 0, 1);
      world.setBlock(xco + 43, yco + 23, zco + 58, Blocks.nether_brick_fence, 0, 1);
      world.setBlock(xco + 34, yco + 23, zco + 59, Blocks.wool, 15, 1);
      world.setBlock(xco + 35, yco + 23, zco + 59, Blocks.wool, 15, 1);
      world.setBlock(xco + 36, yco + 23, zco + 59, Blocks.wool, 15, 1);
      world.setBlock(xco + 37, yco + 23, zco + 59, Blocks.wool, 15, 1);
      world.setBlock(xco + 41, yco + 23, zco + 59, Blocks.stained_hardened_clay, 4, 1);
      world.setBlock(xco + 42, yco + 23, zco + 59, Blocks.redstone_block, 0, 1);
      world.setBlock(xco + 43, yco + 23, zco + 59, Blocks.nether_brick_fence, 0, 1);
      world.setBlock(xco + 33, yco + 23, zco + 60, Blocks.wool, 15, 1);
      world.setBlock(xco + 38, yco + 23, zco + 60, Blocks.wool, 15, 1);
      world.setBlock(xco + 42, yco + 23, zco + 60, Blocks.stone, 0, 1);
      world.setBlock(xco + 43, yco + 23, zco + 60, Blocks.stone, 0, 1);
      world.setBlock(xco + 44, yco + 23, zco + 60, Blocks.stone, 0, 1);
      world.setBlock(xco + 45, yco + 23, zco + 60, Blocks.stone, 0, 1);
      world.setBlock(xco + 32, yco + 23, zco + 61, Blocks.wool, 15, 1);
      world.setBlock(xco + 39, yco + 23, zco + 61, Blocks.wool, 15, 1);
      world.setBlock(xco + 41, yco + 23, zco + 61, Blocks.stone, 0, 1);
      world.setBlock(xco + 46, yco + 23, zco + 61, Blocks.stone, 0, 1);
      world.setBlock(xco + 32, yco + 23, zco + 62, Blocks.wool, 15, 1);
      world.setBlock(xco + 39, yco + 23, zco + 62, Blocks.wool, 15, 1);
      world.setBlock(xco + 40, yco + 23, zco + 62, Blocks.stone, 0, 1);
      world.setBlock(xco + 47, yco + 23, zco + 62, Blocks.stone, 0, 1);
      world.setBlock(xco + 32, yco + 23, zco + 63, Blocks.wool, 15, 1);
      world.setBlock(xco + 39, yco + 23, zco + 63, Blocks.wool, 15, 1);
      world.setBlock(xco + 40, yco + 23, zco + 63, Blocks.stone, 0, 1);
      world.setBlock(xco + 47, yco + 23, zco + 63, Blocks.stone, 0, 1);
      world.setBlock(xco + 32, yco + 23, zco + 64, Blocks.wool, 15, 1);
      world.setBlock(xco + 39, yco + 23, zco + 64, Blocks.wool, 15, 1);
      world.setBlock(xco + 40, yco + 23, zco + 64, Blocks.stone, 0, 1);
      world.setBlock(xco + 47, yco + 23, zco + 64, Blocks.stone, 0, 1);
      world.setBlock(xco + 33, yco + 23, zco + 65, Blocks.wool, 15, 1);
      world.setBlock(xco + 38, yco + 23, zco + 65, Blocks.wool, 15, 1);
      world.setBlock(xco + 40, yco + 23, zco + 65, Blocks.stone, 0, 1);
      world.setBlock(xco + 47, yco + 23, zco + 65, Blocks.stone, 0, 1);
      world.setBlock(xco + 34, yco + 23, zco + 66, Blocks.wool, 15, 1);
      world.setBlock(xco + 35, yco + 23, zco + 66, Blocks.wool, 15, 1);
      world.setBlock(xco + 36, yco + 23, zco + 66, Blocks.wool, 15, 1);
      world.setBlock(xco + 37, yco + 23, zco + 66, Blocks.wool, 15, 1);
      world.setBlock(xco + 41, yco + 23, zco + 66, Blocks.stone, 0, 1);
      world.setBlock(xco + 46, yco + 23, zco + 66, Blocks.stone, 0, 1);
      world.setBlock(xco + 42, yco + 23, zco + 67, Blocks.stone, 0, 1);
      world.setBlock(xco + 43, yco + 23, zco + 67, Blocks.stone, 0, 1);
      world.setBlock(xco + 44, yco + 23, zco + 67, Blocks.stone, 0, 1);
      world.setBlock(xco + 45, yco + 23, zco + 67, Blocks.stone, 0, 1);
      world.setBlock(xco + 18, yco + 24, zco + 37, Blocks.stained_hardened_clay, 4, 1);
      world.setBlock(xco + 19, yco + 24, zco + 37, Blocks.stained_hardened_clay, 4, 1);
      world.setBlock(xco + 23, yco + 24, zco + 37, Blocks.stained_hardened_clay, 4, 1);
      world.setBlock(xco + 24, yco + 24, zco + 37, Blocks.stained_hardened_clay, 4, 1);
      world.setBlock(xco + 25, yco + 24, zco + 37, Blocks.stained_hardened_clay, 4, 1);
      world.setBlock(xco + 26, yco + 24, zco + 37, Blocks.diamond_block, 0, 1);
      world.setBlock(xco + 27, yco + 24, zco + 37, Blocks.stained_hardened_clay, 4, 1);
      world.setBlock(xco + 28, yco + 24, zco + 37, Blocks.stained_hardened_clay, 4, 1);
      world.setBlock(xco + 29, yco + 24, zco + 37, Blocks.stained_hardened_clay, 4, 1);
      world.setBlock(xco + 33, yco + 24, zco + 37, Blocks.stained_hardened_clay, 4, 1);
      world.setBlock(xco + 34, yco + 24, zco + 37, Blocks.stained_hardened_clay, 4, 1);
      world.setBlock(xco + 18, yco + 24, zco + 38, Blocks.stained_hardened_clay, 4, 1);
      world.setBlock(xco + 19, yco + 24, zco + 38, Blocks.stained_hardened_clay, 4, 1);
      world.setBlock(xco + 20, yco + 24, zco + 38, Blocks.stained_hardened_clay, 7, 1);
      world.setBlock(xco + 23, yco + 24, zco + 38, Blocks.diamond_block, 0, 1);
      world.setBlock(xco + 29, yco + 24, zco + 38, Blocks.diamond_block, 0, 1);
      world.setBlock(xco + 32, yco + 24, zco + 38, Blocks.stained_hardened_clay, 7, 1);
      world.setBlock(xco + 33, yco + 24, zco + 38, Blocks.stained_hardened_clay, 4, 1);
      world.setBlock(xco + 34, yco + 24, zco + 38, Blocks.stained_hardened_clay, 4, 1);
      world.setBlock(xco + 18, yco + 24, zco + 39, Blocks.stained_hardened_clay, 4, 1);
      world.setBlock(xco + 20, yco + 24, zco + 39, Blocks.stained_hardened_clay, 4, 1);
      world.setBlock(xco + 23, yco + 24, zco + 39, Blocks.diamond_block, 0, 1);
      world.setBlock(xco + 29, yco + 24, zco + 39, Blocks.diamond_block, 0, 1);
      world.setBlock(xco + 32, yco + 24, zco + 39, Blocks.stained_hardened_clay, 4, 1);
      world.setBlock(xco + 34, yco + 24, zco + 39, Blocks.stained_hardened_clay, 4, 1);
      world.setBlock(xco + 18, yco + 24, zco + 40, Blocks.stained_hardened_clay, 4, 1);
      world.setBlock(xco + 20, yco + 24, zco + 40, Blocks.stained_hardened_clay, 4, 1);
      world.setBlock(xco + 23, yco + 24, zco + 40, Blocks.diamond_block, 0, 1);
      world.setBlock(xco + 29, yco + 24, zco + 40, Blocks.diamond_block, 0, 1);
      world.setBlock(xco + 32, yco + 24, zco + 40, Blocks.stained_hardened_clay, 4, 1);
      world.setBlock(xco + 33, yco + 24, zco + 40, Blocks.stained_hardened_clay, 4, 1);
      world.setBlock(xco + 34, yco + 24, zco + 40, Blocks.stained_hardened_clay, 4, 1);
      world.setBlock(xco + 19, yco + 24, zco + 41, Blocks.quartz_block, 0, 1);
      world.setBlock(xco + 20, yco + 24, zco + 41, Blocks.quartz_block, 0, 1);
      world.setBlock(xco + 23, yco + 24, zco + 41, Blocks.stained_hardened_clay, 4, 1);
      world.setBlock(xco + 26, yco + 24, zco + 41, Blocks.stone, 0, 1);
      world.setBlock(xco + 27, yco + 24, zco + 41, Blocks.stone, 0, 1);
      world.setBlock(xco + 29, yco + 24, zco + 41, Blocks.stained_hardened_clay, 4, 1);
      world.setBlock(xco + 32, yco + 24, zco + 41, Blocks.quartz_block, 0, 1);
      world.setBlock(xco + 33, yco + 24, zco + 41, Blocks.quartz_block, 0, 1);
      world.setBlock(xco + 19, yco + 24, zco + 42, Blocks.quartz_block, 0, 1);
      world.setBlock(xco + 20, yco + 24, zco + 42, Blocks.quartz_block, 0, 1);
      world.setBlock(xco + 23, yco + 24, zco + 42, Blocks.stained_hardened_clay, 4, 1);
      world.setBlock(xco + 26, yco + 24, zco + 42, Blocks.stone, 0, 1);
      world.setBlock(xco + 27, yco + 24, zco + 42, Blocks.stone, 0, 1);
      world.setBlock(xco + 29, yco + 24, zco + 42, Blocks.stained_hardened_clay, 4, 1);
      world.setBlock(xco + 32, yco + 24, zco + 42, Blocks.quartz_block, 0, 1);
      world.setBlock(xco + 33, yco + 24, zco + 42, Blocks.quartz_block, 0, 1);
      world.setBlock(xco + 18, yco + 24, zco + 43, Blocks.stained_hardened_clay, 4, 1);
      world.setBlock(xco + 20, yco + 24, zco + 43, Blocks.stained_hardened_clay, 4, 1);
      world.setBlock(xco + 23, yco + 24, zco + 43, Blocks.diamond_block, 0, 1);
      world.setBlock(xco + 29, yco + 24, zco + 43, Blocks.diamond_block, 0, 1);
      world.setBlock(xco + 32, yco + 24, zco + 43, Blocks.stained_hardened_clay, 4, 1);
      world.setBlock(xco + 34, yco + 24, zco + 43, Blocks.stained_hardened_clay, 4, 1);
      world.setBlock(xco + 18, yco + 24, zco + 44, Blocks.stained_hardened_clay, 4, 1);
      world.setBlock(xco + 20, yco + 24, zco + 44, Blocks.stained_hardened_clay, 4, 1);
      world.setBlock(xco + 23, yco + 24, zco + 44, Blocks.diamond_block, 0, 1);
      world.setBlock(xco + 29, yco + 24, zco + 44, Blocks.diamond_block, 0, 1);
      world.setBlock(xco + 32, yco + 24, zco + 44, Blocks.stained_hardened_clay, 4, 1);
      world.setBlock(xco + 34, yco + 24, zco + 44, Blocks.stained_hardened_clay, 4, 1);
      world.setBlock(xco + 18, yco + 24, zco + 45, Blocks.stained_hardened_clay, 4, 1);
      world.setBlock(xco + 20, yco + 24, zco + 45, Blocks.stained_hardened_clay, 4, 1);
      world.setBlock(xco + 23, yco + 24, zco + 45, Blocks.diamond_block, 0, 1);
      world.setBlock(xco + 29, yco + 24, zco + 45, Blocks.diamond_block, 0, 1);
      world.setBlock(xco + 32, yco + 24, zco + 45, Blocks.stained_hardened_clay, 4, 1);
      world.setBlock(xco + 34, yco + 24, zco + 45, Blocks.stained_hardened_clay, 4, 1);
      world.setBlock(xco + 19, yco + 24, zco + 46, Blocks.quartz_block, 0, 1);
      world.setBlock(xco + 20, yco + 24, zco + 46, Blocks.quartz_block, 0, 1);
      world.setBlock(xco + 23, yco + 24, zco + 46, Blocks.stained_hardened_clay, 4, 1);
      world.setBlock(xco + 25, yco + 24, zco + 46, Blocks.stone, 0, 1);
      world.setBlock(xco + 26, yco + 24, zco + 46, Blocks.stone, 0, 1);
      world.setBlock(xco + 29, yco + 24, zco + 46, Blocks.stained_hardened_clay, 4, 1);
      world.setBlock(xco + 32, yco + 24, zco + 46, Blocks.quartz_block, 0, 1);
      world.setBlock(xco + 33, yco + 24, zco + 46, Blocks.quartz_block, 0, 1);
      world.setBlock(xco + 19, yco + 24, zco + 47, Blocks.quartz_block, 0, 1);
      world.setBlock(xco + 20, yco + 24, zco + 47, Blocks.quartz_block, 0, 1);
      world.setBlock(xco + 23, yco + 24, zco + 47, Blocks.stained_hardened_clay, 4, 1);
      world.setBlock(xco + 25, yco + 24, zco + 47, Blocks.stone, 0, 1);
      world.setBlock(xco + 26, yco + 24, zco + 47, Blocks.stone, 0, 1);
      world.setBlock(xco + 29, yco + 24, zco + 47, Blocks.stained_hardened_clay, 4, 1);
      world.setBlock(xco + 32, yco + 24, zco + 47, Blocks.quartz_block, 0, 1);
      world.setBlock(xco + 33, yco + 24, zco + 47, Blocks.quartz_block, 0, 1);
      world.setBlock(xco + 18, yco + 24, zco + 48, Blocks.stained_hardened_clay, 4, 1);
      world.setBlock(xco + 20, yco + 24, zco + 48, Blocks.stained_hardened_clay, 4, 1);
      world.setBlock(xco + 23, yco + 24, zco + 48, Blocks.diamond_block, 0, 1);
      world.setBlock(xco + 29, yco + 24, zco + 48, Blocks.diamond_block, 0, 1);
      world.setBlock(xco + 32, yco + 24, zco + 48, Blocks.stained_hardened_clay, 4, 1);
      world.setBlock(xco + 33, yco + 24, zco + 48, Blocks.stained_hardened_clay, 4, 1);
      world.setBlock(xco + 34, yco + 24, zco + 48, Blocks.stained_hardened_clay, 4, 1);
      world.setBlock(xco + 18, yco + 24, zco + 49, Blocks.stained_hardened_clay, 4, 1);
      world.setBlock(xco + 20, yco + 24, zco + 49, Blocks.stained_hardened_clay, 4, 1);
      world.setBlock(xco + 23, yco + 24, zco + 49, Blocks.diamond_block, 0, 1);
      world.setBlock(xco + 29, yco + 24, zco + 49, Blocks.diamond_block, 0, 1);
      world.setBlock(xco + 32, yco + 24, zco + 49, Blocks.stained_hardened_clay, 4, 1);
      world.setBlock(xco + 34, yco + 24, zco + 49, Blocks.stained_hardened_clay, 4, 1);
      world.setBlock(xco + 18, yco + 24, zco + 50, Blocks.stained_hardened_clay, 4, 1);
      world.setBlock(xco + 19, yco + 24, zco + 50, Blocks.stained_hardened_clay, 4, 1);
      world.setBlock(xco + 20, yco + 24, zco + 50, Blocks.stained_hardened_clay, 4, 1);
      world.setBlock(xco + 23, yco + 24, zco + 50, Blocks.diamond_block, 0, 1);
      world.setBlock(xco + 29, yco + 24, zco + 50, Blocks.diamond_block, 0, 1);
      world.setBlock(xco + 32, yco + 24, zco + 50, Blocks.stained_hardened_clay, 4, 1);
      world.setBlock(xco + 33, yco + 24, zco + 50, Blocks.stained_hardened_clay, 4, 1);
      world.setBlock(xco + 34, yco + 24, zco + 50, Blocks.stained_hardened_clay, 4, 1);
      world.setBlock(xco + 19, yco + 24, zco + 51, Blocks.stained_hardened_clay, 4, 1);
      world.setBlock(xco + 20, yco + 24, zco + 51, Blocks.stained_hardened_clay, 4, 1);
      world.setBlock(xco + 21, yco + 24, zco + 51, Blocks.stained_hardened_clay, 4, 1);
      world.setBlock(xco + 23, yco + 24, zco + 51, Blocks.stained_hardened_clay, 4, 1);
      world.setBlock(xco + 24, yco + 24, zco + 51, Blocks.stained_hardened_clay, 4, 1);
      world.setBlock(xco + 25, yco + 24, zco + 51, Blocks.stained_hardened_clay, 4, 1);
      world.setBlock(xco + 26, yco + 24, zco + 51, Blocks.stained_hardened_clay, 4, 1);
      world.setBlock(xco + 27, yco + 24, zco + 51, Blocks.stained_hardened_clay, 4, 1);
      world.setBlock(xco + 28, yco + 24, zco + 51, Blocks.stained_hardened_clay, 4, 1);
      world.setBlock(xco + 29, yco + 24, zco + 51, Blocks.stained_hardened_clay, 4, 1);
      world.setBlock(xco + 31, yco + 24, zco + 51, Blocks.stained_hardened_clay, 4, 1);
      world.setBlock(xco + 32, yco + 24, zco + 51, Blocks.stained_hardened_clay, 4, 1);
      world.setBlock(xco + 33, yco + 24, zco + 51, Blocks.stained_hardened_clay, 4, 1);
      world.setBlock(xco + 18, yco + 24, zco + 52, Blocks.stained_hardened_clay, 4, 1);
      world.setBlock(xco + 22, yco + 24, zco + 52, Blocks.stained_hardened_clay, 4, 1);
      world.setBlock(xco + 30, yco + 24, zco + 52, Blocks.stained_hardened_clay, 4, 1);
      world.setBlock(xco + 34, yco + 24, zco + 52, Blocks.stained_hardened_clay, 4, 1);
      world.setBlock(xco + 17, yco + 24, zco + 53, Blocks.stained_hardened_clay, 4, 1);
      world.setBlock(xco + 23, yco + 24, zco + 53, Blocks.stained_hardened_clay, 4, 1);
      world.setBlock(xco + 29, yco + 24, zco + 53, Blocks.stained_hardened_clay, 4, 1);
      world.setBlock(xco + 35, yco + 24, zco + 53, Blocks.stained_hardened_clay, 4, 1);
      world.setBlock(xco + 17, yco + 24, zco + 54, Blocks.stained_hardened_clay, 4, 1);
      world.setBlock(xco + 23, yco + 24, zco + 54, Blocks.stained_hardened_clay, 4, 1);
return true;
  }
}
