package com.slugterra.world.greatForge;
import java.util.Random;

import net.minecraft.block.BlockColored;
import net.minecraft.block.BlockRedstoneTorch;
import net.minecraft.block.BlockStairs;
import net.minecraft.block.BlockStaticLiquid;
import net.minecraft.block.BlockStone;
import net.minecraft.init.Blocks;
import net.minecraft.util.math.BlockPos;
import net.minecraft.world.World;
public class GreatWesternForgeStructure9 {
public boolean generate(World world, Random par2Random, BlockPos pos) {
      world.setBlockState(pos.add(21, 14, 40), Blocks.QUARTZ_BLOCK.getDefaultState());
      world.setBlockState(pos.add(22, 14, 40), Blocks.QUARTZ_BLOCK.getDefaultState());
      world.setBlockState(pos.add(23, 14, 40), ((BlockStaticLiquid)Blocks.LAVA).getStateFromMeta(10));
      world.setBlockState(pos.add(29, 14, 40), ((BlockStaticLiquid)Blocks.LAVA).getStateFromMeta(10));
      world.setBlockState(pos.add(30, 14, 40), Blocks.QUARTZ_BLOCK.getDefaultState());
      world.setBlockState(pos.add(31, 14, 40), Blocks.QUARTZ_BLOCK.getDefaultState());
      world.setBlockState(pos.add(32, 14, 40), ((BlockColored)Blocks.STAINED_HARDENED_CLAY).getStateFromMeta(4));
      world.setBlockState(pos.add(35, 14, 40), ((BlockColored)Blocks.STAINED_HARDENED_CLAY).getStateFromMeta(4));
      world.setBlockState(pos.add(36, 14, 40), ((BlockColored)Blocks.STAINED_HARDENED_CLAY).getStateFromMeta(4));
      world.setBlockState(pos.add(2, 14, 41), Blocks.STONE.getDefaultState());
      world.setBlockState(pos.add(3, 14, 41), Blocks.STONE.getDefaultState());
      world.setBlockState(pos.add(9, 14, 41), Blocks.STONE.getDefaultState());
      world.setBlockState(pos.add(10, 14, 41), Blocks.STONE.getDefaultState());
      world.setBlockState(pos.add(17, 14, 41), Blocks.QUARTZ_BLOCK.getDefaultState());
      world.setBlockState(pos.add(20, 14, 41), Blocks.QUARTZ_BLOCK.getDefaultState());
      world.setBlockState(pos.add(21, 14, 41), Blocks.QUARTZ_BLOCK.getDefaultState());
      world.setBlockState(pos.add(22, 14, 41), Blocks.QUARTZ_BLOCK.getDefaultState());
      world.setBlockState(pos.add(23, 14, 41), Blocks.STONE.getDefaultState());
      world.setBlockState(pos.add(24, 14, 41), Blocks.STONE.getDefaultState());
      world.setBlockState(pos.add(25, 14, 41), Blocks.STONE.getDefaultState());
      world.setBlockState(pos.add(26, 14, 41), Blocks.STONE.getDefaultState());
      world.setBlockState(pos.add(27, 14, 41), Blocks.STONE.getDefaultState());
      world.setBlockState(pos.add(28, 14, 41), Blocks.STONE.getDefaultState());
      world.setBlockState(pos.add(29, 14, 41), Blocks.STONE.getDefaultState());
      world.setBlockState(pos.add(30, 14, 41), Blocks.QUARTZ_BLOCK.getDefaultState());
      world.setBlockState(pos.add(31, 14, 41), Blocks.QUARTZ_BLOCK.getDefaultState());
      world.setBlockState(pos.add(32, 14, 41), Blocks.QUARTZ_BLOCK.getDefaultState());
      world.setBlockState(pos.add(35, 14, 41), Blocks.QUARTZ_BLOCK.getDefaultState());
      world.setBlockState(pos.add(2, 14, 42), Blocks.STONE.getDefaultState());
      world.setBlockState(pos.add(10, 14, 42), Blocks.STONE.getDefaultState());
      world.setBlockState(pos.add(17, 14, 42), Blocks.QUARTZ_BLOCK.getDefaultState());
      world.setBlockState(pos.add(20, 14, 42), Blocks.QUARTZ_BLOCK.getDefaultState());
      world.setBlockState(pos.add(21, 14, 42), Blocks.QUARTZ_BLOCK.getDefaultState());
      world.setBlockState(pos.add(22, 14, 42), Blocks.QUARTZ_BLOCK.getDefaultState());
      world.setBlockState(pos.add(23, 14, 42), Blocks.STONE.getDefaultState());
      world.setBlockState(pos.add(24, 14, 42), Blocks.STONE.getDefaultState());
      world.setBlockState(pos.add(25, 14, 42), Blocks.STONE.getDefaultState());
      world.setBlockState(pos.add(26, 14, 42), Blocks.STONE.getDefaultState());
      world.setBlockState(pos.add(27, 14, 42), Blocks.STONE.getDefaultState());
      world.setBlockState(pos.add(28, 14, 42), Blocks.STONE.getDefaultState());
      world.setBlockState(pos.add(29, 14, 42), Blocks.STONE.getDefaultState());
      world.setBlockState(pos.add(30, 14, 42), Blocks.QUARTZ_BLOCK.getDefaultState());
      world.setBlockState(pos.add(31, 14, 42), Blocks.QUARTZ_BLOCK.getDefaultState());
      world.setBlockState(pos.add(32, 14, 42), Blocks.QUARTZ_BLOCK.getDefaultState());
      world.setBlockState(pos.add(35, 14, 42), Blocks.QUARTZ_BLOCK.getDefaultState());
      world.setBlockState(pos.add(2, 14, 43), Blocks.STONE.getDefaultState());
      world.setBlockState(pos.add(10, 14, 43), Blocks.STONE.getDefaultState());
      world.setBlockState(pos.add(16, 14, 43), ((BlockColored)Blocks.STAINED_HARDENED_CLAY).getStateFromMeta(4));
      world.setBlockState(pos.add(20, 14, 43), ((BlockColored)Blocks.STAINED_HARDENED_CLAY).getStateFromMeta(4));
      world.setBlockState(pos.add(21, 14, 43), Blocks.QUARTZ_BLOCK.getDefaultState());
      world.setBlockState(pos.add(22, 14, 43), Blocks.QUARTZ_BLOCK.getDefaultState());
      world.setBlockState(pos.add(23, 14, 43), ((BlockStaticLiquid)Blocks.LAVA).getStateFromMeta(10));
      world.setBlockState(pos.add(29, 14, 43), ((BlockStaticLiquid)Blocks.LAVA).getStateFromMeta(10));
      world.setBlockState(pos.add(30, 14, 43), Blocks.QUARTZ_BLOCK.getDefaultState());
      world.setBlockState(pos.add(31, 14, 43), Blocks.QUARTZ_BLOCK.getDefaultState());
      world.setBlockState(pos.add(32, 14, 43), ((BlockColored)Blocks.STAINED_HARDENED_CLAY).getStateFromMeta(4));
      world.setBlockState(pos.add(36, 14, 43), ((BlockColored)Blocks.STAINED_HARDENED_CLAY).getStateFromMeta(4));
      world.setBlockState(pos.add(2, 14, 44), Blocks.STONE.getDefaultState());
      world.setBlockState(pos.add(10, 14, 44), Blocks.STONE.getDefaultState());
      world.setBlockState(pos.add(16, 14, 44), ((BlockColored)Blocks.STAINED_HARDENED_CLAY).getStateFromMeta(4));
      world.setBlockState(pos.add(20, 14, 44), ((BlockColored)Blocks.STAINED_HARDENED_CLAY).getStateFromMeta(4));
      world.setBlockState(pos.add(21, 14, 44), Blocks.QUARTZ_BLOCK.getDefaultState());
      world.setBlockState(pos.add(22, 14, 44), Blocks.QUARTZ_BLOCK.getDefaultState());
      world.setBlockState(pos.add(30, 14, 44), Blocks.QUARTZ_BLOCK.getDefaultState());
      world.setBlockState(pos.add(31, 14, 44), Blocks.QUARTZ_BLOCK.getDefaultState());
      world.setBlockState(pos.add(32, 14, 44), ((BlockColored)Blocks.STAINED_HARDENED_CLAY).getStateFromMeta(4));
      world.setBlockState(pos.add(36, 14, 44), ((BlockColored)Blocks.STAINED_HARDENED_CLAY).getStateFromMeta(4));
      world.setBlockState(pos.add(2, 14, 45), Blocks.STONE.getDefaultState());
      world.setBlockState(pos.add(3, 14, 45), Blocks.STONE.getDefaultState());
      world.setBlockState(pos.add(9, 14, 45), Blocks.STONE.getDefaultState());
      world.setBlockState(pos.add(10, 14, 45), Blocks.STONE.getDefaultState());
      world.setBlockState(pos.add(16, 14, 45), ((BlockColored)Blocks.STAINED_HARDENED_CLAY).getStateFromMeta(4));
      world.setBlockState(pos.add(20, 14, 45), ((BlockColored)Blocks.STAINED_HARDENED_CLAY).getStateFromMeta(4));
      world.setBlockState(pos.add(21, 14, 45), Blocks.QUARTZ_BLOCK.getDefaultState());
      world.setBlockState(pos.add(22, 14, 45), Blocks.QUARTZ_BLOCK.getDefaultState());
      world.setBlockState(pos.add(23, 14, 45), ((BlockStaticLiquid)Blocks.LAVA).getStateFromMeta(2));
      world.setBlockState(pos.add(29, 14, 45), ((BlockStaticLiquid)Blocks.LAVA).getStateFromMeta(2));
      world.setBlockState(pos.add(30, 14, 45), Blocks.QUARTZ_BLOCK.getDefaultState());
      world.setBlockState(pos.add(31, 14, 45), Blocks.QUARTZ_BLOCK.getDefaultState());
      world.setBlockState(pos.add(32, 14, 45), ((BlockColored)Blocks.STAINED_HARDENED_CLAY).getStateFromMeta(4));
      world.setBlockState(pos.add(36, 14, 45), ((BlockColored)Blocks.STAINED_HARDENED_CLAY).getStateFromMeta(4));
      world.setBlockState(pos.add(3, 14, 46), Blocks.STONE.getDefaultState());
      world.setBlockState(pos.add(4, 14, 46), Blocks.STONE.getDefaultState());
      world.setBlockState(pos.add(8, 14, 46), Blocks.STONE.getDefaultState());
      world.setBlockState(pos.add(9, 14, 46), Blocks.STONE.getDefaultState());
      world.setBlockState(pos.add(17, 14, 46), Blocks.QUARTZ_BLOCK.getDefaultState());
      world.setBlockState(pos.add(18, 14, 46), Blocks.QUARTZ_BLOCK.getDefaultState());
      world.setBlockState(pos.add(19, 14, 46), Blocks.QUARTZ_BLOCK.getDefaultState());
      world.setBlockState(pos.add(20, 14, 46), Blocks.QUARTZ_BLOCK.getDefaultState());
      world.setBlockState(pos.add(21, 14, 46), Blocks.QUARTZ_BLOCK.getDefaultState());
      world.setBlockState(pos.add(22, 14, 46), Blocks.QUARTZ_BLOCK.getDefaultState());
      world.setBlockState(pos.add(23, 14, 46), Blocks.LAVA.getDefaultState());
      world.setBlockState(pos.add(24, 14, 46), Blocks.STONE.getDefaultState());
      world.setBlockState(pos.add(25, 14, 46), Blocks.STONE.getDefaultState());
      world.setBlockState(pos.add(26, 14, 46), Blocks.STONE.getDefaultState());
      world.setBlockState(pos.add(27, 14, 46), Blocks.STONE.getDefaultState());
      world.setBlockState(pos.add(28, 14, 46), Blocks.STONE.getDefaultState());
      world.setBlockState(pos.add(29, 14, 46), Blocks.LAVA.getDefaultState());
      world.setBlockState(pos.add(30, 14, 46), Blocks.QUARTZ_BLOCK.getDefaultState());
      world.setBlockState(pos.add(31, 14, 46), Blocks.QUARTZ_BLOCK.getDefaultState());
      world.setBlockState(pos.add(32, 14, 46), Blocks.QUARTZ_BLOCK.getDefaultState());
      world.setBlockState(pos.add(35, 14, 46), Blocks.QUARTZ_BLOCK.getDefaultState());
      world.setBlockState(pos.add(4, 14, 47), Blocks.STONE.getDefaultState());
      world.setBlockState(pos.add(5, 14, 47), Blocks.STONE.getDefaultState());
      world.setBlockState(pos.add(6, 14, 47), Blocks.STONE.getDefaultState());
      world.setBlockState(pos.add(7, 14, 47), Blocks.STONE.getDefaultState());
      world.setBlockState(pos.add(8, 14, 47), Blocks.STONE.getDefaultState());
      world.setBlockState(pos.add(17, 14, 47), Blocks.QUARTZ_BLOCK.getDefaultState());
      world.setBlockState(pos.add(18, 14, 47), Blocks.QUARTZ_BLOCK.getDefaultState());
      world.setBlockState(pos.add(19, 14, 47), Blocks.QUARTZ_BLOCK.getDefaultState());
      world.setBlockState(pos.add(20, 14, 47), Blocks.QUARTZ_BLOCK.getDefaultState());
      world.setBlockState(pos.add(21, 14, 47), Blocks.QUARTZ_BLOCK.getDefaultState());
      world.setBlockState(pos.add(22, 14, 47), Blocks.QUARTZ_BLOCK.getDefaultState());
      world.setBlockState(pos.add(23, 14, 47), Blocks.LAVA.getDefaultState());
      world.setBlockState(pos.add(24, 14, 47), Blocks.STONE.getDefaultState());
      world.setBlockState(pos.add(25, 14, 47), Blocks.STONE.getDefaultState());
      world.setBlockState(pos.add(26, 14, 47), Blocks.STONE.getDefaultState());
      world.setBlockState(pos.add(27, 14, 47), Blocks.STONE.getDefaultState());
      world.setBlockState(pos.add(28, 14, 47), Blocks.STONE.getDefaultState());
      world.setBlockState(pos.add(29, 14, 47), Blocks.LAVA.getDefaultState());
      world.setBlockState(pos.add(30, 14, 47), Blocks.QUARTZ_BLOCK.getDefaultState());
      world.setBlockState(pos.add(31, 14, 47), Blocks.QUARTZ_BLOCK.getDefaultState());
      world.setBlockState(pos.add(32, 14, 47), Blocks.QUARTZ_BLOCK.getDefaultState());
      world.setBlockState(pos.add(35, 14, 47), Blocks.QUARTZ_BLOCK.getDefaultState());
      world.setBlockState(pos.add(16, 14, 48), ((BlockColored)Blocks.STAINED_HARDENED_CLAY).getStateFromMeta(4));
      world.setBlockState(pos.add(20, 14, 48), ((BlockColored)Blocks.STAINED_HARDENED_CLAY).getStateFromMeta(4));
      world.setBlockState(pos.add(21, 14, 48), Blocks.QUARTZ_BLOCK.getDefaultState());
      world.setBlockState(pos.add(22, 14, 48), Blocks.QUARTZ_BLOCK.getDefaultState());
      world.setBlockState(pos.add(23, 14, 48), ((BlockStaticLiquid)Blocks.LAVA).getStateFromMeta(2));
      world.setBlockState(pos.add(29, 14, 48), ((BlockStaticLiquid)Blocks.LAVA).getStateFromMeta(2));
      world.setBlockState(pos.add(30, 14, 48), Blocks.QUARTZ_BLOCK.getDefaultState());
      world.setBlockState(pos.add(31, 14, 48), Blocks.QUARTZ_BLOCK.getDefaultState());
      world.setBlockState(pos.add(32, 14, 48), ((BlockColored)Blocks.STAINED_HARDENED_CLAY).getStateFromMeta(4));
      world.setBlockState(pos.add(36, 14, 48), ((BlockColored)Blocks.STAINED_HARDENED_CLAY).getStateFromMeta(4));
      world.setBlockState(pos.add(16, 14, 49), ((BlockColored)Blocks.STAINED_HARDENED_CLAY).getStateFromMeta(4));
      world.setBlockState(pos.add(20, 14, 49), ((BlockColored)Blocks.STAINED_HARDENED_CLAY).getStateFromMeta(4));
      world.setBlockState(pos.add(21, 14, 49), Blocks.QUARTZ_BLOCK.getDefaultState());
      world.setBlockState(pos.add(22, 14, 49), Blocks.QUARTZ_BLOCK.getDefaultState());
      world.setBlockState(pos.add(30, 14, 49), Blocks.QUARTZ_BLOCK.getDefaultState());
      world.setBlockState(pos.add(31, 14, 49), Blocks.QUARTZ_BLOCK.getDefaultState());
      world.setBlockState(pos.add(32, 14, 49), ((BlockColored)Blocks.STAINED_HARDENED_CLAY).getStateFromMeta(4));
      world.setBlockState(pos.add(36, 14, 49), ((BlockColored)Blocks.STAINED_HARDENED_CLAY).getStateFromMeta(4));
      world.setBlockState(pos.add(16, 14, 50), ((BlockColored)Blocks.STAINED_HARDENED_CLAY).getStateFromMeta(4));
      world.setBlockState(pos.add(17, 14, 50), ((BlockColored)Blocks.STAINED_HARDENED_CLAY).getStateFromMeta(4));
      world.setBlockState(pos.add(18, 14, 50), ((BlockColored)Blocks.STAINED_HARDENED_CLAY).getStateFromMeta(4));
      world.setBlockState(pos.add(19, 14, 50), ((BlockColored)Blocks.STAINED_HARDENED_CLAY).getStateFromMeta(4));
      world.setBlockState(pos.add(20, 14, 50), ((BlockColored)Blocks.STAINED_HARDENED_CLAY).getStateFromMeta(4));
      world.setBlockState(pos.add(21, 14, 50), Blocks.QUARTZ_BLOCK.getDefaultState());
      world.setBlockState(pos.add(22, 14, 50), Blocks.QUARTZ_BLOCK.getDefaultState());
      world.setBlockState(pos.add(30, 14, 50), Blocks.QUARTZ_BLOCK.getDefaultState());
      world.setBlockState(pos.add(31, 14, 50), Blocks.QUARTZ_BLOCK.getDefaultState());
      world.setBlockState(pos.add(32, 14, 50), ((BlockColored)Blocks.STAINED_HARDENED_CLAY).getStateFromMeta(4));
      world.setBlockState(pos.add(33, 14, 50), ((BlockColored)Blocks.STAINED_HARDENED_CLAY).getStateFromMeta(4));
      world.setBlockState(pos.add(34, 14, 50), ((BlockColored)Blocks.STAINED_HARDENED_CLAY).getStateFromMeta(4));
      world.setBlockState(pos.add(35, 14, 50), ((BlockColored)Blocks.STAINED_HARDENED_CLAY).getStateFromMeta(4));
      world.setBlockState(pos.add(36, 14, 50), ((BlockColored)Blocks.STAINED_HARDENED_CLAY).getStateFromMeta(4));
      world.setBlockState(pos.add(18, 14, 51), ((BlockColored)Blocks.STAINED_HARDENED_CLAY).getStateFromMeta(4));
      world.setBlockState(pos.add(19, 14, 51), ((BlockColored)Blocks.STAINED_HARDENED_CLAY).getStateFromMeta(4));
      world.setBlockState(pos.add(20, 14, 51), ((BlockColored)Blocks.STAINED_HARDENED_CLAY).getStateFromMeta(4));
      world.setBlockState(pos.add(21, 14, 51), ((BlockColored)Blocks.STAINED_HARDENED_CLAY).getStateFromMeta(4));
      world.setBlockState(pos.add(30, 14, 51), ((BlockColored)Blocks.STAINED_HARDENED_CLAY).getStateFromMeta(4));
      world.setBlockState(pos.add(31, 14, 51), ((BlockColored)Blocks.STAINED_HARDENED_CLAY).getStateFromMeta(4));
      world.setBlockState(pos.add(32, 14, 51), ((BlockColored)Blocks.STAINED_HARDENED_CLAY).getStateFromMeta(4));
      world.setBlockState(pos.add(33, 14, 51), ((BlockColored)Blocks.STAINED_HARDENED_CLAY).getStateFromMeta(4));
      world.setBlockState(pos.add(34, 14, 51), ((BlockColored)Blocks.STAINED_HARDENED_CLAY).getStateFromMeta(4));
      world.setBlockState(pos.add(17, 14, 52), ((BlockColored)Blocks.STAINED_HARDENED_CLAY).getStateFromMeta(4));
      world.setBlockState(pos.add(18, 14, 52), ((BlockColored)Blocks.STAINED_HARDENED_CLAY).getStateFromMeta(4));
      world.setBlockState(pos.add(22, 14, 52), ((BlockColored)Blocks.STAINED_HARDENED_CLAY).getStateFromMeta(4));
      world.setBlockState(pos.add(29, 14, 52), ((BlockColored)Blocks.STAINED_HARDENED_CLAY).getStateFromMeta(4));
      world.setBlockState(pos.add(30, 14, 52), ((BlockColored)Blocks.STAINED_HARDENED_CLAY).getStateFromMeta(4));
      world.setBlockState(pos.add(34, 14, 52), ((BlockColored)Blocks.STAINED_HARDENED_CLAY).getStateFromMeta(4));
      world.setBlockState(pos.add(35, 14, 52), ((BlockColored)Blocks.STAINED_HARDENED_CLAY).getStateFromMeta(4));
      world.setBlockState(pos.add(16, 14, 53), ((BlockColored)Blocks.STAINED_HARDENED_CLAY).getStateFromMeta(4));
      world.setBlockState(pos.add(17, 14, 53), ((BlockColored)Blocks.STAINED_HARDENED_CLAY).getStateFromMeta(4));
      world.setBlockState(pos.add(23, 14, 53), ((BlockColored)Blocks.STAINED_HARDENED_CLAY).getStateFromMeta(4));
      world.setBlockState(pos.add(24, 14, 53), ((BlockColored)Blocks.STAINED_HARDENED_CLAY).getStateFromMeta(4));
      world.setBlockState(pos.add(28, 14, 53), ((BlockColored)Blocks.STAINED_HARDENED_CLAY).getStateFromMeta(4));
      world.setBlockState(pos.add(29, 14, 53), ((BlockColored)Blocks.STAINED_HARDENED_CLAY).getStateFromMeta(4));
      world.setBlockState(pos.add(35, 14, 53), ((BlockColored)Blocks.STAINED_HARDENED_CLAY).getStateFromMeta(4));
      world.setBlockState(pos.add(36, 14, 53), ((BlockColored)Blocks.STAINED_HARDENED_CLAY).getStateFromMeta(4));
      world.setBlockState(pos.add(16, 14, 54), ((BlockColored)Blocks.STAINED_HARDENED_CLAY).getStateFromMeta(4));
      world.setBlockState(pos.add(17, 14, 54), ((BlockColored)Blocks.STAINED_HARDENED_CLAY).getStateFromMeta(4));
      world.setBlockState(pos.add(23, 14, 54), ((BlockColored)Blocks.STAINED_HARDENED_CLAY).getStateFromMeta(4));
      world.setBlockState(pos.add(24, 14, 54), ((BlockColored)Blocks.STAINED_HARDENED_CLAY).getStateFromMeta(4));
      world.setBlockState(pos.add(28, 14, 54), ((BlockColored)Blocks.STAINED_HARDENED_CLAY).getStateFromMeta(4));
      world.setBlockState(pos.add(29, 14, 54), ((BlockColored)Blocks.STAINED_HARDENED_CLAY).getStateFromMeta(4));
      world.setBlockState(pos.add(35, 14, 54), ((BlockColored)Blocks.STAINED_HARDENED_CLAY).getStateFromMeta(4));
      world.setBlockState(pos.add(36, 14, 54), ((BlockColored)Blocks.STAINED_HARDENED_CLAY).getStateFromMeta(4));
      world.setBlockState(pos.add(16, 14, 55), ((BlockColored)Blocks.STAINED_HARDENED_CLAY).getStateFromMeta(4));
      world.setBlockState(pos.add(17, 14, 55), ((BlockColored)Blocks.STAINED_HARDENED_CLAY).getStateFromMeta(4));
      world.setBlockState(pos.add(23, 14, 55), ((BlockColored)Blocks.STAINED_HARDENED_CLAY).getStateFromMeta(4));
      world.setBlockState(pos.add(24, 14, 55), ((BlockColored)Blocks.STAINED_HARDENED_CLAY).getStateFromMeta(4));
      world.setBlockState(pos.add(28, 14, 55), ((BlockColored)Blocks.STAINED_HARDENED_CLAY).getStateFromMeta(4));
      world.setBlockState(pos.add(29, 14, 55), ((BlockColored)Blocks.STAINED_HARDENED_CLAY).getStateFromMeta(4));
      world.setBlockState(pos.add(35, 14, 55), ((BlockColored)Blocks.STAINED_HARDENED_CLAY).getStateFromMeta(4));
      world.setBlockState(pos.add(36, 14, 55), ((BlockColored)Blocks.STAINED_HARDENED_CLAY).getStateFromMeta(4));
      world.setBlockState(pos.add(37, 14, 55), ((BlockColored)Blocks.STAINED_HARDENED_CLAY).getStateFromMeta(4));
      world.setBlockState(pos.add(17, 14, 56), ((BlockColored)Blocks.STAINED_HARDENED_CLAY).getStateFromMeta(4));
      world.setBlockState(pos.add(18, 14, 56), ((BlockColored)Blocks.STAINED_HARDENED_CLAY).getStateFromMeta(4));
      world.setBlockState(pos.add(22, 14, 56), ((BlockColored)Blocks.STAINED_HARDENED_CLAY).getStateFromMeta(4));
      world.setBlockState(pos.add(23, 14, 56), ((BlockColored)Blocks.STAINED_HARDENED_CLAY).getStateFromMeta(4));
      world.setBlockState(pos.add(29, 14, 56), ((BlockColored)Blocks.STAINED_HARDENED_CLAY).getStateFromMeta(4));
      world.setBlockState(pos.add(30, 14, 56), ((BlockColored)Blocks.STAINED_HARDENED_CLAY).getStateFromMeta(4));
      world.setBlockState(pos.add(34, 14, 56), ((BlockColored)Blocks.STAINED_HARDENED_CLAY).getStateFromMeta(4));
      world.setBlockState(pos.add(35, 14, 56), ((BlockColored)Blocks.STAINED_HARDENED_CLAY).getStateFromMeta(4));
      world.setBlockState(pos.add(38, 14, 56), ((BlockColored)Blocks.STAINED_HARDENED_CLAY).getStateFromMeta(4));
      world.setBlockState(pos.add(39, 14, 56), ((BlockColored)Blocks.WOOL).getStateFromMeta(15));
      world.setBlockState(pos.add(40, 14, 56), ((BlockColored)Blocks.WOOL).getStateFromMeta(15));
      world.setBlockState(pos.add(18, 14, 57), ((BlockColored)Blocks.STAINED_HARDENED_CLAY).getStateFromMeta(4));
      world.setBlockState(pos.add(19, 14, 57), ((BlockColored)Blocks.STAINED_HARDENED_CLAY).getStateFromMeta(4));
      world.setBlockState(pos.add(20, 14, 57), ((BlockColored)Blocks.STAINED_HARDENED_CLAY).getStateFromMeta(4));
      world.setBlockState(pos.add(21, 14, 57), ((BlockColored)Blocks.STAINED_HARDENED_CLAY).getStateFromMeta(4));
      world.setBlockState(pos.add(22, 14, 57), ((BlockColored)Blocks.STAINED_HARDENED_CLAY).getStateFromMeta(4));
      world.setBlockState(pos.add(23, 14, 57), Blocks.STONE.getDefaultState());
      world.setBlockState(pos.add(24, 14, 57), Blocks.NETHER_BRICK_FENCE.getDefaultState());
      world.setBlockState(pos.add(28, 14, 57), Blocks.NETHER_BRICK_FENCE.getDefaultState());
      world.setBlockState(pos.add(29, 14, 57), Blocks.STONE.getDefaultState());
      world.setBlockState(pos.add(30, 14, 57), ((BlockColored)Blocks.STAINED_HARDENED_CLAY).getStateFromMeta(4));
      world.setBlockState(pos.add(31, 14, 57), ((BlockColored)Blocks.STAINED_HARDENED_CLAY).getStateFromMeta(4));
      world.setBlockState(pos.add(32, 14, 57), ((BlockColored)Blocks.STAINED_HARDENED_CLAY).getStateFromMeta(4));
      world.setBlockState(pos.add(33, 14, 57), ((BlockColored)Blocks.STAINED_HARDENED_CLAY).getStateFromMeta(4));
      world.setBlockState(pos.add(34, 14, 57), ((BlockColored)Blocks.STAINED_HARDENED_CLAY).getStateFromMeta(4));
      world.setBlockState(pos.add(39, 14, 57), ((BlockColored)Blocks.STAINED_HARDENED_CLAY).getStateFromMeta(4));
      world.setBlockState(pos.add(41, 14, 57), ((BlockColored)Blocks.WOOL).getStateFromMeta(15));
      world.setBlockState(pos.add(19, 14, 58), ((BlockColored)Blocks.STAINED_HARDENED_CLAY).getStateFromMeta(4));
      world.setBlockState(pos.add(20, 14, 58), ((BlockColored)Blocks.STAINED_HARDENED_CLAY).getStateFromMeta(4));
      world.setBlockState(pos.add(21, 14, 58), ((BlockColored)Blocks.STAINED_HARDENED_CLAY).getStateFromMeta(4));
      world.setBlockState(pos.add(23, 14, 58), Blocks.STONE.getDefaultState());
      world.setBlockState(pos.add(29, 14, 58), Blocks.STONE.getDefaultState());
      world.setBlockState(pos.add(31, 14, 58), ((BlockColored)Blocks.STAINED_HARDENED_CLAY).getStateFromMeta(4));
      world.setBlockState(pos.add(32, 14, 58), ((BlockColored)Blocks.STAINED_HARDENED_CLAY).getStateFromMeta(4));
      world.setBlockState(pos.add(33, 14, 58), ((BlockColored)Blocks.STAINED_HARDENED_CLAY).getStateFromMeta(4));
      world.setBlockState(pos.add(40, 14, 58), ((BlockColored)Blocks.STAINED_HARDENED_CLAY).getStateFromMeta(4));
      world.setBlockState(pos.add(42, 14, 58), ((BlockColored)Blocks.WOOL).getStateFromMeta(15));
      world.setBlockState(pos.add(21, 14, 59), Blocks.STONE.getDefaultState());
      world.setBlockState(pos.add(22, 14, 59), Blocks.STONE.getDefaultState());
      world.setBlockState(pos.add(23, 14, 59), ((BlockRedstoneTorch)Blocks.REDSTONE_TORCH).getStateFromMeta(1));
      world.setBlockState(pos.add(28, 14, 59), ((BlockRedstoneTorch)Blocks.REDSTONE_TORCH).getStateFromMeta(2));
      world.setBlockState(pos.add(29, 14, 59), Blocks.STONE.getDefaultState());
      world.setBlockState(pos.add(34, 14, 59), ((BlockColored)Blocks.WOOL).getStateFromMeta(15));
      world.setBlockState(pos.add(35, 14, 59), ((BlockColored)Blocks.WOOL).getStateFromMeta(15));
      world.setBlockState(pos.add(36, 14, 59), ((BlockColored)Blocks.WOOL).getStateFromMeta(15));
      world.setBlockState(pos.add(37, 14, 59), ((BlockColored)Blocks.WOOL).getStateFromMeta(15));
      world.setBlockState(pos.add(41, 14, 59), ((BlockColored)Blocks.STAINED_HARDENED_CLAY).getStateFromMeta(4));
      world.setBlockState(pos.add(42, 14, 59), ((BlockColored)Blocks.WOOL).getStateFromMeta(15));
      world.setBlockState(pos.add(18, 14, 60), Blocks.STONE.getDefaultState());
      world.setBlockState(pos.add(19, 14, 60), Blocks.STONE.getDefaultState());
      world.setBlockState(pos.add(20, 14, 60), Blocks.STONE.getDefaultState());
      world.setBlockState(pos.add(21, 14, 60), ((BlockRedstoneTorch)Blocks.REDSTONE_TORCH).getStateFromMeta(1));
      world.setBlockState(pos.add(29, 14, 60), Blocks.STONE.getDefaultState());
      world.setBlockState(pos.add(33, 14, 60), ((BlockColored)Blocks.WOOL).getStateFromMeta(15));
      world.setBlockState(pos.add(38, 14, 60), ((BlockColored)Blocks.WOOL).getStateFromMeta(15));
      world.setBlockState(pos.add(42, 14, 60), Blocks.STONE.getDefaultState());
      world.setBlockState(pos.add(43, 14, 60), Blocks.STONE.getDefaultState());
      world.setBlockState(pos.add(44, 14, 60), Blocks.STONE.getDefaultState());
      world.setBlockState(pos.add(45, 14, 60), Blocks.STONE.getDefaultState());
      world.setBlockState(pos.add(18, 14, 61), Blocks.OBSIDIAN.getDefaultState());
      world.setBlockState(pos.add(21, 14, 61), Blocks.STONE.getDefaultState());
      world.setBlockState(pos.add(28, 14, 61), ((BlockRedstoneTorch)Blocks.REDSTONE_TORCH).getStateFromMeta(2));
      world.setBlockState(pos.add(29, 14, 61), Blocks.STONE.getDefaultState());
      world.setBlockState(pos.add(32, 14, 61), ((BlockColored)Blocks.WOOL).getStateFromMeta(15));
      world.setBlockState(pos.add(39, 14, 61), ((BlockColored)Blocks.WOOL).getStateFromMeta(15));
      world.setBlockState(pos.add(41, 14, 61), Blocks.STONE.getDefaultState());
      world.setBlockState(pos.add(46, 14, 61), Blocks.STONE.getDefaultState());
      world.setBlockState(pos.add(18, 14, 62), Blocks.OBSIDIAN.getDefaultState());
      world.setBlockState(pos.add(21, 14, 62), Blocks.IRON_BARS.getDefaultState());
      world.setBlockState(pos.add(29, 14, 62), Blocks.STONE.getDefaultState());
      world.setBlockState(pos.add(32, 14, 62), ((BlockColored)Blocks.WOOL).getStateFromMeta(15));
      world.setBlockState(pos.add(39, 14, 62), ((BlockColored)Blocks.WOOL).getStateFromMeta(15));
      world.setBlockState(pos.add(40, 14, 62), Blocks.STONE.getDefaultState());
      world.setBlockState(pos.add(47, 14, 62), Blocks.STONE.getDefaultState());
      world.setBlockState(pos.add(18, 14, 63), Blocks.OBSIDIAN.getDefaultState());
      world.setBlockState(pos.add(21, 14, 63), Blocks.IRON_BARS.getDefaultState());
      world.setBlockState(pos.add(23, 14, 63), Blocks.IRON_BARS.getDefaultState());
      world.setBlockState(pos.add(24, 14, 63), Blocks.IRON_BARS.getDefaultState());
      world.setBlockState(pos.add(25, 14, 63), Blocks.IRON_BARS.getDefaultState());
      world.setBlockState(pos.add(26, 14, 63), Blocks.IRON_BARS.getDefaultState());
      world.setBlockState(pos.add(27, 14, 63), Blocks.IRON_BARS.getDefaultState());
      world.setBlockState(pos.add(28, 14, 63), Blocks.IRON_BARS.getDefaultState());
      world.setBlockState(pos.add(29, 14, 63), Blocks.STONE.getDefaultState());
      world.setBlockState(pos.add(32, 14, 63), ((BlockColored)Blocks.WOOL).getStateFromMeta(15));
      world.setBlockState(pos.add(39, 14, 63), ((BlockColored)Blocks.WOOL).getStateFromMeta(15));
      world.setBlockState(pos.add(40, 14, 63), Blocks.STONE.getDefaultState());
      world.setBlockState(pos.add(47, 14, 63), Blocks.STONE.getDefaultState());
      world.setBlockState(pos.add(18, 14, 64), Blocks.OBSIDIAN.getDefaultState());
      world.setBlockState(pos.add(21, 14, 64), Blocks.STONE.getDefaultState());
      world.setBlockState(pos.add(23, 14, 64), Blocks.IRON_BARS.getDefaultState());
      world.setBlockState(pos.add(28, 14, 64), ((BlockRedstoneTorch)Blocks.REDSTONE_TORCH).getStateFromMeta(2));
      world.setBlockState(pos.add(29, 14, 64), Blocks.STONE.getDefaultState());
      world.setBlockState(pos.add(32, 14, 64), ((BlockColored)Blocks.WOOL).getStateFromMeta(15));
      world.setBlockState(pos.add(39, 14, 64), ((BlockColored)Blocks.WOOL).getStateFromMeta(15));
      world.setBlockState(pos.add(40, 14, 64), Blocks.STONE.getDefaultState());
      world.setBlockState(pos.add(47, 14, 64), Blocks.STONE.getDefaultState());
      world.setBlockState(pos.add(18, 14, 65), Blocks.OBSIDIAN.getDefaultState());
      world.setBlockState(pos.add(20, 14, 65), Blocks.STONE.getDefaultState());
      world.setBlockState(pos.add(23, 14, 65), Blocks.IRON_BARS.getDefaultState());
      world.setBlockState(pos.add(29, 14, 65), Blocks.STONE.getDefaultState());
      world.setBlockState(pos.add(33, 14, 65), ((BlockColored)Blocks.WOOL).getStateFromMeta(15));
      world.setBlockState(pos.add(38, 14, 65), ((BlockColored)Blocks.WOOL).getStateFromMeta(15));
      world.setBlockState(pos.add(40, 14, 65), Blocks.STONE.getDefaultState());
      world.setBlockState(pos.add(47, 14, 65), Blocks.STONE.getDefaultState());
      world.setBlockState(pos.add(18, 14, 66), Blocks.STONE.getDefaultState());
      world.setBlockState(pos.add(19, 14, 66), Blocks.STONE.getDefaultState());
      world.setBlockState(pos.add(23, 14, 66), Blocks.IRON_BARS.getDefaultState());
      world.setBlockState(pos.add(24, 14, 66), ((BlockRedstoneTorch)Blocks.REDSTONE_TORCH).getStateFromMeta(4));
      world.setBlockState(pos.add(26, 14, 66), ((BlockRedstoneTorch)Blocks.REDSTONE_TORCH).getStateFromMeta(4));
      world.setBlockState(pos.add(28, 14, 66), ((BlockRedstoneTorch)Blocks.REDSTONE_TORCH).getStateFromMeta(4));
      world.setBlockState(pos.add(29, 14, 66), Blocks.STONE.getDefaultState());
      world.setBlockState(pos.add(34, 14, 66), ((BlockColored)Blocks.WOOL).getStateFromMeta(15));
      world.setBlockState(pos.add(35, 14, 66), ((BlockColored)Blocks.WOOL).getStateFromMeta(15));
      world.setBlockState(pos.add(36, 14, 66), ((BlockColored)Blocks.WOOL).getStateFromMeta(15));
      world.setBlockState(pos.add(37, 14, 66), ((BlockColored)Blocks.WOOL).getStateFromMeta(15));
      world.setBlockState(pos.add(41, 14, 66), Blocks.STONE.getDefaultState());
      world.setBlockState(pos.add(46, 14, 66), Blocks.STONE.getDefaultState());
      world.setBlockState(pos.add(20, 14, 67), Blocks.STONE.getDefaultState());
      world.setBlockState(pos.add(21, 14, 67), Blocks.STONE.getDefaultState());
      world.setBlockState(pos.add(22, 14, 67), Blocks.STONE.getDefaultState());
      world.setBlockState(pos.add(23, 14, 67), Blocks.STONE.getDefaultState());
      world.setBlockState(pos.add(24, 14, 67), Blocks.STONE.getDefaultState());
      world.setBlockState(pos.add(25, 14, 67), Blocks.STONE.getDefaultState());
      world.setBlockState(pos.add(26, 14, 67), Blocks.STONE.getDefaultState());
      world.setBlockState(pos.add(27, 14, 67), Blocks.STONE.getDefaultState());
      world.setBlockState(pos.add(28, 14, 67), Blocks.STONE.getDefaultState());
      world.setBlockState(pos.add(42, 14, 67), Blocks.STONE.getDefaultState());
      world.setBlockState(pos.add(43, 14, 67), Blocks.STONE.getDefaultState());
      world.setBlockState(pos.add(44, 14, 67), Blocks.STONE.getDefaultState());
      world.setBlockState(pos.add(45, 14, 67), Blocks.STONE.getDefaultState());
      world.setBlockState(pos.add(24, 15, 36), Blocks.QUARTZ_BLOCK.getDefaultState());
      world.setBlockState(pos.add(25, 15, 36), ((BlockColored)Blocks.STAINED_HARDENED_CLAY).getStateFromMeta(10));
      world.setBlockState(pos.add(27, 15, 36), ((BlockColored)Blocks.STAINED_HARDENED_CLAY).getStateFromMeta(10));
      world.setBlockState(pos.add(28, 15, 36), Blocks.QUARTZ_BLOCK.getDefaultState());
      world.setBlockState(pos.add(16, 15, 37), ((BlockColored)Blocks.STAINED_HARDENED_CLAY).getStateFromMeta(4));
      world.setBlockState(pos.add(17, 15, 37), ((BlockColored)Blocks.STAINED_HARDENED_CLAY).getStateFromMeta(4));
      world.setBlockState(pos.add(18, 15, 37), ((BlockColored)Blocks.STAINED_HARDENED_CLAY).getStateFromMeta(4));
      world.setBlockState(pos.add(19, 15, 37), ((BlockColored)Blocks.STAINED_HARDENED_CLAY).getStateFromMeta(4));
      world.setBlockState(pos.add(20, 15, 37), ((BlockColored)Blocks.STAINED_HARDENED_CLAY).getStateFromMeta(4));
      world.setBlockState(pos.add(21, 15, 37), Blocks.QUARTZ_BLOCK.getDefaultState());
      world.setBlockState(pos.add(22, 15, 37), Blocks.QUARTZ_BLOCK.getDefaultState());
      world.setBlockState(pos.add(23, 15, 37), ((BlockColored)Blocks.STAINED_HARDENED_CLAY).getStateFromMeta(4));
      world.setBlockState(pos.add(29, 15, 37), ((BlockColored)Blocks.STAINED_HARDENED_CLAY).getStateFromMeta(4));
      world.setBlockState(pos.add(32, 15, 37), ((BlockColored)Blocks.STAINED_HARDENED_CLAY).getStateFromMeta(4));
      world.setBlockState(pos.add(33, 15, 37), ((BlockColored)Blocks.STAINED_HARDENED_CLAY).getStateFromMeta(4));
      world.setBlockState(pos.add(34, 15, 37), ((BlockColored)Blocks.STAINED_HARDENED_CLAY).getStateFromMeta(4));
      world.setBlockState(pos.add(35, 15, 37), ((BlockColored)Blocks.STAINED_HARDENED_CLAY).getStateFromMeta(4));
      world.setBlockState(pos.add(36, 15, 37), ((BlockColored)Blocks.STAINED_HARDENED_CLAY).getStateFromMeta(4));
      world.setBlockState(pos.add(3, 15, 38), Blocks.STONE.getDefaultState());
      world.setBlockState(pos.add(4, 15, 38), Blocks.STONE.getDefaultState());
      world.setBlockState(pos.add(5, 15, 38), Blocks.STONE.getDefaultState());
      world.setBlockState(pos.add(6, 15, 38), Blocks.STONE.getDefaultState());
      world.setBlockState(pos.add(7, 15, 38), Blocks.STONE.getDefaultState());
      world.setBlockState(pos.add(8, 15, 38), Blocks.STONE.getDefaultState());
      world.setBlockState(pos.add(9, 15, 38), Blocks.STONE.getDefaultState());
      world.setBlockState(pos.add(16, 15, 38), ((BlockColored)Blocks.STAINED_HARDENED_CLAY).getStateFromMeta(4));
      world.setBlockState(pos.add(17, 15, 38), ((BlockColored)Blocks.STAINED_HARDENED_CLAY).getStateFromMeta(4));
      world.setBlockState(pos.add(18, 15, 38), ((BlockColored)Blocks.STAINED_HARDENED_CLAY).getStateFromMeta(4));
      world.setBlockState(pos.add(19, 15, 38), ((BlockColored)Blocks.STAINED_HARDENED_CLAY).getStateFromMeta(4));
      world.setBlockState(pos.add(20, 15, 38), ((BlockColored)Blocks.STAINED_HARDENED_CLAY).getStateFromMeta(4));
      world.setBlockState(pos.add(21, 15, 38), Blocks.QUARTZ_BLOCK.getDefaultState());
      world.setBlockState(pos.add(22, 15, 38), Blocks.QUARTZ_BLOCK.getDefaultState());
      world.setBlockState(pos.add(30, 15, 38), Blocks.QUARTZ_BLOCK.getDefaultState());
      world.setBlockState(pos.add(31, 15, 38), Blocks.QUARTZ_BLOCK.getDefaultState());
      world.setBlockState(pos.add(32, 15, 38), ((BlockColored)Blocks.STAINED_HARDENED_CLAY).getStateFromMeta(4));
      world.setBlockState(pos.add(33, 15, 38), ((BlockColored)Blocks.STAINED_HARDENED_CLAY).getStateFromMeta(4));
      world.setBlockState(pos.add(34, 15, 38), ((BlockColored)Blocks.STAINED_HARDENED_CLAY).getStateFromMeta(4));
      world.setBlockState(pos.add(35, 15, 38), ((BlockColored)Blocks.STAINED_HARDENED_CLAY).getStateFromMeta(4));
      world.setBlockState(pos.add(36, 15, 38), ((BlockColored)Blocks.STAINED_HARDENED_CLAY).getStateFromMeta(4));
      world.setBlockState(pos.add(2, 15, 39), Blocks.STONE.getDefaultState());
      world.setBlockState(pos.add(3, 15, 39), Blocks.STONE.getDefaultState());
      world.setBlockState(pos.add(9, 15, 39), Blocks.STONE.getDefaultState());
      world.setBlockState(pos.add(10, 15, 39), Blocks.STONE.getDefaultState());
      world.setBlockState(pos.add(16, 15, 39), ((BlockColored)Blocks.STAINED_HARDENED_CLAY).getStateFromMeta(4));
      world.setBlockState(pos.add(20, 15, 39), ((BlockColored)Blocks.STAINED_HARDENED_CLAY).getStateFromMeta(4));
      world.setBlockState(pos.add(21, 15, 39), Blocks.QUARTZ_BLOCK.getDefaultState());
      world.setBlockState(pos.add(22, 15, 39), Blocks.QUARTZ_BLOCK.getDefaultState());
      world.setBlockState(pos.add(30, 15, 39), Blocks.QUARTZ_BLOCK.getDefaultState());
      world.setBlockState(pos.add(31, 15, 39), Blocks.QUARTZ_BLOCK.getDefaultState());
      world.setBlockState(pos.add(32, 15, 39), ((BlockColored)Blocks.STAINED_HARDENED_CLAY).getStateFromMeta(4));
      world.setBlockState(pos.add(36, 15, 39), ((BlockColored)Blocks.STAINED_HARDENED_CLAY).getStateFromMeta(4));
      world.setBlockState(pos.add(1, 15, 40), Blocks.STONE.getDefaultState());
      world.setBlockState(pos.add(2, 15, 40), Blocks.STONE.getDefaultState());
      world.setBlockState(pos.add(10, 15, 40), Blocks.STONE.getDefaultState());
      world.setBlockState(pos.add(11, 15, 40), Blocks.STONE.getDefaultState());
      world.setBlockState(pos.add(16, 15, 40), ((BlockColored)Blocks.STAINED_HARDENED_CLAY).getStateFromMeta(4));
      world.setBlockState(pos.add(20, 15, 40), ((BlockColored)Blocks.STAINED_HARDENED_CLAY).getStateFromMeta(4));
      world.setBlockState(pos.add(21, 15, 40), Blocks.QUARTZ_BLOCK.getDefaultState());
      world.setBlockState(pos.add(22, 15, 40), Blocks.QUARTZ_BLOCK.getDefaultState());
      world.setBlockState(pos.add(23, 15, 40), ((BlockStaticLiquid)Blocks.LAVA).getStateFromMeta(2));
      world.setBlockState(pos.add(29, 15, 40), ((BlockStaticLiquid)Blocks.LAVA).getStateFromMeta(2));
      world.setBlockState(pos.add(30, 15, 40), Blocks.QUARTZ_BLOCK.getDefaultState());
      world.setBlockState(pos.add(31, 15, 40), Blocks.QUARTZ_BLOCK.getDefaultState());
      world.setBlockState(pos.add(32, 15, 40), ((BlockColored)Blocks.STAINED_HARDENED_CLAY).getStateFromMeta(4));
      world.setBlockState(pos.add(34, 15, 40), ((BlockColored)Blocks.STAINED_HARDENED_CLAY).getStateFromMeta(4));
      world.setBlockState(pos.add(35, 15, 40), ((BlockColored)Blocks.STAINED_HARDENED_CLAY).getStateFromMeta(4));
      world.setBlockState(pos.add(36, 15, 40), ((BlockColored)Blocks.STAINED_HARDENED_CLAY).getStateFromMeta(4));
      world.setBlockState(pos.add(1, 15, 41), Blocks.STONE.getDefaultState());
      world.setBlockState(pos.add(11, 15, 41), Blocks.STONE.getDefaultState());
      world.setBlockState(pos.add(17, 15, 41), Blocks.QUARTZ_BLOCK.getDefaultState());
      world.setBlockState(pos.add(20, 15, 41), Blocks.QUARTZ_BLOCK.getDefaultState());
      world.setBlockState(pos.add(21, 15, 41), Blocks.QUARTZ_BLOCK.getDefaultState());
      world.setBlockState(pos.add(22, 15, 41), Blocks.QUARTZ_BLOCK.getDefaultState());
      world.setBlockState(pos.add(23, 15, 41), Blocks.LAVA.getDefaultState());
      world.setBlockState(pos.add(24, 15, 41), Blocks.STONE.getDefaultState());
      world.setBlockState(pos.add(25, 15, 41), Blocks.STONE.getDefaultState());
      world.setBlockState(pos.add(26, 15, 41), Blocks.STONE.getDefaultState());
      world.setBlockState(pos.add(27, 15, 41), Blocks.STONE.getDefaultState());
      world.setBlockState(pos.add(28, 15, 41), Blocks.STONE.getDefaultState());
      world.setBlockState(pos.add(29, 15, 41), Blocks.LAVA.getDefaultState());
      world.setBlockState(pos.add(30, 15, 41), Blocks.QUARTZ_BLOCK.getDefaultState());
      world.setBlockState(pos.add(31, 15, 41), Blocks.QUARTZ_BLOCK.getDefaultState());
      world.setBlockState(pos.add(32, 15, 41), Blocks.QUARTZ_BLOCK.getDefaultState());
      world.setBlockState(pos.add(35, 15, 41), Blocks.QUARTZ_BLOCK.getDefaultState());
      world.setBlockState(pos.add(1, 15, 42), Blocks.STONE.getDefaultState());
      world.setBlockState(pos.add(11, 15, 42), Blocks.STONE.getDefaultState());
      world.setBlockState(pos.add(17, 15, 42), Blocks.QUARTZ_BLOCK.getDefaultState());
      world.setBlockState(pos.add(20, 15, 42), Blocks.QUARTZ_BLOCK.getDefaultState());
      world.setBlockState(pos.add(21, 15, 42), Blocks.QUARTZ_BLOCK.getDefaultState());
      world.setBlockState(pos.add(22, 15, 42), Blocks.QUARTZ_BLOCK.getDefaultState());
      world.setBlockState(pos.add(23, 15, 42), Blocks.LAVA.getDefaultState());
      world.setBlockState(pos.add(24, 15, 42), Blocks.STONE.getDefaultState());
      world.setBlockState(pos.add(25, 15, 42), Blocks.STONE.getDefaultState());
      world.setBlockState(pos.add(26, 15, 42), Blocks.STONE.getDefaultState());
      world.setBlockState(pos.add(27, 15, 42), Blocks.STONE.getDefaultState());
      world.setBlockState(pos.add(28, 15, 42), Blocks.STONE.getDefaultState());
      world.setBlockState(pos.add(29, 15, 42), Blocks.LAVA.getDefaultState());
      world.setBlockState(pos.add(30, 15, 42), Blocks.QUARTZ_BLOCK.getDefaultState());
      world.setBlockState(pos.add(31, 15, 42), Blocks.QUARTZ_BLOCK.getDefaultState());
      world.setBlockState(pos.add(32, 15, 42), Blocks.QUARTZ_BLOCK.getDefaultState());
      world.setBlockState(pos.add(35, 15, 42), Blocks.QUARTZ_BLOCK.getDefaultState());
      world.setBlockState(pos.add(1, 15, 43), Blocks.STONE.getDefaultState());
      world.setBlockState(pos.add(11, 15, 43), Blocks.STONE.getDefaultState());
      world.setBlockState(pos.add(16, 15, 43), ((BlockColored)Blocks.STAINED_HARDENED_CLAY).getStateFromMeta(4));
      world.setBlockState(pos.add(20, 15, 43), ((BlockColored)Blocks.STAINED_HARDENED_CLAY).getStateFromMeta(4));
      world.setBlockState(pos.add(21, 15, 43), Blocks.QUARTZ_BLOCK.getDefaultState());
      world.setBlockState(pos.add(22, 15, 43), Blocks.QUARTZ_BLOCK.getDefaultState());
      world.setBlockState(pos.add(23, 15, 43), ((BlockStaticLiquid)Blocks.LAVA).getStateFromMeta(2));
      world.setBlockState(pos.add(29, 15, 43), ((BlockStaticLiquid)Blocks.LAVA).getStateFromMeta(2));
      world.setBlockState(pos.add(30, 15, 43), Blocks.QUARTZ_BLOCK.getDefaultState());
      world.setBlockState(pos.add(31, 15, 43), Blocks.QUARTZ_BLOCK.getDefaultState());
      world.setBlockState(pos.add(32, 15, 43), ((BlockColored)Blocks.STAINED_HARDENED_CLAY).getStateFromMeta(4));
      world.setBlockState(pos.add(36, 15, 43), ((BlockColored)Blocks.STAINED_HARDENED_CLAY).getStateFromMeta(4));
      world.setBlockState(pos.add(1, 15, 44), Blocks.STONE.getDefaultState());
      world.setBlockState(pos.add(11, 15, 44), Blocks.STONE.getDefaultState());
      world.setBlockState(pos.add(16, 15, 44), ((BlockColored)Blocks.STAINED_HARDENED_CLAY).getStateFromMeta(4));
      world.setBlockState(pos.add(20, 15, 44), ((BlockColored)Blocks.STAINED_HARDENED_CLAY).getStateFromMeta(4));
      world.setBlockState(pos.add(21, 15, 44), Blocks.QUARTZ_BLOCK.getDefaultState());
      world.setBlockState(pos.add(22, 15, 44), Blocks.QUARTZ_BLOCK.getDefaultState());
      world.setBlockState(pos.add(30, 15, 44), Blocks.QUARTZ_BLOCK.getDefaultState());
      world.setBlockState(pos.add(31, 15, 44), Blocks.QUARTZ_BLOCK.getDefaultState());
      world.setBlockState(pos.add(32, 15, 44), ((BlockColored)Blocks.STAINED_HARDENED_CLAY).getStateFromMeta(4));
      world.setBlockState(pos.add(36, 15, 44), ((BlockColored)Blocks.STAINED_HARDENED_CLAY).getStateFromMeta(4));
      world.setBlockState(pos.add(1, 15, 45), Blocks.STONE.getDefaultState());
      world.setBlockState(pos.add(11, 15, 45), Blocks.STONE.getDefaultState());
      world.setBlockState(pos.add(16, 15, 45), ((BlockColored)Blocks.STAINED_HARDENED_CLAY).getStateFromMeta(4));
      world.setBlockState(pos.add(20, 15, 45), ((BlockColored)Blocks.STAINED_HARDENED_CLAY).getStateFromMeta(4));
      world.setBlockState(pos.add(21, 15, 45), Blocks.QUARTZ_BLOCK.getDefaultState());
      world.setBlockState(pos.add(22, 15, 45), Blocks.QUARTZ_BLOCK.getDefaultState());
      world.setBlockState(pos.add(30, 15, 45), Blocks.QUARTZ_BLOCK.getDefaultState());
      world.setBlockState(pos.add(31, 15, 45), Blocks.QUARTZ_BLOCK.getDefaultState());
      world.setBlockState(pos.add(32, 15, 45), ((BlockColored)Blocks.STAINED_HARDENED_CLAY).getStateFromMeta(4));
      world.setBlockState(pos.add(36, 15, 45), ((BlockColored)Blocks.STAINED_HARDENED_CLAY).getStateFromMeta(4));
      world.setBlockState(pos.add(1, 15, 46), Blocks.STONE.getDefaultState());
      world.setBlockState(pos.add(2, 15, 46), Blocks.STONE.getDefaultState());
      world.setBlockState(pos.add(10, 15, 46), Blocks.STONE.getDefaultState());
      world.setBlockState(pos.add(11, 15, 46), Blocks.STONE.getDefaultState());
      world.setBlockState(pos.add(17, 15, 46), Blocks.QUARTZ_BLOCK.getDefaultState());
      world.setBlockState(pos.add(18, 15, 46), Blocks.QUARTZ_BLOCK.getDefaultState());
      world.setBlockState(pos.add(19, 15, 46), Blocks.QUARTZ_BLOCK.getDefaultState());
      world.setBlockState(pos.add(20, 15, 46), Blocks.QUARTZ_BLOCK.getDefaultState());
      world.setBlockState(pos.add(21, 15, 46), Blocks.QUARTZ_BLOCK.getDefaultState());
      world.setBlockState(pos.add(22, 15, 46), Blocks.QUARTZ_BLOCK.getDefaultState());
      world.setBlockState(pos.add(25, 15, 46), Blocks.STONE.getDefaultState());
      world.setBlockState(pos.add(26, 15, 46), Blocks.STONE.getDefaultState());
      world.setBlockState(pos.add(30, 15, 46), Blocks.QUARTZ_BLOCK.getDefaultState());
      world.setBlockState(pos.add(31, 15, 46), Blocks.QUARTZ_BLOCK.getDefaultState());
      world.setBlockState(pos.add(32, 15, 46), Blocks.QUARTZ_BLOCK.getDefaultState());
      world.setBlockState(pos.add(35, 15, 46), Blocks.QUARTZ_BLOCK.getDefaultState());
      world.setBlockState(pos.add(2, 15, 47), Blocks.STONE.getDefaultState());
      world.setBlockState(pos.add(3, 15, 47), Blocks.STONE.getDefaultState());
      world.setBlockState(pos.add(9, 15, 47), Blocks.STONE.getDefaultState());
      world.setBlockState(pos.add(10, 15, 47), Blocks.STONE.getDefaultState());
      world.setBlockState(pos.add(17, 15, 47), Blocks.QUARTZ_BLOCK.getDefaultState());
      world.setBlockState(pos.add(18, 15, 47), Blocks.QUARTZ_BLOCK.getDefaultState());
      world.setBlockState(pos.add(19, 15, 47), Blocks.QUARTZ_BLOCK.getDefaultState());
      world.setBlockState(pos.add(20, 15, 47), Blocks.QUARTZ_BLOCK.getDefaultState());
      world.setBlockState(pos.add(21, 15, 47), Blocks.QUARTZ_BLOCK.getDefaultState());
      world.setBlockState(pos.add(22, 15, 47), Blocks.QUARTZ_BLOCK.getDefaultState());
      world.setBlockState(pos.add(25, 15, 47), Blocks.STONE.getDefaultState());
      world.setBlockState(pos.add(26, 15, 47), Blocks.STONE.getDefaultState());
      world.setBlockState(pos.add(30, 15, 47), Blocks.QUARTZ_BLOCK.getDefaultState());
      world.setBlockState(pos.add(31, 15, 47), Blocks.QUARTZ_BLOCK.getDefaultState());
      world.setBlockState(pos.add(32, 15, 47), Blocks.QUARTZ_BLOCK.getDefaultState());
      world.setBlockState(pos.add(35, 15, 47), Blocks.QUARTZ_BLOCK.getDefaultState());
      world.setBlockState(pos.add(3, 15, 48), Blocks.STONE.getDefaultState());
      world.setBlockState(pos.add(4, 15, 48), Blocks.STONE.getDefaultState());
      world.setBlockState(pos.add(5, 15, 48), Blocks.STONE.getDefaultState());
      world.setBlockState(pos.add(6, 15, 48), Blocks.STONE.getDefaultState());
      world.setBlockState(pos.add(7, 15, 48), Blocks.STONE.getDefaultState());
      world.setBlockState(pos.add(8, 15, 48), Blocks.STONE.getDefaultState());
      world.setBlockState(pos.add(9, 15, 48), Blocks.STONE.getDefaultState());
      world.setBlockState(pos.add(16, 15, 48), ((BlockColored)Blocks.STAINED_HARDENED_CLAY).getStateFromMeta(4));
      world.setBlockState(pos.add(20, 15, 48), ((BlockColored)Blocks.STAINED_HARDENED_CLAY).getStateFromMeta(4));
      world.setBlockState(pos.add(21, 15, 48), Blocks.QUARTZ_BLOCK.getDefaultState());
      world.setBlockState(pos.add(22, 15, 48), Blocks.QUARTZ_BLOCK.getDefaultState());
      world.setBlockState(pos.add(30, 15, 48), Blocks.QUARTZ_BLOCK.getDefaultState());
      world.setBlockState(pos.add(31, 15, 48), Blocks.QUARTZ_BLOCK.getDefaultState());
      world.setBlockState(pos.add(32, 15, 48), ((BlockColored)Blocks.STAINED_HARDENED_CLAY).getStateFromMeta(4));
      world.setBlockState(pos.add(36, 15, 48), ((BlockColored)Blocks.STAINED_HARDENED_CLAY).getStateFromMeta(4));
      world.setBlockState(pos.add(16, 15, 49), ((BlockColored)Blocks.STAINED_HARDENED_CLAY).getStateFromMeta(4));
      world.setBlockState(pos.add(20, 15, 49), ((BlockColored)Blocks.STAINED_HARDENED_CLAY).getStateFromMeta(4));
      world.setBlockState(pos.add(21, 15, 49), Blocks.QUARTZ_BLOCK.getDefaultState());
      world.setBlockState(pos.add(22, 15, 49), Blocks.QUARTZ_BLOCK.getDefaultState());
      world.setBlockState(pos.add(30, 15, 49), Blocks.QUARTZ_BLOCK.getDefaultState());
      world.setBlockState(pos.add(31, 15, 49), Blocks.QUARTZ_BLOCK.getDefaultState());
      world.setBlockState(pos.add(32, 15, 49), ((BlockColored)Blocks.STAINED_HARDENED_CLAY).getStateFromMeta(4));
      world.setBlockState(pos.add(36, 15, 49), ((BlockColored)Blocks.STAINED_HARDENED_CLAY).getStateFromMeta(4));
      world.setBlockState(pos.add(16, 15, 50), ((BlockColored)Blocks.STAINED_HARDENED_CLAY).getStateFromMeta(4));
      world.setBlockState(pos.add(17, 15, 50), ((BlockColored)Blocks.STAINED_HARDENED_CLAY).getStateFromMeta(4));
      world.setBlockState(pos.add(18, 15, 50), ((BlockColored)Blocks.STAINED_HARDENED_CLAY).getStateFromMeta(4));
      world.setBlockState(pos.add(19, 15, 50), ((BlockColored)Blocks.STAINED_HARDENED_CLAY).getStateFromMeta(4));
      world.setBlockState(pos.add(20, 15, 50), ((BlockColored)Blocks.STAINED_HARDENED_CLAY).getStateFromMeta(4));
      world.setBlockState(pos.add(21, 15, 50), Blocks.QUARTZ_BLOCK.getDefaultState());
      world.setBlockState(pos.add(22, 15, 50), Blocks.QUARTZ_BLOCK.getDefaultState());
      world.setBlockState(pos.add(30, 15, 50), Blocks.QUARTZ_BLOCK.getDefaultState());
      world.setBlockState(pos.add(31, 15, 50), Blocks.QUARTZ_BLOCK.getDefaultState());
      world.setBlockState(pos.add(32, 15, 50), ((BlockColored)Blocks.STAINED_HARDENED_CLAY).getStateFromMeta(4));
      world.setBlockState(pos.add(33, 15, 50), ((BlockColored)Blocks.STAINED_HARDENED_CLAY).getStateFromMeta(4));
      world.setBlockState(pos.add(34, 15, 50), ((BlockColored)Blocks.STAINED_HARDENED_CLAY).getStateFromMeta(4));
      world.setBlockState(pos.add(35, 15, 50), ((BlockColored)Blocks.STAINED_HARDENED_CLAY).getStateFromMeta(4));
      world.setBlockState(pos.add(36, 15, 50), ((BlockColored)Blocks.STAINED_HARDENED_CLAY).getStateFromMeta(4));
      world.setBlockState(pos.add(18, 15, 51), ((BlockColored)Blocks.STAINED_HARDENED_CLAY).getStateFromMeta(4));
      world.setBlockState(pos.add(19, 15, 51), ((BlockColored)Blocks.STAINED_HARDENED_CLAY).getStateFromMeta(4));
      world.setBlockState(pos.add(20, 15, 51), ((BlockColored)Blocks.STAINED_HARDENED_CLAY).getStateFromMeta(4));
      world.setBlockState(pos.add(21, 15, 51), ((BlockColored)Blocks.STAINED_HARDENED_CLAY).getStateFromMeta(4));
      world.setBlockState(pos.add(30, 15, 51), ((BlockColored)Blocks.STAINED_HARDENED_CLAY).getStateFromMeta(4));
      world.setBlockState(pos.add(31, 15, 51), ((BlockColored)Blocks.STAINED_HARDENED_CLAY).getStateFromMeta(4));
      world.setBlockState(pos.add(32, 15, 51), ((BlockColored)Blocks.STAINED_HARDENED_CLAY).getStateFromMeta(4));
      world.setBlockState(pos.add(33, 15, 51), ((BlockColored)Blocks.STAINED_HARDENED_CLAY).getStateFromMeta(4));
      world.setBlockState(pos.add(34, 15, 51), ((BlockColored)Blocks.STAINED_HARDENED_CLAY).getStateFromMeta(4));
      world.setBlockState(pos.add(17, 15, 52), ((BlockColored)Blocks.STAINED_HARDENED_CLAY).getStateFromMeta(4));
      world.setBlockState(pos.add(18, 15, 52), ((BlockColored)Blocks.STAINED_HARDENED_CLAY).getStateFromMeta(4));
      world.setBlockState(pos.add(22, 15, 52), ((BlockColored)Blocks.STAINED_HARDENED_CLAY).getStateFromMeta(4));
      world.setBlockState(pos.add(29, 15, 52), ((BlockColored)Blocks.STAINED_HARDENED_CLAY).getStateFromMeta(4));
      world.setBlockState(pos.add(30, 15, 52), ((BlockColored)Blocks.STAINED_HARDENED_CLAY).getStateFromMeta(4));
      world.setBlockState(pos.add(34, 15, 52), ((BlockColored)Blocks.STAINED_HARDENED_CLAY).getStateFromMeta(4));
      world.setBlockState(pos.add(35, 15, 52), ((BlockColored)Blocks.STAINED_HARDENED_CLAY).getStateFromMeta(4));
      world.setBlockState(pos.add(16, 15, 53), ((BlockColored)Blocks.STAINED_HARDENED_CLAY).getStateFromMeta(4));
      world.setBlockState(pos.add(17, 15, 53), ((BlockColored)Blocks.STAINED_HARDENED_CLAY).getStateFromMeta(4));
      world.setBlockState(pos.add(23, 15, 53), ((BlockColored)Blocks.STAINED_HARDENED_CLAY).getStateFromMeta(4));
      world.setBlockState(pos.add(24, 15, 53), ((BlockColored)Blocks.STAINED_HARDENED_CLAY).getStateFromMeta(4));
      world.setBlockState(pos.add(28, 15, 53), ((BlockColored)Blocks.STAINED_HARDENED_CLAY).getStateFromMeta(4));
      world.setBlockState(pos.add(29, 15, 53), ((BlockColored)Blocks.STAINED_HARDENED_CLAY).getStateFromMeta(4));
      world.setBlockState(pos.add(35, 15, 53), ((BlockColored)Blocks.STAINED_HARDENED_CLAY).getStateFromMeta(4));
      world.setBlockState(pos.add(36, 15, 53), ((BlockColored)Blocks.STAINED_HARDENED_CLAY).getStateFromMeta(4));
      world.setBlockState(pos.add(16, 15, 54), ((BlockColored)Blocks.STAINED_HARDENED_CLAY).getStateFromMeta(4));
      world.setBlockState(pos.add(17, 15, 54), ((BlockColored)Blocks.STAINED_HARDENED_CLAY).getStateFromMeta(4));
      world.setBlockState(pos.add(23, 15, 54), ((BlockColored)Blocks.STAINED_HARDENED_CLAY).getStateFromMeta(4));
      world.setBlockState(pos.add(24, 15, 54), ((BlockColored)Blocks.STAINED_HARDENED_CLAY).getStateFromMeta(4));
      world.setBlockState(pos.add(28, 15, 54), ((BlockColored)Blocks.STAINED_HARDENED_CLAY).getStateFromMeta(4));
      world.setBlockState(pos.add(29, 15, 54), ((BlockColored)Blocks.STAINED_HARDENED_CLAY).getStateFromMeta(4));
      world.setBlockState(pos.add(35, 15, 54), ((BlockColored)Blocks.STAINED_HARDENED_CLAY).getStateFromMeta(4));
      world.setBlockState(pos.add(36, 15, 54), ((BlockColored)Blocks.STAINED_HARDENED_CLAY).getStateFromMeta(4));
      world.setBlockState(pos.add(16, 15, 55), ((BlockColored)Blocks.STAINED_HARDENED_CLAY).getStateFromMeta(4));
      world.setBlockState(pos.add(17, 15, 55), ((BlockColored)Blocks.STAINED_HARDENED_CLAY).getStateFromMeta(4));
      world.setBlockState(pos.add(23, 15, 55), ((BlockColored)Blocks.STAINED_HARDENED_CLAY).getStateFromMeta(4));
      world.setBlockState(pos.add(24, 15, 55), ((BlockColored)Blocks.STAINED_HARDENED_CLAY).getStateFromMeta(4));
      world.setBlockState(pos.add(28, 15, 55), ((BlockColored)Blocks.STAINED_HARDENED_CLAY).getStateFromMeta(4));
      world.setBlockState(pos.add(29, 15, 55), ((BlockColored)Blocks.STAINED_HARDENED_CLAY).getStateFromMeta(4));
      world.setBlockState(pos.add(35, 15, 55), ((BlockColored)Blocks.STAINED_HARDENED_CLAY).getStateFromMeta(4));
      world.setBlockState(pos.add(36, 15, 55), ((BlockColored)Blocks.STAINED_HARDENED_CLAY).getStateFromMeta(4));
      world.setBlockState(pos.add(37, 15, 55), ((BlockColored)Blocks.STAINED_HARDENED_CLAY).getStateFromMeta(4));
      world.setBlockState(pos.add(17, 15, 56), ((BlockColored)Blocks.STAINED_HARDENED_CLAY).getStateFromMeta(4));
      world.setBlockState(pos.add(18, 15, 56), ((BlockColored)Blocks.STAINED_HARDENED_CLAY).getStateFromMeta(4));
      world.setBlockState(pos.add(22, 15, 56), ((BlockColored)Blocks.STAINED_HARDENED_CLAY).getStateFromMeta(4));
      world.setBlockState(pos.add(23, 15, 56), ((BlockColored)Blocks.STAINED_HARDENED_CLAY).getStateFromMeta(4));
      world.setBlockState(pos.add(29, 15, 56), ((BlockColored)Blocks.STAINED_HARDENED_CLAY).getStateFromMeta(4));
      world.setBlockState(pos.add(30, 15, 56), ((BlockColored)Blocks.STAINED_HARDENED_CLAY).getStateFromMeta(4));
      world.setBlockState(pos.add(34, 15, 56), ((BlockColored)Blocks.STAINED_HARDENED_CLAY).getStateFromMeta(4));
      world.setBlockState(pos.add(35, 15, 56), ((BlockColored)Blocks.STAINED_HARDENED_CLAY).getStateFromMeta(4));
      world.setBlockState(pos.add(38, 15, 56), ((BlockColored)Blocks.STAINED_HARDENED_CLAY).getStateFromMeta(4));
      world.setBlockState(pos.add(39, 15, 56), ((BlockColored)Blocks.WOOL).getStateFromMeta(15));
      world.setBlockState(pos.add(40, 15, 56), ((BlockColored)Blocks.WOOL).getStateFromMeta(15));
      world.setBlockState(pos.add(18, 15, 57), ((BlockColored)Blocks.STAINED_HARDENED_CLAY).getStateFromMeta(4));
      world.setBlockState(pos.add(19, 15, 57), ((BlockColored)Blocks.STAINED_HARDENED_CLAY).getStateFromMeta(4));
      world.setBlockState(pos.add(20, 15, 57), ((BlockColored)Blocks.STAINED_HARDENED_CLAY).getStateFromMeta(4));
      world.setBlockState(pos.add(21, 15, 57), ((BlockColored)Blocks.STAINED_HARDENED_CLAY).getStateFromMeta(4));
      world.setBlockState(pos.add(22, 15, 57), ((BlockColored)Blocks.STAINED_HARDENED_CLAY).getStateFromMeta(4));
      world.setBlockState(pos.add(23, 15, 57), Blocks.STONE.getDefaultState());
      world.setBlockState(pos.add(29, 15, 57), Blocks.STONE.getDefaultState());
      world.setBlockState(pos.add(30, 15, 57), ((BlockColored)Blocks.STAINED_HARDENED_CLAY).getStateFromMeta(4));
      world.setBlockState(pos.add(31, 15, 57), ((BlockColored)Blocks.STAINED_HARDENED_CLAY).getStateFromMeta(4));
      world.setBlockState(pos.add(32, 15, 57), ((BlockColored)Blocks.STAINED_HARDENED_CLAY).getStateFromMeta(4));
      world.setBlockState(pos.add(33, 15, 57), ((BlockColored)Blocks.STAINED_HARDENED_CLAY).getStateFromMeta(4));
      world.setBlockState(pos.add(34, 15, 57), ((BlockColored)Blocks.STAINED_HARDENED_CLAY).getStateFromMeta(4));
      world.setBlockState(pos.add(39, 15, 57), ((BlockColored)Blocks.STAINED_HARDENED_CLAY).getStateFromMeta(4));
      world.setBlockState(pos.add(41, 15, 57), ((BlockColored)Blocks.WOOL).getStateFromMeta(15));
      world.setBlockState(pos.add(19, 15, 58), ((BlockColored)Blocks.STAINED_HARDENED_CLAY).getStateFromMeta(4));
      world.setBlockState(pos.add(20, 15, 58), ((BlockColored)Blocks.STAINED_HARDENED_CLAY).getStateFromMeta(4));
      world.setBlockState(pos.add(21, 15, 58), ((BlockColored)Blocks.STAINED_HARDENED_CLAY).getStateFromMeta(4));
      world.setBlockState(pos.add(23, 15, 58), Blocks.STONE.getDefaultState());
      world.setBlockState(pos.add(29, 15, 58), Blocks.STONE.getDefaultState());
      world.setBlockState(pos.add(31, 15, 58), ((BlockColored)Blocks.STAINED_HARDENED_CLAY).getStateFromMeta(4));
      world.setBlockState(pos.add(32, 15, 58), ((BlockColored)Blocks.STAINED_HARDENED_CLAY).getStateFromMeta(4));
      world.setBlockState(pos.add(33, 15, 58), ((BlockColored)Blocks.STAINED_HARDENED_CLAY).getStateFromMeta(4));
      world.setBlockState(pos.add(40, 15, 58), ((BlockColored)Blocks.STAINED_HARDENED_CLAY).getStateFromMeta(4));
      world.setBlockState(pos.add(42, 15, 58), ((BlockColored)Blocks.WOOL).getStateFromMeta(15));
      world.setBlockState(pos.add(21, 15, 59), Blocks.STONE.getDefaultState());
      world.setBlockState(pos.add(22, 15, 59), Blocks.STONE.getDefaultState());
      world.setBlockState(pos.add(29, 15, 59), Blocks.STONE.getDefaultState());
      world.setBlockState(pos.add(34, 15, 59), ((BlockColored)Blocks.WOOL).getStateFromMeta(15));
      world.setBlockState(pos.add(35, 15, 59), ((BlockColored)Blocks.WOOL).getStateFromMeta(15));
      world.setBlockState(pos.add(36, 15, 59), ((BlockColored)Blocks.WOOL).getStateFromMeta(15));
      world.setBlockState(pos.add(37, 15, 59), ((BlockColored)Blocks.WOOL).getStateFromMeta(15));
      world.setBlockState(pos.add(41, 15, 59), ((BlockColored)Blocks.STAINED_HARDENED_CLAY).getStateFromMeta(4));
      world.setBlockState(pos.add(42, 15, 59), ((BlockColored)Blocks.WOOL).getStateFromMeta(15));
      world.setBlockState(pos.add(18, 15, 60), Blocks.STONE.getDefaultState());
      world.setBlockState(pos.add(19, 15, 60), Blocks.STONE.getDefaultState());
      world.setBlockState(pos.add(20, 15, 60), Blocks.STONE.getDefaultState());
      world.setBlockState(pos.add(29, 15, 60), Blocks.STONE.getDefaultState());
      world.setBlockState(pos.add(33, 15, 60), ((BlockColored)Blocks.WOOL).getStateFromMeta(15));
      world.setBlockState(pos.add(38, 15, 60), ((BlockColored)Blocks.WOOL).getStateFromMeta(15));
      world.setBlockState(pos.add(42, 15, 60), Blocks.STONE.getDefaultState());
      world.setBlockState(pos.add(43, 15, 60), Blocks.STONE.getDefaultState());
      world.setBlockState(pos.add(44, 15, 60), Blocks.STONE.getDefaultState());
      world.setBlockState(pos.add(45, 15, 60), Blocks.STONE.getDefaultState());
      world.setBlockState(pos.add(18, 15, 61), Blocks.OBSIDIAN.getDefaultState());
      world.setBlockState(pos.add(20, 15, 61), Blocks.STONE.getDefaultState());
      world.setBlockState(pos.add(29, 15, 61), Blocks.STONE.getDefaultState());
      world.setBlockState(pos.add(32, 15, 61), ((BlockColored)Blocks.WOOL).getStateFromMeta(15));
      world.setBlockState(pos.add(39, 15, 61), ((BlockColored)Blocks.WOOL).getStateFromMeta(15));
      world.setBlockState(pos.add(41, 15, 61), Blocks.STONE.getDefaultState());
      world.setBlockState(pos.add(46, 15, 61), Blocks.STONE.getDefaultState());
      world.setBlockState(pos.add(18, 15, 62), Blocks.OBSIDIAN.getDefaultState());
      world.setBlockState(pos.add(21, 15, 62), Blocks.STONE.getDefaultState());
      world.setBlockState(pos.add(29, 15, 62), Blocks.STONE.getDefaultState());
      world.setBlockState(pos.add(32, 15, 62), ((BlockColored)Blocks.WOOL).getStateFromMeta(15));
      world.setBlockState(pos.add(39, 15, 62), ((BlockColored)Blocks.WOOL).getStateFromMeta(15));
      world.setBlockState(pos.add(40, 15, 62), Blocks.STONE.getDefaultState());
      world.setBlockState(pos.add(47, 15, 62), Blocks.STONE.getDefaultState());
      world.setBlockState(pos.add(18, 15, 63), Blocks.OBSIDIAN.getDefaultState());
      world.setBlockState(pos.add(21, 15, 63), Blocks.STONE.getDefaultState());
      world.setBlockState(pos.add(29, 15, 63), Blocks.STONE.getDefaultState());
      world.setBlockState(pos.add(32, 15, 63), ((BlockColored)Blocks.WOOL).getStateFromMeta(15));
      world.setBlockState(pos.add(39, 15, 63), ((BlockColored)Blocks.WOOL).getStateFromMeta(15));
      world.setBlockState(pos.add(40, 15, 63), Blocks.STONE.getDefaultState());
      world.setBlockState(pos.add(47, 15, 63), Blocks.STONE.getDefaultState());
      world.setBlockState(pos.add(18, 15, 64), Blocks.OBSIDIAN.getDefaultState());
      world.setBlockState(pos.add(20, 15, 64), Blocks.STONE.getDefaultState());
      world.setBlockState(pos.add(29, 15, 64), Blocks.STONE.getDefaultState());
      world.setBlockState(pos.add(32, 15, 64), ((BlockColored)Blocks.WOOL).getStateFromMeta(15));
      world.setBlockState(pos.add(39, 15, 64), ((BlockColored)Blocks.WOOL).getStateFromMeta(15));
      world.setBlockState(pos.add(40, 15, 64), Blocks.STONE.getDefaultState());
      world.setBlockState(pos.add(47, 15, 64), Blocks.STONE.getDefaultState());
      world.setBlockState(pos.add(18, 15, 65), Blocks.STONE.getDefaultState());
      world.setBlockState(pos.add(19, 15, 65), Blocks.STONE.getDefaultState());
      world.setBlockState(pos.add(29, 15, 65), Blocks.STONE.getDefaultState());
      world.setBlockState(pos.add(33, 15, 65), ((BlockColored)Blocks.WOOL).getStateFromMeta(15));
      world.setBlockState(pos.add(38, 15, 65), ((BlockColored)Blocks.WOOL).getStateFromMeta(15));
      world.setBlockState(pos.add(40, 15, 65), Blocks.STONE.getDefaultState());
      world.setBlockState(pos.add(47, 15, 65), Blocks.STONE.getDefaultState());
      world.setBlockState(pos.add(18, 15, 66), Blocks.STONE.getDefaultState());
      world.setBlockState(pos.add(19, 15, 66), Blocks.STONE.getDefaultState());
      world.setBlockState(pos.add(29, 15, 66), Blocks.STONE.getDefaultState());
      world.setBlockState(pos.add(34, 15, 66), ((BlockColored)Blocks.WOOL).getStateFromMeta(15));
      world.setBlockState(pos.add(35, 15, 66), ((BlockColored)Blocks.WOOL).getStateFromMeta(15));
      world.setBlockState(pos.add(36, 15, 66), ((BlockColored)Blocks.WOOL).getStateFromMeta(15));
      world.setBlockState(pos.add(37, 15, 66), ((BlockColored)Blocks.WOOL).getStateFromMeta(15));
      world.setBlockState(pos.add(41, 15, 66), Blocks.STONE.getDefaultState());
      world.setBlockState(pos.add(46, 15, 66), Blocks.STONE.getDefaultState());
      world.setBlockState(pos.add(20, 15, 67), Blocks.STONE.getDefaultState());
      world.setBlockState(pos.add(21, 15, 67), Blocks.STONE.getDefaultState());
      world.setBlockState(pos.add(22, 15, 67), Blocks.STONE.getDefaultState());
      world.setBlockState(pos.add(23, 15, 67), Blocks.STONE.getDefaultState());
      world.setBlockState(pos.add(24, 15, 67), Blocks.STONE.getDefaultState());
      world.setBlockState(pos.add(25, 15, 67), Blocks.STONE.getDefaultState());
      world.setBlockState(pos.add(26, 15, 67), Blocks.STONE.getDefaultState());
      world.setBlockState(pos.add(27, 15, 67), Blocks.STONE.getDefaultState());
      world.setBlockState(pos.add(28, 15, 67), Blocks.STONE.getDefaultState());
      world.setBlockState(pos.add(42, 15, 67), Blocks.STONE.getDefaultState());
      world.setBlockState(pos.add(43, 15, 67), Blocks.STONE.getDefaultState());
      world.setBlockState(pos.add(44, 15, 67), Blocks.STONE.getDefaultState());
      world.setBlockState(pos.add(45, 15, 67), Blocks.STONE.getDefaultState());
      world.setBlockState(pos.add(25, 16, 36), Blocks.QUARTZ_BLOCK.getDefaultState());
      world.setBlockState(pos.add(27, 16, 36), Blocks.QUARTZ_BLOCK.getDefaultState());
      world.setBlockState(pos.add(16, 16, 37), ((BlockColored)Blocks.STAINED_HARDENED_CLAY).getStateFromMeta(4));
      world.setBlockState(pos.add(17, 16, 37), ((BlockColored)Blocks.STAINED_HARDENED_CLAY).getStateFromMeta(4));
      world.setBlockState(pos.add(18, 16, 37), ((BlockColored)Blocks.STAINED_HARDENED_CLAY).getStateFromMeta(4));
      world.setBlockState(pos.add(19, 16, 37), ((BlockColored)Blocks.STAINED_HARDENED_CLAY).getStateFromMeta(4));
      world.setBlockState(pos.add(20, 16, 37), ((BlockColored)Blocks.STAINED_HARDENED_CLAY).getStateFromMeta(4));
      world.setBlockState(pos.add(21, 16, 37), Blocks.QUARTZ_STAIRS.getDefaultState());
      world.setBlockState(pos.add(22, 16, 37), Blocks.QUARTZ_BLOCK.getDefaultState());
      world.setBlockState(pos.add(23, 16, 37), ((BlockColored)Blocks.STAINED_HARDENED_CLAY).getStateFromMeta(4));
      world.setBlockState(pos.add(24, 16, 37), Blocks.QUARTZ_BLOCK.getDefaultState());
      world.setBlockState(pos.add(28, 16, 37), Blocks.QUARTZ_BLOCK.getDefaultState());
      world.setBlockState(pos.add(29, 16, 37), ((BlockColored)Blocks.STAINED_HARDENED_CLAY).getStateFromMeta(4));
      world.setBlockState(pos.add(32, 16, 37), ((BlockColored)Blocks.STAINED_HARDENED_CLAY).getStateFromMeta(4));
      world.setBlockState(pos.add(33, 16, 37), ((BlockColored)Blocks.STAINED_HARDENED_CLAY).getStateFromMeta(4));
      world.setBlockState(pos.add(34, 16, 37), ((BlockColored)Blocks.STAINED_HARDENED_CLAY).getStateFromMeta(4));
      world.setBlockState(pos.add(35, 16, 37), ((BlockColored)Blocks.STAINED_HARDENED_CLAY).getStateFromMeta(4));
      world.setBlockState(pos.add(36, 16, 37), ((BlockColored)Blocks.STAINED_HARDENED_CLAY).getStateFromMeta(4));
      world.setBlockState(pos.add(16, 16, 38), ((BlockColored)Blocks.STAINED_HARDENED_CLAY).getStateFromMeta(4));
      world.setBlockState(pos.add(17, 16, 38), ((BlockColored)Blocks.STAINED_HARDENED_CLAY).getStateFromMeta(4));
      world.setBlockState(pos.add(18, 16, 38), ((BlockColored)Blocks.STAINED_HARDENED_CLAY).getStateFromMeta(4));
      world.setBlockState(pos.add(19, 16, 38), ((BlockColored)Blocks.STAINED_HARDENED_CLAY).getStateFromMeta(4));
      world.setBlockState(pos.add(20, 16, 38), ((BlockColored)Blocks.STAINED_HARDENED_CLAY).getStateFromMeta(4));
      world.setBlockState(pos.add(21, 16, 38), Blocks.QUARTZ_STAIRS.getDefaultState());
      world.setBlockState(pos.add(22, 16, 38), Blocks.QUARTZ_BLOCK.getDefaultState());
      world.setBlockState(pos.add(30, 16, 38), Blocks.QUARTZ_BLOCK.getDefaultState());
      world.setBlockState(pos.add(31, 16, 38), ((BlockStairs)Blocks.QUARTZ_STAIRS).getStateFromMeta(1));
      world.setBlockState(pos.add(32, 16, 38), ((BlockColored)Blocks.STAINED_HARDENED_CLAY).getStateFromMeta(4));
      world.setBlockState(pos.add(33, 16, 38), ((BlockColored)Blocks.STAINED_HARDENED_CLAY).getStateFromMeta(4));
      world.setBlockState(pos.add(34, 16, 38), ((BlockColored)Blocks.STAINED_HARDENED_CLAY).getStateFromMeta(4));
      world.setBlockState(pos.add(35, 16, 38), ((BlockColored)Blocks.STAINED_HARDENED_CLAY).getStateFromMeta(4));
      world.setBlockState(pos.add(36, 16, 38), ((BlockColored)Blocks.STAINED_HARDENED_CLAY).getStateFromMeta(4));
      world.setBlockState(pos.add(4, 16, 39), Blocks.STONE.getDefaultState());
      world.setBlockState(pos.add(5, 16, 39), Blocks.STONE.getDefaultState());
      world.setBlockState(pos.add(6, 16, 39), Blocks.STONE.getDefaultState());
      world.setBlockState(pos.add(7, 16, 39), Blocks.STONE.getDefaultState());
      world.setBlockState(pos.add(8, 16, 39), Blocks.STONE.getDefaultState());
      world.setBlockState(pos.add(16, 16, 39), ((BlockColored)Blocks.STAINED_HARDENED_CLAY).getStateFromMeta(4));
      world.setBlockState(pos.add(20, 16, 39), ((BlockColored)Blocks.STAINED_HARDENED_CLAY).getStateFromMeta(4));
      world.setBlockState(pos.add(21, 16, 39), Blocks.QUARTZ_STAIRS.getDefaultState());
      world.setBlockState(pos.add(22, 16, 39), Blocks.QUARTZ_BLOCK.getDefaultState());
      world.setBlockState(pos.add(30, 16, 39), Blocks.QUARTZ_BLOCK.getDefaultState());
      world.setBlockState(pos.add(31, 16, 39), ((BlockStairs)Blocks.QUARTZ_STAIRS).getStateFromMeta(1));
      world.setBlockState(pos.add(32, 16, 39), ((BlockColored)Blocks.STAINED_HARDENED_CLAY).getStateFromMeta(4));
      world.setBlockState(pos.add(36, 16, 39), ((BlockColored)Blocks.STAINED_HARDENED_CLAY).getStateFromMeta(4));
      world.setBlockState(pos.add(3, 16, 40), Blocks.STONE.getDefaultState());
      world.setBlockState(pos.add(4, 16, 40), Blocks.STONE.getDefaultState());
      world.setBlockState(pos.add(8, 16, 40), Blocks.STONE.getDefaultState());
      world.setBlockState(pos.add(9, 16, 40), Blocks.STONE.getDefaultState());
      world.setBlockState(pos.add(16, 16, 40), ((BlockColored)Blocks.STAINED_HARDENED_CLAY).getStateFromMeta(4));
      world.setBlockState(pos.add(20, 16, 40), ((BlockColored)Blocks.STAINED_HARDENED_CLAY).getStateFromMeta(4));
      world.setBlockState(pos.add(21, 16, 40), Blocks.QUARTZ_STAIRS.getDefaultState());
      world.setBlockState(pos.add(22, 16, 40), Blocks.QUARTZ_BLOCK.getDefaultState());
      world.setBlockState(pos.add(30, 16, 40), Blocks.QUARTZ_BLOCK.getDefaultState());
      world.setBlockState(pos.add(31, 16, 40), ((BlockStairs)Blocks.QUARTZ_STAIRS).getStateFromMeta(1));
      world.setBlockState(pos.add(32, 16, 40), ((BlockColored)Blocks.STAINED_HARDENED_CLAY).getStateFromMeta(4));
      world.setBlockState(pos.add(34, 16, 40), ((BlockColored)Blocks.STAINED_HARDENED_CLAY).getStateFromMeta(4));
      world.setBlockState(pos.add(35, 16, 40), ((BlockColored)Blocks.STAINED_HARDENED_CLAY).getStateFromMeta(4));
      world.setBlockState(pos.add(36, 16, 40), ((BlockColored)Blocks.STAINED_HARDENED_CLAY).getStateFromMeta(4));
      world.setBlockState(pos.add(2, 16, 41), Blocks.STONE.getDefaultState());
      world.setBlockState(pos.add(3, 16, 41), Blocks.STONE.getDefaultState());
      world.setBlockState(pos.add(9, 16, 41), Blocks.STONE.getDefaultState());
      world.setBlockState(pos.add(10, 16, 41), Blocks.STONE.getDefaultState());
      world.setBlockState(pos.add(17, 16, 41), Blocks.QUARTZ_BLOCK.getDefaultState());
      world.setBlockState(pos.add(18, 16, 41), Blocks.QUARTZ_BLOCK.getDefaultState());
      world.setBlockState(pos.add(20, 16, 41), Blocks.QUARTZ_BLOCK.getDefaultState());
      world.setBlockState(pos.add(21, 16, 41), Blocks.QUARTZ_STAIRS.getDefaultState());
      world.setBlockState(pos.add(22, 16, 41), Blocks.QUARTZ_BLOCK.getDefaultState());
      world.setBlockState(pos.add(26, 16, 41), Blocks.STONE.getDefaultState());
      world.setBlockState(pos.add(27, 16, 41), Blocks.STONE.getDefaultState());
      world.setBlockState(pos.add(30, 16, 41), Blocks.QUARTZ_BLOCK.getDefaultState());
      world.setBlockState(pos.add(31, 16, 41), ((BlockStairs)Blocks.QUARTZ_STAIRS).getStateFromMeta(1));
      world.setBlockState(pos.add(32, 16, 41), Blocks.QUARTZ_BLOCK.getDefaultState());
      world.setBlockState(pos.add(35, 16, 41), Blocks.QUARTZ_BLOCK.getDefaultState());
      world.setBlockState(pos.add(2, 16, 42), Blocks.STONE.getDefaultState());
      world.setBlockState(pos.add(10, 16, 42), Blocks.STONE.getDefaultState());
      world.setBlockState(pos.add(17, 16, 42), Blocks.QUARTZ_BLOCK.getDefaultState());
      world.setBlockState(pos.add(20, 16, 42), Blocks.QUARTZ_BLOCK.getDefaultState());
      world.setBlockState(pos.add(21, 16, 42), Blocks.QUARTZ_STAIRS.getDefaultState());
      world.setBlockState(pos.add(22, 16, 42), Blocks.QUARTZ_BLOCK.getDefaultState());
      world.setBlockState(pos.add(26, 16, 42), Blocks.STONE.getDefaultState());
      world.setBlockState(pos.add(27, 16, 42), Blocks.STONE.getDefaultState());
      world.setBlockState(pos.add(30, 16, 42), Blocks.QUARTZ_BLOCK.getDefaultState());
      world.setBlockState(pos.add(31, 16, 42), ((BlockStairs)Blocks.QUARTZ_STAIRS).getStateFromMeta(1));
      world.setBlockState(pos.add(32, 16, 42), Blocks.QUARTZ_BLOCK.getDefaultState());
      world.setBlockState(pos.add(35, 16, 42), Blocks.QUARTZ_BLOCK.getDefaultState());
      world.setBlockState(pos.add(2, 16, 43), Blocks.STONE.getDefaultState());
      world.setBlockState(pos.add(10, 16, 43), Blocks.STONE.getDefaultState());
      world.setBlockState(pos.add(16, 16, 43), ((BlockColored)Blocks.STAINED_HARDENED_CLAY).getStateFromMeta(4));
      world.setBlockState(pos.add(17, 16, 43), ((BlockColored)Blocks.STAINED_HARDENED_CLAY).getStateFromMeta(4));
      world.setBlockState(pos.add(20, 16, 43), ((BlockColored)Blocks.STAINED_HARDENED_CLAY).getStateFromMeta(4));
      world.setBlockState(pos.add(21, 16, 43), Blocks.QUARTZ_STAIRS.getDefaultState());
      world.setBlockState(pos.add(22, 16, 43), Blocks.QUARTZ_BLOCK.getDefaultState());
      world.setBlockState(pos.add(30, 16, 43), Blocks.QUARTZ_BLOCK.getDefaultState());
      world.setBlockState(pos.add(31, 16, 43), ((BlockStairs)Blocks.QUARTZ_STAIRS).getStateFromMeta(1));
      world.setBlockState(pos.add(32, 16, 43), ((BlockColored)Blocks.STAINED_HARDENED_CLAY).getStateFromMeta(4));
      world.setBlockState(pos.add(36, 16, 43), ((BlockColored)Blocks.STAINED_HARDENED_CLAY).getStateFromMeta(4));
      world.setBlockState(pos.add(2, 16, 44), Blocks.STONE.getDefaultState());
      world.setBlockState(pos.add(10, 16, 44), Blocks.STONE.getDefaultState());
      world.setBlockState(pos.add(16, 16, 44), ((BlockColored)Blocks.STAINED_HARDENED_CLAY).getStateFromMeta(4));
      world.setBlockState(pos.add(20, 16, 44), ((BlockColored)Blocks.STAINED_HARDENED_CLAY).getStateFromMeta(4));
      world.setBlockState(pos.add(21, 16, 44), Blocks.QUARTZ_STAIRS.getDefaultState());
      world.setBlockState(pos.add(22, 16, 44), Blocks.QUARTZ_BLOCK.getDefaultState());
      world.setBlockState(pos.add(30, 16, 44), Blocks.QUARTZ_BLOCK.getDefaultState());
      world.setBlockState(pos.add(31, 16, 44), ((BlockStairs)Blocks.QUARTZ_STAIRS).getStateFromMeta(1));
      world.setBlockState(pos.add(32, 16, 44), ((BlockColored)Blocks.STAINED_HARDENED_CLAY).getStateFromMeta(4));
      world.setBlockState(pos.add(36, 16, 44), ((BlockColored)Blocks.STAINED_HARDENED_CLAY).getStateFromMeta(4));
      world.setBlockState(pos.add(2, 16, 45), Blocks.STONE.getDefaultState());
      world.setBlockState(pos.add(3, 16, 45), Blocks.STONE.getDefaultState());
      world.setBlockState(pos.add(9, 16, 45), Blocks.STONE.getDefaultState());
      world.setBlockState(pos.add(10, 16, 45), Blocks.STONE.getDefaultState());
      world.setBlockState(pos.add(16, 16, 45), ((BlockColored)Blocks.STAINED_HARDENED_CLAY).getStateFromMeta(4));
      world.setBlockState(pos.add(20, 16, 45), ((BlockColored)Blocks.STAINED_HARDENED_CLAY).getStateFromMeta(4));
      world.setBlockState(pos.add(21, 16, 45), Blocks.QUARTZ_STAIRS.getDefaultState());
      world.setBlockState(pos.add(22, 16, 45), Blocks.QUARTZ_BLOCK.getDefaultState());
      world.setBlockState(pos.add(30, 16, 45), Blocks.QUARTZ_BLOCK.getDefaultState());
      world.setBlockState(pos.add(31, 16, 45), ((BlockStairs)Blocks.QUARTZ_STAIRS).getStateFromMeta(1));
      world.setBlockState(pos.add(32, 16, 45), ((BlockColored)Blocks.STAINED_HARDENED_CLAY).getStateFromMeta(4));
      world.setBlockState(pos.add(36, 16, 45), ((BlockColored)Blocks.STAINED_HARDENED_CLAY).getStateFromMeta(4));
      world.setBlockState(pos.add(3, 16, 46), Blocks.STONE.getDefaultState());
      world.setBlockState(pos.add(4, 16, 46), Blocks.STONE.getDefaultState());
      world.setBlockState(pos.add(8, 16, 46), Blocks.STONE.getDefaultState());
      world.setBlockState(pos.add(9, 16, 46), Blocks.STONE.getDefaultState());
      world.setBlockState(pos.add(17, 16, 46), Blocks.QUARTZ_BLOCK.getDefaultState());
      world.setBlockState(pos.add(18, 16, 46), Blocks.QUARTZ_BLOCK.getDefaultState());
      world.setBlockState(pos.add(19, 16, 46), Blocks.QUARTZ_BLOCK.getDefaultState());
      world.setBlockState(pos.add(20, 16, 46), Blocks.QUARTZ_BLOCK.getDefaultState());
      world.setBlockState(pos.add(21, 16, 46), Blocks.QUARTZ_STAIRS.getDefaultState());
      world.setBlockState(pos.add(22, 16, 46), Blocks.QUARTZ_BLOCK.getDefaultState());
      world.setBlockState(pos.add(25, 16, 46), Blocks.STONE.getDefaultState());
      world.setBlockState(pos.add(26, 16, 46), Blocks.STONE.getDefaultState());
      world.setBlockState(pos.add(30, 16, 46), Blocks.QUARTZ_BLOCK.getDefaultState());
      world.setBlockState(pos.add(31, 16, 46), ((BlockStairs)Blocks.QUARTZ_STAIRS).getStateFromMeta(1));
      world.setBlockState(pos.add(32, 16, 46), Blocks.QUARTZ_BLOCK.getDefaultState());
      world.setBlockState(pos.add(34, 16, 46), Blocks.QUARTZ_BLOCK.getDefaultState());
      world.setBlockState(pos.add(35, 16, 46), Blocks.QUARTZ_BLOCK.getDefaultState());
      world.setBlockState(pos.add(4, 16, 47), Blocks.STONE.getDefaultState());
      world.setBlockState(pos.add(5, 16, 47), Blocks.STONE.getDefaultState());
      world.setBlockState(pos.add(6, 16, 47), Blocks.STONE.getDefaultState());
      world.setBlockState(pos.add(7, 16, 47), Blocks.STONE.getDefaultState());
      world.setBlockState(pos.add(8, 16, 47), Blocks.STONE.getDefaultState());
      world.setBlockState(pos.add(17, 16, 47), Blocks.QUARTZ_BLOCK.getDefaultState());
      world.setBlockState(pos.add(18, 16, 47), Blocks.QUARTZ_BLOCK.getDefaultState());
      world.setBlockState(pos.add(19, 16, 47), Blocks.QUARTZ_BLOCK.getDefaultState());
      world.setBlockState(pos.add(20, 16, 47), Blocks.QUARTZ_BLOCK.getDefaultState());
      world.setBlockState(pos.add(21, 16, 47), Blocks.QUARTZ_STAIRS.getDefaultState());
      world.setBlockState(pos.add(22, 16, 47), Blocks.QUARTZ_BLOCK.getDefaultState());
      world.setBlockState(pos.add(25, 16, 47), Blocks.STONE.getDefaultState());
      world.setBlockState(pos.add(26, 16, 47), Blocks.STONE.getDefaultState());
      world.setBlockState(pos.add(30, 16, 47), Blocks.QUARTZ_BLOCK.getDefaultState());
      world.setBlockState(pos.add(31, 16, 47), ((BlockStairs)Blocks.QUARTZ_STAIRS).getStateFromMeta(1));
      world.setBlockState(pos.add(32, 16, 47), Blocks.QUARTZ_BLOCK.getDefaultState());
      world.setBlockState(pos.add(34, 16, 47), Blocks.QUARTZ_BLOCK.getDefaultState());
      world.setBlockState(pos.add(35, 16, 47), Blocks.QUARTZ_BLOCK.getDefaultState());
      world.setBlockState(pos.add(16, 16, 48), ((BlockColored)Blocks.STAINED_HARDENED_CLAY).getStateFromMeta(4));
      world.setBlockState(pos.add(20, 16, 48), ((BlockColored)Blocks.STAINED_HARDENED_CLAY).getStateFromMeta(4));
      world.setBlockState(pos.add(21, 16, 48), Blocks.QUARTZ_STAIRS.getDefaultState());
      world.setBlockState(pos.add(22, 16, 48), Blocks.QUARTZ_BLOCK.getDefaultState());
      world.setBlockState(pos.add(30, 16, 48), Blocks.QUARTZ_BLOCK.getDefaultState());
      world.setBlockState(pos.add(31, 16, 48), ((BlockStairs)Blocks.QUARTZ_STAIRS).getStateFromMeta(1));
      world.setBlockState(pos.add(32, 16, 48), ((BlockColored)Blocks.STAINED_HARDENED_CLAY).getStateFromMeta(4));
      world.setBlockState(pos.add(35, 16, 48), ((BlockColored)Blocks.STAINED_HARDENED_CLAY).getStateFromMeta(4));
      world.setBlockState(pos.add(36, 16, 48), ((BlockColored)Blocks.STAINED_HARDENED_CLAY).getStateFromMeta(4));
      world.setBlockState(pos.add(16, 16, 49), ((BlockColored)Blocks.STAINED_HARDENED_CLAY).getStateFromMeta(4));
      world.setBlockState(pos.add(20, 16, 49), ((BlockColored)Blocks.STAINED_HARDENED_CLAY).getStateFromMeta(4));
      world.setBlockState(pos.add(21, 16, 49), Blocks.QUARTZ_STAIRS.getDefaultState());
      world.setBlockState(pos.add(22, 16, 49), Blocks.QUARTZ_BLOCK.getDefaultState());
      world.setBlockState(pos.add(30, 16, 49), Blocks.QUARTZ_BLOCK.getDefaultState());
      world.setBlockState(pos.add(31, 16, 49), ((BlockStairs)Blocks.QUARTZ_STAIRS).getStateFromMeta(1));
      world.setBlockState(pos.add(32, 16, 49), ((BlockColored)Blocks.STAINED_HARDENED_CLAY).getStateFromMeta(4));
      world.setBlockState(pos.add(36, 16, 49), ((BlockColored)Blocks.STAINED_HARDENED_CLAY).getStateFromMeta(4));
      world.setBlockState(pos.add(16, 16, 50), ((BlockColored)Blocks.STAINED_HARDENED_CLAY).getStateFromMeta(4));
      world.setBlockState(pos.add(17, 16, 50), ((BlockColored)Blocks.STAINED_HARDENED_CLAY).getStateFromMeta(4));
      world.setBlockState(pos.add(18, 16, 50), ((BlockColored)Blocks.STAINED_HARDENED_CLAY).getStateFromMeta(4));
      world.setBlockState(pos.add(19, 16, 50), ((BlockColored)Blocks.STAINED_HARDENED_CLAY).getStateFromMeta(4));
      world.setBlockState(pos.add(20, 16, 50), ((BlockColored)Blocks.STAINED_HARDENED_CLAY).getStateFromMeta(4));
      world.setBlockState(pos.add(21, 16, 50), Blocks.QUARTZ_STAIRS.getDefaultState());
      world.setBlockState(pos.add(22, 16, 50), Blocks.QUARTZ_BLOCK.getDefaultState());
      world.setBlockState(pos.add(30, 16, 50), Blocks.QUARTZ_BLOCK.getDefaultState());
      world.setBlockState(pos.add(31, 16, 50), ((BlockStairs)Blocks.QUARTZ_STAIRS).getStateFromMeta(1));
      world.setBlockState(pos.add(32, 16, 50), ((BlockColored)Blocks.STAINED_HARDENED_CLAY).getStateFromMeta(4));
      world.setBlockState(pos.add(33, 16, 50), ((BlockColored)Blocks.STAINED_HARDENED_CLAY).getStateFromMeta(4));
      world.setBlockState(pos.add(34, 16, 50), ((BlockColored)Blocks.STAINED_HARDENED_CLAY).getStateFromMeta(4));
      world.setBlockState(pos.add(35, 16, 50), ((BlockColored)Blocks.STAINED_HARDENED_CLAY).getStateFromMeta(4));
      world.setBlockState(pos.add(36, 16, 50), ((BlockColored)Blocks.STAINED_HARDENED_CLAY).getStateFromMeta(4));
      world.setBlockState(pos.add(18, 16, 51), ((BlockColored)Blocks.STAINED_HARDENED_CLAY).getStateFromMeta(4));
      world.setBlockState(pos.add(19, 16, 51), ((BlockColored)Blocks.STAINED_HARDENED_CLAY).getStateFromMeta(4));
      world.setBlockState(pos.add(20, 16, 51), ((BlockColored)Blocks.STAINED_HARDENED_CLAY).getStateFromMeta(4));
      world.setBlockState(pos.add(21, 16, 51), ((BlockColored)Blocks.STAINED_HARDENED_CLAY).getStateFromMeta(4));
      world.setBlockState(pos.add(30, 16, 51), ((BlockColored)Blocks.STAINED_HARDENED_CLAY).getStateFromMeta(4));
      world.setBlockState(pos.add(31, 16, 51), ((BlockColored)Blocks.STAINED_HARDENED_CLAY).getStateFromMeta(4));
      world.setBlockState(pos.add(32, 16, 51), ((BlockColored)Blocks.STAINED_HARDENED_CLAY).getStateFromMeta(4));
      world.setBlockState(pos.add(33, 16, 51), ((BlockColored)Blocks.STAINED_HARDENED_CLAY).getStateFromMeta(4));
      world.setBlockState(pos.add(34, 16, 51), ((BlockColored)Blocks.STAINED_HARDENED_CLAY).getStateFromMeta(4));
      world.setBlockState(pos.add(17, 16, 52), ((BlockColored)Blocks.STAINED_HARDENED_CLAY).getStateFromMeta(4));
      world.setBlockState(pos.add(18, 16, 52), ((BlockColored)Blocks.STAINED_HARDENED_CLAY).getStateFromMeta(4));
      world.setBlockState(pos.add(22, 16, 52), ((BlockColored)Blocks.STAINED_HARDENED_CLAY).getStateFromMeta(4));
      world.setBlockState(pos.add(29, 16, 52), ((BlockColored)Blocks.STAINED_HARDENED_CLAY).getStateFromMeta(4));
      world.setBlockState(pos.add(30, 16, 52), ((BlockColored)Blocks.STAINED_HARDENED_CLAY).getStateFromMeta(4));
      world.setBlockState(pos.add(34, 16, 52), ((BlockColored)Blocks.STAINED_HARDENED_CLAY).getStateFromMeta(4));
      world.setBlockState(pos.add(35, 16, 52), ((BlockColored)Blocks.STAINED_HARDENED_CLAY).getStateFromMeta(4));
      world.setBlockState(pos.add(16, 16, 53), ((BlockColored)Blocks.STAINED_HARDENED_CLAY).getStateFromMeta(4));
      world.setBlockState(pos.add(17, 16, 53), ((BlockColored)Blocks.STAINED_HARDENED_CLAY).getStateFromMeta(4));
      world.setBlockState(pos.add(23, 16, 53), ((BlockColored)Blocks.STAINED_HARDENED_CLAY).getStateFromMeta(4));
      world.setBlockState(pos.add(24, 16, 53), ((BlockColored)Blocks.STAINED_HARDENED_CLAY).getStateFromMeta(4));
      world.setBlockState(pos.add(28, 16, 53), ((BlockColored)Blocks.STAINED_HARDENED_CLAY).getStateFromMeta(4));
      world.setBlockState(pos.add(29, 16, 53), ((BlockColored)Blocks.STAINED_HARDENED_CLAY).getStateFromMeta(4));
      world.setBlockState(pos.add(35, 16, 53), ((BlockColored)Blocks.STAINED_HARDENED_CLAY).getStateFromMeta(4));
      world.setBlockState(pos.add(36, 16, 53), ((BlockColored)Blocks.STAINED_HARDENED_CLAY).getStateFromMeta(4));
      world.setBlockState(pos.add(16, 16, 54), ((BlockColored)Blocks.STAINED_HARDENED_CLAY).getStateFromMeta(4));
      world.setBlockState(pos.add(17, 16, 54), ((BlockColored)Blocks.STAINED_HARDENED_CLAY).getStateFromMeta(4));
      world.setBlockState(pos.add(23, 16, 54), ((BlockColored)Blocks.STAINED_HARDENED_CLAY).getStateFromMeta(4));
      world.setBlockState(pos.add(24, 16, 54), ((BlockColored)Blocks.STAINED_HARDENED_CLAY).getStateFromMeta(4));
      world.setBlockState(pos.add(28, 16, 54), ((BlockColored)Blocks.STAINED_HARDENED_CLAY).getStateFromMeta(4));
      world.setBlockState(pos.add(29, 16, 54), ((BlockColored)Blocks.STAINED_HARDENED_CLAY).getStateFromMeta(4));
      world.setBlockState(pos.add(35, 16, 54), ((BlockColored)Blocks.STAINED_HARDENED_CLAY).getStateFromMeta(4));
      world.setBlockState(pos.add(36, 16, 54), ((BlockColored)Blocks.STAINED_HARDENED_CLAY).getStateFromMeta(4));
      world.setBlockState(pos.add(16, 16, 55), ((BlockColored)Blocks.STAINED_HARDENED_CLAY).getStateFromMeta(4));
      world.setBlockState(pos.add(17, 16, 55), ((BlockColored)Blocks.STAINED_HARDENED_CLAY).getStateFromMeta(4));
      world.setBlockState(pos.add(23, 16, 55), ((BlockColored)Blocks.STAINED_HARDENED_CLAY).getStateFromMeta(4));
      world.setBlockState(pos.add(24, 16, 55), ((BlockColored)Blocks.STAINED_HARDENED_CLAY).getStateFromMeta(4));
      world.setBlockState(pos.add(28, 16, 55), ((BlockColored)Blocks.STAINED_HARDENED_CLAY).getStateFromMeta(4));
      world.setBlockState(pos.add(29, 16, 55), ((BlockColored)Blocks.STAINED_HARDENED_CLAY).getStateFromMeta(4));
      world.setBlockState(pos.add(35, 16, 55), ((BlockColored)Blocks.STAINED_HARDENED_CLAY).getStateFromMeta(4));
      world.setBlockState(pos.add(36, 16, 55), ((BlockColored)Blocks.STAINED_HARDENED_CLAY).getStateFromMeta(4));
      world.setBlockState(pos.add(37, 16, 55), ((BlockColored)Blocks.STAINED_HARDENED_CLAY).getStateFromMeta(4));
      world.setBlockState(pos.add(17, 16, 56), ((BlockColored)Blocks.STAINED_HARDENED_CLAY).getStateFromMeta(4));
      world.setBlockState(pos.add(18, 16, 56), ((BlockColored)Blocks.STAINED_HARDENED_CLAY).getStateFromMeta(4));
      world.setBlockState(pos.add(22, 16, 56), ((BlockColored)Blocks.STAINED_HARDENED_CLAY).getStateFromMeta(4));
      world.setBlockState(pos.add(23, 16, 56), ((BlockColored)Blocks.STAINED_HARDENED_CLAY).getStateFromMeta(4));
      world.setBlockState(pos.add(24, 16, 56), ((BlockStone)Blocks.STONE).getStateFromMeta(4));
      world.setBlockState(pos.add(28, 16, 56), ((BlockStone)Blocks.STONE).getStateFromMeta(4));
      world.setBlockState(pos.add(29, 16, 56), ((BlockColored)Blocks.STAINED_HARDENED_CLAY).getStateFromMeta(4));
      world.setBlockState(pos.add(30, 16, 56), ((BlockColored)Blocks.STAINED_HARDENED_CLAY).getStateFromMeta(4));
      world.setBlockState(pos.add(34, 16, 56), ((BlockColored)Blocks.STAINED_HARDENED_CLAY).getStateFromMeta(4));
      world.setBlockState(pos.add(35, 16, 56), ((BlockColored)Blocks.STAINED_HARDENED_CLAY).getStateFromMeta(4));
      world.setBlockState(pos.add(38, 16, 56), ((BlockColored)Blocks.STAINED_HARDENED_CLAY).getStateFromMeta(4));
      world.setBlockState(pos.add(39, 16, 56), ((BlockColored)Blocks.WOOL).getStateFromMeta(15));
      world.setBlockState(pos.add(40, 16, 56), ((BlockColored)Blocks.WOOL).getStateFromMeta(15));
      world.setBlockState(pos.add(18, 16, 57), ((BlockColored)Blocks.STAINED_HARDENED_CLAY).getStateFromMeta(4));
      world.setBlockState(pos.add(19, 16, 57), ((BlockColored)Blocks.STAINED_HARDENED_CLAY).getStateFromMeta(4));
      world.setBlockState(pos.add(20, 16, 57), ((BlockColored)Blocks.STAINED_HARDENED_CLAY).getStateFromMeta(4));
      world.setBlockState(pos.add(21, 16, 57), ((BlockColored)Blocks.STAINED_HARDENED_CLAY).getStateFromMeta(4));
      world.setBlockState(pos.add(22, 16, 57), ((BlockColored)Blocks.STAINED_HARDENED_CLAY).getStateFromMeta(4));
      world.setBlockState(pos.add(24, 16, 57), Blocks.STONE.getDefaultState());
      world.setBlockState(pos.add(28, 16, 57), Blocks.STONE.getDefaultState());
      world.setBlockState(pos.add(30, 16, 57), ((BlockColored)Blocks.STAINED_HARDENED_CLAY).getStateFromMeta(4));
      world.setBlockState(pos.add(31, 16, 57), ((BlockColored)Blocks.STAINED_HARDENED_CLAY).getStateFromMeta(4));
      world.setBlockState(pos.add(32, 16, 57), ((BlockColored)Blocks.STAINED_HARDENED_CLAY).getStateFromMeta(4));
      world.setBlockState(pos.add(33, 16, 57), ((BlockColored)Blocks.STAINED_HARDENED_CLAY).getStateFromMeta(4));
      world.setBlockState(pos.add(34, 16, 57), ((BlockColored)Blocks.STAINED_HARDENED_CLAY).getStateFromMeta(4));
      world.setBlockState(pos.add(39, 16, 57), ((BlockColored)Blocks.STAINED_HARDENED_CLAY).getStateFromMeta(4));
      world.setBlockState(pos.add(41, 16, 57), ((BlockColored)Blocks.WOOL).getStateFromMeta(15));
      world.setBlockState(pos.add(19, 16, 58), ((BlockColored)Blocks.STAINED_HARDENED_CLAY).getStateFromMeta(4));
      world.setBlockState(pos.add(20, 16, 58), ((BlockColored)Blocks.STAINED_HARDENED_CLAY).getStateFromMeta(4));
      world.setBlockState(pos.add(21, 16, 58), ((BlockColored)Blocks.STAINED_HARDENED_CLAY).getStateFromMeta(4));
      world.setBlockState(pos.add(24, 16, 58), Blocks.STONE.getDefaultState());
      world.setBlockState(pos.add(28, 16, 58), Blocks.STONE.getDefaultState());
      world.setBlockState(pos.add(31, 16, 58), ((BlockColored)Blocks.STAINED_HARDENED_CLAY).getStateFromMeta(4));
      world.setBlockState(pos.add(32, 16, 58), ((BlockColored)Blocks.STAINED_HARDENED_CLAY).getStateFromMeta(4));
      world.setBlockState(pos.add(33, 16, 58), ((BlockColored)Blocks.STAINED_HARDENED_CLAY).getStateFromMeta(4));
      world.setBlockState(pos.add(40, 16, 58), ((BlockColored)Blocks.STAINED_HARDENED_CLAY).getStateFromMeta(4));
      world.setBlockState(pos.add(42, 16, 58), ((BlockColored)Blocks.WOOL).getStateFromMeta(15));
      world.setBlockState(pos.add(23, 16, 59), Blocks.STONE.getDefaultState());
      world.setBlockState(pos.add(24, 16, 59), Blocks.STONE.getDefaultState());
      world.setBlockState(pos.add(28, 16, 59), Blocks.STONE.getDefaultState());
      world.setBlockState(pos.add(34, 16, 59), Blocks.REDSTONE_BLOCK.getDefaultState());
      world.setBlockState(pos.add(35, 16, 59), Blocks.REDSTONE_BLOCK.getDefaultState());
      world.setBlockState(pos.add(36, 16, 59), Blocks.REDSTONE_BLOCK.getDefaultState());
      world.setBlockState(pos.add(37, 16, 59), Blocks.REDSTONE_BLOCK.getDefaultState());
      world.setBlockState(pos.add(41, 16, 59), ((BlockColored)Blocks.STAINED_HARDENED_CLAY).getStateFromMeta(4));
      world.setBlockState(pos.add(42, 16, 59), ((BlockColored)Blocks.WOOL).getStateFromMeta(15));
      world.setBlockState(pos.add(20, 16, 60), Blocks.STONE.getDefaultState());
      world.setBlockState(pos.add(21, 16, 60), Blocks.STONE.getDefaultState());
      world.setBlockState(pos.add(22, 16, 60), Blocks.STONE.getDefaultState());
      world.setBlockState(pos.add(23, 16, 60), Blocks.STONE.getDefaultState());
      world.setBlockState(pos.add(28, 16, 60), Blocks.STONE.getDefaultState());
      world.setBlockState(pos.add(33, 16, 60), Blocks.REDSTONE_BLOCK.getDefaultState());
      world.setBlockState(pos.add(38, 16, 60), Blocks.REDSTONE_BLOCK.getDefaultState());
      world.setBlockState(pos.add(42, 16, 60), Blocks.STONE.getDefaultState());
      world.setBlockState(pos.add(43, 16, 60), Blocks.STONE.getDefaultState());
      world.setBlockState(pos.add(44, 16, 60), Blocks.STONE.getDefaultState());
      world.setBlockState(pos.add(45, 16, 60), Blocks.STONE.getDefaultState());
      world.setBlockState(pos.add(18, 16, 61), Blocks.STONE.getDefaultState());
      world.setBlockState(pos.add(19, 16, 61), Blocks.STONE.getDefaultState());
      world.setBlockState(pos.add(20, 16, 61), Blocks.STONE.getDefaultState());
      world.setBlockState(pos.add(28, 16, 61), Blocks.STONE.getDefaultState());
      world.setBlockState(pos.add(32, 16, 61), Blocks.REDSTONE_BLOCK.getDefaultState());
      world.setBlockState(pos.add(39, 16, 61), Blocks.REDSTONE_BLOCK.getDefaultState());
      world.setBlockState(pos.add(41, 16, 61), Blocks.STONE.getDefaultState());
      world.setBlockState(pos.add(46, 16, 61), Blocks.STONE.getDefaultState());
      world.setBlockState(pos.add(18, 16, 62), Blocks.OBSIDIAN.getDefaultState());
      world.setBlockState(pos.add(20, 16, 62), Blocks.STONE.getDefaultState());
      world.setBlockState(pos.add(28, 16, 62), Blocks.STONE.getDefaultState());
      world.setBlockState(pos.add(32, 16, 62), Blocks.REDSTONE_BLOCK.getDefaultState());
      world.setBlockState(pos.add(39, 16, 62), Blocks.REDSTONE_BLOCK.getDefaultState());
      world.setBlockState(pos.add(40, 16, 62), Blocks.STONE.getDefaultState());
      world.setBlockState(pos.add(47, 16, 62), Blocks.STONE.getDefaultState());
      world.setBlockState(pos.add(18, 16, 63), Blocks.OBSIDIAN.getDefaultState());
      world.setBlockState(pos.add(20, 16, 63), Blocks.STONE.getDefaultState());
      world.setBlockState(pos.add(28, 16, 63), Blocks.STONE.getDefaultState());
      world.setBlockState(pos.add(32, 16, 63), Blocks.REDSTONE_BLOCK.getDefaultState());
      world.setBlockState(pos.add(39, 16, 63), Blocks.REDSTONE_BLOCK.getDefaultState());
      world.setBlockState(pos.add(40, 16, 63), Blocks.STONE.getDefaultState());
      world.setBlockState(pos.add(47, 16, 63), Blocks.STONE.getDefaultState());
      world.setBlockState(pos.add(18, 16, 64), Blocks.STONE.getDefaultState());
      world.setBlockState(pos.add(19, 16, 64), Blocks.STONE.getDefaultState());
      world.setBlockState(pos.add(28, 16, 64), Blocks.STONE.getDefaultState());
      world.setBlockState(pos.add(32, 16, 64), Blocks.REDSTONE_BLOCK.getDefaultState());
      world.setBlockState(pos.add(39, 16, 64), Blocks.REDSTONE_BLOCK.getDefaultState());
      world.setBlockState(pos.add(40, 16, 64), Blocks.STONE.getDefaultState());
      world.setBlockState(pos.add(47, 16, 64), Blocks.STONE.getDefaultState());
      world.setBlockState(pos.add(18, 16, 65), Blocks.STONE.getDefaultState());
      world.setBlockState(pos.add(19, 16, 65), Blocks.STONE.getDefaultState());
      world.setBlockState(pos.add(20, 16, 65), Blocks.STONE.getDefaultState());
      world.setBlockState(pos.add(21, 16, 65), Blocks.STONE.getDefaultState());
      world.setBlockState(pos.add(22, 16, 65), Blocks.STONE.getDefaultState());
      world.setBlockState(pos.add(23, 16, 65), Blocks.STONE.getDefaultState());
      world.setBlockState(pos.add(24, 16, 65), Blocks.STONE.getDefaultState());
return true;
  }
}
