package com.slugterra.world.greatForge;
import java.util.Random;

import net.minecraft.init.Blocks;
import net.minecraft.world.World;
public class GreatWesternForgeStructure10 {
public boolean generate(World world, Random par2Random, int xco, int yco, int zco) {
      world.setBlock(xco + 25, yco + 16, zco + 65, Blocks.stone, 0, 1);
      world.setBlock(xco + 26, yco + 16, zco + 65, Blocks.stone, 0, 1);
      world.setBlock(xco + 27, yco + 16, zco + 65, Blocks.stone, 0, 1);
      world.setBlock(xco + 28, yco + 16, zco + 65, Blocks.stone, 0, 1);
      world.setBlock(xco + 33, yco + 16, zco + 65, Blocks.redstone_block, 0, 1);
      world.setBlock(xco + 38, yco + 16, zco + 65, Blocks.redstone_block, 0, 1);
      world.setBlock(xco + 40, yco + 16, zco + 65, Blocks.stone, 0, 1);
      world.setBlock(xco + 47, yco + 16, zco + 65, Blocks.stone, 0, 1);
      world.setBlock(xco + 19, yco + 16, zco + 66, Blocks.stone, 0, 1);
      world.setBlock(xco + 20, yco + 16, zco + 66, Blocks.stone, 0, 1);
      world.setBlock(xco + 21, yco + 16, zco + 66, Blocks.stone, 0, 1);
      world.setBlock(xco + 22, yco + 16, zco + 66, Blocks.stone, 0, 1);
      world.setBlock(xco + 23, yco + 16, zco + 66, Blocks.stone, 0, 1);
      world.setBlock(xco + 24, yco + 16, zco + 66, Blocks.stone, 0, 1);
      world.setBlock(xco + 25, yco + 16, zco + 66, Blocks.stone, 0, 1);
      world.setBlock(xco + 26, yco + 16, zco + 66, Blocks.stone, 0, 1);
      world.setBlock(xco + 27, yco + 16, zco + 66, Blocks.stone, 0, 1);
      world.setBlock(xco + 28, yco + 16, zco + 66, Blocks.stone, 0, 1);
      world.setBlock(xco + 34, yco + 16, zco + 66, Blocks.redstone_block, 0, 1);
      world.setBlock(xco + 35, yco + 16, zco + 66, Blocks.redstone_block, 0, 1);
      world.setBlock(xco + 36, yco + 16, zco + 66, Blocks.redstone_block, 0, 1);
      world.setBlock(xco + 37, yco + 16, zco + 66, Blocks.redstone_block, 0, 1);
      world.setBlock(xco + 41, yco + 16, zco + 66, Blocks.stone, 0, 1);
      world.setBlock(xco + 46, yco + 16, zco + 66, Blocks.stone, 0, 1);
      world.setBlock(xco + 42, yco + 16, zco + 67, Blocks.stone, 0, 1);
      world.setBlock(xco + 43, yco + 16, zco + 67, Blocks.stone, 0, 1);
      world.setBlock(xco + 44, yco + 16, zco + 67, Blocks.stone, 0, 1);
      world.setBlock(xco + 45, yco + 16, zco + 67, Blocks.stone, 0, 1);
      world.setBlock(xco + 26, yco + 17, zco + 36, Blocks.quartz_block, 0, 1);
      world.setBlock(xco + 17, yco + 17, zco + 37, Blocks.stained_hardened_clay, 4, 1);
      world.setBlock(xco + 18, yco + 17, zco + 37, Blocks.stained_hardened_clay, 4, 1);
      world.setBlock(xco + 22, yco + 17, zco + 37, Blocks.quartz_stairs, 0, 1);
      world.setBlock(xco + 23, yco + 17, zco + 37, Blocks.stained_hardened_clay, 4, 1);
      world.setBlock(xco + 24, yco + 17, zco + 37, Blocks.stained_hardened_clay, 4, 1);
      world.setBlock(xco + 25, yco + 17, zco + 37, Blocks.quartz_block, 0, 1);
      world.setBlock(xco + 27, yco + 17, zco + 37, Blocks.quartz_block, 0, 1);
      world.setBlock(xco + 28, yco + 17, zco + 37, Blocks.stained_hardened_clay, 4, 1);
      world.setBlock(xco + 29, yco + 17, zco + 37, Blocks.stained_hardened_clay, 4, 1);
      world.setBlock(xco + 34, yco + 17, zco + 37, Blocks.stained_hardened_clay, 4, 1);
      world.setBlock(xco + 35, yco + 17, zco + 37, Blocks.stained_hardened_clay, 4, 1);
      world.setBlock(xco + 17, yco + 17, zco + 38, Blocks.stained_hardened_clay, 4, 1);
      world.setBlock(xco + 18, yco + 17, zco + 38, Blocks.stained_hardened_clay, 4, 1);
      world.setBlock(xco + 19, yco + 17, zco + 38, Blocks.stained_hardened_clay, 7, 1);
      world.setBlock(xco + 20, yco + 17, zco + 38, Blocks.stained_hardened_clay, 7, 1);
      world.setBlock(xco + 22, yco + 17, zco + 38, Blocks.quartz_stairs, 0, 1);
      world.setBlock(xco + 23, yco + 17, zco + 38, Blocks.stained_hardened_clay, 4, 1);
      world.setBlock(xco + 29, yco + 17, zco + 38, Blocks.stained_hardened_clay, 4, 1);
      world.setBlock(xco + 30, yco + 17, zco + 38, Blocks.quartz_stairs, 1, 1);
      world.setBlock(xco + 32, yco + 17, zco + 38, Blocks.stained_hardened_clay, 7, 1);
      world.setBlock(xco + 33, yco + 17, zco + 38, Blocks.stained_hardened_clay, 7, 1);
      world.setBlock(xco + 34, yco + 17, zco + 38, Blocks.stained_hardened_clay, 4, 1);
      world.setBlock(xco + 35, yco + 17, zco + 38, Blocks.stained_hardened_clay, 4, 1);
      world.setBlock(xco + 17, yco + 17, zco + 39, Blocks.stained_hardened_clay, 4, 1);
      world.setBlock(xco + 20, yco + 17, zco + 39, Blocks.stained_hardened_clay, 4, 1);
      world.setBlock(xco + 22, yco + 17, zco + 39, Blocks.quartz_stairs, 0, 1);
      world.setBlock(xco + 23, yco + 17, zco + 39, Blocks.stained_hardened_clay, 4, 1);
      world.setBlock(xco + 29, yco + 17, zco + 39, Blocks.stained_hardened_clay, 4, 1);
      world.setBlock(xco + 30, yco + 17, zco + 39, Blocks.quartz_stairs, 1, 1);
      world.setBlock(xco + 32, yco + 17, zco + 39, Blocks.stained_hardened_clay, 4, 1);
      world.setBlock(xco + 35, yco + 17, zco + 39, Blocks.stained_hardened_clay, 4, 1);
      world.setBlock(xco + 4, yco + 17, zco + 40, Blocks.diamond_block, 0, 1);
      world.setBlock(xco + 5, yco + 17, zco + 40, Blocks.diamond_block, 0, 1);
      world.setBlock(xco + 6, yco + 17, zco + 40, Blocks.stained_glass, 11, 1);
      world.setBlock(xco + 7, yco + 17, zco + 40, Blocks.diamond_block, 0, 1);
      world.setBlock(xco + 8, yco + 17, zco + 40, Blocks.diamond_block, 0, 1);
      world.setBlock(xco + 17, yco + 17, zco + 40, Blocks.stained_hardened_clay, 4, 1);
      world.setBlock(xco + 20, yco + 17, zco + 40, Blocks.stained_hardened_clay, 4, 1);
      world.setBlock(xco + 22, yco + 17, zco + 40, Blocks.quartz_stairs, 0, 1);
      world.setBlock(xco + 23, yco + 17, zco + 40, Blocks.stained_hardened_clay, 4, 1);
      world.setBlock(xco + 29, yco + 17, zco + 40, Blocks.stained_hardened_clay, 4, 1);
      world.setBlock(xco + 30, yco + 17, zco + 40, Blocks.quartz_stairs, 1, 1);
      world.setBlock(xco + 32, yco + 17, zco + 40, Blocks.stained_hardened_clay, 4, 1);
      world.setBlock(xco + 34, yco + 17, zco + 40, Blocks.stained_hardened_clay, 4, 1);
      world.setBlock(xco + 35, yco + 17, zco + 40, Blocks.stained_hardened_clay, 4, 1);
      world.setBlock(xco + 3, yco + 17, zco + 41, Blocks.diamond_block, 0, 1);
      world.setBlock(xco + 4, yco + 17, zco + 41, Blocks.diamond_block, 0, 1);
      world.setBlock(xco + 5, yco + 17, zco + 41, Blocks.stone, 0, 1);
      world.setBlock(xco + 6, yco + 17, zco + 41, Blocks.glowstone, 0, 1);
      world.setBlock(xco + 7, yco + 17, zco + 41, Blocks.stone, 0, 1);
      world.setBlock(xco + 8, yco + 17, zco + 41, Blocks.diamond_block, 0, 1);
      world.setBlock(xco + 9, yco + 17, zco + 41, Blocks.diamond_block, 0, 1);
      world.setBlock(xco + 18, yco + 17, zco + 41, Blocks.quartz_block, 0, 1);
      world.setBlock(xco + 20, yco + 17, zco + 41, Blocks.quartz_block, 0, 1);
      world.setBlock(xco + 22, yco + 17, zco + 41, Blocks.quartz_stairs, 0, 1);
      world.setBlock(xco + 23, yco + 17, zco + 41, Blocks.stained_hardened_clay, 4, 1);
      world.setBlock(xco + 26, yco + 17, zco + 41, Blocks.stone, 0, 1);
      world.setBlock(xco + 27, yco + 17, zco + 41, Blocks.stone, 0, 1);
      world.setBlock(xco + 29, yco + 17, zco + 41, Blocks.stained_hardened_clay, 4, 1);
      world.setBlock(xco + 30, yco + 17, zco + 41, Blocks.quartz_stairs, 1, 1);
      world.setBlock(xco + 32, yco + 17, zco + 41, Blocks.quartz_block, 0, 1);
      world.setBlock(xco + 34, yco + 17, zco + 41, Blocks.quartz_block, 0, 1);
      world.setBlock(xco + 3, yco + 17, zco + 42, Blocks.diamond_block, 0, 1);
      world.setBlock(xco + 4, yco + 17, zco + 42, Blocks.stone, 0, 1);
      world.setBlock(xco + 5, yco + 17, zco + 42, Blocks.stone, 0, 1);
      world.setBlock(xco + 6, yco + 17, zco + 42, Blocks.stone, 0, 1);
      world.setBlock(xco + 7, yco + 17, zco + 42, Blocks.stone, 0, 1);
      world.setBlock(xco + 8, yco + 17, zco + 42, Blocks.stone, 0, 1);
      world.setBlock(xco + 9, yco + 17, zco + 42, Blocks.diamond_block, 0, 1);
      world.setBlock(xco + 18, yco + 17, zco + 42, Blocks.quartz_block, 0, 1);
      world.setBlock(xco + 20, yco + 17, zco + 42, Blocks.quartz_block, 0, 1);
      world.setBlock(xco + 22, yco + 17, zco + 42, Blocks.quartz_stairs, 0, 1);
      world.setBlock(xco + 23, yco + 17, zco + 42, Blocks.stained_hardened_clay, 4, 1);
      world.setBlock(xco + 26, yco + 17, zco + 42, Blocks.stone, 0, 1);
      world.setBlock(xco + 27, yco + 17, zco + 42, Blocks.stone, 0, 1);
      world.setBlock(xco + 29, yco + 17, zco + 42, Blocks.stained_hardened_clay, 4, 1);
      world.setBlock(xco + 30, yco + 17, zco + 42, Blocks.quartz_stairs, 1, 1);
      world.setBlock(xco + 32, yco + 17, zco + 42, Blocks.quartz_block, 0, 1);
      world.setBlock(xco + 34, yco + 17, zco + 42, Blocks.quartz_block, 0, 1);
      world.setBlock(xco + 3, yco + 17, zco + 43, Blocks.stained_glass, 11, 1);
      world.setBlock(xco + 4, yco + 17, zco + 43, Blocks.glowstone, 0, 1);
      world.setBlock(xco + 5, yco + 17, zco + 43, Blocks.stone, 0, 1);
      world.setBlock(xco + 6, yco + 17, zco + 43, Blocks.stone, 0, 1);
      world.setBlock(xco + 7, yco + 17, zco + 43, Blocks.stone, 0, 1);
      world.setBlock(xco + 8, yco + 17, zco + 43, Blocks.glowstone, 0, 1);
      world.setBlock(xco + 9, yco + 17, zco + 43, Blocks.stained_glass, 11, 1);
      world.setBlock(xco + 17, yco + 17, zco + 43, Blocks.stained_hardened_clay, 4, 1);
      world.setBlock(xco + 20, yco + 17, zco + 43, Blocks.stained_hardened_clay, 4, 1);
      world.setBlock(xco + 22, yco + 17, zco + 43, Blocks.quartz_stairs, 0, 1);
      world.setBlock(xco + 23, yco + 17, zco + 43, Blocks.stained_hardened_clay, 4, 1);
      world.setBlock(xco + 29, yco + 17, zco + 43, Blocks.stained_hardened_clay, 4, 1);
      world.setBlock(xco + 30, yco + 17, zco + 43, Blocks.quartz_stairs, 1, 1);
      world.setBlock(xco + 32, yco + 17, zco + 43, Blocks.stained_hardened_clay, 4, 1);
      world.setBlock(xco + 35, yco + 17, zco + 43, Blocks.stained_hardened_clay, 4, 1);
      world.setBlock(xco + 3, yco + 17, zco + 44, Blocks.diamond_block, 0, 1);
      world.setBlock(xco + 4, yco + 17, zco + 44, Blocks.stone, 0, 1);
      world.setBlock(xco + 5, yco + 17, zco + 44, Blocks.stone, 0, 1);
      world.setBlock(xco + 6, yco + 17, zco + 44, Blocks.stone, 0, 1);
      world.setBlock(xco + 7, yco + 17, zco + 44, Blocks.stone, 0, 1);
      world.setBlock(xco + 8, yco + 17, zco + 44, Blocks.stone, 0, 1);
      world.setBlock(xco + 9, yco + 17, zco + 44, Blocks.diamond_block, 0, 1);
      world.setBlock(xco + 17, yco + 17, zco + 44, Blocks.stained_hardened_clay, 4, 1);
      world.setBlock(xco + 20, yco + 17, zco + 44, Blocks.stained_hardened_clay, 4, 1);
      world.setBlock(xco + 22, yco + 17, zco + 44, Blocks.quartz_stairs, 0, 1);
      world.setBlock(xco + 23, yco + 17, zco + 44, Blocks.stained_hardened_clay, 4, 1);
      world.setBlock(xco + 29, yco + 17, zco + 44, Blocks.stained_hardened_clay, 4, 1);
      world.setBlock(xco + 30, yco + 17, zco + 44, Blocks.quartz_stairs, 1, 1);
      world.setBlock(xco + 32, yco + 17, zco + 44, Blocks.stained_hardened_clay, 4, 1);
      world.setBlock(xco + 35, yco + 17, zco + 44, Blocks.stained_hardened_clay, 4, 1);
      world.setBlock(xco + 3, yco + 17, zco + 45, Blocks.diamond_block, 0, 1);
      world.setBlock(xco + 4, yco + 17, zco + 45, Blocks.diamond_block, 0, 1);
      world.setBlock(xco + 5, yco + 17, zco + 45, Blocks.stone, 0, 1);
      world.setBlock(xco + 6, yco + 17, zco + 45, Blocks.glowstone, 0, 1);
      world.setBlock(xco + 7, yco + 17, zco + 45, Blocks.stone, 0, 1);
      world.setBlock(xco + 8, yco + 17, zco + 45, Blocks.diamond_block, 0, 1);
      world.setBlock(xco + 9, yco + 17, zco + 45, Blocks.diamond_block, 0, 1);
      world.setBlock(xco + 17, yco + 17, zco + 45, Blocks.stained_hardened_clay, 4, 1);
      world.setBlock(xco + 20, yco + 17, zco + 45, Blocks.stained_hardened_clay, 4, 1);
      world.setBlock(xco + 22, yco + 17, zco + 45, Blocks.quartz_stairs, 0, 1);
      world.setBlock(xco + 23, yco + 17, zco + 45, Blocks.stained_hardened_clay, 4, 1);
      world.setBlock(xco + 29, yco + 17, zco + 45, Blocks.stained_hardened_clay, 4, 1);
      world.setBlock(xco + 30, yco + 17, zco + 45, Blocks.quartz_stairs, 1, 1);
      world.setBlock(xco + 32, yco + 17, zco + 45, Blocks.stained_hardened_clay, 4, 1);
      world.setBlock(xco + 35, yco + 17, zco + 45, Blocks.stained_hardened_clay, 4, 1);
      world.setBlock(xco + 4, yco + 17, zco + 46, Blocks.diamond_block, 0, 1);
      world.setBlock(xco + 5, yco + 17, zco + 46, Blocks.diamond_block, 0, 1);
      world.setBlock(xco + 6, yco + 17, zco + 46, Blocks.stained_glass, 11, 1);
      world.setBlock(xco + 7, yco + 17, zco + 46, Blocks.diamond_block, 0, 1);
      world.setBlock(xco + 8, yco + 17, zco + 46, Blocks.diamond_block, 0, 1);
      world.setBlock(xco + 18, yco + 17, zco + 46, Blocks.quartz_block, 0, 1);
      world.setBlock(xco + 19, yco + 17, zco + 46, Blocks.quartz_block, 0, 1);
      world.setBlock(xco + 20, yco + 17, zco + 46, Blocks.quartz_block, 0, 1);
      world.setBlock(xco + 22, yco + 17, zco + 46, Blocks.quartz_stairs, 0, 1);
      world.setBlock(xco + 23, yco + 17, zco + 46, Blocks.stained_hardened_clay, 4, 1);
      world.setBlock(xco + 25, yco + 17, zco + 46, Blocks.stone, 0, 1);
      world.setBlock(xco + 26, yco + 17, zco + 46, Blocks.stone, 0, 1);
      world.setBlock(xco + 29, yco + 17, zco + 46, Blocks.stained_hardened_clay, 4, 1);
      world.setBlock(xco + 30, yco + 17, zco + 46, Blocks.quartz_stairs, 1, 1);
      world.setBlock(xco + 32, yco + 17, zco + 46, Blocks.quartz_block, 0, 1);
      world.setBlock(xco + 34, yco + 17, zco + 46, Blocks.quartz_block, 0, 1);
      world.setBlock(xco + 18, yco + 17, zco + 47, Blocks.quartz_block, 0, 1);
      world.setBlock(xco + 19, yco + 17, zco + 47, Blocks.quartz_block, 0, 1);
      world.setBlock(xco + 20, yco + 17, zco + 47, Blocks.quartz_block, 0, 1);
      world.setBlock(xco + 22, yco + 17, zco + 47, Blocks.quartz_stairs, 0, 1);
      world.setBlock(xco + 23, yco + 17, zco + 47, Blocks.stained_hardened_clay, 4, 1);
      world.setBlock(xco + 25, yco + 17, zco + 47, Blocks.stone, 0, 1);
      world.setBlock(xco + 26, yco + 17, zco + 47, Blocks.stone, 0, 1);
      world.setBlock(xco + 29, yco + 17, zco + 47, Blocks.stained_hardened_clay, 4, 1);
      world.setBlock(xco + 30, yco + 17, zco + 47, Blocks.quartz_stairs, 1, 1);
      world.setBlock(xco + 32, yco + 17, zco + 47, Blocks.quartz_block, 0, 1);
      world.setBlock(xco + 34, yco + 17, zco + 47, Blocks.quartz_block, 0, 1);
      world.setBlock(xco + 17, yco + 17, zco + 48, Blocks.stained_hardened_clay, 4, 1);
      world.setBlock(xco + 20, yco + 17, zco + 48, Blocks.stained_hardened_clay, 4, 1);
      world.setBlock(xco + 22, yco + 17, zco + 48, Blocks.quartz_stairs, 0, 1);
      world.setBlock(xco + 23, yco + 17, zco + 48, Blocks.stained_hardened_clay, 4, 1);
      world.setBlock(xco + 29, yco + 17, zco + 48, Blocks.stained_hardened_clay, 4, 1);
      world.setBlock(xco + 30, yco + 17, zco + 48, Blocks.quartz_stairs, 1, 1);
      world.setBlock(xco + 32, yco + 17, zco + 48, Blocks.stained_hardened_clay, 4, 1);
      world.setBlock(xco + 35, yco + 17, zco + 48, Blocks.stained_hardened_clay, 4, 1);
      world.setBlock(xco + 17, yco + 17, zco + 49, Blocks.stained_hardened_clay, 4, 1);
      world.setBlock(xco + 20, yco + 17, zco + 49, Blocks.stained_hardened_clay, 4, 1);
      world.setBlock(xco + 22, yco + 17, zco + 49, Blocks.quartz_stairs, 0, 1);
      world.setBlock(xco + 23, yco + 17, zco + 49, Blocks.stained_hardened_clay, 4, 1);
      world.setBlock(xco + 29, yco + 17, zco + 49, Blocks.stained_hardened_clay, 4, 1);
      world.setBlock(xco + 30, yco + 17, zco + 49, Blocks.quartz_stairs, 1, 1);
      world.setBlock(xco + 32, yco + 17, zco + 49, Blocks.stained_hardened_clay, 4, 1);
      world.setBlock(xco + 35, yco + 17, zco + 49, Blocks.stained_hardened_clay, 4, 1);
      world.setBlock(xco + 17, yco + 17, zco + 50, Blocks.stained_hardened_clay, 4, 1);
      world.setBlock(xco + 18, yco + 17, zco + 50, Blocks.stained_hardened_clay, 4, 1);
      world.setBlock(xco + 19, yco + 17, zco + 50, Blocks.stained_hardened_clay, 4, 1);
      world.setBlock(xco + 20, yco + 17, zco + 50, Blocks.stained_hardened_clay, 4, 1);
      world.setBlock(xco + 21, yco + 17, zco + 50, Blocks.stained_hardened_clay, 4, 1);
      world.setBlock(xco + 22, yco + 17, zco + 50, Blocks.quartz_stairs, 0, 1);
      world.setBlock(xco + 23, yco + 17, zco + 50, Blocks.stained_hardened_clay, 4, 1);
      world.setBlock(xco + 29, yco + 17, zco + 50, Blocks.stained_hardened_clay, 4, 1);
      world.setBlock(xco + 30, yco + 17, zco + 50, Blocks.quartz_stairs, 1, 1);
      world.setBlock(xco + 32, yco + 17, zco + 50, Blocks.stained_hardened_clay, 4, 1);
      world.setBlock(xco + 33, yco + 17, zco + 50, Blocks.stained_hardened_clay, 4, 1);
      world.setBlock(xco + 34, yco + 17, zco + 50, Blocks.stained_hardened_clay, 4, 1);
      world.setBlock(xco + 35, yco + 17, zco + 50, Blocks.stained_hardened_clay, 4, 1);
      world.setBlock(xco + 18, yco + 17, zco + 51, Blocks.stained_hardened_clay, 4, 1);
      world.setBlock(xco + 19, yco + 17, zco + 51, Blocks.stained_hardened_clay, 4, 1);
      world.setBlock(xco + 20, yco + 17, zco + 51, Blocks.stained_hardened_clay, 4, 1);
      world.setBlock(xco + 21, yco + 17, zco + 51, Blocks.stained_hardened_clay, 4, 1);
      world.setBlock(xco + 23, yco + 17, zco + 51, Blocks.stained_hardened_clay, 4, 1);
      world.setBlock(xco + 24, yco + 17, zco + 51, Blocks.stained_hardened_clay, 4, 1);
      world.setBlock(xco + 25, yco + 17, zco + 51, Blocks.stained_hardened_clay, 4, 1);
      world.setBlock(xco + 26, yco + 17, zco + 51, Blocks.stained_hardened_clay, 4, 1);
      world.setBlock(xco + 27, yco + 17, zco + 51, Blocks.stained_hardened_clay, 4, 1);
      world.setBlock(xco + 28, yco + 17, zco + 51, Blocks.stained_hardened_clay, 4, 1);
      world.setBlock(xco + 29, yco + 17, zco + 51, Blocks.stained_hardened_clay, 4, 1);
      world.setBlock(xco + 30, yco + 17, zco + 51, Blocks.stained_hardened_clay, 4, 1);
      world.setBlock(xco + 31, yco + 17, zco + 51, Blocks.stained_hardened_clay, 4, 1);
      world.setBlock(xco + 32, yco + 17, zco + 51, Blocks.stained_hardened_clay, 4, 1);
      world.setBlock(xco + 33, yco + 17, zco + 51, Blocks.stained_hardened_clay, 4, 1);
      world.setBlock(xco + 34, yco + 17, zco + 51, Blocks.stained_hardened_clay, 4, 1);
      world.setBlock(xco + 17, yco + 17, zco + 52, Blocks.stained_hardened_clay, 4, 1);
      world.setBlock(xco + 18, yco + 17, zco + 52, Blocks.stained_hardened_clay, 4, 1);
      world.setBlock(xco + 22, yco + 17, zco + 52, Blocks.stained_hardened_clay, 4, 1);
      world.setBlock(xco + 23, yco + 17, zco + 52, Blocks.stone, 4, 1);
      world.setBlock(xco + 24, yco + 17, zco + 52, Blocks.stone, 4, 1);
      world.setBlock(xco + 25, yco + 17, zco + 52, Blocks.stone, 4, 1);
      world.setBlock(xco + 27, yco + 17, zco + 52, Blocks.stone, 4, 1);
      world.setBlock(xco + 28, yco + 17, zco + 52, Blocks.stone, 4, 1);
      world.setBlock(xco + 29, yco + 17, zco + 52, Blocks.stained_hardened_clay, 4, 1);
      world.setBlock(xco + 30, yco + 17, zco + 52, Blocks.stained_hardened_clay, 4, 1);
      world.setBlock(xco + 34, yco + 17, zco + 52, Blocks.stained_hardened_clay, 4, 1);
      world.setBlock(xco + 35, yco + 17, zco + 52, Blocks.stained_hardened_clay, 4, 1);
      world.setBlock(xco + 16, yco + 17, zco + 53, Blocks.stained_hardened_clay, 4, 1);
      world.setBlock(xco + 17, yco + 17, zco + 53, Blocks.stained_hardened_clay, 4, 1);
      world.setBlock(xco + 23, yco + 17, zco + 53, Blocks.stained_hardened_clay, 4, 1);
      world.setBlock(xco + 24, yco + 17, zco + 53, Blocks.stained_hardened_clay, 4, 1);
      world.setBlock(xco + 25, yco + 17, zco + 53, Blocks.stone, 4, 1);
      world.setBlock(xco + 27, yco + 17, zco + 53, Blocks.stone, 4, 1);
      world.setBlock(xco + 28, yco + 17, zco + 53, Blocks.stained_hardened_clay, 4, 1);
      world.setBlock(xco + 29, yco + 17, zco + 53, Blocks.stained_hardened_clay, 4, 1);
      world.setBlock(xco + 35, yco + 17, zco + 53, Blocks.stained_hardened_clay, 4, 1);
      world.setBlock(xco + 36, yco + 17, zco + 53, Blocks.stained_hardened_clay, 4, 1);
      world.setBlock(xco + 16, yco + 17, zco + 54, Blocks.stained_hardened_clay, 4, 1);
      world.setBlock(xco + 17, yco + 17, zco + 54, Blocks.stained_hardened_clay, 4, 1);
      world.setBlock(xco + 23, yco + 17, zco + 54, Blocks.stained_hardened_clay, 4, 1);
      world.setBlock(xco + 24, yco + 17, zco + 54, Blocks.stained_hardened_clay, 4, 1);
      world.setBlock(xco + 25, yco + 17, zco + 54, Blocks.stone, 4, 1);
      world.setBlock(xco + 27, yco + 17, zco + 54, Blocks.stone, 4, 1);
      world.setBlock(xco + 28, yco + 17, zco + 54, Blocks.stained_hardened_clay, 4, 1);
      world.setBlock(xco + 29, yco + 17, zco + 54, Blocks.stained_hardened_clay, 4, 1);
      world.setBlock(xco + 35, yco + 17, zco + 54, Blocks.stained_hardened_clay, 4, 1);
      world.setBlock(xco + 36, yco + 17, zco + 54, Blocks.stained_hardened_clay, 4, 1);
      world.setBlock(xco + 16, yco + 17, zco + 55, Blocks.stained_hardened_clay, 4, 1);
      world.setBlock(xco + 17, yco + 17, zco + 55, Blocks.stained_hardened_clay, 4, 1);
      world.setBlock(xco + 23, yco + 17, zco + 55, Blocks.stained_hardened_clay, 4, 1);
      world.setBlock(xco + 24, yco + 17, zco + 55, Blocks.stained_hardened_clay, 4, 1);
      world.setBlock(xco + 25, yco + 17, zco + 55, Blocks.stone, 4, 1);
      world.setBlock(xco + 27, yco + 17, zco + 55, Blocks.stone, 4, 1);
      world.setBlock(xco + 28, yco + 17, zco + 55, Blocks.stained_hardened_clay, 4, 1);
      world.setBlock(xco + 29, yco + 17, zco + 55, Blocks.stained_hardened_clay, 4, 1);
      world.setBlock(xco + 35, yco + 17, zco + 55, Blocks.stained_hardened_clay, 4, 1);
      world.setBlock(xco + 36, yco + 17, zco + 55, Blocks.stained_hardened_clay, 4, 1);
      world.setBlock(xco + 37, yco + 17, zco + 55, Blocks.stained_hardened_clay, 4, 1);
      world.setBlock(xco + 17, yco + 17, zco + 56, Blocks.stained_hardened_clay, 4, 1);
      world.setBlock(xco + 18, yco + 17, zco + 56, Blocks.stained_hardened_clay, 4, 1);
      world.setBlock(xco + 22, yco + 17, zco + 56, Blocks.stained_hardened_clay, 4, 1);
      world.setBlock(xco + 23, yco + 17, zco + 56, Blocks.stained_hardened_clay, 4, 1);
      world.setBlock(xco + 25, yco + 17, zco + 56, Blocks.stone, 4, 1);
      world.setBlock(xco + 27, yco + 17, zco + 56, Blocks.stone, 4, 1);
      world.setBlock(xco + 29, yco + 17, zco + 56, Blocks.stained_hardened_clay, 4, 1);
      world.setBlock(xco + 30, yco + 17, zco + 56, Blocks.stained_hardened_clay, 4, 1);
      world.setBlock(xco + 34, yco + 17, zco + 56, Blocks.stained_hardened_clay, 4, 1);
      world.setBlock(xco + 35, yco + 17, zco + 56, Blocks.stained_hardened_clay, 4, 1);
      world.setBlock(xco + 38, yco + 17, zco + 56, Blocks.stained_hardened_clay, 4, 1);
      world.setBlock(xco + 39, yco + 17, zco + 56, Blocks.wool, 15, 1);
      world.setBlock(xco + 40, yco + 17, zco + 56, Blocks.wool, 15, 1);
      world.setBlock(xco + 18, yco + 17, zco + 57, Blocks.stained_hardened_clay, 4, 1);
      world.setBlock(xco + 19, yco + 17, zco + 57, Blocks.stained_hardened_clay, 4, 1);
      world.setBlock(xco + 20, yco + 17, zco + 57, Blocks.stained_hardened_clay, 4, 1);
      world.setBlock(xco + 21, yco + 17, zco + 57, Blocks.stained_hardened_clay, 4, 1);
      world.setBlock(xco + 22, yco + 17, zco + 57, Blocks.stained_hardened_clay, 4, 1);
      world.setBlock(xco + 25, yco + 17, zco + 57, Blocks.stone, 0, 1);
      world.setBlock(xco + 27, yco + 17, zco + 57, Blocks.stone, 0, 1);
      world.setBlock(xco + 30, yco + 17, zco + 57, Blocks.stained_hardened_clay, 4, 1);
      world.setBlock(xco + 31, yco + 17, zco + 57, Blocks.stained_hardened_clay, 4, 1);
      world.setBlock(xco + 32, yco + 17, zco + 57, Blocks.stained_hardened_clay, 4, 1);
      world.setBlock(xco + 33, yco + 17, zco + 57, Blocks.stained_hardened_clay, 4, 1);
      world.setBlock(xco + 34, yco + 17, zco + 57, Blocks.stained_hardened_clay, 4, 1);
      world.setBlock(xco + 39, yco + 17, zco + 57, Blocks.stained_hardened_clay, 4, 1);
      world.setBlock(xco + 41, yco + 17, zco + 57, Blocks.wool, 15, 1);
      world.setBlock(xco + 19, yco + 17, zco + 58, Blocks.stained_hardened_clay, 4, 1);
      world.setBlock(xco + 20, yco + 17, zco + 58, Blocks.stained_hardened_clay, 4, 1);
      world.setBlock(xco + 21, yco + 17, zco + 58, Blocks.stained_hardened_clay, 4, 1);
      world.setBlock(xco + 25, yco + 17, zco + 58, Blocks.stone, 0, 1);
      world.setBlock(xco + 27, yco + 17, zco + 58, Blocks.stone, 0, 1);
      world.setBlock(xco + 31, yco + 17, zco + 58, Blocks.stained_hardened_clay, 4, 1);
      world.setBlock(xco + 32, yco + 17, zco + 58, Blocks.stained_hardened_clay, 4, 1);
      world.setBlock(xco + 33, yco + 17, zco + 58, Blocks.stained_hardened_clay, 4, 1);
      world.setBlock(xco + 40, yco + 17, zco + 58, Blocks.stained_hardened_clay, 4, 1);
      world.setBlock(xco + 42, yco + 17, zco + 58, Blocks.wool, 15, 1);
      world.setBlock(xco + 25, yco + 17, zco + 59, Blocks.stone, 0, 1);
      world.setBlock(xco + 27, yco + 17, zco + 59, Blocks.stone, 0, 1);
      world.setBlock(xco + 34, yco + 17, zco + 59, Blocks.wool, 15, 1);
      world.setBlock(xco + 35, yco + 17, zco + 59, Blocks.wool, 15, 1);
      world.setBlock(xco + 36, yco + 17, zco + 59, Blocks.wool, 15, 1);
      world.setBlock(xco + 37, yco + 17, zco + 59, Blocks.wool, 15, 1);
      world.setBlock(xco + 41, yco + 17, zco + 59, Blocks.stained_hardened_clay, 4, 1);
      world.setBlock(xco + 42, yco + 17, zco + 59, Blocks.wool, 15, 1);
      world.setBlock(xco + 24, yco + 17, zco + 60, Blocks.stone, 0, 1);
      world.setBlock(xco + 25, yco + 17, zco + 60, Blocks.stone, 0, 1);
      world.setBlock(xco + 27, yco + 17, zco + 60, Blocks.stone, 0, 1);
      world.setBlock(xco + 33, yco + 17, zco + 60, Blocks.wool, 15, 1);
      world.setBlock(xco + 38, yco + 17, zco + 60, Blocks.wool, 15, 1);
      world.setBlock(xco + 42, yco + 17, zco + 60, Blocks.stone, 0, 1);
      world.setBlock(xco + 43, yco + 17, zco + 60, Blocks.stone, 0, 1);
      world.setBlock(xco + 44, yco + 17, zco + 60, Blocks.stone, 0, 1);
      world.setBlock(xco + 45, yco + 17, zco + 60, Blocks.stone, 0, 1);
      world.setBlock(xco + 20, yco + 17, zco + 61, Blocks.stone, 0, 1);
      world.setBlock(xco + 21, yco + 17, zco + 61, Blocks.stone, 0, 1);
      world.setBlock(xco + 22, yco + 17, zco + 61, Blocks.stone, 0, 1);
      world.setBlock(xco + 23, yco + 17, zco + 61, Blocks.stone, 0, 1);
      world.setBlock(xco + 24, yco + 17, zco + 61, Blocks.stone, 0, 1);
      world.setBlock(xco + 28, yco + 17, zco + 61, Blocks.stone, 0, 1);
      world.setBlock(xco + 32, yco + 17, zco + 61, Blocks.wool, 15, 1);
      world.setBlock(xco + 39, yco + 17, zco + 61, Blocks.wool, 15, 1);
      world.setBlock(xco + 41, yco + 17, zco + 61, Blocks.stone, 0, 1);
      world.setBlock(xco + 46, yco + 17, zco + 61, Blocks.stone, 0, 1);
      world.setBlock(xco + 18, yco + 17, zco + 62, Blocks.stone, 0, 1);
      world.setBlock(xco + 19, yco + 17, zco + 62, Blocks.stone, 0, 1);
      world.setBlock(xco + 28, yco + 17, zco + 62, Blocks.stone, 0, 1);
      world.setBlock(xco + 32, yco + 17, zco + 62, Blocks.wool, 15, 1);
      world.setBlock(xco + 39, yco + 17, zco + 62, Blocks.wool, 15, 1);
      world.setBlock(xco + 40, yco + 17, zco + 62, Blocks.stone, 0, 1);
      world.setBlock(xco + 47, yco + 17, zco + 62, Blocks.stone, 0, 1);
      world.setBlock(xco + 18, yco + 17, zco + 63, Blocks.stone, 0, 1);
      world.setBlock(xco + 19, yco + 17, zco + 63, Blocks.stone, 0, 1);
      world.setBlock(xco + 28, yco + 17, zco + 63, Blocks.stone, 0, 1);
      world.setBlock(xco + 32, yco + 17, zco + 63, Blocks.wool, 15, 1);
      world.setBlock(xco + 39, yco + 17, zco + 63, Blocks.wool, 15, 1);
      world.setBlock(xco + 40, yco + 17, zco + 63, Blocks.stone, 0, 1);
      world.setBlock(xco + 47, yco + 17, zco + 63, Blocks.stone, 0, 1);
      world.setBlock(xco + 20, yco + 17, zco + 64, Blocks.stone, 0, 1);
      world.setBlock(xco + 21, yco + 17, zco + 64, Blocks.stone, 0, 1);
      world.setBlock(xco + 22, yco + 17, zco + 64, Blocks.stone, 0, 1);
      world.setBlock(xco + 23, yco + 17, zco + 64, Blocks.stone, 0, 1);
      world.setBlock(xco + 24, yco + 17, zco + 64, Blocks.stone, 0, 1);
      world.setBlock(xco + 25, yco + 17, zco + 64, Blocks.stone, 0, 1);
      world.setBlock(xco + 26, yco + 17, zco + 64, Blocks.stone, 0, 1);
      world.setBlock(xco + 27, yco + 17, zco + 64, Blocks.stone, 0, 1);
      world.setBlock(xco + 28, yco + 17, zco + 64, Blocks.stone, 0, 1);
      world.setBlock(xco + 32, yco + 17, zco + 64, Blocks.wool, 15, 1);
      world.setBlock(xco + 39, yco + 17, zco + 64, Blocks.wool, 15, 1);
      world.setBlock(xco + 40, yco + 17, zco + 64, Blocks.stone, 0, 1);
      world.setBlock(xco + 47, yco + 17, zco + 64, Blocks.stone, 0, 1);
      world.setBlock(xco + 33, yco + 17, zco + 65, Blocks.wool, 15, 1);
      world.setBlock(xco + 38, yco + 17, zco + 65, Blocks.wool, 15, 1);
      world.setBlock(xco + 40, yco + 17, zco + 65, Blocks.stone, 0, 1);
      world.setBlock(xco + 47, yco + 17, zco + 65, Blocks.stone, 0, 1);
      world.setBlock(xco + 34, yco + 17, zco + 66, Blocks.wool, 15, 1);
      world.setBlock(xco + 35, yco + 17, zco + 66, Blocks.wool, 15, 1);
      world.setBlock(xco + 36, yco + 17, zco + 66, Blocks.wool, 15, 1);
      world.setBlock(xco + 37, yco + 17, zco + 66, Blocks.wool, 15, 1);
      world.setBlock(xco + 41, yco + 17, zco + 66, Blocks.stone, 0, 1);
      world.setBlock(xco + 46, yco + 17, zco + 66, Blocks.stone, 0, 1);
      world.setBlock(xco + 42, yco + 17, zco + 67, Blocks.stone, 0, 1);
      world.setBlock(xco + 43, yco + 17, zco + 67, Blocks.stone, 0, 1);
      world.setBlock(xco + 44, yco + 17, zco + 67, Blocks.stone, 0, 1);
      world.setBlock(xco + 45, yco + 17, zco + 67, Blocks.stone, 0, 1);
      world.setBlock(xco + 17, yco + 18, zco + 37, Blocks.stained_hardened_clay, 4, 1);
      world.setBlock(xco + 18, yco + 18, zco + 37, Blocks.stained_hardened_clay, 4, 1);
      world.setBlock(xco + 23, yco + 18, zco + 37, Blocks.stained_hardened_clay, 4, 1);
      world.setBlock(xco + 24, yco + 18, zco + 37, Blocks.stained_hardened_clay, 4, 1);
      world.setBlock(xco + 25, yco + 18, zco + 37, Blocks.stained_hardened_clay, 4, 1);
      world.setBlock(xco + 26, yco + 18, zco + 37, Blocks.quartz_block, 0, 1);
      world.setBlock(xco + 27, yco + 18, zco + 37, Blocks.stained_hardened_clay, 4, 1);
      world.setBlock(xco + 28, yco + 18, zco + 37, Blocks.stained_hardened_clay, 4, 1);
      world.setBlock(xco + 29, yco + 18, zco + 37, Blocks.stained_hardened_clay, 4, 1);
      world.setBlock(xco + 34, yco + 18, zco + 37, Blocks.stained_hardened_clay, 4, 1);
      world.setBlock(xco + 35, yco + 18, zco + 37, Blocks.stained_hardened_clay, 4, 1);
      world.setBlock(xco + 17, yco + 18, zco + 38, Blocks.stained_hardened_clay, 4, 1);
      world.setBlock(xco + 18, yco + 18, zco + 38, Blocks.stained_hardened_clay, 4, 1);
      world.setBlock(xco + 19, yco + 18, zco + 38, Blocks.stained_hardened_clay, 7, 1);
      world.setBlock(xco + 20, yco + 18, zco + 38, Blocks.stained_hardened_clay, 7, 1);
      world.setBlock(xco + 23, yco + 18, zco + 38, Blocks.stained_hardened_clay, 4, 1);
      world.setBlock(xco + 29, yco + 18, zco + 38, Blocks.stained_hardened_clay, 4, 1);
      world.setBlock(xco + 32, yco + 18, zco + 38, Blocks.stained_hardened_clay, 7, 1);
      world.setBlock(xco + 33, yco + 18, zco + 38, Blocks.stained_hardened_clay, 7, 1);
      world.setBlock(xco + 34, yco + 18, zco + 38, Blocks.stained_hardened_clay, 4, 1);
      world.setBlock(xco + 35, yco + 18, zco + 38, Blocks.stained_hardened_clay, 4, 1);
      world.setBlock(xco + 17, yco + 18, zco + 39, Blocks.stained_hardened_clay, 4, 1);
      world.setBlock(xco + 20, yco + 18, zco + 39, Blocks.stained_hardened_clay, 4, 1);
      world.setBlock(xco + 23, yco + 18, zco + 39, Blocks.stained_hardened_clay, 4, 1);
      world.setBlock(xco + 29, yco + 18, zco + 39, Blocks.stained_hardened_clay, 4, 1);
      world.setBlock(xco + 32, yco + 18, zco + 39, Blocks.stained_hardened_clay, 4, 1);
      world.setBlock(xco + 35, yco + 18, zco + 39, Blocks.stained_hardened_clay, 4, 1);
      world.setBlock(xco + 17, yco + 18, zco + 40, Blocks.stained_hardened_clay, 4, 1);
      world.setBlock(xco + 20, yco + 18, zco + 40, Blocks.stained_hardened_clay, 4, 1);
      world.setBlock(xco + 23, yco + 18, zco + 40, Blocks.stained_hardened_clay, 4, 1);
      world.setBlock(xco + 29, yco + 18, zco + 40, Blocks.stained_hardened_clay, 4, 1);
      world.setBlock(xco + 32, yco + 18, zco + 40, Blocks.stained_hardened_clay, 4, 1);
      world.setBlock(xco + 34, yco + 18, zco + 40, Blocks.stained_hardened_clay, 4, 1);
      world.setBlock(xco + 35, yco + 18, zco + 40, Blocks.stained_hardened_clay, 4, 1);
      world.setBlock(xco + 5, yco + 18, zco + 41, Blocks.stone, 0, 1);
      world.setBlock(xco + 6, yco + 18, zco + 41, Blocks.stone, 0, 1);
      world.setBlock(xco + 7, yco + 18, zco + 41, Blocks.stone, 0, 1);
      world.setBlock(xco + 18, yco + 18, zco + 41, Blocks.quartz_block, 0, 1);
      world.setBlock(xco + 20, yco + 18, zco + 41, Blocks.quartz_block, 0, 1);
      world.setBlock(xco + 23, yco + 18, zco + 41, Blocks.stained_hardened_clay, 4, 1);
      world.setBlock(xco + 26, yco + 18, zco + 41, Blocks.stone, 0, 1);
      world.setBlock(xco + 27, yco + 18, zco + 41, Blocks.stone, 0, 1);
      world.setBlock(xco + 29, yco + 18, zco + 41, Blocks.stained_hardened_clay, 4, 1);
      world.setBlock(xco + 32, yco + 18, zco + 41, Blocks.quartz_block, 0, 1);
      world.setBlock(xco + 34, yco + 18, zco + 41, Blocks.quartz_block, 0, 1);
      world.setBlock(xco + 4, yco + 18, zco + 42, Blocks.stone, 0, 1);
      world.setBlock(xco + 5, yco + 18, zco + 42, Blocks.stone, 0, 1);
      world.setBlock(xco + 6, yco + 18, zco + 42, Blocks.stone, 0, 1);
      world.setBlock(xco + 7, yco + 18, zco + 42, Blocks.stone, 0, 1);
      world.setBlock(xco + 8, yco + 18, zco + 42, Blocks.stone, 0, 1);
      world.setBlock(xco + 18, yco + 18, zco + 42, Blocks.quartz_block, 0, 1);
      world.setBlock(xco + 20, yco + 18, zco + 42, Blocks.quartz_block, 0, 1);
      world.setBlock(xco + 23, yco + 18, zco + 42, Blocks.stained_hardened_clay, 4, 1);
      world.setBlock(xco + 26, yco + 18, zco + 42, Blocks.stone, 0, 1);
      world.setBlock(xco + 27, yco + 18, zco + 42, Blocks.stone, 0, 1);
      world.setBlock(xco + 29, yco + 18, zco + 42, Blocks.stained_hardened_clay, 4, 1);
      world.setBlock(xco + 32, yco + 18, zco + 42, Blocks.quartz_block, 0, 1);
      world.setBlock(xco + 34, yco + 18, zco + 42, Blocks.quartz_block, 0, 1);
      world.setBlock(xco + 4, yco + 18, zco + 43, Blocks.stone, 0, 1);
      world.setBlock(xco + 5, yco + 18, zco + 43, Blocks.stone, 0, 1);
      world.setBlock(xco + 6, yco + 18, zco + 43, Blocks.stone, 0, 1);
      world.setBlock(xco + 7, yco + 18, zco + 43, Blocks.stone, 0, 1);
      world.setBlock(xco + 8, yco + 18, zco + 43, Blocks.stone, 0, 1);
      world.setBlock(xco + 17, yco + 18, zco + 43, Blocks.stained_hardened_clay, 4, 1);
      world.setBlock(xco + 20, yco + 18, zco + 43, Blocks.stained_hardened_clay, 4, 1);
      world.setBlock(xco + 23, yco + 18, zco + 43, Blocks.stained_hardened_clay, 4, 1);
      world.setBlock(xco + 29, yco + 18, zco + 43, Blocks.stained_hardened_clay, 4, 1);
      world.setBlock(xco + 32, yco + 18, zco + 43, Blocks.stained_hardened_clay, 4, 1);
      world.setBlock(xco + 35, yco + 18, zco + 43, Blocks.stained_hardened_clay, 4, 1);
      world.setBlock(xco + 4, yco + 18, zco + 44, Blocks.stone, 0, 1);
      world.setBlock(xco + 5, yco + 18, zco + 44, Blocks.stone, 0, 1);
      world.setBlock(xco + 6, yco + 18, zco + 44, Blocks.stone, 0, 1);
      world.setBlock(xco + 7, yco + 18, zco + 44, Blocks.stone, 0, 1);
      world.setBlock(xco + 8, yco + 18, zco + 44, Blocks.stone, 0, 1);
      world.setBlock(xco + 17, yco + 18, zco + 44, Blocks.stained_hardened_clay, 4, 1);
      world.setBlock(xco + 20, yco + 18, zco + 44, Blocks.stained_hardened_clay, 4, 1);
      world.setBlock(xco + 23, yco + 18, zco + 44, Blocks.stained_hardened_clay, 4, 1);
      world.setBlock(xco + 29, yco + 18, zco + 44, Blocks.stained_hardened_clay, 4, 1);
      world.setBlock(xco + 32, yco + 18, zco + 44, Blocks.stained_hardened_clay, 4, 1);
      world.setBlock(xco + 35, yco + 18, zco + 44, Blocks.stained_hardened_clay, 4, 1);
      world.setBlock(xco + 5, yco + 18, zco + 45, Blocks.stone, 0, 1);
      world.setBlock(xco + 6, yco + 18, zco + 45, Blocks.stone, 0, 1);
      world.setBlock(xco + 7, yco + 18, zco + 45, Blocks.stone, 0, 1);
      world.setBlock(xco + 17, yco + 18, zco + 45, Blocks.stained_hardened_clay, 4, 1);
      world.setBlock(xco + 20, yco + 18, zco + 45, Blocks.stained_hardened_clay, 4, 1);
      world.setBlock(xco + 23, yco + 18, zco + 45, Blocks.stained_hardened_clay, 4, 1);
      world.setBlock(xco + 29, yco + 18, zco + 45, Blocks.stained_hardened_clay, 4, 1);
      world.setBlock(xco + 32, yco + 18, zco + 45, Blocks.stained_hardened_clay, 4, 1);
      world.setBlock(xco + 35, yco + 18, zco + 45, Blocks.stained_hardened_clay, 4, 1);
      world.setBlock(xco + 18, yco + 18, zco + 46, Blocks.quartz_block, 0, 1);
      world.setBlock(xco + 19, yco + 18, zco + 46, Blocks.quartz_block, 0, 1);
      world.setBlock(xco + 20, yco + 18, zco + 46, Blocks.quartz_block, 0, 1);
      world.setBlock(xco + 23, yco + 18, zco + 46, Blocks.stained_hardened_clay, 4, 1);
      world.setBlock(xco + 25, yco + 18, zco + 46, Blocks.stone, 0, 1);
      world.setBlock(xco + 26, yco + 18, zco + 46, Blocks.stone, 0, 1);
      world.setBlock(xco + 29, yco + 18, zco + 46, Blocks.stained_hardened_clay, 4, 1);
      world.setBlock(xco + 32, yco + 18, zco + 46, Blocks.quartz_block, 0, 1);
      world.setBlock(xco + 34, yco + 18, zco + 46, Blocks.quartz_block, 0, 1);
      world.setBlock(xco + 18, yco + 18, zco + 47, Blocks.quartz_block, 0, 1);
      world.setBlock(xco + 19, yco + 18, zco + 47, Blocks.quartz_block, 0, 1);
      world.setBlock(xco + 20, yco + 18, zco + 47, Blocks.quartz_block, 0, 1);
      world.setBlock(xco + 23, yco + 18, zco + 47, Blocks.stained_hardened_clay, 4, 1);
      world.setBlock(xco + 25, yco + 18, zco + 47, Blocks.stone, 0, 1);
      world.setBlock(xco + 26, yco + 18, zco + 47, Blocks.stone, 0, 1);
      world.setBlock(xco + 29, yco + 18, zco + 47, Blocks.stained_hardened_clay, 4, 1);
      world.setBlock(xco + 32, yco + 18, zco + 47, Blocks.quartz_block, 0, 1);
      world.setBlock(xco + 34, yco + 18, zco + 47, Blocks.quartz_block, 0, 1);
      world.setBlock(xco + 17, yco + 18, zco + 48, Blocks.stained_hardened_clay, 4, 1);
      world.setBlock(xco + 20, yco + 18, zco + 48, Blocks.stained_hardened_clay, 4, 1);
      world.setBlock(xco + 23, yco + 18, zco + 48, Blocks.stained_hardened_clay, 4, 1);
      world.setBlock(xco + 29, yco + 18, zco + 48, Blocks.stained_hardened_clay, 4, 1);
      world.setBlock(xco + 32, yco + 18, zco + 48, Blocks.stained_hardened_clay, 4, 1);
      world.setBlock(xco + 35, yco + 18, zco + 48, Blocks.stained_hardened_clay, 4, 1);
      world.setBlock(xco + 17, yco + 18, zco + 49, Blocks.stained_hardened_clay, 4, 1);
      world.setBlock(xco + 20, yco + 18, zco + 49, Blocks.stained_hardened_clay, 4, 1);
      world.setBlock(xco + 23, yco + 18, zco + 49, Blocks.stained_hardened_clay, 4, 1);
      world.setBlock(xco + 29, yco + 18, zco + 49, Blocks.stained_hardened_clay, 4, 1);
      world.setBlock(xco + 32, yco + 18, zco + 49, Blocks.stained_hardened_clay, 4, 1);
      world.setBlock(xco + 35, yco + 18, zco + 49, Blocks.stained_hardened_clay, 4, 1);
      world.setBlock(xco + 17, yco + 18, zco + 50, Blocks.stained_hardened_clay, 4, 1);
      world.setBlock(xco + 18, yco + 18, zco + 50, Blocks.stained_hardened_clay, 4, 1);
      world.setBlock(xco + 19, yco + 18, zco + 50, Blocks.stained_hardened_clay, 4, 1);
      world.setBlock(xco + 20, yco + 18, zco + 50, Blocks.stained_hardened_clay, 4, 1);
      world.setBlock(xco + 21, yco + 18, zco + 50, Blocks.stained_hardened_clay, 4, 1);
      world.setBlock(xco + 23, yco + 18, zco + 50, Blocks.stained_hardened_clay, 4, 1);
      world.setBlock(xco + 29, yco + 18, zco + 50, Blocks.stained_hardened_clay, 4, 1);
      world.setBlock(xco + 31, yco + 18, zco + 50, Blocks.stained_hardened_clay, 4, 1);
      world.setBlock(xco + 32, yco + 18, zco + 50, Blocks.stained_hardened_clay, 4, 1);
      world.setBlock(xco + 33, yco + 18, zco + 50, Blocks.stained_hardened_clay, 4, 1);
      world.setBlock(xco + 34, yco + 18, zco + 50, Blocks.stained_hardened_clay, 4, 1);
      world.setBlock(xco + 35, yco + 18, zco + 50, Blocks.stained_hardened_clay, 4, 1);
      world.setBlock(xco + 18, yco + 18, zco + 51, Blocks.stained_hardened_clay, 4, 1);
      world.setBlock(xco + 19, yco + 18, zco + 51, Blocks.stained_hardened_clay, 4, 1);
      world.setBlock(xco + 20, yco + 18, zco + 51, Blocks.stained_hardened_clay, 4, 1);
      world.setBlock(xco + 21, yco + 18, zco + 51, Blocks.stained_hardened_clay, 4, 1);
      world.setBlock(xco + 22, yco + 18, zco + 51, Blocks.stained_hardened_clay, 4, 1);
      world.setBlock(xco + 23, yco + 18, zco + 51, Blocks.stained_hardened_clay, 4, 1);
      world.setBlock(xco + 24, yco + 18, zco + 51, Blocks.stained_hardened_clay, 4, 1);
      world.setBlock(xco + 25, yco + 18, zco + 51, Blocks.stained_hardened_clay, 4, 1);
      world.setBlock(xco + 26, yco + 18, zco + 51, Blocks.stained_hardened_clay, 4, 1);
      world.setBlock(xco + 27, yco + 18, zco + 51, Blocks.stained_hardened_clay, 4, 1);
      world.setBlock(xco + 28, yco + 18, zco + 51, Blocks.stained_hardened_clay, 4, 1);
      world.setBlock(xco + 29, yco + 18, zco + 51, Blocks.stained_hardened_clay, 4, 1);
      world.setBlock(xco + 30, yco + 18, zco + 51, Blocks.stained_hardened_clay, 4, 1);
      world.setBlock(xco + 31, yco + 18, zco + 51, Blocks.stained_hardened_clay, 4, 1);
      world.setBlock(xco + 32, yco + 18, zco + 51, Blocks.stained_hardened_clay, 4, 1);
      world.setBlock(xco + 33, yco + 18, zco + 51, Blocks.stained_hardened_clay, 4, 1);
      world.setBlock(xco + 34, yco + 18, zco + 51, Blocks.stained_hardened_clay, 4, 1);
      world.setBlock(xco + 17, yco + 18, zco + 52, Blocks.stained_hardened_clay, 4, 1);
      world.setBlock(xco + 18, yco + 18, zco + 52, Blocks.stained_hardened_clay, 4, 1);
      world.setBlock(xco + 22, yco + 18, zco + 52, Blocks.stained_hardened_clay, 4, 1);
      world.setBlock(xco + 23, yco + 18, zco + 52, Blocks.stained_hardened_clay, 4, 1);
      world.setBlock(xco + 26, yco + 18, zco + 52, Blocks.stone, 4, 1);
      world.setBlock(xco + 29, yco + 18, zco + 52, Blocks.stained_hardened_clay, 4, 1);
      world.setBlock(xco + 30, yco + 18, zco + 52, Blocks.stained_hardened_clay, 4, 1);
      world.setBlock(xco + 34, yco + 18, zco + 52, Blocks.stained_hardened_clay, 4, 1);
      world.setBlock(xco + 35, yco + 18, zco + 52, Blocks.stained_hardened_clay, 4, 1);
      world.setBlock(xco + 16, yco + 18, zco + 53, Blocks.stained_hardened_clay, 4, 1);
      world.setBlock(xco + 17, yco + 18, zco + 53, Blocks.stained_hardened_clay, 4, 1);
      world.setBlock(xco + 23, yco + 18, zco + 53, Blocks.stained_hardened_clay, 4, 1);
      world.setBlock(xco + 24, yco + 18, zco + 53, Blocks.stained_hardened_clay, 4, 1);
      world.setBlock(xco + 26, yco + 18, zco + 53, Blocks.stone, 4, 1);
      world.setBlock(xco + 28, yco + 18, zco + 53, Blocks.stained_hardened_clay, 4, 1);
      world.setBlock(xco + 29, yco + 18, zco + 53, Blocks.stained_hardened_clay, 4, 1);
      world.setBlock(xco + 35, yco + 18, zco + 53, Blocks.stained_hardened_clay, 4, 1);
      world.setBlock(xco + 36, yco + 18, zco + 53, Blocks.stained_hardened_clay, 4, 1);
      world.setBlock(xco + 16, yco + 18, zco + 54, Blocks.stained_hardened_clay, 4, 1);
      world.setBlock(xco + 17, yco + 18, zco + 54, Blocks.stained_hardened_clay, 4, 1);
      world.setBlock(xco + 23, yco + 18, zco + 54, Blocks.stained_hardened_clay, 4, 1);
      world.setBlock(xco + 24, yco + 18, zco + 54, Blocks.stained_hardened_clay, 4, 1);
      world.setBlock(xco + 26, yco + 18, zco + 54, Blocks.stone, 4, 1);
      world.setBlock(xco + 28, yco + 18, zco + 54, Blocks.stained_hardened_clay, 4, 1);
      world.setBlock(xco + 29, yco + 18, zco + 54, Blocks.stained_hardened_clay, 4, 1);
      world.setBlock(xco + 35, yco + 18, zco + 54, Blocks.stained_hardened_clay, 4, 1);
      world.setBlock(xco + 36, yco + 18, zco + 54, Blocks.stained_hardened_clay, 4, 1);
      world.setBlock(xco + 16, yco + 18, zco + 55, Blocks.stained_hardened_clay, 4, 1);
      world.setBlock(xco + 17, yco + 18, zco + 55, Blocks.stained_hardened_clay, 4, 1);
      world.setBlock(xco + 23, yco + 18, zco + 55, Blocks.stained_hardened_clay, 4, 1);
      world.setBlock(xco + 24, yco + 18, zco + 55, Blocks.stained_hardened_clay, 4, 1);
      world.setBlock(xco + 26, yco + 18, zco + 55, Blocks.stone, 4, 1);
      world.setBlock(xco + 28, yco + 18, zco + 55, Blocks.stained_hardened_clay, 4, 1);
      world.setBlock(xco + 29, yco + 18, zco + 55, Blocks.stained_hardened_clay, 4, 1);
      world.setBlock(xco + 35, yco + 18, zco + 55, Blocks.stained_hardened_clay, 4, 1);
      world.setBlock(xco + 36, yco + 18, zco + 55, Blocks.stained_hardened_clay, 4, 1);
      world.setBlock(xco + 37, yco + 18, zco + 55, Blocks.stained_hardened_clay, 4, 1);
      world.setBlock(xco + 17, yco + 18, zco + 56, Blocks.stained_hardened_clay, 4, 1);
      world.setBlock(xco + 18, yco + 18, zco + 56, Blocks.stained_hardened_clay, 4, 1);
      world.setBlock(xco + 22, yco + 18, zco + 56, Blocks.stained_hardened_clay, 4, 1);
      world.setBlock(xco + 23, yco + 18, zco + 56, Blocks.stained_hardened_clay, 4, 1);
      world.setBlock(xco + 26, yco + 18, zco + 56, Blocks.stone, 4, 1);
      world.setBlock(xco + 29, yco + 18, zco + 56, Blocks.stained_hardened_clay, 4, 1);
      world.setBlock(xco + 30, yco + 18, zco + 56, Blocks.stained_hardened_clay, 4, 1);
      world.setBlock(xco + 34, yco + 18, zco + 56, Blocks.stained_hardened_clay, 4, 1);
      world.setBlock(xco + 35, yco + 18, zco + 56, Blocks.stained_hardened_clay, 4, 1);
      world.setBlock(xco + 38, yco + 18, zco + 56, Blocks.stained_hardened_clay, 4, 1);
      world.setBlock(xco + 39, yco + 18, zco + 56, Blocks.wool, 15, 1);
      world.setBlock(xco + 40, yco + 18, zco + 56, Blocks.wool, 15, 1);
      world.setBlock(xco + 18, yco + 18, zco + 57, Blocks.stained_hardened_clay, 4, 1);
      world.setBlock(xco + 19, yco + 18, zco + 57, Blocks.stained_hardened_clay, 4, 1);
      world.setBlock(xco + 20, yco + 18, zco + 57, Blocks.stained_hardened_clay, 4, 1);
      world.setBlock(xco + 21, yco + 18, zco + 57, Blocks.stained_hardened_clay, 4, 1);
      world.setBlock(xco + 22, yco + 18, zco + 57, Blocks.stained_hardened_clay, 4, 1);
      world.setBlock(xco + 26, yco + 18, zco + 57, Blocks.stone, 0, 1);
      world.setBlock(xco + 30, yco + 18, zco + 57, Blocks.stained_hardened_clay, 4, 1);
      world.setBlock(xco + 31, yco + 18, zco + 57, Blocks.stained_hardened_clay, 4, 1);
      world.setBlock(xco + 32, yco + 18, zco + 57, Blocks.stained_hardened_clay, 4, 1);
      world.setBlock(xco + 33, yco + 18, zco + 57, Blocks.stained_hardened_clay, 4, 1);
      world.setBlock(xco + 34, yco + 18, zco + 57, Blocks.stained_hardened_clay, 4, 1);
      world.setBlock(xco + 39, yco + 18, zco + 57, Blocks.stained_hardened_clay, 4, 1);
      world.setBlock(xco + 41, yco + 18, zco + 57, Blocks.wool, 15, 1);
      world.setBlock(xco + 19, yco + 18, zco + 58, Blocks.stained_hardened_clay, 4, 1);
      world.setBlock(xco + 20, yco + 18, zco + 58, Blocks.stained_hardened_clay, 4, 1);
      world.setBlock(xco + 21, yco + 18, zco + 58, Blocks.stained_hardened_clay, 4, 1);
      world.setBlock(xco + 26, yco + 18, zco + 58, Blocks.stone, 0, 1);
      world.setBlock(xco + 31, yco + 18, zco + 58, Blocks.stained_hardened_clay, 4, 1);
      world.setBlock(xco + 32, yco + 18, zco + 58, Blocks.stained_hardened_clay, 4, 1);
      world.setBlock(xco + 33, yco + 18, zco + 58, Blocks.stained_hardened_clay, 4, 1);
      world.setBlock(xco + 40, yco + 18, zco + 58, Blocks.stained_hardened_clay, 4, 1);
      world.setBlock(xco + 42, yco + 18, zco + 58, Blocks.wool, 15, 1);
      world.setBlock(xco + 26, yco + 18, zco + 59, Blocks.stone, 0, 1);
      world.setBlock(xco + 34, yco + 18, zco + 59, Blocks.redstone_block, 0, 1);
      world.setBlock(xco + 35, yco + 18, zco + 59, Blocks.redstone_block, 0, 1);
      world.setBlock(xco + 36, yco + 18, zco + 59, Blocks.redstone_block, 0, 1);
      world.setBlock(xco + 37, yco + 18, zco + 59, Blocks.redstone_block, 0, 1);
      world.setBlock(xco + 41, yco + 18, zco + 59, Blocks.stained_hardened_clay, 4, 1);
      world.setBlock(xco + 42, yco + 18, zco + 59, Blocks.wool, 15, 1);
      world.setBlock(xco + 26, yco + 18, zco + 60, Blocks.stone, 0, 1);
      world.setBlock(xco + 33, yco + 18, zco + 60, Blocks.redstone_block, 0, 1);
      world.setBlock(xco + 38, yco + 18, zco + 60, Blocks.redstone_block, 0, 1);
      world.setBlock(xco + 42, yco + 18, zco + 60, Blocks.stone, 0, 1);
      world.setBlock(xco + 43, yco + 18, zco + 60, Blocks.stone, 0, 1);
      world.setBlock(xco + 44, yco + 18, zco + 60, Blocks.stone, 0, 1);
      world.setBlock(xco + 45, yco + 18, zco + 60, Blocks.stone, 0, 1);
      world.setBlock(xco + 25, yco + 18, zco + 61, Blocks.stone, 0, 1);
      world.setBlock(xco + 26, yco + 18, zco + 61, Blocks.stone, 0, 1);
      world.setBlock(xco + 27, yco + 18, zco + 61, Blocks.stone, 0, 1);
      world.setBlock(xco + 32, yco + 18, zco + 61, Blocks.redstone_block, 0, 1);
      world.setBlock(xco + 39, yco + 18, zco + 61, Blocks.redstone_block, 0, 1);
      world.setBlock(xco + 41, yco + 18, zco + 61, Blocks.stone, 0, 1);
      world.setBlock(xco + 46, yco + 18, zco + 61, Blocks.stone, 0, 1);
      world.setBlock(xco + 20, yco + 18, zco + 62, Blocks.stone, 0, 1);
      world.setBlock(xco + 21, yco + 18, zco + 62, Blocks.stone, 0, 1);
      world.setBlock(xco + 22, yco + 18, zco + 62, Blocks.stone, 0, 1);
      world.setBlock(xco + 23, yco + 18, zco + 62, Blocks.stone, 0, 1);
      world.setBlock(xco + 24, yco + 18, zco + 62, Blocks.stone, 0, 1);
      world.setBlock(xco + 25, yco + 18, zco + 62, Blocks.stone, 0, 1);
      world.setBlock(xco + 26, yco + 18, zco + 62, Blocks.stone, 0, 1);
      world.setBlock(xco + 27, yco + 18, zco + 62, Blocks.stone, 0, 1);
      world.setBlock(xco + 32, yco + 18, zco + 62, Blocks.redstone_block, 0, 1);
      world.setBlock(xco + 39, yco + 18, zco + 62, Blocks.redstone_block, 0, 1);
      world.setBlock(xco + 40, yco + 18, zco + 62, Blocks.stone, 0, 1);
      world.setBlock(xco + 47, yco + 18, zco + 62, Blocks.stone, 0, 1);
      world.setBlock(xco + 20, yco + 18, zco + 63, Blocks.stone, 0, 1);
      world.setBlock(xco + 21, yco + 18, zco + 63, Blocks.stone, 0, 1);
      world.setBlock(xco + 22, yco + 18, zco + 63, Blocks.stone, 0, 1);
      world.setBlock(xco + 23, yco + 18, zco + 63, Blocks.stone, 0, 1);
      world.setBlock(xco + 24, yco + 18, zco + 63, Blocks.stone, 0, 1);
      world.setBlock(xco + 25, yco + 18, zco + 63, Blocks.stone, 0, 1);
      world.setBlock(xco + 26, yco + 18, zco + 63, Blocks.stone, 0, 1);
      world.setBlock(xco + 27, yco + 18, zco + 63, Blocks.stone, 0, 1);
      world.setBlock(xco + 32, yco + 18, zco + 63, Blocks.redstone_block, 0, 1);
      world.setBlock(xco + 39, yco + 18, zco + 63, Blocks.redstone_block, 0, 1);
      world.setBlock(xco + 40, yco + 18, zco + 63, Blocks.stone, 0, 1);
      world.setBlock(xco + 47, yco + 18, zco + 63, Blocks.stone, 0, 1);
      world.setBlock(xco + 32, yco + 18, zco + 64, Blocks.redstone_block, 0, 1);
      world.setBlock(xco + 39, yco + 18, zco + 64, Blocks.redstone_block, 0, 1);
      world.setBlock(xco + 40, yco + 18, zco + 64, Blocks.stone, 0, 1);
      world.setBlock(xco + 47, yco + 18, zco + 64, Blocks.stone, 0, 1);
      world.setBlock(xco + 33, yco + 18, zco + 65, Blocks.redstone_block, 0, 1);
      world.setBlock(xco + 38, yco + 18, zco + 65, Blocks.redstone_block, 0, 1);
      world.setBlock(xco + 40, yco + 18, zco + 65, Blocks.stone, 0, 1);
      world.setBlock(xco + 47, yco + 18, zco + 65, Blocks.stone, 0, 1);
      world.setBlock(xco + 34, yco + 18, zco + 66, Blocks.redstone_block, 0, 1);
      world.setBlock(xco + 35, yco + 18, zco + 66, Blocks.redstone_block, 0, 1);
      world.setBlock(xco + 36, yco + 18, zco + 66, Blocks.redstone_block, 0, 1);
      world.setBlock(xco + 37, yco + 18, zco + 66, Blocks.redstone_block, 0, 1);
      world.setBlock(xco + 41, yco + 18, zco + 66, Blocks.stone, 0, 1);
      world.setBlock(xco + 46, yco + 18, zco + 66, Blocks.stone, 0, 1);
      world.setBlock(xco + 42, yco + 18, zco + 67, Blocks.stone, 0, 1);
      world.setBlock(xco + 43, yco + 18, zco + 67, Blocks.stone, 0, 1);
      world.setBlock(xco + 44, yco + 18, zco + 67, Blocks.stone, 0, 1);
      world.setBlock(xco + 45, yco + 18, zco + 67, Blocks.stone, 0, 1);
      world.setBlock(xco + 26, yco + 19, zco + 36, Blocks.nether_brick_fence, 0, 1);
      world.setBlock(xco + 17, yco + 19, zco + 37, Blocks.stained_hardened_clay, 4, 1);
      world.setBlock(xco + 18, yco + 19, zco + 37, Blocks.stained_hardened_clay, 4, 1);
      world.setBlock(xco + 19, yco + 19, zco + 37, Blocks.stained_hardened_clay, 4, 1);
      world.setBlock(xco + 20, yco + 19, zco + 37, Blocks.stained_hardened_clay, 4, 1);
      world.setBlock(xco + 23, yco + 19, zco + 37, Blocks.stained_hardened_clay, 4, 1);
      world.setBlock(xco + 24, yco + 19, zco + 37, Blocks.stained_hardened_clay, 4, 1);
      world.setBlock(xco + 25, yco + 19, zco + 37, Blocks.stained_hardened_clay, 4, 1);
      world.setBlock(xco + 26, yco + 19, zco + 37, Blocks.stained_hardened_clay, 4, 1);
      world.setBlock(xco + 27, yco + 19, zco + 37, Blocks.stained_hardened_clay, 4, 1);
      world.setBlock(xco + 28, yco + 19, zco + 37, Blocks.stained_hardened_clay, 4, 1);
      world.setBlock(xco + 29, yco + 19, zco + 37, Blocks.stained_hardened_clay, 4, 1);
      world.setBlock(xco + 32, yco + 19, zco + 37, Blocks.stained_hardened_clay, 4, 1);
      world.setBlock(xco + 33, yco + 19, zco + 37, Blocks.stained_hardened_clay, 4, 1);
      world.setBlock(xco + 34, yco + 19, zco + 37, Blocks.stained_hardened_clay, 4, 1);
      world.setBlock(xco + 35, yco + 19, zco + 37, Blocks.stained_hardened_clay, 4, 1);
      world.setBlock(xco + 17, yco + 19, zco + 38, Blocks.stained_hardened_clay, 4, 1);
      world.setBlock(xco + 18, yco + 19, zco + 38, Blocks.stained_hardened_clay, 4, 1);
      world.setBlock(xco + 19, yco + 19, zco + 38, Blocks.stained_hardened_clay, 4, 1);
      world.setBlock(xco + 20, yco + 19, zco + 38, Blocks.stained_hardened_clay, 4, 1);
      world.setBlock(xco + 23, yco + 19, zco + 38, Blocks.stained_hardened_clay, 4, 1);
      world.setBlock(xco + 29, yco + 19, zco + 38, Blocks.stained_hardened_clay, 4, 1);
      world.setBlock(xco + 32, yco + 19, zco + 38, Blocks.stained_hardened_clay, 4, 1);
      world.setBlock(xco + 33, yco + 19, zco + 38, Blocks.stained_hardened_clay, 4, 1);
      world.setBlock(xco + 34, yco + 19, zco + 38, Blocks.stained_hardened_clay, 4, 1);
      world.setBlock(xco + 35, yco + 19, zco + 38, Blocks.stained_hardened_clay, 4, 1);
      world.setBlock(xco + 17, yco + 19, zco + 39, Blocks.stained_hardened_clay, 4, 1);
      world.setBlock(xco + 20, yco + 19, zco + 39, Blocks.stained_hardened_clay, 4, 1);
      world.setBlock(xco + 23, yco + 19, zco + 39, Blocks.stained_hardened_clay, 4, 1);
      world.setBlock(xco + 29, yco + 19, zco + 39, Blocks.stained_hardened_clay, 4, 1);
      world.setBlock(xco + 32, yco + 19, zco + 39, Blocks.stained_hardened_clay, 4, 1);
      world.setBlock(xco + 34, yco + 19, zco + 39, Blocks.stained_hardened_clay, 4, 1);
      world.setBlock(xco + 35, yco + 19, zco + 39, Blocks.stained_hardened_clay, 4, 1);
      world.setBlock(xco + 17, yco + 19, zco + 40, Blocks.stained_hardened_clay, 4, 1);
      world.setBlock(xco + 20, yco + 19, zco + 40, Blocks.stained_hardened_clay, 4, 1);
      world.setBlock(xco + 23, yco + 19, zco + 40, Blocks.stained_hardened_clay, 4, 1);
      world.setBlock(xco + 29, yco + 19, zco + 40, Blocks.stained_hardened_clay, 4, 1);
      world.setBlock(xco + 32, yco + 19, zco + 40, Blocks.stained_hardened_clay, 4, 1);
      world.setBlock(xco + 34, yco + 19, zco + 40, Blocks.stained_hardened_clay, 4, 1);
      world.setBlock(xco + 35, yco + 19, zco + 40, Blocks.stained_hardened_clay, 4, 1);
      world.setBlock(xco + 18, yco + 19, zco + 41, Blocks.quartz_block, 0, 1);
      world.setBlock(xco + 20, yco + 19, zco + 41, Blocks.quartz_block, 0, 1);
      world.setBlock(xco + 23, yco + 19, zco + 41, Blocks.stained_hardened_clay, 4, 1);
      world.setBlock(xco + 26, yco + 19, zco + 41, Blocks.stone, 0, 1);
      world.setBlock(xco + 27, yco + 19, zco + 41, Blocks.stone, 0, 1);
      world.setBlock(xco + 29, yco + 19, zco + 41, Blocks.stained_hardened_clay, 4, 1);
      world.setBlock(xco + 32, yco + 19, zco + 41, Blocks.quartz_block, 0, 1);
      world.setBlock(xco + 34, yco + 19, zco + 41, Blocks.quartz_block, 0, 1);
      world.setBlock(xco + 18, yco + 19, zco + 42, Blocks.quartz_block, 0, 1);
      world.setBlock(xco + 20, yco + 19, zco + 42, Blocks.quartz_block, 0, 1);
      world.setBlock(xco + 23, yco + 19, zco + 42, Blocks.stained_hardened_clay, 4, 1);
      world.setBlock(xco + 26, yco + 19, zco + 42, Blocks.stone, 0, 1);
      world.setBlock(xco + 27, yco + 19, zco + 42, Blocks.stone, 0, 1);
      world.setBlock(xco + 29, yco + 19, zco + 42, Blocks.stained_hardened_clay, 4, 1);
      world.setBlock(xco + 32, yco + 19, zco + 42, Blocks.quartz_block, 0, 1);
      world.setBlock(xco + 34, yco + 19, zco + 42, Blocks.quartz_block, 0, 1);
      world.setBlock(xco + 17, yco + 19, zco + 43, Blocks.stained_hardened_clay, 4, 1);
      world.setBlock(xco + 20, yco + 19, zco + 43, Blocks.stained_hardened_clay, 4, 1);
      world.setBlock(xco + 23, yco + 19, zco + 43, Blocks.stained_hardened_clay, 4, 1);
      world.setBlock(xco + 29, yco + 19, zco + 43, Blocks.stained_hardened_clay, 4, 1);
      world.setBlock(xco + 32, yco + 19, zco + 43, Blocks.stained_hardened_clay, 4, 1);
      world.setBlock(xco + 35, yco + 19, zco + 43, Blocks.stained_hardened_clay, 4, 1);
      world.setBlock(xco + 17, yco + 19, zco + 44, Blocks.stained_hardened_clay, 4, 1);
      world.setBlock(xco + 20, yco + 19, zco + 44, Blocks.stained_hardened_clay, 4, 1);
      world.setBlock(xco + 23, yco + 19, zco + 44, Blocks.stained_hardened_clay, 4, 1);
      world.setBlock(xco + 29, yco + 19, zco + 44, Blocks.stained_hardened_clay, 4, 1);
      world.setBlock(xco + 32, yco + 19, zco + 44, Blocks.stained_hardened_clay, 4, 1);
      world.setBlock(xco + 35, yco + 19, zco + 44, Blocks.stained_hardened_clay, 4, 1);
      world.setBlock(xco + 17, yco + 19, zco + 45, Blocks.stained_hardened_clay, 4, 1);
      world.setBlock(xco + 20, yco + 19, zco + 45, Blocks.stained_hardened_clay, 4, 1);
      world.setBlock(xco + 23, yco + 19, zco + 45, Blocks.stained_hardened_clay, 4, 1);
      world.setBlock(xco + 29, yco + 19, zco + 45, Blocks.stained_hardened_clay, 4, 1);
      world.setBlock(xco + 32, yco + 19, zco + 45, Blocks.stained_hardened_clay, 4, 1);
      world.setBlock(xco + 35, yco + 19, zco + 45, Blocks.stained_hardened_clay, 4, 1);
      world.setBlock(xco + 18, yco + 19, zco + 46, Blocks.quartz_block, 0, 1);
      world.setBlock(xco + 19, yco + 19, zco + 46, Blocks.quartz_block, 0, 1);
      world.setBlock(xco + 20, yco + 19, zco + 46, Blocks.quartz_block, 0, 1);
      world.setBlock(xco + 23, yco + 19, zco + 46, Blocks.stained_hardened_clay, 4, 1);
      world.setBlock(xco + 25, yco + 19, zco + 46, Blocks.stone, 0, 1);
      world.setBlock(xco + 26, yco + 19, zco + 46, Blocks.stone, 0, 1);
      world.setBlock(xco + 29, yco + 19, zco + 46, Blocks.stained_hardened_clay, 4, 1);
      world.setBlock(xco + 32, yco + 19, zco + 46, Blocks.quartz_block, 0, 1);
      world.setBlock(xco + 34, yco + 19, zco + 46, Blocks.quartz_block, 0, 1);
      world.setBlock(xco + 18, yco + 19, zco + 47, Blocks.quartz_block, 0, 1);
      world.setBlock(xco + 19, yco + 19, zco + 47, Blocks.quartz_block, 0, 1);
      world.setBlock(xco + 20, yco + 19, zco + 47, Blocks.quartz_block, 0, 1);
      world.setBlock(xco + 23, yco + 19, zco + 47, Blocks.stained_hardened_clay, 4, 1);
      world.setBlock(xco + 25, yco + 19, zco + 47, Blocks.stone, 0, 1);
      world.setBlock(xco + 26, yco + 19, zco + 47, Blocks.stone, 0, 1);
      world.setBlock(xco + 29, yco + 19, zco + 47, Blocks.stained_hardened_clay, 4, 1);
      world.setBlock(xco + 32, yco + 19, zco + 47, Blocks.quartz_block, 0, 1);
      world.setBlock(xco + 34, yco + 19, zco + 47, Blocks.quartz_block, 0, 1);
      world.setBlock(xco + 17, yco + 19, zco + 48, Blocks.stained_hardened_clay, 4, 1);
      world.setBlock(xco + 20, yco + 19, zco + 48, Blocks.stained_hardened_clay, 4, 1);
      world.setBlock(xco + 23, yco + 19, zco + 48, Blocks.stained_hardened_clay, 4, 1);
      world.setBlock(xco + 29, yco + 19, zco + 48, Blocks.stained_hardened_clay, 4, 1);
      world.setBlock(xco + 32, yco + 19, zco + 48, Blocks.stained_hardened_clay, 4, 1);
      world.setBlock(xco + 35, yco + 19, zco + 48, Blocks.stained_hardened_clay, 4, 1);
      world.setBlock(xco + 17, yco + 19, zco + 49, Blocks.stained_hardened_clay, 4, 1);
      world.setBlock(xco + 20, yco + 19, zco + 49, Blocks.stained_hardened_clay, 4, 1);
      world.setBlock(xco + 23, yco + 19, zco + 49, Blocks.stained_hardened_clay, 4, 1);
      world.setBlock(xco + 29, yco + 19, zco + 49, Blocks.stained_hardened_clay, 4, 1);
      world.setBlock(xco + 32, yco + 19, zco + 49, Blocks.stained_hardened_clay, 4, 1);
      world.setBlock(xco + 35, yco + 19, zco + 49, Blocks.stained_hardened_clay, 4, 1);
      world.setBlock(xco + 17, yco + 19, zco + 50, Blocks.stained_hardened_clay, 4, 1);
      world.setBlock(xco + 18, yco + 19, zco + 50, Blocks.stained_hardened_clay, 4, 1);
      world.setBlock(xco + 19, yco + 19, zco + 50, Blocks.stained_hardened_clay, 4, 1);
      world.setBlock(xco + 20, yco + 19, zco + 50, Blocks.stained_hardened_clay, 4, 1);
      world.setBlock(xco + 21, yco + 19, zco + 50, Blocks.stained_hardened_clay, 4, 1);
      world.setBlock(xco + 23, yco + 19, zco + 50, Blocks.stained_hardened_clay, 4, 1);
      world.setBlock(xco + 29, yco + 19, zco + 50, Blocks.stained_hardened_clay, 4, 1);
      world.setBlock(xco + 31, yco + 19, zco + 50, Blocks.stained_hardened_clay, 4, 1);
      world.setBlock(xco + 32, yco + 19, zco + 50, Blocks.stained_hardened_clay, 4, 1);
      world.setBlock(xco + 33, yco + 19, zco + 50, Blocks.stained_hardened_clay, 4, 1);
      world.setBlock(xco + 34, yco + 19, zco + 50, Blocks.stained_hardened_clay, 4, 1);
      world.setBlock(xco + 35, yco + 19, zco + 50, Blocks.stained_hardened_clay, 4, 1);
      world.setBlock(xco + 18, yco + 19, zco + 51, Blocks.stained_hardened_clay, 4, 1);
      world.setBlock(xco + 19, yco + 19, zco + 51, Blocks.stained_hardened_clay, 4, 1);
      world.setBlock(xco + 20, yco + 19, zco + 51, Blocks.stained_hardened_clay, 4, 1);
      world.setBlock(xco + 21, yco + 19, zco + 51, Blocks.stained_hardened_clay, 4, 1);
      world.setBlock(xco + 22, yco + 19, zco + 51, Blocks.stained_hardened_clay, 4, 1);
      world.setBlock(xco + 23, yco + 19, zco + 51, Blocks.stained_hardened_clay, 4, 1);
      world.setBlock(xco + 24, yco + 19, zco + 51, Blocks.stained_hardened_clay, 4, 1);
      world.setBlock(xco + 25, yco + 19, zco + 51, Blocks.stained_hardened_clay, 4, 1);
      world.setBlock(xco + 26, yco + 19, zco + 51, Blocks.stained_hardened_clay, 4, 1);
      world.setBlock(xco + 27, yco + 19, zco + 51, Blocks.stained_hardened_clay, 4, 1);
      world.setBlock(xco + 28, yco + 19, zco + 51, Blocks.stained_hardened_clay, 4, 1);
      world.setBlock(xco + 29, yco + 19, zco + 51, Blocks.stained_hardened_clay, 4, 1);
      world.setBlock(xco + 30, yco + 19, zco + 51, Blocks.stained_hardened_clay, 4, 1);
      world.setBlock(xco + 31, yco + 19, zco + 51, Blocks.stained_hardened_clay, 4, 1);
      world.setBlock(xco + 32, yco + 19, zco + 51, Blocks.stained_hardened_clay, 4, 1);
      world.setBlock(xco + 33, yco + 19, zco + 51, Blocks.stained_hardened_clay, 4, 1);
      world.setBlock(xco + 34, yco + 19, zco + 51, Blocks.stained_hardened_clay, 4, 1);
      world.setBlock(xco + 17, yco + 19, zco + 52, Blocks.stained_hardened_clay, 4, 1);
      world.setBlock(xco + 18, yco + 19, zco + 52, Blocks.stained_hardened_clay, 4, 1);
      world.setBlock(xco + 22, yco + 19, zco + 52, Blocks.stained_hardened_clay, 4, 1);
      world.setBlock(xco + 23, yco + 19, zco + 52, Blocks.stained_hardened_clay, 4, 1);
      world.setBlock(xco + 29, yco + 19, zco + 52, Blocks.stained_hardened_clay, 4, 1);
      world.setBlock(xco + 30, yco + 19, zco + 52, Blocks.stained_hardened_clay, 4, 1);
      world.setBlock(xco + 34, yco + 19, zco + 52, Blocks.stained_hardened_clay, 4, 1);
      world.setBlock(xco + 35, yco + 19, zco + 52, Blocks.stained_hardened_clay, 4, 1);
      world.setBlock(xco + 16, yco + 19, zco + 53, Blocks.stained_hardened_clay, 4, 1);
      world.setBlock(xco + 17, yco + 19, zco + 53, Blocks.stained_hardened_clay, 4, 1);
      world.setBlock(xco + 23, yco + 19, zco + 53, Blocks.stained_hardened_clay, 4, 1);
      world.setBlock(xco + 24, yco + 19, zco + 53, Blocks.stained_hardened_clay, 4, 1);
      world.setBlock(xco + 28, yco + 19, zco + 53, Blocks.stained_hardened_clay, 4, 1);
      world.setBlock(xco + 29, yco + 19, zco + 53, Blocks.stained_hardened_clay, 4, 1);
      world.setBlock(xco + 35, yco + 19, zco + 53, Blocks.stained_hardened_clay, 4, 1);
      world.setBlock(xco + 36, yco + 19, zco + 53, Blocks.stained_hardened_clay, 4, 1);
      world.setBlock(xco + 16, yco + 19, zco + 54, Blocks.stained_hardened_clay, 4, 1);
      world.setBlock(xco + 17, yco + 19, zco + 54, Blocks.stained_hardened_clay, 4, 1);
      world.setBlock(xco + 23, yco + 19, zco + 54, Blocks.stained_hardened_clay, 4, 1);
      world.setBlock(xco + 24, yco + 19, zco + 54, Blocks.stained_hardened_clay, 4, 1);
      world.setBlock(xco + 28, yco + 19, zco + 54, Blocks.stained_hardened_clay, 4, 1);
      world.setBlock(xco + 29, yco + 19, zco + 54, Blocks.stained_hardened_clay, 4, 1);
      world.setBlock(xco + 35, yco + 19, zco + 54, Blocks.stained_hardened_clay, 4, 1);
      world.setBlock(xco + 36, yco + 19, zco + 54, Blocks.stained_hardened_clay, 4, 1);
      world.setBlock(xco + 16, yco + 19, zco + 55, Blocks.stained_hardened_clay, 4, 1);
      world.setBlock(xco + 17, yco + 19, zco + 55, Blocks.stained_hardened_clay, 4, 1);
      world.setBlock(xco + 23, yco + 19, zco + 55, Blocks.stained_hardened_clay, 4, 1);
      world.setBlock(xco + 24, yco + 19, zco + 55, Blocks.stained_hardened_clay, 4, 1);
      world.setBlock(xco + 28, yco + 19, zco + 55, Blocks.stained_hardened_clay, 4, 1);
      world.setBlock(xco + 29, yco + 19, zco + 55, Blocks.stained_hardened_clay, 4, 1);
      world.setBlock(xco + 35, yco + 19, zco + 55, Blocks.stained_hardened_clay, 4, 1);
      world.setBlock(xco + 36, yco + 19, zco + 55, Blocks.stained_hardened_clay, 4, 1);
      world.setBlock(xco + 37, yco + 19, zco + 55, Blocks.stained_hardened_clay, 4, 1);
      world.setBlock(xco + 17, yco + 19, zco + 56, Blocks.stained_hardened_clay, 4, 1);
      world.setBlock(xco + 18, yco + 19, zco + 56, Blocks.stained_hardened_clay, 4, 1);
      world.setBlock(xco + 22, yco + 19, zco + 56, Blocks.stained_hardened_clay, 4, 1);
      world.setBlock(xco + 23, yco + 19, zco + 56, Blocks.stained_hardened_clay, 4, 1);
      world.setBlock(xco + 29, yco + 19, zco + 56, Blocks.stained_hardened_clay, 4, 1);
      world.setBlock(xco + 30, yco + 19, zco + 56, Blocks.stained_hardened_clay, 4, 1);
      world.setBlock(xco + 34, yco + 19, zco + 56, Blocks.stained_hardened_clay, 4, 1);
      world.setBlock(xco + 35, yco + 19, zco + 56, Blocks.stained_hardened_clay, 4, 1);
      world.setBlock(xco + 38, yco + 19, zco + 56, Blocks.stained_hardened_clay, 4, 1);
      world.setBlock(xco + 39, yco + 19, zco + 56, Blocks.wool, 15, 1);
      world.setBlock(xco + 40, yco + 19, zco + 56, Blocks.wool, 15, 1);
      world.setBlock(xco + 18, yco + 19, zco + 57, Blocks.stained_hardened_clay, 4, 1);
      world.setBlock(xco + 19, yco + 19, zco + 57, Blocks.stained_hardened_clay, 4, 1);
      world.setBlock(xco + 20, yco + 19, zco + 57, Blocks.stained_hardened_clay, 4, 1);
      world.setBlock(xco + 21, yco + 19, zco + 57, Blocks.stained_hardened_clay, 4, 1);
      world.setBlock(xco + 22, yco + 19, zco + 57, Blocks.stained_hardened_clay, 4, 1);
      world.setBlock(xco + 30, yco + 19, zco + 57, Blocks.stained_hardened_clay, 4, 1);
      world.setBlock(xco + 31, yco + 19, zco + 57, Blocks.stained_hardened_clay, 4, 1);
      world.setBlock(xco + 32, yco + 19, zco + 57, Blocks.stained_hardened_clay, 4, 1);
      world.setBlock(xco + 33, yco + 19, zco + 57, Blocks.stained_hardened_clay, 4, 1);
      world.setBlock(xco + 34, yco + 19, zco + 57, Blocks.stained_hardened_clay, 4, 1);
      world.setBlock(xco + 39, yco + 19, zco + 57, Blocks.stained_hardened_clay, 4, 1);
      world.setBlock(xco + 41, yco + 19, zco + 57, Blocks.wool, 15, 1);
      world.setBlock(xco + 19, yco + 19, zco + 58, Blocks.stained_hardened_clay, 4, 1);
      world.setBlock(xco + 20, yco + 19, zco + 58, Blocks.stained_hardened_clay, 4, 1);
      world.setBlock(xco + 21, yco + 19, zco + 58, Blocks.stained_hardened_clay, 4, 1);
      world.setBlock(xco + 31, yco + 19, zco + 58, Blocks.stained_hardened_clay, 4, 1);
      world.setBlock(xco + 32, yco + 19, zco + 58, Blocks.stained_hardened_clay, 4, 1);
      world.setBlock(xco + 33, yco + 19, zco + 58, Blocks.stained_hardened_clay, 4, 1);
      world.setBlock(xco + 40, yco + 19, zco + 58, Blocks.stained_hardened_clay, 4, 1);
      world.setBlock(xco + 42, yco + 19, zco + 58, Blocks.wool, 15, 1);
      world.setBlock(xco + 34, yco + 19, zco + 59, Blocks.wool, 15, 1);
      world.setBlock(xco + 35, yco + 19, zco + 59, Blocks.wool, 15, 1);
      world.setBlock(xco + 36, yco + 19, zco + 59, Blocks.wool, 15, 1);
      world.setBlock(xco + 37, yco + 19, zco + 59, Blocks.wool, 15, 1);
      world.setBlock(xco + 41, yco + 19, zco + 59, Blocks.stained_hardened_clay, 4, 1);
      world.setBlock(xco + 42, yco + 19, zco + 59, Blocks.wool, 15, 1);
      world.setBlock(xco + 33, yco + 19, zco + 60, Blocks.wool, 15, 1);
      world.setBlock(xco + 38, yco + 19, zco + 60, Blocks.wool, 15, 1);
      world.setBlock(xco + 42, yco + 19, zco + 60, Blocks.stone, 0, 1);
      world.setBlock(xco + 43, yco + 19, zco + 60, Blocks.stone, 0, 1);
      world.setBlock(xco + 44, yco + 19, zco + 60, Blocks.stone, 0, 1);
      world.setBlock(xco + 45, yco + 19, zco + 60, Blocks.stone, 0, 1);
      world.setBlock(xco + 32, yco + 19, zco + 61, Blocks.wool, 15, 1);
      world.setBlock(xco + 39, yco + 19, zco + 61, Blocks.wool, 15, 1);
      world.setBlock(xco + 41, yco + 19, zco + 61, Blocks.stone, 0, 1);
      world.setBlock(xco + 46, yco + 19, zco + 61, Blocks.stone, 0, 1);
      world.setBlock(xco + 32, yco + 19, zco + 62, Blocks.wool, 15, 1);
      world.setBlock(xco + 39, yco + 19, zco + 62, Blocks.wool, 15, 1);
      world.setBlock(xco + 40, yco + 19, zco + 62, Blocks.stone, 0, 1);
      world.setBlock(xco + 47, yco + 19, zco + 62, Blocks.stone, 0, 1);
      world.setBlock(xco + 32, yco + 19, zco + 63, Blocks.wool, 15, 1);
      world.setBlock(xco + 39, yco + 19, zco + 63, Blocks.wool, 15, 1);
      world.setBlock(xco + 40, yco + 19, zco + 63, Blocks.stone, 0, 1);
      world.setBlock(xco + 47, yco + 19, zco + 63, Blocks.stone, 0, 1);
      world.setBlock(xco + 32, yco + 19, zco + 64, Blocks.wool, 15, 1);
      world.setBlock(xco + 39, yco + 19, zco + 64, Blocks.wool, 15, 1);
      world.setBlock(xco + 40, yco + 19, zco + 64, Blocks.stone, 0, 1);
      world.setBlock(xco + 47, yco + 19, zco + 64, Blocks.stone, 0, 1);
      world.setBlock(xco + 33, yco + 19, zco + 65, Blocks.wool, 15, 1);
      world.setBlock(xco + 38, yco + 19, zco + 65, Blocks.wool, 15, 1);
      world.setBlock(xco + 40, yco + 19, zco + 65, Blocks.stone, 0, 1);
      world.setBlock(xco + 47, yco + 19, zco + 65, Blocks.stone, 0, 1);
      world.setBlock(xco + 34, yco + 19, zco + 66, Blocks.wool, 15, 1);
      world.setBlock(xco + 35, yco + 19, zco + 66, Blocks.wool, 15, 1);
      world.setBlock(xco + 36, yco + 19, zco + 66, Blocks.wool, 15, 1);
      world.setBlock(xco + 37, yco + 19, zco + 66, Blocks.wool, 15, 1);
      world.setBlock(xco + 41, yco + 19, zco + 66, Blocks.stone, 0, 1);
      world.setBlock(xco + 46, yco + 19, zco + 66, Blocks.stone, 0, 1);
      world.setBlock(xco + 42, yco + 19, zco + 67, Blocks.stone, 0, 1);
      world.setBlock(xco + 43, yco + 19, zco + 67, Blocks.stone, 0, 1);
      world.setBlock(xco + 44, yco + 19, zco + 67, Blocks.stone, 0, 1);
      world.setBlock(xco + 45, yco + 19, zco + 67, Blocks.stone, 0, 1);
      world.setBlock(xco + 26, yco + 20, zco + 36, Blocks.nether_brick_fence, 0, 1);
      world.setBlock(xco + 17, yco + 20, zco + 37, Blocks.stained_hardened_clay, 4, 1);
      world.setBlock(xco + 18, yco + 20, zco + 37, Blocks.stained_hardened_clay, 4, 1);
      world.setBlock(xco + 19, yco + 20, zco + 37, Blocks.stained_hardened_clay, 4, 1);
      world.setBlock(xco + 20, yco + 20, zco + 37, Blocks.stained_hardened_clay, 4, 1);
      world.setBlock(xco + 23, yco + 20, zco + 37, Blocks.stained_hardened_clay, 4, 1);
      world.setBlock(xco + 24, yco + 20, zco + 37, Blocks.stained_hardened_clay, 4, 1);
      world.setBlock(xco + 25, yco + 20, zco + 37, Blocks.stained_hardened_clay, 4, 1);
      world.setBlock(xco + 26, yco + 20, zco + 37, Blocks.diamond_block, 0, 1);
      world.setBlock(xco + 27, yco + 20, zco + 37, Blocks.stained_hardened_clay, 4, 1);
      world.setBlock(xco + 28, yco + 20, zco + 37, Blocks.stained_hardened_clay, 4, 1);
      world.setBlock(xco + 29, yco + 20, zco + 37, Blocks.stained_hardened_clay, 4, 1);
      world.setBlock(xco + 32, yco + 20, zco + 37, Blocks.stained_hardened_clay, 4, 1);
      world.setBlock(xco + 33, yco + 20, zco + 37, Blocks.stained_hardened_clay, 4, 1);
      world.setBlock(xco + 34, yco + 20, zco + 37, Blocks.stained_hardened_clay, 4, 1);
      world.setBlock(xco + 35, yco + 20, zco + 37, Blocks.stained_hardened_clay, 4, 1);
      world.setBlock(xco + 17, yco + 20, zco + 38, Blocks.stained_hardened_clay, 4, 1);
      world.setBlock(xco + 18, yco + 20, zco + 38, Blocks.stained_hardened_clay, 4, 1);
      world.setBlock(xco + 19, yco + 20, zco + 38, Blocks.stained_hardened_clay, 4, 1);
      world.setBlock(xco + 20, yco + 20, zco + 38, Blocks.stained_hardened_clay, 4, 1);
      world.setBlock(xco + 23, yco + 20, zco + 38, Blocks.diamond_block, 0, 1);
      world.setBlock(xco + 29, yco + 20, zco + 38, Blocks.diamond_block, 0, 1);
      world.setBlock(xco + 32, yco + 20, zco + 38, Blocks.stained_hardened_clay, 4, 1);
      world.setBlock(xco + 33, yco + 20, zco + 38, Blocks.stained_hardened_clay, 4, 1);
      world.setBlock(xco + 34, yco + 20, zco + 38, Blocks.stained_hardened_clay, 4, 1);
      world.setBlock(xco + 35, yco + 20, zco + 38, Blocks.stained_hardened_clay, 4, 1);
      world.setBlock(xco + 17, yco + 20, zco + 39, Blocks.stained_hardened_clay, 4, 1);
      world.setBlock(xco + 20, yco + 20, zco + 39, Blocks.stained_hardened_clay, 4, 1);
      world.setBlock(xco + 23, yco + 20, zco + 39, Blocks.diamond_block, 0, 1);
      world.setBlock(xco + 29, yco + 20, zco + 39, Blocks.diamond_block, 0, 1);
      world.setBlock(xco + 32, yco + 20, zco + 39, Blocks.stained_hardened_clay, 4, 1);
      world.setBlock(xco + 35, yco + 20, zco + 39, Blocks.stained_hardened_clay, 4, 1);
      world.setBlock(xco + 17, yco + 20, zco + 40, Blocks.stained_hardened_clay, 4, 1);
      world.setBlock(xco + 20, yco + 20, zco + 40, Blocks.stained_hardened_clay, 4, 1);
      world.setBlock(xco + 23, yco + 20, zco + 40, Blocks.diamond_block, 0, 1);
      world.setBlock(xco + 29, yco + 20, zco + 40, Blocks.diamond_block, 0, 1);
      world.setBlock(xco + 32, yco + 20, zco + 40, Blocks.stained_hardened_clay, 4, 1);
      world.setBlock(xco + 34, yco + 20, zco + 40, Blocks.stained_hardened_clay, 4, 1);
      world.setBlock(xco + 35, yco + 20, zco + 40, Blocks.stained_hardened_clay, 4, 1);
      world.setBlock(xco + 18, yco + 20, zco + 41, Blocks.quartz_block, 0, 1);
      world.setBlock(xco + 20, yco + 20, zco + 41, Blocks.quartz_block, 0, 1);
      world.setBlock(xco + 23, yco + 20, zco + 41, Blocks.stained_hardened_clay, 4, 1);
      world.setBlock(xco + 26, yco + 20, zco + 41, Blocks.stone, 0, 1);
      world.setBlock(xco + 27, yco + 20, zco + 41, Blocks.stone, 0, 1);
      world.setBlock(xco + 29, yco + 20, zco + 41, Blocks.stained_hardened_clay, 4, 1);
      world.setBlock(xco + 32, yco + 20, zco + 41, Blocks.quartz_block, 0, 1);
      world.setBlock(xco + 34, yco + 20, zco + 41, Blocks.quartz_block, 0, 1);
      world.setBlock(xco + 18, yco + 20, zco + 42, Blocks.quartz_block, 0, 1);
      world.setBlock(xco + 20, yco + 20, zco + 42, Blocks.quartz_block, 0, 1);
      world.setBlock(xco + 23, yco + 20, zco + 42, Blocks.stained_hardened_clay, 4, 1);
      world.setBlock(xco + 26, yco + 20, zco + 42, Blocks.stone, 0, 1);
      world.setBlock(xco + 27, yco + 20, zco + 42, Blocks.stone, 0, 1);
      world.setBlock(xco + 29, yco + 20, zco + 42, Blocks.stained_hardened_clay, 4, 1);
      world.setBlock(xco + 32, yco + 20, zco + 42, Blocks.quartz_block, 0, 1);
      world.setBlock(xco + 34, yco + 20, zco + 42, Blocks.quartz_block, 0, 1);
      world.setBlock(xco + 17, yco + 20, zco + 43, Blocks.stained_hardened_clay, 4, 1);
      world.setBlock(xco + 20, yco + 20, zco + 43, Blocks.stained_hardened_clay, 4, 1);
      world.setBlock(xco + 23, yco + 20, zco + 43, Blocks.diamond_block, 0, 1);
      world.setBlock(xco + 29, yco + 20, zco + 43, Blocks.diamond_block, 0, 1);
      world.setBlock(xco + 32, yco + 20, zco + 43, Blocks.stained_hardened_clay, 4, 1);
      world.setBlock(xco + 35, yco + 20, zco + 43, Blocks.stained_hardened_clay, 4, 1);
      world.setBlock(xco + 17, yco + 20, zco + 44, Blocks.stained_hardened_clay, 4, 1);
      world.setBlock(xco + 20, yco + 20, zco + 44, Blocks.stained_hardened_clay, 4, 1);
      world.setBlock(xco + 23, yco + 20, zco + 44, Blocks.diamond_block, 0, 1);
      world.setBlock(xco + 29, yco + 20, zco + 44, Blocks.diamond_block, 0, 1);
      world.setBlock(xco + 32, yco + 20, zco + 44, Blocks.stained_hardened_clay, 4, 1);
      world.setBlock(xco + 35, yco + 20, zco + 44, Blocks.stained_hardened_clay, 4, 1);
      world.setBlock(xco + 17, yco + 20, zco + 45, Blocks.stained_hardened_clay, 4, 1);
      world.setBlock(xco + 20, yco + 20, zco + 45, Blocks.stained_hardened_clay, 4, 1);
      world.setBlock(xco + 23, yco + 20, zco + 45, Blocks.diamond_block, 0, 1);
      world.setBlock(xco + 29, yco + 20, zco + 45, Blocks.diamond_block, 0, 1);
      world.setBlock(xco + 32, yco + 20, zco + 45, Blocks.stained_hardened_clay, 4, 1);
      world.setBlock(xco + 35, yco + 20, zco + 45, Blocks.stained_hardened_clay, 4, 1);
      world.setBlock(xco + 18, yco + 20, zco + 46, Blocks.quartz_block, 0, 1);
      world.setBlock(xco + 19, yco + 20, zco + 46, Blocks.quartz_block, 0, 1);
      world.setBlock(xco + 20, yco + 20, zco + 46, Blocks.quartz_block, 0, 1);
      world.setBlock(xco + 23, yco + 20, zco + 46, Blocks.stained_hardened_clay, 4, 1);
      world.setBlock(xco + 25, yco + 20, zco + 46, Blocks.stone, 0, 1);
      world.setBlock(xco + 26, yco + 20, zco + 46, Blocks.stone, 0, 1);
      world.setBlock(xco + 29, yco + 20, zco + 46, Blocks.stained_hardened_clay, 4, 1);
      world.setBlock(xco + 32, yco + 20, zco + 46, Blocks.quartz_block, 0, 1);
      world.setBlock(xco + 34, yco + 20, zco + 46, Blocks.quartz_block, 0, 1);
      world.setBlock(xco + 18, yco + 20, zco + 47, Blocks.quartz_block, 0, 1);
      world.setBlock(xco + 19, yco + 20, zco + 47, Blocks.quartz_block, 0, 1);
      world.setBlock(xco + 20, yco + 20, zco + 47, Blocks.quartz_block, 0, 1);
      world.setBlock(xco + 23, yco + 20, zco + 47, Blocks.stained_hardened_clay, 4, 1);
      world.setBlock(xco + 25, yco + 20, zco + 47, Blocks.stone, 0, 1);
      world.setBlock(xco + 26, yco + 20, zco + 47, Blocks.stone, 0, 1);
      world.setBlock(xco + 29, yco + 20, zco + 47, Blocks.stained_hardened_clay, 4, 1);
      world.setBlock(xco + 32, yco + 20, zco + 47, Blocks.quartz_block, 0, 1);
      world.setBlock(xco + 34, yco + 20, zco + 47, Blocks.quartz_block, 0, 1);
      world.setBlock(xco + 17, yco + 20, zco + 48, Blocks.stained_hardened_clay, 4, 1);
      world.setBlock(xco + 20, yco + 20, zco + 48, Blocks.stained_hardened_clay, 4, 1);
      world.setBlock(xco + 23, yco + 20, zco + 48, Blocks.diamond_block, 0, 1);
      world.setBlock(xco + 29, yco + 20, zco + 48, Blocks.diamond_block, 0, 1);
      world.setBlock(xco + 32, yco + 20, zco + 48, Blocks.stained_hardened_clay, 4, 1);
      world.setBlock(xco + 35, yco + 20, zco + 48, Blocks.stained_hardened_clay, 4, 1);
      world.setBlock(xco + 17, yco + 20, zco + 49, Blocks.stained_hardened_clay, 4, 1);
      world.setBlock(xco + 20, yco + 20, zco + 49, Blocks.stained_hardened_clay, 4, 1);
      world.setBlock(xco + 23, yco + 20, zco + 49, Blocks.diamond_block, 0, 1);
      world.setBlock(xco + 29, yco + 20, zco + 49, Blocks.diamond_block, 0, 1);
      world.setBlock(xco + 32, yco + 20, zco + 49, Blocks.stained_hardened_clay, 4, 1);
      world.setBlock(xco + 35, yco + 20, zco + 49, Blocks.stained_hardened_clay, 4, 1);
      world.setBlock(xco + 17, yco + 20, zco + 50, Blocks.stained_hardened_clay, 4, 1);
      world.setBlock(xco + 18, yco + 20, zco + 50, Blocks.stained_hardened_clay, 4, 1);
      world.setBlock(xco + 19, yco + 20, zco + 50, Blocks.stained_hardened_clay, 4, 1);
return true;
  }
}
