package com.slugterra.world.greatForge;
import java.util.Random;

import net.minecraft.world.World;
import net.minecraft.init.Blocks;
public class GreatWesternForgeStructure5 {
public boolean generate(World world, Random par2Random, int xco, int yco, int zco) {
      world.setBlock(xco + 25, yco + 4, zco + 9, Blocks.grass, 0, 1);
      world.setBlock(xco + 26, yco + 4, zco + 9, Blocks.grass, 0, 1);
      world.setBlock(xco + 27, yco + 4, zco + 9, Blocks.grass, 0, 1);
      world.setBlock(xco + 28, yco + 4, zco + 9, Blocks.grass, 0, 1);
      world.setBlock(xco + 29, yco + 4, zco + 9, Blocks.grass, 0, 1);
      world.setBlock(xco + 30, yco + 4, zco + 9, Blocks.grass, 0, 1);
      world.setBlock(xco + 21, yco + 4, zco + 10, Blocks.grass, 0, 1);
      world.setBlock(xco + 22, yco + 4, zco + 10, Blocks.grass, 0, 1);
      world.setBlock(xco + 23, yco + 4, zco + 10, Blocks.grass, 0, 1);
      world.setBlock(xco + 24, yco + 4, zco + 10, Blocks.grass, 0, 1);
      world.setBlock(xco + 25, yco + 4, zco + 10, Blocks.grass, 0, 1);
      world.setBlock(xco + 26, yco + 4, zco + 10, Blocks.grass, 0, 1);
      world.setBlock(xco + 27, yco + 4, zco + 10, Blocks.grass, 0, 1);
      world.setBlock(xco + 28, yco + 4, zco + 10, Blocks.grass, 0, 1);
      world.setBlock(xco + 29, yco + 4, zco + 10, Blocks.grass, 0, 1);
      world.setBlock(xco + 30, yco + 4, zco + 10, Blocks.grass, 0, 1);
      world.setBlock(xco + 21, yco + 4, zco + 11, Blocks.grass, 0, 1);
      world.setBlock(xco + 22, yco + 4, zco + 11, Blocks.grass, 0, 1);
      world.setBlock(xco + 23, yco + 4, zco + 11, Blocks.grass, 0, 1);
      world.setBlock(xco + 24, yco + 4, zco + 11, Blocks.grass, 0, 1);
      world.setBlock(xco + 25, yco + 4, zco + 11, Blocks.grass, 0, 1);
      world.setBlock(xco + 26, yco + 4, zco + 11, Blocks.grass, 0, 1);
      world.setBlock(xco + 27, yco + 4, zco + 11, Blocks.grass, 0, 1);
      world.setBlock(xco + 28, yco + 4, zco + 11, Blocks.grass, 0, 1);
      world.setBlock(xco + 29, yco + 4, zco + 11, Blocks.grass, 0, 1);
      world.setBlock(xco + 30, yco + 4, zco + 11, Blocks.grass, 0, 1);
      world.setBlock(xco + 25, yco + 4, zco + 12, Blocks.planks, 0, 1);
      world.setBlock(xco + 26, yco + 4, zco + 12, Blocks.planks, 0, 1);
      world.setBlock(xco + 27, yco + 4, zco + 12, Blocks.planks, 0, 1);
      world.setBlock(xco + 25, yco + 4, zco + 13, Blocks.planks, 0, 1);
      world.setBlock(xco + 26, yco + 4, zco + 13, Blocks.planks, 0, 1);
      world.setBlock(xco + 27, yco + 4, zco + 13, Blocks.planks, 0, 1);
      world.setBlock(xco + 25, yco + 4, zco + 14, Blocks.planks, 0, 1);
      world.setBlock(xco + 26, yco + 4, zco + 14, Blocks.planks, 0, 1);
      world.setBlock(xco + 27, yco + 4, zco + 14, Blocks.planks, 0, 1);
      world.setBlock(xco + 25, yco + 4, zco + 15, Blocks.planks, 0, 1);
      world.setBlock(xco + 26, yco + 4, zco + 15, Blocks.planks, 0, 1);
      world.setBlock(xco + 27, yco + 4, zco + 15, Blocks.planks, 0, 1);
      world.setBlock(xco + 25, yco + 4, zco + 16, Blocks.planks, 0, 1);
      world.setBlock(xco + 26, yco + 4, zco + 16, Blocks.planks, 0, 1);
      world.setBlock(xco + 27, yco + 4, zco + 16, Blocks.planks, 0, 1);
      world.setBlock(xco + 25, yco + 4, zco + 17, Blocks.planks, 0, 1);
      world.setBlock(xco + 26, yco + 4, zco + 17, Blocks.planks, 0, 1);
      world.setBlock(xco + 27, yco + 4, zco + 17, Blocks.planks, 0, 1);
      world.setBlock(xco + 25, yco + 4, zco + 18, Blocks.planks, 0, 1);
      world.setBlock(xco + 26, yco + 4, zco + 18, Blocks.planks, 0, 1);
      world.setBlock(xco + 27, yco + 4, zco + 18, Blocks.planks, 0, 1);
      world.setBlock(xco + 25, yco + 4, zco + 19, Blocks.planks, 0, 1);
      world.setBlock(xco + 26, yco + 4, zco + 19, Blocks.planks, 0, 1);
      world.setBlock(xco + 27, yco + 4, zco + 19, Blocks.planks, 0, 1);
      world.setBlock(xco + 25, yco + 4, zco + 20, Blocks.planks, 0, 1);
      world.setBlock(xco + 26, yco + 4, zco + 20, Blocks.planks, 0, 1);
      world.setBlock(xco + 27, yco + 4, zco + 20, Blocks.planks, 0, 1);
      world.setBlock(xco + 25, yco + 4, zco + 21, Blocks.planks, 0, 1);
      world.setBlock(xco + 26, yco + 4, zco + 21, Blocks.planks, 0, 1);
      world.setBlock(xco + 27, yco + 4, zco + 21, Blocks.planks, 0, 1);
      world.setBlock(xco + 25, yco + 4, zco + 22, Blocks.planks, 0, 1);
      world.setBlock(xco + 26, yco + 4, zco + 22, Blocks.planks, 0, 1);
      world.setBlock(xco + 27, yco + 4, zco + 22, Blocks.planks, 0, 1);
      world.setBlock(xco + 25, yco + 4, zco + 23, Blocks.planks, 0, 1);
      world.setBlock(xco + 26, yco + 4, zco + 23, Blocks.planks, 0, 1);
      world.setBlock(xco + 27, yco + 4, zco + 23, Blocks.planks, 0, 1);
      world.setBlock(xco + 25, yco + 4, zco + 24, Blocks.planks, 0, 1);
      world.setBlock(xco + 26, yco + 4, zco + 24, Blocks.planks, 0, 1);
      world.setBlock(xco + 27, yco + 4, zco + 24, Blocks.planks, 0, 1);
      world.setBlock(xco + 25, yco + 4, zco + 25, Blocks.planks, 0, 1);
      world.setBlock(xco + 26, yco + 4, zco + 25, Blocks.planks, 0, 1);
      world.setBlock(xco + 27, yco + 4, zco + 25, Blocks.planks, 0, 1);
      world.setBlock(xco + 25, yco + 4, zco + 26, Blocks.planks, 0, 1);
      world.setBlock(xco + 26, yco + 4, zco + 26, Blocks.planks, 0, 1);
      world.setBlock(xco + 27, yco + 4, zco + 26, Blocks.planks, 0, 1);
      world.setBlock(xco + 25, yco + 4, zco + 27, Blocks.planks, 0, 1);
      world.setBlock(xco + 26, yco + 4, zco + 27, Blocks.planks, 0, 1);
      world.setBlock(xco + 27, yco + 4, zco + 27, Blocks.planks, 0, 1);
      world.setBlock(xco + 25, yco + 4, zco + 28, Blocks.planks, 0, 1);
      world.setBlock(xco + 26, yco + 4, zco + 28, Blocks.planks, 0, 1);
      world.setBlock(xco + 27, yco + 4, zco + 28, Blocks.planks, 0, 1);
      world.setBlock(xco + 25, yco + 4, zco + 29, Blocks.planks, 0, 1);
      world.setBlock(xco + 26, yco + 4, zco + 29, Blocks.planks, 0, 1);
      world.setBlock(xco + 27, yco + 4, zco + 29, Blocks.planks, 0, 1);
      world.setBlock(xco + 24, yco + 4, zco + 30, Blocks.stained_hardened_clay, 4, 1);
      world.setBlock(xco + 25, yco + 4, zco + 30, Blocks.planks, 0, 1);
      world.setBlock(xco + 26, yco + 4, zco + 30, Blocks.planks, 0, 1);
      world.setBlock(xco + 27, yco + 4, zco + 30, Blocks.planks, 0, 1);
      world.setBlock(xco + 28, yco + 4, zco + 30, Blocks.stained_hardened_clay, 4, 1);
      world.setBlock(xco + 24, yco + 4, zco + 31, Blocks.stained_hardened_clay, 4, 1);
      world.setBlock(xco + 28, yco + 4, zco + 31, Blocks.stained_hardened_clay, 4, 1);
      world.setBlock(xco + 24, yco + 4, zco + 32, Blocks.stained_hardened_clay, 4, 1);
      world.setBlock(xco + 28, yco + 4, zco + 32, Blocks.stained_hardened_clay, 4, 1);
      world.setBlock(xco + 32, yco + 4, zco + 32, Blocks.stone, 0, 1);
      world.setBlock(xco + 35, yco + 4, zco + 32, Blocks.stone, 0, 1);
      world.setBlock(xco + 38, yco + 4, zco + 32, Blocks.stone, 0, 1);
      world.setBlock(xco + 41, yco + 4, zco + 32, Blocks.stone, 0, 1);
      world.setBlock(xco + 32, yco + 4, zco + 33, Blocks.stone, 0, 1);
      world.setBlock(xco + 35, yco + 4, zco + 33, Blocks.stone, 0, 1);
      world.setBlock(xco + 38, yco + 4, zco + 33, Blocks.stone, 0, 1);
      world.setBlock(xco + 41, yco + 4, zco + 33, Blocks.stone, 0, 1);
      world.setBlock(xco + 32, yco + 4, zco + 34, Blocks.stone, 0, 1);
      world.setBlock(xco + 35, yco + 4, zco + 34, Blocks.stone, 0, 1);
      world.setBlock(xco + 38, yco + 4, zco + 34, Blocks.stone, 0, 1);
      world.setBlock(xco + 41, yco + 4, zco + 34, Blocks.stone, 0, 1);
      world.setBlock(xco + 32, yco + 4, zco + 35, Blocks.stone, 0, 1);
      world.setBlock(xco + 36, yco + 4, zco + 35, Blocks.stone, 0, 1);
      world.setBlock(xco + 37, yco + 4, zco + 35, Blocks.stone, 0, 1);
      world.setBlock(xco + 38, yco + 4, zco + 35, Blocks.stone, 0, 1);
      world.setBlock(xco + 41, yco + 4, zco + 35, Blocks.stone, 0, 1);
      world.setBlock(xco + 33, yco + 4, zco + 36, Blocks.stone, 0, 1);
      world.setBlock(xco + 36, yco + 4, zco + 36, Blocks.water, 1, 1);
      world.setBlock(xco + 37, yco + 4, zco + 36, Blocks.water, 0, 1);
      world.setBlock(xco + 38, yco + 4, zco + 36, Blocks.stone, 0, 1);
      world.setBlock(xco + 41, yco + 4, zco + 36, Blocks.stone, 0, 1);
      world.setBlock(xco + 26, yco + 4, zco + 37, Blocks.stone, 0, 1);
      world.setBlock(xco + 34, yco + 4, zco + 37, Blocks.stone, 0, 1);
      world.setBlock(xco + 36, yco + 4, zco + 37, Blocks.water, 1, 1);
      world.setBlock(xco + 37, yco + 4, zco + 37, Blocks.water, 0, 1);
      world.setBlock(xco + 38, yco + 4, zco + 37, Blocks.stone, 0, 1);
      world.setBlock(xco + 41, yco + 4, zco + 37, Blocks.stone, 0, 1);
      world.setBlock(xco + 25, yco + 4, zco + 38, Blocks.stone, 0, 1);
      world.setBlock(xco + 26, yco + 4, zco + 38, Blocks.stone, 0, 1);
      world.setBlock(xco + 27, yco + 4, zco + 38, Blocks.stone, 0, 1);
      world.setBlock(xco + 35, yco + 4, zco + 38, Blocks.stone, 0, 1);
      world.setBlock(xco + 36, yco + 4, zco + 38, Blocks.stone, 0, 1);
      world.setBlock(xco + 37, yco + 4, zco + 38, Blocks.stone, 0, 1);
      world.setBlock(xco + 38, yco + 4, zco + 38, Blocks.stone, 0, 1);
      world.setBlock(xco + 39, yco + 4, zco + 38, Blocks.water, 9, 1);
      world.setBlock(xco + 40, yco + 4, zco + 38, Blocks.water, 9, 1);
      world.setBlock(xco + 41, yco + 4, zco + 38, Blocks.stone, 0, 1);
      world.setBlock(xco + 25, yco + 4, zco + 39, Blocks.stone, 0, 1);
      world.setBlock(xco + 26, yco + 4, zco + 39, Blocks.stone, 0, 1);
      world.setBlock(xco + 27, yco + 4, zco + 39, Blocks.stone, 0, 1);
      world.setBlock(xco + 38, yco + 4, zco + 39, Blocks.stone, 0, 1);
      world.setBlock(xco + 39, yco + 4, zco + 39, Blocks.water, 8, 1);
      world.setBlock(xco + 40, yco + 4, zco + 39, Blocks.water, 8, 1);
      world.setBlock(xco + 41, yco + 4, zco + 39, Blocks.stone, 0, 1);
      world.setBlock(xco + 25, yco + 4, zco + 40, Blocks.stone, 0, 1);
      world.setBlock(xco + 26, yco + 4, zco + 40, Blocks.stone, 0, 1);
      world.setBlock(xco + 27, yco + 4, zco + 40, Blocks.stone, 0, 1);
      world.setBlock(xco + 39, yco + 4, zco + 40, Blocks.stone, 0, 1);
      world.setBlock(xco + 40, yco + 4, zco + 40, Blocks.stone, 0, 1);
      world.setBlock(xco + 5, yco + 4, zco + 41, Blocks.stone, 0, 1);
      world.setBlock(xco + 6, yco + 4, zco + 41, Blocks.stone, 0, 1);
      world.setBlock(xco + 7, yco + 4, zco + 41, Blocks.stone, 0, 1);
      world.setBlock(xco + 25, yco + 4, zco + 41, Blocks.stone, 0, 1);
      world.setBlock(xco + 26, yco + 4, zco + 41, Blocks.stone, 0, 1);
      world.setBlock(xco + 27, yco + 4, zco + 41, Blocks.stone, 0, 1);
      world.setBlock(xco + 4, yco + 4, zco + 42, Blocks.stone, 0, 1);
      world.setBlock(xco + 8, yco + 4, zco + 42, Blocks.stone, 0, 1);
      world.setBlock(xco + 25, yco + 4, zco + 42, Blocks.stone, 0, 1);
      world.setBlock(xco + 26, yco + 4, zco + 42, Blocks.stone, 0, 1);
      world.setBlock(xco + 27, yco + 4, zco + 42, Blocks.stone, 0, 1);
      world.setBlock(xco + 4, yco + 4, zco + 43, Blocks.stone, 0, 1);
      world.setBlock(xco + 8, yco + 4, zco + 43, Blocks.stone, 0, 1);
      world.setBlock(xco + 25, yco + 4, zco + 43, Blocks.stone, 0, 1);
      world.setBlock(xco + 26, yco + 4, zco + 43, Blocks.stone, 0, 1);
      world.setBlock(xco + 27, yco + 4, zco + 43, Blocks.stone, 0, 1);
      world.setBlock(xco + 4, yco + 4, zco + 44, Blocks.stone, 0, 1);
      world.setBlock(xco + 8, yco + 4, zco + 44, Blocks.stone, 0, 1);
      world.setBlock(xco + 25, yco + 4, zco + 44, Blocks.stone, 0, 1);
      world.setBlock(xco + 26, yco + 4, zco + 44, Blocks.stone, 0, 1);
      world.setBlock(xco + 27, yco + 4, zco + 44, Blocks.stone, 0, 1);
      world.setBlock(xco + 5, yco + 4, zco + 45, Blocks.stone, 0, 1);
      world.setBlock(xco + 6, yco + 4, zco + 45, Blocks.stone, 0, 1);
      world.setBlock(xco + 7, yco + 4, zco + 45, Blocks.stone, 0, 1);
      world.setBlock(xco + 25, yco + 4, zco + 45, Blocks.stone, 0, 1);
      world.setBlock(xco + 26, yco + 4, zco + 45, Blocks.stone, 0, 1);
      world.setBlock(xco + 27, yco + 4, zco + 45, Blocks.stone, 0, 1);
      world.setBlock(xco + 25, yco + 4, zco + 46, Blocks.stone, 0, 1);
      world.setBlock(xco + 26, yco + 4, zco + 46, Blocks.stone, 0, 1);
      world.setBlock(xco + 27, yco + 4, zco + 46, Blocks.stone, 0, 1);
      world.setBlock(xco + 25, yco + 4, zco + 47, Blocks.stone, 0, 1);
      world.setBlock(xco + 26, yco + 4, zco + 47, Blocks.stone, 0, 1);
      world.setBlock(xco + 27, yco + 4, zco + 47, Blocks.stone, 0, 1);
      world.setBlock(xco + 25, yco + 4, zco + 48, Blocks.stone, 0, 1);
      world.setBlock(xco + 26, yco + 4, zco + 48, Blocks.stone, 0, 1);
      world.setBlock(xco + 27, yco + 4, zco + 48, Blocks.stone, 0, 1);
      world.setBlock(xco + 25, yco + 4, zco + 49, Blocks.stone, 0, 1);
      world.setBlock(xco + 26, yco + 4, zco + 49, Blocks.stone, 0, 1);
      world.setBlock(xco + 27, yco + 4, zco + 49, Blocks.stone, 0, 1);
      world.setBlock(xco + 25, yco + 4, zco + 50, Blocks.stone, 0, 1);
      world.setBlock(xco + 26, yco + 4, zco + 50, Blocks.stone, 0, 1);
      world.setBlock(xco + 27, yco + 4, zco + 50, Blocks.stone, 0, 1);
      world.setBlock(xco + 26, yco + 4, zco + 51, Blocks.stone, 0, 1);
      world.setBlock(xco + 27, yco + 5, zco + 9, Blocks.fence, 0, 1);
      world.setBlock(xco + 25, yco + 5, zco + 10, Blocks.fence, 0, 1);
      world.setBlock(xco + 25, yco + 5, zco + 12, Blocks.fence, 0, 1);
      world.setBlock(xco + 27, yco + 5, zco + 12, Blocks.fence, 0, 1);
      world.setBlock(xco + 25, yco + 5, zco + 13, Blocks.fence, 0, 1);
      world.setBlock(xco + 27, yco + 5, zco + 13, Blocks.fence, 0, 1);
      world.setBlock(xco + 25, yco + 5, zco + 14, Blocks.fence, 0, 1);
      world.setBlock(xco + 27, yco + 5, zco + 14, Blocks.fence, 0, 1);
      world.setBlock(xco + 25, yco + 5, zco + 15, Blocks.fence, 0, 1);
      world.setBlock(xco + 27, yco + 5, zco + 15, Blocks.fence, 0, 1);
      world.setBlock(xco + 25, yco + 5, zco + 16, Blocks.fence, 0, 1);
      world.setBlock(xco + 27, yco + 5, zco + 16, Blocks.fence, 0, 1);
      world.setBlock(xco + 25, yco + 5, zco + 17, Blocks.fence, 0, 1);
      world.setBlock(xco + 27, yco + 5, zco + 17, Blocks.fence, 0, 1);
      world.setBlock(xco + 25, yco + 5, zco + 18, Blocks.fence, 0, 1);
      world.setBlock(xco + 27, yco + 5, zco + 18, Blocks.fence, 0, 1);
      world.setBlock(xco + 25, yco + 5, zco + 19, Blocks.fence, 0, 1);
      world.setBlock(xco + 27, yco + 5, zco + 19, Blocks.fence, 0, 1);
      world.setBlock(xco + 25, yco + 5, zco + 20, Blocks.fence, 0, 1);
      world.setBlock(xco + 27, yco + 5, zco + 20, Blocks.fence, 0, 1);
      world.setBlock(xco + 25, yco + 5, zco + 21, Blocks.fence, 0, 1);
      world.setBlock(xco + 27, yco + 5, zco + 21, Blocks.fence, 0, 1);
      world.setBlock(xco + 25, yco + 5, zco + 22, Blocks.fence, 0, 1);
      world.setBlock(xco + 27, yco + 5, zco + 22, Blocks.fence, 0, 1);
      world.setBlock(xco + 25, yco + 5, zco + 23, Blocks.fence, 0, 1);
      world.setBlock(xco + 27, yco + 5, zco + 23, Blocks.fence, 0, 1);
      world.setBlock(xco + 25, yco + 5, zco + 24, Blocks.fence, 0, 1);
      world.setBlock(xco + 27, yco + 5, zco + 24, Blocks.fence, 0, 1);
      world.setBlock(xco + 25, yco + 5, zco + 25, Blocks.fence, 0, 1);
      world.setBlock(xco + 27, yco + 5, zco + 25, Blocks.fence, 0, 1);
      world.setBlock(xco + 25, yco + 5, zco + 26, Blocks.fence, 0, 1);
      world.setBlock(xco + 27, yco + 5, zco + 26, Blocks.fence, 0, 1);
      world.setBlock(xco + 25, yco + 5, zco + 27, Blocks.fence, 0, 1);
      world.setBlock(xco + 27, yco + 5, zco + 27, Blocks.fence, 0, 1);
      world.setBlock(xco + 25, yco + 5, zco + 28, Blocks.fence, 0, 1);
      world.setBlock(xco + 27, yco + 5, zco + 28, Blocks.fence, 0, 1);
      world.setBlock(xco + 25, yco + 5, zco + 29, Blocks.fence, 0, 1);
      world.setBlock(xco + 27, yco + 5, zco + 29, Blocks.fence, 0, 1);
      world.setBlock(xco + 25, yco + 5, zco + 30, Blocks.fence, 0, 1);
      world.setBlock(xco + 27, yco + 5, zco + 30, Blocks.fence, 0, 1);
      world.setBlock(xco + 24, yco + 5, zco + 31, Blocks.stained_hardened_clay, 4, 1);
      world.setBlock(xco + 25, yco + 5, zco + 31, Blocks.nether_brick_stairs, 2, 1);
      world.setBlock(xco + 26, yco + 5, zco + 31, Blocks.nether_brick_stairs, 2, 1);
      world.setBlock(xco + 27, yco + 5, zco + 31, Blocks.nether_brick_stairs, 2, 1);
      world.setBlock(xco + 28, yco + 5, zco + 31, Blocks.stained_hardened_clay, 4, 1);
      world.setBlock(xco + 24, yco + 5, zco + 32, Blocks.stained_hardened_clay, 4, 1);
      world.setBlock(xco + 28, yco + 5, zco + 32, Blocks.stained_hardened_clay, 4, 1);
      world.setBlock(xco + 33, yco + 5, zco + 32, Blocks.stone, 0, 1);
      world.setBlock(xco + 34, yco + 5, zco + 32, Blocks.stone, 0, 1);
      world.setBlock(xco + 39, yco + 5, zco + 32, Blocks.stone, 0, 1);
      world.setBlock(xco + 40, yco + 5, zco + 32, Blocks.stone, 0, 1);
      world.setBlock(xco + 33, yco + 5, zco + 33, Blocks.stone, 0, 1);
      world.setBlock(xco + 34, yco + 5, zco + 33, Blocks.stone, 0, 1);
      world.setBlock(xco + 39, yco + 5, zco + 33, Blocks.stone, 0, 1);
      world.setBlock(xco + 40, yco + 5, zco + 33, Blocks.stone, 0, 1);
      world.setBlock(xco + 33, yco + 5, zco + 34, Blocks.stone, 0, 1);
      world.setBlock(xco + 34, yco + 5, zco + 34, Blocks.stone, 0, 1);
      world.setBlock(xco + 39, yco + 5, zco + 34, Blocks.stone, 0, 1);
      world.setBlock(xco + 40, yco + 5, zco + 34, Blocks.stone, 0, 1);
      world.setBlock(xco + 33, yco + 5, zco + 35, Blocks.stone, 0, 1);
      world.setBlock(xco + 34, yco + 5, zco + 35, Blocks.stone, 0, 1);
      world.setBlock(xco + 35, yco + 5, zco + 35, Blocks.stone, 0, 1);
      world.setBlock(xco + 39, yco + 5, zco + 35, Blocks.stone, 0, 1);
      world.setBlock(xco + 40, yco + 5, zco + 35, Blocks.stone, 0, 1);
      world.setBlock(xco + 26, yco + 5, zco + 36, Blocks.stone, 0, 1);
      world.setBlock(xco + 34, yco + 5, zco + 36, Blocks.stone, 0, 1);
      world.setBlock(xco + 35, yco + 5, zco + 36, Blocks.stone, 0, 1);
      world.setBlock(xco + 36, yco + 5, zco + 36, Blocks.stone, 0, 1);
      world.setBlock(xco + 37, yco + 5, zco + 36, Blocks.stone, 0, 1);
      world.setBlock(xco + 38, yco + 5, zco + 36, Blocks.stone, 0, 1);
      world.setBlock(xco + 39, yco + 5, zco + 36, Blocks.stone, 0, 1);
      world.setBlock(xco + 40, yco + 5, zco + 36, Blocks.stone, 0, 1);
      world.setBlock(xco + 23, yco + 5, zco + 37, Blocks.stained_glass, 1, 1);
      world.setBlock(xco + 25, yco + 5, zco + 37, Blocks.stone, 0, 1);
      world.setBlock(xco + 26, yco + 5, zco + 37, Blocks.lava, 0, 1);
      world.setBlock(xco + 27, yco + 5, zco + 37, Blocks.stone, 0, 1);
      world.setBlock(xco + 35, yco + 5, zco + 37, Blocks.stone, 0, 1);
      world.setBlock(xco + 36, yco + 5, zco + 37, Blocks.stone, 0, 1);
      world.setBlock(xco + 37, yco + 5, zco + 37, Blocks.stone, 0, 1);
      world.setBlock(xco + 38, yco + 5, zco + 37, Blocks.stone, 0, 1);
      world.setBlock(xco + 39, yco + 5, zco + 37, Blocks.stone, 0, 1);
      world.setBlock(xco + 40, yco + 5, zco + 37, Blocks.stone, 0, 1);
      world.setBlock(xco + 23, yco + 5, zco + 38, Blocks.stained_glass, 1, 1);
      world.setBlock(xco + 24, yco + 5, zco + 38, Blocks.stone, 0, 1);
      world.setBlock(xco + 25, yco + 5, zco + 38, Blocks.lava, 0, 1);
      world.setBlock(xco + 26, yco + 5, zco + 38, Blocks.lava, 2, 1);
      world.setBlock(xco + 27, yco + 5, zco + 38, Blocks.lava, 0, 1);
      world.setBlock(xco + 28, yco + 5, zco + 38, Blocks.stone, 0, 1);
      world.setBlock(xco + 29, yco + 5, zco + 38, Blocks.stained_glass, 14, 1);
      world.setBlock(xco + 38, yco + 5, zco + 38, Blocks.stone, 0, 1);
      world.setBlock(xco + 39, yco + 5, zco + 38, Blocks.water, 1, 1);
      world.setBlock(xco + 40, yco + 5, zco + 38, Blocks.water, 1, 1);
      world.setBlock(xco + 41, yco + 5, zco + 38, Blocks.stone, 0, 1);
      world.setBlock(xco + 23, yco + 5, zco + 39, Blocks.stained_glass, 1, 1);
      world.setBlock(xco + 24, yco + 5, zco + 39, Blocks.stone, 0, 1);
      world.setBlock(xco + 25, yco + 5, zco + 39, Blocks.lava, 0, 1);
      world.setBlock(xco + 26, yco + 5, zco + 39, Blocks.lava, 2, 1);
      world.setBlock(xco + 27, yco + 5, zco + 39, Blocks.lava, 0, 1);
      world.setBlock(xco + 28, yco + 5, zco + 39, Blocks.stone, 0, 1);
      world.setBlock(xco + 29, yco + 5, zco + 39, Blocks.stained_glass, 14, 1);
      world.setBlock(xco + 38, yco + 5, zco + 39, Blocks.stone, 0, 1);
      world.setBlock(xco + 39, yco + 5, zco + 39, Blocks.water, 0, 1);
      world.setBlock(xco + 40, yco + 5, zco + 39, Blocks.water, 0, 1);
      world.setBlock(xco + 41, yco + 5, zco + 39, Blocks.stone, 0, 1);
      world.setBlock(xco + 23, yco + 5, zco + 40, Blocks.stained_glass, 1, 1);
      world.setBlock(xco + 24, yco + 5, zco + 40, Blocks.stone, 0, 1);
      world.setBlock(xco + 25, yco + 5, zco + 40, Blocks.lava, 0, 1);
      world.setBlock(xco + 26, yco + 5, zco + 40, Blocks.lava, 2, 1);
      world.setBlock(xco + 27, yco + 5, zco + 40, Blocks.lava, 0, 1);
      world.setBlock(xco + 28, yco + 5, zco + 40, Blocks.stone, 0, 1);
      world.setBlock(xco + 29, yco + 5, zco + 40, Blocks.stained_glass, 14, 1);
      world.setBlock(xco + 39, yco + 5, zco + 40, Blocks.stone, 0, 1);
      world.setBlock(xco + 40, yco + 5, zco + 40, Blocks.stone, 0, 1);
      world.setBlock(xco + 5, yco + 5, zco + 41, Blocks.stone, 0, 1);
      world.setBlock(xco + 6, yco + 5, zco + 41, Blocks.stone, 0, 1);
      world.setBlock(xco + 7, yco + 5, zco + 41, Blocks.stone, 0, 1);
      world.setBlock(xco + 24, yco + 5, zco + 41, Blocks.stone, 0, 1);
      world.setBlock(xco + 25, yco + 5, zco + 41, Blocks.lava, 0, 1);
      world.setBlock(xco + 26, yco + 5, zco + 41, Blocks.lava, 2, 1);
      world.setBlock(xco + 27, yco + 5, zco + 41, Blocks.lava, 0, 1);
      world.setBlock(xco + 28, yco + 5, zco + 41, Blocks.stone, 0, 1);
      world.setBlock(xco + 4, yco + 5, zco + 42, Blocks.stone, 0, 1);
      world.setBlock(xco + 8, yco + 5, zco + 42, Blocks.stone, 0, 1);
      world.setBlock(xco + 24, yco + 5, zco + 42, Blocks.stone, 0, 1);
      world.setBlock(xco + 25, yco + 5, zco + 42, Blocks.lava, 0, 1);
      world.setBlock(xco + 26, yco + 5, zco + 42, Blocks.lava, 2, 1);
      world.setBlock(xco + 27, yco + 5, zco + 42, Blocks.lava, 0, 1);
      world.setBlock(xco + 28, yco + 5, zco + 42, Blocks.stone, 0, 1);
      world.setBlock(xco + 4, yco + 5, zco + 43, Blocks.stone, 0, 1);
      world.setBlock(xco + 8, yco + 5, zco + 43, Blocks.stone, 0, 1);
      world.setBlock(xco + 23, yco + 5, zco + 43, Blocks.stained_glass, 1, 1);
      world.setBlock(xco + 24, yco + 5, zco + 43, Blocks.stone, 0, 1);
      world.setBlock(xco + 25, yco + 5, zco + 43, Blocks.lava, 0, 1);
      world.setBlock(xco + 26, yco + 5, zco + 43, Blocks.lava, 2, 1);
      world.setBlock(xco + 27, yco + 5, zco + 43, Blocks.lava, 0, 1);
      world.setBlock(xco + 28, yco + 5, zco + 43, Blocks.stone, 0, 1);
      world.setBlock(xco + 29, yco + 5, zco + 43, Blocks.stained_glass, 14, 1);
      world.setBlock(xco + 4, yco + 5, zco + 44, Blocks.stone, 0, 1);
      world.setBlock(xco + 8, yco + 5, zco + 44, Blocks.stone, 0, 1);
      world.setBlock(xco + 22, yco + 5, zco + 44, Blocks.stained_hardened_clay, 4, 1);
      world.setBlock(xco + 23, yco + 5, zco + 44, Blocks.stained_glass, 1, 1);
      world.setBlock(xco + 24, yco + 5, zco + 44, Blocks.stone, 0, 1);
      world.setBlock(xco + 25, yco + 5, zco + 44, Blocks.lava, 0, 1);
      world.setBlock(xco + 26, yco + 5, zco + 44, Blocks.lava, 2, 1);
      world.setBlock(xco + 27, yco + 5, zco + 44, Blocks.lava, 0, 1);
      world.setBlock(xco + 28, yco + 5, zco + 44, Blocks.stone, 0, 1);
      world.setBlock(xco + 29, yco + 5, zco + 44, Blocks.stained_glass, 14, 1);
      world.setBlock(xco + 5, yco + 5, zco + 45, Blocks.stone, 0, 1);
      world.setBlock(xco + 6, yco + 5, zco + 45, Blocks.stone, 0, 1);
      world.setBlock(xco + 7, yco + 5, zco + 45, Blocks.stone, 0, 1);
      world.setBlock(xco + 23, yco + 5, zco + 45, Blocks.stained_glass, 1, 1);
      world.setBlock(xco + 24, yco + 5, zco + 45, Blocks.stone, 0, 1);
      world.setBlock(xco + 25, yco + 5, zco + 45, Blocks.lava, 0, 1);
      world.setBlock(xco + 26, yco + 5, zco + 45, Blocks.lava, 2, 1);
      world.setBlock(xco + 27, yco + 5, zco + 45, Blocks.lava, 0, 1);
      world.setBlock(xco + 28, yco + 5, zco + 45, Blocks.stone, 0, 1);
      world.setBlock(xco + 29, yco + 5, zco + 45, Blocks.stained_glass, 14, 1);
      world.setBlock(xco + 23, yco + 5, zco + 46, Blocks.stained_glass, 1, 1);
      world.setBlock(xco + 24, yco + 5, zco + 46, Blocks.stone, 0, 1);
      world.setBlock(xco + 25, yco + 5, zco + 46, Blocks.lava, 0, 1);
      world.setBlock(xco + 26, yco + 5, zco + 46, Blocks.lava, 2, 1);
      world.setBlock(xco + 27, yco + 5, zco + 46, Blocks.lava, 0, 1);
      world.setBlock(xco + 28, yco + 5, zco + 46, Blocks.stone, 0, 1);
      world.setBlock(xco + 24, yco + 5, zco + 47, Blocks.stone, 0, 1);
      world.setBlock(xco + 25, yco + 5, zco + 47, Blocks.lava, 0, 1);
      world.setBlock(xco + 26, yco + 5, zco + 47, Blocks.lava, 2, 1);
      world.setBlock(xco + 27, yco + 5, zco + 47, Blocks.lava, 0, 1);
      world.setBlock(xco + 28, yco + 5, zco + 47, Blocks.stone, 0, 1);
      world.setBlock(xco + 23, yco + 5, zco + 48, Blocks.stained_glass, 1, 1);
      world.setBlock(xco + 24, yco + 5, zco + 48, Blocks.stone, 0, 1);
      world.setBlock(xco + 25, yco + 5, zco + 48, Blocks.lava, 0, 1);
      world.setBlock(xco + 26, yco + 5, zco + 48, Blocks.lava, 2, 1);
      world.setBlock(xco + 27, yco + 5, zco + 48, Blocks.lava, 0, 1);
      world.setBlock(xco + 28, yco + 5, zco + 48, Blocks.stone, 0, 1);
      world.setBlock(xco + 29, yco + 5, zco + 48, Blocks.stained_glass, 14, 1);
      world.setBlock(xco + 23, yco + 5, zco + 49, Blocks.stained_glass, 1, 1);
      world.setBlock(xco + 24, yco + 5, zco + 49, Blocks.stone, 0, 1);
      world.setBlock(xco + 25, yco + 5, zco + 49, Blocks.lava, 0, 1);
      world.setBlock(xco + 26, yco + 5, zco + 49, Blocks.lava, 2, 1);
      world.setBlock(xco + 27, yco + 5, zco + 49, Blocks.lava, 0, 1);
      world.setBlock(xco + 28, yco + 5, zco + 49, Blocks.stone, 0, 1);
      world.setBlock(xco + 29, yco + 5, zco + 49, Blocks.stained_glass, 14, 1);
      world.setBlock(xco + 23, yco + 5, zco + 50, Blocks.stained_glass, 1, 1);
      world.setBlock(xco + 24, yco + 5, zco + 50, Blocks.stone, 0, 1);
      world.setBlock(xco + 25, yco + 5, zco + 50, Blocks.lava, 0, 1);
      world.setBlock(xco + 26, yco + 5, zco + 50, Blocks.lava, 2, 1);
      world.setBlock(xco + 27, yco + 5, zco + 50, Blocks.lava, 0, 1);
      world.setBlock(xco + 28, yco + 5, zco + 50, Blocks.stone, 0, 1);
      world.setBlock(xco + 29, yco + 5, zco + 50, Blocks.stained_glass, 14, 1);
      world.setBlock(xco + 25, yco + 5, zco + 51, Blocks.stone, 0, 1);
      world.setBlock(xco + 26, yco + 5, zco + 51, Blocks.lava, 0, 1);
      world.setBlock(xco + 27, yco + 5, zco + 51, Blocks.stone, 0, 1);
      world.setBlock(xco + 26, yco + 5, zco + 52, Blocks.stone, 0, 1);
      world.setBlock(xco + 24, yco + 6, zco + 32, Blocks.stained_hardened_clay, 4, 1);
      world.setBlock(xco + 25, yco + 6, zco + 32, Blocks.nether_brick_stairs, 2, 1);
      world.setBlock(xco + 26, yco + 6, zco + 32, Blocks.nether_brick_stairs, 2, 1);
      world.setBlock(xco + 27, yco + 6, zco + 32, Blocks.nether_brick_stairs, 2, 1);
      world.setBlock(xco + 28, yco + 6, zco + 32, Blocks.stained_hardened_clay, 4, 1);
      world.setBlock(xco + 13, yco + 6, zco + 33, Blocks.stained_hardened_clay, 4, 1);
      world.setBlock(xco + 14, yco + 6, zco + 33, Blocks.stained_hardened_clay, 4, 1);
      world.setBlock(xco + 15, yco + 6, zco + 33, Blocks.stained_hardened_clay, 4, 1);
      world.setBlock(xco + 16, yco + 6, zco + 33, Blocks.stained_hardened_clay, 4, 1);
      world.setBlock(xco + 17, yco + 6, zco + 33, Blocks.stained_hardened_clay, 4, 1);
      world.setBlock(xco + 18, yco + 6, zco + 33, Blocks.stained_hardened_clay, 4, 1);
      world.setBlock(xco + 19, yco + 6, zco + 33, Blocks.stained_hardened_clay, 4, 1);
      world.setBlock(xco + 20, yco + 6, zco + 33, Blocks.stained_hardened_clay, 4, 1);
      world.setBlock(xco + 21, yco + 6, zco + 33, Blocks.stained_hardened_clay, 4, 1);
      world.setBlock(xco + 22, yco + 6, zco + 33, Blocks.stained_hardened_clay, 4, 1);
      world.setBlock(xco + 23, yco + 6, zco + 33, Blocks.stained_hardened_clay, 4, 1);
      world.setBlock(xco + 24, yco + 6, zco + 33, Blocks.stained_hardened_clay, 4, 1);
      world.setBlock(xco + 25, yco + 6, zco + 33, Blocks.stone, 0, 1);
      world.setBlock(xco + 26, yco + 6, zco + 33, Blocks.stone, 0, 1);
      world.setBlock(xco + 27, yco + 6, zco + 33, Blocks.stone, 0, 1);
      world.setBlock(xco + 28, yco + 6, zco + 33, Blocks.stone, 0, 1);
      world.setBlock(xco + 29, yco + 6, zco + 33, Blocks.stained_hardened_clay, 4, 1);
      world.setBlock(xco + 30, yco + 6, zco + 33, Blocks.stained_hardened_clay, 4, 1);
      world.setBlock(xco + 31, yco + 6, zco + 33, Blocks.stained_hardened_clay, 4, 1);
      world.setBlock(xco + 32, yco + 6, zco + 33, Blocks.stained_hardened_clay, 4, 1);
      world.setBlock(xco + 33, yco + 6, zco + 33, Blocks.stained_hardened_clay, 4, 1);
      world.setBlock(xco + 34, yco + 6, zco + 33, Blocks.stained_hardened_clay, 4, 1);
      world.setBlock(xco + 35, yco + 6, zco + 33, Blocks.stained_hardened_clay, 4, 1);
      world.setBlock(xco + 36, yco + 6, zco + 33, Blocks.stained_hardened_clay, 4, 1);
      world.setBlock(xco + 37, yco + 6, zco + 33, Blocks.stained_hardened_clay, 4, 1);
      world.setBlock(xco + 38, yco + 6, zco + 33, Blocks.stained_hardened_clay, 4, 1);
      world.setBlock(xco + 39, yco + 6, zco + 33, Blocks.stained_hardened_clay, 4, 1);
      world.setBlock(xco + 40, yco + 6, zco + 33, Blocks.stained_hardened_clay, 4, 1);
      world.setBlock(xco + 41, yco + 6, zco + 33, Blocks.stained_hardened_clay, 4, 1);
      world.setBlock(xco + 42, yco + 6, zco + 33, Blocks.stained_hardened_clay, 4, 1);
      world.setBlock(xco + 43, yco + 6, zco + 33, Blocks.stained_hardened_clay, 4, 1);
      world.setBlock(xco + 44, yco + 6, zco + 33, Blocks.stained_hardened_clay, 4, 1);
      world.setBlock(xco + 45, yco + 6, zco + 33, Blocks.stained_hardened_clay, 4, 1);
      world.setBlock(xco + 46, yco + 6, zco + 33, Blocks.stained_hardened_clay, 4, 1);
      world.setBlock(xco + 47, yco + 6, zco + 33, Blocks.stained_hardened_clay, 4, 1);
      world.setBlock(xco + 13, yco + 6, zco + 34, Blocks.stained_hardened_clay, 4, 1);
      world.setBlock(xco + 14, yco + 6, zco + 34, Blocks.stone, 0, 1);
      world.setBlock(xco + 15, yco + 6, zco + 34, Blocks.stone, 0, 1);
      world.setBlock(xco + 16, yco + 6, zco + 34, Blocks.stone, 0, 1);
      world.setBlock(xco + 17, yco + 6, zco + 34, Blocks.stone, 0, 1);
      world.setBlock(xco + 18, yco + 6, zco + 34, Blocks.stone, 0, 1);
      world.setBlock(xco + 19, yco + 6, zco + 34, Blocks.stone, 0, 1);
      world.setBlock(xco + 20, yco + 6, zco + 34, Blocks.stone, 0, 1);
      world.setBlock(xco + 21, yco + 6, zco + 34, Blocks.stone, 0, 1);
      world.setBlock(xco + 22, yco + 6, zco + 34, Blocks.stone, 0, 1);
      world.setBlock(xco + 23, yco + 6, zco + 34, Blocks.stained_hardened_clay, 4, 1);
      world.setBlock(xco + 24, yco + 6, zco + 34, Blocks.stone, 0, 1);
      world.setBlock(xco + 25, yco + 6, zco + 34, Blocks.stone, 0, 1);
      world.setBlock(xco + 26, yco + 6, zco + 34, Blocks.stone, 0, 1);
      world.setBlock(xco + 27, yco + 6, zco + 34, Blocks.stone, 0, 1);
      world.setBlock(xco + 28, yco + 6, zco + 34, Blocks.stone, 0, 1);
      world.setBlock(xco + 29, yco + 6, zco + 34, Blocks.stained_hardened_clay, 4, 1);
      world.setBlock(xco + 30, yco + 6, zco + 34, Blocks.stone, 0, 1);
      world.setBlock(xco + 31, yco + 6, zco + 34, Blocks.stone, 0, 1);
      world.setBlock(xco + 32, yco + 6, zco + 34, Blocks.stone, 0, 1);
      world.setBlock(xco + 33, yco + 6, zco + 34, Blocks.stone, 0, 1);
      world.setBlock(xco + 34, yco + 6, zco + 34, Blocks.stone, 0, 1);
      world.setBlock(xco + 35, yco + 6, zco + 34, Blocks.stone, 0, 1);
      world.setBlock(xco + 36, yco + 6, zco + 34, Blocks.stone, 0, 1);
      world.setBlock(xco + 37, yco + 6, zco + 34, Blocks.stone, 0, 1);
      world.setBlock(xco + 38, yco + 6, zco + 34, Blocks.stone, 0, 1);
      world.setBlock(xco + 39, yco + 6, zco + 34, Blocks.stone, 0, 1);
      world.setBlock(xco + 40, yco + 6, zco + 34, Blocks.stone, 0, 1);
      world.setBlock(xco + 41, yco + 6, zco + 34, Blocks.stone, 0, 1);
      world.setBlock(xco + 42, yco + 6, zco + 34, Blocks.stone, 0, 1);
      world.setBlock(xco + 43, yco + 6, zco + 34, Blocks.stone, 0, 1);
      world.setBlock(xco + 44, yco + 6, zco + 34, Blocks.stone, 0, 1);
      world.setBlock(xco + 45, yco + 6, zco + 34, Blocks.stone, 0, 1);
      world.setBlock(xco + 46, yco + 6, zco + 34, Blocks.stone, 0, 1);
      world.setBlock(xco + 47, yco + 6, zco + 34, Blocks.stained_hardened_clay, 4, 1);
      world.setBlock(xco + 13, yco + 6, zco + 35, Blocks.stained_hardened_clay, 4, 1);
      world.setBlock(xco + 14, yco + 6, zco + 35, Blocks.stone, 0, 1);
      world.setBlock(xco + 15, yco + 6, zco + 35, Blocks.stone, 0, 1);
      world.setBlock(xco + 16, yco + 6, zco + 35, Blocks.stone, 0, 1);
      world.setBlock(xco + 17, yco + 6, zco + 35, Blocks.stone, 0, 1);
      world.setBlock(xco + 18, yco + 6, zco + 35, Blocks.stone, 0, 1);
      world.setBlock(xco + 19, yco + 6, zco + 35, Blocks.stone, 0, 1);
      world.setBlock(xco + 20, yco + 6, zco + 35, Blocks.stone, 0, 1);
      world.setBlock(xco + 21, yco + 6, zco + 35, Blocks.stone, 0, 1);
      world.setBlock(xco + 22, yco + 6, zco + 35, Blocks.stone, 0, 1);
      world.setBlock(xco + 23, yco + 6, zco + 35, Blocks.stained_hardened_clay, 4, 1);
      world.setBlock(xco + 24, yco + 6, zco + 35, Blocks.stone, 0, 1);
      world.setBlock(xco + 25, yco + 6, zco + 35, Blocks.stone, 0, 1);
      world.setBlock(xco + 26, yco + 6, zco + 35, Blocks.stone, 0, 1);
      world.setBlock(xco + 27, yco + 6, zco + 35, Blocks.stone, 0, 1);
      world.setBlock(xco + 28, yco + 6, zco + 35, Blocks.stone, 0, 1);
      world.setBlock(xco + 29, yco + 6, zco + 35, Blocks.stained_hardened_clay, 4, 1);
      world.setBlock(xco + 30, yco + 6, zco + 35, Blocks.stone, 0, 1);
      world.setBlock(xco + 31, yco + 6, zco + 35, Blocks.stone, 0, 1);
      world.setBlock(xco + 32, yco + 6, zco + 35, Blocks.stone, 0, 1);
      world.setBlock(xco + 33, yco + 6, zco + 35, Blocks.stone, 0, 1);
      world.setBlock(xco + 34, yco + 6, zco + 35, Blocks.stone, 0, 1);
      world.setBlock(xco + 35, yco + 6, zco + 35, Blocks.stone, 0, 1);
      world.setBlock(xco + 36, yco + 6, zco + 35, Blocks.stone, 0, 1);
      world.setBlock(xco + 37, yco + 6, zco + 35, Blocks.stone, 0, 1);
      world.setBlock(xco + 38, yco + 6, zco + 35, Blocks.stone, 0, 1);
      world.setBlock(xco + 39, yco + 6, zco + 35, Blocks.stone, 0, 1);
      world.setBlock(xco + 40, yco + 6, zco + 35, Blocks.stone, 0, 1);
      world.setBlock(xco + 41, yco + 6, zco + 35, Blocks.stone, 0, 1);
      world.setBlock(xco + 42, yco + 6, zco + 35, Blocks.stone, 0, 1);
      world.setBlock(xco + 43, yco + 6, zco + 35, Blocks.stone, 0, 1);
      world.setBlock(xco + 44, yco + 6, zco + 35, Blocks.stone, 0, 1);
      world.setBlock(xco + 45, yco + 6, zco + 35, Blocks.stone, 0, 1);
      world.setBlock(xco + 46, yco + 6, zco + 35, Blocks.stone, 0, 1);
      world.setBlock(xco + 47, yco + 6, zco + 35, Blocks.stained_hardened_clay, 4, 1);
      world.setBlock(xco + 13, yco + 6, zco + 36, Blocks.stained_hardened_clay, 4, 1);
      world.setBlock(xco + 14, yco + 6, zco + 36, Blocks.stone, 0, 1);
      world.setBlock(xco + 15, yco + 6, zco + 36, Blocks.stone, 0, 1);
      world.setBlock(xco + 16, yco + 6, zco + 36, Blocks.stone, 0, 1);
      world.setBlock(xco + 17, yco + 6, zco + 36, Blocks.stone, 0, 1);
      world.setBlock(xco + 18, yco + 6, zco + 36, Blocks.stone, 0, 1);
      world.setBlock(xco + 19, yco + 6, zco + 36, Blocks.stone, 0, 1);
      world.setBlock(xco + 20, yco + 6, zco + 36, Blocks.stone, 0, 1);
      world.setBlock(xco + 21, yco + 6, zco + 36, Blocks.stone, 0, 1);
      world.setBlock(xco + 22, yco + 6, zco + 36, Blocks.stone, 0, 1);
      world.setBlock(xco + 23, yco + 6, zco + 36, Blocks.stained_hardened_clay, 4, 1);
      world.setBlock(xco + 24, yco + 6, zco + 36, Blocks.stained_hardened_clay, 4, 1);
      world.setBlock(xco + 25, yco + 6, zco + 36, Blocks.stained_hardened_clay, 4, 1);
      world.setBlock(xco + 26, yco + 6, zco + 36, Blocks.stained_hardened_clay, 4, 1);
      world.setBlock(xco + 27, yco + 6, zco + 36, Blocks.stained_hardened_clay, 4, 1);
      world.setBlock(xco + 28, yco + 6, zco + 36, Blocks.stained_hardened_clay, 4, 1);
      world.setBlock(xco + 29, yco + 6, zco + 36, Blocks.stained_hardened_clay, 4, 1);
      world.setBlock(xco + 30, yco + 6, zco + 36, Blocks.stone, 0, 1);
      world.setBlock(xco + 31, yco + 6, zco + 36, Blocks.stone, 0, 1);
      world.setBlock(xco + 32, yco + 6, zco + 36, Blocks.stone, 0, 1);
      world.setBlock(xco + 33, yco + 6, zco + 36, Blocks.stone, 0, 1);
      world.setBlock(xco + 34, yco + 6, zco + 36, Blocks.stone, 0, 1);
      world.setBlock(xco + 35, yco + 6, zco + 36, Blocks.stone, 0, 1);
      world.setBlock(xco + 36, yco + 6, zco + 36, Blocks.stone, 0, 1);
      world.setBlock(xco + 37, yco + 6, zco + 36, Blocks.stone, 0, 1);
      world.setBlock(xco + 38, yco + 6, zco + 36, Blocks.stone, 0, 1);
      world.setBlock(xco + 39, yco + 6, zco + 36, Blocks.stone, 0, 1);
      world.setBlock(xco + 40, yco + 6, zco + 36, Blocks.stained_hardened_clay, 4, 1);
      world.setBlock(xco + 41, yco + 6, zco + 36, Blocks.stone, 0, 1);
      world.setBlock(xco + 42, yco + 6, zco + 36, Blocks.stained_hardened_clay, 4, 1);
      world.setBlock(xco + 43, yco + 6, zco + 36, Blocks.stone, 0, 1);
      world.setBlock(xco + 44, yco + 6, zco + 36, Blocks.stone, 0, 1);
      world.setBlock(xco + 45, yco + 6, zco + 36, Blocks.stone, 0, 1);
      world.setBlock(xco + 46, yco + 6, zco + 36, Blocks.stone, 0, 1);
      world.setBlock(xco + 47, yco + 6, zco + 36, Blocks.stained_hardened_clay, 4, 1);
      world.setBlock(xco + 13, yco + 6, zco + 37, Blocks.stained_hardened_clay, 4, 1);
      world.setBlock(xco + 14, yco + 6, zco + 37, Blocks.stone, 0, 1);
      world.setBlock(xco + 15, yco + 6, zco + 37, Blocks.stained_hardened_clay, 4, 1);
      world.setBlock(xco + 16, yco + 6, zco + 37, Blocks.stained_hardened_clay, 4, 1);
      world.setBlock(xco + 17, yco + 6, zco + 37, Blocks.stained_hardened_clay, 4, 1);
      world.setBlock(xco + 18, yco + 6, zco + 37, Blocks.stained_hardened_clay, 4, 1);
      world.setBlock(xco + 19, yco + 6, zco + 37, Blocks.stained_hardened_clay, 4, 1);
      world.setBlock(xco + 20, yco + 6, zco + 37, Blocks.stained_hardened_clay, 4, 1);
      world.setBlock(xco + 22, yco + 6, zco + 37, Blocks.stained_hardened_clay, 4, 1);
      world.setBlock(xco + 23, yco + 6, zco + 37, Blocks.stained_hardened_clay, 4, 1);
      world.setBlock(xco + 24, yco + 6, zco + 37, Blocks.stained_hardened_clay, 4, 1);
      world.setBlock(xco + 25, yco + 6, zco + 37, Blocks.stained_hardened_clay, 4, 1);
      world.setBlock(xco + 26, yco + 6, zco + 37, Blocks.stained_glass, 1, 1);
      world.setBlock(xco + 27, yco + 6, zco + 37, Blocks.stained_hardened_clay, 4, 1);
      world.setBlock(xco + 28, yco + 6, zco + 37, Blocks.stained_hardened_clay, 4, 1);
      world.setBlock(xco + 29, yco + 6, zco + 37, Blocks.stained_hardened_clay, 4, 1);
      world.setBlock(xco + 30, yco + 6, zco + 37, Blocks.stone, 0, 1);
      world.setBlock(xco + 31, yco + 6, zco + 37, Blocks.stone, 0, 1);
      world.setBlock(xco + 32, yco + 6, zco + 37, Blocks.stained_hardened_clay, 4, 1);
      world.setBlock(xco + 33, yco + 6, zco + 37, Blocks.stained_hardened_clay, 4, 1);
      world.setBlock(xco + 34, yco + 6, zco + 37, Blocks.stained_hardened_clay, 4, 1);
      world.setBlock(xco + 35, yco + 6, zco + 37, Blocks.stained_hardened_clay, 4, 1);
      world.setBlock(xco + 36, yco + 6, zco + 37, Blocks.stained_hardened_clay, 4, 1);
      world.setBlock(xco + 37, yco + 6, zco + 37, Blocks.stained_hardened_clay, 4, 1);
      world.setBlock(xco + 38, yco + 6, zco + 37, Blocks.stone, 0, 1);
      world.setBlock(xco + 39, yco + 6, zco + 37, Blocks.stained_hardened_clay, 4, 1);
      world.setBlock(xco + 40, yco + 6, zco + 37, Blocks.stone, 0, 1);
      world.setBlock(xco + 41, yco + 6, zco + 37, Blocks.stone, 0, 1);
      world.setBlock(xco + 42, yco + 6, zco + 37, Blocks.stone, 0, 1);
      world.setBlock(xco + 43, yco + 6, zco + 37, Blocks.stained_hardened_clay, 4, 1);
      world.setBlock(xco + 44, yco + 6, zco + 37, Blocks.stone, 0, 1);
      world.setBlock(xco + 45, yco + 6, zco + 37, Blocks.stone, 0, 1);
      world.setBlock(xco + 46, yco + 6, zco + 37, Blocks.stone, 0, 1);
      world.setBlock(xco + 47, yco + 6, zco + 37, Blocks.stained_hardened_clay, 4, 1);
      world.setBlock(xco + 13, yco + 6, zco + 38, Blocks.stained_hardened_clay, 4, 1);
      world.setBlock(xco + 14, yco + 6, zco + 38, Blocks.stone, 0, 1);
      world.setBlock(xco + 15, yco + 6, zco + 38, Blocks.stained_hardened_clay, 4, 1);
      world.setBlock(xco + 16, yco + 6, zco + 38, Blocks.stained_hardened_clay, 4, 1);
      world.setBlock(xco + 17, yco + 6, zco + 38, Blocks.stained_hardened_clay, 4, 1);
      world.setBlock(xco + 18, yco + 6, zco + 38, Blocks.stained_hardened_clay, 4, 1);
      world.setBlock(xco + 19, yco + 6, zco + 38, Blocks.stained_hardened_clay, 4, 1);
      world.setBlock(xco + 20, yco + 6, zco + 38, Blocks.stained_hardened_clay, 4, 1);
      world.setBlock(xco + 21, yco + 6, zco + 38, Blocks.stained_hardened_clay, 4, 1);
      world.setBlock(xco + 22, yco + 6, zco + 38, Blocks.stained_hardened_clay, 4, 1);
      world.setBlock(xco + 23, yco + 6, zco + 38, Blocks.lava, 4, 1);
      world.setBlock(xco + 24, yco + 6, zco + 38, Blocks.stained_hardened_clay, 4, 1);
      world.setBlock(xco + 25, yco + 6, zco + 38, Blocks.glass, 0, 1);
      world.setBlock(xco + 26, yco + 6, zco + 38, Blocks.stained_glass, 1, 1);
      world.setBlock(xco + 27, yco + 6, zco + 38, Blocks.glass, 0, 1);
      world.setBlock(xco + 28, yco + 6, zco + 38, Blocks.stained_hardened_clay, 4, 1);
      world.setBlock(xco + 29, yco + 6, zco + 38, Blocks.lava, 4, 1);
      world.setBlock(xco + 30, yco + 6, zco + 38, Blocks.stained_hardened_clay, 4, 1);
      world.setBlock(xco + 31, yco + 6, zco + 38, Blocks.stained_hardened_clay, 4, 1);
      world.setBlock(xco + 32, yco + 6, zco + 38, Blocks.stained_hardened_clay, 4, 1);
      world.setBlock(xco + 33, yco + 6, zco + 38, Blocks.stained_hardened_clay, 4, 1);
      world.setBlock(xco + 34, yco + 6, zco + 38, Blocks.stained_hardened_clay, 4, 1);
      world.setBlock(xco + 35, yco + 6, zco + 38, Blocks.stained_hardened_clay, 4, 1);
      world.setBlock(xco + 36, yco + 6, zco + 38, Blocks.stained_hardened_clay, 4, 1);
      world.setBlock(xco + 37, yco + 6, zco + 38, Blocks.stained_hardened_clay, 4, 1);
      world.setBlock(xco + 38, yco + 6, zco + 38, Blocks.stained_hardened_clay, 4, 1);
      world.setBlock(xco + 39, yco + 6, zco + 38, Blocks.stone, 0, 1);
      world.setBlock(xco + 40, yco + 6, zco + 38, Blocks.stone, 0, 1);
      world.setBlock(xco + 41, yco + 6, zco + 38, Blocks.stone, 0, 1);
      world.setBlock(xco + 42, yco + 6, zco + 38, Blocks.stone, 0, 1);
      world.setBlock(xco + 43, yco + 6, zco + 38, Blocks.stone, 0, 1);
      world.setBlock(xco + 44, yco + 6, zco + 38, Blocks.stained_hardened_clay, 4, 1);
      world.setBlock(xco + 45, yco + 6, zco + 38, Blocks.stone, 0, 1);
      world.setBlock(xco + 46, yco + 6, zco + 38, Blocks.stone, 0, 1);
      world.setBlock(xco + 47, yco + 6, zco + 38, Blocks.stained_hardened_clay, 4, 1);
      world.setBlock(xco + 13, yco + 6, zco + 39, Blocks.stained_hardened_clay, 4, 1);
      world.setBlock(xco + 14, yco + 6, zco + 39, Blocks.stone, 0, 1);
      world.setBlock(xco + 15, yco + 6, zco + 39, Blocks.stained_hardened_clay, 4, 1);
      world.setBlock(xco + 16, yco + 6, zco + 39, Blocks.stained_hardened_clay, 4, 1);
      world.setBlock(xco + 17, yco + 6, zco + 39, Blocks.stained_hardened_clay, 4, 1);
      world.setBlock(xco + 18, yco + 6, zco + 39, Blocks.stained_hardened_clay, 4, 1);
      world.setBlock(xco + 19, yco + 6, zco + 39, Blocks.stained_hardened_clay, 4, 1);
      world.setBlock(xco + 20, yco + 6, zco + 39, Blocks.stained_hardened_clay, 4, 1);
      world.setBlock(xco + 21, yco + 6, zco + 39, Blocks.stained_hardened_clay, 4, 1);
      world.setBlock(xco + 22, yco + 6, zco + 39, Blocks.stained_hardened_clay, 4, 1);
      world.setBlock(xco + 23, yco + 6, zco + 39, Blocks.lava, 2, 1);
      world.setBlock(xco + 24, yco + 6, zco + 39, Blocks.glowstone, 0, 1);
      world.setBlock(xco + 25, yco + 6, zco + 39, Blocks.glass, 0, 1);
      world.setBlock(xco + 26, yco + 6, zco + 39, Blocks.stained_glass, 1, 1);
      world.setBlock(xco + 27, yco + 6, zco + 39, Blocks.glass, 0, 1);
      world.setBlock(xco + 28, yco + 6, zco + 39, Blocks.glowstone, 0, 1);
      world.setBlock(xco + 29, yco + 6, zco + 39, Blocks.lava, 2, 1);
      world.setBlock(xco + 30, yco + 6, zco + 39, Blocks.stained_hardened_clay, 4, 1);
      world.setBlock(xco + 31, yco + 6, zco + 39, Blocks.stained_hardened_clay, 4, 1);
      world.setBlock(xco + 32, yco + 6, zco + 39, Blocks.stained_hardened_clay, 4, 1);
      world.setBlock(xco + 33, yco + 6, zco + 39, Blocks.stained_hardened_clay, 4, 1);
      world.setBlock(xco + 34, yco + 6, zco + 39, Blocks.stained_hardened_clay, 4, 1);
      world.setBlock(xco + 35, yco + 6, zco + 39, Blocks.stained_hardened_clay, 4, 1);
      world.setBlock(xco + 36, yco + 6, zco + 39, Blocks.stained_hardened_clay, 4, 1);
      world.setBlock(xco + 37, yco + 6, zco + 39, Blocks.stained_hardened_clay, 4, 1);
      world.setBlock(xco + 38, yco + 6, zco + 39, Blocks.stained_hardened_clay, 4, 1);
      world.setBlock(xco + 39, yco + 6, zco + 39, Blocks.stone, 0, 1);
      world.setBlock(xco + 40, yco + 6, zco + 39, Blocks.stone, 0, 1);
      world.setBlock(xco + 41, yco + 6, zco + 39, Blocks.stone, 0, 1);
      world.setBlock(xco + 42, yco + 6, zco + 39, Blocks.stone, 0, 1);
      world.setBlock(xco + 43, yco + 6, zco + 39, Blocks.stone, 0, 1);
      world.setBlock(xco + 44, yco + 6, zco + 39, Blocks.stained_hardened_clay, 4, 1);
      world.setBlock(xco + 45, yco + 6, zco + 39, Blocks.stone, 0, 1);
      world.setBlock(xco + 46, yco + 6, zco + 39, Blocks.stone, 0, 1);
      world.setBlock(xco + 47, yco + 6, zco + 39, Blocks.stained_hardened_clay, 4, 1);
      world.setBlock(xco + 13, yco + 6, zco + 40, Blocks.stained_hardened_clay, 4, 1);
      world.setBlock(xco + 14, yco + 6, zco + 40, Blocks.stone, 0, 1);
      world.setBlock(xco + 15, yco + 6, zco + 40, Blocks.stained_hardened_clay, 4, 1);
      world.setBlock(xco + 16, yco + 6, zco + 40, Blocks.stained_hardened_clay, 4, 1);
      world.setBlock(xco + 17, yco + 6, zco + 40, Blocks.stained_hardened_clay, 4, 1);
      world.setBlock(xco + 18, yco + 6, zco + 40, Blocks.stained_hardened_clay, 4, 1);
      world.setBlock(xco + 19, yco + 6, zco + 40, Blocks.stained_hardened_clay, 4, 1);
      world.setBlock(xco + 20, yco + 6, zco + 40, Blocks.stained_hardened_clay, 4, 1);
      world.setBlock(xco + 21, yco + 6, zco + 40, Blocks.stained_hardened_clay, 4, 1);
      world.setBlock(xco + 22, yco + 6, zco + 40, Blocks.stained_hardened_clay, 4, 1);
      world.setBlock(xco + 23, yco + 6, zco + 40, Blocks.lava, 10, 1);
      world.setBlock(xco + 24, yco + 6, zco + 40, Blocks.glowstone, 0, 1);
      world.setBlock(xco + 25, yco + 6, zco + 40, Blocks.glass, 0, 1);
      world.setBlock(xco + 26, yco + 6, zco + 40, Blocks.stained_glass, 1, 1);
      world.setBlock(xco + 27, yco + 6, zco + 40, Blocks.glass, 0, 1);
      world.setBlock(xco + 28, yco + 6, zco + 40, Blocks.glowstone, 0, 1);
      world.setBlock(xco + 29, yco + 6, zco + 40, Blocks.lava, 10, 1);
      world.setBlock(xco + 30, yco + 6, zco + 40, Blocks.stained_hardened_clay, 4, 1);
      world.setBlock(xco + 31, yco + 6, zco + 40, Blocks.stained_hardened_clay, 4, 1);
      world.setBlock(xco + 32, yco + 6, zco + 40, Blocks.stained_hardened_clay, 4, 1);
      world.setBlock(xco + 33, yco + 6, zco + 40, Blocks.stained_hardened_clay, 4, 1);
      world.setBlock(xco + 34, yco + 6, zco + 40, Blocks.stained_hardened_clay, 4, 1);
      world.setBlock(xco + 35, yco + 6, zco + 40, Blocks.stained_hardened_clay, 4, 1);
      world.setBlock(xco + 36, yco + 6, zco + 40, Blocks.stained_hardened_clay, 4, 1);
      world.setBlock(xco + 37, yco + 6, zco + 40, Blocks.stained_hardened_clay, 4, 1);
      world.setBlock(xco + 38, yco + 6, zco + 40, Blocks.stained_hardened_clay, 4, 1);
      world.setBlock(xco + 39, yco + 6, zco + 40, Blocks.stone, 0, 1);
      world.setBlock(xco + 40, yco + 6, zco + 40, Blocks.stone, 0, 1);
      world.setBlock(xco + 41, yco + 6, zco + 40, Blocks.stone, 0, 1);
      world.setBlock(xco + 42, yco + 6, zco + 40, Blocks.stone, 0, 1);
      world.setBlock(xco + 43, yco + 6, zco + 40, Blocks.stone, 0, 1);
      world.setBlock(xco + 44, yco + 6, zco + 40, Blocks.stained_hardened_clay, 4, 1);
      world.setBlock(xco + 45, yco + 6, zco + 40, Blocks.stone, 0, 1);
      world.setBlock(xco + 46, yco + 6, zco + 40, Blocks.stone, 0, 1);
      world.setBlock(xco + 47, yco + 6, zco + 40, Blocks.stained_hardened_clay, 4, 1);
      world.setBlock(xco + 5, yco + 6, zco + 41, Blocks.stone, 0, 1);
      world.setBlock(xco + 6, yco + 6, zco + 41, Blocks.stone, 0, 1);
      world.setBlock(xco + 7, yco + 6, zco + 41, Blocks.stone, 0, 1);
      world.setBlock(xco + 13, yco + 6, zco + 41, Blocks.stained_hardened_clay, 4, 1);
      world.setBlock(xco + 14, yco + 6, zco + 41, Blocks.stone, 0, 1);
      world.setBlock(xco + 15, yco + 6, zco + 41, Blocks.stone, 0, 1);
      world.setBlock(xco + 16, yco + 6, zco + 41, Blocks.stone, 0, 1);
      world.setBlock(xco + 17, yco + 6, zco + 41, Blocks.stained_hardened_clay, 4, 1);
      world.setBlock(xco + 18, yco + 6, zco + 41, Blocks.stained_hardened_clay, 4, 1);
      world.setBlock(xco + 19, yco + 6, zco + 41, Blocks.stained_hardened_clay, 4, 1);
      world.setBlock(xco + 20, yco + 6, zco + 41, Blocks.stained_hardened_clay, 4, 1);
      world.setBlock(xco + 21, yco + 6, zco + 41, Blocks.stained_hardened_clay, 4, 1);
      world.setBlock(xco + 22, yco + 6, zco + 41, Blocks.stained_hardened_clay, 4, 1);
      world.setBlock(xco + 23, yco + 6, zco + 41, Blocks.stained_hardened_clay, 4, 1);
      world.setBlock(xco + 24, yco + 6, zco + 41, Blocks.glowstone, 0, 1);
      world.setBlock(xco + 25, yco + 6, zco + 41, Blocks.glass, 0, 1);
      world.setBlock(xco + 26, yco + 6, zco + 41, Blocks.stained_glass, 1, 1);
      world.setBlock(xco + 27, yco + 6, zco + 41, Blocks.glass, 0, 1);
      world.setBlock(xco + 28, yco + 6, zco + 41, Blocks.glowstone, 0, 1);
      world.setBlock(xco + 29, yco + 6, zco + 41, Blocks.stained_hardened_clay, 4, 1);
      world.setBlock(xco + 30, yco + 6, zco + 41, Blocks.stained_hardened_clay, 4, 1);
      world.setBlock(xco + 31, yco + 6, zco + 41, Blocks.stained_hardened_clay, 4, 1);
      world.setBlock(xco + 32, yco + 6, zco + 41, Blocks.stained_hardened_clay, 4, 1);
      world.setBlock(xco + 33, yco + 6, zco + 41, Blocks.stained_hardened_clay, 4, 1);
      world.setBlock(xco + 34, yco + 6, zco + 41, Blocks.stained_hardened_clay, 4, 1);
      world.setBlock(xco + 35, yco + 6, zco + 41, Blocks.stained_hardened_clay, 4, 1);
      world.setBlock(xco + 36, yco + 6, zco + 41, Blocks.stained_hardened_clay, 4, 1);
      world.setBlock(xco + 37, yco + 6, zco + 41, Blocks.stone, 0, 1);
      world.setBlock(xco + 38, yco + 6, zco + 41, Blocks.stone, 0, 1);
      world.setBlock(xco + 39, yco + 6, zco + 41, Blocks.stained_hardened_clay, 4, 1);
      world.setBlock(xco + 40, yco + 6, zco + 41, Blocks.stone, 0, 1);
      world.setBlock(xco + 41, yco + 6, zco + 41, Blocks.stone, 0, 1);
      world.setBlock(xco + 42, yco + 6, zco + 41, Blocks.stone, 0, 1);
      world.setBlock(xco + 43, yco + 6, zco + 41, Blocks.stained_hardened_clay, 4, 1);
      world.setBlock(xco + 44, yco + 6, zco + 41, Blocks.stone, 0, 1);
      world.setBlock(xco + 45, yco + 6, zco + 41, Blocks.stone, 0, 1);
      world.setBlock(xco + 46, yco + 6, zco + 41, Blocks.stone, 0, 1);
      world.setBlock(xco + 47, yco + 6, zco + 41, Blocks.stained_hardened_clay, 4, 1);
      world.setBlock(xco + 4, yco + 6, zco + 42, Blocks.stone, 0, 1);
      world.setBlock(xco + 8, yco + 6, zco + 42, Blocks.stone, 0, 1);
      world.setBlock(xco + 13, yco + 6, zco + 42, Blocks.stained_hardened_clay, 4, 1);
      world.setBlock(xco + 14, yco + 6, zco + 42, Blocks.stone, 0, 1);
      world.setBlock(xco + 15, yco + 6, zco + 42, Blocks.stone, 0, 1);
      world.setBlock(xco + 16, yco + 6, zco + 42, Blocks.stained_hardened_clay, 4, 1);
      world.setBlock(xco + 17, yco + 6, zco + 42, Blocks.stained_hardened_clay, 4, 1);
      world.setBlock(xco + 18, yco + 6, zco + 42, Blocks.stained_hardened_clay, 4, 1);
      world.setBlock(xco + 19, yco + 6, zco + 42, Blocks.stained_hardened_clay, 4, 1);
      world.setBlock(xco + 20, yco + 6, zco + 42, Blocks.stained_hardened_clay, 4, 1);
      world.setBlock(xco + 21, yco + 6, zco + 42, Blocks.stained_hardened_clay, 4, 1);
      world.setBlock(xco + 22, yco + 6, zco + 42, Blocks.stained_hardened_clay, 4, 1);
      world.setBlock(xco + 23, yco + 6, zco + 42, Blocks.stained_hardened_clay, 4, 1);
      world.setBlock(xco + 24, yco + 6, zco + 42, Blocks.glowstone, 0, 1);
      world.setBlock(xco + 25, yco + 6, zco + 42, Blocks.glass, 0, 1);
      world.setBlock(xco + 26, yco + 6, zco + 42, Blocks.stained_glass, 1, 1);
      world.setBlock(xco + 27, yco + 6, zco + 42, Blocks.glass, 0, 1);
      world.setBlock(xco + 28, yco + 6, zco + 42, Blocks.glowstone, 0, 1);
      world.setBlock(xco + 29, yco + 6, zco + 42, Blocks.stained_hardened_clay, 4, 1);
      world.setBlock(xco + 30, yco + 6, zco + 42, Blocks.stained_hardened_clay, 4, 1);
      world.setBlock(xco + 31, yco + 6, zco + 42, Blocks.stained_hardened_clay, 4, 1);
      world.setBlock(xco + 32, yco + 6, zco + 42, Blocks.stained_hardened_clay, 4, 1);
      world.setBlock(xco + 33, yco + 6, zco + 42, Blocks.stained_hardened_clay, 4, 1);
      world.setBlock(xco + 34, yco + 6, zco + 42, Blocks.stained_hardened_clay, 4, 1);
      world.setBlock(xco + 35, yco + 6, zco + 42, Blocks.stained_hardened_clay, 4, 1);
      world.setBlock(xco + 36, yco + 6, zco + 42, Blocks.stained_hardened_clay, 4, 1);
      world.setBlock(xco + 37, yco + 6, zco + 42, Blocks.stone, 0, 1);
      world.setBlock(xco + 38, yco + 6, zco + 42, Blocks.stone, 0, 1);
      world.setBlock(xco + 39, yco + 6, zco + 42, Blocks.stone, 0, 1);
      world.setBlock(xco + 40, yco + 6, zco + 42, Blocks.stained_hardened_clay, 4, 1);
      world.setBlock(xco + 41, yco + 6, zco + 42, Blocks.stained_hardened_clay, 4, 1);
      world.setBlock(xco + 42, yco + 6, zco + 42, Blocks.stained_hardened_clay, 4, 1);
      world.setBlock(xco + 43, yco + 6, zco + 42, Blocks.stone, 0, 1);
      world.setBlock(xco + 44, yco + 6, zco + 42, Blocks.stone, 0, 1);
      world.setBlock(xco + 45, yco + 6, zco + 42, Blocks.stone, 0, 1);
      world.setBlock(xco + 46, yco + 6, zco + 42, Blocks.stone, 0, 1);
      world.setBlock(xco + 47, yco + 6, zco + 42, Blocks.stained_hardened_clay, 4, 1);
      world.setBlock(xco + 4, yco + 6, zco + 43, Blocks.stone, 0, 1);
      world.setBlock(xco + 8, yco + 6, zco + 43, Blocks.stone, 0, 1);
      world.setBlock(xco + 13, yco + 6, zco + 43, Blocks.stained_hardened_clay, 4, 1);
      world.setBlock(xco + 14, yco + 6, zco + 43, Blocks.stone, 0, 1);
      world.setBlock(xco + 15, yco + 6, zco + 43, Blocks.stained_hardened_clay, 4, 1);
      world.setBlock(xco + 16, yco + 6, zco + 43, Blocks.stained_hardened_clay, 4, 1);
      world.setBlock(xco + 17, yco + 6, zco + 43, Blocks.stained_hardened_clay, 4, 1);
      world.setBlock(xco + 18, yco + 6, zco + 43, Blocks.stained_hardened_clay, 4, 1);
      world.setBlock(xco + 19, yco + 6, zco + 43, Blocks.stained_hardened_clay, 4, 1);
      world.setBlock(xco + 20, yco + 6, zco + 43, Blocks.stained_hardened_clay, 4, 1);
      world.setBlock(xco + 21, yco + 6, zco + 43, Blocks.stained_hardened_clay, 4, 1);
      world.setBlock(xco + 22, yco + 6, zco + 43, Blocks.stained_hardened_clay, 4, 1);
      world.setBlock(xco + 23, yco + 6, zco + 43, Blocks.lava, 10, 1);
      world.setBlock(xco + 24, yco + 6, zco + 43, Blocks.glowstone, 0, 1);
      world.setBlock(xco + 25, yco + 6, zco + 43, Blocks.glass, 0, 1);
      world.setBlock(xco + 26, yco + 6, zco + 43, Blocks.stained_glass, 1, 1);
      world.setBlock(xco + 27, yco + 6, zco + 43, Blocks.glass, 0, 1);
      world.setBlock(xco + 28, yco + 6, zco + 43, Blocks.glowstone, 0, 1);
      world.setBlock(xco + 29, yco + 6, zco + 43, Blocks.lava, 10, 1);
      world.setBlock(xco + 30, yco + 6, zco + 43, Blocks.stained_hardened_clay, 4, 1);
      world.setBlock(xco + 31, yco + 6, zco + 43, Blocks.stained_hardened_clay, 4, 1);
      world.setBlock(xco + 32, yco + 6, zco + 43, Blocks.stained_hardened_clay, 4, 1);
      world.setBlock(xco + 33, yco + 6, zco + 43, Blocks.stained_hardened_clay, 4, 1);
      world.setBlock(xco + 34, yco + 6, zco + 43, Blocks.stained_hardened_clay, 4, 1);
      world.setBlock(xco + 35, yco + 6, zco + 43, Blocks.stained_hardened_clay, 4, 1);
      world.setBlock(xco + 36, yco + 6, zco + 43, Blocks.stained_hardened_clay, 4, 1);
      world.setBlock(xco + 37, yco + 6, zco + 43, Blocks.stained_hardened_clay, 4, 1);
      world.setBlock(xco + 38, yco + 6, zco + 43, Blocks.stone, 0, 1);
      world.setBlock(xco + 39, yco + 6, zco + 43, Blocks.stone, 0, 1);
      world.setBlock(xco + 40, yco + 6, zco + 43, Blocks.stone, 0, 1);
      world.setBlock(xco + 41, yco + 6, zco + 43, Blocks.stone, 0, 1);
      world.setBlock(xco + 42, yco + 6, zco + 43, Blocks.stone, 0, 1);
      world.setBlock(xco + 43, yco + 6, zco + 43, Blocks.stone, 0, 1);
      world.setBlock(xco + 44, yco + 6, zco + 43, Blocks.stone, 0, 1);
      world.setBlock(xco + 45, yco + 6, zco + 43, Blocks.stone, 0, 1);
      world.setBlock(xco + 46, yco + 6, zco + 43, Blocks.stone, 0, 1);
      world.setBlock(xco + 47, yco + 6, zco + 43, Blocks.stained_hardened_clay, 4, 1);
      world.setBlock(xco + 4, yco + 6, zco + 44, Blocks.stone, 0, 1);
      world.setBlock(xco + 8, yco + 6, zco + 44, Blocks.stone, 0, 1);
      world.setBlock(xco + 13, yco + 6, zco + 44, Blocks.stained_hardened_clay, 4, 1);
      world.setBlock(xco + 14, yco + 6, zco + 44, Blocks.stone, 0, 1);
      world.setBlock(xco + 15, yco + 6, zco + 44, Blocks.stained_hardened_clay, 4, 1);
      world.setBlock(xco + 16, yco + 6, zco + 44, Blocks.stained_hardened_clay, 4, 1);
      world.setBlock(xco + 17, yco + 6, zco + 44, Blocks.stained_hardened_clay, 4, 1);
      world.setBlock(xco + 18, yco + 6, zco + 44, Blocks.stained_hardened_clay, 4, 1);
      world.setBlock(xco + 19, yco + 6, zco + 44, Blocks.stained_hardened_clay, 4, 1);
      world.setBlock(xco + 20, yco + 6, zco + 44, Blocks.stained_hardened_clay, 4, 1);
      world.setBlock(xco + 21, yco + 6, zco + 44, Blocks.stained_hardened_clay, 4, 1);
      world.setBlock(xco + 22, yco + 6, zco + 44, Blocks.stained_hardened_clay, 4, 1);
      world.setBlock(xco + 23, yco + 6, zco + 44, Blocks.lava, 2, 1);
      world.setBlock(xco + 24, yco + 6, zco + 44, Blocks.glowstone, 0, 1);
      world.setBlock(xco + 25, yco + 6, zco + 44, Blocks.glass, 0, 1);
      world.setBlock(xco + 26, yco + 6, zco + 44, Blocks.stained_glass, 1, 1);
      world.setBlock(xco + 27, yco + 6, zco + 44, Blocks.glass, 0, 1);
      world.setBlock(xco + 28, yco + 6, zco + 44, Blocks.glowstone, 0, 1);
      world.setBlock(xco + 29, yco + 6, zco + 44, Blocks.lava, 2, 1);
      world.setBlock(xco + 30, yco + 6, zco + 44, Blocks.stained_hardened_clay, 4, 1);
      world.setBlock(xco + 31, yco + 6, zco + 44, Blocks.stained_hardened_clay, 4, 1);
      world.setBlock(xco + 32, yco + 6, zco + 44, Blocks.stained_hardened_clay, 4, 1);
      world.setBlock(xco + 33, yco + 6, zco + 44, Blocks.stained_hardened_clay, 4, 1);
      world.setBlock(xco + 34, yco + 6, zco + 44, Blocks.stained_hardened_clay, 4, 1);
      world.setBlock(xco + 35, yco + 6, zco + 44, Blocks.stained_hardened_clay, 4, 1);
      world.setBlock(xco + 36, yco + 6, zco + 44, Blocks.stained_hardened_clay, 4, 1);
      world.setBlock(xco + 37, yco + 6, zco + 44, Blocks.stained_hardened_clay, 4, 1);
      world.setBlock(xco + 38, yco + 6, zco + 44, Blocks.stone, 0, 1);
      world.setBlock(xco + 39, yco + 6, zco + 44, Blocks.stone, 0, 1);
      world.setBlock(xco + 40, yco + 6, zco + 44, Blocks.stone, 0, 1);
      world.setBlock(xco + 41, yco + 6, zco + 44, Blocks.stone, 0, 1);
      world.setBlock(xco + 42, yco + 6, zco + 44, Blocks.stone, 0, 1);
      world.setBlock(xco + 43, yco + 6, zco + 44, Blocks.stone, 0, 1);
      world.setBlock(xco + 44, yco + 6, zco + 44, Blocks.stone, 0, 1);
      world.setBlock(xco + 45, yco + 6, zco + 44, Blocks.stone, 0, 1);
      world.setBlock(xco + 46, yco + 6, zco + 44, Blocks.stone, 0, 1);
      world.setBlock(xco + 47, yco + 6, zco + 44, Blocks.stained_hardened_clay, 4, 1);
      world.setBlock(xco + 5, yco + 6, zco + 45, Blocks.stone, 0, 1);
      world.setBlock(xco + 6, yco + 6, zco + 45, Blocks.stone, 0, 1);
      world.setBlock(xco + 7, yco + 6, zco + 45, Blocks.stone, 0, 1);
      world.setBlock(xco + 13, yco + 6, zco + 45, Blocks.stained_hardened_clay, 4, 1);
      world.setBlock(xco + 14, yco + 6, zco + 45, Blocks.stone, 0, 1);
      world.setBlock(xco + 15, yco + 6, zco + 45, Blocks.stained_hardened_clay, 4, 1);
      world.setBlock(xco + 16, yco + 6, zco + 45, Blocks.stained_hardened_clay, 4, 1);
      world.setBlock(xco + 17, yco + 6, zco + 45, Blocks.stained_hardened_clay, 4, 1);
      world.setBlock(xco + 18, yco + 6, zco + 45, Blocks.stained_hardened_clay, 4, 1);
      world.setBlock(xco + 19, yco + 6, zco + 45, Blocks.stained_hardened_clay, 4, 1);
      world.setBlock(xco + 20, yco + 6, zco + 45, Blocks.stained_hardened_clay, 4, 1);
      world.setBlock(xco + 21, yco + 6, zco + 45, Blocks.stained_hardened_clay, 4, 1);
      world.setBlock(xco + 22, yco + 6, zco + 45, Blocks.stained_hardened_clay, 4, 1);
      world.setBlock(xco + 23, yco + 6, zco + 45, Blocks.lava, 10, 1);
      world.setBlock(xco + 24, yco + 6, zco + 45, Blocks.glowstone, 0, 1);
      world.setBlock(xco + 25, yco + 6, zco + 45, Blocks.glass, 0, 1);
      world.setBlock(xco + 26, yco + 6, zco + 45, Blocks.stained_glass, 1, 1);
      world.setBlock(xco + 27, yco + 6, zco + 45, Blocks.glass, 0, 1);
      world.setBlock(xco + 28, yco + 6, zco + 45, Blocks.glowstone, 0, 1);
      world.setBlock(xco + 29, yco + 6, zco + 45, Blocks.lava, 10, 1);
      world.setBlock(xco + 30, yco + 6, zco + 45, Blocks.stained_hardened_clay, 4, 1);
      world.setBlock(xco + 31, yco + 6, zco + 45, Blocks.stained_hardened_clay, 4, 1);
      world.setBlock(xco + 32, yco + 6, zco + 45, Blocks.stained_hardened_clay, 4, 1);
      world.setBlock(xco + 33, yco + 6, zco + 45, Blocks.stained_hardened_clay, 4, 1);
      world.setBlock(xco + 34, yco + 6, zco + 45, Blocks.stained_hardened_clay, 4, 1);
      world.setBlock(xco + 35, yco + 6, zco + 45, Blocks.stained_hardened_clay, 4, 1);
      world.setBlock(xco + 36, yco + 6, zco + 45, Blocks.stained_hardened_clay, 4, 1);
      world.setBlock(xco + 37, yco + 6, zco + 45, Blocks.stained_hardened_clay, 4, 1);
      world.setBlock(xco + 38, yco + 6, zco + 45, Blocks.stone, 0, 1);
      world.setBlock(xco + 39, yco + 6, zco + 45, Blocks.stone, 0, 1);
      world.setBlock(xco + 40, yco + 6, zco + 45, Blocks.stone, 0, 1);
      world.setBlock(xco + 41, yco + 6, zco + 45, Blocks.stone, 0, 1);
      world.setBlock(xco + 42, yco + 6, zco + 45, Blocks.stone, 0, 1);
      world.setBlock(xco + 43, yco + 6, zco + 45, Blocks.stone, 0, 1);
      world.setBlock(xco + 44, yco + 6, zco + 45, Blocks.stone, 0, 1);
      world.setBlock(xco + 45, yco + 6, zco + 45, Blocks.stone, 0, 1);
      world.setBlock(xco + 46, yco + 6, zco + 45, Blocks.stone, 0, 1);
      world.setBlock(xco + 47, yco + 6, zco + 45, Blocks.stained_hardened_clay, 4, 1);
      world.setBlock(xco + 13, yco + 6, zco + 46, Blocks.stained_hardened_clay, 4, 1);
      world.setBlock(xco + 14, yco + 6, zco + 46, Blocks.stone, 0, 1);
      world.setBlock(xco + 15, yco + 6, zco + 46, Blocks.stone, 0, 1);
      world.setBlock(xco + 16, yco + 6, zco + 46, Blocks.stained_hardened_clay, 4, 1);
      world.setBlock(xco + 17, yco + 6, zco + 46, Blocks.stained_hardened_clay, 4, 1);
      world.setBlock(xco + 18, yco + 6, zco + 46, Blocks.stained_hardened_clay, 4, 1);
      world.setBlock(xco + 19, yco + 6, zco + 46, Blocks.stained_hardened_clay, 4, 1);
      world.setBlock(xco + 20, yco + 6, zco + 46, Blocks.stained_hardened_clay, 4, 1);
      world.setBlock(xco + 21, yco + 6, zco + 46, Blocks.stained_hardened_clay, 4, 1);
      world.setBlock(xco + 22, yco + 6, zco + 46, Blocks.stained_hardened_clay, 4, 1);
      world.setBlock(xco + 23, yco + 6, zco + 46, Blocks.stained_hardened_clay, 4, 1);
      world.setBlock(xco + 24, yco + 6, zco + 46, Blocks.glowstone, 0, 1);
      world.setBlock(xco + 25, yco + 6, zco + 46, Blocks.glass, 0, 1);
      world.setBlock(xco + 26, yco + 6, zco + 46, Blocks.stained_glass, 1, 1);
      world.setBlock(xco + 27, yco + 6, zco + 46, Blocks.glass, 0, 1);
      world.setBlock(xco + 28, yco + 6, zco + 46, Blocks.glowstone, 0, 1);
      world.setBlock(xco + 29, yco + 6, zco + 46, Blocks.stained_hardened_clay, 4, 1);
      world.setBlock(xco + 30, yco + 6, zco + 46, Blocks.stained_hardened_clay, 4, 1);
      world.setBlock(xco + 31, yco + 6, zco + 46, Blocks.stained_hardened_clay, 4, 1);
      world.setBlock(xco + 32, yco + 6, zco + 46, Blocks.stained_hardened_clay, 4, 1);
      world.setBlock(xco + 33, yco + 6, zco + 46, Blocks.stained_hardened_clay, 4, 1);
      world.setBlock(xco + 34, yco + 6, zco + 46, Blocks.stained_hardened_clay, 4, 1);
      world.setBlock(xco + 35, yco + 6, zco + 46, Blocks.stained_hardened_clay, 4, 1);
      world.setBlock(xco + 36, yco + 6, zco + 46, Blocks.stained_hardened_clay, 4, 1);
      world.setBlock(xco + 37, yco + 6, zco + 46, Blocks.stone, 0, 1);
      world.setBlock(xco + 38, yco + 6, zco + 46, Blocks.stone, 0, 1);
      world.setBlock(xco + 39, yco + 6, zco + 46, Blocks.stone, 0, 1);
      world.setBlock(xco + 40, yco + 6, zco + 46, Blocks.stone, 0, 1);
      world.setBlock(xco + 41, yco + 6, zco + 46, Blocks.stone, 0, 1);
      world.setBlock(xco + 42, yco + 6, zco + 46, Blocks.stone, 0, 1);
      world.setBlock(xco + 43, yco + 6, zco + 46, Blocks.stone, 0, 1);
      world.setBlock(xco + 44, yco + 6, zco + 46, Blocks.stone, 0, 1);
      world.setBlock(xco + 45, yco + 6, zco + 46, Blocks.stone, 0, 1);
      world.setBlock(xco + 46, yco + 6, zco + 46, Blocks.stone, 0, 1);
      world.setBlock(xco + 47, yco + 6, zco + 46, Blocks.stained_hardened_clay, 4, 1);
      world.setBlock(xco + 13, yco + 6, zco + 47, Blocks.stained_hardened_clay, 4, 1);
      world.setBlock(xco + 14, yco + 6, zco + 47, Blocks.stone, 0, 1);
      world.setBlock(xco + 15, yco + 6, zco + 47, Blocks.stone, 0, 1);
      world.setBlock(xco + 16, yco + 6, zco + 47, Blocks.stained_hardened_clay, 4, 1);
      world.setBlock(xco + 17, yco + 6, zco + 47, Blocks.stained_hardened_clay, 4, 1);
      world.setBlock(xco + 18, yco + 6, zco + 47, Blocks.stained_hardened_clay, 4, 1);
      world.setBlock(xco + 19, yco + 6, zco + 47, Blocks.stained_hardened_clay, 4, 1);
      world.setBlock(xco + 20, yco + 6, zco + 47, Blocks.stained_hardened_clay, 4, 1);
      world.setBlock(xco + 21, yco + 6, zco + 47, Blocks.stained_hardened_clay, 4, 1);
      world.setBlock(xco + 22, yco + 6, zco + 47, Blocks.stained_hardened_clay, 4, 1);
      world.setBlock(xco + 23, yco + 6, zco + 47, Blocks.stained_hardened_clay, 4, 1);
      world.setBlock(xco + 24, yco + 6, zco + 47, Blocks.glowstone, 0, 1);
      world.setBlock(xco + 25, yco + 6, zco + 47, Blocks.glass, 0, 1);
      world.setBlock(xco + 26, yco + 6, zco + 47, Blocks.stained_glass, 1, 1);
      world.setBlock(xco + 27, yco + 6, zco + 47, Blocks.glass, 0, 1);
      world.setBlock(xco + 28, yco + 6, zco + 47, Blocks.glowstone, 0, 1);
      world.setBlock(xco + 29, yco + 6, zco + 47, Blocks.stained_hardened_clay, 4, 1);
      world.setBlock(xco + 30, yco + 6, zco + 47, Blocks.stained_hardened_clay, 4, 1);
      world.setBlock(xco + 31, yco + 6, zco + 47, Blocks.stained_hardened_clay, 4, 1);
      world.setBlock(xco + 32, yco + 6, zco + 47, Blocks.stained_hardened_clay, 4, 1);
      world.setBlock(xco + 33, yco + 6, zco + 47, Blocks.stained_hardened_clay, 4, 1);
      world.setBlock(xco + 34, yco + 6, zco + 47, Blocks.stained_hardened_clay, 4, 1);
      world.setBlock(xco + 35, yco + 6, zco + 47, Blocks.stained_hardened_clay, 4, 1);
      world.setBlock(xco + 36, yco + 6, zco + 47, Blocks.stained_hardened_clay, 4, 1);
      world.setBlock(xco + 37, yco + 6, zco + 47, Blocks.stone, 0, 1);
      world.setBlock(xco + 38, yco + 6, zco + 47, Blocks.stone, 0, 1);
      world.setBlock(xco + 39, yco + 6, zco + 47, Blocks.stone, 0, 1);
      world.setBlock(xco + 40, yco + 6, zco + 47, Blocks.stone, 0, 1);
      world.setBlock(xco + 41, yco + 6, zco + 47, Blocks.stone, 0, 1);
      world.setBlock(xco + 42, yco + 6, zco + 47, Blocks.stone, 0, 1);
      world.setBlock(xco + 43, yco + 6, zco + 47, Blocks.stone, 0, 1);
      world.setBlock(xco + 44, yco + 6, zco + 47, Blocks.stone, 0, 1);
      world.setBlock(xco + 45, yco + 6, zco + 47, Blocks.stone, 0, 1);
      world.setBlock(xco + 46, yco + 6, zco + 47, Blocks.stone, 0, 1);
      world.setBlock(xco + 47, yco + 6, zco + 47, Blocks.stained_hardened_clay, 4, 1);
      world.setBlock(xco + 13, yco + 6, zco + 48, Blocks.stained_hardened_clay, 4, 1);
      world.setBlock(xco + 14, yco + 6, zco + 48, Blocks.stone, 0, 1);
      world.setBlock(xco + 15, yco + 6, zco + 48, Blocks.stained_hardened_clay, 4, 1);
      world.setBlock(xco + 16, yco + 6, zco + 48, Blocks.stained_hardened_clay, 4, 1);
      world.setBlock(xco + 17, yco + 6, zco + 48, Blocks.stained_hardened_clay, 4, 1);
      world.setBlock(xco + 18, yco + 6, zco + 48, Blocks.stained_hardened_clay, 4, 1);
      world.setBlock(xco + 19, yco + 6, zco + 48, Blocks.stained_hardened_clay, 4, 1);
      world.setBlock(xco + 20, yco + 6, zco + 48, Blocks.stained_hardened_clay, 4, 1);
      world.setBlock(xco + 21, yco + 6, zco + 48, Blocks.stained_hardened_clay, 4, 1);
      world.setBlock(xco + 22, yco + 6, zco + 48, Blocks.stained_hardened_clay, 4, 1);
      world.setBlock(xco + 23, yco + 6, zco + 48, Blocks.lava, 10, 1);
      world.setBlock(xco + 24, yco + 6, zco + 48, Blocks.glowstone, 0, 1);
      world.setBlock(xco + 25, yco + 6, zco + 48, Blocks.glass, 0, 1);
      world.setBlock(xco + 26, yco + 6, zco + 48, Blocks.stained_glass, 1, 1);
      world.setBlock(xco + 27, yco + 6, zco + 48, Blocks.glass, 0, 1);
      world.setBlock(xco + 28, yco + 6, zco + 48, Blocks.glowstone, 0, 1);
      world.setBlock(xco + 29, yco + 6, zco + 48, Blocks.lava, 10, 1);
      world.setBlock(xco + 30, yco + 6, zco + 48, Blocks.stained_hardened_clay, 4, 1);
      world.setBlock(xco + 31, yco + 6, zco + 48, Blocks.stained_hardened_clay, 4, 1);
      world.setBlock(xco + 32, yco + 6, zco + 48, Blocks.stained_hardened_clay, 4, 1);
      world.setBlock(xco + 33, yco + 6, zco + 48, Blocks.stained_hardened_clay, 4, 1);
      world.setBlock(xco + 34, yco + 6, zco + 48, Blocks.stained_hardened_clay, 4, 1);
      world.setBlock(xco + 35, yco + 6, zco + 48, Blocks.stained_hardened_clay, 4, 1);
      world.setBlock(xco + 36, yco + 6, zco + 48, Blocks.stained_hardened_clay, 4, 1);
      world.setBlock(xco + 37, yco + 6, zco + 48, Blocks.stained_hardened_clay, 4, 1);
      world.setBlock(xco + 38, yco + 6, zco + 48, Blocks.stone, 0, 1);
      world.setBlock(xco + 39, yco + 6, zco + 48, Blocks.stone, 0, 1);
      world.setBlock(xco + 40, yco + 6, zco + 48, Blocks.stone, 0, 1);
      world.setBlock(xco + 41, yco + 6, zco + 48, Blocks.stone, 0, 1);
      world.setBlock(xco + 42, yco + 6, zco + 48, Blocks.stone, 0, 1);
      world.setBlock(xco + 43, yco + 6, zco + 48, Blocks.stone, 0, 1);
      world.setBlock(xco + 44, yco + 6, zco + 48, Blocks.stone, 0, 1);
      world.setBlock(xco + 45, yco + 6, zco + 48, Blocks.stone, 0, 1);
      world.setBlock(xco + 46, yco + 6, zco + 48, Blocks.stone, 0, 1);
      world.setBlock(xco + 47, yco + 6, zco + 48, Blocks.stained_hardened_clay, 4, 1);
      world.setBlock(xco + 13, yco + 6, zco + 49, Blocks.stained_hardened_clay, 4, 1);
      world.setBlock(xco + 14, yco + 6, zco + 49, Blocks.stone, 0, 1);
      world.setBlock(xco + 15, yco + 6, zco + 49, Blocks.stained_hardened_clay, 4, 1);
      world.setBlock(xco + 16, yco + 6, zco + 49, Blocks.stained_hardened_clay, 4, 1);
      world.setBlock(xco + 17, yco + 6, zco + 49, Blocks.stained_hardened_clay, 4, 1);
      world.setBlock(xco + 18, yco + 6, zco + 49, Blocks.stained_hardened_clay, 4, 1);
      world.setBlock(xco + 19, yco + 6, zco + 49, Blocks.stained_hardened_clay, 4, 1);
      world.setBlock(xco + 20, yco + 6, zco + 49, Blocks.stained_hardened_clay, 4, 1);
      world.setBlock(xco + 21, yco + 6, zco + 49, Blocks.stained_hardened_clay, 4, 1);
      world.setBlock(xco + 22, yco + 6, zco + 49, Blocks.stained_hardened_clay, 4, 1);
      world.setBlock(xco + 23, yco + 6, zco + 49, Blocks.lava, 2, 1);
      world.setBlock(xco + 24, yco + 6, zco + 49, Blocks.glowstone, 0, 1);
      world.setBlock(xco + 25, yco + 6, zco + 49, Blocks.glass, 0, 1);
      world.setBlock(xco + 26, yco + 6, zco + 49, Blocks.stained_glass, 1, 1);
      world.setBlock(xco + 27, yco + 6, zco + 49, Blocks.glass, 0, 1);
      world.setBlock(xco + 28, yco + 6, zco + 49, Blocks.glowstone, 0, 1);
      world.setBlock(xco + 29, yco + 6, zco + 49, Blocks.lava, 2, 1);
      world.setBlock(xco + 30, yco + 6, zco + 49, Blocks.stained_hardened_clay, 4, 1);
      world.setBlock(xco + 31, yco + 6, zco + 49, Blocks.stained_hardened_clay, 4, 1);
      world.setBlock(xco + 32, yco + 6, zco + 49, Blocks.stained_hardened_clay, 4, 1);
      world.setBlock(xco + 33, yco + 6, zco + 49, Blocks.stained_hardened_clay, 4, 1);
      world.setBlock(xco + 34, yco + 6, zco + 49, Blocks.stained_hardened_clay, 4, 1);
      world.setBlock(xco + 35, yco + 6, zco + 49, Blocks.stained_hardened_clay, 4, 1);
      world.setBlock(xco + 36, yco + 6, zco + 49, Blocks.stained_hardened_clay, 4, 1);
      world.setBlock(xco + 37, yco + 6, zco + 49, Blocks.stained_hardened_clay, 4, 1);
      world.setBlock(xco + 38, yco + 6, zco + 49, Blocks.stone, 0, 1);
      world.setBlock(xco + 39, yco + 6, zco + 49, Blocks.stone, 0, 1);
      world.setBlock(xco + 40, yco + 6, zco + 49, Blocks.stone, 0, 1);
      world.setBlock(xco + 41, yco + 6, zco + 49, Blocks.stone, 0, 1);
      world.setBlock(xco + 42, yco + 6, zco + 49, Blocks.stone, 0, 1);
      world.setBlock(xco + 43, yco + 6, zco + 49, Blocks.stone, 0, 1);
      world.setBlock(xco + 44, yco + 6, zco + 49, Blocks.stone, 0, 1);
      world.setBlock(xco + 45, yco + 6, zco + 49, Blocks.stone, 0, 1);
      world.setBlock(xco + 46, yco + 6, zco + 49, Blocks.stone, 0, 1);
      world.setBlock(xco + 47, yco + 6, zco + 49, Blocks.stained_hardened_clay, 4, 1);
      world.setBlock(xco + 13, yco + 6, zco + 50, Blocks.stained_hardened_clay, 4, 1);
      world.setBlock(xco + 14, yco + 6, zco + 50, Blocks.stone, 0, 1);
      world.setBlock(xco + 15, yco + 6, zco + 50, Blocks.stained_hardened_clay, 4, 1);
      world.setBlock(xco + 16, yco + 6, zco + 50, Blocks.stained_hardened_clay, 4, 1);
      world.setBlock(xco + 17, yco + 6, zco + 50, Blocks.stained_hardened_clay, 4, 1);
      world.setBlock(xco + 18, yco + 6, zco + 50, Blocks.stained_hardened_clay, 4, 1);
      world.setBlock(xco + 19, yco + 6, zco + 50, Blocks.stained_hardened_clay, 4, 1);
      world.setBlock(xco + 20, yco + 6, zco + 50, Blocks.stained_hardened_clay, 4, 1);
      world.setBlock(xco + 21, yco + 6, zco + 50, Blocks.stained_hardened_clay, 4, 1);
      world.setBlock(xco + 22, yco + 6, zco + 50, Blocks.stained_hardened_clay, 4, 1);
      world.setBlock(xco + 23, yco + 6, zco + 50, Blocks.lava, 4, 1);
      world.setBlock(xco + 24, yco + 6, zco + 50, Blocks.stained_hardened_clay, 4, 1);
      world.setBlock(xco + 25, yco + 6, zco + 50, Blocks.glass, 0, 1);
      world.setBlock(xco + 26, yco + 6, zco + 50, Blocks.stained_glass, 1, 1);
return true;
  }
}
