package com.slugterra.world.greatForge;
import java.util.Random;

import net.minecraft.block.BlockColored;
import net.minecraft.init.Blocks;
import net.minecraft.util.math.BlockPos;
import net.minecraft.world.World;
public class GreatWesternForgeStructure12 {
public boolean generate(World world, Random par2Random, BlockPos pos) {
      world.setBlockState(pos.add(29, 24, 54), ((BlockColored)Blocks.STAINED_HARDENED_CLAY).getStateFromMeta(4));
      world.setBlockState(pos.add(35, 24, 54), ((BlockColored)Blocks.STAINED_HARDENED_CLAY).getStateFromMeta(4));
      world.setBlockState(pos.add(17, 24, 55), ((BlockColored)Blocks.STAINED_HARDENED_CLAY).getStateFromMeta(4));
      world.setBlockState(pos.add(23, 24, 55), ((BlockColored)Blocks.STAINED_HARDENED_CLAY).getStateFromMeta(4));
      world.setBlockState(pos.add(29, 24, 55), ((BlockColored)Blocks.STAINED_HARDENED_CLAY).getStateFromMeta(4));
      world.setBlockState(pos.add(35, 24, 55), ((BlockColored)Blocks.STAINED_HARDENED_CLAY).getStateFromMeta(4));
      world.setBlockState(pos.add(37, 24, 55), ((BlockColored)Blocks.WOOL).getStateFromMeta(15));
      world.setBlockState(pos.add(18, 24, 56), ((BlockColored)Blocks.STAINED_HARDENED_CLAY).getStateFromMeta(4));
      world.setBlockState(pos.add(22, 24, 56), ((BlockColored)Blocks.STAINED_HARDENED_CLAY).getStateFromMeta(4));
      world.setBlockState(pos.add(30, 24, 56), ((BlockColored)Blocks.STAINED_HARDENED_CLAY).getStateFromMeta(4));
      world.setBlockState(pos.add(34, 24, 56), ((BlockColored)Blocks.STAINED_HARDENED_CLAY).getStateFromMeta(4));
      world.setBlockState(pos.add(38, 24, 56), ((BlockColored)Blocks.STAINED_HARDENED_CLAY).getStateFromMeta(4));
      world.setBlockState(pos.add(39, 24, 56), ((BlockColored)Blocks.WOOL).getStateFromMeta(15));
      world.setBlockState(pos.add(40, 24, 56), ((BlockColored)Blocks.WOOL).getStateFromMeta(15));
      world.setBlockState(pos.add(19, 24, 57), ((BlockColored)Blocks.STAINED_HARDENED_CLAY).getStateFromMeta(4));
      world.setBlockState(pos.add(20, 24, 57), ((BlockColored)Blocks.STAINED_HARDENED_CLAY).getStateFromMeta(4));
      world.setBlockState(pos.add(21, 24, 57), ((BlockColored)Blocks.STAINED_HARDENED_CLAY).getStateFromMeta(4));
      world.setBlockState(pos.add(31, 24, 57), ((BlockColored)Blocks.STAINED_HARDENED_CLAY).getStateFromMeta(4));
      world.setBlockState(pos.add(32, 24, 57), ((BlockColored)Blocks.STAINED_HARDENED_CLAY).getStateFromMeta(4));
      world.setBlockState(pos.add(33, 24, 57), ((BlockColored)Blocks.STAINED_HARDENED_CLAY).getStateFromMeta(4));
      world.setBlockState(pos.add(39, 24, 57), ((BlockColored)Blocks.STAINED_HARDENED_CLAY).getStateFromMeta(4));
      world.setBlockState(pos.add(41, 24, 57), ((BlockColored)Blocks.WOOL).getStateFromMeta(15));
      world.setBlockState(pos.add(40, 24, 58), ((BlockColored)Blocks.STAINED_HARDENED_CLAY).getStateFromMeta(4));
      world.setBlockState(pos.add(42, 24, 58), ((BlockColored)Blocks.WOOL).getStateFromMeta(15));
      world.setBlockState(pos.add(41, 24, 59), ((BlockColored)Blocks.STAINED_HARDENED_CLAY).getStateFromMeta(4));
      world.setBlockState(pos.add(42, 24, 59), ((BlockColored)Blocks.WOOL).getStateFromMeta(15));
      world.setBlockState(pos.add(34, 24, 60), ((BlockColored)Blocks.WOOL).getStateFromMeta(15));
      world.setBlockState(pos.add(35, 24, 60), ((BlockColored)Blocks.WOOL).getStateFromMeta(15));
      world.setBlockState(pos.add(36, 24, 60), ((BlockColored)Blocks.WOOL).getStateFromMeta(15));
      world.setBlockState(pos.add(37, 24, 60), ((BlockColored)Blocks.WOOL).getStateFromMeta(15));
      world.setBlockState(pos.add(42, 24, 60), Blocks.STONE.getDefaultState());
      world.setBlockState(pos.add(43, 24, 60), Blocks.STONE.getDefaultState());
      world.setBlockState(pos.add(44, 24, 60), Blocks.STONE.getDefaultState());
      world.setBlockState(pos.add(45, 24, 60), Blocks.STONE.getDefaultState());
      world.setBlockState(pos.add(33, 24, 61), ((BlockColored)Blocks.WOOL).getStateFromMeta(15));
      world.setBlockState(pos.add(34, 24, 61), ((BlockColored)Blocks.WOOL).getStateFromMeta(15));
      world.setBlockState(pos.add(35, 24, 61), ((BlockColored)Blocks.WOOL).getStateFromMeta(15));
      world.setBlockState(pos.add(36, 24, 61), ((BlockColored)Blocks.WOOL).getStateFromMeta(15));
      world.setBlockState(pos.add(37, 24, 61), ((BlockColored)Blocks.WOOL).getStateFromMeta(15));
      world.setBlockState(pos.add(38, 24, 61), ((BlockColored)Blocks.WOOL).getStateFromMeta(15));
      world.setBlockState(pos.add(41, 24, 61), Blocks.STONE.getDefaultState());
      world.setBlockState(pos.add(46, 24, 61), Blocks.STONE.getDefaultState());
      world.setBlockState(pos.add(33, 24, 62), ((BlockColored)Blocks.WOOL).getStateFromMeta(15));
      world.setBlockState(pos.add(34, 24, 62), ((BlockColored)Blocks.WOOL).getStateFromMeta(15));
      world.setBlockState(pos.add(35, 24, 62), ((BlockColored)Blocks.WOOL).getStateFromMeta(15));
      world.setBlockState(pos.add(36, 24, 62), ((BlockColored)Blocks.WOOL).getStateFromMeta(15));
      world.setBlockState(pos.add(37, 24, 62), ((BlockColored)Blocks.WOOL).getStateFromMeta(15));
      world.setBlockState(pos.add(38, 24, 62), ((BlockColored)Blocks.WOOL).getStateFromMeta(15));
      world.setBlockState(pos.add(40, 24, 62), Blocks.STONE.getDefaultState());
      world.setBlockState(pos.add(47, 24, 62), Blocks.STONE.getDefaultState());
      world.setBlockState(pos.add(33, 24, 63), ((BlockColored)Blocks.WOOL).getStateFromMeta(15));
      world.setBlockState(pos.add(34, 24, 63), ((BlockColored)Blocks.WOOL).getStateFromMeta(15));
      world.setBlockState(pos.add(35, 24, 63), ((BlockColored)Blocks.WOOL).getStateFromMeta(15));
      world.setBlockState(pos.add(36, 24, 63), ((BlockColored)Blocks.WOOL).getStateFromMeta(15));
      world.setBlockState(pos.add(37, 24, 63), ((BlockColored)Blocks.WOOL).getStateFromMeta(15));
      world.setBlockState(pos.add(38, 24, 63), ((BlockColored)Blocks.WOOL).getStateFromMeta(15));
      world.setBlockState(pos.add(40, 24, 63), Blocks.STONE.getDefaultState());
      world.setBlockState(pos.add(47, 24, 63), Blocks.STONE.getDefaultState());
      world.setBlockState(pos.add(33, 24, 64), ((BlockColored)Blocks.WOOL).getStateFromMeta(15));
      world.setBlockState(pos.add(34, 24, 64), ((BlockColored)Blocks.WOOL).getStateFromMeta(15));
      world.setBlockState(pos.add(35, 24, 64), ((BlockColored)Blocks.WOOL).getStateFromMeta(15));
      world.setBlockState(pos.add(36, 24, 64), ((BlockColored)Blocks.WOOL).getStateFromMeta(15));
      world.setBlockState(pos.add(37, 24, 64), ((BlockColored)Blocks.WOOL).getStateFromMeta(15));
      world.setBlockState(pos.add(38, 24, 64), ((BlockColored)Blocks.WOOL).getStateFromMeta(15));
      world.setBlockState(pos.add(40, 24, 64), Blocks.STONE.getDefaultState());
      world.setBlockState(pos.add(47, 24, 64), Blocks.STONE.getDefaultState());
      world.setBlockState(pos.add(34, 24, 65), ((BlockColored)Blocks.WOOL).getStateFromMeta(15));
      world.setBlockState(pos.add(35, 24, 65), ((BlockColored)Blocks.WOOL).getStateFromMeta(15));
      world.setBlockState(pos.add(36, 24, 65), ((BlockColored)Blocks.WOOL).getStateFromMeta(15));
      world.setBlockState(pos.add(37, 24, 65), ((BlockColored)Blocks.WOOL).getStateFromMeta(15));
      world.setBlockState(pos.add(40, 24, 65), Blocks.STONE.getDefaultState());
      world.setBlockState(pos.add(47, 24, 65), Blocks.STONE.getDefaultState());
      world.setBlockState(pos.add(41, 24, 66), Blocks.STONE.getDefaultState());
      world.setBlockState(pos.add(46, 24, 66), Blocks.STONE.getDefaultState());
      world.setBlockState(pos.add(42, 24, 67), Blocks.STONE.getDefaultState());
      world.setBlockState(pos.add(43, 24, 67), Blocks.STONE.getDefaultState());
      world.setBlockState(pos.add(44, 24, 67), Blocks.STONE.getDefaultState());
      world.setBlockState(pos.add(45, 24, 67), Blocks.STONE.getDefaultState());
      world.setBlockState(pos.add(18, 25, 37), ((BlockColored)Blocks.STAINED_HARDENED_CLAY).getStateFromMeta(4));
      world.setBlockState(pos.add(19, 25, 37), ((BlockColored)Blocks.STAINED_HARDENED_CLAY).getStateFromMeta(4));
      world.setBlockState(pos.add(20, 25, 37), ((BlockColored)Blocks.STAINED_HARDENED_CLAY).getStateFromMeta(4));
      world.setBlockState(pos.add(23, 25, 37), ((BlockColored)Blocks.STAINED_HARDENED_CLAY).getStateFromMeta(4));
      world.setBlockState(pos.add(24, 25, 37), ((BlockColored)Blocks.STAINED_HARDENED_CLAY).getStateFromMeta(4));
      world.setBlockState(pos.add(25, 25, 37), ((BlockColored)Blocks.STAINED_HARDENED_CLAY).getStateFromMeta(4));
      world.setBlockState(pos.add(26, 25, 37), ((BlockColored)Blocks.STAINED_HARDENED_CLAY).getStateFromMeta(4));
      world.setBlockState(pos.add(27, 25, 37), ((BlockColored)Blocks.STAINED_HARDENED_CLAY).getStateFromMeta(4));
      world.setBlockState(pos.add(28, 25, 37), ((BlockColored)Blocks.STAINED_HARDENED_CLAY).getStateFromMeta(4));
      world.setBlockState(pos.add(29, 25, 37), ((BlockColored)Blocks.STAINED_HARDENED_CLAY).getStateFromMeta(4));
      world.setBlockState(pos.add(32, 25, 37), ((BlockColored)Blocks.STAINED_HARDENED_CLAY).getStateFromMeta(4));
      world.setBlockState(pos.add(33, 25, 37), ((BlockColored)Blocks.STAINED_HARDENED_CLAY).getStateFromMeta(4));
      world.setBlockState(pos.add(34, 25, 37), ((BlockColored)Blocks.STAINED_HARDENED_CLAY).getStateFromMeta(4));
      world.setBlockState(pos.add(18, 25, 38), ((BlockColored)Blocks.STAINED_HARDENED_CLAY).getStateFromMeta(4));
      world.setBlockState(pos.add(19, 25, 38), ((BlockColored)Blocks.STAINED_HARDENED_CLAY).getStateFromMeta(4));
      world.setBlockState(pos.add(20, 25, 38), ((BlockColored)Blocks.STAINED_HARDENED_CLAY).getStateFromMeta(4));
      world.setBlockState(pos.add(23, 25, 38), Blocks.DIAMOND_BLOCK.getDefaultState());
      world.setBlockState(pos.add(29, 25, 38), Blocks.DIAMOND_BLOCK.getDefaultState());
      world.setBlockState(pos.add(32, 25, 38), ((BlockColored)Blocks.STAINED_HARDENED_CLAY).getStateFromMeta(4));
      world.setBlockState(pos.add(33, 25, 38), ((BlockColored)Blocks.STAINED_HARDENED_CLAY).getStateFromMeta(4));
      world.setBlockState(pos.add(34, 25, 38), ((BlockColored)Blocks.STAINED_HARDENED_CLAY).getStateFromMeta(4));
      world.setBlockState(pos.add(18, 25, 39), ((BlockColored)Blocks.STAINED_HARDENED_CLAY).getStateFromMeta(4));
      world.setBlockState(pos.add(20, 25, 39), ((BlockColored)Blocks.STAINED_HARDENED_CLAY).getStateFromMeta(4));
      world.setBlockState(pos.add(23, 25, 39), Blocks.DIAMOND_BLOCK.getDefaultState());
      world.setBlockState(pos.add(29, 25, 39), Blocks.DIAMOND_BLOCK.getDefaultState());
      world.setBlockState(pos.add(32, 25, 39), ((BlockColored)Blocks.STAINED_HARDENED_CLAY).getStateFromMeta(4));
      world.setBlockState(pos.add(34, 25, 39), ((BlockColored)Blocks.STAINED_HARDENED_CLAY).getStateFromMeta(4));
      world.setBlockState(pos.add(18, 25, 40), ((BlockColored)Blocks.STAINED_HARDENED_CLAY).getStateFromMeta(4));
      world.setBlockState(pos.add(20, 25, 40), ((BlockColored)Blocks.STAINED_HARDENED_CLAY).getStateFromMeta(4));
      world.setBlockState(pos.add(23, 25, 40), Blocks.DIAMOND_BLOCK.getDefaultState());
      world.setBlockState(pos.add(29, 25, 40), Blocks.DIAMOND_BLOCK.getDefaultState());
      world.setBlockState(pos.add(32, 25, 40), ((BlockColored)Blocks.STAINED_HARDENED_CLAY).getStateFromMeta(4));
      world.setBlockState(pos.add(33, 25, 40), ((BlockColored)Blocks.STAINED_HARDENED_CLAY).getStateFromMeta(4));
      world.setBlockState(pos.add(34, 25, 40), ((BlockColored)Blocks.STAINED_HARDENED_CLAY).getStateFromMeta(4));
      world.setBlockState(pos.add(19, 25, 41), Blocks.QUARTZ_BLOCK.getDefaultState());
      world.setBlockState(pos.add(20, 25, 41), Blocks.QUARTZ_BLOCK.getDefaultState());
      world.setBlockState(pos.add(23, 25, 41), ((BlockColored)Blocks.STAINED_HARDENED_CLAY).getStateFromMeta(4));
      world.setBlockState(pos.add(26, 25, 41), Blocks.STONE.getDefaultState());
      world.setBlockState(pos.add(27, 25, 41), Blocks.STONE.getDefaultState());
      world.setBlockState(pos.add(29, 25, 41), ((BlockColored)Blocks.STAINED_HARDENED_CLAY).getStateFromMeta(4));
      world.setBlockState(pos.add(32, 25, 41), Blocks.QUARTZ_BLOCK.getDefaultState());
      world.setBlockState(pos.add(33, 25, 41), Blocks.QUARTZ_BLOCK.getDefaultState());
      world.setBlockState(pos.add(19, 25, 42), Blocks.QUARTZ_BLOCK.getDefaultState());
      world.setBlockState(pos.add(20, 25, 42), Blocks.QUARTZ_BLOCK.getDefaultState());
      world.setBlockState(pos.add(23, 25, 42), ((BlockColored)Blocks.STAINED_HARDENED_CLAY).getStateFromMeta(4));
      world.setBlockState(pos.add(26, 25, 42), Blocks.STONE.getDefaultState());
      world.setBlockState(pos.add(27, 25, 42), Blocks.STONE.getDefaultState());
      world.setBlockState(pos.add(29, 25, 42), ((BlockColored)Blocks.STAINED_HARDENED_CLAY).getStateFromMeta(4));
      world.setBlockState(pos.add(32, 25, 42), Blocks.QUARTZ_BLOCK.getDefaultState());
      world.setBlockState(pos.add(33, 25, 42), Blocks.QUARTZ_BLOCK.getDefaultState());
      world.setBlockState(pos.add(18, 25, 43), ((BlockColored)Blocks.STAINED_HARDENED_CLAY).getStateFromMeta(4));
      world.setBlockState(pos.add(19, 25, 43), ((BlockColored)Blocks.STAINED_HARDENED_CLAY).getStateFromMeta(4));
      world.setBlockState(pos.add(20, 25, 43), ((BlockColored)Blocks.STAINED_HARDENED_CLAY).getStateFromMeta(4));
      world.setBlockState(pos.add(23, 25, 43), Blocks.DIAMOND_BLOCK.getDefaultState());
      world.setBlockState(pos.add(29, 25, 43), Blocks.DIAMOND_BLOCK.getDefaultState());
      world.setBlockState(pos.add(32, 25, 43), ((BlockColored)Blocks.STAINED_HARDENED_CLAY).getStateFromMeta(4));
      world.setBlockState(pos.add(34, 25, 43), ((BlockColored)Blocks.STAINED_HARDENED_CLAY).getStateFromMeta(4));
      world.setBlockState(pos.add(18, 25, 44), ((BlockColored)Blocks.STAINED_HARDENED_CLAY).getStateFromMeta(4));
      world.setBlockState(pos.add(20, 25, 44), ((BlockColored)Blocks.STAINED_HARDENED_CLAY).getStateFromMeta(4));
      world.setBlockState(pos.add(23, 25, 44), Blocks.DIAMOND_BLOCK.getDefaultState());
      world.setBlockState(pos.add(29, 25, 44), Blocks.DIAMOND_BLOCK.getDefaultState());
      world.setBlockState(pos.add(32, 25, 44), ((BlockColored)Blocks.STAINED_HARDENED_CLAY).getStateFromMeta(4));
      world.setBlockState(pos.add(34, 25, 44), ((BlockColored)Blocks.STAINED_HARDENED_CLAY).getStateFromMeta(4));
      world.setBlockState(pos.add(18, 25, 45), ((BlockColored)Blocks.STAINED_HARDENED_CLAY).getStateFromMeta(4));
      world.setBlockState(pos.add(20, 25, 45), ((BlockColored)Blocks.STAINED_HARDENED_CLAY).getStateFromMeta(4));
      world.setBlockState(pos.add(23, 25, 45), Blocks.DIAMOND_BLOCK.getDefaultState());
      world.setBlockState(pos.add(29, 25, 45), Blocks.DIAMOND_BLOCK.getDefaultState());
      world.setBlockState(pos.add(32, 25, 45), ((BlockColored)Blocks.STAINED_HARDENED_CLAY).getStateFromMeta(4));
      world.setBlockState(pos.add(34, 25, 45), ((BlockColored)Blocks.STAINED_HARDENED_CLAY).getStateFromMeta(4));
      world.setBlockState(pos.add(19, 25, 46), Blocks.QUARTZ_BLOCK.getDefaultState());
      world.setBlockState(pos.add(20, 25, 46), Blocks.QUARTZ_BLOCK.getDefaultState());
      world.setBlockState(pos.add(23, 25, 46), ((BlockColored)Blocks.STAINED_HARDENED_CLAY).getStateFromMeta(4));
      world.setBlockState(pos.add(25, 25, 46), Blocks.STONE.getDefaultState());
      world.setBlockState(pos.add(26, 25, 46), Blocks.STONE.getDefaultState());
      world.setBlockState(pos.add(29, 25, 46), ((BlockColored)Blocks.STAINED_HARDENED_CLAY).getStateFromMeta(4));
      world.setBlockState(pos.add(32, 25, 46), Blocks.QUARTZ_BLOCK.getDefaultState());
      world.setBlockState(pos.add(33, 25, 46), Blocks.QUARTZ_BLOCK.getDefaultState());
      world.setBlockState(pos.add(19, 25, 47), Blocks.QUARTZ_BLOCK.getDefaultState());
      world.setBlockState(pos.add(20, 25, 47), Blocks.QUARTZ_BLOCK.getDefaultState());
      world.setBlockState(pos.add(23, 25, 47), ((BlockColored)Blocks.STAINED_HARDENED_CLAY).getStateFromMeta(4));
      world.setBlockState(pos.add(25, 25, 47), Blocks.STONE.getDefaultState());
      world.setBlockState(pos.add(26, 25, 47), Blocks.STONE.getDefaultState());
      world.setBlockState(pos.add(29, 25, 47), ((BlockColored)Blocks.STAINED_HARDENED_CLAY).getStateFromMeta(4));
      world.setBlockState(pos.add(32, 25, 47), Blocks.QUARTZ_BLOCK.getDefaultState());
      world.setBlockState(pos.add(33, 25, 47), Blocks.QUARTZ_BLOCK.getDefaultState());
      world.setBlockState(pos.add(18, 25, 48), ((BlockColored)Blocks.STAINED_HARDENED_CLAY).getStateFromMeta(4));
      world.setBlockState(pos.add(20, 25, 48), ((BlockColored)Blocks.STAINED_HARDENED_CLAY).getStateFromMeta(4));
      world.setBlockState(pos.add(23, 25, 48), Blocks.DIAMOND_BLOCK.getDefaultState());
      world.setBlockState(pos.add(29, 25, 48), Blocks.DIAMOND_BLOCK.getDefaultState());
      world.setBlockState(pos.add(32, 25, 48), ((BlockColored)Blocks.STAINED_HARDENED_CLAY).getStateFromMeta(4));
      world.setBlockState(pos.add(33, 25, 48), ((BlockColored)Blocks.STAINED_HARDENED_CLAY).getStateFromMeta(4));
      world.setBlockState(pos.add(34, 25, 48), ((BlockColored)Blocks.STAINED_HARDENED_CLAY).getStateFromMeta(4));
      world.setBlockState(pos.add(18, 25, 49), ((BlockColored)Blocks.STAINED_HARDENED_CLAY).getStateFromMeta(4));
      world.setBlockState(pos.add(20, 25, 49), ((BlockColored)Blocks.STAINED_HARDENED_CLAY).getStateFromMeta(4));
      world.setBlockState(pos.add(23, 25, 49), Blocks.DIAMOND_BLOCK.getDefaultState());
      world.setBlockState(pos.add(29, 25, 49), Blocks.DIAMOND_BLOCK.getDefaultState());
      world.setBlockState(pos.add(32, 25, 49), ((BlockColored)Blocks.STAINED_HARDENED_CLAY).getStateFromMeta(4));
      world.setBlockState(pos.add(34, 25, 49), ((BlockColored)Blocks.STAINED_HARDENED_CLAY).getStateFromMeta(4));
      world.setBlockState(pos.add(18, 25, 50), ((BlockColored)Blocks.STAINED_HARDENED_CLAY).getStateFromMeta(4));
      world.setBlockState(pos.add(19, 25, 50), ((BlockColored)Blocks.STAINED_HARDENED_CLAY).getStateFromMeta(4));
      world.setBlockState(pos.add(20, 25, 50), ((BlockColored)Blocks.STAINED_HARDENED_CLAY).getStateFromMeta(4));
      world.setBlockState(pos.add(23, 25, 50), Blocks.DIAMOND_BLOCK.getDefaultState());
      world.setBlockState(pos.add(29, 25, 50), Blocks.DIAMOND_BLOCK.getDefaultState());
      world.setBlockState(pos.add(32, 25, 50), ((BlockColored)Blocks.STAINED_HARDENED_CLAY).getStateFromMeta(4));
      world.setBlockState(pos.add(33, 25, 50), ((BlockColored)Blocks.STAINED_HARDENED_CLAY).getStateFromMeta(4));
      world.setBlockState(pos.add(34, 25, 50), ((BlockColored)Blocks.STAINED_HARDENED_CLAY).getStateFromMeta(4));
      world.setBlockState(pos.add(19, 25, 51), ((BlockColored)Blocks.STAINED_HARDENED_CLAY).getStateFromMeta(4));
      world.setBlockState(pos.add(20, 25, 51), ((BlockColored)Blocks.STAINED_HARDENED_CLAY).getStateFromMeta(4));
      world.setBlockState(pos.add(21, 25, 51), ((BlockColored)Blocks.STAINED_HARDENED_CLAY).getStateFromMeta(4));
      world.setBlockState(pos.add(23, 25, 51), ((BlockColored)Blocks.STAINED_HARDENED_CLAY).getStateFromMeta(4));
      world.setBlockState(pos.add(24, 25, 51), ((BlockColored)Blocks.STAINED_HARDENED_CLAY).getStateFromMeta(4));
      world.setBlockState(pos.add(25, 25, 51), ((BlockColored)Blocks.STAINED_HARDENED_CLAY).getStateFromMeta(4));
      world.setBlockState(pos.add(26, 25, 51), ((BlockColored)Blocks.STAINED_HARDENED_CLAY).getStateFromMeta(4));
      world.setBlockState(pos.add(27, 25, 51), ((BlockColored)Blocks.STAINED_HARDENED_CLAY).getStateFromMeta(4));
      world.setBlockState(pos.add(28, 25, 51), ((BlockColored)Blocks.STAINED_HARDENED_CLAY).getStateFromMeta(4));
      world.setBlockState(pos.add(29, 25, 51), ((BlockColored)Blocks.STAINED_HARDENED_CLAY).getStateFromMeta(4));
      world.setBlockState(pos.add(31, 25, 51), ((BlockColored)Blocks.STAINED_HARDENED_CLAY).getStateFromMeta(4));
      world.setBlockState(pos.add(32, 25, 51), ((BlockColored)Blocks.STAINED_HARDENED_CLAY).getStateFromMeta(4));
      world.setBlockState(pos.add(33, 25, 51), ((BlockColored)Blocks.STAINED_HARDENED_CLAY).getStateFromMeta(4));
      world.setBlockState(pos.add(18, 25, 52), ((BlockColored)Blocks.STAINED_HARDENED_CLAY).getStateFromMeta(4));
      world.setBlockState(pos.add(22, 25, 52), ((BlockColored)Blocks.STAINED_HARDENED_CLAY).getStateFromMeta(4));
      world.setBlockState(pos.add(30, 25, 52), ((BlockColored)Blocks.STAINED_HARDENED_CLAY).getStateFromMeta(4));
      world.setBlockState(pos.add(34, 25, 52), ((BlockColored)Blocks.STAINED_HARDENED_CLAY).getStateFromMeta(4));
      world.setBlockState(pos.add(17, 25, 53), ((BlockColored)Blocks.STAINED_HARDENED_CLAY).getStateFromMeta(4));
      world.setBlockState(pos.add(23, 25, 53), ((BlockColored)Blocks.STAINED_HARDENED_CLAY).getStateFromMeta(4));
      world.setBlockState(pos.add(29, 25, 53), ((BlockColored)Blocks.STAINED_HARDENED_CLAY).getStateFromMeta(4));
      world.setBlockState(pos.add(35, 25, 53), ((BlockColored)Blocks.STAINED_HARDENED_CLAY).getStateFromMeta(4));
      world.setBlockState(pos.add(17, 25, 54), ((BlockColored)Blocks.STAINED_HARDENED_CLAY).getStateFromMeta(4));
      world.setBlockState(pos.add(23, 25, 54), ((BlockColored)Blocks.STAINED_HARDENED_CLAY).getStateFromMeta(4));
      world.setBlockState(pos.add(29, 25, 54), ((BlockColored)Blocks.STAINED_HARDENED_CLAY).getStateFromMeta(4));
      world.setBlockState(pos.add(35, 25, 54), ((BlockColored)Blocks.STAINED_HARDENED_CLAY).getStateFromMeta(4));
      world.setBlockState(pos.add(17, 25, 55), ((BlockColored)Blocks.STAINED_HARDENED_CLAY).getStateFromMeta(4));
      world.setBlockState(pos.add(23, 25, 55), ((BlockColored)Blocks.STAINED_HARDENED_CLAY).getStateFromMeta(4));
      world.setBlockState(pos.add(29, 25, 55), ((BlockColored)Blocks.STAINED_HARDENED_CLAY).getStateFromMeta(4));
      world.setBlockState(pos.add(35, 25, 55), ((BlockColored)Blocks.STAINED_HARDENED_CLAY).getStateFromMeta(4));
      world.setBlockState(pos.add(18, 25, 56), ((BlockColored)Blocks.STAINED_HARDENED_CLAY).getStateFromMeta(4));
      world.setBlockState(pos.add(22, 25, 56), ((BlockColored)Blocks.STAINED_HARDENED_CLAY).getStateFromMeta(4));
      world.setBlockState(pos.add(30, 25, 56), ((BlockColored)Blocks.STAINED_HARDENED_CLAY).getStateFromMeta(4));
      world.setBlockState(pos.add(34, 25, 56), ((BlockColored)Blocks.STAINED_HARDENED_CLAY).getStateFromMeta(4));
      world.setBlockState(pos.add(38, 25, 56), ((BlockColored)Blocks.WOOL).getStateFromMeta(15));
      world.setBlockState(pos.add(19, 25, 57), ((BlockColored)Blocks.STAINED_HARDENED_CLAY).getStateFromMeta(4));
      world.setBlockState(pos.add(20, 25, 57), ((BlockColored)Blocks.STAINED_HARDENED_CLAY).getStateFromMeta(4));
      world.setBlockState(pos.add(21, 25, 57), ((BlockColored)Blocks.STAINED_HARDENED_CLAY).getStateFromMeta(4));
      world.setBlockState(pos.add(31, 25, 57), ((BlockColored)Blocks.STAINED_HARDENED_CLAY).getStateFromMeta(4));
      world.setBlockState(pos.add(32, 25, 57), ((BlockColored)Blocks.STAINED_HARDENED_CLAY).getStateFromMeta(4));
      world.setBlockState(pos.add(33, 25, 57), ((BlockColored)Blocks.STAINED_HARDENED_CLAY).getStateFromMeta(4));
      world.setBlockState(pos.add(39, 25, 57), ((BlockColored)Blocks.STAINED_HARDENED_CLAY).getStateFromMeta(4));
      world.setBlockState(pos.add(40, 25, 58), ((BlockColored)Blocks.STAINED_HARDENED_CLAY).getStateFromMeta(4));
      world.setBlockState(pos.add(41, 25, 59), ((BlockColored)Blocks.STAINED_HARDENED_CLAY).getStateFromMeta(4));
      world.setBlockState(pos.add(42, 25, 60), Blocks.STONE.getDefaultState());
      world.setBlockState(pos.add(43, 25, 60), Blocks.STONE.getDefaultState());
      world.setBlockState(pos.add(44, 25, 60), Blocks.STONE.getDefaultState());
      world.setBlockState(pos.add(45, 25, 60), Blocks.STONE.getDefaultState());
      world.setBlockState(pos.add(41, 25, 61), Blocks.STONE.getDefaultState());
      world.setBlockState(pos.add(46, 25, 61), Blocks.STONE.getDefaultState());
      world.setBlockState(pos.add(38, 25, 62), ((BlockColored)Blocks.STAINED_HARDENED_CLAY).getStateFromMeta(4));
      world.setBlockState(pos.add(39, 25, 62), ((BlockColored)Blocks.STAINED_HARDENED_CLAY).getStateFromMeta(4));
      world.setBlockState(pos.add(40, 25, 62), Blocks.STONE.getDefaultState());
      world.setBlockState(pos.add(47, 25, 62), Blocks.STONE.getDefaultState());
      world.setBlockState(pos.add(40, 25, 63), Blocks.STONE.getDefaultState());
      world.setBlockState(pos.add(47, 25, 63), Blocks.STONE.getDefaultState());
      world.setBlockState(pos.add(40, 25, 64), Blocks.STONE.getDefaultState());
      world.setBlockState(pos.add(47, 25, 64), Blocks.STONE.getDefaultState());
      world.setBlockState(pos.add(40, 25, 65), Blocks.STONE.getDefaultState());
      world.setBlockState(pos.add(47, 25, 65), Blocks.STONE.getDefaultState());
      world.setBlockState(pos.add(41, 25, 66), Blocks.STONE.getDefaultState());
      world.setBlockState(pos.add(46, 25, 66), Blocks.STONE.getDefaultState());
      world.setBlockState(pos.add(42, 25, 67), Blocks.STONE.getDefaultState());
      world.setBlockState(pos.add(43, 25, 67), Blocks.STONE.getDefaultState());
      world.setBlockState(pos.add(44, 25, 67), Blocks.STONE.getDefaultState());
      world.setBlockState(pos.add(45, 25, 67), Blocks.STONE.getDefaultState());
      world.setBlockState(pos.add(19, 26, 37), ((BlockColored)Blocks.STAINED_HARDENED_CLAY).getStateFromMeta(4));
      world.setBlockState(pos.add(20, 26, 37), ((BlockColored)Blocks.STAINED_HARDENED_CLAY).getStateFromMeta(4));
      world.setBlockState(pos.add(24, 26, 37), ((BlockColored)Blocks.STAINED_HARDENED_CLAY).getStateFromMeta(4));
      world.setBlockState(pos.add(25, 26, 37), ((BlockColored)Blocks.STAINED_HARDENED_CLAY).getStateFromMeta(4));
      world.setBlockState(pos.add(26, 26, 37), ((BlockColored)Blocks.STAINED_HARDENED_CLAY).getStateFromMeta(4));
      world.setBlockState(pos.add(27, 26, 37), ((BlockColored)Blocks.STAINED_HARDENED_CLAY).getStateFromMeta(4));
      world.setBlockState(pos.add(28, 26, 37), ((BlockColored)Blocks.STAINED_HARDENED_CLAY).getStateFromMeta(4));
      world.setBlockState(pos.add(32, 26, 37), ((BlockColored)Blocks.STAINED_HARDENED_CLAY).getStateFromMeta(4));
      world.setBlockState(pos.add(33, 26, 37), ((BlockColored)Blocks.STAINED_HARDENED_CLAY).getStateFromMeta(4));
      world.setBlockState(pos.add(19, 26, 38), ((BlockColored)Blocks.STAINED_HARDENED_CLAY).getStateFromMeta(4));
      world.setBlockState(pos.add(20, 26, 38), ((BlockColored)Blocks.STAINED_HARDENED_CLAY).getStateFromMeta(4));
      world.setBlockState(pos.add(24, 26, 38), Blocks.DIAMOND_BLOCK.getDefaultState());
      world.setBlockState(pos.add(28, 26, 38), Blocks.DIAMOND_BLOCK.getDefaultState());
      world.setBlockState(pos.add(32, 26, 38), ((BlockColored)Blocks.STAINED_HARDENED_CLAY).getStateFromMeta(4));
      world.setBlockState(pos.add(33, 26, 38), ((BlockColored)Blocks.STAINED_HARDENED_CLAY).getStateFromMeta(4));
      world.setBlockState(pos.add(19, 26, 39), ((BlockColored)Blocks.STAINED_HARDENED_CLAY).getStateFromMeta(4));
      world.setBlockState(pos.add(20, 26, 39), ((BlockColored)Blocks.STAINED_HARDENED_CLAY).getStateFromMeta(4));
      world.setBlockState(pos.add(24, 26, 39), Blocks.DIAMOND_BLOCK.getDefaultState());
      world.setBlockState(pos.add(28, 26, 39), Blocks.DIAMOND_BLOCK.getDefaultState());
      world.setBlockState(pos.add(32, 26, 39), ((BlockColored)Blocks.STAINED_HARDENED_CLAY).getStateFromMeta(4));
      world.setBlockState(pos.add(33, 26, 39), ((BlockColored)Blocks.STAINED_HARDENED_CLAY).getStateFromMeta(4));
      world.setBlockState(pos.add(19, 26, 40), ((BlockColored)Blocks.STAINED_HARDENED_CLAY).getStateFromMeta(4));
      world.setBlockState(pos.add(20, 26, 40), ((BlockColored)Blocks.STAINED_HARDENED_CLAY).getStateFromMeta(4));
      world.setBlockState(pos.add(24, 26, 40), Blocks.DIAMOND_BLOCK.getDefaultState());
      world.setBlockState(pos.add(28, 26, 40), Blocks.DIAMOND_BLOCK.getDefaultState());
      world.setBlockState(pos.add(32, 26, 40), ((BlockColored)Blocks.STAINED_HARDENED_CLAY).getStateFromMeta(4));
      world.setBlockState(pos.add(33, 26, 40), ((BlockColored)Blocks.STAINED_HARDENED_CLAY).getStateFromMeta(4));
      world.setBlockState(pos.add(24, 26, 41), ((BlockColored)Blocks.STAINED_HARDENED_CLAY).getStateFromMeta(4));
      world.setBlockState(pos.add(26, 26, 41), Blocks.STONE.getDefaultState());
      world.setBlockState(pos.add(27, 26, 41), Blocks.STONE.getDefaultState());
      world.setBlockState(pos.add(28, 26, 41), ((BlockColored)Blocks.STAINED_HARDENED_CLAY).getStateFromMeta(4));
      world.setBlockState(pos.add(24, 26, 42), ((BlockColored)Blocks.STAINED_HARDENED_CLAY).getStateFromMeta(4));
      world.setBlockState(pos.add(26, 26, 42), Blocks.STONE.getDefaultState());
      world.setBlockState(pos.add(27, 26, 42), Blocks.STONE.getDefaultState());
      world.setBlockState(pos.add(28, 26, 42), ((BlockColored)Blocks.STAINED_HARDENED_CLAY).getStateFromMeta(4));
      world.setBlockState(pos.add(19, 26, 43), ((BlockColored)Blocks.STAINED_HARDENED_CLAY).getStateFromMeta(4));
      world.setBlockState(pos.add(20, 26, 43), ((BlockColored)Blocks.STAINED_HARDENED_CLAY).getStateFromMeta(4));
      world.setBlockState(pos.add(24, 26, 43), Blocks.DIAMOND_BLOCK.getDefaultState());
      world.setBlockState(pos.add(28, 26, 43), Blocks.DIAMOND_BLOCK.getDefaultState());
      world.setBlockState(pos.add(32, 26, 43), ((BlockColored)Blocks.STAINED_HARDENED_CLAY).getStateFromMeta(4));
      world.setBlockState(pos.add(33, 26, 43), ((BlockColored)Blocks.STAINED_HARDENED_CLAY).getStateFromMeta(4));
      world.setBlockState(pos.add(19, 26, 44), ((BlockColored)Blocks.STAINED_HARDENED_CLAY).getStateFromMeta(4));
      world.setBlockState(pos.add(20, 26, 44), ((BlockColored)Blocks.STAINED_HARDENED_CLAY).getStateFromMeta(4));
      world.setBlockState(pos.add(24, 26, 44), Blocks.DIAMOND_BLOCK.getDefaultState());
      world.setBlockState(pos.add(28, 26, 44), Blocks.DIAMOND_BLOCK.getDefaultState());
      world.setBlockState(pos.add(32, 26, 44), ((BlockColored)Blocks.STAINED_HARDENED_CLAY).getStateFromMeta(4));
      world.setBlockState(pos.add(33, 26, 44), ((BlockColored)Blocks.STAINED_HARDENED_CLAY).getStateFromMeta(4));
      world.setBlockState(pos.add(19, 26, 45), ((BlockColored)Blocks.STAINED_HARDENED_CLAY).getStateFromMeta(4));
      world.setBlockState(pos.add(20, 26, 45), ((BlockColored)Blocks.STAINED_HARDENED_CLAY).getStateFromMeta(4));
      world.setBlockState(pos.add(24, 26, 45), Blocks.DIAMOND_BLOCK.getDefaultState());
      world.setBlockState(pos.add(28, 26, 45), Blocks.DIAMOND_BLOCK.getDefaultState());
      world.setBlockState(pos.add(32, 26, 45), ((BlockColored)Blocks.STAINED_HARDENED_CLAY).getStateFromMeta(4));
      world.setBlockState(pos.add(33, 26, 45), ((BlockColored)Blocks.STAINED_HARDENED_CLAY).getStateFromMeta(4));
      world.setBlockState(pos.add(24, 26, 46), ((BlockColored)Blocks.STAINED_HARDENED_CLAY).getStateFromMeta(4));
      world.setBlockState(pos.add(25, 26, 46), Blocks.STONE.getDefaultState());
      world.setBlockState(pos.add(26, 26, 46), Blocks.STONE.getDefaultState());
      world.setBlockState(pos.add(28, 26, 46), ((BlockColored)Blocks.STAINED_HARDENED_CLAY).getStateFromMeta(4));
      world.setBlockState(pos.add(24, 26, 47), ((BlockColored)Blocks.STAINED_HARDENED_CLAY).getStateFromMeta(4));
      world.setBlockState(pos.add(25, 26, 47), Blocks.STONE.getDefaultState());
      world.setBlockState(pos.add(26, 26, 47), Blocks.STONE.getDefaultState());
      world.setBlockState(pos.add(28, 26, 47), ((BlockColored)Blocks.STAINED_HARDENED_CLAY).getStateFromMeta(4));
      world.setBlockState(pos.add(19, 26, 48), ((BlockColored)Blocks.STAINED_HARDENED_CLAY).getStateFromMeta(4));
      world.setBlockState(pos.add(20, 26, 48), ((BlockColored)Blocks.STAINED_HARDENED_CLAY).getStateFromMeta(4));
      world.setBlockState(pos.add(24, 26, 48), Blocks.DIAMOND_BLOCK.getDefaultState());
      world.setBlockState(pos.add(28, 26, 48), Blocks.DIAMOND_BLOCK.getDefaultState());
      world.setBlockState(pos.add(32, 26, 48), ((BlockColored)Blocks.STAINED_HARDENED_CLAY).getStateFromMeta(4));
      world.setBlockState(pos.add(33, 26, 48), ((BlockColored)Blocks.STAINED_HARDENED_CLAY).getStateFromMeta(4));
      world.setBlockState(pos.add(19, 26, 49), ((BlockColored)Blocks.STAINED_HARDENED_CLAY).getStateFromMeta(4));
      world.setBlockState(pos.add(20, 26, 49), ((BlockColored)Blocks.STAINED_HARDENED_CLAY).getStateFromMeta(4));
      world.setBlockState(pos.add(24, 26, 49), Blocks.DIAMOND_BLOCK.getDefaultState());
      world.setBlockState(pos.add(28, 26, 49), Blocks.DIAMOND_BLOCK.getDefaultState());
      world.setBlockState(pos.add(32, 26, 49), ((BlockColored)Blocks.STAINED_HARDENED_CLAY).getStateFromMeta(4));
      world.setBlockState(pos.add(33, 26, 49), ((BlockColored)Blocks.STAINED_HARDENED_CLAY).getStateFromMeta(4));
      world.setBlockState(pos.add(19, 26, 50), ((BlockColored)Blocks.STAINED_HARDENED_CLAY).getStateFromMeta(4));
      world.setBlockState(pos.add(20, 26, 50), ((BlockColored)Blocks.STAINED_HARDENED_CLAY).getStateFromMeta(4));
      world.setBlockState(pos.add(24, 26, 50), Blocks.DIAMOND_BLOCK.getDefaultState());
      world.setBlockState(pos.add(28, 26, 50), Blocks.DIAMOND_BLOCK.getDefaultState());
      world.setBlockState(pos.add(32, 26, 50), ((BlockColored)Blocks.STAINED_HARDENED_CLAY).getStateFromMeta(4));
      world.setBlockState(pos.add(33, 26, 50), ((BlockColored)Blocks.STAINED_HARDENED_CLAY).getStateFromMeta(4));
      world.setBlockState(pos.add(19, 26, 51), ((BlockColored)Blocks.STAINED_HARDENED_CLAY).getStateFromMeta(4));
      world.setBlockState(pos.add(20, 26, 51), ((BlockColored)Blocks.STAINED_HARDENED_CLAY).getStateFromMeta(4));
      world.setBlockState(pos.add(21, 26, 51), ((BlockColored)Blocks.STAINED_HARDENED_CLAY).getStateFromMeta(4));
      world.setBlockState(pos.add(24, 26, 51), ((BlockColored)Blocks.STAINED_HARDENED_CLAY).getStateFromMeta(4));
      world.setBlockState(pos.add(25, 26, 51), ((BlockColored)Blocks.STAINED_HARDENED_CLAY).getStateFromMeta(4));
      world.setBlockState(pos.add(26, 26, 51), ((BlockColored)Blocks.STAINED_HARDENED_CLAY).getStateFromMeta(4));
      world.setBlockState(pos.add(27, 26, 51), ((BlockColored)Blocks.STAINED_HARDENED_CLAY).getStateFromMeta(4));
      world.setBlockState(pos.add(28, 26, 51), ((BlockColored)Blocks.STAINED_HARDENED_CLAY).getStateFromMeta(4));
      world.setBlockState(pos.add(31, 26, 51), ((BlockColored)Blocks.STAINED_HARDENED_CLAY).getStateFromMeta(4));
      world.setBlockState(pos.add(32, 26, 51), ((BlockColored)Blocks.STAINED_HARDENED_CLAY).getStateFromMeta(4));
      world.setBlockState(pos.add(33, 26, 51), ((BlockColored)Blocks.STAINED_HARDENED_CLAY).getStateFromMeta(4));
      world.setBlockState(pos.add(18, 26, 52), ((BlockColored)Blocks.STAINED_HARDENED_CLAY).getStateFromMeta(4));
      world.setBlockState(pos.add(22, 26, 52), ((BlockColored)Blocks.STAINED_HARDENED_CLAY).getStateFromMeta(4));
      world.setBlockState(pos.add(30, 26, 52), ((BlockColored)Blocks.STAINED_HARDENED_CLAY).getStateFromMeta(4));
      world.setBlockState(pos.add(34, 26, 52), ((BlockColored)Blocks.STAINED_HARDENED_CLAY).getStateFromMeta(4));
      world.setBlockState(pos.add(17, 26, 53), ((BlockColored)Blocks.STAINED_HARDENED_CLAY).getStateFromMeta(4));
      world.setBlockState(pos.add(23, 26, 53), ((BlockColored)Blocks.STAINED_HARDENED_CLAY).getStateFromMeta(4));
      world.setBlockState(pos.add(29, 26, 53), ((BlockColored)Blocks.STAINED_HARDENED_CLAY).getStateFromMeta(4));
      world.setBlockState(pos.add(35, 26, 53), ((BlockColored)Blocks.STAINED_HARDENED_CLAY).getStateFromMeta(4));
      world.setBlockState(pos.add(17, 26, 54), ((BlockColored)Blocks.STAINED_HARDENED_CLAY).getStateFromMeta(4));
      world.setBlockState(pos.add(23, 26, 54), ((BlockColored)Blocks.STAINED_HARDENED_CLAY).getStateFromMeta(4));
      world.setBlockState(pos.add(29, 26, 54), ((BlockColored)Blocks.STAINED_HARDENED_CLAY).getStateFromMeta(4));
      world.setBlockState(pos.add(35, 26, 54), ((BlockColored)Blocks.STAINED_HARDENED_CLAY).getStateFromMeta(4));
      world.setBlockState(pos.add(17, 26, 55), ((BlockColored)Blocks.STAINED_HARDENED_CLAY).getStateFromMeta(4));
      world.setBlockState(pos.add(23, 26, 55), ((BlockColored)Blocks.STAINED_HARDENED_CLAY).getStateFromMeta(4));
      world.setBlockState(pos.add(29, 26, 55), ((BlockColored)Blocks.STAINED_HARDENED_CLAY).getStateFromMeta(4));
      world.setBlockState(pos.add(35, 26, 55), ((BlockColored)Blocks.STAINED_HARDENED_CLAY).getStateFromMeta(4));
      world.setBlockState(pos.add(18, 26, 56), ((BlockColored)Blocks.STAINED_HARDENED_CLAY).getStateFromMeta(4));
      world.setBlockState(pos.add(22, 26, 56), ((BlockColored)Blocks.STAINED_HARDENED_CLAY).getStateFromMeta(4));
      world.setBlockState(pos.add(30, 26, 56), ((BlockColored)Blocks.STAINED_HARDENED_CLAY).getStateFromMeta(4));
      world.setBlockState(pos.add(34, 26, 56), ((BlockColored)Blocks.STAINED_HARDENED_CLAY).getStateFromMeta(4));
      world.setBlockState(pos.add(19, 26, 57), ((BlockColored)Blocks.STAINED_HARDENED_CLAY).getStateFromMeta(4));
      world.setBlockState(pos.add(20, 26, 57), ((BlockColored)Blocks.STAINED_HARDENED_CLAY).getStateFromMeta(4));
      world.setBlockState(pos.add(21, 26, 57), ((BlockColored)Blocks.STAINED_HARDENED_CLAY).getStateFromMeta(4));
      world.setBlockState(pos.add(31, 26, 57), ((BlockColored)Blocks.STAINED_HARDENED_CLAY).getStateFromMeta(4));
      world.setBlockState(pos.add(32, 26, 57), ((BlockColored)Blocks.STAINED_HARDENED_CLAY).getStateFromMeta(4));
      world.setBlockState(pos.add(33, 26, 57), ((BlockColored)Blocks.STAINED_HARDENED_CLAY).getStateFromMeta(4));
      world.setBlockState(pos.add(39, 26, 57), ((BlockColored)Blocks.WOOL).getStateFromMeta(15));
      world.setBlockState(pos.add(40, 26, 58), ((BlockColored)Blocks.WOOL).getStateFromMeta(15));
      world.setBlockState(pos.add(41, 26, 59), ((BlockColored)Blocks.WOOL).getStateFromMeta(15));
      world.setBlockState(pos.add(42, 26, 60), Blocks.STONE.getDefaultState());
      world.setBlockState(pos.add(43, 26, 60), Blocks.STONE.getDefaultState());
      world.setBlockState(pos.add(44, 26, 60), Blocks.STONE.getDefaultState());
      world.setBlockState(pos.add(45, 26, 60), Blocks.STONE.getDefaultState());
      world.setBlockState(pos.add(37, 26, 61), ((BlockColored)Blocks.STAINED_HARDENED_CLAY).getStateFromMeta(4));
      world.setBlockState(pos.add(38, 26, 61), ((BlockColored)Blocks.STAINED_HARDENED_CLAY).getStateFromMeta(4));
      world.setBlockState(pos.add(41, 26, 61), Blocks.STONE.getDefaultState());
      world.setBlockState(pos.add(46, 26, 61), Blocks.STONE.getDefaultState());
      world.setBlockState(pos.add(40, 26, 62), Blocks.STONE.getDefaultState());
      world.setBlockState(pos.add(47, 26, 62), Blocks.STONE.getDefaultState());
      world.setBlockState(pos.add(40, 26, 63), Blocks.STONE.getDefaultState());
      world.setBlockState(pos.add(47, 26, 63), Blocks.STONE.getDefaultState());
      world.setBlockState(pos.add(40, 26, 64), Blocks.STONE.getDefaultState());
      world.setBlockState(pos.add(47, 26, 64), Blocks.STONE.getDefaultState());
      world.setBlockState(pos.add(40, 26, 65), Blocks.STONE.getDefaultState());
      world.setBlockState(pos.add(47, 26, 65), Blocks.STONE.getDefaultState());
      world.setBlockState(pos.add(41, 26, 66), Blocks.STONE.getDefaultState());
      world.setBlockState(pos.add(46, 26, 66), Blocks.STONE.getDefaultState());
      world.setBlockState(pos.add(42, 26, 67), Blocks.STONE.getDefaultState());
      world.setBlockState(pos.add(43, 26, 67), Blocks.STONE.getDefaultState());
      world.setBlockState(pos.add(44, 26, 67), Blocks.STONE.getDefaultState());
      world.setBlockState(pos.add(45, 26, 67), Blocks.STONE.getDefaultState());
      world.setBlockState(pos.add(24, 27, 37), ((BlockColored)Blocks.STAINED_HARDENED_CLAY).getStateFromMeta(4));
      world.setBlockState(pos.add(25, 27, 37), ((BlockColored)Blocks.STAINED_HARDENED_CLAY).getStateFromMeta(4));
      world.setBlockState(pos.add(26, 27, 37), ((BlockColored)Blocks.STAINED_HARDENED_CLAY).getStateFromMeta(4));
      world.setBlockState(pos.add(27, 27, 37), ((BlockColored)Blocks.STAINED_HARDENED_CLAY).getStateFromMeta(4));
      world.setBlockState(pos.add(28, 27, 37), ((BlockColored)Blocks.STAINED_HARDENED_CLAY).getStateFromMeta(4));
      world.setBlockState(pos.add(24, 27, 38), Blocks.DIAMOND_BLOCK.getDefaultState());
      world.setBlockState(pos.add(28, 27, 38), Blocks.DIAMOND_BLOCK.getDefaultState());
      world.setBlockState(pos.add(24, 27, 39), Blocks.DIAMOND_BLOCK.getDefaultState());
      world.setBlockState(pos.add(26, 27, 39), Blocks.GLOWSTONE.getDefaultState());
      world.setBlockState(pos.add(28, 27, 39), Blocks.DIAMOND_BLOCK.getDefaultState());
      world.setBlockState(pos.add(24, 27, 40), Blocks.DIAMOND_BLOCK.getDefaultState());
      world.setBlockState(pos.add(28, 27, 40), Blocks.DIAMOND_BLOCK.getDefaultState());
      world.setBlockState(pos.add(24, 27, 41), ((BlockColored)Blocks.STAINED_HARDENED_CLAY).getStateFromMeta(4));
      world.setBlockState(pos.add(26, 27, 41), Blocks.STONE.getDefaultState());
      world.setBlockState(pos.add(27, 27, 41), Blocks.STONE.getDefaultState());
      world.setBlockState(pos.add(28, 27, 41), ((BlockColored)Blocks.STAINED_HARDENED_CLAY).getStateFromMeta(4));
      world.setBlockState(pos.add(24, 27, 42), ((BlockColored)Blocks.STAINED_HARDENED_CLAY).getStateFromMeta(4));
      world.setBlockState(pos.add(26, 27, 42), Blocks.STONE.getDefaultState());
      world.setBlockState(pos.add(27, 27, 42), Blocks.STONE.getDefaultState());
      world.setBlockState(pos.add(28, 27, 42), ((BlockColored)Blocks.STAINED_HARDENED_CLAY).getStateFromMeta(4));
      world.setBlockState(pos.add(24, 27, 43), Blocks.DIAMOND_BLOCK.getDefaultState());
      world.setBlockState(pos.add(28, 27, 43), Blocks.DIAMOND_BLOCK.getDefaultState());
      world.setBlockState(pos.add(24, 27, 44), Blocks.DIAMOND_BLOCK.getDefaultState());
      world.setBlockState(pos.add(28, 27, 44), Blocks.DIAMOND_BLOCK.getDefaultState());
      world.setBlockState(pos.add(24, 27, 45), Blocks.DIAMOND_BLOCK.getDefaultState());
      world.setBlockState(pos.add(28, 27, 45), Blocks.DIAMOND_BLOCK.getDefaultState());
      world.setBlockState(pos.add(24, 27, 46), ((BlockColored)Blocks.STAINED_HARDENED_CLAY).getStateFromMeta(4));
      world.setBlockState(pos.add(25, 27, 46), Blocks.STONE.getDefaultState());
      world.setBlockState(pos.add(26, 27, 46), Blocks.STONE.getDefaultState());
      world.setBlockState(pos.add(28, 27, 46), ((BlockColored)Blocks.STAINED_HARDENED_CLAY).getStateFromMeta(4));
      world.setBlockState(pos.add(24, 27, 47), ((BlockColored)Blocks.STAINED_HARDENED_CLAY).getStateFromMeta(4));
      world.setBlockState(pos.add(25, 27, 47), Blocks.STONE.getDefaultState());
      world.setBlockState(pos.add(26, 27, 47), Blocks.STONE.getDefaultState());
      world.setBlockState(pos.add(28, 27, 47), ((BlockColored)Blocks.STAINED_HARDENED_CLAY).getStateFromMeta(4));
      world.setBlockState(pos.add(24, 27, 48), Blocks.DIAMOND_BLOCK.getDefaultState());
      world.setBlockState(pos.add(28, 27, 48), Blocks.DIAMOND_BLOCK.getDefaultState());
      world.setBlockState(pos.add(24, 27, 49), Blocks.DIAMOND_BLOCK.getDefaultState());
      world.setBlockState(pos.add(26, 27, 49), Blocks.GLOWSTONE.getDefaultState());
      world.setBlockState(pos.add(28, 27, 49), Blocks.DIAMOND_BLOCK.getDefaultState());
      world.setBlockState(pos.add(24, 27, 50), Blocks.DIAMOND_BLOCK.getDefaultState());
      world.setBlockState(pos.add(28, 27, 50), Blocks.DIAMOND_BLOCK.getDefaultState());
      world.setBlockState(pos.add(19, 27, 51), ((BlockColored)Blocks.STAINED_HARDENED_CLAY).getStateFromMeta(4));
      world.setBlockState(pos.add(20, 27, 51), ((BlockColored)Blocks.STAINED_HARDENED_CLAY).getStateFromMeta(4));
      world.setBlockState(pos.add(21, 27, 51), ((BlockColored)Blocks.STAINED_HARDENED_CLAY).getStateFromMeta(4));
      world.setBlockState(pos.add(24, 27, 51), ((BlockColored)Blocks.STAINED_HARDENED_CLAY).getStateFromMeta(4));
      world.setBlockState(pos.add(25, 27, 51), ((BlockColored)Blocks.STAINED_HARDENED_CLAY).getStateFromMeta(4));
      world.setBlockState(pos.add(26, 27, 51), ((BlockColored)Blocks.STAINED_HARDENED_CLAY).getStateFromMeta(4));
      world.setBlockState(pos.add(27, 27, 51), ((BlockColored)Blocks.STAINED_HARDENED_CLAY).getStateFromMeta(4));
      world.setBlockState(pos.add(28, 27, 51), ((BlockColored)Blocks.STAINED_HARDENED_CLAY).getStateFromMeta(4));
      world.setBlockState(pos.add(31, 27, 51), ((BlockColored)Blocks.STAINED_HARDENED_CLAY).getStateFromMeta(4));
      world.setBlockState(pos.add(32, 27, 51), ((BlockColored)Blocks.STAINED_HARDENED_CLAY).getStateFromMeta(4));
      world.setBlockState(pos.add(33, 27, 51), ((BlockColored)Blocks.STAINED_HARDENED_CLAY).getStateFromMeta(4));
      world.setBlockState(pos.add(18, 27, 52), ((BlockColored)Blocks.STAINED_HARDENED_CLAY).getStateFromMeta(4));
      world.setBlockState(pos.add(22, 27, 52), ((BlockColored)Blocks.STAINED_HARDENED_CLAY).getStateFromMeta(4));
      world.setBlockState(pos.add(30, 27, 52), ((BlockColored)Blocks.STAINED_HARDENED_CLAY).getStateFromMeta(4));
      world.setBlockState(pos.add(34, 27, 52), ((BlockColored)Blocks.STAINED_HARDENED_CLAY).getStateFromMeta(4));
      world.setBlockState(pos.add(17, 27, 53), ((BlockColored)Blocks.STAINED_HARDENED_CLAY).getStateFromMeta(4));
      world.setBlockState(pos.add(23, 27, 53), ((BlockColored)Blocks.STAINED_HARDENED_CLAY).getStateFromMeta(4));
      world.setBlockState(pos.add(29, 27, 53), ((BlockColored)Blocks.STAINED_HARDENED_CLAY).getStateFromMeta(4));
      world.setBlockState(pos.add(35, 27, 53), ((BlockColored)Blocks.STAINED_HARDENED_CLAY).getStateFromMeta(4));
      world.setBlockState(pos.add(17, 27, 54), ((BlockColored)Blocks.STAINED_HARDENED_CLAY).getStateFromMeta(4));
      world.setBlockState(pos.add(23, 27, 54), ((BlockColored)Blocks.STAINED_HARDENED_CLAY).getStateFromMeta(4));
      world.setBlockState(pos.add(29, 27, 54), ((BlockColored)Blocks.STAINED_HARDENED_CLAY).getStateFromMeta(4));
      world.setBlockState(pos.add(35, 27, 54), ((BlockColored)Blocks.STAINED_HARDENED_CLAY).getStateFromMeta(4));
      world.setBlockState(pos.add(17, 27, 55), ((BlockColored)Blocks.STAINED_HARDENED_CLAY).getStateFromMeta(4));
      world.setBlockState(pos.add(23, 27, 55), ((BlockColored)Blocks.STAINED_HARDENED_CLAY).getStateFromMeta(4));
      world.setBlockState(pos.add(29, 27, 55), ((BlockColored)Blocks.STAINED_HARDENED_CLAY).getStateFromMeta(4));
      world.setBlockState(pos.add(35, 27, 55), ((BlockColored)Blocks.STAINED_HARDENED_CLAY).getStateFromMeta(4));
      world.setBlockState(pos.add(18, 27, 56), ((BlockColored)Blocks.STAINED_HARDENED_CLAY).getStateFromMeta(4));
      world.setBlockState(pos.add(22, 27, 56), ((BlockColored)Blocks.STAINED_HARDENED_CLAY).getStateFromMeta(4));
      world.setBlockState(pos.add(30, 27, 56), ((BlockColored)Blocks.STAINED_HARDENED_CLAY).getStateFromMeta(4));
      world.setBlockState(pos.add(34, 27, 56), ((BlockColored)Blocks.STAINED_HARDENED_CLAY).getStateFromMeta(4));
      world.setBlockState(pos.add(19, 27, 57), ((BlockColored)Blocks.STAINED_HARDENED_CLAY).getStateFromMeta(4));
      world.setBlockState(pos.add(20, 27, 57), ((BlockColored)Blocks.STAINED_HARDENED_CLAY).getStateFromMeta(4));
      world.setBlockState(pos.add(21, 27, 57), ((BlockColored)Blocks.STAINED_HARDENED_CLAY).getStateFromMeta(4));
      world.setBlockState(pos.add(31, 27, 57), ((BlockColored)Blocks.STAINED_HARDENED_CLAY).getStateFromMeta(4));
      world.setBlockState(pos.add(32, 27, 57), ((BlockColored)Blocks.STAINED_HARDENED_CLAY).getStateFromMeta(4));
      world.setBlockState(pos.add(33, 27, 57), ((BlockColored)Blocks.STAINED_HARDENED_CLAY).getStateFromMeta(4));
      world.setBlockState(pos.add(34, 27, 57), ((BlockColored)Blocks.STAINED_HARDENED_CLAY).getStateFromMeta(4));
      world.setBlockState(pos.add(34, 27, 58), ((BlockColored)Blocks.STAINED_HARDENED_CLAY).getStateFromMeta(4));
      world.setBlockState(pos.add(35, 27, 58), ((BlockColored)Blocks.STAINED_HARDENED_CLAY).getStateFromMeta(4));
      world.setBlockState(pos.add(35, 27, 59), ((BlockColored)Blocks.STAINED_HARDENED_CLAY).getStateFromMeta(4));
      world.setBlockState(pos.add(36, 27, 59), ((BlockColored)Blocks.STAINED_HARDENED_CLAY).getStateFromMeta(4));
      world.setBlockState(pos.add(36, 27, 60), ((BlockColored)Blocks.STAINED_HARDENED_CLAY).getStateFromMeta(4));
      world.setBlockState(pos.add(37, 27, 60), ((BlockColored)Blocks.STAINED_HARDENED_CLAY).getStateFromMeta(4));
      world.setBlockState(pos.add(42, 27, 61), Blocks.STONE.getDefaultState());
      world.setBlockState(pos.add(43, 27, 61), Blocks.STONE.getDefaultState());
      world.setBlockState(pos.add(44, 27, 61), Blocks.STONE.getDefaultState());
      world.setBlockState(pos.add(45, 27, 61), Blocks.STONE.getDefaultState());
      world.setBlockState(pos.add(41, 27, 62), Blocks.STONE.getDefaultState());
      world.setBlockState(pos.add(46, 27, 62), Blocks.STONE.getDefaultState());
      world.setBlockState(pos.add(41, 27, 63), Blocks.STONE.getDefaultState());
      world.setBlockState(pos.add(46, 27, 63), Blocks.STONE.getDefaultState());
      world.setBlockState(pos.add(41, 27, 64), Blocks.STONE.getDefaultState());
      world.setBlockState(pos.add(46, 27, 64), Blocks.STONE.getDefaultState());
      world.setBlockState(pos.add(41, 27, 65), Blocks.STONE.getDefaultState());
      world.setBlockState(pos.add(46, 27, 65), Blocks.STONE.getDefaultState());
      world.setBlockState(pos.add(42, 27, 66), Blocks.STONE.getDefaultState());
      world.setBlockState(pos.add(43, 27, 66), Blocks.STONE.getDefaultState());
      world.setBlockState(pos.add(44, 27, 66), Blocks.STONE.getDefaultState());
      world.setBlockState(pos.add(45, 27, 66), Blocks.STONE.getDefaultState());
      world.setBlockState(pos.add(25, 28, 37), ((BlockColored)Blocks.STAINED_HARDENED_CLAY).getStateFromMeta(4));
      world.setBlockState(pos.add(26, 28, 37), ((BlockColored)Blocks.STAINED_HARDENED_CLAY).getStateFromMeta(4));
      world.setBlockState(pos.add(27, 28, 37), ((BlockColored)Blocks.STAINED_HARDENED_CLAY).getStateFromMeta(4));
      world.setBlockState(pos.add(25, 28, 38), Blocks.DIAMOND_BLOCK.getDefaultState());
      world.setBlockState(pos.add(26, 28, 38), Blocks.DIAMOND_BLOCK.getDefaultState());
      world.setBlockState(pos.add(27, 28, 38), Blocks.DIAMOND_BLOCK.getDefaultState());
      world.setBlockState(pos.add(25, 28, 39), Blocks.DIAMOND_BLOCK.getDefaultState());
      world.setBlockState(pos.add(26, 28, 39), Blocks.STAINED_GLASS.getStateFromMeta(11));
      world.setBlockState(pos.add(27, 28, 39), Blocks.DIAMOND_BLOCK.getDefaultState());
      world.setBlockState(pos.add(25, 28, 40), Blocks.DIAMOND_BLOCK.getDefaultState());
      world.setBlockState(pos.add(26, 28, 40), Blocks.DIAMOND_BLOCK.getDefaultState());
      world.setBlockState(pos.add(27, 28, 40), Blocks.DIAMOND_BLOCK.getDefaultState());
      world.setBlockState(pos.add(25, 28, 41), ((BlockColored)Blocks.STAINED_HARDENED_CLAY).getStateFromMeta(4));
      world.setBlockState(pos.add(26, 28, 41), Blocks.STONE.getDefaultState());
      world.setBlockState(pos.add(27, 28, 41), Blocks.STONE.getDefaultState());
      world.setBlockState(pos.add(25, 28, 42), ((BlockColored)Blocks.STAINED_HARDENED_CLAY).getStateFromMeta(4));
      world.setBlockState(pos.add(26, 28, 42), Blocks.STONE.getDefaultState());
      world.setBlockState(pos.add(27, 28, 42), Blocks.STONE.getDefaultState());
      world.setBlockState(pos.add(25, 28, 43), Blocks.DIAMOND_BLOCK.getDefaultState());
      world.setBlockState(pos.add(26, 28, 43), Blocks.DIAMOND_BLOCK.getDefaultState());
      world.setBlockState(pos.add(27, 28, 43), Blocks.DIAMOND_BLOCK.getDefaultState());
      world.setBlockState(pos.add(25, 28, 44), Blocks.DIAMOND_BLOCK.getDefaultState());
      world.setBlockState(pos.add(26, 28, 44), Blocks.DIAMOND_BLOCK.getDefaultState());
      world.setBlockState(pos.add(27, 28, 44), Blocks.DIAMOND_BLOCK.getDefaultState());
      world.setBlockState(pos.add(25, 28, 45), Blocks.DIAMOND_BLOCK.getDefaultState());
      world.setBlockState(pos.add(26, 28, 45), Blocks.DIAMOND_BLOCK.getDefaultState());
      world.setBlockState(pos.add(27, 28, 45), Blocks.DIAMOND_BLOCK.getDefaultState());
      world.setBlockState(pos.add(25, 28, 46), Blocks.STONE.getDefaultState());
      world.setBlockState(pos.add(26, 28, 46), Blocks.STONE.getDefaultState());
      world.setBlockState(pos.add(27, 28, 46), ((BlockColored)Blocks.STAINED_HARDENED_CLAY).getStateFromMeta(4));
      world.setBlockState(pos.add(25, 28, 47), Blocks.STONE.getDefaultState());
      world.setBlockState(pos.add(26, 28, 47), Blocks.STONE.getDefaultState());
      world.setBlockState(pos.add(27, 28, 47), ((BlockColored)Blocks.STAINED_HARDENED_CLAY).getStateFromMeta(4));
      world.setBlockState(pos.add(25, 28, 48), Blocks.DIAMOND_BLOCK.getDefaultState());
      world.setBlockState(pos.add(26, 28, 48), Blocks.DIAMOND_BLOCK.getDefaultState());
      world.setBlockState(pos.add(27, 28, 48), Blocks.DIAMOND_BLOCK.getDefaultState());
      world.setBlockState(pos.add(25, 28, 49), Blocks.DIAMOND_BLOCK.getDefaultState());
      world.setBlockState(pos.add(26, 28, 49), Blocks.STAINED_GLASS.getStateFromMeta(11));
      world.setBlockState(pos.add(27, 28, 49), Blocks.DIAMOND_BLOCK.getDefaultState());
      world.setBlockState(pos.add(25, 28, 50), Blocks.DIAMOND_BLOCK.getDefaultState());
      world.setBlockState(pos.add(26, 28, 50), Blocks.DIAMOND_BLOCK.getDefaultState());
      world.setBlockState(pos.add(27, 28, 50), Blocks.DIAMOND_BLOCK.getDefaultState());
      world.setBlockState(pos.add(25, 28, 51), ((BlockColored)Blocks.STAINED_HARDENED_CLAY).getStateFromMeta(4));
      world.setBlockState(pos.add(26, 28, 51), ((BlockColored)Blocks.STAINED_HARDENED_CLAY).getStateFromMeta(4));
      world.setBlockState(pos.add(27, 28, 51), ((BlockColored)Blocks.STAINED_HARDENED_CLAY).getStateFromMeta(4));
      world.setBlockState(pos.add(19, 28, 52), ((BlockColored)Blocks.STAINED_HARDENED_CLAY).getStateFromMeta(4));
      world.setBlockState(pos.add(20, 28, 52), ((BlockColored)Blocks.STAINED_HARDENED_CLAY).getStateFromMeta(4));
      world.setBlockState(pos.add(21, 28, 52), ((BlockColored)Blocks.STAINED_HARDENED_CLAY).getStateFromMeta(4));
      world.setBlockState(pos.add(31, 28, 52), ((BlockColored)Blocks.STAINED_HARDENED_CLAY).getStateFromMeta(4));
      world.setBlockState(pos.add(32, 28, 52), ((BlockColored)Blocks.STAINED_HARDENED_CLAY).getStateFromMeta(4));
      world.setBlockState(pos.add(33, 28, 52), ((BlockColored)Blocks.STAINED_HARDENED_CLAY).getStateFromMeta(4));
      world.setBlockState(pos.add(18, 28, 53), ((BlockColored)Blocks.STAINED_HARDENED_CLAY).getStateFromMeta(4));
      world.setBlockState(pos.add(19, 28, 53), ((BlockColored)Blocks.STAINED_HARDENED_CLAY).getStateFromMeta(4));
      world.setBlockState(pos.add(20, 28, 53), ((BlockColored)Blocks.STAINED_HARDENED_CLAY).getStateFromMeta(4));
      world.setBlockState(pos.add(21, 28, 53), ((BlockColored)Blocks.STAINED_HARDENED_CLAY).getStateFromMeta(4));
      world.setBlockState(pos.add(22, 28, 53), ((BlockColored)Blocks.STAINED_HARDENED_CLAY).getStateFromMeta(4));
      world.setBlockState(pos.add(30, 28, 53), ((BlockColored)Blocks.STAINED_HARDENED_CLAY).getStateFromMeta(4));
      world.setBlockState(pos.add(31, 28, 53), ((BlockColored)Blocks.STAINED_HARDENED_CLAY).getStateFromMeta(4));
      world.setBlockState(pos.add(32, 28, 53), ((BlockColored)Blocks.STAINED_HARDENED_CLAY).getStateFromMeta(4));
      world.setBlockState(pos.add(33, 28, 53), ((BlockColored)Blocks.STAINED_HARDENED_CLAY).getStateFromMeta(4));
      world.setBlockState(pos.add(34, 28, 53), ((BlockColored)Blocks.STAINED_HARDENED_CLAY).getStateFromMeta(4));
      world.setBlockState(pos.add(18, 28, 54), ((BlockColored)Blocks.STAINED_HARDENED_CLAY).getStateFromMeta(4));
      world.setBlockState(pos.add(19, 28, 54), ((BlockColored)Blocks.STAINED_HARDENED_CLAY).getStateFromMeta(4));
      world.setBlockState(pos.add(20, 28, 54), ((BlockColored)Blocks.STAINED_HARDENED_CLAY).getStateFromMeta(4));
      world.setBlockState(pos.add(21, 28, 54), ((BlockColored)Blocks.STAINED_HARDENED_CLAY).getStateFromMeta(4));
      world.setBlockState(pos.add(22, 28, 54), ((BlockColored)Blocks.STAINED_HARDENED_CLAY).getStateFromMeta(4));
      world.setBlockState(pos.add(30, 28, 54), ((BlockColored)Blocks.STAINED_HARDENED_CLAY).getStateFromMeta(4));
      world.setBlockState(pos.add(31, 28, 54), ((BlockColored)Blocks.STAINED_HARDENED_CLAY).getStateFromMeta(4));
      world.setBlockState(pos.add(32, 28, 54), ((BlockColored)Blocks.STAINED_HARDENED_CLAY).getStateFromMeta(4));
      world.setBlockState(pos.add(33, 28, 54), ((BlockColored)Blocks.STAINED_HARDENED_CLAY).getStateFromMeta(4));
      world.setBlockState(pos.add(34, 28, 54), ((BlockColored)Blocks.STAINED_HARDENED_CLAY).getStateFromMeta(4));
      world.setBlockState(pos.add(18, 28, 55), ((BlockColored)Blocks.STAINED_HARDENED_CLAY).getStateFromMeta(4));
      world.setBlockState(pos.add(19, 28, 55), ((BlockColored)Blocks.STAINED_HARDENED_CLAY).getStateFromMeta(4));
      world.setBlockState(pos.add(20, 28, 55), ((BlockColored)Blocks.STAINED_HARDENED_CLAY).getStateFromMeta(4));
      world.setBlockState(pos.add(21, 28, 55), ((BlockColored)Blocks.STAINED_HARDENED_CLAY).getStateFromMeta(4));
      world.setBlockState(pos.add(22, 28, 55), ((BlockColored)Blocks.STAINED_HARDENED_CLAY).getStateFromMeta(4));
      world.setBlockState(pos.add(30, 28, 55), ((BlockColored)Blocks.STAINED_HARDENED_CLAY).getStateFromMeta(4));
      world.setBlockState(pos.add(31, 28, 55), ((BlockColored)Blocks.STAINED_HARDENED_CLAY).getStateFromMeta(4));
      world.setBlockState(pos.add(32, 28, 55), ((BlockColored)Blocks.STAINED_HARDENED_CLAY).getStateFromMeta(4));
      world.setBlockState(pos.add(33, 28, 55), ((BlockColored)Blocks.STAINED_HARDENED_CLAY).getStateFromMeta(4));
      world.setBlockState(pos.add(34, 28, 55), ((BlockColored)Blocks.STAINED_HARDENED_CLAY).getStateFromMeta(4));
      world.setBlockState(pos.add(19, 28, 56), ((BlockColored)Blocks.STAINED_HARDENED_CLAY).getStateFromMeta(4));
      world.setBlockState(pos.add(20, 28, 56), ((BlockColored)Blocks.STAINED_HARDENED_CLAY).getStateFromMeta(4));
      world.setBlockState(pos.add(21, 28, 56), ((BlockColored)Blocks.STAINED_HARDENED_CLAY).getStateFromMeta(4));
      world.setBlockState(pos.add(31, 28, 56), ((BlockColored)Blocks.STAINED_HARDENED_CLAY).getStateFromMeta(4));
      world.setBlockState(pos.add(32, 28, 56), ((BlockColored)Blocks.STAINED_HARDENED_CLAY).getStateFromMeta(4));
      world.setBlockState(pos.add(33, 28, 56), ((BlockColored)Blocks.STAINED_HARDENED_CLAY).getStateFromMeta(4));
      world.setBlockState(pos.add(42, 28, 60), Blocks.STONE.getDefaultState());
      world.setBlockState(pos.add(43, 28, 60), Blocks.STONE.getDefaultState());
      world.setBlockState(pos.add(44, 28, 60), Blocks.STONE.getDefaultState());
      world.setBlockState(pos.add(45, 28, 60), Blocks.STONE.getDefaultState());
      world.setBlockState(pos.add(41, 28, 61), Blocks.STONE.getDefaultState());
      world.setBlockState(pos.add(46, 28, 61), Blocks.STONE.getDefaultState());
      world.setBlockState(pos.add(40, 28, 62), Blocks.STONE.getDefaultState());
      world.setBlockState(pos.add(47, 28, 62), Blocks.STONE.getDefaultState());
      world.setBlockState(pos.add(40, 28, 63), Blocks.STONE.getDefaultState());
      world.setBlockState(pos.add(47, 28, 63), Blocks.STONE.getDefaultState());
      world.setBlockState(pos.add(40, 28, 64), Blocks.STONE.getDefaultState());
      world.setBlockState(pos.add(47, 28, 64), Blocks.STONE.getDefaultState());
      world.setBlockState(pos.add(40, 28, 65), Blocks.STONE.getDefaultState());
      world.setBlockState(pos.add(47, 28, 65), Blocks.STONE.getDefaultState());
      world.setBlockState(pos.add(41, 28, 66), Blocks.STONE.getDefaultState());
      world.setBlockState(pos.add(46, 28, 66), Blocks.STONE.getDefaultState());
      world.setBlockState(pos.add(42, 28, 67), Blocks.STONE.getDefaultState());
      world.setBlockState(pos.add(43, 28, 67), Blocks.STONE.getDefaultState());
      world.setBlockState(pos.add(44, 28, 67), Blocks.STONE.getDefaultState());
      world.setBlockState(pos.add(45, 28, 67), Blocks.STONE.getDefaultState());
      world.setBlockState(pos.add(26, 29, 41), Blocks.STONE.getDefaultState());
      world.setBlockState(pos.add(27, 29, 41), Blocks.STONE.getDefaultState());
      world.setBlockState(pos.add(26, 29, 42), Blocks.STONE.getDefaultState());
      world.setBlockState(pos.add(27, 29, 42), Blocks.STONE.getDefaultState());
      world.setBlockState(pos.add(25, 29, 46), Blocks.STONE.getDefaultState());
      world.setBlockState(pos.add(25, 29, 47), Blocks.STONE.getDefaultState());
      world.setBlockState(pos.add(26, 29, 47), Blocks.STONE.getDefaultState());
      world.setBlockState(pos.add(21, 29, 53), Blocks.NETHER_BRICK_FENCE.getDefaultState());
      world.setBlockState(pos.add(33, 29, 53), Blocks.NETHER_BRICK_FENCE.getDefaultState());
      world.setBlockState(pos.add(19, 29, 54), Blocks.NETHER_BRICK_FENCE.getDefaultState());
      world.setBlockState(pos.add(31, 29, 54), Blocks.NETHER_BRICK_FENCE.getDefaultState());
      world.setBlockState(pos.add(20, 29, 55), Blocks.NETHER_BRICK_FENCE.getDefaultState());
      world.setBlockState(pos.add(32, 29, 55), Blocks.NETHER_BRICK_FENCE.getDefaultState());
      world.setBlockState(pos.add(42, 29, 59), Blocks.DIAMOND_BLOCK.getDefaultState());
      world.setBlockState(pos.add(43, 29, 59), Blocks.STAINED_GLASS.getStateFromMeta(11));
      world.setBlockState(pos.add(44, 29, 59), Blocks.DIAMOND_BLOCK.getDefaultState());
      world.setBlockState(pos.add(45, 29, 59), Blocks.DIAMOND_BLOCK.getDefaultState());
      world.setBlockState(pos.add(41, 29, 60), Blocks.DIAMOND_BLOCK.getDefaultState());
      world.setBlockState(pos.add(42, 29, 60), Blocks.DIAMOND_BLOCK.getDefaultState());
      world.setBlockState(pos.add(43, 29, 60), Blocks.GLOWSTONE.getDefaultState());
      world.setBlockState(pos.add(44, 29, 60), Blocks.DIAMOND_BLOCK.getDefaultState());
      world.setBlockState(pos.add(45, 29, 60), Blocks.DIAMOND_BLOCK.getDefaultState());
      world.setBlockState(pos.add(46, 29, 60), Blocks.DIAMOND_BLOCK.getDefaultState());
      world.setBlockState(pos.add(40, 29, 61), Blocks.DIAMOND_BLOCK.getDefaultState());
      world.setBlockState(pos.add(41, 29, 61), Blocks.DIAMOND_BLOCK.getDefaultState());
      world.setBlockState(pos.add(46, 29, 61), Blocks.GLOWSTONE.getDefaultState());
      world.setBlockState(pos.add(47, 29, 61), Blocks.STAINED_GLASS.getStateFromMeta(11));
      world.setBlockState(pos.add(39, 29, 62), Blocks.DIAMOND_BLOCK.getDefaultState());
      world.setBlockState(pos.add(40, 29, 62), Blocks.DIAMOND_BLOCK.getDefaultState());
      world.setBlockState(pos.add(47, 29, 62), Blocks.DIAMOND_BLOCK.getDefaultState());
      world.setBlockState(pos.add(48, 29, 62), Blocks.DIAMOND_BLOCK.getDefaultState());
      world.setBlockState(pos.add(39, 29, 63), Blocks.STAINED_GLASS.getStateFromMeta(11));
      world.setBlockState(pos.add(40, 29, 63), Blocks.GLOWSTONE.getDefaultState());
      world.setBlockState(pos.add(47, 29, 63), Blocks.DIAMOND_BLOCK.getDefaultState());
      world.setBlockState(pos.add(48, 29, 63), Blocks.DIAMOND_BLOCK.getDefaultState());
      world.setBlockState(pos.add(39, 29, 64), Blocks.DIAMOND_BLOCK.getDefaultState());
      world.setBlockState(pos.add(40, 29, 64), Blocks.DIAMOND_BLOCK.getDefaultState());
      world.setBlockState(pos.add(47, 29, 64), Blocks.GLOWSTONE.getDefaultState());
      world.setBlockState(pos.add(48, 29, 64), Blocks.STAINED_GLASS.getStateFromMeta(11));
      world.setBlockState(pos.add(39, 29, 65), Blocks.DIAMOND_BLOCK.getDefaultState());
      world.setBlockState(pos.add(40, 29, 65), Blocks.DIAMOND_BLOCK.getDefaultState());
      world.setBlockState(pos.add(47, 29, 65), Blocks.DIAMOND_BLOCK.getDefaultState());
      world.setBlockState(pos.add(48, 29, 65), Blocks.DIAMOND_BLOCK.getDefaultState());
      world.setBlockState(pos.add(40, 29, 66), Blocks.STAINED_GLASS.getStateFromMeta(11));
      world.setBlockState(pos.add(41, 29, 66), Blocks.GLOWSTONE.getDefaultState());
      world.setBlockState(pos.add(46, 29, 66), Blocks.DIAMOND_BLOCK.getDefaultState());
      world.setBlockState(pos.add(47, 29, 66), Blocks.DIAMOND_BLOCK.getDefaultState());
      world.setBlockState(pos.add(41, 29, 67), Blocks.DIAMOND_BLOCK.getDefaultState());
      world.setBlockState(pos.add(42, 29, 67), Blocks.DIAMOND_BLOCK.getDefaultState());
      world.setBlockState(pos.add(43, 29, 67), Blocks.DIAMOND_BLOCK.getDefaultState());
      world.setBlockState(pos.add(44, 29, 67), Blocks.DIAMOND_BLOCK.getDefaultState());
      world.setBlockState(pos.add(45, 29, 67), Blocks.GLOWSTONE.getDefaultState());
      world.setBlockState(pos.add(46, 29, 67), Blocks.DIAMOND_BLOCK.getDefaultState());
      world.setBlockState(pos.add(42, 29, 68), Blocks.DIAMOND_BLOCK.getDefaultState());
      world.setBlockState(pos.add(43, 29, 68), Blocks.DIAMOND_BLOCK.getDefaultState());
      world.setBlockState(pos.add(44, 29, 68), Blocks.DIAMOND_BLOCK.getDefaultState());
      world.setBlockState(pos.add(45, 29, 68), Blocks.STAINED_GLASS.getStateFromMeta(11));
      world.setBlockState(pos.add(26, 30, 41), Blocks.STONE.getDefaultState());
      world.setBlockState(pos.add(27, 30, 41), Blocks.STONE.getDefaultState());
      world.setBlockState(pos.add(26, 30, 42), Blocks.STONE.getDefaultState());
      world.setBlockState(pos.add(27, 30, 42), Blocks.STONE.getDefaultState());
      world.setBlockState(pos.add(25, 30, 47), Blocks.STONE.getDefaultState());
      world.setBlockState(pos.add(26, 30, 47), Blocks.STONE.getDefaultState());
      world.setBlockState(pos.add(21, 30, 53), Blocks.NETHER_BRICK_FENCE.getDefaultState());
      world.setBlockState(pos.add(33, 30, 53), Blocks.NETHER_BRICK_FENCE.getDefaultState());
      world.setBlockState(pos.add(19, 30, 54), Blocks.NETHER_BRICK_FENCE.getDefaultState());
      world.setBlockState(pos.add(31, 30, 54), Blocks.NETHER_BRICK_FENCE.getDefaultState());
      world.setBlockState(pos.add(20, 30, 55), Blocks.NETHER_BRICK_FENCE.getDefaultState());
      world.setBlockState(pos.add(32, 30, 55), Blocks.NETHER_BRICK_FENCE.getDefaultState());
      world.setBlockState(pos.add(42, 30, 60), Blocks.STONE.getDefaultState());
      world.setBlockState(pos.add(43, 30, 60), Blocks.STONE.getDefaultState());
      world.setBlockState(pos.add(44, 30, 60), Blocks.STONE.getDefaultState());
      world.setBlockState(pos.add(45, 30, 60), Blocks.STONE.getDefaultState());
      world.setBlockState(pos.add(41, 30, 61), Blocks.STONE.getDefaultState());
      world.setBlockState(pos.add(46, 30, 61), Blocks.STONE.getDefaultState());
      world.setBlockState(pos.add(40, 30, 62), Blocks.STONE.getDefaultState());
      world.setBlockState(pos.add(47, 30, 62), Blocks.STONE.getDefaultState());
      world.setBlockState(pos.add(40, 30, 63), Blocks.STONE.getDefaultState());
      world.setBlockState(pos.add(47, 30, 63), Blocks.STONE.getDefaultState());
      world.setBlockState(pos.add(40, 30, 64), Blocks.STONE.getDefaultState());
      world.setBlockState(pos.add(47, 30, 64), Blocks.STONE.getDefaultState());
      world.setBlockState(pos.add(40, 30, 65), Blocks.STONE.getDefaultState());
      world.setBlockState(pos.add(47, 30, 65), Blocks.STONE.getDefaultState());
      world.setBlockState(pos.add(41, 30, 66), Blocks.STONE.getDefaultState());
      world.setBlockState(pos.add(46, 30, 66), Blocks.STONE.getDefaultState());
      world.setBlockState(pos.add(42, 30, 67), Blocks.STONE.getDefaultState());
      world.setBlockState(pos.add(43, 30, 67), Blocks.STONE.getDefaultState());
      world.setBlockState(pos.add(44, 30, 67), Blocks.STONE.getDefaultState());
      world.setBlockState(pos.add(45, 30, 67), Blocks.STONE.getDefaultState());
      world.setBlockState(pos.add(26, 31, 41), Blocks.STONE.getDefaultState());
      world.setBlockState(pos.add(27, 31, 41), Blocks.STONE.getDefaultState());
      world.setBlockState(pos.add(26, 31, 42), Blocks.STONE.getDefaultState());
      world.setBlockState(pos.add(27, 31, 42), Blocks.STONE.getDefaultState());
      world.setBlockState(pos.add(26, 31, 47), Blocks.STONE.getDefaultState());
      world.setBlockState(pos.add(21, 31, 53), Blocks.NETHER_BRICK_FENCE.getDefaultState());
      world.setBlockState(pos.add(33, 31, 53), Blocks.NETHER_BRICK_FENCE.getDefaultState());
      world.setBlockState(pos.add(19, 31, 54), Blocks.NETHER_BRICK_FENCE.getDefaultState());
      world.setBlockState(pos.add(31, 31, 54), Blocks.NETHER_BRICK_FENCE.getDefaultState());
      world.setBlockState(pos.add(20, 31, 55), Blocks.NETHER_BRICK_FENCE.getDefaultState());
      world.setBlockState(pos.add(32, 31, 55), Blocks.NETHER_BRICK_FENCE.getDefaultState());
      world.setBlockState(pos.add(42, 31, 61), Blocks.STONE.getDefaultState());
      world.setBlockState(pos.add(43, 31, 61), Blocks.STONE.getDefaultState());
      world.setBlockState(pos.add(44, 31, 61), Blocks.STONE.getDefaultState());
      world.setBlockState(pos.add(45, 31, 61), Blocks.STONE.getDefaultState());
      world.setBlockState(pos.add(41, 31, 62), Blocks.STONE.getDefaultState());
      world.setBlockState(pos.add(42, 31, 62), Blocks.STONE.getDefaultState());
      world.setBlockState(pos.add(43, 31, 62), Blocks.STONE.getDefaultState());
      world.setBlockState(pos.add(44, 31, 62), Blocks.STONE.getDefaultState());
      world.setBlockState(pos.add(45, 31, 62), Blocks.STONE.getDefaultState());
      world.setBlockState(pos.add(46, 31, 62), Blocks.STONE.getDefaultState());
      world.setBlockState(pos.add(41, 31, 63), Blocks.STONE.getDefaultState());
      world.setBlockState(pos.add(42, 31, 63), Blocks.STONE.getDefaultState());
      world.setBlockState(pos.add(43, 31, 63), Blocks.STONE.getDefaultState());
      world.setBlockState(pos.add(44, 31, 63), Blocks.STONE.getDefaultState());
      world.setBlockState(pos.add(45, 31, 63), Blocks.STONE.getDefaultState());
      world.setBlockState(pos.add(46, 31, 63), Blocks.STONE.getDefaultState());
      world.setBlockState(pos.add(41, 31, 64), Blocks.STONE.getDefaultState());
      world.setBlockState(pos.add(42, 31, 64), Blocks.STONE.getDefaultState());
      world.setBlockState(pos.add(43, 31, 64), Blocks.STONE.getDefaultState());
      world.setBlockState(pos.add(44, 31, 64), Blocks.STONE.getDefaultState());
      world.setBlockState(pos.add(45, 31, 64), Blocks.STONE.getDefaultState());
      world.setBlockState(pos.add(46, 31, 64), Blocks.STONE.getDefaultState());
      world.setBlockState(pos.add(41, 31, 65), Blocks.STONE.getDefaultState());
      world.setBlockState(pos.add(42, 31, 65), Blocks.STONE.getDefaultState());
      world.setBlockState(pos.add(43, 31, 65), Blocks.STONE.getDefaultState());
      world.setBlockState(pos.add(44, 31, 65), Blocks.STONE.getDefaultState());
      world.setBlockState(pos.add(45, 31, 65), Blocks.STONE.getDefaultState());
      world.setBlockState(pos.add(46, 31, 65), Blocks.STONE.getDefaultState());
      world.setBlockState(pos.add(42, 31, 66), Blocks.STONE.getDefaultState());
      world.setBlockState(pos.add(43, 31, 66), Blocks.STONE.getDefaultState());
      world.setBlockState(pos.add(44, 31, 66), Blocks.STONE.getDefaultState());
      world.setBlockState(pos.add(45, 31, 66), Blocks.STONE.getDefaultState());
      world.setBlockState(pos.add(26, 32, 41), Blocks.STONE.getDefaultState());
      world.setBlockState(pos.add(27, 32, 41), Blocks.STONE.getDefaultState());
      world.setBlockState(pos.add(26, 32, 42), Blocks.STONE.getDefaultState());
      world.setBlockState(pos.add(26, 32, 47), Blocks.STONE.getDefaultState());
      world.setBlockState(pos.add(26, 33, 41), Blocks.STONE.getDefaultState());
      world.setBlockState(pos.add(27, 33, 41), Blocks.STONE.getDefaultState());
      world.setBlockState(pos.add(26, 33, 42), Blocks.STONE.getDefaultState());
      world.setBlockState(pos.add(26, 33, 47), Blocks.STONE.getDefaultState());
      world.setBlockState(pos.add(26, 34, 41), Blocks.STONE.getDefaultState());
      world.setBlockState(pos.add(26, 34, 42), Blocks.STONE.getDefaultState());
      world.setBlockState(pos.add(26, 34, 47), Blocks.STONE.getDefaultState());
      world.setBlockState(pos.add(26, 35, 41), Blocks.STONE.getDefaultState());
      world.setBlockState(pos.add(26, 35, 42), Blocks.STONE.getDefaultState());
      world.setBlockState(pos.add(26, 35, 47), Blocks.STONE.getDefaultState());
      world.setBlockState(pos.add(26, 36, 41), Blocks.STONE.getDefaultState());
      world.setBlockState(pos.add(26, 36, 47), Blocks.STONE.getDefaultState());
      world.setBlockState(pos.add(26, 37, 41), Blocks.STONE.getDefaultState());
      world.setBlockState(pos.add(26, 37, 47), Blocks.STONE.getDefaultState());
      world.setBlockState(pos.add(26, 38, 41), Blocks.STONE.getDefaultState());
      world.setBlockState(pos.add(26, 38, 47), Blocks.STONE.getDefaultState());
      world.setBlockState(pos.add(26, 39, 41), Blocks.STONE.getDefaultState());
      world.setBlockState(pos.add(26, 39, 47), Blocks.STONE.getDefaultState());
      world.setBlockState(pos.add(26, 40, 41), Blocks.STONE.getDefaultState());
      world.setBlockState(pos.add(26, 40, 47), Blocks.STONE.getDefaultState());
return true;
  }
}
