package com.slugterra.world.greatForge;
import java.util.Random;

import net.minecraft.block.BlockColored;
import net.minecraft.block.BlockRedstoneTorch;
import net.minecraft.block.BlockStairs;
import net.minecraft.block.BlockStaticLiquid;
import net.minecraft.init.Blocks;
import net.minecraft.util.math.BlockPos;
import net.minecraft.world.World;

public class GreatWesternForgeStructure8 {
public boolean generate(World world, Random par2Random, BlockPos pos) {
      world.setBlockState(pos.add(20, 11, 44), ((BlockColored)Blocks.STAINED_HARDENED_CLAY).getStateFromMeta(4));
      world.setBlockState(pos.add(21, 11, 44), Blocks.QUARTZ_BLOCK.getDefaultState());
      world.setBlockState(pos.add(22, 11, 44), Blocks.QUARTZ_BLOCK.getDefaultState());
      world.setBlockState(pos.add(30, 11, 44), Blocks.QUARTZ_BLOCK.getDefaultState());
      world.setBlockState(pos.add(31, 11, 44), Blocks.QUARTZ_BLOCK.getDefaultState());
      world.setBlockState(pos.add(32, 11, 44), ((BlockColored)Blocks.STAINED_HARDENED_CLAY).getStateFromMeta(4));
      world.setBlockState(pos.add(37, 11, 44), ((BlockColored)Blocks.STAINED_HARDENED_CLAY).getStateFromMeta(4));
      world.setBlockState(pos.add(5, 11, 45), Blocks.STONE.getDefaultState());
      world.setBlockState(pos.add(6, 11, 45), Blocks.STONE.getDefaultState());
      world.setBlockState(pos.add(7, 11, 45), Blocks.STONE.getDefaultState());
      world.setBlockState(pos.add(15, 11, 45), ((BlockColored)Blocks.STAINED_HARDENED_CLAY).getStateFromMeta(4));
      world.setBlockState(pos.add(20, 11, 45), ((BlockColored)Blocks.STAINED_HARDENED_CLAY).getStateFromMeta(4));
      world.setBlockState(pos.add(21, 11, 45), Blocks.QUARTZ_BLOCK.getDefaultState());
      world.setBlockState(pos.add(22, 11, 45), Blocks.QUARTZ_BLOCK.getDefaultState());
      world.setBlockState(pos.add(23, 11, 45), ((BlockStaticLiquid)Blocks.LAVA).getStateFromMeta(10));
      world.setBlockState(pos.add(29, 11, 45), ((BlockStaticLiquid)Blocks.LAVA).getStateFromMeta(10));
      world.setBlockState(pos.add(30, 11, 45), Blocks.QUARTZ_BLOCK.getDefaultState());
      world.setBlockState(pos.add(31, 11, 45), Blocks.QUARTZ_BLOCK.getDefaultState());
      world.setBlockState(pos.add(32, 11, 45), ((BlockColored)Blocks.STAINED_HARDENED_CLAY).getStateFromMeta(4));
      world.setBlockState(pos.add(37, 11, 45), ((BlockColored)Blocks.STAINED_HARDENED_CLAY).getStateFromMeta(4));
      world.setBlockState(pos.add(16, 11, 46), Blocks.QUARTZ_BLOCK.getDefaultState());
      world.setBlockState(pos.add(17, 11, 46), Blocks.QUARTZ_BLOCK.getDefaultState());
      world.setBlockState(pos.add(18, 11, 46), Blocks.QUARTZ_BLOCK.getDefaultState());
      world.setBlockState(pos.add(19, 11, 46), Blocks.QUARTZ_BLOCK.getDefaultState());
      world.setBlockState(pos.add(20, 11, 46), Blocks.QUARTZ_BLOCK.getDefaultState());
      world.setBlockState(pos.add(21, 11, 46), Blocks.QUARTZ_BLOCK.getDefaultState());
      world.setBlockState(pos.add(22, 11, 46), Blocks.QUARTZ_BLOCK.getDefaultState());
      world.setBlockState(pos.add(23, 11, 46), Blocks.STONE.getDefaultState());
      world.setBlockState(pos.add(29, 11, 46), Blocks.STONE.getDefaultState());
      world.setBlockState(pos.add(30, 11, 46), Blocks.QUARTZ_BLOCK.getDefaultState());
      world.setBlockState(pos.add(31, 11, 46), Blocks.QUARTZ_BLOCK.getDefaultState());
      world.setBlockState(pos.add(32, 11, 46), Blocks.QUARTZ_BLOCK.getDefaultState());
      world.setBlockState(pos.add(36, 11, 46), Blocks.QUARTZ_BLOCK.getDefaultState());
      world.setBlockState(pos.add(16, 11, 47), Blocks.QUARTZ_BLOCK.getDefaultState());
      world.setBlockState(pos.add(17, 11, 47), Blocks.QUARTZ_BLOCK.getDefaultState());
      world.setBlockState(pos.add(18, 11, 47), Blocks.QUARTZ_BLOCK.getDefaultState());
      world.setBlockState(pos.add(19, 11, 47), Blocks.QUARTZ_BLOCK.getDefaultState());
      world.setBlockState(pos.add(20, 11, 47), Blocks.QUARTZ_BLOCK.getDefaultState());
      world.setBlockState(pos.add(21, 11, 47), Blocks.QUARTZ_BLOCK.getDefaultState());
      world.setBlockState(pos.add(22, 11, 47), Blocks.QUARTZ_BLOCK.getDefaultState());
      world.setBlockState(pos.add(23, 11, 47), Blocks.STONE.getDefaultState());
      world.setBlockState(pos.add(29, 11, 47), Blocks.STONE.getDefaultState());
      world.setBlockState(pos.add(30, 11, 47), Blocks.QUARTZ_BLOCK.getDefaultState());
      world.setBlockState(pos.add(31, 11, 47), Blocks.QUARTZ_BLOCK.getDefaultState());
      world.setBlockState(pos.add(32, 11, 47), Blocks.QUARTZ_BLOCK.getDefaultState());
      world.setBlockState(pos.add(36, 11, 47), Blocks.QUARTZ_BLOCK.getDefaultState());
      world.setBlockState(pos.add(15, 11, 48), ((BlockColored)Blocks.STAINED_HARDENED_CLAY).getStateFromMeta(4));
      world.setBlockState(pos.add(20, 11, 48), ((BlockColored)Blocks.STAINED_HARDENED_CLAY).getStateFromMeta(4));
      world.setBlockState(pos.add(21, 11, 48), Blocks.QUARTZ_BLOCK.getDefaultState());
      world.setBlockState(pos.add(22, 11, 48), Blocks.QUARTZ_BLOCK.getDefaultState());
      world.setBlockState(pos.add(23, 11, 48), ((BlockStaticLiquid)Blocks.LAVA).getStateFromMeta(10));
      world.setBlockState(pos.add(29, 11, 48), ((BlockStaticLiquid)Blocks.LAVA).getStateFromMeta(10));
      world.setBlockState(pos.add(30, 11, 48), Blocks.QUARTZ_BLOCK.getDefaultState());
      world.setBlockState(pos.add(31, 11, 48), Blocks.QUARTZ_BLOCK.getDefaultState());
      world.setBlockState(pos.add(32, 11, 48), ((BlockColored)Blocks.STAINED_HARDENED_CLAY).getStateFromMeta(4));
      world.setBlockState(pos.add(37, 11, 48), ((BlockColored)Blocks.STAINED_HARDENED_CLAY).getStateFromMeta(4));
      world.setBlockState(pos.add(15, 11, 49), ((BlockColored)Blocks.STAINED_HARDENED_CLAY).getStateFromMeta(4));
      world.setBlockState(pos.add(20, 11, 49), ((BlockColored)Blocks.STAINED_HARDENED_CLAY).getStateFromMeta(4));
      world.setBlockState(pos.add(21, 11, 49), Blocks.QUARTZ_BLOCK.getDefaultState());
      world.setBlockState(pos.add(22, 11, 49), Blocks.QUARTZ_BLOCK.getDefaultState());
      world.setBlockState(pos.add(30, 11, 49), Blocks.QUARTZ_BLOCK.getDefaultState());
      world.setBlockState(pos.add(31, 11, 49), Blocks.QUARTZ_BLOCK.getDefaultState());
      world.setBlockState(pos.add(32, 11, 49), ((BlockColored)Blocks.STAINED_HARDENED_CLAY).getStateFromMeta(4));
      world.setBlockState(pos.add(37, 11, 49), ((BlockColored)Blocks.STAINED_HARDENED_CLAY).getStateFromMeta(4));
      world.setBlockState(pos.add(15, 11, 50), ((BlockColored)Blocks.STAINED_HARDENED_CLAY).getStateFromMeta(4));
      world.setBlockState(pos.add(16, 11, 50), ((BlockColored)Blocks.STAINED_HARDENED_CLAY).getStateFromMeta(4));
      world.setBlockState(pos.add(17, 11, 50), ((BlockColored)Blocks.STAINED_HARDENED_CLAY).getStateFromMeta(4));
      world.setBlockState(pos.add(18, 11, 50), ((BlockColored)Blocks.STAINED_HARDENED_CLAY).getStateFromMeta(4));
      world.setBlockState(pos.add(19, 11, 50), ((BlockColored)Blocks.STAINED_HARDENED_CLAY).getStateFromMeta(4));
      world.setBlockState(pos.add(20, 11, 50), ((BlockColored)Blocks.STAINED_HARDENED_CLAY).getStateFromMeta(4));
      world.setBlockState(pos.add(21, 11, 50), Blocks.QUARTZ_BLOCK.getDefaultState());
      world.setBlockState(pos.add(22, 11, 50), Blocks.QUARTZ_BLOCK.getDefaultState());
      world.setBlockState(pos.add(30, 11, 50), Blocks.QUARTZ_BLOCK.getDefaultState());
      world.setBlockState(pos.add(31, 11, 50), Blocks.QUARTZ_BLOCK.getDefaultState());
      world.setBlockState(pos.add(32, 11, 50), ((BlockColored)Blocks.STAINED_HARDENED_CLAY).getStateFromMeta(4));
      world.setBlockState(pos.add(33, 11, 50), ((BlockColored)Blocks.STAINED_HARDENED_CLAY).getStateFromMeta(4));
      world.setBlockState(pos.add(34, 11, 50), ((BlockColored)Blocks.STAINED_HARDENED_CLAY).getStateFromMeta(4));
      world.setBlockState(pos.add(35, 11, 50), ((BlockColored)Blocks.STAINED_HARDENED_CLAY).getStateFromMeta(4));
      world.setBlockState(pos.add(36, 11, 50), ((BlockColored)Blocks.STAINED_HARDENED_CLAY).getStateFromMeta(4));
      world.setBlockState(pos.add(37, 11, 50), ((BlockColored)Blocks.STAINED_HARDENED_CLAY).getStateFromMeta(4));
      world.setBlockState(pos.add(18, 11, 51), ((BlockColored)Blocks.STAINED_HARDENED_CLAY).getStateFromMeta(4));
      world.setBlockState(pos.add(19, 11, 51), ((BlockColored)Blocks.STAINED_HARDENED_CLAY).getStateFromMeta(4));
      world.setBlockState(pos.add(20, 11, 51), ((BlockColored)Blocks.STAINED_HARDENED_CLAY).getStateFromMeta(4));
      world.setBlockState(pos.add(21, 11, 51), ((BlockColored)Blocks.STAINED_HARDENED_CLAY).getStateFromMeta(4));
      world.setBlockState(pos.add(30, 11, 51), ((BlockColored)Blocks.STAINED_HARDENED_CLAY).getStateFromMeta(4));
      world.setBlockState(pos.add(31, 11, 51), ((BlockColored)Blocks.STAINED_HARDENED_CLAY).getStateFromMeta(4));
      world.setBlockState(pos.add(32, 11, 51), ((BlockColored)Blocks.STAINED_HARDENED_CLAY).getStateFromMeta(4));
      world.setBlockState(pos.add(33, 11, 51), ((BlockColored)Blocks.STAINED_HARDENED_CLAY).getStateFromMeta(4));
      world.setBlockState(pos.add(34, 11, 51), ((BlockColored)Blocks.STAINED_HARDENED_CLAY).getStateFromMeta(4));
      world.setBlockState(pos.add(17, 11, 52), ((BlockColored)Blocks.STAINED_HARDENED_CLAY).getStateFromMeta(4));
      world.setBlockState(pos.add(18, 11, 52), ((BlockColored)Blocks.STAINED_HARDENED_CLAY).getStateFromMeta(4));
      world.setBlockState(pos.add(22, 11, 52), ((BlockColored)Blocks.STAINED_HARDENED_CLAY).getStateFromMeta(4));
      world.setBlockState(pos.add(29, 11, 52), ((BlockColored)Blocks.STAINED_HARDENED_CLAY).getStateFromMeta(4));
      world.setBlockState(pos.add(30, 11, 52), ((BlockColored)Blocks.STAINED_HARDENED_CLAY).getStateFromMeta(4));
      world.setBlockState(pos.add(34, 11, 52), ((BlockColored)Blocks.STAINED_HARDENED_CLAY).getStateFromMeta(4));
      world.setBlockState(pos.add(35, 11, 52), ((BlockColored)Blocks.STAINED_HARDENED_CLAY).getStateFromMeta(4));
      world.setBlockState(pos.add(16, 11, 53), ((BlockColored)Blocks.STAINED_HARDENED_CLAY).getStateFromMeta(4));
      world.setBlockState(pos.add(17, 11, 53), ((BlockColored)Blocks.STAINED_HARDENED_CLAY).getStateFromMeta(4));
      world.setBlockState(pos.add(23, 11, 53), ((BlockColored)Blocks.STAINED_HARDENED_CLAY).getStateFromMeta(4));
      world.setBlockState(pos.add(24, 11, 53), ((BlockColored)Blocks.STAINED_HARDENED_CLAY).getStateFromMeta(4));
      world.setBlockState(pos.add(25, 11, 53), ((BlockRedstoneTorch)Blocks.REDSTONE_TORCH).getStateFromMeta(1));
      world.setBlockState(pos.add(27, 11, 53), ((BlockRedstoneTorch)Blocks.REDSTONE_TORCH).getStateFromMeta(2));
      world.setBlockState(pos.add(28, 11, 53), ((BlockColored)Blocks.STAINED_HARDENED_CLAY).getStateFromMeta(4));
      world.setBlockState(pos.add(29, 11, 53), ((BlockColored)Blocks.STAINED_HARDENED_CLAY).getStateFromMeta(4));
      world.setBlockState(pos.add(35, 11, 53), ((BlockColored)Blocks.STAINED_HARDENED_CLAY).getStateFromMeta(4));
      world.setBlockState(pos.add(36, 11, 53), ((BlockColored)Blocks.STAINED_HARDENED_CLAY).getStateFromMeta(4));
      world.setBlockState(pos.add(16, 11, 54), ((BlockColored)Blocks.STAINED_HARDENED_CLAY).getStateFromMeta(4));
      world.setBlockState(pos.add(17, 11, 54), ((BlockColored)Blocks.STAINED_HARDENED_CLAY).getStateFromMeta(4));
      world.setBlockState(pos.add(23, 11, 54), ((BlockColored)Blocks.STAINED_HARDENED_CLAY).getStateFromMeta(4));
      world.setBlockState(pos.add(24, 11, 54), ((BlockColored)Blocks.STAINED_HARDENED_CLAY).getStateFromMeta(4));
      world.setBlockState(pos.add(28, 11, 54), ((BlockColored)Blocks.STAINED_HARDENED_CLAY).getStateFromMeta(4));
      world.setBlockState(pos.add(29, 11, 54), ((BlockColored)Blocks.STAINED_HARDENED_CLAY).getStateFromMeta(4));
      world.setBlockState(pos.add(35, 11, 54), ((BlockColored)Blocks.STAINED_HARDENED_CLAY).getStateFromMeta(4));
      world.setBlockState(pos.add(36, 11, 54), ((BlockColored)Blocks.STAINED_HARDENED_CLAY).getStateFromMeta(4));
      world.setBlockState(pos.add(16, 11, 55), ((BlockColored)Blocks.STAINED_HARDENED_CLAY).getStateFromMeta(4));
      world.setBlockState(pos.add(17, 11, 55), ((BlockColored)Blocks.STAINED_HARDENED_CLAY).getStateFromMeta(4));
      world.setBlockState(pos.add(23, 11, 55), ((BlockColored)Blocks.STAINED_HARDENED_CLAY).getStateFromMeta(4));
      world.setBlockState(pos.add(24, 11, 55), ((BlockColored)Blocks.STAINED_HARDENED_CLAY).getStateFromMeta(4));
      world.setBlockState(pos.add(28, 11, 55), ((BlockColored)Blocks.STAINED_HARDENED_CLAY).getStateFromMeta(4));
      world.setBlockState(pos.add(29, 11, 55), ((BlockColored)Blocks.STAINED_HARDENED_CLAY).getStateFromMeta(4));
      world.setBlockState(pos.add(35, 11, 55), ((BlockColored)Blocks.STAINED_HARDENED_CLAY).getStateFromMeta(4));
      world.setBlockState(pos.add(36, 11, 55), ((BlockColored)Blocks.STAINED_HARDENED_CLAY).getStateFromMeta(4));
      world.setBlockState(pos.add(37, 11, 55), ((BlockColored)Blocks.STAINED_HARDENED_CLAY).getStateFromMeta(4));
      world.setBlockState(pos.add(17, 11, 56), ((BlockColored)Blocks.STAINED_HARDENED_CLAY).getStateFromMeta(4));
      world.setBlockState(pos.add(18, 11, 56), ((BlockColored)Blocks.STAINED_HARDENED_CLAY).getStateFromMeta(4));
      world.setBlockState(pos.add(22, 11, 56), ((BlockColored)Blocks.STAINED_HARDENED_CLAY).getStateFromMeta(4));
      world.setBlockState(pos.add(23, 11, 56), ((BlockColored)Blocks.STAINED_HARDENED_CLAY).getStateFromMeta(4));
      world.setBlockState(pos.add(24, 11, 56), Blocks.NETHER_BRICK_FENCE.getDefaultState());
      world.setBlockState(pos.add(25, 11, 56), ((BlockStairs)Blocks.NETHER_BRICK_STAIRS).getStateFromMeta(2));
      world.setBlockState(pos.add(26, 11, 56), ((BlockStairs)Blocks.NETHER_BRICK_STAIRS).getStateFromMeta(2));
      world.setBlockState(pos.add(27, 11, 56), ((BlockStairs)Blocks.NETHER_BRICK_STAIRS).getStateFromMeta(2));
      world.setBlockState(pos.add(28, 11, 56), Blocks.NETHER_BRICK_FENCE.getDefaultState());
      world.setBlockState(pos.add(29, 11, 56), ((BlockColored)Blocks.STAINED_HARDENED_CLAY).getStateFromMeta(4));
      world.setBlockState(pos.add(30, 11, 56), ((BlockColored)Blocks.STAINED_HARDENED_CLAY).getStateFromMeta(4));
      world.setBlockState(pos.add(34, 11, 56), ((BlockColored)Blocks.STAINED_HARDENED_CLAY).getStateFromMeta(4));
      world.setBlockState(pos.add(35, 11, 56), ((BlockColored)Blocks.STAINED_HARDENED_CLAY).getStateFromMeta(4));
      world.setBlockState(pos.add(38, 11, 56), ((BlockColored)Blocks.STAINED_HARDENED_CLAY).getStateFromMeta(4));
      world.setBlockState(pos.add(39, 11, 56), ((BlockColored)Blocks.WOOL).getStateFromMeta(15));
      world.setBlockState(pos.add(40, 11, 56), ((BlockColored)Blocks.WOOL).getStateFromMeta(15));
      world.setBlockState(pos.add(18, 11, 57), ((BlockColored)Blocks.STAINED_HARDENED_CLAY).getStateFromMeta(4));
      world.setBlockState(pos.add(19, 11, 57), ((BlockColored)Blocks.STAINED_HARDENED_CLAY).getStateFromMeta(4));
      world.setBlockState(pos.add(20, 11, 57), ((BlockColored)Blocks.STAINED_HARDENED_CLAY).getStateFromMeta(4));
      world.setBlockState(pos.add(21, 11, 57), ((BlockColored)Blocks.STAINED_HARDENED_CLAY).getStateFromMeta(4));
      world.setBlockState(pos.add(22, 11, 57), ((BlockColored)Blocks.STAINED_HARDENED_CLAY).getStateFromMeta(4));
      world.setBlockState(pos.add(29, 11, 57), Blocks.STONE.getDefaultState());
      world.setBlockState(pos.add(30, 11, 57), ((BlockColored)Blocks.STAINED_HARDENED_CLAY).getStateFromMeta(4));
      world.setBlockState(pos.add(31, 11, 57), ((BlockColored)Blocks.STAINED_HARDENED_CLAY).getStateFromMeta(4));
      world.setBlockState(pos.add(32, 11, 57), ((BlockColored)Blocks.STAINED_HARDENED_CLAY).getStateFromMeta(4));
      world.setBlockState(pos.add(33, 11, 57), ((BlockColored)Blocks.STAINED_HARDENED_CLAY).getStateFromMeta(4));
      world.setBlockState(pos.add(34, 11, 57), ((BlockColored)Blocks.STAINED_HARDENED_CLAY).getStateFromMeta(4));
      world.setBlockState(pos.add(39, 11, 57), ((BlockColored)Blocks.STAINED_HARDENED_CLAY).getStateFromMeta(4));
      world.setBlockState(pos.add(41, 11, 57), ((BlockColored)Blocks.WOOL).getStateFromMeta(15));
      world.setBlockState(pos.add(19, 11, 58), ((BlockColored)Blocks.STAINED_HARDENED_CLAY).getStateFromMeta(4));
      world.setBlockState(pos.add(20, 11, 58), ((BlockColored)Blocks.STAINED_HARDENED_CLAY).getStateFromMeta(4));
      world.setBlockState(pos.add(21, 11, 58), ((BlockColored)Blocks.STAINED_HARDENED_CLAY).getStateFromMeta(4));
      world.setBlockState(pos.add(31, 11, 58), ((BlockColored)Blocks.STAINED_HARDENED_CLAY).getStateFromMeta(4));
      world.setBlockState(pos.add(32, 11, 58), ((BlockColored)Blocks.STAINED_HARDENED_CLAY).getStateFromMeta(4));
      world.setBlockState(pos.add(33, 11, 58), ((BlockColored)Blocks.STAINED_HARDENED_CLAY).getStateFromMeta(4));
      world.setBlockState(pos.add(40, 11, 58), ((BlockColored)Blocks.STAINED_HARDENED_CLAY).getStateFromMeta(4));
      world.setBlockState(pos.add(42, 11, 58), ((BlockColored)Blocks.WOOL).getStateFromMeta(15));
      world.setBlockState(pos.add(34, 11, 59), ((BlockColored)Blocks.WOOL).getStateFromMeta(15));
      world.setBlockState(pos.add(35, 11, 59), ((BlockColored)Blocks.WOOL).getStateFromMeta(15));
      world.setBlockState(pos.add(36, 11, 59), ((BlockColored)Blocks.WOOL).getStateFromMeta(15));
      world.setBlockState(pos.add(37, 11, 59), ((BlockColored)Blocks.WOOL).getStateFromMeta(15));
      world.setBlockState(pos.add(41, 11, 59), ((BlockColored)Blocks.STAINED_HARDENED_CLAY).getStateFromMeta(4));
      world.setBlockState(pos.add(42, 11, 59), ((BlockColored)Blocks.WOOL).getStateFromMeta(15));
      world.setBlockState(pos.add(33, 11, 60), ((BlockColored)Blocks.WOOL).getStateFromMeta(15));
      world.setBlockState(pos.add(38, 11, 60), ((BlockColored)Blocks.WOOL).getStateFromMeta(15));
      world.setBlockState(pos.add(42, 11, 60), Blocks.STONE.getDefaultState());
      world.setBlockState(pos.add(43, 11, 60), Blocks.STONE.getDefaultState());
      world.setBlockState(pos.add(44, 11, 60), Blocks.STONE.getDefaultState());
      world.setBlockState(pos.add(45, 11, 60), Blocks.STONE.getDefaultState());
      world.setBlockState(pos.add(32, 11, 61), ((BlockColored)Blocks.WOOL).getStateFromMeta(15));
      world.setBlockState(pos.add(39, 11, 61), ((BlockColored)Blocks.WOOL).getStateFromMeta(15));
      world.setBlockState(pos.add(41, 11, 61), Blocks.STONE.getDefaultState());
      world.setBlockState(pos.add(46, 11, 61), Blocks.STONE.getDefaultState());
      world.setBlockState(pos.add(32, 11, 62), ((BlockColored)Blocks.WOOL).getStateFromMeta(15));
      world.setBlockState(pos.add(39, 11, 62), ((BlockColored)Blocks.WOOL).getStateFromMeta(15));
      world.setBlockState(pos.add(40, 11, 62), Blocks.STONE.getDefaultState());
      world.setBlockState(pos.add(47, 11, 62), Blocks.STONE.getDefaultState());
      world.setBlockState(pos.add(19, 11, 63), Blocks.OBSIDIAN.getDefaultState());
      world.setBlockState(pos.add(32, 11, 63), ((BlockColored)Blocks.WOOL).getStateFromMeta(15));
      world.setBlockState(pos.add(39, 11, 63), ((BlockColored)Blocks.WOOL).getStateFromMeta(15));
      world.setBlockState(pos.add(40, 11, 63), Blocks.STONE.getDefaultState());
      world.setBlockState(pos.add(47, 11, 63), Blocks.STONE.getDefaultState());
      world.setBlockState(pos.add(19, 11, 64), Blocks.OBSIDIAN.getDefaultState());
      world.setBlockState(pos.add(32, 11, 64), ((BlockColored)Blocks.WOOL).getStateFromMeta(15));
      world.setBlockState(pos.add(39, 11, 64), ((BlockColored)Blocks.WOOL).getStateFromMeta(15));
      world.setBlockState(pos.add(40, 11, 64), Blocks.STONE.getDefaultState());
      world.setBlockState(pos.add(47, 11, 64), Blocks.STONE.getDefaultState());
      world.setBlockState(pos.add(23, 11, 65), Blocks.OBSIDIAN.getDefaultState());
      world.setBlockState(pos.add(24, 11, 65), Blocks.OBSIDIAN.getDefaultState());
      world.setBlockState(pos.add(33, 11, 65), ((BlockColored)Blocks.WOOL).getStateFromMeta(15));
      world.setBlockState(pos.add(38, 11, 65), ((BlockColored)Blocks.WOOL).getStateFromMeta(15));
      world.setBlockState(pos.add(40, 11, 65), Blocks.STONE.getDefaultState());
      world.setBlockState(pos.add(47, 11, 65), Blocks.STONE.getDefaultState());
      world.setBlockState(pos.add(34, 11, 66), ((BlockColored)Blocks.WOOL).getStateFromMeta(15));
      world.setBlockState(pos.add(35, 11, 66), ((BlockColored)Blocks.WOOL).getStateFromMeta(15));
      world.setBlockState(pos.add(36, 11, 66), ((BlockColored)Blocks.WOOL).getStateFromMeta(15));
      world.setBlockState(pos.add(37, 11, 66), ((BlockColored)Blocks.WOOL).getStateFromMeta(15));
      world.setBlockState(pos.add(41, 11, 66), Blocks.STONE.getDefaultState());
      world.setBlockState(pos.add(46, 11, 66), Blocks.STONE.getDefaultState());
      world.setBlockState(pos.add(42, 11, 67), Blocks.STONE.getDefaultState());
      world.setBlockState(pos.add(43, 11, 67), Blocks.STONE.getDefaultState());
      world.setBlockState(pos.add(44, 11, 67), Blocks.STONE.getDefaultState());
      world.setBlockState(pos.add(45, 11, 67), Blocks.STONE.getDefaultState());
      world.setBlockState(pos.add(24, 12, 36), Blocks.QUARTZ_BLOCK.getDefaultState());
      world.setBlockState(pos.add(25, 12, 36), ((BlockColored)Blocks.STAINED_HARDENED_CLAY).getStateFromMeta(10));
      world.setBlockState(pos.add(27, 12, 36), ((BlockColored)Blocks.STAINED_HARDENED_CLAY).getStateFromMeta(10));
      world.setBlockState(pos.add(28, 12, 36), Blocks.QUARTZ_BLOCK.getDefaultState());
      world.setBlockState(pos.add(15, 12, 37), ((BlockColored)Blocks.STAINED_HARDENED_CLAY).getStateFromMeta(4));
      world.setBlockState(pos.add(16, 12, 37), ((BlockColored)Blocks.STAINED_HARDENED_CLAY).getStateFromMeta(4));
      world.setBlockState(pos.add(17, 12, 37), ((BlockColored)Blocks.STAINED_HARDENED_CLAY).getStateFromMeta(4));
      world.setBlockState(pos.add(18, 12, 37), ((BlockColored)Blocks.STAINED_HARDENED_CLAY).getStateFromMeta(4));
      world.setBlockState(pos.add(19, 12, 37), ((BlockColored)Blocks.STAINED_HARDENED_CLAY).getStateFromMeta(4));
      world.setBlockState(pos.add(20, 12, 37), ((BlockColored)Blocks.STAINED_HARDENED_CLAY).getStateFromMeta(4));
      world.setBlockState(pos.add(21, 12, 37), Blocks.QUARTZ_BLOCK.getDefaultState());
      world.setBlockState(pos.add(22, 12, 37), Blocks.QUARTZ_BLOCK.getDefaultState());
      world.setBlockState(pos.add(23, 12, 37), ((BlockColored)Blocks.STAINED_HARDENED_CLAY).getStateFromMeta(4));
      world.setBlockState(pos.add(29, 12, 37), ((BlockColored)Blocks.STAINED_HARDENED_CLAY).getStateFromMeta(4));
      world.setBlockState(pos.add(32, 12, 37), ((BlockColored)Blocks.STAINED_HARDENED_CLAY).getStateFromMeta(4));
      world.setBlockState(pos.add(33, 12, 37), ((BlockColored)Blocks.STAINED_HARDENED_CLAY).getStateFromMeta(4));
      world.setBlockState(pos.add(34, 12, 37), ((BlockColored)Blocks.STAINED_HARDENED_CLAY).getStateFromMeta(4));
      world.setBlockState(pos.add(35, 12, 37), ((BlockColored)Blocks.STAINED_HARDENED_CLAY).getStateFromMeta(4));
      world.setBlockState(pos.add(36, 12, 37), ((BlockColored)Blocks.STAINED_HARDENED_CLAY).getStateFromMeta(4));
      world.setBlockState(pos.add(37, 12, 37), ((BlockColored)Blocks.STAINED_HARDENED_CLAY).getStateFromMeta(4));
      world.setBlockState(pos.add(15, 12, 38), ((BlockColored)Blocks.STAINED_HARDENED_CLAY).getStateFromMeta(4));
      world.setBlockState(pos.add(16, 12, 38), ((BlockColored)Blocks.STAINED_HARDENED_CLAY).getStateFromMeta(4));
      world.setBlockState(pos.add(17, 12, 38), ((BlockColored)Blocks.STAINED_HARDENED_CLAY).getStateFromMeta(4));
      world.setBlockState(pos.add(18, 12, 38), ((BlockColored)Blocks.STAINED_HARDENED_CLAY).getStateFromMeta(4));
      world.setBlockState(pos.add(19, 12, 38), ((BlockColored)Blocks.STAINED_HARDENED_CLAY).getStateFromMeta(4));
      world.setBlockState(pos.add(20, 12, 38), ((BlockColored)Blocks.STAINED_HARDENED_CLAY).getStateFromMeta(4));
      world.setBlockState(pos.add(21, 12, 38), Blocks.QUARTZ_BLOCK.getDefaultState());
      world.setBlockState(pos.add(22, 12, 38), Blocks.QUARTZ_BLOCK.getDefaultState());
      world.setBlockState(pos.add(30, 12, 38), Blocks.QUARTZ_BLOCK.getDefaultState());
      world.setBlockState(pos.add(31, 12, 38), Blocks.QUARTZ_BLOCK.getDefaultState());
      world.setBlockState(pos.add(32, 12, 38), ((BlockColored)Blocks.STAINED_HARDENED_CLAY).getStateFromMeta(4));
      world.setBlockState(pos.add(33, 12, 38), ((BlockColored)Blocks.STAINED_HARDENED_CLAY).getStateFromMeta(4));
      world.setBlockState(pos.add(34, 12, 38), ((BlockColored)Blocks.STAINED_HARDENED_CLAY).getStateFromMeta(4));
      world.setBlockState(pos.add(35, 12, 38), ((BlockColored)Blocks.STAINED_HARDENED_CLAY).getStateFromMeta(4));
      world.setBlockState(pos.add(36, 12, 38), ((BlockColored)Blocks.STAINED_HARDENED_CLAY).getStateFromMeta(4));
      world.setBlockState(pos.add(37, 12, 38), ((BlockColored)Blocks.STAINED_HARDENED_CLAY).getStateFromMeta(4));
      world.setBlockState(pos.add(15, 12, 39), ((BlockColored)Blocks.STAINED_HARDENED_CLAY).getStateFromMeta(4));
      world.setBlockState(pos.add(20, 12, 39), ((BlockColored)Blocks.STAINED_HARDENED_CLAY).getStateFromMeta(4));
      world.setBlockState(pos.add(21, 12, 39), Blocks.QUARTZ_BLOCK.getDefaultState());
      world.setBlockState(pos.add(22, 12, 39), Blocks.QUARTZ_BLOCK.getDefaultState());
      world.setBlockState(pos.add(30, 12, 39), Blocks.QUARTZ_BLOCK.getDefaultState());
      world.setBlockState(pos.add(31, 12, 39), Blocks.QUARTZ_BLOCK.getDefaultState());
      world.setBlockState(pos.add(32, 12, 39), ((BlockColored)Blocks.STAINED_HARDENED_CLAY).getStateFromMeta(4));
      world.setBlockState(pos.add(37, 12, 39), ((BlockColored)Blocks.STAINED_HARDENED_CLAY).getStateFromMeta(4));
      world.setBlockState(pos.add(15, 12, 40), ((BlockColored)Blocks.STAINED_HARDENED_CLAY).getStateFromMeta(4));
      world.setBlockState(pos.add(20, 12, 40), ((BlockColored)Blocks.STAINED_HARDENED_CLAY).getStateFromMeta(4));
      world.setBlockState(pos.add(21, 12, 40), Blocks.QUARTZ_BLOCK.getDefaultState());
      world.setBlockState(pos.add(22, 12, 40), Blocks.QUARTZ_BLOCK.getDefaultState());
      world.setBlockState(pos.add(23, 12, 40), ((BlockStaticLiquid)Blocks.LAVA).getStateFromMeta(10));
      world.setBlockState(pos.add(29, 12, 40), ((BlockStaticLiquid)Blocks.LAVA).getStateFromMeta(10));
      world.setBlockState(pos.add(30, 12, 40), Blocks.QUARTZ_BLOCK.getDefaultState());
      world.setBlockState(pos.add(31, 12, 40), Blocks.QUARTZ_BLOCK.getDefaultState());
      world.setBlockState(pos.add(32, 12, 40), ((BlockColored)Blocks.STAINED_HARDENED_CLAY).getStateFromMeta(4));
      world.setBlockState(pos.add(35, 12, 40), ((BlockColored)Blocks.STAINED_HARDENED_CLAY).getStateFromMeta(4));
      world.setBlockState(pos.add(36, 12, 40), ((BlockColored)Blocks.STAINED_HARDENED_CLAY).getStateFromMeta(4));
      world.setBlockState(pos.add(37, 12, 40), ((BlockColored)Blocks.STAINED_HARDENED_CLAY).getStateFromMeta(4));
      world.setBlockState(pos.add(5, 12, 41), Blocks.STONE.getDefaultState());
      world.setBlockState(pos.add(6, 12, 41), Blocks.STONE.getDefaultState());
      world.setBlockState(pos.add(7, 12, 41), Blocks.STONE.getDefaultState());
      world.setBlockState(pos.add(16, 12, 41), Blocks.QUARTZ_BLOCK.getDefaultState());
      world.setBlockState(pos.add(17, 12, 41), Blocks.QUARTZ_BLOCK.getDefaultState());
      world.setBlockState(pos.add(20, 12, 41), Blocks.QUARTZ_BLOCK.getDefaultState());
      world.setBlockState(pos.add(21, 12, 41), Blocks.QUARTZ_BLOCK.getDefaultState());
      world.setBlockState(pos.add(22, 12, 41), Blocks.QUARTZ_BLOCK.getDefaultState());
      world.setBlockState(pos.add(23, 12, 41), Blocks.STONE.getDefaultState());
      world.setBlockState(pos.add(29, 12, 41), Blocks.STONE.getDefaultState());
      world.setBlockState(pos.add(30, 12, 41), Blocks.QUARTZ_BLOCK.getDefaultState());
      world.setBlockState(pos.add(31, 12, 41), Blocks.QUARTZ_BLOCK.getDefaultState());
      world.setBlockState(pos.add(32, 12, 41), Blocks.QUARTZ_BLOCK.getDefaultState());
      world.setBlockState(pos.add(36, 12, 41), Blocks.QUARTZ_BLOCK.getDefaultState());
      world.setBlockState(pos.add(4, 12, 42), Blocks.STONE.getDefaultState());
      world.setBlockState(pos.add(7, 12, 42), Blocks.STONE.getDefaultState());
      world.setBlockState(pos.add(8, 12, 42), Blocks.STONE.getDefaultState());
      world.setBlockState(pos.add(16, 12, 42), Blocks.QUARTZ_BLOCK.getDefaultState());
      world.setBlockState(pos.add(17, 12, 42), Blocks.QUARTZ_BLOCK.getDefaultState());
      world.setBlockState(pos.add(20, 12, 42), Blocks.QUARTZ_BLOCK.getDefaultState());
      world.setBlockState(pos.add(21, 12, 42), Blocks.QUARTZ_BLOCK.getDefaultState());
      world.setBlockState(pos.add(22, 12, 42), Blocks.QUARTZ_BLOCK.getDefaultState());
      world.setBlockState(pos.add(23, 12, 42), Blocks.STONE.getDefaultState());
      world.setBlockState(pos.add(29, 12, 42), Blocks.STONE.getDefaultState());
      world.setBlockState(pos.add(30, 12, 42), Blocks.QUARTZ_BLOCK.getDefaultState());
      world.setBlockState(pos.add(31, 12, 42), Blocks.QUARTZ_BLOCK.getDefaultState());
      world.setBlockState(pos.add(32, 12, 42), Blocks.QUARTZ_BLOCK.getDefaultState());
      world.setBlockState(pos.add(36, 12, 42), Blocks.QUARTZ_BLOCK.getDefaultState());
      world.setBlockState(pos.add(4, 12, 43), Blocks.STONE.getDefaultState());
      world.setBlockState(pos.add(8, 12, 43), Blocks.STONE.getDefaultState());
      world.setBlockState(pos.add(15, 12, 43), ((BlockColored)Blocks.STAINED_HARDENED_CLAY).getStateFromMeta(4));
      world.setBlockState(pos.add(16, 12, 43), ((BlockColored)Blocks.STAINED_HARDENED_CLAY).getStateFromMeta(4));
      world.setBlockState(pos.add(20, 12, 43), ((BlockColored)Blocks.STAINED_HARDENED_CLAY).getStateFromMeta(4));
      world.setBlockState(pos.add(21, 12, 43), Blocks.QUARTZ_BLOCK.getDefaultState());
      world.setBlockState(pos.add(22, 12, 43), Blocks.QUARTZ_BLOCK.getDefaultState());
      world.setBlockState(pos.add(23, 12, 43), ((BlockStaticLiquid)Blocks.LAVA).getStateFromMeta(10));
      world.setBlockState(pos.add(29, 12, 43), ((BlockStaticLiquid)Blocks.LAVA).getStateFromMeta(10));
      world.setBlockState(pos.add(30, 12, 43), Blocks.QUARTZ_BLOCK.getDefaultState());
      world.setBlockState(pos.add(31, 12, 43), Blocks.QUARTZ_BLOCK.getDefaultState());
      world.setBlockState(pos.add(32, 12, 43), ((BlockColored)Blocks.STAINED_HARDENED_CLAY).getStateFromMeta(4));
      world.setBlockState(pos.add(36, 12, 43), ((BlockColored)Blocks.STAINED_HARDENED_CLAY).getStateFromMeta(4));
      world.setBlockState(pos.add(37, 12, 43), ((BlockColored)Blocks.STAINED_HARDENED_CLAY).getStateFromMeta(4));
      world.setBlockState(pos.add(4, 12, 44), Blocks.STONE.getDefaultState());
      world.setBlockState(pos.add(5, 12, 44), Blocks.STONE.getDefaultState());
      world.setBlockState(pos.add(7, 12, 44), Blocks.STONE.getDefaultState());
      world.setBlockState(pos.add(8, 12, 44), Blocks.STONE.getDefaultState());
      world.setBlockState(pos.add(15, 12, 44), ((BlockColored)Blocks.STAINED_HARDENED_CLAY).getStateFromMeta(4));
      world.setBlockState(pos.add(20, 12, 44), ((BlockColored)Blocks.STAINED_HARDENED_CLAY).getStateFromMeta(4));
      world.setBlockState(pos.add(21, 12, 44), Blocks.QUARTZ_BLOCK.getDefaultState());
      world.setBlockState(pos.add(22, 12, 44), Blocks.QUARTZ_BLOCK.getDefaultState());
      world.setBlockState(pos.add(30, 12, 44), Blocks.QUARTZ_BLOCK.getDefaultState());
      world.setBlockState(pos.add(31, 12, 44), Blocks.QUARTZ_BLOCK.getDefaultState());
      world.setBlockState(pos.add(32, 12, 44), ((BlockColored)Blocks.STAINED_HARDENED_CLAY).getStateFromMeta(4));
      world.setBlockState(pos.add(37, 12, 44), ((BlockColored)Blocks.STAINED_HARDENED_CLAY).getStateFromMeta(4));
      world.setBlockState(pos.add(5, 12, 45), Blocks.STONE.getDefaultState());
      world.setBlockState(pos.add(6, 12, 45), Blocks.STONE.getDefaultState());
      world.setBlockState(pos.add(7, 12, 45), Blocks.STONE.getDefaultState());
      world.setBlockState(pos.add(15, 12, 45), ((BlockColored)Blocks.STAINED_HARDENED_CLAY).getStateFromMeta(4));
      world.setBlockState(pos.add(20, 12, 45), ((BlockColored)Blocks.STAINED_HARDENED_CLAY).getStateFromMeta(4));
      world.setBlockState(pos.add(21, 12, 45), Blocks.QUARTZ_BLOCK.getDefaultState());
      world.setBlockState(pos.add(22, 12, 45), Blocks.QUARTZ_BLOCK.getDefaultState());
      world.setBlockState(pos.add(23, 12, 45), ((BlockStaticLiquid)Blocks.LAVA).getStateFromMeta(10));
      world.setBlockState(pos.add(29, 12, 45), ((BlockStaticLiquid)Blocks.LAVA).getStateFromMeta(10));
      world.setBlockState(pos.add(30, 12, 45), Blocks.QUARTZ_BLOCK.getDefaultState());
      world.setBlockState(pos.add(31, 12, 45), Blocks.QUARTZ_BLOCK.getDefaultState());
      world.setBlockState(pos.add(32, 12, 45), ((BlockColored)Blocks.STAINED_HARDENED_CLAY).getStateFromMeta(4));
      world.setBlockState(pos.add(37, 12, 45), ((BlockColored)Blocks.STAINED_HARDENED_CLAY).getStateFromMeta(4));
      world.setBlockState(pos.add(16, 12, 46), Blocks.QUARTZ_BLOCK.getDefaultState());
      world.setBlockState(pos.add(17, 12, 46), Blocks.QUARTZ_BLOCK.getDefaultState());
      world.setBlockState(pos.add(18, 12, 46), Blocks.QUARTZ_BLOCK.getDefaultState());
      world.setBlockState(pos.add(19, 12, 46), Blocks.QUARTZ_BLOCK.getDefaultState());
      world.setBlockState(pos.add(20, 12, 46), Blocks.QUARTZ_BLOCK.getDefaultState());
      world.setBlockState(pos.add(21, 12, 46), Blocks.QUARTZ_BLOCK.getDefaultState());
      world.setBlockState(pos.add(22, 12, 46), Blocks.QUARTZ_BLOCK.getDefaultState());
      world.setBlockState(pos.add(23, 12, 46), Blocks.STONE.getDefaultState());
      world.setBlockState(pos.add(29, 12, 46), Blocks.STONE.getDefaultState());
      world.setBlockState(pos.add(30, 12, 46), Blocks.QUARTZ_BLOCK.getDefaultState());
      world.setBlockState(pos.add(31, 12, 46), Blocks.QUARTZ_BLOCK.getDefaultState());
      world.setBlockState(pos.add(32, 12, 46), Blocks.QUARTZ_BLOCK.getDefaultState());
      world.setBlockState(pos.add(35, 12, 46), Blocks.QUARTZ_BLOCK.getDefaultState());
      world.setBlockState(pos.add(36, 12, 46), Blocks.QUARTZ_BLOCK.getDefaultState());
      world.setBlockState(pos.add(16, 12, 47), Blocks.QUARTZ_BLOCK.getDefaultState());
      world.setBlockState(pos.add(17, 12, 47), Blocks.QUARTZ_BLOCK.getDefaultState());
      world.setBlockState(pos.add(18, 12, 47), Blocks.QUARTZ_BLOCK.getDefaultState());
      world.setBlockState(pos.add(19, 12, 47), Blocks.QUARTZ_BLOCK.getDefaultState());
      world.setBlockState(pos.add(20, 12, 47), Blocks.QUARTZ_BLOCK.getDefaultState());
      world.setBlockState(pos.add(21, 12, 47), Blocks.QUARTZ_BLOCK.getDefaultState());
      world.setBlockState(pos.add(22, 12, 47), Blocks.QUARTZ_BLOCK.getDefaultState());
      world.setBlockState(pos.add(23, 12, 47), Blocks.STONE.getDefaultState());
      world.setBlockState(pos.add(29, 12, 47), Blocks.STONE.getDefaultState());
      world.setBlockState(pos.add(30, 12, 47), Blocks.QUARTZ_BLOCK.getDefaultState());
      world.setBlockState(pos.add(31, 12, 47), Blocks.QUARTZ_BLOCK.getDefaultState());
      world.setBlockState(pos.add(32, 12, 47), Blocks.QUARTZ_BLOCK.getDefaultState());
      world.setBlockState(pos.add(35, 12, 47), Blocks.QUARTZ_BLOCK.getDefaultState());
      world.setBlockState(pos.add(36, 12, 47), Blocks.QUARTZ_BLOCK.getDefaultState());
      world.setBlockState(pos.add(15, 12, 48), ((BlockColored)Blocks.STAINED_HARDENED_CLAY).getStateFromMeta(4));
      world.setBlockState(pos.add(20, 12, 48), ((BlockColored)Blocks.STAINED_HARDENED_CLAY).getStateFromMeta(4));
      world.setBlockState(pos.add(21, 12, 48), Blocks.QUARTZ_BLOCK.getDefaultState());
      world.setBlockState(pos.add(22, 12, 48), Blocks.QUARTZ_BLOCK.getDefaultState());
      world.setBlockState(pos.add(23, 12, 48), ((BlockStaticLiquid)Blocks.LAVA).getStateFromMeta(10));
      world.setBlockState(pos.add(29, 12, 48), ((BlockStaticLiquid)Blocks.LAVA).getStateFromMeta(10));
      world.setBlockState(pos.add(30, 12, 48), Blocks.QUARTZ_BLOCK.getDefaultState());
      world.setBlockState(pos.add(31, 12, 48), Blocks.QUARTZ_BLOCK.getDefaultState());
      world.setBlockState(pos.add(32, 12, 48), ((BlockColored)Blocks.STAINED_HARDENED_CLAY).getStateFromMeta(4));
      world.setBlockState(pos.add(36, 12, 48), ((BlockColored)Blocks.STAINED_HARDENED_CLAY).getStateFromMeta(4));
      world.setBlockState(pos.add(37, 12, 48), ((BlockColored)Blocks.STAINED_HARDENED_CLAY).getStateFromMeta(4));
      world.setBlockState(pos.add(15, 12, 49), ((BlockColored)Blocks.STAINED_HARDENED_CLAY).getStateFromMeta(4));
      world.setBlockState(pos.add(20, 12, 49), ((BlockColored)Blocks.STAINED_HARDENED_CLAY).getStateFromMeta(4));
      world.setBlockState(pos.add(21, 12, 49), Blocks.QUARTZ_BLOCK.getDefaultState());
      world.setBlockState(pos.add(22, 12, 49), Blocks.QUARTZ_BLOCK.getDefaultState());
      world.setBlockState(pos.add(30, 12, 49), Blocks.QUARTZ_BLOCK.getDefaultState());
      world.setBlockState(pos.add(31, 12, 49), Blocks.QUARTZ_BLOCK.getDefaultState());
      world.setBlockState(pos.add(32, 12, 49), ((BlockColored)Blocks.STAINED_HARDENED_CLAY).getStateFromMeta(4));
      world.setBlockState(pos.add(37, 12, 49), ((BlockColored)Blocks.STAINED_HARDENED_CLAY).getStateFromMeta(4));
      world.setBlockState(pos.add(15, 12, 50), ((BlockColored)Blocks.STAINED_HARDENED_CLAY).getStateFromMeta(4));
      world.setBlockState(pos.add(16, 12, 50), ((BlockColored)Blocks.STAINED_HARDENED_CLAY).getStateFromMeta(4));
      world.setBlockState(pos.add(17, 12, 50), ((BlockColored)Blocks.STAINED_HARDENED_CLAY).getStateFromMeta(4));
      world.setBlockState(pos.add(18, 12, 50), ((BlockColored)Blocks.STAINED_HARDENED_CLAY).getStateFromMeta(4));
      world.setBlockState(pos.add(19, 12, 50), ((BlockColored)Blocks.STAINED_HARDENED_CLAY).getStateFromMeta(4));
      world.setBlockState(pos.add(20, 12, 50), ((BlockColored)Blocks.STAINED_HARDENED_CLAY).getStateFromMeta(4));
      world.setBlockState(pos.add(21, 12, 50), Blocks.QUARTZ_BLOCK.getDefaultState());
      world.setBlockState(pos.add(22, 12, 50), Blocks.QUARTZ_BLOCK.getDefaultState());
      world.setBlockState(pos.add(30, 12, 50), Blocks.QUARTZ_BLOCK.getDefaultState());
      world.setBlockState(pos.add(31, 12, 50), Blocks.QUARTZ_BLOCK.getDefaultState());
      world.setBlockState(pos.add(32, 12, 50), ((BlockColored)Blocks.STAINED_HARDENED_CLAY).getStateFromMeta(4));
      world.setBlockState(pos.add(33, 12, 50), ((BlockColored)Blocks.STAINED_HARDENED_CLAY).getStateFromMeta(4));
      world.setBlockState(pos.add(34, 12, 50), ((BlockColored)Blocks.STAINED_HARDENED_CLAY).getStateFromMeta(4));
      world.setBlockState(pos.add(35, 12, 50), ((BlockColored)Blocks.STAINED_HARDENED_CLAY).getStateFromMeta(4));
      world.setBlockState(pos.add(36, 12, 50), ((BlockColored)Blocks.STAINED_HARDENED_CLAY).getStateFromMeta(4));
      world.setBlockState(pos.add(37, 12, 50), ((BlockColored)Blocks.STAINED_HARDENED_CLAY).getStateFromMeta(4));
      world.setBlockState(pos.add(18, 12, 51), ((BlockColored)Blocks.STAINED_HARDENED_CLAY).getStateFromMeta(4));
      world.setBlockState(pos.add(19, 12, 51), ((BlockColored)Blocks.STAINED_HARDENED_CLAY).getStateFromMeta(4));
      world.setBlockState(pos.add(20, 12, 51), ((BlockColored)Blocks.STAINED_HARDENED_CLAY).getStateFromMeta(4));
      world.setBlockState(pos.add(21, 12, 51), ((BlockColored)Blocks.STAINED_HARDENED_CLAY).getStateFromMeta(4));
      world.setBlockState(pos.add(30, 12, 51), ((BlockColored)Blocks.STAINED_HARDENED_CLAY).getStateFromMeta(4));
      world.setBlockState(pos.add(31, 12, 51), ((BlockColored)Blocks.STAINED_HARDENED_CLAY).getStateFromMeta(4));
      world.setBlockState(pos.add(32, 12, 51), ((BlockColored)Blocks.STAINED_HARDENED_CLAY).getStateFromMeta(4));
      world.setBlockState(pos.add(33, 12, 51), ((BlockColored)Blocks.STAINED_HARDENED_CLAY).getStateFromMeta(4));
      world.setBlockState(pos.add(34, 12, 51), ((BlockColored)Blocks.STAINED_HARDENED_CLAY).getStateFromMeta(4));
      world.setBlockState(pos.add(17, 12, 52), ((BlockColored)Blocks.STAINED_HARDENED_CLAY).getStateFromMeta(4));
      world.setBlockState(pos.add(18, 12, 52), ((BlockColored)Blocks.STAINED_HARDENED_CLAY).getStateFromMeta(4));
      world.setBlockState(pos.add(22, 12, 52), ((BlockColored)Blocks.STAINED_HARDENED_CLAY).getStateFromMeta(4));
      world.setBlockState(pos.add(29, 12, 52), ((BlockColored)Blocks.STAINED_HARDENED_CLAY).getStateFromMeta(4));
      world.setBlockState(pos.add(30, 12, 52), ((BlockColored)Blocks.STAINED_HARDENED_CLAY).getStateFromMeta(4));
      world.setBlockState(pos.add(34, 12, 52), ((BlockColored)Blocks.STAINED_HARDENED_CLAY).getStateFromMeta(4));
      world.setBlockState(pos.add(35, 12, 52), ((BlockColored)Blocks.STAINED_HARDENED_CLAY).getStateFromMeta(4));
      world.setBlockState(pos.add(16, 12, 53), ((BlockColored)Blocks.STAINED_HARDENED_CLAY).getStateFromMeta(4));
      world.setBlockState(pos.add(17, 12, 53), ((BlockColored)Blocks.STAINED_HARDENED_CLAY).getStateFromMeta(4));
      world.setBlockState(pos.add(23, 12, 53), ((BlockColored)Blocks.STAINED_HARDENED_CLAY).getStateFromMeta(4));
      world.setBlockState(pos.add(24, 12, 53), ((BlockColored)Blocks.STAINED_HARDENED_CLAY).getStateFromMeta(4));
      world.setBlockState(pos.add(28, 12, 53), ((BlockColored)Blocks.STAINED_HARDENED_CLAY).getStateFromMeta(4));
      world.setBlockState(pos.add(29, 12, 53), ((BlockColored)Blocks.STAINED_HARDENED_CLAY).getStateFromMeta(4));
      world.setBlockState(pos.add(35, 12, 53), ((BlockColored)Blocks.STAINED_HARDENED_CLAY).getStateFromMeta(4));
      world.setBlockState(pos.add(36, 12, 53), ((BlockColored)Blocks.STAINED_HARDENED_CLAY).getStateFromMeta(4));
      world.setBlockState(pos.add(16, 12, 54), ((BlockColored)Blocks.STAINED_HARDENED_CLAY).getStateFromMeta(4));
      world.setBlockState(pos.add(17, 12, 54), ((BlockColored)Blocks.STAINED_HARDENED_CLAY).getStateFromMeta(4));
      world.setBlockState(pos.add(23, 12, 54), ((BlockColored)Blocks.STAINED_HARDENED_CLAY).getStateFromMeta(4));
      world.setBlockState(pos.add(24, 12, 54), ((BlockColored)Blocks.STAINED_HARDENED_CLAY).getStateFromMeta(4));
      world.setBlockState(pos.add(25, 12, 54), ((BlockRedstoneTorch)Blocks.REDSTONE_TORCH).getStateFromMeta(1));
      world.setBlockState(pos.add(27, 12, 54), ((BlockRedstoneTorch)Blocks.REDSTONE_TORCH).getStateFromMeta(2));
      world.setBlockState(pos.add(28, 12, 54), ((BlockColored)Blocks.STAINED_HARDENED_CLAY).getStateFromMeta(4));
      world.setBlockState(pos.add(29, 12, 54), ((BlockColored)Blocks.STAINED_HARDENED_CLAY).getStateFromMeta(4));
      world.setBlockState(pos.add(35, 12, 54), ((BlockColored)Blocks.STAINED_HARDENED_CLAY).getStateFromMeta(4));
      world.setBlockState(pos.add(36, 12, 54), ((BlockColored)Blocks.STAINED_HARDENED_CLAY).getStateFromMeta(4));
      world.setBlockState(pos.add(16, 12, 55), ((BlockColored)Blocks.STAINED_HARDENED_CLAY).getStateFromMeta(4));
      world.setBlockState(pos.add(17, 12, 55), ((BlockColored)Blocks.STAINED_HARDENED_CLAY).getStateFromMeta(4));
      world.setBlockState(pos.add(23, 12, 55), ((BlockColored)Blocks.STAINED_HARDENED_CLAY).getStateFromMeta(4));
      world.setBlockState(pos.add(24, 12, 55), ((BlockColored)Blocks.STAINED_HARDENED_CLAY).getStateFromMeta(4));
      world.setBlockState(pos.add(28, 12, 55), ((BlockColored)Blocks.STAINED_HARDENED_CLAY).getStateFromMeta(4));
      world.setBlockState(pos.add(29, 12, 55), ((BlockColored)Blocks.STAINED_HARDENED_CLAY).getStateFromMeta(4));
      world.setBlockState(pos.add(35, 12, 55), ((BlockColored)Blocks.STAINED_HARDENED_CLAY).getStateFromMeta(4));
      world.setBlockState(pos.add(36, 12, 55), ((BlockColored)Blocks.STAINED_HARDENED_CLAY).getStateFromMeta(4));
      world.setBlockState(pos.add(37, 12, 55), ((BlockColored)Blocks.STAINED_HARDENED_CLAY).getStateFromMeta(4));
      world.setBlockState(pos.add(17, 12, 56), ((BlockColored)Blocks.STAINED_HARDENED_CLAY).getStateFromMeta(4));
      world.setBlockState(pos.add(18, 12, 56), ((BlockColored)Blocks.STAINED_HARDENED_CLAY).getStateFromMeta(4));
      world.setBlockState(pos.add(22, 12, 56), ((BlockColored)Blocks.STAINED_HARDENED_CLAY).getStateFromMeta(4));
      world.setBlockState(pos.add(23, 12, 56), ((BlockColored)Blocks.STAINED_HARDENED_CLAY).getStateFromMeta(4));
      world.setBlockState(pos.add(24, 12, 56), Blocks.NETHER_BRICK_FENCE.getDefaultState());
      world.setBlockState(pos.add(28, 12, 56), Blocks.NETHER_BRICK_FENCE.getDefaultState());
      world.setBlockState(pos.add(29, 12, 56), ((BlockColored)Blocks.STAINED_HARDENED_CLAY).getStateFromMeta(4));
      world.setBlockState(pos.add(30, 12, 56), ((BlockColored)Blocks.STAINED_HARDENED_CLAY).getStateFromMeta(4));
      world.setBlockState(pos.add(34, 12, 56), ((BlockColored)Blocks.STAINED_HARDENED_CLAY).getStateFromMeta(4));
      world.setBlockState(pos.add(35, 12, 56), ((BlockColored)Blocks.STAINED_HARDENED_CLAY).getStateFromMeta(4));
      world.setBlockState(pos.add(38, 12, 56), ((BlockColored)Blocks.STAINED_HARDENED_CLAY).getStateFromMeta(4));
      world.setBlockState(pos.add(39, 12, 56), ((BlockColored)Blocks.WOOL).getStateFromMeta(15));
      world.setBlockState(pos.add(40, 12, 56), ((BlockColored)Blocks.WOOL).getStateFromMeta(15));
      world.setBlockState(pos.add(18, 12, 57), ((BlockColored)Blocks.STAINED_HARDENED_CLAY).getStateFromMeta(4));
      world.setBlockState(pos.add(19, 12, 57), ((BlockColored)Blocks.STAINED_HARDENED_CLAY).getStateFromMeta(4));
      world.setBlockState(pos.add(20, 12, 57), ((BlockColored)Blocks.STAINED_HARDENED_CLAY).getStateFromMeta(4));
      world.setBlockState(pos.add(21, 12, 57), ((BlockColored)Blocks.STAINED_HARDENED_CLAY).getStateFromMeta(4));
      world.setBlockState(pos.add(22, 12, 57), ((BlockColored)Blocks.STAINED_HARDENED_CLAY).getStateFromMeta(4));
      world.setBlockState(pos.add(24, 12, 57), Blocks.NETHER_BRICK_FENCE.getDefaultState());
      world.setBlockState(pos.add(25, 12, 57), ((BlockStairs)Blocks.NETHER_BRICK_STAIRS).getStateFromMeta(2));
      world.setBlockState(pos.add(26, 12, 57), ((BlockStairs)Blocks.NETHER_BRICK_STAIRS).getStateFromMeta(2));
      world.setBlockState(pos.add(27, 12, 57), ((BlockStairs)Blocks.NETHER_BRICK_STAIRS).getStateFromMeta(2));
      world.setBlockState(pos.add(28, 12, 57), Blocks.NETHER_BRICK_FENCE.getDefaultState());
      world.setBlockState(pos.add(29, 12, 57), Blocks.STONE.getDefaultState());
      world.setBlockState(pos.add(30, 12, 57), ((BlockColored)Blocks.STAINED_HARDENED_CLAY).getStateFromMeta(4));
      world.setBlockState(pos.add(31, 12, 57), ((BlockColored)Blocks.STAINED_HARDENED_CLAY).getStateFromMeta(4));
      world.setBlockState(pos.add(32, 12, 57), ((BlockColored)Blocks.STAINED_HARDENED_CLAY).getStateFromMeta(4));
      world.setBlockState(pos.add(33, 12, 57), ((BlockColored)Blocks.STAINED_HARDENED_CLAY).getStateFromMeta(4));
      world.setBlockState(pos.add(34, 12, 57), ((BlockColored)Blocks.STAINED_HARDENED_CLAY).getStateFromMeta(4));
      world.setBlockState(pos.add(39, 12, 57), ((BlockColored)Blocks.STAINED_HARDENED_CLAY).getStateFromMeta(4));
      world.setBlockState(pos.add(41, 12, 57), ((BlockColored)Blocks.WOOL).getStateFromMeta(15));
      world.setBlockState(pos.add(19, 12, 58), ((BlockColored)Blocks.STAINED_HARDENED_CLAY).getStateFromMeta(4));
      world.setBlockState(pos.add(20, 12, 58), ((BlockColored)Blocks.STAINED_HARDENED_CLAY).getStateFromMeta(4));
      world.setBlockState(pos.add(21, 12, 58), ((BlockColored)Blocks.STAINED_HARDENED_CLAY).getStateFromMeta(4));
      world.setBlockState(pos.add(24, 12, 58), Blocks.STONE.getDefaultState());
      world.setBlockState(pos.add(25, 12, 58), Blocks.STONE.getDefaultState());
      world.setBlockState(pos.add(26, 12, 58), Blocks.STONE.getDefaultState());
      world.setBlockState(pos.add(27, 12, 58), Blocks.STONE.getDefaultState());
      world.setBlockState(pos.add(28, 12, 58), Blocks.STONE.getDefaultState());
      world.setBlockState(pos.add(31, 12, 58), ((BlockColored)Blocks.STAINED_HARDENED_CLAY).getStateFromMeta(4));
      world.setBlockState(pos.add(32, 12, 58), ((BlockColored)Blocks.STAINED_HARDENED_CLAY).getStateFromMeta(4));
      world.setBlockState(pos.add(33, 12, 58), ((BlockColored)Blocks.STAINED_HARDENED_CLAY).getStateFromMeta(4));
      world.setBlockState(pos.add(40, 12, 58), ((BlockColored)Blocks.STAINED_HARDENED_CLAY).getStateFromMeta(4));
      world.setBlockState(pos.add(42, 12, 58), ((BlockColored)Blocks.WOOL).getStateFromMeta(15));
      world.setBlockState(pos.add(23, 12, 59), Blocks.STONE.getDefaultState());
      world.setBlockState(pos.add(24, 12, 59), Blocks.STONE.getDefaultState());
      world.setBlockState(pos.add(25, 12, 59), Blocks.STONE.getDefaultState());
      world.setBlockState(pos.add(26, 12, 59), Blocks.STONE.getDefaultState());
      world.setBlockState(pos.add(27, 12, 59), Blocks.STONE.getDefaultState());
      world.setBlockState(pos.add(28, 12, 59), Blocks.STONE.getDefaultState());
      world.setBlockState(pos.add(34, 12, 59), ((BlockColored)Blocks.WOOL).getStateFromMeta(15));
      world.setBlockState(pos.add(35, 12, 59), ((BlockColored)Blocks.WOOL).getStateFromMeta(15));
      world.setBlockState(pos.add(36, 12, 59), ((BlockColored)Blocks.WOOL).getStateFromMeta(15));
      world.setBlockState(pos.add(37, 12, 59), ((BlockColored)Blocks.WOOL).getStateFromMeta(15));
      world.setBlockState(pos.add(41, 12, 59), ((BlockColored)Blocks.STAINED_HARDENED_CLAY).getStateFromMeta(4));
      world.setBlockState(pos.add(42, 12, 59), ((BlockColored)Blocks.WOOL).getStateFromMeta(15));
      world.setBlockState(pos.add(18, 12, 60), Blocks.STONE.getDefaultState());
      world.setBlockState(pos.add(19, 12, 60), Blocks.STONE.getDefaultState());
      world.setBlockState(pos.add(20, 12, 60), Blocks.STONE.getDefaultState());
      world.setBlockState(pos.add(21, 12, 60), Blocks.STONE.getDefaultState());
      world.setBlockState(pos.add(22, 12, 60), Blocks.STONE.getDefaultState());
      world.setBlockState(pos.add(23, 12, 60), Blocks.STONE.getDefaultState());
      world.setBlockState(pos.add(24, 12, 60), Blocks.STONE.getDefaultState());
      world.setBlockState(pos.add(25, 12, 60), Blocks.STONE.getDefaultState());
      world.setBlockState(pos.add(26, 12, 60), Blocks.STONE.getDefaultState());
      world.setBlockState(pos.add(27, 12, 60), Blocks.STONE.getDefaultState());
      world.setBlockState(pos.add(28, 12, 60), Blocks.STONE.getDefaultState());
      world.setBlockState(pos.add(33, 12, 60), ((BlockColored)Blocks.WOOL).getStateFromMeta(15));
      world.setBlockState(pos.add(38, 12, 60), ((BlockColored)Blocks.WOOL).getStateFromMeta(15));
      world.setBlockState(pos.add(42, 12, 60), Blocks.STONE.getDefaultState());
      world.setBlockState(pos.add(43, 12, 60), Blocks.STONE.getDefaultState());
      world.setBlockState(pos.add(44, 12, 60), Blocks.STONE.getDefaultState());
      world.setBlockState(pos.add(45, 12, 60), Blocks.STONE.getDefaultState());
      world.setBlockState(pos.add(18, 12, 61), Blocks.STONE.getDefaultState());
      world.setBlockState(pos.add(19, 12, 61), Blocks.NETHERRACK.getDefaultState());
      world.setBlockState(pos.add(20, 12, 61), Blocks.NETHERRACK.getDefaultState());
      world.setBlockState(pos.add(21, 12, 61), Blocks.STONE.getDefaultState());
      world.setBlockState(pos.add(22, 12, 61), Blocks.STONE.getDefaultState());
      world.setBlockState(pos.add(23, 12, 61), Blocks.STONE.getDefaultState());
      world.setBlockState(pos.add(24, 12, 61), Blocks.STONE.getDefaultState());
      world.setBlockState(pos.add(25, 12, 61), Blocks.STONE.getDefaultState());
      world.setBlockState(pos.add(26, 12, 61), Blocks.STONE.getDefaultState());
      world.setBlockState(pos.add(27, 12, 61), Blocks.STONE.getDefaultState());
      world.setBlockState(pos.add(28, 12, 61), Blocks.STONE.getDefaultState());
      world.setBlockState(pos.add(32, 12, 61), ((BlockColored)Blocks.WOOL).getStateFromMeta(15));
      world.setBlockState(pos.add(39, 12, 61), ((BlockColored)Blocks.WOOL).getStateFromMeta(15));
      world.setBlockState(pos.add(41, 12, 61), Blocks.STONE.getDefaultState());
      world.setBlockState(pos.add(46, 12, 61), Blocks.STONE.getDefaultState());
      world.setBlockState(pos.add(18, 12, 62), Blocks.STONE.getDefaultState());
      world.setBlockState(pos.add(19, 12, 62), Blocks.NETHERRACK.getDefaultState());
      world.setBlockState(pos.add(20, 12, 62), Blocks.NETHERRACK.getDefaultState());
      world.setBlockState(pos.add(21, 12, 62), Blocks.STONE.getDefaultState());
      world.setBlockState(pos.add(22, 12, 62), Blocks.STONE.getDefaultState());
      world.setBlockState(pos.add(23, 12, 62), Blocks.STONE.getDefaultState());
      world.setBlockState(pos.add(24, 12, 62), Blocks.STONE.getDefaultState());
      world.setBlockState(pos.add(25, 12, 62), Blocks.STONE.getDefaultState());
      world.setBlockState(pos.add(26, 12, 62), Blocks.STONE.getDefaultState());
      world.setBlockState(pos.add(27, 12, 62), Blocks.STONE.getDefaultState());
      world.setBlockState(pos.add(28, 12, 62), Blocks.STONE.getDefaultState());
      world.setBlockState(pos.add(32, 12, 62), ((BlockColored)Blocks.WOOL).getStateFromMeta(15));
      world.setBlockState(pos.add(39, 12, 62), ((BlockColored)Blocks.WOOL).getStateFromMeta(15));
      world.setBlockState(pos.add(40, 12, 62), Blocks.STONE.getDefaultState());
      world.setBlockState(pos.add(47, 12, 62), Blocks.STONE.getDefaultState());
      world.setBlockState(pos.add(18, 12, 63), Blocks.STONE.getDefaultState());
      world.setBlockState(pos.add(19, 12, 63), Blocks.NETHERRACK.getDefaultState());
      world.setBlockState(pos.add(20, 12, 63), Blocks.NETHERRACK.getDefaultState());
      world.setBlockState(pos.add(21, 12, 63), Blocks.STONE.getDefaultState());
      world.setBlockState(pos.add(22, 12, 63), Blocks.STONE.getDefaultState());
      world.setBlockState(pos.add(23, 12, 63), Blocks.STONE.getDefaultState());
      world.setBlockState(pos.add(24, 12, 63), Blocks.STONE.getDefaultState());
      world.setBlockState(pos.add(25, 12, 63), Blocks.STONE.getDefaultState());
      world.setBlockState(pos.add(26, 12, 63), Blocks.STONE.getDefaultState());
      world.setBlockState(pos.add(27, 12, 63), Blocks.STONE.getDefaultState());
      world.setBlockState(pos.add(28, 12, 63), Blocks.STONE.getDefaultState());
      world.setBlockState(pos.add(32, 12, 63), ((BlockColored)Blocks.WOOL).getStateFromMeta(15));
      world.setBlockState(pos.add(39, 12, 63), ((BlockColored)Blocks.WOOL).getStateFromMeta(15));
      world.setBlockState(pos.add(40, 12, 63), Blocks.STONE.getDefaultState());
      world.setBlockState(pos.add(47, 12, 63), Blocks.STONE.getDefaultState());
      world.setBlockState(pos.add(18, 12, 64), Blocks.STONE.getDefaultState());
      world.setBlockState(pos.add(19, 12, 64), Blocks.NETHERRACK.getDefaultState());
      world.setBlockState(pos.add(20, 12, 64), Blocks.NETHERRACK.getDefaultState());
      world.setBlockState(pos.add(21, 12, 64), Blocks.STONE.getDefaultState());
      world.setBlockState(pos.add(22, 12, 64), Blocks.STONE.getDefaultState());
      world.setBlockState(pos.add(23, 12, 64), Blocks.STONE.getDefaultState());
      world.setBlockState(pos.add(24, 12, 64), Blocks.STONE.getDefaultState());
      world.setBlockState(pos.add(25, 12, 64), Blocks.STONE.getDefaultState());
      world.setBlockState(pos.add(26, 12, 64), Blocks.STONE.getDefaultState());
      world.setBlockState(pos.add(27, 12, 64), Blocks.STONE.getDefaultState());
      world.setBlockState(pos.add(28, 12, 64), Blocks.STONE.getDefaultState());
      world.setBlockState(pos.add(32, 12, 64), ((BlockColored)Blocks.WOOL).getStateFromMeta(15));
      world.setBlockState(pos.add(39, 12, 64), ((BlockColored)Blocks.WOOL).getStateFromMeta(15));
      world.setBlockState(pos.add(40, 12, 64), Blocks.STONE.getDefaultState());
      world.setBlockState(pos.add(47, 12, 64), Blocks.STONE.getDefaultState());
      world.setBlockState(pos.add(18, 12, 65), Blocks.STONE.getDefaultState());
      world.setBlockState(pos.add(19, 12, 65), Blocks.STONE.getDefaultState());
      world.setBlockState(pos.add(20, 12, 65), Blocks.STONE.getDefaultState());
      world.setBlockState(pos.add(21, 12, 65), Blocks.STONE.getDefaultState());
      world.setBlockState(pos.add(22, 12, 65), Blocks.STONE.getDefaultState());
      world.setBlockState(pos.add(23, 12, 65), Blocks.STONE.getDefaultState());
      world.setBlockState(pos.add(24, 12, 65), Blocks.STONE.getDefaultState());
      world.setBlockState(pos.add(25, 12, 65), Blocks.STONE.getDefaultState());
      world.setBlockState(pos.add(26, 12, 65), Blocks.STONE.getDefaultState());
      world.setBlockState(pos.add(27, 12, 65), Blocks.STONE.getDefaultState());
      world.setBlockState(pos.add(28, 12, 65), Blocks.STONE.getDefaultState());
      world.setBlockState(pos.add(33, 12, 65), ((BlockColored)Blocks.WOOL).getStateFromMeta(15));
      world.setBlockState(pos.add(38, 12, 65), ((BlockColored)Blocks.WOOL).getStateFromMeta(15));
      world.setBlockState(pos.add(40, 12, 65), Blocks.STONE.getDefaultState());
      world.setBlockState(pos.add(47, 12, 65), Blocks.STONE.getDefaultState());
      world.setBlockState(pos.add(18, 12, 66), Blocks.STONE.getDefaultState());
      world.setBlockState(pos.add(19, 12, 66), Blocks.STONE.getDefaultState());
      world.setBlockState(pos.add(20, 12, 66), Blocks.STONE.getDefaultState());
      world.setBlockState(pos.add(21, 12, 66), Blocks.STONE.getDefaultState());
      world.setBlockState(pos.add(22, 12, 66), Blocks.STONE.getDefaultState());
      world.setBlockState(pos.add(23, 12, 66), Blocks.STONE.getDefaultState());
      world.setBlockState(pos.add(24, 12, 66), Blocks.STONE.getDefaultState());
      world.setBlockState(pos.add(25, 12, 66), Blocks.STONE.getDefaultState());
      world.setBlockState(pos.add(26, 12, 66), Blocks.STONE.getDefaultState());
      world.setBlockState(pos.add(27, 12, 66), Blocks.STONE.getDefaultState());
      world.setBlockState(pos.add(28, 12, 66), Blocks.STONE.getDefaultState());
      world.setBlockState(pos.add(34, 12, 66), ((BlockColored)Blocks.WOOL).getStateFromMeta(15));
      world.setBlockState(pos.add(35, 12, 66), ((BlockColored)Blocks.WOOL).getStateFromMeta(15));
      world.setBlockState(pos.add(36, 12, 66), ((BlockColored)Blocks.WOOL).getStateFromMeta(15));
      world.setBlockState(pos.add(37, 12, 66), ((BlockColored)Blocks.WOOL).getStateFromMeta(15));
      world.setBlockState(pos.add(41, 12, 66), Blocks.STONE.getDefaultState());
      world.setBlockState(pos.add(46, 12, 66), Blocks.STONE.getDefaultState());
      world.setBlockState(pos.add(42, 12, 67), Blocks.STONE.getDefaultState());
      world.setBlockState(pos.add(43, 12, 67), Blocks.STONE.getDefaultState());
      world.setBlockState(pos.add(44, 12, 67), Blocks.STONE.getDefaultState());
      world.setBlockState(pos.add(45, 12, 67), Blocks.STONE.getDefaultState());
      world.setBlockState(pos.add(24, 13, 36), Blocks.QUARTZ_BLOCK.getDefaultState());
      world.setBlockState(pos.add(25, 13, 36), ((BlockColored)Blocks.STAINED_HARDENED_CLAY).getStateFromMeta(10));
      world.setBlockState(pos.add(27, 13, 36), ((BlockColored)Blocks.STAINED_HARDENED_CLAY).getStateFromMeta(10));
      world.setBlockState(pos.add(28, 13, 36), Blocks.QUARTZ_BLOCK.getDefaultState());
      world.setBlockState(pos.add(16, 13, 37), ((BlockColored)Blocks.STAINED_HARDENED_CLAY).getStateFromMeta(4));
      world.setBlockState(pos.add(17, 13, 37), ((BlockColored)Blocks.STAINED_HARDENED_CLAY).getStateFromMeta(4));
      world.setBlockState(pos.add(21, 13, 37), Blocks.QUARTZ_BLOCK.getDefaultState());
      world.setBlockState(pos.add(22, 13, 37), Blocks.QUARTZ_BLOCK.getDefaultState());
      world.setBlockState(pos.add(23, 13, 37), ((BlockColored)Blocks.STAINED_HARDENED_CLAY).getStateFromMeta(4));
      world.setBlockState(pos.add(29, 13, 37), ((BlockColored)Blocks.STAINED_HARDENED_CLAY).getStateFromMeta(4));
      world.setBlockState(pos.add(35, 13, 37), ((BlockColored)Blocks.STAINED_HARDENED_CLAY).getStateFromMeta(4));
      world.setBlockState(pos.add(36, 13, 37), ((BlockColored)Blocks.STAINED_HARDENED_CLAY).getStateFromMeta(4));
      world.setBlockState(pos.add(16, 13, 38), ((BlockColored)Blocks.STAINED_HARDENED_CLAY).getStateFromMeta(4));
      world.setBlockState(pos.add(17, 13, 38), ((BlockColored)Blocks.STAINED_HARDENED_CLAY).getStateFromMeta(4));
      world.setBlockState(pos.add(18, 13, 38), ((BlockColored)Blocks.STAINED_HARDENED_CLAY).getStateFromMeta(7));
      world.setBlockState(pos.add(19, 13, 38), ((BlockColored)Blocks.STAINED_HARDENED_CLAY).getStateFromMeta(7));
      world.setBlockState(pos.add(20, 13, 38), ((BlockColored)Blocks.STAINED_HARDENED_CLAY).getStateFromMeta(7));
      world.setBlockState(pos.add(21, 13, 38), Blocks.QUARTZ_BLOCK.getDefaultState());
      world.setBlockState(pos.add(22, 13, 38), Blocks.QUARTZ_BLOCK.getDefaultState());
      world.setBlockState(pos.add(30, 13, 38), Blocks.QUARTZ_BLOCK.getDefaultState());
      world.setBlockState(pos.add(31, 13, 38), Blocks.QUARTZ_BLOCK.getDefaultState());
      world.setBlockState(pos.add(32, 13, 38), ((BlockColored)Blocks.STAINED_HARDENED_CLAY).getStateFromMeta(7));
      world.setBlockState(pos.add(33, 13, 38), ((BlockColored)Blocks.STAINED_HARDENED_CLAY).getStateFromMeta(7));
      world.setBlockState(pos.add(34, 13, 38), ((BlockColored)Blocks.STAINED_HARDENED_CLAY).getStateFromMeta(7));
      world.setBlockState(pos.add(35, 13, 38), ((BlockColored)Blocks.STAINED_HARDENED_CLAY).getStateFromMeta(4));
      world.setBlockState(pos.add(36, 13, 38), ((BlockColored)Blocks.STAINED_HARDENED_CLAY).getStateFromMeta(4));
      world.setBlockState(pos.add(16, 13, 39), ((BlockColored)Blocks.STAINED_HARDENED_CLAY).getStateFromMeta(4));
      world.setBlockState(pos.add(20, 13, 39), ((BlockColored)Blocks.STAINED_HARDENED_CLAY).getStateFromMeta(4));
      world.setBlockState(pos.add(21, 13, 39), Blocks.QUARTZ_BLOCK.getDefaultState());
      world.setBlockState(pos.add(22, 13, 39), Blocks.QUARTZ_BLOCK.getDefaultState());
      world.setBlockState(pos.add(30, 13, 39), Blocks.QUARTZ_BLOCK.getDefaultState());
      world.setBlockState(pos.add(31, 13, 39), Blocks.QUARTZ_BLOCK.getDefaultState());
      world.setBlockState(pos.add(32, 13, 39), ((BlockColored)Blocks.STAINED_HARDENED_CLAY).getStateFromMeta(4));
      world.setBlockState(pos.add(36, 13, 39), ((BlockColored)Blocks.STAINED_HARDENED_CLAY).getStateFromMeta(4));
      world.setBlockState(pos.add(5, 13, 40), Blocks.STONE.getDefaultState());
      world.setBlockState(pos.add(6, 13, 40), Blocks.STONE.getDefaultState());
      world.setBlockState(pos.add(7, 13, 40), Blocks.STONE.getDefaultState());
      world.setBlockState(pos.add(16, 13, 40), ((BlockColored)Blocks.STAINED_HARDENED_CLAY).getStateFromMeta(4));
      world.setBlockState(pos.add(20, 13, 40), ((BlockColored)Blocks.STAINED_HARDENED_CLAY).getStateFromMeta(4));
      world.setBlockState(pos.add(21, 13, 40), Blocks.QUARTZ_BLOCK.getDefaultState());
      world.setBlockState(pos.add(22, 13, 40), Blocks.QUARTZ_BLOCK.getDefaultState());
      world.setBlockState(pos.add(23, 13, 40), ((BlockStaticLiquid)Blocks.LAVA).getStateFromMeta(10));
      world.setBlockState(pos.add(29, 13, 40), ((BlockStaticLiquid)Blocks.LAVA).getStateFromMeta(10));
      world.setBlockState(pos.add(30, 13, 40), Blocks.QUARTZ_BLOCK.getDefaultState());
      world.setBlockState(pos.add(31, 13, 40), Blocks.QUARTZ_BLOCK.getDefaultState());
      world.setBlockState(pos.add(32, 13, 40), ((BlockColored)Blocks.STAINED_HARDENED_CLAY).getStateFromMeta(4));
      world.setBlockState(pos.add(35, 13, 40), ((BlockColored)Blocks.STAINED_HARDENED_CLAY).getStateFromMeta(4));
      world.setBlockState(pos.add(36, 13, 40), ((BlockColored)Blocks.STAINED_HARDENED_CLAY).getStateFromMeta(4));
      world.setBlockState(pos.add(4, 13, 41), Blocks.STONE.getDefaultState());
      world.setBlockState(pos.add(8, 13, 41), Blocks.STONE.getDefaultState());
      world.setBlockState(pos.add(17, 13, 41), Blocks.QUARTZ_BLOCK.getDefaultState());
      world.setBlockState(pos.add(20, 13, 41), Blocks.QUARTZ_BLOCK.getDefaultState());
      world.setBlockState(pos.add(21, 13, 41), Blocks.QUARTZ_BLOCK.getDefaultState());
      world.setBlockState(pos.add(22, 13, 41), Blocks.QUARTZ_BLOCK.getDefaultState());
      world.setBlockState(pos.add(23, 13, 41), Blocks.STONE.getDefaultState());
      world.setBlockState(pos.add(24, 13, 41), Blocks.STONE.getDefaultState());
      world.setBlockState(pos.add(28, 13, 41), Blocks.STONE.getDefaultState());
      world.setBlockState(pos.add(29, 13, 41), Blocks.STONE.getDefaultState());
      world.setBlockState(pos.add(30, 13, 41), Blocks.QUARTZ_BLOCK.getDefaultState());
      world.setBlockState(pos.add(31, 13, 41), Blocks.QUARTZ_BLOCK.getDefaultState());
      world.setBlockState(pos.add(32, 13, 41), Blocks.QUARTZ_BLOCK.getDefaultState());
      world.setBlockState(pos.add(35, 13, 41), Blocks.QUARTZ_BLOCK.getDefaultState());
      world.setBlockState(pos.add(3, 13, 42), Blocks.STONE.getDefaultState());
      world.setBlockState(pos.add(9, 13, 42), Blocks.STONE.getDefaultState());
      world.setBlockState(pos.add(17, 13, 42), Blocks.QUARTZ_BLOCK.getDefaultState());
      world.setBlockState(pos.add(20, 13, 42), Blocks.QUARTZ_BLOCK.getDefaultState());
      world.setBlockState(pos.add(21, 13, 42), Blocks.QUARTZ_BLOCK.getDefaultState());
      world.setBlockState(pos.add(22, 13, 42), Blocks.QUARTZ_BLOCK.getDefaultState());
      world.setBlockState(pos.add(23, 13, 42), Blocks.STONE.getDefaultState());
      world.setBlockState(pos.add(24, 13, 42), Blocks.STONE.getDefaultState());
      world.setBlockState(pos.add(28, 13, 42), Blocks.STONE.getDefaultState());
      world.setBlockState(pos.add(29, 13, 42), Blocks.STONE.getDefaultState());
      world.setBlockState(pos.add(30, 13, 42), Blocks.QUARTZ_BLOCK.getDefaultState());
      world.setBlockState(pos.add(31, 13, 42), Blocks.QUARTZ_BLOCK.getDefaultState());
      world.setBlockState(pos.add(32, 13, 42), Blocks.QUARTZ_BLOCK.getDefaultState());
      world.setBlockState(pos.add(35, 13, 42), Blocks.QUARTZ_BLOCK.getDefaultState());
      world.setBlockState(pos.add(3, 13, 43), Blocks.STONE.getDefaultState());
      world.setBlockState(pos.add(9, 13, 43), Blocks.STONE.getDefaultState());
      world.setBlockState(pos.add(16, 13, 43), ((BlockColored)Blocks.STAINED_HARDENED_CLAY).getStateFromMeta(4));
      world.setBlockState(pos.add(20, 13, 43), ((BlockColored)Blocks.STAINED_HARDENED_CLAY).getStateFromMeta(4));
      world.setBlockState(pos.add(21, 13, 43), Blocks.QUARTZ_BLOCK.getDefaultState());
      world.setBlockState(pos.add(22, 13, 43), Blocks.QUARTZ_BLOCK.getDefaultState());
      world.setBlockState(pos.add(23, 13, 43), ((BlockStaticLiquid)Blocks.LAVA).getStateFromMeta(10));
      world.setBlockState(pos.add(29, 13, 43), ((BlockStaticLiquid)Blocks.LAVA).getStateFromMeta(10));
      world.setBlockState(pos.add(30, 13, 43), Blocks.QUARTZ_BLOCK.getDefaultState());
      world.setBlockState(pos.add(31, 13, 43), Blocks.QUARTZ_BLOCK.getDefaultState());
      world.setBlockState(pos.add(32, 13, 43), ((BlockColored)Blocks.STAINED_HARDENED_CLAY).getStateFromMeta(4));
      world.setBlockState(pos.add(36, 13, 43), ((BlockColored)Blocks.STAINED_HARDENED_CLAY).getStateFromMeta(4));
      world.setBlockState(pos.add(3, 13, 44), Blocks.STONE.getDefaultState());
      world.setBlockState(pos.add(9, 13, 44), Blocks.STONE.getDefaultState());
      world.setBlockState(pos.add(16, 13, 44), ((BlockColored)Blocks.STAINED_HARDENED_CLAY).getStateFromMeta(4));
      world.setBlockState(pos.add(20, 13, 44), ((BlockColored)Blocks.STAINED_HARDENED_CLAY).getStateFromMeta(4));
      world.setBlockState(pos.add(21, 13, 44), Blocks.QUARTZ_BLOCK.getDefaultState());
      world.setBlockState(pos.add(22, 13, 44), Blocks.QUARTZ_BLOCK.getDefaultState());
      world.setBlockState(pos.add(30, 13, 44), Blocks.QUARTZ_BLOCK.getDefaultState());
      world.setBlockState(pos.add(31, 13, 44), Blocks.QUARTZ_BLOCK.getDefaultState());
      world.setBlockState(pos.add(32, 13, 44), ((BlockColored)Blocks.STAINED_HARDENED_CLAY).getStateFromMeta(4));
      world.setBlockState(pos.add(36, 13, 44), ((BlockColored)Blocks.STAINED_HARDENED_CLAY).getStateFromMeta(4));
      world.setBlockState(pos.add(4, 13, 45), Blocks.STONE.getDefaultState());
      world.setBlockState(pos.add(8, 13, 45), Blocks.STONE.getDefaultState());
      world.setBlockState(pos.add(16, 13, 45), ((BlockColored)Blocks.STAINED_HARDENED_CLAY).getStateFromMeta(4));
      world.setBlockState(pos.add(20, 13, 45), ((BlockColored)Blocks.STAINED_HARDENED_CLAY).getStateFromMeta(4));
      world.setBlockState(pos.add(21, 13, 45), Blocks.QUARTZ_BLOCK.getDefaultState());
      world.setBlockState(pos.add(22, 13, 45), Blocks.QUARTZ_BLOCK.getDefaultState());
      world.setBlockState(pos.add(23, 13, 45), ((BlockStaticLiquid)Blocks.LAVA).getStateFromMeta(10));
      world.setBlockState(pos.add(29, 13, 45), ((BlockStaticLiquid)Blocks.LAVA).getStateFromMeta(10));
      world.setBlockState(pos.add(30, 13, 45), Blocks.QUARTZ_BLOCK.getDefaultState());
      world.setBlockState(pos.add(31, 13, 45), Blocks.QUARTZ_BLOCK.getDefaultState());
      world.setBlockState(pos.add(32, 13, 45), ((BlockColored)Blocks.STAINED_HARDENED_CLAY).getStateFromMeta(4));
      world.setBlockState(pos.add(36, 13, 45), ((BlockColored)Blocks.STAINED_HARDENED_CLAY).getStateFromMeta(4));
      world.setBlockState(pos.add(5, 13, 46), Blocks.STONE.getDefaultState());
      world.setBlockState(pos.add(6, 13, 46), Blocks.STONE.getDefaultState());
      world.setBlockState(pos.add(7, 13, 46), Blocks.STONE.getDefaultState());
      world.setBlockState(pos.add(17, 13, 46), Blocks.QUARTZ_BLOCK.getDefaultState());
      world.setBlockState(pos.add(18, 13, 46), Blocks.QUARTZ_BLOCK.getDefaultState());
      world.setBlockState(pos.add(19, 13, 46), Blocks.QUARTZ_BLOCK.getDefaultState());
      world.setBlockState(pos.add(20, 13, 46), Blocks.QUARTZ_BLOCK.getDefaultState());
      world.setBlockState(pos.add(21, 13, 46), Blocks.QUARTZ_BLOCK.getDefaultState());
      world.setBlockState(pos.add(22, 13, 46), Blocks.QUARTZ_BLOCK.getDefaultState());
      world.setBlockState(pos.add(23, 13, 46), Blocks.STONE.getDefaultState());
      world.setBlockState(pos.add(24, 13, 46), Blocks.STONE.getDefaultState());
      world.setBlockState(pos.add(28, 13, 46), Blocks.STONE.getDefaultState());
      world.setBlockState(pos.add(29, 13, 46), Blocks.STONE.getDefaultState());
      world.setBlockState(pos.add(30, 13, 46), Blocks.QUARTZ_BLOCK.getDefaultState());
      world.setBlockState(pos.add(31, 13, 46), Blocks.QUARTZ_BLOCK.getDefaultState());
      world.setBlockState(pos.add(32, 13, 46), Blocks.QUARTZ_BLOCK.getDefaultState());
      world.setBlockState(pos.add(35, 13, 46), Blocks.QUARTZ_BLOCK.getDefaultState());
      world.setBlockState(pos.add(17, 13, 47), Blocks.QUARTZ_BLOCK.getDefaultState());
      world.setBlockState(pos.add(18, 13, 47), Blocks.QUARTZ_BLOCK.getDefaultState());
      world.setBlockState(pos.add(19, 13, 47), Blocks.QUARTZ_BLOCK.getDefaultState());
      world.setBlockState(pos.add(20, 13, 47), Blocks.QUARTZ_BLOCK.getDefaultState());
      world.setBlockState(pos.add(21, 13, 47), Blocks.QUARTZ_BLOCK.getDefaultState());
      world.setBlockState(pos.add(22, 13, 47), Blocks.QUARTZ_BLOCK.getDefaultState());
      world.setBlockState(pos.add(23, 13, 47), Blocks.STONE.getDefaultState());
      world.setBlockState(pos.add(24, 13, 47), Blocks.STONE.getDefaultState());
      world.setBlockState(pos.add(28, 13, 47), Blocks.STONE.getDefaultState());
      world.setBlockState(pos.add(29, 13, 47), Blocks.STONE.getDefaultState());
      world.setBlockState(pos.add(30, 13, 47), Blocks.QUARTZ_BLOCK.getDefaultState());
      world.setBlockState(pos.add(31, 13, 47), Blocks.QUARTZ_BLOCK.getDefaultState());
      world.setBlockState(pos.add(32, 13, 47), Blocks.QUARTZ_BLOCK.getDefaultState());
      world.setBlockState(pos.add(35, 13, 47), Blocks.QUARTZ_BLOCK.getDefaultState());
      world.setBlockState(pos.add(16, 13, 48), ((BlockColored)Blocks.STAINED_HARDENED_CLAY).getStateFromMeta(4));
      world.setBlockState(pos.add(20, 13, 48), ((BlockColored)Blocks.STAINED_HARDENED_CLAY).getStateFromMeta(4));
      world.setBlockState(pos.add(21, 13, 48), Blocks.QUARTZ_BLOCK.getDefaultState());
      world.setBlockState(pos.add(22, 13, 48), Blocks.QUARTZ_BLOCK.getDefaultState());
      world.setBlockState(pos.add(23, 13, 48), ((BlockStaticLiquid)Blocks.LAVA).getStateFromMeta(10));
      world.setBlockState(pos.add(29, 13, 48), ((BlockStaticLiquid)Blocks.LAVA).getStateFromMeta(10));
      world.setBlockState(pos.add(30, 13, 48), Blocks.QUARTZ_BLOCK.getDefaultState());
      world.setBlockState(pos.add(31, 13, 48), Blocks.QUARTZ_BLOCK.getDefaultState());
      world.setBlockState(pos.add(32, 13, 48), ((BlockColored)Blocks.STAINED_HARDENED_CLAY).getStateFromMeta(4));
      world.setBlockState(pos.add(36, 13, 48), ((BlockColored)Blocks.STAINED_HARDENED_CLAY).getStateFromMeta(4));
      world.setBlockState(pos.add(16, 13, 49), ((BlockColored)Blocks.STAINED_HARDENED_CLAY).getStateFromMeta(4));
      world.setBlockState(pos.add(20, 13, 49), ((BlockColored)Blocks.STAINED_HARDENED_CLAY).getStateFromMeta(4));
      world.setBlockState(pos.add(21, 13, 49), Blocks.QUARTZ_BLOCK.getDefaultState());
      world.setBlockState(pos.add(22, 13, 49), Blocks.QUARTZ_BLOCK.getDefaultState());
      world.setBlockState(pos.add(30, 13, 49), Blocks.QUARTZ_BLOCK.getDefaultState());
      world.setBlockState(pos.add(31, 13, 49), Blocks.QUARTZ_BLOCK.getDefaultState());
      world.setBlockState(pos.add(32, 13, 49), ((BlockColored)Blocks.STAINED_HARDENED_CLAY).getStateFromMeta(4));
      world.setBlockState(pos.add(36, 13, 49), ((BlockColored)Blocks.STAINED_HARDENED_CLAY).getStateFromMeta(4));
      world.setBlockState(pos.add(16, 13, 50), ((BlockColored)Blocks.STAINED_HARDENED_CLAY).getStateFromMeta(4));
      world.setBlockState(pos.add(17, 13, 50), ((BlockColored)Blocks.STAINED_HARDENED_CLAY).getStateFromMeta(4));
      world.setBlockState(pos.add(18, 13, 50), ((BlockColored)Blocks.STAINED_HARDENED_CLAY).getStateFromMeta(4));
      world.setBlockState(pos.add(19, 13, 50), ((BlockColored)Blocks.STAINED_HARDENED_CLAY).getStateFromMeta(4));
      world.setBlockState(pos.add(20, 13, 50), ((BlockColored)Blocks.STAINED_HARDENED_CLAY).getStateFromMeta(4));
      world.setBlockState(pos.add(21, 13, 50), Blocks.QUARTZ_BLOCK.getDefaultState());
      world.setBlockState(pos.add(22, 13, 50), Blocks.QUARTZ_BLOCK.getDefaultState());
      world.setBlockState(pos.add(30, 13, 50), Blocks.QUARTZ_BLOCK.getDefaultState());
      world.setBlockState(pos.add(31, 13, 50), Blocks.QUARTZ_BLOCK.getDefaultState());
      world.setBlockState(pos.add(32, 13, 50), ((BlockColored)Blocks.STAINED_HARDENED_CLAY).getStateFromMeta(4));
      world.setBlockState(pos.add(33, 13, 50), ((BlockColored)Blocks.STAINED_HARDENED_CLAY).getStateFromMeta(4));
      world.setBlockState(pos.add(34, 13, 50), ((BlockColored)Blocks.STAINED_HARDENED_CLAY).getStateFromMeta(4));
      world.setBlockState(pos.add(35, 13, 50), ((BlockColored)Blocks.STAINED_HARDENED_CLAY).getStateFromMeta(4));
      world.setBlockState(pos.add(36, 13, 50), ((BlockColored)Blocks.STAINED_HARDENED_CLAY).getStateFromMeta(4));
      world.setBlockState(pos.add(18, 13, 51), ((BlockColored)Blocks.STAINED_HARDENED_CLAY).getStateFromMeta(4));
      world.setBlockState(pos.add(19, 13, 51), ((BlockColored)Blocks.STAINED_HARDENED_CLAY).getStateFromMeta(4));
      world.setBlockState(pos.add(20, 13, 51), ((BlockColored)Blocks.STAINED_HARDENED_CLAY).getStateFromMeta(4));
      world.setBlockState(pos.add(21, 13, 51), ((BlockColored)Blocks.STAINED_HARDENED_CLAY).getStateFromMeta(4));
      world.setBlockState(pos.add(30, 13, 51), ((BlockColored)Blocks.STAINED_HARDENED_CLAY).getStateFromMeta(4));
      world.setBlockState(pos.add(31, 13, 51), ((BlockColored)Blocks.STAINED_HARDENED_CLAY).getStateFromMeta(4));
      world.setBlockState(pos.add(32, 13, 51), ((BlockColored)Blocks.STAINED_HARDENED_CLAY).getStateFromMeta(4));
      world.setBlockState(pos.add(33, 13, 51), ((BlockColored)Blocks.STAINED_HARDENED_CLAY).getStateFromMeta(4));
      world.setBlockState(pos.add(34, 13, 51), ((BlockColored)Blocks.STAINED_HARDENED_CLAY).getStateFromMeta(4));
      world.setBlockState(pos.add(17, 13, 52), ((BlockColored)Blocks.STAINED_HARDENED_CLAY).getStateFromMeta(4));
      world.setBlockState(pos.add(18, 13, 52), ((BlockColored)Blocks.STAINED_HARDENED_CLAY).getStateFromMeta(4));
      world.setBlockState(pos.add(22, 13, 52), ((BlockColored)Blocks.STAINED_HARDENED_CLAY).getStateFromMeta(4));
      world.setBlockState(pos.add(29, 13, 52), ((BlockColored)Blocks.STAINED_HARDENED_CLAY).getStateFromMeta(4));
      world.setBlockState(pos.add(30, 13, 52), ((BlockColored)Blocks.STAINED_HARDENED_CLAY).getStateFromMeta(4));
      world.setBlockState(pos.add(34, 13, 52), ((BlockColored)Blocks.STAINED_HARDENED_CLAY).getStateFromMeta(4));
      world.setBlockState(pos.add(35, 13, 52), ((BlockColored)Blocks.STAINED_HARDENED_CLAY).getStateFromMeta(4));
      world.setBlockState(pos.add(16, 13, 53), ((BlockColored)Blocks.STAINED_HARDENED_CLAY).getStateFromMeta(4));
      world.setBlockState(pos.add(17, 13, 53), ((BlockColored)Blocks.STAINED_HARDENED_CLAY).getStateFromMeta(4));
      world.setBlockState(pos.add(23, 13, 53), ((BlockColored)Blocks.STAINED_HARDENED_CLAY).getStateFromMeta(4));
      world.setBlockState(pos.add(24, 13, 53), ((BlockColored)Blocks.STAINED_HARDENED_CLAY).getStateFromMeta(4));
      world.setBlockState(pos.add(28, 13, 53), ((BlockColored)Blocks.STAINED_HARDENED_CLAY).getStateFromMeta(4));
      world.setBlockState(pos.add(29, 13, 53), ((BlockColored)Blocks.STAINED_HARDENED_CLAY).getStateFromMeta(4));
      world.setBlockState(pos.add(35, 13, 53), ((BlockColored)Blocks.STAINED_HARDENED_CLAY).getStateFromMeta(4));
      world.setBlockState(pos.add(36, 13, 53), ((BlockColored)Blocks.STAINED_HARDENED_CLAY).getStateFromMeta(4));
      world.setBlockState(pos.add(16, 13, 54), ((BlockColored)Blocks.STAINED_HARDENED_CLAY).getStateFromMeta(4));
      world.setBlockState(pos.add(17, 13, 54), ((BlockColored)Blocks.STAINED_HARDENED_CLAY).getStateFromMeta(4));
      world.setBlockState(pos.add(23, 13, 54), ((BlockColored)Blocks.STAINED_HARDENED_CLAY).getStateFromMeta(4));
      world.setBlockState(pos.add(24, 13, 54), ((BlockColored)Blocks.STAINED_HARDENED_CLAY).getStateFromMeta(4));
      world.setBlockState(pos.add(28, 13, 54), ((BlockColored)Blocks.STAINED_HARDENED_CLAY).getStateFromMeta(4));
      world.setBlockState(pos.add(29, 13, 54), ((BlockColored)Blocks.STAINED_HARDENED_CLAY).getStateFromMeta(4));
      world.setBlockState(pos.add(35, 13, 54), ((BlockColored)Blocks.STAINED_HARDENED_CLAY).getStateFromMeta(4));
      world.setBlockState(pos.add(36, 13, 54), ((BlockColored)Blocks.STAINED_HARDENED_CLAY).getStateFromMeta(4));
      world.setBlockState(pos.add(16, 13, 55), ((BlockColored)Blocks.STAINED_HARDENED_CLAY).getStateFromMeta(4));
      world.setBlockState(pos.add(17, 13, 55), ((BlockColored)Blocks.STAINED_HARDENED_CLAY).getStateFromMeta(4));
      world.setBlockState(pos.add(23, 13, 55), ((BlockColored)Blocks.STAINED_HARDENED_CLAY).getStateFromMeta(4));
      world.setBlockState(pos.add(24, 13, 55), ((BlockColored)Blocks.STAINED_HARDENED_CLAY).getStateFromMeta(4));
      world.setBlockState(pos.add(25, 13, 55), ((BlockRedstoneTorch)Blocks.REDSTONE_TORCH).getStateFromMeta(1));
      world.setBlockState(pos.add(27, 13, 55), ((BlockRedstoneTorch)Blocks.REDSTONE_TORCH).getStateFromMeta(2));
      world.setBlockState(pos.add(28, 13, 55), ((BlockColored)Blocks.STAINED_HARDENED_CLAY).getStateFromMeta(4));
      world.setBlockState(pos.add(29, 13, 55), ((BlockColored)Blocks.STAINED_HARDENED_CLAY).getStateFromMeta(4));
      world.setBlockState(pos.add(35, 13, 55), ((BlockColored)Blocks.STAINED_HARDENED_CLAY).getStateFromMeta(4));
      world.setBlockState(pos.add(36, 13, 55), ((BlockColored)Blocks.STAINED_HARDENED_CLAY).getStateFromMeta(4));
      world.setBlockState(pos.add(37, 13, 55), ((BlockColored)Blocks.STAINED_HARDENED_CLAY).getStateFromMeta(4));
      world.setBlockState(pos.add(17, 13, 56), ((BlockColored)Blocks.STAINED_HARDENED_CLAY).getStateFromMeta(4));
      world.setBlockState(pos.add(18, 13, 56), ((BlockColored)Blocks.STAINED_HARDENED_CLAY).getStateFromMeta(4));
      world.setBlockState(pos.add(22, 13, 56), ((BlockColored)Blocks.STAINED_HARDENED_CLAY).getStateFromMeta(4));
      world.setBlockState(pos.add(23, 13, 56), ((BlockColored)Blocks.STAINED_HARDENED_CLAY).getStateFromMeta(4));
      world.setBlockState(pos.add(24, 13, 56), Blocks.NETHER_BRICK_FENCE.getDefaultState());
      world.setBlockState(pos.add(28, 13, 56), Blocks.NETHER_BRICK_FENCE.getDefaultState());
      world.setBlockState(pos.add(29, 13, 56), ((BlockColored)Blocks.STAINED_HARDENED_CLAY).getStateFromMeta(4));
      world.setBlockState(pos.add(30, 13, 56), ((BlockColored)Blocks.STAINED_HARDENED_CLAY).getStateFromMeta(4));
      world.setBlockState(pos.add(34, 13, 56), ((BlockColored)Blocks.STAINED_HARDENED_CLAY).getStateFromMeta(4));
      world.setBlockState(pos.add(35, 13, 56), ((BlockColored)Blocks.STAINED_HARDENED_CLAY).getStateFromMeta(4));
      world.setBlockState(pos.add(38, 13, 56), ((BlockColored)Blocks.STAINED_HARDENED_CLAY).getStateFromMeta(4));
      world.setBlockState(pos.add(39, 13, 56), ((BlockColored)Blocks.WOOL).getStateFromMeta(15));
      world.setBlockState(pos.add(40, 13, 56), ((BlockColored)Blocks.WOOL).getStateFromMeta(15));
      world.setBlockState(pos.add(18, 13, 57), ((BlockColored)Blocks.STAINED_HARDENED_CLAY).getStateFromMeta(4));
      world.setBlockState(pos.add(19, 13, 57), ((BlockColored)Blocks.STAINED_HARDENED_CLAY).getStateFromMeta(4));
      world.setBlockState(pos.add(20, 13, 57), ((BlockColored)Blocks.STAINED_HARDENED_CLAY).getStateFromMeta(4));
      world.setBlockState(pos.add(21, 13, 57), ((BlockColored)Blocks.STAINED_HARDENED_CLAY).getStateFromMeta(4));
      world.setBlockState(pos.add(22, 13, 57), ((BlockColored)Blocks.STAINED_HARDENED_CLAY).getStateFromMeta(4));
      world.setBlockState(pos.add(23, 13, 57), Blocks.STONE.getDefaultState());
      world.setBlockState(pos.add(24, 13, 57), Blocks.NETHER_BRICK_FENCE.getDefaultState());
      world.setBlockState(pos.add(28, 13, 57), Blocks.NETHER_BRICK_FENCE.getDefaultState());
      world.setBlockState(pos.add(29, 13, 57), Blocks.STONE.getDefaultState());
      world.setBlockState(pos.add(30, 13, 57), ((BlockColored)Blocks.STAINED_HARDENED_CLAY).getStateFromMeta(4));
      world.setBlockState(pos.add(31, 13, 57), ((BlockColored)Blocks.STAINED_HARDENED_CLAY).getStateFromMeta(4));
      world.setBlockState(pos.add(32, 13, 57), ((BlockColored)Blocks.STAINED_HARDENED_CLAY).getStateFromMeta(4));
      world.setBlockState(pos.add(33, 13, 57), ((BlockColored)Blocks.STAINED_HARDENED_CLAY).getStateFromMeta(4));
      world.setBlockState(pos.add(34, 13, 57), ((BlockColored)Blocks.STAINED_HARDENED_CLAY).getStateFromMeta(4));
      world.setBlockState(pos.add(39, 13, 57), ((BlockColored)Blocks.STAINED_HARDENED_CLAY).getStateFromMeta(4));
      world.setBlockState(pos.add(41, 13, 57), ((BlockColored)Blocks.WOOL).getStateFromMeta(15));
      world.setBlockState(pos.add(19, 13, 58), ((BlockColored)Blocks.STAINED_HARDENED_CLAY).getStateFromMeta(4));
      world.setBlockState(pos.add(20, 13, 58), ((BlockColored)Blocks.STAINED_HARDENED_CLAY).getStateFromMeta(4));
      world.setBlockState(pos.add(21, 13, 58), ((BlockColored)Blocks.STAINED_HARDENED_CLAY).getStateFromMeta(4));
      world.setBlockState(pos.add(23, 13, 58), Blocks.STONE.getDefaultState());
      world.setBlockState(pos.add(29, 13, 58), Blocks.STONE.getDefaultState());
      world.setBlockState(pos.add(31, 13, 58), ((BlockColored)Blocks.STAINED_HARDENED_CLAY).getStateFromMeta(4));
      world.setBlockState(pos.add(32, 13, 58), ((BlockColored)Blocks.STAINED_HARDENED_CLAY).getStateFromMeta(4));
      world.setBlockState(pos.add(33, 13, 58), ((BlockColored)Blocks.STAINED_HARDENED_CLAY).getStateFromMeta(4));
      world.setBlockState(pos.add(40, 13, 58), ((BlockColored)Blocks.STAINED_HARDENED_CLAY).getStateFromMeta(4));
      world.setBlockState(pos.add(42, 13, 58), ((BlockColored)Blocks.WOOL).getStateFromMeta(15));
      world.setBlockState(pos.add(21, 13, 59), Blocks.STONE.getDefaultState());
      world.setBlockState(pos.add(22, 13, 59), Blocks.STONE.getDefaultState());
      world.setBlockState(pos.add(29, 13, 59), Blocks.STONE.getDefaultState());
      world.setBlockState(pos.add(34, 13, 59), ((BlockColored)Blocks.WOOL).getStateFromMeta(15));
      world.setBlockState(pos.add(35, 13, 59), ((BlockColored)Blocks.WOOL).getStateFromMeta(15));
      world.setBlockState(pos.add(36, 13, 59), ((BlockColored)Blocks.WOOL).getStateFromMeta(15));
      world.setBlockState(pos.add(37, 13, 59), ((BlockColored)Blocks.WOOL).getStateFromMeta(15));
      world.setBlockState(pos.add(41, 13, 59), ((BlockColored)Blocks.STAINED_HARDENED_CLAY).getStateFromMeta(4));
      world.setBlockState(pos.add(42, 13, 59), ((BlockColored)Blocks.WOOL).getStateFromMeta(15));
      world.setBlockState(pos.add(18, 13, 60), Blocks.STONE.getDefaultState());
      world.setBlockState(pos.add(19, 13, 60), Blocks.STONE.getDefaultState());
      world.setBlockState(pos.add(20, 13, 60), Blocks.STONE.getDefaultState());
      world.setBlockState(pos.add(29, 13, 60), Blocks.STONE.getDefaultState());
      world.setBlockState(pos.add(33, 13, 60), ((BlockColored)Blocks.WOOL).getStateFromMeta(15));
      world.setBlockState(pos.add(38, 13, 60), ((BlockColored)Blocks.WOOL).getStateFromMeta(15));
      world.setBlockState(pos.add(42, 13, 60), Blocks.STONE.getDefaultState());
      world.setBlockState(pos.add(43, 13, 60), Blocks.STONE.getDefaultState());
      world.setBlockState(pos.add(44, 13, 60), Blocks.STONE.getDefaultState());
      world.setBlockState(pos.add(45, 13, 60), Blocks.STONE.getDefaultState());
      world.setBlockState(pos.add(18, 13, 61), Blocks.OBSIDIAN.getDefaultState());
      world.setBlockState(pos.add(19, 13, 61), Blocks.FIRE.getStateFromMeta(15));
      world.setBlockState(pos.add(20, 13, 61), Blocks.FIRE.getStateFromMeta(15));
      world.setBlockState(pos.add(21, 13, 61), Blocks.STONE.getDefaultState());
      world.setBlockState(pos.add(29, 13, 61), Blocks.STONE.getDefaultState());
      world.setBlockState(pos.add(32, 13, 61), ((BlockColored)Blocks.WOOL).getStateFromMeta(15));
      world.setBlockState(pos.add(39, 13, 61), ((BlockColored)Blocks.WOOL).getStateFromMeta(15));
      world.setBlockState(pos.add(41, 13, 61), Blocks.STONE.getDefaultState());
      world.setBlockState(pos.add(46, 13, 61), Blocks.STONE.getDefaultState());
      world.setBlockState(pos.add(18, 13, 62), Blocks.OBSIDIAN.getDefaultState());
      world.setBlockState(pos.add(19, 13, 62), Blocks.FIRE.getStateFromMeta(15));
      world.setBlockState(pos.add(20, 13, 62), Blocks.FIRE.getStateFromMeta(15));
      world.setBlockState(pos.add(21, 13, 62), Blocks.IRON_BARS.getDefaultState());
      world.setBlockState(pos.add(29, 13, 62), Blocks.STONE.getDefaultState());
      world.setBlockState(pos.add(32, 13, 62), ((BlockColored)Blocks.WOOL).getStateFromMeta(15));
      world.setBlockState(pos.add(39, 13, 62), ((BlockColored)Blocks.WOOL).getStateFromMeta(15));
      world.setBlockState(pos.add(40, 13, 62), Blocks.STONE.getDefaultState());
      world.setBlockState(pos.add(47, 13, 62), Blocks.STONE.getDefaultState());
      world.setBlockState(pos.add(18, 13, 63), Blocks.OBSIDIAN.getDefaultState());
      world.setBlockState(pos.add(19, 13, 63), Blocks.FIRE.getStateFromMeta(15));
      world.setBlockState(pos.add(20, 13, 63), Blocks.FIRE.getStateFromMeta(15));
      world.setBlockState(pos.add(21, 13, 63), Blocks.IRON_BARS.getDefaultState());
      world.setBlockState(pos.add(23, 13, 63), Blocks.IRON_BARS.getDefaultState());
      world.setBlockState(pos.add(24, 13, 63), Blocks.IRON_BARS.getDefaultState());
      world.setBlockState(pos.add(25, 13, 63), Blocks.IRON_BARS.getDefaultState());
      world.setBlockState(pos.add(26, 13, 63), Blocks.IRON_BARS.getDefaultState());
      world.setBlockState(pos.add(27, 13, 63), Blocks.IRON_BARS.getDefaultState());
      world.setBlockState(pos.add(28, 13, 63), Blocks.IRON_BARS.getDefaultState());
      world.setBlockState(pos.add(29, 13, 63), Blocks.STONE.getDefaultState());
      world.setBlockState(pos.add(32, 13, 63), ((BlockColored)Blocks.WOOL).getStateFromMeta(15));
      world.setBlockState(pos.add(39, 13, 63), ((BlockColored)Blocks.WOOL).getStateFromMeta(15));
      world.setBlockState(pos.add(40, 13, 63), Blocks.STONE.getDefaultState());
      world.setBlockState(pos.add(47, 13, 63), Blocks.STONE.getDefaultState());
      world.setBlockState(pos.add(18, 13, 64), Blocks.OBSIDIAN.getDefaultState());
      world.setBlockState(pos.add(19, 13, 64), Blocks.FIRE.getStateFromMeta(15));
      world.setBlockState(pos.add(20, 13, 64), Blocks.FIRE.getStateFromMeta(15));
      world.setBlockState(pos.add(21, 13, 64), Blocks.STONE.getDefaultState());
      world.setBlockState(pos.add(23, 13, 64), Blocks.IRON_BARS.getDefaultState());
      world.setBlockState(pos.add(29, 13, 64), Blocks.STONE.getDefaultState());
      world.setBlockState(pos.add(32, 13, 64), ((BlockColored)Blocks.WOOL).getStateFromMeta(15));
      world.setBlockState(pos.add(39, 13, 64), ((BlockColored)Blocks.WOOL).getStateFromMeta(15));
      world.setBlockState(pos.add(40, 13, 64), Blocks.STONE.getDefaultState());
      world.setBlockState(pos.add(47, 13, 64), Blocks.STONE.getDefaultState());
      world.setBlockState(pos.add(18, 13, 65), Blocks.OBSIDIAN.getDefaultState());
      world.setBlockState(pos.add(19, 13, 65), Blocks.OBSIDIAN.getDefaultState());
      world.setBlockState(pos.add(20, 13, 65), Blocks.STONE.getDefaultState());
      world.setBlockState(pos.add(21, 13, 65), Blocks.STONE.getDefaultState());
      world.setBlockState(pos.add(23, 13, 65), Blocks.IRON_BARS.getDefaultState());
      world.setBlockState(pos.add(29, 13, 65), Blocks.STONE.getDefaultState());
      world.setBlockState(pos.add(33, 13, 65), ((BlockColored)Blocks.WOOL).getStateFromMeta(15));
      world.setBlockState(pos.add(38, 13, 65), ((BlockColored)Blocks.WOOL).getStateFromMeta(15));
      world.setBlockState(pos.add(40, 13, 65), Blocks.STONE.getDefaultState());
      world.setBlockState(pos.add(47, 13, 65), Blocks.STONE.getDefaultState());
      world.setBlockState(pos.add(18, 13, 66), Blocks.STONE.getDefaultState());
      world.setBlockState(pos.add(19, 13, 66), Blocks.STONE.getDefaultState());
      world.setBlockState(pos.add(20, 13, 66), Blocks.STONE.getDefaultState());
      world.setBlockState(pos.add(23, 13, 66), Blocks.IRON_BARS.getDefaultState());
      world.setBlockState(pos.add(29, 13, 66), Blocks.STONE.getDefaultState());
      world.setBlockState(pos.add(34, 13, 66), ((BlockColored)Blocks.WOOL).getStateFromMeta(15));
      world.setBlockState(pos.add(35, 13, 66), ((BlockColored)Blocks.WOOL).getStateFromMeta(15));
      world.setBlockState(pos.add(36, 13, 66), ((BlockColored)Blocks.WOOL).getStateFromMeta(15));
      world.setBlockState(pos.add(37, 13, 66), ((BlockColored)Blocks.WOOL).getStateFromMeta(15));
      world.setBlockState(pos.add(41, 13, 66), Blocks.STONE.getDefaultState());
      world.setBlockState(pos.add(46, 13, 66), Blocks.STONE.getDefaultState());
      world.setBlockState(pos.add(20, 13, 67), Blocks.STONE.getDefaultState());
      world.setBlockState(pos.add(21, 13, 67), Blocks.STONE.getDefaultState());
      world.setBlockState(pos.add(22, 13, 67), Blocks.STONE.getDefaultState());
      world.setBlockState(pos.add(23, 13, 67), Blocks.STONE.getDefaultState());
      world.setBlockState(pos.add(24, 13, 67), Blocks.STONE.getDefaultState());
      world.setBlockState(pos.add(25, 13, 67), Blocks.STONE.getDefaultState());
      world.setBlockState(pos.add(26, 13, 67), Blocks.STONE.getDefaultState());
      world.setBlockState(pos.add(27, 13, 67), Blocks.STONE.getDefaultState());
      world.setBlockState(pos.add(28, 13, 67), Blocks.STONE.getDefaultState());
      world.setBlockState(pos.add(42, 13, 67), Blocks.STONE.getDefaultState());
      world.setBlockState(pos.add(43, 13, 67), Blocks.STONE.getDefaultState());
      world.setBlockState(pos.add(44, 13, 67), Blocks.STONE.getDefaultState());
      world.setBlockState(pos.add(45, 13, 67), Blocks.STONE.getDefaultState());
      world.setBlockState(pos.add(24, 14, 36), Blocks.QUARTZ_BLOCK.getDefaultState());
      world.setBlockState(pos.add(25, 14, 36), ((BlockColored)Blocks.STAINED_HARDENED_CLAY).getStateFromMeta(10));
      world.setBlockState(pos.add(27, 14, 36), ((BlockColored)Blocks.STAINED_HARDENED_CLAY).getStateFromMeta(10));
      world.setBlockState(pos.add(28, 14, 36), Blocks.QUARTZ_BLOCK.getDefaultState());
      world.setBlockState(pos.add(16, 14, 37), ((BlockColored)Blocks.STAINED_HARDENED_CLAY).getStateFromMeta(4));
      world.setBlockState(pos.add(17, 14, 37), ((BlockColored)Blocks.STAINED_HARDENED_CLAY).getStateFromMeta(4));
      world.setBlockState(pos.add(21, 14, 37), Blocks.QUARTZ_BLOCK.getDefaultState());
      world.setBlockState(pos.add(22, 14, 37), Blocks.QUARTZ_BLOCK.getDefaultState());
      world.setBlockState(pos.add(23, 14, 37), ((BlockColored)Blocks.STAINED_HARDENED_CLAY).getStateFromMeta(4));
      world.setBlockState(pos.add(29, 14, 37), ((BlockColored)Blocks.STAINED_HARDENED_CLAY).getStateFromMeta(4));
      world.setBlockState(pos.add(35, 14, 37), ((BlockColored)Blocks.STAINED_HARDENED_CLAY).getStateFromMeta(4));
      world.setBlockState(pos.add(36, 14, 37), ((BlockColored)Blocks.STAINED_HARDENED_CLAY).getStateFromMeta(4));
      world.setBlockState(pos.add(16, 14, 38), ((BlockColored)Blocks.STAINED_HARDENED_CLAY).getStateFromMeta(4));
      world.setBlockState(pos.add(17, 14, 38), ((BlockColored)Blocks.STAINED_HARDENED_CLAY).getStateFromMeta(4));
      world.setBlockState(pos.add(18, 14, 38), ((BlockColored)Blocks.STAINED_HARDENED_CLAY).getStateFromMeta(7));
      world.setBlockState(pos.add(19, 14, 38), ((BlockColored)Blocks.STAINED_HARDENED_CLAY).getStateFromMeta(7));
      world.setBlockState(pos.add(20, 14, 38), ((BlockColored)Blocks.STAINED_HARDENED_CLAY).getStateFromMeta(7));
      world.setBlockState(pos.add(21, 14, 38), Blocks.QUARTZ_BLOCK.getDefaultState());
      world.setBlockState(pos.add(22, 14, 38), Blocks.QUARTZ_BLOCK.getDefaultState());
      world.setBlockState(pos.add(30, 14, 38), Blocks.QUARTZ_BLOCK.getDefaultState());
      world.setBlockState(pos.add(31, 14, 38), Blocks.QUARTZ_BLOCK.getDefaultState());
      world.setBlockState(pos.add(32, 14, 38), ((BlockColored)Blocks.STAINED_HARDENED_CLAY).getStateFromMeta(7));
      world.setBlockState(pos.add(33, 14, 38), ((BlockColored)Blocks.STAINED_HARDENED_CLAY).getStateFromMeta(7));
      world.setBlockState(pos.add(34, 14, 38), ((BlockColored)Blocks.STAINED_HARDENED_CLAY).getStateFromMeta(7));
      world.setBlockState(pos.add(35, 14, 38), ((BlockColored)Blocks.STAINED_HARDENED_CLAY).getStateFromMeta(4));
      world.setBlockState(pos.add(36, 14, 38), ((BlockColored)Blocks.STAINED_HARDENED_CLAY).getStateFromMeta(4));
      world.setBlockState(pos.add(4, 14, 39), Blocks.STONE.getDefaultState());
      world.setBlockState(pos.add(5, 14, 39), Blocks.STONE.getDefaultState());
      world.setBlockState(pos.add(6, 14, 39), Blocks.STONE.getDefaultState());
      world.setBlockState(pos.add(7, 14, 39), Blocks.STONE.getDefaultState());
      world.setBlockState(pos.add(8, 14, 39), Blocks.STONE.getDefaultState());
      world.setBlockState(pos.add(16, 14, 39), ((BlockColored)Blocks.STAINED_HARDENED_CLAY).getStateFromMeta(4));
      world.setBlockState(pos.add(20, 14, 39), ((BlockColored)Blocks.STAINED_HARDENED_CLAY).getStateFromMeta(4));
      world.setBlockState(pos.add(21, 14, 39), Blocks.QUARTZ_BLOCK.getDefaultState());
      world.setBlockState(pos.add(22, 14, 39), Blocks.QUARTZ_BLOCK.getDefaultState());
      world.setBlockState(pos.add(30, 14, 39), Blocks.QUARTZ_BLOCK.getDefaultState());
      world.setBlockState(pos.add(31, 14, 39), Blocks.QUARTZ_BLOCK.getDefaultState());
      world.setBlockState(pos.add(32, 14, 39), ((BlockColored)Blocks.STAINED_HARDENED_CLAY).getStateFromMeta(4));
      world.setBlockState(pos.add(36, 14, 39), ((BlockColored)Blocks.STAINED_HARDENED_CLAY).getStateFromMeta(4));
      world.setBlockState(pos.add(3, 14, 40), Blocks.STONE.getDefaultState());
      world.setBlockState(pos.add(4, 14, 40), Blocks.STONE.getDefaultState());
      world.setBlockState(pos.add(8, 14, 40), Blocks.STONE.getDefaultState());
      world.setBlockState(pos.add(9, 14, 40), Blocks.STONE.getDefaultState());
      world.setBlockState(pos.add(16, 14, 40), ((BlockColored)Blocks.STAINED_HARDENED_CLAY).getStateFromMeta(4));
      world.setBlockState(pos.add(20, 14, 40), ((BlockColored)Blocks.STAINED_HARDENED_CLAY).getStateFromMeta(4));
return true;
  }
}
