package com.slugterra.world.greatForge;
import java.util.Random;

import net.minecraft.init.Blocks;
import net.minecraft.world.World;
public class GreatWesternForgeStructure9 {
public boolean generate(World world, Random par2Random, int xco, int yco, int zco) {
      world.setBlock(xco + 21, yco + 14, zco + 40, Blocks.quartz_block, 0, 1);
      world.setBlock(xco + 22, yco + 14, zco + 40, Blocks.quartz_block, 0, 1);
      world.setBlock(xco + 23, yco + 14, zco + 40, Blocks.lava, 10, 1);
      world.setBlock(xco + 29, yco + 14, zco + 40, Blocks.lava, 10, 1);
      world.setBlock(xco + 30, yco + 14, zco + 40, Blocks.quartz_block, 0, 1);
      world.setBlock(xco + 31, yco + 14, zco + 40, Blocks.quartz_block, 0, 1);
      world.setBlock(xco + 32, yco + 14, zco + 40, Blocks.stained_hardened_clay, 4, 1);
      world.setBlock(xco + 35, yco + 14, zco + 40, Blocks.stained_hardened_clay, 4, 1);
      world.setBlock(xco + 36, yco + 14, zco + 40, Blocks.stained_hardened_clay, 4, 1);
      world.setBlock(xco + 2, yco + 14, zco + 41, Blocks.stone, 0, 1);
      world.setBlock(xco + 3, yco + 14, zco + 41, Blocks.stone, 0, 1);
      world.setBlock(xco + 9, yco + 14, zco + 41, Blocks.stone, 0, 1);
      world.setBlock(xco + 10, yco + 14, zco + 41, Blocks.stone, 0, 1);
      world.setBlock(xco + 17, yco + 14, zco + 41, Blocks.quartz_block, 0, 1);
      world.setBlock(xco + 20, yco + 14, zco + 41, Blocks.quartz_block, 0, 1);
      world.setBlock(xco + 21, yco + 14, zco + 41, Blocks.quartz_block, 0, 1);
      world.setBlock(xco + 22, yco + 14, zco + 41, Blocks.quartz_block, 0, 1);
      world.setBlock(xco + 23, yco + 14, zco + 41, Blocks.stone, 0, 1);
      world.setBlock(xco + 24, yco + 14, zco + 41, Blocks.stone, 0, 1);
      world.setBlock(xco + 25, yco + 14, zco + 41, Blocks.stone, 0, 1);
      world.setBlock(xco + 26, yco + 14, zco + 41, Blocks.stone, 0, 1);
      world.setBlock(xco + 27, yco + 14, zco + 41, Blocks.stone, 0, 1);
      world.setBlock(xco + 28, yco + 14, zco + 41, Blocks.stone, 0, 1);
      world.setBlock(xco + 29, yco + 14, zco + 41, Blocks.stone, 0, 1);
      world.setBlock(xco + 30, yco + 14, zco + 41, Blocks.quartz_block, 0, 1);
      world.setBlock(xco + 31, yco + 14, zco + 41, Blocks.quartz_block, 0, 1);
      world.setBlock(xco + 32, yco + 14, zco + 41, Blocks.quartz_block, 0, 1);
      world.setBlock(xco + 35, yco + 14, zco + 41, Blocks.quartz_block, 0, 1);
      world.setBlock(xco + 2, yco + 14, zco + 42, Blocks.stone, 0, 1);
      world.setBlock(xco + 10, yco + 14, zco + 42, Blocks.stone, 0, 1);
      world.setBlock(xco + 17, yco + 14, zco + 42, Blocks.quartz_block, 0, 1);
      world.setBlock(xco + 20, yco + 14, zco + 42, Blocks.quartz_block, 0, 1);
      world.setBlock(xco + 21, yco + 14, zco + 42, Blocks.quartz_block, 0, 1);
      world.setBlock(xco + 22, yco + 14, zco + 42, Blocks.quartz_block, 0, 1);
      world.setBlock(xco + 23, yco + 14, zco + 42, Blocks.stone, 0, 1);
      world.setBlock(xco + 24, yco + 14, zco + 42, Blocks.stone, 0, 1);
      world.setBlock(xco + 25, yco + 14, zco + 42, Blocks.stone, 0, 1);
      world.setBlock(xco + 26, yco + 14, zco + 42, Blocks.stone, 0, 1);
      world.setBlock(xco + 27, yco + 14, zco + 42, Blocks.stone, 0, 1);
      world.setBlock(xco + 28, yco + 14, zco + 42, Blocks.stone, 0, 1);
      world.setBlock(xco + 29, yco + 14, zco + 42, Blocks.stone, 0, 1);
      world.setBlock(xco + 30, yco + 14, zco + 42, Blocks.quartz_block, 0, 1);
      world.setBlock(xco + 31, yco + 14, zco + 42, Blocks.quartz_block, 0, 1);
      world.setBlock(xco + 32, yco + 14, zco + 42, Blocks.quartz_block, 0, 1);
      world.setBlock(xco + 35, yco + 14, zco + 42, Blocks.quartz_block, 0, 1);
      world.setBlock(xco + 2, yco + 14, zco + 43, Blocks.stone, 0, 1);
      world.setBlock(xco + 10, yco + 14, zco + 43, Blocks.stone, 0, 1);
      world.setBlock(xco + 16, yco + 14, zco + 43, Blocks.stained_hardened_clay, 4, 1);
      world.setBlock(xco + 20, yco + 14, zco + 43, Blocks.stained_hardened_clay, 4, 1);
      world.setBlock(xco + 21, yco + 14, zco + 43, Blocks.quartz_block, 0, 1);
      world.setBlock(xco + 22, yco + 14, zco + 43, Blocks.quartz_block, 0, 1);
      world.setBlock(xco + 23, yco + 14, zco + 43, Blocks.lava, 10, 1);
      world.setBlock(xco + 29, yco + 14, zco + 43, Blocks.lava, 10, 1);
      world.setBlock(xco + 30, yco + 14, zco + 43, Blocks.quartz_block, 0, 1);
      world.setBlock(xco + 31, yco + 14, zco + 43, Blocks.quartz_block, 0, 1);
      world.setBlock(xco + 32, yco + 14, zco + 43, Blocks.stained_hardened_clay, 4, 1);
      world.setBlock(xco + 36, yco + 14, zco + 43, Blocks.stained_hardened_clay, 4, 1);
      world.setBlock(xco + 2, yco + 14, zco + 44, Blocks.stone, 0, 1);
      world.setBlock(xco + 10, yco + 14, zco + 44, Blocks.stone, 0, 1);
      world.setBlock(xco + 16, yco + 14, zco + 44, Blocks.stained_hardened_clay, 4, 1);
      world.setBlock(xco + 20, yco + 14, zco + 44, Blocks.stained_hardened_clay, 4, 1);
      world.setBlock(xco + 21, yco + 14, zco + 44, Blocks.quartz_block, 0, 1);
      world.setBlock(xco + 22, yco + 14, zco + 44, Blocks.quartz_block, 0, 1);
      world.setBlock(xco + 30, yco + 14, zco + 44, Blocks.quartz_block, 0, 1);
      world.setBlock(xco + 31, yco + 14, zco + 44, Blocks.quartz_block, 0, 1);
      world.setBlock(xco + 32, yco + 14, zco + 44, Blocks.stained_hardened_clay, 4, 1);
      world.setBlock(xco + 36, yco + 14, zco + 44, Blocks.stained_hardened_clay, 4, 1);
      world.setBlock(xco + 2, yco + 14, zco + 45, Blocks.stone, 0, 1);
      world.setBlock(xco + 3, yco + 14, zco + 45, Blocks.stone, 0, 1);
      world.setBlock(xco + 9, yco + 14, zco + 45, Blocks.stone, 0, 1);
      world.setBlock(xco + 10, yco + 14, zco + 45, Blocks.stone, 0, 1);
      world.setBlock(xco + 16, yco + 14, zco + 45, Blocks.stained_hardened_clay, 4, 1);
      world.setBlock(xco + 20, yco + 14, zco + 45, Blocks.stained_hardened_clay, 4, 1);
      world.setBlock(xco + 21, yco + 14, zco + 45, Blocks.quartz_block, 0, 1);
      world.setBlock(xco + 22, yco + 14, zco + 45, Blocks.quartz_block, 0, 1);
      world.setBlock(xco + 23, yco + 14, zco + 45, Blocks.lava, 2, 1);
      world.setBlock(xco + 29, yco + 14, zco + 45, Blocks.lava, 2, 1);
      world.setBlock(xco + 30, yco + 14, zco + 45, Blocks.quartz_block, 0, 1);
      world.setBlock(xco + 31, yco + 14, zco + 45, Blocks.quartz_block, 0, 1);
      world.setBlock(xco + 32, yco + 14, zco + 45, Blocks.stained_hardened_clay, 4, 1);
      world.setBlock(xco + 36, yco + 14, zco + 45, Blocks.stained_hardened_clay, 4, 1);
      world.setBlock(xco + 3, yco + 14, zco + 46, Blocks.stone, 0, 1);
      world.setBlock(xco + 4, yco + 14, zco + 46, Blocks.stone, 0, 1);
      world.setBlock(xco + 8, yco + 14, zco + 46, Blocks.stone, 0, 1);
      world.setBlock(xco + 9, yco + 14, zco + 46, Blocks.stone, 0, 1);
      world.setBlock(xco + 17, yco + 14, zco + 46, Blocks.quartz_block, 0, 1);
      world.setBlock(xco + 18, yco + 14, zco + 46, Blocks.quartz_block, 0, 1);
      world.setBlock(xco + 19, yco + 14, zco + 46, Blocks.quartz_block, 0, 1);
      world.setBlock(xco + 20, yco + 14, zco + 46, Blocks.quartz_block, 0, 1);
      world.setBlock(xco + 21, yco + 14, zco + 46, Blocks.quartz_block, 0, 1);
      world.setBlock(xco + 22, yco + 14, zco + 46, Blocks.quartz_block, 0, 1);
      world.setBlock(xco + 23, yco + 14, zco + 46, Blocks.lava, 0, 1);
      world.setBlock(xco + 24, yco + 14, zco + 46, Blocks.stone, 0, 1);
      world.setBlock(xco + 25, yco + 14, zco + 46, Blocks.stone, 0, 1);
      world.setBlock(xco + 26, yco + 14, zco + 46, Blocks.stone, 0, 1);
      world.setBlock(xco + 27, yco + 14, zco + 46, Blocks.stone, 0, 1);
      world.setBlock(xco + 28, yco + 14, zco + 46, Blocks.stone, 0, 1);
      world.setBlock(xco + 29, yco + 14, zco + 46, Blocks.lava, 0, 1);
      world.setBlock(xco + 30, yco + 14, zco + 46, Blocks.quartz_block, 0, 1);
      world.setBlock(xco + 31, yco + 14, zco + 46, Blocks.quartz_block, 0, 1);
      world.setBlock(xco + 32, yco + 14, zco + 46, Blocks.quartz_block, 0, 1);
      world.setBlock(xco + 35, yco + 14, zco + 46, Blocks.quartz_block, 0, 1);
      world.setBlock(xco + 4, yco + 14, zco + 47, Blocks.stone, 0, 1);
      world.setBlock(xco + 5, yco + 14, zco + 47, Blocks.stone, 0, 1);
      world.setBlock(xco + 6, yco + 14, zco + 47, Blocks.stone, 0, 1);
      world.setBlock(xco + 7, yco + 14, zco + 47, Blocks.stone, 0, 1);
      world.setBlock(xco + 8, yco + 14, zco + 47, Blocks.stone, 0, 1);
      world.setBlock(xco + 17, yco + 14, zco + 47, Blocks.quartz_block, 0, 1);
      world.setBlock(xco + 18, yco + 14, zco + 47, Blocks.quartz_block, 0, 1);
      world.setBlock(xco + 19, yco + 14, zco + 47, Blocks.quartz_block, 0, 1);
      world.setBlock(xco + 20, yco + 14, zco + 47, Blocks.quartz_block, 0, 1);
      world.setBlock(xco + 21, yco + 14, zco + 47, Blocks.quartz_block, 0, 1);
      world.setBlock(xco + 22, yco + 14, zco + 47, Blocks.quartz_block, 0, 1);
      world.setBlock(xco + 23, yco + 14, zco + 47, Blocks.lava, 0, 1);
      world.setBlock(xco + 24, yco + 14, zco + 47, Blocks.stone, 0, 1);
      world.setBlock(xco + 25, yco + 14, zco + 47, Blocks.stone, 0, 1);
      world.setBlock(xco + 26, yco + 14, zco + 47, Blocks.stone, 0, 1);
      world.setBlock(xco + 27, yco + 14, zco + 47, Blocks.stone, 0, 1);
      world.setBlock(xco + 28, yco + 14, zco + 47, Blocks.stone, 0, 1);
      world.setBlock(xco + 29, yco + 14, zco + 47, Blocks.lava, 0, 1);
      world.setBlock(xco + 30, yco + 14, zco + 47, Blocks.quartz_block, 0, 1);
      world.setBlock(xco + 31, yco + 14, zco + 47, Blocks.quartz_block, 0, 1);
      world.setBlock(xco + 32, yco + 14, zco + 47, Blocks.quartz_block, 0, 1);
      world.setBlock(xco + 35, yco + 14, zco + 47, Blocks.quartz_block, 0, 1);
      world.setBlock(xco + 16, yco + 14, zco + 48, Blocks.stained_hardened_clay, 4, 1);
      world.setBlock(xco + 20, yco + 14, zco + 48, Blocks.stained_hardened_clay, 4, 1);
      world.setBlock(xco + 21, yco + 14, zco + 48, Blocks.quartz_block, 0, 1);
      world.setBlock(xco + 22, yco + 14, zco + 48, Blocks.quartz_block, 0, 1);
      world.setBlock(xco + 23, yco + 14, zco + 48, Blocks.lava, 2, 1);
      world.setBlock(xco + 29, yco + 14, zco + 48, Blocks.lava, 2, 1);
      world.setBlock(xco + 30, yco + 14, zco + 48, Blocks.quartz_block, 0, 1);
      world.setBlock(xco + 31, yco + 14, zco + 48, Blocks.quartz_block, 0, 1);
      world.setBlock(xco + 32, yco + 14, zco + 48, Blocks.stained_hardened_clay, 4, 1);
      world.setBlock(xco + 36, yco + 14, zco + 48, Blocks.stained_hardened_clay, 4, 1);
      world.setBlock(xco + 16, yco + 14, zco + 49, Blocks.stained_hardened_clay, 4, 1);
      world.setBlock(xco + 20, yco + 14, zco + 49, Blocks.stained_hardened_clay, 4, 1);
      world.setBlock(xco + 21, yco + 14, zco + 49, Blocks.quartz_block, 0, 1);
      world.setBlock(xco + 22, yco + 14, zco + 49, Blocks.quartz_block, 0, 1);
      world.setBlock(xco + 30, yco + 14, zco + 49, Blocks.quartz_block, 0, 1);
      world.setBlock(xco + 31, yco + 14, zco + 49, Blocks.quartz_block, 0, 1);
      world.setBlock(xco + 32, yco + 14, zco + 49, Blocks.stained_hardened_clay, 4, 1);
      world.setBlock(xco + 36, yco + 14, zco + 49, Blocks.stained_hardened_clay, 4, 1);
      world.setBlock(xco + 16, yco + 14, zco + 50, Blocks.stained_hardened_clay, 4, 1);
      world.setBlock(xco + 17, yco + 14, zco + 50, Blocks.stained_hardened_clay, 4, 1);
      world.setBlock(xco + 18, yco + 14, zco + 50, Blocks.stained_hardened_clay, 4, 1);
      world.setBlock(xco + 19, yco + 14, zco + 50, Blocks.stained_hardened_clay, 4, 1);
      world.setBlock(xco + 20, yco + 14, zco + 50, Blocks.stained_hardened_clay, 4, 1);
      world.setBlock(xco + 21, yco + 14, zco + 50, Blocks.quartz_block, 0, 1);
      world.setBlock(xco + 22, yco + 14, zco + 50, Blocks.quartz_block, 0, 1);
      world.setBlock(xco + 30, yco + 14, zco + 50, Blocks.quartz_block, 0, 1);
      world.setBlock(xco + 31, yco + 14, zco + 50, Blocks.quartz_block, 0, 1);
      world.setBlock(xco + 32, yco + 14, zco + 50, Blocks.stained_hardened_clay, 4, 1);
      world.setBlock(xco + 33, yco + 14, zco + 50, Blocks.stained_hardened_clay, 4, 1);
      world.setBlock(xco + 34, yco + 14, zco + 50, Blocks.stained_hardened_clay, 4, 1);
      world.setBlock(xco + 35, yco + 14, zco + 50, Blocks.stained_hardened_clay, 4, 1);
      world.setBlock(xco + 36, yco + 14, zco + 50, Blocks.stained_hardened_clay, 4, 1);
      world.setBlock(xco + 18, yco + 14, zco + 51, Blocks.stained_hardened_clay, 4, 1);
      world.setBlock(xco + 19, yco + 14, zco + 51, Blocks.stained_hardened_clay, 4, 1);
      world.setBlock(xco + 20, yco + 14, zco + 51, Blocks.stained_hardened_clay, 4, 1);
      world.setBlock(xco + 21, yco + 14, zco + 51, Blocks.stained_hardened_clay, 4, 1);
      world.setBlock(xco + 30, yco + 14, zco + 51, Blocks.stained_hardened_clay, 4, 1);
      world.setBlock(xco + 31, yco + 14, zco + 51, Blocks.stained_hardened_clay, 4, 1);
      world.setBlock(xco + 32, yco + 14, zco + 51, Blocks.stained_hardened_clay, 4, 1);
      world.setBlock(xco + 33, yco + 14, zco + 51, Blocks.stained_hardened_clay, 4, 1);
      world.setBlock(xco + 34, yco + 14, zco + 51, Blocks.stained_hardened_clay, 4, 1);
      world.setBlock(xco + 17, yco + 14, zco + 52, Blocks.stained_hardened_clay, 4, 1);
      world.setBlock(xco + 18, yco + 14, zco + 52, Blocks.stained_hardened_clay, 4, 1);
      world.setBlock(xco + 22, yco + 14, zco + 52, Blocks.stained_hardened_clay, 4, 1);
      world.setBlock(xco + 29, yco + 14, zco + 52, Blocks.stained_hardened_clay, 4, 1);
      world.setBlock(xco + 30, yco + 14, zco + 52, Blocks.stained_hardened_clay, 4, 1);
      world.setBlock(xco + 34, yco + 14, zco + 52, Blocks.stained_hardened_clay, 4, 1);
      world.setBlock(xco + 35, yco + 14, zco + 52, Blocks.stained_hardened_clay, 4, 1);
      world.setBlock(xco + 16, yco + 14, zco + 53, Blocks.stained_hardened_clay, 4, 1);
      world.setBlock(xco + 17, yco + 14, zco + 53, Blocks.stained_hardened_clay, 4, 1);
      world.setBlock(xco + 23, yco + 14, zco + 53, Blocks.stained_hardened_clay, 4, 1);
      world.setBlock(xco + 24, yco + 14, zco + 53, Blocks.stained_hardened_clay, 4, 1);
      world.setBlock(xco + 28, yco + 14, zco + 53, Blocks.stained_hardened_clay, 4, 1);
      world.setBlock(xco + 29, yco + 14, zco + 53, Blocks.stained_hardened_clay, 4, 1);
      world.setBlock(xco + 35, yco + 14, zco + 53, Blocks.stained_hardened_clay, 4, 1);
      world.setBlock(xco + 36, yco + 14, zco + 53, Blocks.stained_hardened_clay, 4, 1);
      world.setBlock(xco + 16, yco + 14, zco + 54, Blocks.stained_hardened_clay, 4, 1);
      world.setBlock(xco + 17, yco + 14, zco + 54, Blocks.stained_hardened_clay, 4, 1);
      world.setBlock(xco + 23, yco + 14, zco + 54, Blocks.stained_hardened_clay, 4, 1);
      world.setBlock(xco + 24, yco + 14, zco + 54, Blocks.stained_hardened_clay, 4, 1);
      world.setBlock(xco + 28, yco + 14, zco + 54, Blocks.stained_hardened_clay, 4, 1);
      world.setBlock(xco + 29, yco + 14, zco + 54, Blocks.stained_hardened_clay, 4, 1);
      world.setBlock(xco + 35, yco + 14, zco + 54, Blocks.stained_hardened_clay, 4, 1);
      world.setBlock(xco + 36, yco + 14, zco + 54, Blocks.stained_hardened_clay, 4, 1);
      world.setBlock(xco + 16, yco + 14, zco + 55, Blocks.stained_hardened_clay, 4, 1);
      world.setBlock(xco + 17, yco + 14, zco + 55, Blocks.stained_hardened_clay, 4, 1);
      world.setBlock(xco + 23, yco + 14, zco + 55, Blocks.stained_hardened_clay, 4, 1);
      world.setBlock(xco + 24, yco + 14, zco + 55, Blocks.stained_hardened_clay, 4, 1);
      world.setBlock(xco + 28, yco + 14, zco + 55, Blocks.stained_hardened_clay, 4, 1);
      world.setBlock(xco + 29, yco + 14, zco + 55, Blocks.stained_hardened_clay, 4, 1);
      world.setBlock(xco + 35, yco + 14, zco + 55, Blocks.stained_hardened_clay, 4, 1);
      world.setBlock(xco + 36, yco + 14, zco + 55, Blocks.stained_hardened_clay, 4, 1);
      world.setBlock(xco + 37, yco + 14, zco + 55, Blocks.stained_hardened_clay, 4, 1);
      world.setBlock(xco + 17, yco + 14, zco + 56, Blocks.stained_hardened_clay, 4, 1);
      world.setBlock(xco + 18, yco + 14, zco + 56, Blocks.stained_hardened_clay, 4, 1);
      world.setBlock(xco + 22, yco + 14, zco + 56, Blocks.stained_hardened_clay, 4, 1);
      world.setBlock(xco + 23, yco + 14, zco + 56, Blocks.stained_hardened_clay, 4, 1);
      world.setBlock(xco + 29, yco + 14, zco + 56, Blocks.stained_hardened_clay, 4, 1);
      world.setBlock(xco + 30, yco + 14, zco + 56, Blocks.stained_hardened_clay, 4, 1);
      world.setBlock(xco + 34, yco + 14, zco + 56, Blocks.stained_hardened_clay, 4, 1);
      world.setBlock(xco + 35, yco + 14, zco + 56, Blocks.stained_hardened_clay, 4, 1);
      world.setBlock(xco + 38, yco + 14, zco + 56, Blocks.stained_hardened_clay, 4, 1);
      world.setBlock(xco + 39, yco + 14, zco + 56, Blocks.wool, 15, 1);
      world.setBlock(xco + 40, yco + 14, zco + 56, Blocks.wool, 15, 1);
      world.setBlock(xco + 18, yco + 14, zco + 57, Blocks.stained_hardened_clay, 4, 1);
      world.setBlock(xco + 19, yco + 14, zco + 57, Blocks.stained_hardened_clay, 4, 1);
      world.setBlock(xco + 20, yco + 14, zco + 57, Blocks.stained_hardened_clay, 4, 1);
      world.setBlock(xco + 21, yco + 14, zco + 57, Blocks.stained_hardened_clay, 4, 1);
      world.setBlock(xco + 22, yco + 14, zco + 57, Blocks.stained_hardened_clay, 4, 1);
      world.setBlock(xco + 23, yco + 14, zco + 57, Blocks.stone, 0, 1);
      world.setBlock(xco + 24, yco + 14, zco + 57, Blocks.nether_brick_fence, 0, 1);
      world.setBlock(xco + 28, yco + 14, zco + 57, Blocks.nether_brick_fence, 0, 1);
      world.setBlock(xco + 29, yco + 14, zco + 57, Blocks.stone, 0, 1);
      world.setBlock(xco + 30, yco + 14, zco + 57, Blocks.stained_hardened_clay, 4, 1);
      world.setBlock(xco + 31, yco + 14, zco + 57, Blocks.stained_hardened_clay, 4, 1);
      world.setBlock(xco + 32, yco + 14, zco + 57, Blocks.stained_hardened_clay, 4, 1);
      world.setBlock(xco + 33, yco + 14, zco + 57, Blocks.stained_hardened_clay, 4, 1);
      world.setBlock(xco + 34, yco + 14, zco + 57, Blocks.stained_hardened_clay, 4, 1);
      world.setBlock(xco + 39, yco + 14, zco + 57, Blocks.stained_hardened_clay, 4, 1);
      world.setBlock(xco + 41, yco + 14, zco + 57, Blocks.wool, 15, 1);
      world.setBlock(xco + 19, yco + 14, zco + 58, Blocks.stained_hardened_clay, 4, 1);
      world.setBlock(xco + 20, yco + 14, zco + 58, Blocks.stained_hardened_clay, 4, 1);
      world.setBlock(xco + 21, yco + 14, zco + 58, Blocks.stained_hardened_clay, 4, 1);
      world.setBlock(xco + 23, yco + 14, zco + 58, Blocks.stone, 0, 1);
      world.setBlock(xco + 29, yco + 14, zco + 58, Blocks.stone, 0, 1);
      world.setBlock(xco + 31, yco + 14, zco + 58, Blocks.stained_hardened_clay, 4, 1);
      world.setBlock(xco + 32, yco + 14, zco + 58, Blocks.stained_hardened_clay, 4, 1);
      world.setBlock(xco + 33, yco + 14, zco + 58, Blocks.stained_hardened_clay, 4, 1);
      world.setBlock(xco + 40, yco + 14, zco + 58, Blocks.stained_hardened_clay, 4, 1);
      world.setBlock(xco + 42, yco + 14, zco + 58, Blocks.wool, 15, 1);
      world.setBlock(xco + 21, yco + 14, zco + 59, Blocks.stone, 0, 1);
      world.setBlock(xco + 22, yco + 14, zco + 59, Blocks.stone, 0, 1);
      world.setBlock(xco + 23, yco + 14, zco + 59, Blocks.redstone_torch, 1, 1);
      world.setBlock(xco + 28, yco + 14, zco + 59, Blocks.redstone_torch, 2, 1);
      world.setBlock(xco + 29, yco + 14, zco + 59, Blocks.stone, 0, 1);
      world.setBlock(xco + 34, yco + 14, zco + 59, Blocks.wool, 15, 1);
      world.setBlock(xco + 35, yco + 14, zco + 59, Blocks.wool, 15, 1);
      world.setBlock(xco + 36, yco + 14, zco + 59, Blocks.wool, 15, 1);
      world.setBlock(xco + 37, yco + 14, zco + 59, Blocks.wool, 15, 1);
      world.setBlock(xco + 41, yco + 14, zco + 59, Blocks.stained_hardened_clay, 4, 1);
      world.setBlock(xco + 42, yco + 14, zco + 59, Blocks.wool, 15, 1);
      world.setBlock(xco + 18, yco + 14, zco + 60, Blocks.stone, 0, 1);
      world.setBlock(xco + 19, yco + 14, zco + 60, Blocks.stone, 0, 1);
      world.setBlock(xco + 20, yco + 14, zco + 60, Blocks.stone, 0, 1);
      world.setBlock(xco + 21, yco + 14, zco + 60, Blocks.redstone_torch, 1, 1);
      world.setBlock(xco + 29, yco + 14, zco + 60, Blocks.stone, 0, 1);
      world.setBlock(xco + 33, yco + 14, zco + 60, Blocks.wool, 15, 1);
      world.setBlock(xco + 38, yco + 14, zco + 60, Blocks.wool, 15, 1);
      world.setBlock(xco + 42, yco + 14, zco + 60, Blocks.stone, 0, 1);
      world.setBlock(xco + 43, yco + 14, zco + 60, Blocks.stone, 0, 1);
      world.setBlock(xco + 44, yco + 14, zco + 60, Blocks.stone, 0, 1);
      world.setBlock(xco + 45, yco + 14, zco + 60, Blocks.stone, 0, 1);
      world.setBlock(xco + 18, yco + 14, zco + 61, Blocks.obsidian, 0, 1);
      world.setBlock(xco + 21, yco + 14, zco + 61, Blocks.stone, 0, 1);
      world.setBlock(xco + 28, yco + 14, zco + 61, Blocks.redstone_torch, 2, 1);
      world.setBlock(xco + 29, yco + 14, zco + 61, Blocks.stone, 0, 1);
      world.setBlock(xco + 32, yco + 14, zco + 61, Blocks.wool, 15, 1);
      world.setBlock(xco + 39, yco + 14, zco + 61, Blocks.wool, 15, 1);
      world.setBlock(xco + 41, yco + 14, zco + 61, Blocks.stone, 0, 1);
      world.setBlock(xco + 46, yco + 14, zco + 61, Blocks.stone, 0, 1);
      world.setBlock(xco + 18, yco + 14, zco + 62, Blocks.obsidian, 0, 1);
      world.setBlock(xco + 21, yco + 14, zco + 62, Blocks.iron_bars, 0, 1);
      world.setBlock(xco + 29, yco + 14, zco + 62, Blocks.stone, 0, 1);
      world.setBlock(xco + 32, yco + 14, zco + 62, Blocks.wool, 15, 1);
      world.setBlock(xco + 39, yco + 14, zco + 62, Blocks.wool, 15, 1);
      world.setBlock(xco + 40, yco + 14, zco + 62, Blocks.stone, 0, 1);
      world.setBlock(xco + 47, yco + 14, zco + 62, Blocks.stone, 0, 1);
      world.setBlock(xco + 18, yco + 14, zco + 63, Blocks.obsidian, 0, 1);
      world.setBlock(xco + 21, yco + 14, zco + 63, Blocks.iron_bars, 0, 1);
      world.setBlock(xco + 23, yco + 14, zco + 63, Blocks.iron_bars, 0, 1);
      world.setBlock(xco + 24, yco + 14, zco + 63, Blocks.iron_bars, 0, 1);
      world.setBlock(xco + 25, yco + 14, zco + 63, Blocks.iron_bars, 0, 1);
      world.setBlock(xco + 26, yco + 14, zco + 63, Blocks.iron_bars, 0, 1);
      world.setBlock(xco + 27, yco + 14, zco + 63, Blocks.iron_bars, 0, 1);
      world.setBlock(xco + 28, yco + 14, zco + 63, Blocks.iron_bars, 0, 1);
      world.setBlock(xco + 29, yco + 14, zco + 63, Blocks.stone, 0, 1);
      world.setBlock(xco + 32, yco + 14, zco + 63, Blocks.wool, 15, 1);
      world.setBlock(xco + 39, yco + 14, zco + 63, Blocks.wool, 15, 1);
      world.setBlock(xco + 40, yco + 14, zco + 63, Blocks.stone, 0, 1);
      world.setBlock(xco + 47, yco + 14, zco + 63, Blocks.stone, 0, 1);
      world.setBlock(xco + 18, yco + 14, zco + 64, Blocks.obsidian, 0, 1);
      world.setBlock(xco + 21, yco + 14, zco + 64, Blocks.stone, 0, 1);
      world.setBlock(xco + 23, yco + 14, zco + 64, Blocks.iron_bars, 0, 1);
      world.setBlock(xco + 28, yco + 14, zco + 64, Blocks.redstone_torch, 2, 1);
      world.setBlock(xco + 29, yco + 14, zco + 64, Blocks.stone, 0, 1);
      world.setBlock(xco + 32, yco + 14, zco + 64, Blocks.wool, 15, 1);
      world.setBlock(xco + 39, yco + 14, zco + 64, Blocks.wool, 15, 1);
      world.setBlock(xco + 40, yco + 14, zco + 64, Blocks.stone, 0, 1);
      world.setBlock(xco + 47, yco + 14, zco + 64, Blocks.stone, 0, 1);
      world.setBlock(xco + 18, yco + 14, zco + 65, Blocks.obsidian, 0, 1);
      world.setBlock(xco + 20, yco + 14, zco + 65, Blocks.stone, 0, 1);
      world.setBlock(xco + 23, yco + 14, zco + 65, Blocks.iron_bars, 0, 1);
      world.setBlock(xco + 29, yco + 14, zco + 65, Blocks.stone, 0, 1);
      world.setBlock(xco + 33, yco + 14, zco + 65, Blocks.wool, 15, 1);
      world.setBlock(xco + 38, yco + 14, zco + 65, Blocks.wool, 15, 1);
      world.setBlock(xco + 40, yco + 14, zco + 65, Blocks.stone, 0, 1);
      world.setBlock(xco + 47, yco + 14, zco + 65, Blocks.stone, 0, 1);
      world.setBlock(xco + 18, yco + 14, zco + 66, Blocks.stone, 0, 1);
      world.setBlock(xco + 19, yco + 14, zco + 66, Blocks.stone, 0, 1);
      world.setBlock(xco + 23, yco + 14, zco + 66, Blocks.iron_bars, 0, 1);
      world.setBlock(xco + 24, yco + 14, zco + 66, Blocks.redstone_torch, 4, 1);
      world.setBlock(xco + 26, yco + 14, zco + 66, Blocks.redstone_torch, 4, 1);
      world.setBlock(xco + 28, yco + 14, zco + 66, Blocks.redstone_torch, 4, 1);
      world.setBlock(xco + 29, yco + 14, zco + 66, Blocks.stone, 0, 1);
      world.setBlock(xco + 34, yco + 14, zco + 66, Blocks.wool, 15, 1);
      world.setBlock(xco + 35, yco + 14, zco + 66, Blocks.wool, 15, 1);
      world.setBlock(xco + 36, yco + 14, zco + 66, Blocks.wool, 15, 1);
      world.setBlock(xco + 37, yco + 14, zco + 66, Blocks.wool, 15, 1);
      world.setBlock(xco + 41, yco + 14, zco + 66, Blocks.stone, 0, 1);
      world.setBlock(xco + 46, yco + 14, zco + 66, Blocks.stone, 0, 1);
      world.setBlock(xco + 20, yco + 14, zco + 67, Blocks.stone, 0, 1);
      world.setBlock(xco + 21, yco + 14, zco + 67, Blocks.stone, 0, 1);
      world.setBlock(xco + 22, yco + 14, zco + 67, Blocks.stone, 0, 1);
      world.setBlock(xco + 23, yco + 14, zco + 67, Blocks.stone, 0, 1);
      world.setBlock(xco + 24, yco + 14, zco + 67, Blocks.stone, 0, 1);
      world.setBlock(xco + 25, yco + 14, zco + 67, Blocks.stone, 0, 1);
      world.setBlock(xco + 26, yco + 14, zco + 67, Blocks.stone, 0, 1);
      world.setBlock(xco + 27, yco + 14, zco + 67, Blocks.stone, 0, 1);
      world.setBlock(xco + 28, yco + 14, zco + 67, Blocks.stone, 0, 1);
      world.setBlock(xco + 42, yco + 14, zco + 67, Blocks.stone, 0, 1);
      world.setBlock(xco + 43, yco + 14, zco + 67, Blocks.stone, 0, 1);
      world.setBlock(xco + 44, yco + 14, zco + 67, Blocks.stone, 0, 1);
      world.setBlock(xco + 45, yco + 14, zco + 67, Blocks.stone, 0, 1);
      world.setBlock(xco + 24, yco + 15, zco + 36, Blocks.quartz_block, 0, 1);
      world.setBlock(xco + 25, yco + 15, zco + 36, Blocks.stained_hardened_clay, 10, 1);
      world.setBlock(xco + 27, yco + 15, zco + 36, Blocks.stained_hardened_clay, 10, 1);
      world.setBlock(xco + 28, yco + 15, zco + 36, Blocks.quartz_block, 0, 1);
      world.setBlock(xco + 16, yco + 15, zco + 37, Blocks.stained_hardened_clay, 4, 1);
      world.setBlock(xco + 17, yco + 15, zco + 37, Blocks.stained_hardened_clay, 4, 1);
      world.setBlock(xco + 18, yco + 15, zco + 37, Blocks.stained_hardened_clay, 4, 1);
      world.setBlock(xco + 19, yco + 15, zco + 37, Blocks.stained_hardened_clay, 4, 1);
      world.setBlock(xco + 20, yco + 15, zco + 37, Blocks.stained_hardened_clay, 4, 1);
      world.setBlock(xco + 21, yco + 15, zco + 37, Blocks.quartz_block, 0, 1);
      world.setBlock(xco + 22, yco + 15, zco + 37, Blocks.quartz_block, 0, 1);
      world.setBlock(xco + 23, yco + 15, zco + 37, Blocks.stained_hardened_clay, 4, 1);
      world.setBlock(xco + 29, yco + 15, zco + 37, Blocks.stained_hardened_clay, 4, 1);
      world.setBlock(xco + 32, yco + 15, zco + 37, Blocks.stained_hardened_clay, 4, 1);
      world.setBlock(xco + 33, yco + 15, zco + 37, Blocks.stained_hardened_clay, 4, 1);
      world.setBlock(xco + 34, yco + 15, zco + 37, Blocks.stained_hardened_clay, 4, 1);
      world.setBlock(xco + 35, yco + 15, zco + 37, Blocks.stained_hardened_clay, 4, 1);
      world.setBlock(xco + 36, yco + 15, zco + 37, Blocks.stained_hardened_clay, 4, 1);
      world.setBlock(xco + 3, yco + 15, zco + 38, Blocks.stone, 0, 1);
      world.setBlock(xco + 4, yco + 15, zco + 38, Blocks.stone, 0, 1);
      world.setBlock(xco + 5, yco + 15, zco + 38, Blocks.stone, 0, 1);
      world.setBlock(xco + 6, yco + 15, zco + 38, Blocks.stone, 0, 1);
      world.setBlock(xco + 7, yco + 15, zco + 38, Blocks.stone, 0, 1);
      world.setBlock(xco + 8, yco + 15, zco + 38, Blocks.stone, 0, 1);
      world.setBlock(xco + 9, yco + 15, zco + 38, Blocks.stone, 0, 1);
      world.setBlock(xco + 16, yco + 15, zco + 38, Blocks.stained_hardened_clay, 4, 1);
      world.setBlock(xco + 17, yco + 15, zco + 38, Blocks.stained_hardened_clay, 4, 1);
      world.setBlock(xco + 18, yco + 15, zco + 38, Blocks.stained_hardened_clay, 4, 1);
      world.setBlock(xco + 19, yco + 15, zco + 38, Blocks.stained_hardened_clay, 4, 1);
      world.setBlock(xco + 20, yco + 15, zco + 38, Blocks.stained_hardened_clay, 4, 1);
      world.setBlock(xco + 21, yco + 15, zco + 38, Blocks.quartz_block, 0, 1);
      world.setBlock(xco + 22, yco + 15, zco + 38, Blocks.quartz_block, 0, 1);
      world.setBlock(xco + 30, yco + 15, zco + 38, Blocks.quartz_block, 0, 1);
      world.setBlock(xco + 31, yco + 15, zco + 38, Blocks.quartz_block, 0, 1);
      world.setBlock(xco + 32, yco + 15, zco + 38, Blocks.stained_hardened_clay, 4, 1);
      world.setBlock(xco + 33, yco + 15, zco + 38, Blocks.stained_hardened_clay, 4, 1);
      world.setBlock(xco + 34, yco + 15, zco + 38, Blocks.stained_hardened_clay, 4, 1);
      world.setBlock(xco + 35, yco + 15, zco + 38, Blocks.stained_hardened_clay, 4, 1);
      world.setBlock(xco + 36, yco + 15, zco + 38, Blocks.stained_hardened_clay, 4, 1);
      world.setBlock(xco + 2, yco + 15, zco + 39, Blocks.stone, 0, 1);
      world.setBlock(xco + 3, yco + 15, zco + 39, Blocks.stone, 0, 1);
      world.setBlock(xco + 9, yco + 15, zco + 39, Blocks.stone, 0, 1);
      world.setBlock(xco + 10, yco + 15, zco + 39, Blocks.stone, 0, 1);
      world.setBlock(xco + 16, yco + 15, zco + 39, Blocks.stained_hardened_clay, 4, 1);
      world.setBlock(xco + 20, yco + 15, zco + 39, Blocks.stained_hardened_clay, 4, 1);
      world.setBlock(xco + 21, yco + 15, zco + 39, Blocks.quartz_block, 0, 1);
      world.setBlock(xco + 22, yco + 15, zco + 39, Blocks.quartz_block, 0, 1);
      world.setBlock(xco + 30, yco + 15, zco + 39, Blocks.quartz_block, 0, 1);
      world.setBlock(xco + 31, yco + 15, zco + 39, Blocks.quartz_block, 0, 1);
      world.setBlock(xco + 32, yco + 15, zco + 39, Blocks.stained_hardened_clay, 4, 1);
      world.setBlock(xco + 36, yco + 15, zco + 39, Blocks.stained_hardened_clay, 4, 1);
      world.setBlock(xco + 1, yco + 15, zco + 40, Blocks.stone, 0, 1);
      world.setBlock(xco + 2, yco + 15, zco + 40, Blocks.stone, 0, 1);
      world.setBlock(xco + 10, yco + 15, zco + 40, Blocks.stone, 0, 1);
      world.setBlock(xco + 11, yco + 15, zco + 40, Blocks.stone, 0, 1);
      world.setBlock(xco + 16, yco + 15, zco + 40, Blocks.stained_hardened_clay, 4, 1);
      world.setBlock(xco + 20, yco + 15, zco + 40, Blocks.stained_hardened_clay, 4, 1);
      world.setBlock(xco + 21, yco + 15, zco + 40, Blocks.quartz_block, 0, 1);
      world.setBlock(xco + 22, yco + 15, zco + 40, Blocks.quartz_block, 0, 1);
      world.setBlock(xco + 23, yco + 15, zco + 40, Blocks.lava, 2, 1);
      world.setBlock(xco + 29, yco + 15, zco + 40, Blocks.lava, 2, 1);
      world.setBlock(xco + 30, yco + 15, zco + 40, Blocks.quartz_block, 0, 1);
      world.setBlock(xco + 31, yco + 15, zco + 40, Blocks.quartz_block, 0, 1);
      world.setBlock(xco + 32, yco + 15, zco + 40, Blocks.stained_hardened_clay, 4, 1);
      world.setBlock(xco + 34, yco + 15, zco + 40, Blocks.stained_hardened_clay, 4, 1);
      world.setBlock(xco + 35, yco + 15, zco + 40, Blocks.stained_hardened_clay, 4, 1);
      world.setBlock(xco + 36, yco + 15, zco + 40, Blocks.stained_hardened_clay, 4, 1);
      world.setBlock(xco + 1, yco + 15, zco + 41, Blocks.stone, 0, 1);
      world.setBlock(xco + 11, yco + 15, zco + 41, Blocks.stone, 0, 1);
      world.setBlock(xco + 17, yco + 15, zco + 41, Blocks.quartz_block, 0, 1);
      world.setBlock(xco + 20, yco + 15, zco + 41, Blocks.quartz_block, 0, 1);
      world.setBlock(xco + 21, yco + 15, zco + 41, Blocks.quartz_block, 0, 1);
      world.setBlock(xco + 22, yco + 15, zco + 41, Blocks.quartz_block, 0, 1);
      world.setBlock(xco + 23, yco + 15, zco + 41, Blocks.lava, 0, 1);
      world.setBlock(xco + 24, yco + 15, zco + 41, Blocks.stone, 0, 1);
      world.setBlock(xco + 25, yco + 15, zco + 41, Blocks.stone, 0, 1);
      world.setBlock(xco + 26, yco + 15, zco + 41, Blocks.stone, 0, 1);
      world.setBlock(xco + 27, yco + 15, zco + 41, Blocks.stone, 0, 1);
      world.setBlock(xco + 28, yco + 15, zco + 41, Blocks.stone, 0, 1);
      world.setBlock(xco + 29, yco + 15, zco + 41, Blocks.lava, 0, 1);
      world.setBlock(xco + 30, yco + 15, zco + 41, Blocks.quartz_block, 0, 1);
      world.setBlock(xco + 31, yco + 15, zco + 41, Blocks.quartz_block, 0, 1);
      world.setBlock(xco + 32, yco + 15, zco + 41, Blocks.quartz_block, 0, 1);
      world.setBlock(xco + 35, yco + 15, zco + 41, Blocks.quartz_block, 0, 1);
      world.setBlock(xco + 1, yco + 15, zco + 42, Blocks.stone, 0, 1);
      world.setBlock(xco + 11, yco + 15, zco + 42, Blocks.stone, 0, 1);
      world.setBlock(xco + 17, yco + 15, zco + 42, Blocks.quartz_block, 0, 1);
      world.setBlock(xco + 20, yco + 15, zco + 42, Blocks.quartz_block, 0, 1);
      world.setBlock(xco + 21, yco + 15, zco + 42, Blocks.quartz_block, 0, 1);
      world.setBlock(xco + 22, yco + 15, zco + 42, Blocks.quartz_block, 0, 1);
      world.setBlock(xco + 23, yco + 15, zco + 42, Blocks.lava, 0, 1);
      world.setBlock(xco + 24, yco + 15, zco + 42, Blocks.stone, 0, 1);
      world.setBlock(xco + 25, yco + 15, zco + 42, Blocks.stone, 0, 1);
      world.setBlock(xco + 26, yco + 15, zco + 42, Blocks.stone, 0, 1);
      world.setBlock(xco + 27, yco + 15, zco + 42, Blocks.stone, 0, 1);
      world.setBlock(xco + 28, yco + 15, zco + 42, Blocks.stone, 0, 1);
      world.setBlock(xco + 29, yco + 15, zco + 42, Blocks.lava, 0, 1);
      world.setBlock(xco + 30, yco + 15, zco + 42, Blocks.quartz_block, 0, 1);
      world.setBlock(xco + 31, yco + 15, zco + 42, Blocks.quartz_block, 0, 1);
      world.setBlock(xco + 32, yco + 15, zco + 42, Blocks.quartz_block, 0, 1);
      world.setBlock(xco + 35, yco + 15, zco + 42, Blocks.quartz_block, 0, 1);
      world.setBlock(xco + 1, yco + 15, zco + 43, Blocks.stone, 0, 1);
      world.setBlock(xco + 11, yco + 15, zco + 43, Blocks.stone, 0, 1);
      world.setBlock(xco + 16, yco + 15, zco + 43, Blocks.stained_hardened_clay, 4, 1);
      world.setBlock(xco + 20, yco + 15, zco + 43, Blocks.stained_hardened_clay, 4, 1);
      world.setBlock(xco + 21, yco + 15, zco + 43, Blocks.quartz_block, 0, 1);
      world.setBlock(xco + 22, yco + 15, zco + 43, Blocks.quartz_block, 0, 1);
      world.setBlock(xco + 23, yco + 15, zco + 43, Blocks.lava, 2, 1);
      world.setBlock(xco + 29, yco + 15, zco + 43, Blocks.lava, 2, 1);
      world.setBlock(xco + 30, yco + 15, zco + 43, Blocks.quartz_block, 0, 1);
      world.setBlock(xco + 31, yco + 15, zco + 43, Blocks.quartz_block, 0, 1);
      world.setBlock(xco + 32, yco + 15, zco + 43, Blocks.stained_hardened_clay, 4, 1);
      world.setBlock(xco + 36, yco + 15, zco + 43, Blocks.stained_hardened_clay, 4, 1);
      world.setBlock(xco + 1, yco + 15, zco + 44, Blocks.stone, 0, 1);
      world.setBlock(xco + 11, yco + 15, zco + 44, Blocks.stone, 0, 1);
      world.setBlock(xco + 16, yco + 15, zco + 44, Blocks.stained_hardened_clay, 4, 1);
      world.setBlock(xco + 20, yco + 15, zco + 44, Blocks.stained_hardened_clay, 4, 1);
      world.setBlock(xco + 21, yco + 15, zco + 44, Blocks.quartz_block, 0, 1);
      world.setBlock(xco + 22, yco + 15, zco + 44, Blocks.quartz_block, 0, 1);
      world.setBlock(xco + 30, yco + 15, zco + 44, Blocks.quartz_block, 0, 1);
      world.setBlock(xco + 31, yco + 15, zco + 44, Blocks.quartz_block, 0, 1);
      world.setBlock(xco + 32, yco + 15, zco + 44, Blocks.stained_hardened_clay, 4, 1);
      world.setBlock(xco + 36, yco + 15, zco + 44, Blocks.stained_hardened_clay, 4, 1);
      world.setBlock(xco + 1, yco + 15, zco + 45, Blocks.stone, 0, 1);
      world.setBlock(xco + 11, yco + 15, zco + 45, Blocks.stone, 0, 1);
      world.setBlock(xco + 16, yco + 15, zco + 45, Blocks.stained_hardened_clay, 4, 1);
      world.setBlock(xco + 20, yco + 15, zco + 45, Blocks.stained_hardened_clay, 4, 1);
      world.setBlock(xco + 21, yco + 15, zco + 45, Blocks.quartz_block, 0, 1);
      world.setBlock(xco + 22, yco + 15, zco + 45, Blocks.quartz_block, 0, 1);
      world.setBlock(xco + 30, yco + 15, zco + 45, Blocks.quartz_block, 0, 1);
      world.setBlock(xco + 31, yco + 15, zco + 45, Blocks.quartz_block, 0, 1);
      world.setBlock(xco + 32, yco + 15, zco + 45, Blocks.stained_hardened_clay, 4, 1);
      world.setBlock(xco + 36, yco + 15, zco + 45, Blocks.stained_hardened_clay, 4, 1);
      world.setBlock(xco + 1, yco + 15, zco + 46, Blocks.stone, 0, 1);
      world.setBlock(xco + 2, yco + 15, zco + 46, Blocks.stone, 0, 1);
      world.setBlock(xco + 10, yco + 15, zco + 46, Blocks.stone, 0, 1);
      world.setBlock(xco + 11, yco + 15, zco + 46, Blocks.stone, 0, 1);
      world.setBlock(xco + 17, yco + 15, zco + 46, Blocks.quartz_block, 0, 1);
      world.setBlock(xco + 18, yco + 15, zco + 46, Blocks.quartz_block, 0, 1);
      world.setBlock(xco + 19, yco + 15, zco + 46, Blocks.quartz_block, 0, 1);
      world.setBlock(xco + 20, yco + 15, zco + 46, Blocks.quartz_block, 0, 1);
      world.setBlock(xco + 21, yco + 15, zco + 46, Blocks.quartz_block, 0, 1);
      world.setBlock(xco + 22, yco + 15, zco + 46, Blocks.quartz_block, 0, 1);
      world.setBlock(xco + 25, yco + 15, zco + 46, Blocks.stone, 0, 1);
      world.setBlock(xco + 26, yco + 15, zco + 46, Blocks.stone, 0, 1);
      world.setBlock(xco + 30, yco + 15, zco + 46, Blocks.quartz_block, 0, 1);
      world.setBlock(xco + 31, yco + 15, zco + 46, Blocks.quartz_block, 0, 1);
      world.setBlock(xco + 32, yco + 15, zco + 46, Blocks.quartz_block, 0, 1);
      world.setBlock(xco + 35, yco + 15, zco + 46, Blocks.quartz_block, 0, 1);
      world.setBlock(xco + 2, yco + 15, zco + 47, Blocks.stone, 0, 1);
      world.setBlock(xco + 3, yco + 15, zco + 47, Blocks.stone, 0, 1);
      world.setBlock(xco + 9, yco + 15, zco + 47, Blocks.stone, 0, 1);
      world.setBlock(xco + 10, yco + 15, zco + 47, Blocks.stone, 0, 1);
      world.setBlock(xco + 17, yco + 15, zco + 47, Blocks.quartz_block, 0, 1);
      world.setBlock(xco + 18, yco + 15, zco + 47, Blocks.quartz_block, 0, 1);
      world.setBlock(xco + 19, yco + 15, zco + 47, Blocks.quartz_block, 0, 1);
      world.setBlock(xco + 20, yco + 15, zco + 47, Blocks.quartz_block, 0, 1);
      world.setBlock(xco + 21, yco + 15, zco + 47, Blocks.quartz_block, 0, 1);
      world.setBlock(xco + 22, yco + 15, zco + 47, Blocks.quartz_block, 0, 1);
      world.setBlock(xco + 25, yco + 15, zco + 47, Blocks.stone, 0, 1);
      world.setBlock(xco + 26, yco + 15, zco + 47, Blocks.stone, 0, 1);
      world.setBlock(xco + 30, yco + 15, zco + 47, Blocks.quartz_block, 0, 1);
      world.setBlock(xco + 31, yco + 15, zco + 47, Blocks.quartz_block, 0, 1);
      world.setBlock(xco + 32, yco + 15, zco + 47, Blocks.quartz_block, 0, 1);
      world.setBlock(xco + 35, yco + 15, zco + 47, Blocks.quartz_block, 0, 1);
      world.setBlock(xco + 3, yco + 15, zco + 48, Blocks.stone, 0, 1);
      world.setBlock(xco + 4, yco + 15, zco + 48, Blocks.stone, 0, 1);
      world.setBlock(xco + 5, yco + 15, zco + 48, Blocks.stone, 0, 1);
      world.setBlock(xco + 6, yco + 15, zco + 48, Blocks.stone, 0, 1);
      world.setBlock(xco + 7, yco + 15, zco + 48, Blocks.stone, 0, 1);
      world.setBlock(xco + 8, yco + 15, zco + 48, Blocks.stone, 0, 1);
      world.setBlock(xco + 9, yco + 15, zco + 48, Blocks.stone, 0, 1);
      world.setBlock(xco + 16, yco + 15, zco + 48, Blocks.stained_hardened_clay, 4, 1);
      world.setBlock(xco + 20, yco + 15, zco + 48, Blocks.stained_hardened_clay, 4, 1);
      world.setBlock(xco + 21, yco + 15, zco + 48, Blocks.quartz_block, 0, 1);
      world.setBlock(xco + 22, yco + 15, zco + 48, Blocks.quartz_block, 0, 1);
      world.setBlock(xco + 30, yco + 15, zco + 48, Blocks.quartz_block, 0, 1);
      world.setBlock(xco + 31, yco + 15, zco + 48, Blocks.quartz_block, 0, 1);
      world.setBlock(xco + 32, yco + 15, zco + 48, Blocks.stained_hardened_clay, 4, 1);
      world.setBlock(xco + 36, yco + 15, zco + 48, Blocks.stained_hardened_clay, 4, 1);
      world.setBlock(xco + 16, yco + 15, zco + 49, Blocks.stained_hardened_clay, 4, 1);
      world.setBlock(xco + 20, yco + 15, zco + 49, Blocks.stained_hardened_clay, 4, 1);
      world.setBlock(xco + 21, yco + 15, zco + 49, Blocks.quartz_block, 0, 1);
      world.setBlock(xco + 22, yco + 15, zco + 49, Blocks.quartz_block, 0, 1);
      world.setBlock(xco + 30, yco + 15, zco + 49, Blocks.quartz_block, 0, 1);
      world.setBlock(xco + 31, yco + 15, zco + 49, Blocks.quartz_block, 0, 1);
      world.setBlock(xco + 32, yco + 15, zco + 49, Blocks.stained_hardened_clay, 4, 1);
      world.setBlock(xco + 36, yco + 15, zco + 49, Blocks.stained_hardened_clay, 4, 1);
      world.setBlock(xco + 16, yco + 15, zco + 50, Blocks.stained_hardened_clay, 4, 1);
      world.setBlock(xco + 17, yco + 15, zco + 50, Blocks.stained_hardened_clay, 4, 1);
      world.setBlock(xco + 18, yco + 15, zco + 50, Blocks.stained_hardened_clay, 4, 1);
      world.setBlock(xco + 19, yco + 15, zco + 50, Blocks.stained_hardened_clay, 4, 1);
      world.setBlock(xco + 20, yco + 15, zco + 50, Blocks.stained_hardened_clay, 4, 1);
      world.setBlock(xco + 21, yco + 15, zco + 50, Blocks.quartz_block, 0, 1);
      world.setBlock(xco + 22, yco + 15, zco + 50, Blocks.quartz_block, 0, 1);
      world.setBlock(xco + 30, yco + 15, zco + 50, Blocks.quartz_block, 0, 1);
      world.setBlock(xco + 31, yco + 15, zco + 50, Blocks.quartz_block, 0, 1);
      world.setBlock(xco + 32, yco + 15, zco + 50, Blocks.stained_hardened_clay, 4, 1);
      world.setBlock(xco + 33, yco + 15, zco + 50, Blocks.stained_hardened_clay, 4, 1);
      world.setBlock(xco + 34, yco + 15, zco + 50, Blocks.stained_hardened_clay, 4, 1);
      world.setBlock(xco + 35, yco + 15, zco + 50, Blocks.stained_hardened_clay, 4, 1);
      world.setBlock(xco + 36, yco + 15, zco + 50, Blocks.stained_hardened_clay, 4, 1);
      world.setBlock(xco + 18, yco + 15, zco + 51, Blocks.stained_hardened_clay, 4, 1);
      world.setBlock(xco + 19, yco + 15, zco + 51, Blocks.stained_hardened_clay, 4, 1);
      world.setBlock(xco + 20, yco + 15, zco + 51, Blocks.stained_hardened_clay, 4, 1);
      world.setBlock(xco + 21, yco + 15, zco + 51, Blocks.stained_hardened_clay, 4, 1);
      world.setBlock(xco + 30, yco + 15, zco + 51, Blocks.stained_hardened_clay, 4, 1);
      world.setBlock(xco + 31, yco + 15, zco + 51, Blocks.stained_hardened_clay, 4, 1);
      world.setBlock(xco + 32, yco + 15, zco + 51, Blocks.stained_hardened_clay, 4, 1);
      world.setBlock(xco + 33, yco + 15, zco + 51, Blocks.stained_hardened_clay, 4, 1);
      world.setBlock(xco + 34, yco + 15, zco + 51, Blocks.stained_hardened_clay, 4, 1);
      world.setBlock(xco + 17, yco + 15, zco + 52, Blocks.stained_hardened_clay, 4, 1);
      world.setBlock(xco + 18, yco + 15, zco + 52, Blocks.stained_hardened_clay, 4, 1);
      world.setBlock(xco + 22, yco + 15, zco + 52, Blocks.stained_hardened_clay, 4, 1);
      world.setBlock(xco + 29, yco + 15, zco + 52, Blocks.stained_hardened_clay, 4, 1);
      world.setBlock(xco + 30, yco + 15, zco + 52, Blocks.stained_hardened_clay, 4, 1);
      world.setBlock(xco + 34, yco + 15, zco + 52, Blocks.stained_hardened_clay, 4, 1);
      world.setBlock(xco + 35, yco + 15, zco + 52, Blocks.stained_hardened_clay, 4, 1);
      world.setBlock(xco + 16, yco + 15, zco + 53, Blocks.stained_hardened_clay, 4, 1);
      world.setBlock(xco + 17, yco + 15, zco + 53, Blocks.stained_hardened_clay, 4, 1);
      world.setBlock(xco + 23, yco + 15, zco + 53, Blocks.stained_hardened_clay, 4, 1);
      world.setBlock(xco + 24, yco + 15, zco + 53, Blocks.stained_hardened_clay, 4, 1);
      world.setBlock(xco + 28, yco + 15, zco + 53, Blocks.stained_hardened_clay, 4, 1);
      world.setBlock(xco + 29, yco + 15, zco + 53, Blocks.stained_hardened_clay, 4, 1);
      world.setBlock(xco + 35, yco + 15, zco + 53, Blocks.stained_hardened_clay, 4, 1);
      world.setBlock(xco + 36, yco + 15, zco + 53, Blocks.stained_hardened_clay, 4, 1);
      world.setBlock(xco + 16, yco + 15, zco + 54, Blocks.stained_hardened_clay, 4, 1);
      world.setBlock(xco + 17, yco + 15, zco + 54, Blocks.stained_hardened_clay, 4, 1);
      world.setBlock(xco + 23, yco + 15, zco + 54, Blocks.stained_hardened_clay, 4, 1);
      world.setBlock(xco + 24, yco + 15, zco + 54, Blocks.stained_hardened_clay, 4, 1);
      world.setBlock(xco + 28, yco + 15, zco + 54, Blocks.stained_hardened_clay, 4, 1);
      world.setBlock(xco + 29, yco + 15, zco + 54, Blocks.stained_hardened_clay, 4, 1);
      world.setBlock(xco + 35, yco + 15, zco + 54, Blocks.stained_hardened_clay, 4, 1);
      world.setBlock(xco + 36, yco + 15, zco + 54, Blocks.stained_hardened_clay, 4, 1);
      world.setBlock(xco + 16, yco + 15, zco + 55, Blocks.stained_hardened_clay, 4, 1);
      world.setBlock(xco + 17, yco + 15, zco + 55, Blocks.stained_hardened_clay, 4, 1);
      world.setBlock(xco + 23, yco + 15, zco + 55, Blocks.stained_hardened_clay, 4, 1);
      world.setBlock(xco + 24, yco + 15, zco + 55, Blocks.stained_hardened_clay, 4, 1);
      world.setBlock(xco + 28, yco + 15, zco + 55, Blocks.stained_hardened_clay, 4, 1);
      world.setBlock(xco + 29, yco + 15, zco + 55, Blocks.stained_hardened_clay, 4, 1);
      world.setBlock(xco + 35, yco + 15, zco + 55, Blocks.stained_hardened_clay, 4, 1);
      world.setBlock(xco + 36, yco + 15, zco + 55, Blocks.stained_hardened_clay, 4, 1);
      world.setBlock(xco + 37, yco + 15, zco + 55, Blocks.stained_hardened_clay, 4, 1);
      world.setBlock(xco + 17, yco + 15, zco + 56, Blocks.stained_hardened_clay, 4, 1);
      world.setBlock(xco + 18, yco + 15, zco + 56, Blocks.stained_hardened_clay, 4, 1);
      world.setBlock(xco + 22, yco + 15, zco + 56, Blocks.stained_hardened_clay, 4, 1);
      world.setBlock(xco + 23, yco + 15, zco + 56, Blocks.stained_hardened_clay, 4, 1);
      world.setBlock(xco + 29, yco + 15, zco + 56, Blocks.stained_hardened_clay, 4, 1);
      world.setBlock(xco + 30, yco + 15, zco + 56, Blocks.stained_hardened_clay, 4, 1);
      world.setBlock(xco + 34, yco + 15, zco + 56, Blocks.stained_hardened_clay, 4, 1);
      world.setBlock(xco + 35, yco + 15, zco + 56, Blocks.stained_hardened_clay, 4, 1);
      world.setBlock(xco + 38, yco + 15, zco + 56, Blocks.stained_hardened_clay, 4, 1);
      world.setBlock(xco + 39, yco + 15, zco + 56, Blocks.wool, 15, 1);
      world.setBlock(xco + 40, yco + 15, zco + 56, Blocks.wool, 15, 1);
      world.setBlock(xco + 18, yco + 15, zco + 57, Blocks.stained_hardened_clay, 4, 1);
      world.setBlock(xco + 19, yco + 15, zco + 57, Blocks.stained_hardened_clay, 4, 1);
      world.setBlock(xco + 20, yco + 15, zco + 57, Blocks.stained_hardened_clay, 4, 1);
      world.setBlock(xco + 21, yco + 15, zco + 57, Blocks.stained_hardened_clay, 4, 1);
      world.setBlock(xco + 22, yco + 15, zco + 57, Blocks.stained_hardened_clay, 4, 1);
      world.setBlock(xco + 23, yco + 15, zco + 57, Blocks.stone, 0, 1);
      world.setBlock(xco + 29, yco + 15, zco + 57, Blocks.stone, 0, 1);
      world.setBlock(xco + 30, yco + 15, zco + 57, Blocks.stained_hardened_clay, 4, 1);
      world.setBlock(xco + 31, yco + 15, zco + 57, Blocks.stained_hardened_clay, 4, 1);
      world.setBlock(xco + 32, yco + 15, zco + 57, Blocks.stained_hardened_clay, 4, 1);
      world.setBlock(xco + 33, yco + 15, zco + 57, Blocks.stained_hardened_clay, 4, 1);
      world.setBlock(xco + 34, yco + 15, zco + 57, Blocks.stained_hardened_clay, 4, 1);
      world.setBlock(xco + 39, yco + 15, zco + 57, Blocks.stained_hardened_clay, 4, 1);
      world.setBlock(xco + 41, yco + 15, zco + 57, Blocks.wool, 15, 1);
      world.setBlock(xco + 19, yco + 15, zco + 58, Blocks.stained_hardened_clay, 4, 1);
      world.setBlock(xco + 20, yco + 15, zco + 58, Blocks.stained_hardened_clay, 4, 1);
      world.setBlock(xco + 21, yco + 15, zco + 58, Blocks.stained_hardened_clay, 4, 1);
      world.setBlock(xco + 23, yco + 15, zco + 58, Blocks.stone, 0, 1);
      world.setBlock(xco + 29, yco + 15, zco + 58, Blocks.stone, 0, 1);
      world.setBlock(xco + 31, yco + 15, zco + 58, Blocks.stained_hardened_clay, 4, 1);
      world.setBlock(xco + 32, yco + 15, zco + 58, Blocks.stained_hardened_clay, 4, 1);
      world.setBlock(xco + 33, yco + 15, zco + 58, Blocks.stained_hardened_clay, 4, 1);
      world.setBlock(xco + 40, yco + 15, zco + 58, Blocks.stained_hardened_clay, 4, 1);
      world.setBlock(xco + 42, yco + 15, zco + 58, Blocks.wool, 15, 1);
      world.setBlock(xco + 21, yco + 15, zco + 59, Blocks.stone, 0, 1);
      world.setBlock(xco + 22, yco + 15, zco + 59, Blocks.stone, 0, 1);
      world.setBlock(xco + 29, yco + 15, zco + 59, Blocks.stone, 0, 1);
      world.setBlock(xco + 34, yco + 15, zco + 59, Blocks.wool, 15, 1);
      world.setBlock(xco + 35, yco + 15, zco + 59, Blocks.wool, 15, 1);
      world.setBlock(xco + 36, yco + 15, zco + 59, Blocks.wool, 15, 1);
      world.setBlock(xco + 37, yco + 15, zco + 59, Blocks.wool, 15, 1);
      world.setBlock(xco + 41, yco + 15, zco + 59, Blocks.stained_hardened_clay, 4, 1);
      world.setBlock(xco + 42, yco + 15, zco + 59, Blocks.wool, 15, 1);
      world.setBlock(xco + 18, yco + 15, zco + 60, Blocks.stone, 0, 1);
      world.setBlock(xco + 19, yco + 15, zco + 60, Blocks.stone, 0, 1);
      world.setBlock(xco + 20, yco + 15, zco + 60, Blocks.stone, 0, 1);
      world.setBlock(xco + 29, yco + 15, zco + 60, Blocks.stone, 0, 1);
      world.setBlock(xco + 33, yco + 15, zco + 60, Blocks.wool, 15, 1);
      world.setBlock(xco + 38, yco + 15, zco + 60, Blocks.wool, 15, 1);
      world.setBlock(xco + 42, yco + 15, zco + 60, Blocks.stone, 0, 1);
      world.setBlock(xco + 43, yco + 15, zco + 60, Blocks.stone, 0, 1);
      world.setBlock(xco + 44, yco + 15, zco + 60, Blocks.stone, 0, 1);
      world.setBlock(xco + 45, yco + 15, zco + 60, Blocks.stone, 0, 1);
      world.setBlock(xco + 18, yco + 15, zco + 61, Blocks.obsidian, 0, 1);
      world.setBlock(xco + 20, yco + 15, zco + 61, Blocks.stone, 0, 1);
      world.setBlock(xco + 29, yco + 15, zco + 61, Blocks.stone, 0, 1);
      world.setBlock(xco + 32, yco + 15, zco + 61, Blocks.wool, 15, 1);
      world.setBlock(xco + 39, yco + 15, zco + 61, Blocks.wool, 15, 1);
      world.setBlock(xco + 41, yco + 15, zco + 61, Blocks.stone, 0, 1);
      world.setBlock(xco + 46, yco + 15, zco + 61, Blocks.stone, 0, 1);
      world.setBlock(xco + 18, yco + 15, zco + 62, Blocks.obsidian, 0, 1);
      world.setBlock(xco + 21, yco + 15, zco + 62, Blocks.stone, 0, 1);
      world.setBlock(xco + 29, yco + 15, zco + 62, Blocks.stone, 0, 1);
      world.setBlock(xco + 32, yco + 15, zco + 62, Blocks.wool, 15, 1);
      world.setBlock(xco + 39, yco + 15, zco + 62, Blocks.wool, 15, 1);
      world.setBlock(xco + 40, yco + 15, zco + 62, Blocks.stone, 0, 1);
      world.setBlock(xco + 47, yco + 15, zco + 62, Blocks.stone, 0, 1);
      world.setBlock(xco + 18, yco + 15, zco + 63, Blocks.obsidian, 0, 1);
      world.setBlock(xco + 21, yco + 15, zco + 63, Blocks.stone, 0, 1);
      world.setBlock(xco + 29, yco + 15, zco + 63, Blocks.stone, 0, 1);
      world.setBlock(xco + 32, yco + 15, zco + 63, Blocks.wool, 15, 1);
      world.setBlock(xco + 39, yco + 15, zco + 63, Blocks.wool, 15, 1);
      world.setBlock(xco + 40, yco + 15, zco + 63, Blocks.stone, 0, 1);
      world.setBlock(xco + 47, yco + 15, zco + 63, Blocks.stone, 0, 1);
      world.setBlock(xco + 18, yco + 15, zco + 64, Blocks.obsidian, 0, 1);
      world.setBlock(xco + 20, yco + 15, zco + 64, Blocks.stone, 0, 1);
      world.setBlock(xco + 29, yco + 15, zco + 64, Blocks.stone, 0, 1);
      world.setBlock(xco + 32, yco + 15, zco + 64, Blocks.wool, 15, 1);
      world.setBlock(xco + 39, yco + 15, zco + 64, Blocks.wool, 15, 1);
      world.setBlock(xco + 40, yco + 15, zco + 64, Blocks.stone, 0, 1);
      world.setBlock(xco + 47, yco + 15, zco + 64, Blocks.stone, 0, 1);
      world.setBlock(xco + 18, yco + 15, zco + 65, Blocks.stone, 0, 1);
      world.setBlock(xco + 19, yco + 15, zco + 65, Blocks.stone, 0, 1);
      world.setBlock(xco + 29, yco + 15, zco + 65, Blocks.stone, 0, 1);
      world.setBlock(xco + 33, yco + 15, zco + 65, Blocks.wool, 15, 1);
      world.setBlock(xco + 38, yco + 15, zco + 65, Blocks.wool, 15, 1);
      world.setBlock(xco + 40, yco + 15, zco + 65, Blocks.stone, 0, 1);
      world.setBlock(xco + 47, yco + 15, zco + 65, Blocks.stone, 0, 1);
      world.setBlock(xco + 18, yco + 15, zco + 66, Blocks.stone, 0, 1);
      world.setBlock(xco + 19, yco + 15, zco + 66, Blocks.stone, 0, 1);
      world.setBlock(xco + 29, yco + 15, zco + 66, Blocks.stone, 0, 1);
      world.setBlock(xco + 34, yco + 15, zco + 66, Blocks.wool, 15, 1);
      world.setBlock(xco + 35, yco + 15, zco + 66, Blocks.wool, 15, 1);
      world.setBlock(xco + 36, yco + 15, zco + 66, Blocks.wool, 15, 1);
      world.setBlock(xco + 37, yco + 15, zco + 66, Blocks.wool, 15, 1);
      world.setBlock(xco + 41, yco + 15, zco + 66, Blocks.stone, 0, 1);
      world.setBlock(xco + 46, yco + 15, zco + 66, Blocks.stone, 0, 1);
      world.setBlock(xco + 20, yco + 15, zco + 67, Blocks.stone, 0, 1);
      world.setBlock(xco + 21, yco + 15, zco + 67, Blocks.stone, 0, 1);
      world.setBlock(xco + 22, yco + 15, zco + 67, Blocks.stone, 0, 1);
      world.setBlock(xco + 23, yco + 15, zco + 67, Blocks.stone, 0, 1);
      world.setBlock(xco + 24, yco + 15, zco + 67, Blocks.stone, 0, 1);
      world.setBlock(xco + 25, yco + 15, zco + 67, Blocks.stone, 0, 1);
      world.setBlock(xco + 26, yco + 15, zco + 67, Blocks.stone, 0, 1);
      world.setBlock(xco + 27, yco + 15, zco + 67, Blocks.stone, 0, 1);
      world.setBlock(xco + 28, yco + 15, zco + 67, Blocks.stone, 0, 1);
      world.setBlock(xco + 42, yco + 15, zco + 67, Blocks.stone, 0, 1);
      world.setBlock(xco + 43, yco + 15, zco + 67, Blocks.stone, 0, 1);
      world.setBlock(xco + 44, yco + 15, zco + 67, Blocks.stone, 0, 1);
      world.setBlock(xco + 45, yco + 15, zco + 67, Blocks.stone, 0, 1);
      world.setBlock(xco + 25, yco + 16, zco + 36, Blocks.quartz_block, 0, 1);
      world.setBlock(xco + 27, yco + 16, zco + 36, Blocks.quartz_block, 0, 1);
      world.setBlock(xco + 16, yco + 16, zco + 37, Blocks.stained_hardened_clay, 4, 1);
      world.setBlock(xco + 17, yco + 16, zco + 37, Blocks.stained_hardened_clay, 4, 1);
      world.setBlock(xco + 18, yco + 16, zco + 37, Blocks.stained_hardened_clay, 4, 1);
      world.setBlock(xco + 19, yco + 16, zco + 37, Blocks.stained_hardened_clay, 4, 1);
      world.setBlock(xco + 20, yco + 16, zco + 37, Blocks.stained_hardened_clay, 4, 1);
      world.setBlock(xco + 21, yco + 16, zco + 37, Blocks.quartz_stairs, 0, 1);
      world.setBlock(xco + 22, yco + 16, zco + 37, Blocks.quartz_block, 0, 1);
      world.setBlock(xco + 23, yco + 16, zco + 37, Blocks.stained_hardened_clay, 4, 1);
      world.setBlock(xco + 24, yco + 16, zco + 37, Blocks.quartz_block, 0, 1);
      world.setBlock(xco + 28, yco + 16, zco + 37, Blocks.quartz_block, 0, 1);
      world.setBlock(xco + 29, yco + 16, zco + 37, Blocks.stained_hardened_clay, 4, 1);
      world.setBlock(xco + 32, yco + 16, zco + 37, Blocks.stained_hardened_clay, 4, 1);
      world.setBlock(xco + 33, yco + 16, zco + 37, Blocks.stained_hardened_clay, 4, 1);
      world.setBlock(xco + 34, yco + 16, zco + 37, Blocks.stained_hardened_clay, 4, 1);
      world.setBlock(xco + 35, yco + 16, zco + 37, Blocks.stained_hardened_clay, 4, 1);
      world.setBlock(xco + 36, yco + 16, zco + 37, Blocks.stained_hardened_clay, 4, 1);
      world.setBlock(xco + 16, yco + 16, zco + 38, Blocks.stained_hardened_clay, 4, 1);
      world.setBlock(xco + 17, yco + 16, zco + 38, Blocks.stained_hardened_clay, 4, 1);
      world.setBlock(xco + 18, yco + 16, zco + 38, Blocks.stained_hardened_clay, 4, 1);
      world.setBlock(xco + 19, yco + 16, zco + 38, Blocks.stained_hardened_clay, 4, 1);
      world.setBlock(xco + 20, yco + 16, zco + 38, Blocks.stained_hardened_clay, 4, 1);
      world.setBlock(xco + 21, yco + 16, zco + 38, Blocks.quartz_stairs, 0, 1);
      world.setBlock(xco + 22, yco + 16, zco + 38, Blocks.quartz_block, 0, 1);
      world.setBlock(xco + 30, yco + 16, zco + 38, Blocks.quartz_block, 0, 1);
      world.setBlock(xco + 31, yco + 16, zco + 38, Blocks.quartz_stairs, 1, 1);
      world.setBlock(xco + 32, yco + 16, zco + 38, Blocks.stained_hardened_clay, 4, 1);
      world.setBlock(xco + 33, yco + 16, zco + 38, Blocks.stained_hardened_clay, 4, 1);
      world.setBlock(xco + 34, yco + 16, zco + 38, Blocks.stained_hardened_clay, 4, 1);
      world.setBlock(xco + 35, yco + 16, zco + 38, Blocks.stained_hardened_clay, 4, 1);
      world.setBlock(xco + 36, yco + 16, zco + 38, Blocks.stained_hardened_clay, 4, 1);
      world.setBlock(xco + 4, yco + 16, zco + 39, Blocks.stone, 0, 1);
      world.setBlock(xco + 5, yco + 16, zco + 39, Blocks.stone, 0, 1);
      world.setBlock(xco + 6, yco + 16, zco + 39, Blocks.stone, 0, 1);
      world.setBlock(xco + 7, yco + 16, zco + 39, Blocks.stone, 0, 1);
      world.setBlock(xco + 8, yco + 16, zco + 39, Blocks.stone, 0, 1);
      world.setBlock(xco + 16, yco + 16, zco + 39, Blocks.stained_hardened_clay, 4, 1);
      world.setBlock(xco + 20, yco + 16, zco + 39, Blocks.stained_hardened_clay, 4, 1);
      world.setBlock(xco + 21, yco + 16, zco + 39, Blocks.quartz_stairs, 0, 1);
      world.setBlock(xco + 22, yco + 16, zco + 39, Blocks.quartz_block, 0, 1);
      world.setBlock(xco + 30, yco + 16, zco + 39, Blocks.quartz_block, 0, 1);
      world.setBlock(xco + 31, yco + 16, zco + 39, Blocks.quartz_stairs, 1, 1);
      world.setBlock(xco + 32, yco + 16, zco + 39, Blocks.stained_hardened_clay, 4, 1);
      world.setBlock(xco + 36, yco + 16, zco + 39, Blocks.stained_hardened_clay, 4, 1);
      world.setBlock(xco + 3, yco + 16, zco + 40, Blocks.stone, 0, 1);
      world.setBlock(xco + 4, yco + 16, zco + 40, Blocks.stone, 0, 1);
      world.setBlock(xco + 8, yco + 16, zco + 40, Blocks.stone, 0, 1);
      world.setBlock(xco + 9, yco + 16, zco + 40, Blocks.stone, 0, 1);
      world.setBlock(xco + 16, yco + 16, zco + 40, Blocks.stained_hardened_clay, 4, 1);
      world.setBlock(xco + 20, yco + 16, zco + 40, Blocks.stained_hardened_clay, 4, 1);
      world.setBlock(xco + 21, yco + 16, zco + 40, Blocks.quartz_stairs, 0, 1);
      world.setBlock(xco + 22, yco + 16, zco + 40, Blocks.quartz_block, 0, 1);
      world.setBlock(xco + 30, yco + 16, zco + 40, Blocks.quartz_block, 0, 1);
      world.setBlock(xco + 31, yco + 16, zco + 40, Blocks.quartz_stairs, 1, 1);
      world.setBlock(xco + 32, yco + 16, zco + 40, Blocks.stained_hardened_clay, 4, 1);
      world.setBlock(xco + 34, yco + 16, zco + 40, Blocks.stained_hardened_clay, 4, 1);
      world.setBlock(xco + 35, yco + 16, zco + 40, Blocks.stained_hardened_clay, 4, 1);
      world.setBlock(xco + 36, yco + 16, zco + 40, Blocks.stained_hardened_clay, 4, 1);
      world.setBlock(xco + 2, yco + 16, zco + 41, Blocks.stone, 0, 1);
      world.setBlock(xco + 3, yco + 16, zco + 41, Blocks.stone, 0, 1);
      world.setBlock(xco + 9, yco + 16, zco + 41, Blocks.stone, 0, 1);
      world.setBlock(xco + 10, yco + 16, zco + 41, Blocks.stone, 0, 1);
      world.setBlock(xco + 17, yco + 16, zco + 41, Blocks.quartz_block, 0, 1);
      world.setBlock(xco + 18, yco + 16, zco + 41, Blocks.quartz_block, 0, 1);
      world.setBlock(xco + 20, yco + 16, zco + 41, Blocks.quartz_block, 0, 1);
      world.setBlock(xco + 21, yco + 16, zco + 41, Blocks.quartz_stairs, 0, 1);
      world.setBlock(xco + 22, yco + 16, zco + 41, Blocks.quartz_block, 0, 1);
      world.setBlock(xco + 26, yco + 16, zco + 41, Blocks.stone, 0, 1);
      world.setBlock(xco + 27, yco + 16, zco + 41, Blocks.stone, 0, 1);
      world.setBlock(xco + 30, yco + 16, zco + 41, Blocks.quartz_block, 0, 1);
      world.setBlock(xco + 31, yco + 16, zco + 41, Blocks.quartz_stairs, 1, 1);
      world.setBlock(xco + 32, yco + 16, zco + 41, Blocks.quartz_block, 0, 1);
      world.setBlock(xco + 35, yco + 16, zco + 41, Blocks.quartz_block, 0, 1);
      world.setBlock(xco + 2, yco + 16, zco + 42, Blocks.stone, 0, 1);
      world.setBlock(xco + 10, yco + 16, zco + 42, Blocks.stone, 0, 1);
      world.setBlock(xco + 17, yco + 16, zco + 42, Blocks.quartz_block, 0, 1);
      world.setBlock(xco + 20, yco + 16, zco + 42, Blocks.quartz_block, 0, 1);
      world.setBlock(xco + 21, yco + 16, zco + 42, Blocks.quartz_stairs, 0, 1);
      world.setBlock(xco + 22, yco + 16, zco + 42, Blocks.quartz_block, 0, 1);
      world.setBlock(xco + 26, yco + 16, zco + 42, Blocks.stone, 0, 1);
      world.setBlock(xco + 27, yco + 16, zco + 42, Blocks.stone, 0, 1);
      world.setBlock(xco + 30, yco + 16, zco + 42, Blocks.quartz_block, 0, 1);
      world.setBlock(xco + 31, yco + 16, zco + 42, Blocks.quartz_stairs, 1, 1);
      world.setBlock(xco + 32, yco + 16, zco + 42, Blocks.quartz_block, 0, 1);
      world.setBlock(xco + 35, yco + 16, zco + 42, Blocks.quartz_block, 0, 1);
      world.setBlock(xco + 2, yco + 16, zco + 43, Blocks.stone, 0, 1);
      world.setBlock(xco + 10, yco + 16, zco + 43, Blocks.stone, 0, 1);
      world.setBlock(xco + 16, yco + 16, zco + 43, Blocks.stained_hardened_clay, 4, 1);
      world.setBlock(xco + 17, yco + 16, zco + 43, Blocks.stained_hardened_clay, 4, 1);
      world.setBlock(xco + 20, yco + 16, zco + 43, Blocks.stained_hardened_clay, 4, 1);
      world.setBlock(xco + 21, yco + 16, zco + 43, Blocks.quartz_stairs, 0, 1);
      world.setBlock(xco + 22, yco + 16, zco + 43, Blocks.quartz_block, 0, 1);
      world.setBlock(xco + 30, yco + 16, zco + 43, Blocks.quartz_block, 0, 1);
      world.setBlock(xco + 31, yco + 16, zco + 43, Blocks.quartz_stairs, 1, 1);
      world.setBlock(xco + 32, yco + 16, zco + 43, Blocks.stained_hardened_clay, 4, 1);
      world.setBlock(xco + 36, yco + 16, zco + 43, Blocks.stained_hardened_clay, 4, 1);
      world.setBlock(xco + 2, yco + 16, zco + 44, Blocks.stone, 0, 1);
      world.setBlock(xco + 10, yco + 16, zco + 44, Blocks.stone, 0, 1);
      world.setBlock(xco + 16, yco + 16, zco + 44, Blocks.stained_hardened_clay, 4, 1);
      world.setBlock(xco + 20, yco + 16, zco + 44, Blocks.stained_hardened_clay, 4, 1);
      world.setBlock(xco + 21, yco + 16, zco + 44, Blocks.quartz_stairs, 0, 1);
      world.setBlock(xco + 22, yco + 16, zco + 44, Blocks.quartz_block, 0, 1);
      world.setBlock(xco + 30, yco + 16, zco + 44, Blocks.quartz_block, 0, 1);
      world.setBlock(xco + 31, yco + 16, zco + 44, Blocks.quartz_stairs, 1, 1);
      world.setBlock(xco + 32, yco + 16, zco + 44, Blocks.stained_hardened_clay, 4, 1);
      world.setBlock(xco + 36, yco + 16, zco + 44, Blocks.stained_hardened_clay, 4, 1);
      world.setBlock(xco + 2, yco + 16, zco + 45, Blocks.stone, 0, 1);
      world.setBlock(xco + 3, yco + 16, zco + 45, Blocks.stone, 0, 1);
      world.setBlock(xco + 9, yco + 16, zco + 45, Blocks.stone, 0, 1);
      world.setBlock(xco + 10, yco + 16, zco + 45, Blocks.stone, 0, 1);
      world.setBlock(xco + 16, yco + 16, zco + 45, Blocks.stained_hardened_clay, 4, 1);
      world.setBlock(xco + 20, yco + 16, zco + 45, Blocks.stained_hardened_clay, 4, 1);
      world.setBlock(xco + 21, yco + 16, zco + 45, Blocks.quartz_stairs, 0, 1);
      world.setBlock(xco + 22, yco + 16, zco + 45, Blocks.quartz_block, 0, 1);
      world.setBlock(xco + 30, yco + 16, zco + 45, Blocks.quartz_block, 0, 1);
      world.setBlock(xco + 31, yco + 16, zco + 45, Blocks.quartz_stairs, 1, 1);
      world.setBlock(xco + 32, yco + 16, zco + 45, Blocks.stained_hardened_clay, 4, 1);
      world.setBlock(xco + 36, yco + 16, zco + 45, Blocks.stained_hardened_clay, 4, 1);
      world.setBlock(xco + 3, yco + 16, zco + 46, Blocks.stone, 0, 1);
      world.setBlock(xco + 4, yco + 16, zco + 46, Blocks.stone, 0, 1);
      world.setBlock(xco + 8, yco + 16, zco + 46, Blocks.stone, 0, 1);
      world.setBlock(xco + 9, yco + 16, zco + 46, Blocks.stone, 0, 1);
      world.setBlock(xco + 17, yco + 16, zco + 46, Blocks.quartz_block, 0, 1);
      world.setBlock(xco + 18, yco + 16, zco + 46, Blocks.quartz_block, 0, 1);
      world.setBlock(xco + 19, yco + 16, zco + 46, Blocks.quartz_block, 0, 1);
      world.setBlock(xco + 20, yco + 16, zco + 46, Blocks.quartz_block, 0, 1);
      world.setBlock(xco + 21, yco + 16, zco + 46, Blocks.quartz_stairs, 0, 1);
      world.setBlock(xco + 22, yco + 16, zco + 46, Blocks.quartz_block, 0, 1);
      world.setBlock(xco + 25, yco + 16, zco + 46, Blocks.stone, 0, 1);
      world.setBlock(xco + 26, yco + 16, zco + 46, Blocks.stone, 0, 1);
      world.setBlock(xco + 30, yco + 16, zco + 46, Blocks.quartz_block, 0, 1);
      world.setBlock(xco + 31, yco + 16, zco + 46, Blocks.quartz_stairs, 1, 1);
      world.setBlock(xco + 32, yco + 16, zco + 46, Blocks.quartz_block, 0, 1);
      world.setBlock(xco + 34, yco + 16, zco + 46, Blocks.quartz_block, 0, 1);
      world.setBlock(xco + 35, yco + 16, zco + 46, Blocks.quartz_block, 0, 1);
      world.setBlock(xco + 4, yco + 16, zco + 47, Blocks.stone, 0, 1);
      world.setBlock(xco + 5, yco + 16, zco + 47, Blocks.stone, 0, 1);
      world.setBlock(xco + 6, yco + 16, zco + 47, Blocks.stone, 0, 1);
      world.setBlock(xco + 7, yco + 16, zco + 47, Blocks.stone, 0, 1);
      world.setBlock(xco + 8, yco + 16, zco + 47, Blocks.stone, 0, 1);
      world.setBlock(xco + 17, yco + 16, zco + 47, Blocks.quartz_block, 0, 1);
      world.setBlock(xco + 18, yco + 16, zco + 47, Blocks.quartz_block, 0, 1);
      world.setBlock(xco + 19, yco + 16, zco + 47, Blocks.quartz_block, 0, 1);
      world.setBlock(xco + 20, yco + 16, zco + 47, Blocks.quartz_block, 0, 1);
      world.setBlock(xco + 21, yco + 16, zco + 47, Blocks.quartz_stairs, 0, 1);
      world.setBlock(xco + 22, yco + 16, zco + 47, Blocks.quartz_block, 0, 1);
      world.setBlock(xco + 25, yco + 16, zco + 47, Blocks.stone, 0, 1);
      world.setBlock(xco + 26, yco + 16, zco + 47, Blocks.stone, 0, 1);
      world.setBlock(xco + 30, yco + 16, zco + 47, Blocks.quartz_block, 0, 1);
      world.setBlock(xco + 31, yco + 16, zco + 47, Blocks.quartz_stairs, 1, 1);
      world.setBlock(xco + 32, yco + 16, zco + 47, Blocks.quartz_block, 0, 1);
      world.setBlock(xco + 34, yco + 16, zco + 47, Blocks.quartz_block, 0, 1);
      world.setBlock(xco + 35, yco + 16, zco + 47, Blocks.quartz_block, 0, 1);
      world.setBlock(xco + 16, yco + 16, zco + 48, Blocks.stained_hardened_clay, 4, 1);
      world.setBlock(xco + 20, yco + 16, zco + 48, Blocks.stained_hardened_clay, 4, 1);
      world.setBlock(xco + 21, yco + 16, zco + 48, Blocks.quartz_stairs, 0, 1);
      world.setBlock(xco + 22, yco + 16, zco + 48, Blocks.quartz_block, 0, 1);
      world.setBlock(xco + 30, yco + 16, zco + 48, Blocks.quartz_block, 0, 1);
      world.setBlock(xco + 31, yco + 16, zco + 48, Blocks.quartz_stairs, 1, 1);
      world.setBlock(xco + 32, yco + 16, zco + 48, Blocks.stained_hardened_clay, 4, 1);
      world.setBlock(xco + 35, yco + 16, zco + 48, Blocks.stained_hardened_clay, 4, 1);
      world.setBlock(xco + 36, yco + 16, zco + 48, Blocks.stained_hardened_clay, 4, 1);
      world.setBlock(xco + 16, yco + 16, zco + 49, Blocks.stained_hardened_clay, 4, 1);
      world.setBlock(xco + 20, yco + 16, zco + 49, Blocks.stained_hardened_clay, 4, 1);
      world.setBlock(xco + 21, yco + 16, zco + 49, Blocks.quartz_stairs, 0, 1);
      world.setBlock(xco + 22, yco + 16, zco + 49, Blocks.quartz_block, 0, 1);
      world.setBlock(xco + 30, yco + 16, zco + 49, Blocks.quartz_block, 0, 1);
      world.setBlock(xco + 31, yco + 16, zco + 49, Blocks.quartz_stairs, 1, 1);
      world.setBlock(xco + 32, yco + 16, zco + 49, Blocks.stained_hardened_clay, 4, 1);
      world.setBlock(xco + 36, yco + 16, zco + 49, Blocks.stained_hardened_clay, 4, 1);
      world.setBlock(xco + 16, yco + 16, zco + 50, Blocks.stained_hardened_clay, 4, 1);
      world.setBlock(xco + 17, yco + 16, zco + 50, Blocks.stained_hardened_clay, 4, 1);
      world.setBlock(xco + 18, yco + 16, zco + 50, Blocks.stained_hardened_clay, 4, 1);
      world.setBlock(xco + 19, yco + 16, zco + 50, Blocks.stained_hardened_clay, 4, 1);
      world.setBlock(xco + 20, yco + 16, zco + 50, Blocks.stained_hardened_clay, 4, 1);
      world.setBlock(xco + 21, yco + 16, zco + 50, Blocks.quartz_stairs, 0, 1);
      world.setBlock(xco + 22, yco + 16, zco + 50, Blocks.quartz_block, 0, 1);
      world.setBlock(xco + 30, yco + 16, zco + 50, Blocks.quartz_block, 0, 1);
      world.setBlock(xco + 31, yco + 16, zco + 50, Blocks.quartz_stairs, 1, 1);
      world.setBlock(xco + 32, yco + 16, zco + 50, Blocks.stained_hardened_clay, 4, 1);
      world.setBlock(xco + 33, yco + 16, zco + 50, Blocks.stained_hardened_clay, 4, 1);
      world.setBlock(xco + 34, yco + 16, zco + 50, Blocks.stained_hardened_clay, 4, 1);
      world.setBlock(xco + 35, yco + 16, zco + 50, Blocks.stained_hardened_clay, 4, 1);
      world.setBlock(xco + 36, yco + 16, zco + 50, Blocks.stained_hardened_clay, 4, 1);
      world.setBlock(xco + 18, yco + 16, zco + 51, Blocks.stained_hardened_clay, 4, 1);
      world.setBlock(xco + 19, yco + 16, zco + 51, Blocks.stained_hardened_clay, 4, 1);
      world.setBlock(xco + 20, yco + 16, zco + 51, Blocks.stained_hardened_clay, 4, 1);
      world.setBlock(xco + 21, yco + 16, zco + 51, Blocks.stained_hardened_clay, 4, 1);
      world.setBlock(xco + 30, yco + 16, zco + 51, Blocks.stained_hardened_clay, 4, 1);
      world.setBlock(xco + 31, yco + 16, zco + 51, Blocks.stained_hardened_clay, 4, 1);
      world.setBlock(xco + 32, yco + 16, zco + 51, Blocks.stained_hardened_clay, 4, 1);
      world.setBlock(xco + 33, yco + 16, zco + 51, Blocks.stained_hardened_clay, 4, 1);
      world.setBlock(xco + 34, yco + 16, zco + 51, Blocks.stained_hardened_clay, 4, 1);
      world.setBlock(xco + 17, yco + 16, zco + 52, Blocks.stained_hardened_clay, 4, 1);
      world.setBlock(xco + 18, yco + 16, zco + 52, Blocks.stained_hardened_clay, 4, 1);
      world.setBlock(xco + 22, yco + 16, zco + 52, Blocks.stained_hardened_clay, 4, 1);
      world.setBlock(xco + 29, yco + 16, zco + 52, Blocks.stained_hardened_clay, 4, 1);
      world.setBlock(xco + 30, yco + 16, zco + 52, Blocks.stained_hardened_clay, 4, 1);
      world.setBlock(xco + 34, yco + 16, zco + 52, Blocks.stained_hardened_clay, 4, 1);
      world.setBlock(xco + 35, yco + 16, zco + 52, Blocks.stained_hardened_clay, 4, 1);
      world.setBlock(xco + 16, yco + 16, zco + 53, Blocks.stained_hardened_clay, 4, 1);
      world.setBlock(xco + 17, yco + 16, zco + 53, Blocks.stained_hardened_clay, 4, 1);
      world.setBlock(xco + 23, yco + 16, zco + 53, Blocks.stained_hardened_clay, 4, 1);
      world.setBlock(xco + 24, yco + 16, zco + 53, Blocks.stained_hardened_clay, 4, 1);
      world.setBlock(xco + 28, yco + 16, zco + 53, Blocks.stained_hardened_clay, 4, 1);
      world.setBlock(xco + 29, yco + 16, zco + 53, Blocks.stained_hardened_clay, 4, 1);
      world.setBlock(xco + 35, yco + 16, zco + 53, Blocks.stained_hardened_clay, 4, 1);
      world.setBlock(xco + 36, yco + 16, zco + 53, Blocks.stained_hardened_clay, 4, 1);
      world.setBlock(xco + 16, yco + 16, zco + 54, Blocks.stained_hardened_clay, 4, 1);
      world.setBlock(xco + 17, yco + 16, zco + 54, Blocks.stained_hardened_clay, 4, 1);
      world.setBlock(xco + 23, yco + 16, zco + 54, Blocks.stained_hardened_clay, 4, 1);
      world.setBlock(xco + 24, yco + 16, zco + 54, Blocks.stained_hardened_clay, 4, 1);
      world.setBlock(xco + 28, yco + 16, zco + 54, Blocks.stained_hardened_clay, 4, 1);
      world.setBlock(xco + 29, yco + 16, zco + 54, Blocks.stained_hardened_clay, 4, 1);
      world.setBlock(xco + 35, yco + 16, zco + 54, Blocks.stained_hardened_clay, 4, 1);
      world.setBlock(xco + 36, yco + 16, zco + 54, Blocks.stained_hardened_clay, 4, 1);
      world.setBlock(xco + 16, yco + 16, zco + 55, Blocks.stained_hardened_clay, 4, 1);
      world.setBlock(xco + 17, yco + 16, zco + 55, Blocks.stained_hardened_clay, 4, 1);
      world.setBlock(xco + 23, yco + 16, zco + 55, Blocks.stained_hardened_clay, 4, 1);
      world.setBlock(xco + 24, yco + 16, zco + 55, Blocks.stained_hardened_clay, 4, 1);
      world.setBlock(xco + 28, yco + 16, zco + 55, Blocks.stained_hardened_clay, 4, 1);
      world.setBlock(xco + 29, yco + 16, zco + 55, Blocks.stained_hardened_clay, 4, 1);
      world.setBlock(xco + 35, yco + 16, zco + 55, Blocks.stained_hardened_clay, 4, 1);
      world.setBlock(xco + 36, yco + 16, zco + 55, Blocks.stained_hardened_clay, 4, 1);
      world.setBlock(xco + 37, yco + 16, zco + 55, Blocks.stained_hardened_clay, 4, 1);
      world.setBlock(xco + 17, yco + 16, zco + 56, Blocks.stained_hardened_clay, 4, 1);
      world.setBlock(xco + 18, yco + 16, zco + 56, Blocks.stained_hardened_clay, 4, 1);
      world.setBlock(xco + 22, yco + 16, zco + 56, Blocks.stained_hardened_clay, 4, 1);
      world.setBlock(xco + 23, yco + 16, zco + 56, Blocks.stained_hardened_clay, 4, 1);
      world.setBlock(xco + 24, yco + 16, zco + 56, Blocks.stone, 4, 1);
      world.setBlock(xco + 28, yco + 16, zco + 56, Blocks.stone, 4, 1);
      world.setBlock(xco + 29, yco + 16, zco + 56, Blocks.stained_hardened_clay, 4, 1);
      world.setBlock(xco + 30, yco + 16, zco + 56, Blocks.stained_hardened_clay, 4, 1);
      world.setBlock(xco + 34, yco + 16, zco + 56, Blocks.stained_hardened_clay, 4, 1);
      world.setBlock(xco + 35, yco + 16, zco + 56, Blocks.stained_hardened_clay, 4, 1);
      world.setBlock(xco + 38, yco + 16, zco + 56, Blocks.stained_hardened_clay, 4, 1);
      world.setBlock(xco + 39, yco + 16, zco + 56, Blocks.wool, 15, 1);
      world.setBlock(xco + 40, yco + 16, zco + 56, Blocks.wool, 15, 1);
      world.setBlock(xco + 18, yco + 16, zco + 57, Blocks.stained_hardened_clay, 4, 1);
      world.setBlock(xco + 19, yco + 16, zco + 57, Blocks.stained_hardened_clay, 4, 1);
      world.setBlock(xco + 20, yco + 16, zco + 57, Blocks.stained_hardened_clay, 4, 1);
      world.setBlock(xco + 21, yco + 16, zco + 57, Blocks.stained_hardened_clay, 4, 1);
      world.setBlock(xco + 22, yco + 16, zco + 57, Blocks.stained_hardened_clay, 4, 1);
      world.setBlock(xco + 24, yco + 16, zco + 57, Blocks.stone, 0, 1);
      world.setBlock(xco + 28, yco + 16, zco + 57, Blocks.stone, 0, 1);
      world.setBlock(xco + 30, yco + 16, zco + 57, Blocks.stained_hardened_clay, 4, 1);
      world.setBlock(xco + 31, yco + 16, zco + 57, Blocks.stained_hardened_clay, 4, 1);
      world.setBlock(xco + 32, yco + 16, zco + 57, Blocks.stained_hardened_clay, 4, 1);
      world.setBlock(xco + 33, yco + 16, zco + 57, Blocks.stained_hardened_clay, 4, 1);
      world.setBlock(xco + 34, yco + 16, zco + 57, Blocks.stained_hardened_clay, 4, 1);
      world.setBlock(xco + 39, yco + 16, zco + 57, Blocks.stained_hardened_clay, 4, 1);
      world.setBlock(xco + 41, yco + 16, zco + 57, Blocks.wool, 15, 1);
      world.setBlock(xco + 19, yco + 16, zco + 58, Blocks.stained_hardened_clay, 4, 1);
      world.setBlock(xco + 20, yco + 16, zco + 58, Blocks.stained_hardened_clay, 4, 1);
      world.setBlock(xco + 21, yco + 16, zco + 58, Blocks.stained_hardened_clay, 4, 1);
      world.setBlock(xco + 24, yco + 16, zco + 58, Blocks.stone, 0, 1);
      world.setBlock(xco + 28, yco + 16, zco + 58, Blocks.stone, 0, 1);
      world.setBlock(xco + 31, yco + 16, zco + 58, Blocks.stained_hardened_clay, 4, 1);
      world.setBlock(xco + 32, yco + 16, zco + 58, Blocks.stained_hardened_clay, 4, 1);
      world.setBlock(xco + 33, yco + 16, zco + 58, Blocks.stained_hardened_clay, 4, 1);
      world.setBlock(xco + 40, yco + 16, zco + 58, Blocks.stained_hardened_clay, 4, 1);
      world.setBlock(xco + 42, yco + 16, zco + 58, Blocks.wool, 15, 1);
      world.setBlock(xco + 23, yco + 16, zco + 59, Blocks.stone, 0, 1);
      world.setBlock(xco + 24, yco + 16, zco + 59, Blocks.stone, 0, 1);
      world.setBlock(xco + 28, yco + 16, zco + 59, Blocks.stone, 0, 1);
      world.setBlock(xco + 34, yco + 16, zco + 59, Blocks.redstone_block, 0, 1);
      world.setBlock(xco + 35, yco + 16, zco + 59, Blocks.redstone_block, 0, 1);
      world.setBlock(xco + 36, yco + 16, zco + 59, Blocks.redstone_block, 0, 1);
      world.setBlock(xco + 37, yco + 16, zco + 59, Blocks.redstone_block, 0, 1);
      world.setBlock(xco + 41, yco + 16, zco + 59, Blocks.stained_hardened_clay, 4, 1);
      world.setBlock(xco + 42, yco + 16, zco + 59, Blocks.wool, 15, 1);
      world.setBlock(xco + 20, yco + 16, zco + 60, Blocks.stone, 0, 1);
      world.setBlock(xco + 21, yco + 16, zco + 60, Blocks.stone, 0, 1);
      world.setBlock(xco + 22, yco + 16, zco + 60, Blocks.stone, 0, 1);
      world.setBlock(xco + 23, yco + 16, zco + 60, Blocks.stone, 0, 1);
      world.setBlock(xco + 28, yco + 16, zco + 60, Blocks.stone, 0, 1);
      world.setBlock(xco + 33, yco + 16, zco + 60, Blocks.redstone_block, 0, 1);
      world.setBlock(xco + 38, yco + 16, zco + 60, Blocks.redstone_block, 0, 1);
      world.setBlock(xco + 42, yco + 16, zco + 60, Blocks.stone, 0, 1);
      world.setBlock(xco + 43, yco + 16, zco + 60, Blocks.stone, 0, 1);
      world.setBlock(xco + 44, yco + 16, zco + 60, Blocks.stone, 0, 1);
      world.setBlock(xco + 45, yco + 16, zco + 60, Blocks.stone, 0, 1);
      world.setBlock(xco + 18, yco + 16, zco + 61, Blocks.stone, 0, 1);
      world.setBlock(xco + 19, yco + 16, zco + 61, Blocks.stone, 0, 1);
      world.setBlock(xco + 20, yco + 16, zco + 61, Blocks.stone, 0, 1);
      world.setBlock(xco + 28, yco + 16, zco + 61, Blocks.stone, 0, 1);
      world.setBlock(xco + 32, yco + 16, zco + 61, Blocks.redstone_block, 0, 1);
      world.setBlock(xco + 39, yco + 16, zco + 61, Blocks.redstone_block, 0, 1);
      world.setBlock(xco + 41, yco + 16, zco + 61, Blocks.stone, 0, 1);
      world.setBlock(xco + 46, yco + 16, zco + 61, Blocks.stone, 0, 1);
      world.setBlock(xco + 18, yco + 16, zco + 62, Blocks.obsidian, 0, 1);
      world.setBlock(xco + 20, yco + 16, zco + 62, Blocks.stone, 0, 1);
      world.setBlock(xco + 28, yco + 16, zco + 62, Blocks.stone, 0, 1);
      world.setBlock(xco + 32, yco + 16, zco + 62, Blocks.redstone_block, 0, 1);
      world.setBlock(xco + 39, yco + 16, zco + 62, Blocks.redstone_block, 0, 1);
      world.setBlock(xco + 40, yco + 16, zco + 62, Blocks.stone, 0, 1);
      world.setBlock(xco + 47, yco + 16, zco + 62, Blocks.stone, 0, 1);
      world.setBlock(xco + 18, yco + 16, zco + 63, Blocks.obsidian, 0, 1);
      world.setBlock(xco + 20, yco + 16, zco + 63, Blocks.stone, 0, 1);
      world.setBlock(xco + 28, yco + 16, zco + 63, Blocks.stone, 0, 1);
      world.setBlock(xco + 32, yco + 16, zco + 63, Blocks.redstone_block, 0, 1);
      world.setBlock(xco + 39, yco + 16, zco + 63, Blocks.redstone_block, 0, 1);
      world.setBlock(xco + 40, yco + 16, zco + 63, Blocks.stone, 0, 1);
      world.setBlock(xco + 47, yco + 16, zco + 63, Blocks.stone, 0, 1);
      world.setBlock(xco + 18, yco + 16, zco + 64, Blocks.stone, 0, 1);
      world.setBlock(xco + 19, yco + 16, zco + 64, Blocks.stone, 0, 1);
      world.setBlock(xco + 28, yco + 16, zco + 64, Blocks.stone, 0, 1);
      world.setBlock(xco + 32, yco + 16, zco + 64, Blocks.redstone_block, 0, 1);
      world.setBlock(xco + 39, yco + 16, zco + 64, Blocks.redstone_block, 0, 1);
      world.setBlock(xco + 40, yco + 16, zco + 64, Blocks.stone, 0, 1);
      world.setBlock(xco + 47, yco + 16, zco + 64, Blocks.stone, 0, 1);
      world.setBlock(xco + 18, yco + 16, zco + 65, Blocks.stone, 0, 1);
      world.setBlock(xco + 19, yco + 16, zco + 65, Blocks.stone, 0, 1);
      world.setBlock(xco + 20, yco + 16, zco + 65, Blocks.stone, 0, 1);
      world.setBlock(xco + 21, yco + 16, zco + 65, Blocks.stone, 0, 1);
      world.setBlock(xco + 22, yco + 16, zco + 65, Blocks.stone, 0, 1);
      world.setBlock(xco + 23, yco + 16, zco + 65, Blocks.stone, 0, 1);
      world.setBlock(xco + 24, yco + 16, zco + 65, Blocks.stone, 0, 1);
return true;
  }
}
