package com.slugterra.world.greatForge;
import java.util.Random;

import net.minecraft.block.BlockColored;
import net.minecraft.block.BlockStairs;
import net.minecraft.block.BlockStaticLiquid;
import net.minecraft.init.Blocks;
import net.minecraft.util.math.BlockPos;
import net.minecraft.world.World;
public class GreatWesternForgeStructure7 {
public boolean generate(World world, Random par2Random, BlockPos pos) {
      world.setBlockState(pos.add(44, 8, 39), Blocks.DIAMOND_BLOCK.getDefaultState());
      world.setBlockState(pos.add(15, 8, 40), ((BlockColored)Blocks.STAINED_HARDENED_CLAY).getStateFromMeta(4));
      world.setBlockState(pos.add(20, 8, 40), ((BlockColored)Blocks.STAINED_HARDENED_CLAY).getStateFromMeta(4));
      world.setBlockState(pos.add(21, 8, 40), Blocks.QUARTZ_BLOCK.getDefaultState());
      world.setBlockState(pos.add(22, 8, 40), Blocks.QUARTZ_BLOCK.getDefaultState());
      world.setBlockState(pos.add(23, 8, 40), ((BlockStaticLiquid)Blocks.LAVA).getStateFromMeta(10));
      world.setBlockState(pos.add(29, 8, 40), ((BlockStaticLiquid)Blocks.LAVA).getStateFromMeta(10));
      world.setBlockState(pos.add(30, 8, 40), Blocks.QUARTZ_BLOCK.getDefaultState());
      world.setBlockState(pos.add(31, 8, 40), Blocks.QUARTZ_BLOCK.getDefaultState());
      world.setBlockState(pos.add(32, 8, 40), ((BlockColored)Blocks.STAINED_HARDENED_CLAY).getStateFromMeta(4));
      world.setBlockState(pos.add(36, 8, 40), ((BlockColored)Blocks.STAINED_HARDENED_CLAY).getStateFromMeta(4));
      world.setBlockState(pos.add(37, 8, 40), ((BlockColored)Blocks.STAINED_HARDENED_CLAY).getStateFromMeta(4));
      world.setBlockState(pos.add(38, 8, 40), ((BlockColored)Blocks.STAINED_HARDENED_CLAY).getStateFromMeta(4));
      world.setBlockState(pos.add(44, 8, 40), ((BlockColored)Blocks.STAINED_HARDENED_CLAY).getStateFromMeta(4));
      world.setBlockState(pos.add(5, 8, 41), Blocks.STONE.getDefaultState());
      world.setBlockState(pos.add(6, 8, 41), Blocks.STONE.getDefaultState());
      world.setBlockState(pos.add(7, 8, 41), Blocks.STONE.getDefaultState());
      world.setBlockState(pos.add(16, 8, 41), Blocks.QUARTZ_BLOCK.getDefaultState());
      world.setBlockState(pos.add(20, 8, 41), Blocks.QUARTZ_BLOCK.getDefaultState());
      world.setBlockState(pos.add(21, 8, 41), Blocks.QUARTZ_BLOCK.getDefaultState());
      world.setBlockState(pos.add(22, 8, 41), Blocks.QUARTZ_BLOCK.getDefaultState());
      world.setBlockState(pos.add(23, 8, 41), Blocks.STONE.getDefaultState());
      world.setBlockState(pos.add(29, 8, 41), Blocks.STONE.getDefaultState());
      world.setBlockState(pos.add(30, 8, 41), Blocks.QUARTZ_BLOCK.getDefaultState());
      world.setBlockState(pos.add(31, 8, 41), Blocks.QUARTZ_BLOCK.getDefaultState());
      world.setBlockState(pos.add(32, 8, 41), Blocks.QUARTZ_BLOCK.getDefaultState());
      world.setBlockState(pos.add(36, 8, 41), Blocks.QUARTZ_BLOCK.getDefaultState());
      world.setBlockState(pos.add(39, 8, 41), ((BlockColored)Blocks.STAINED_HARDENED_CLAY).getStateFromMeta(4));
      world.setBlockState(pos.add(43, 8, 41), Blocks.DIAMOND_BLOCK.getDefaultState());
      world.setBlockState(pos.add(4, 8, 42), Blocks.STONE.getDefaultState());
      world.setBlockState(pos.add(8, 8, 42), Blocks.STONE.getDefaultState());
      world.setBlockState(pos.add(16, 8, 42), Blocks.QUARTZ_BLOCK.getDefaultState());
      world.setBlockState(pos.add(20, 8, 42), Blocks.QUARTZ_BLOCK.getDefaultState());
      world.setBlockState(pos.add(21, 8, 42), Blocks.QUARTZ_BLOCK.getDefaultState());
      world.setBlockState(pos.add(22, 8, 42), Blocks.QUARTZ_BLOCK.getDefaultState());
      world.setBlockState(pos.add(23, 8, 42), Blocks.STONE.getDefaultState());
      world.setBlockState(pos.add(29, 8, 42), Blocks.STONE.getDefaultState());
      world.setBlockState(pos.add(30, 8, 42), Blocks.QUARTZ_BLOCK.getDefaultState());
      world.setBlockState(pos.add(31, 8, 42), Blocks.QUARTZ_BLOCK.getDefaultState());
      world.setBlockState(pos.add(32, 8, 42), Blocks.QUARTZ_BLOCK.getDefaultState());
      world.setBlockState(pos.add(36, 8, 42), Blocks.QUARTZ_BLOCK.getDefaultState());
      world.setBlockState(pos.add(40, 8, 42), Blocks.DIAMOND_BLOCK.getDefaultState());
      world.setBlockState(pos.add(41, 8, 42), ((BlockColored)Blocks.STAINED_HARDENED_CLAY).getStateFromMeta(4));
      world.setBlockState(pos.add(42, 8, 42), ((BlockColored)Blocks.STAINED_HARDENED_CLAY).getStateFromMeta(4));
      world.setBlockState(pos.add(4, 8, 43), Blocks.STONE.getDefaultState());
      world.setBlockState(pos.add(8, 8, 43), Blocks.STONE.getDefaultState());
      world.setBlockState(pos.add(15, 8, 43), ((BlockColored)Blocks.STAINED_HARDENED_CLAY).getStateFromMeta(4));
      world.setBlockState(pos.add(20, 8, 43), ((BlockColored)Blocks.STAINED_HARDENED_CLAY).getStateFromMeta(4));
      world.setBlockState(pos.add(21, 8, 43), Blocks.QUARTZ_BLOCK.getDefaultState());
      world.setBlockState(pos.add(22, 8, 43), Blocks.QUARTZ_BLOCK.getDefaultState());
      world.setBlockState(pos.add(23, 8, 43), ((BlockStaticLiquid)Blocks.LAVA).getStateFromMeta(10));
      world.setBlockState(pos.add(29, 8, 43), ((BlockStaticLiquid)Blocks.LAVA).getStateFromMeta(10));
      world.setBlockState(pos.add(30, 8, 43), Blocks.QUARTZ_BLOCK.getDefaultState());
      world.setBlockState(pos.add(31, 8, 43), Blocks.QUARTZ_BLOCK.getDefaultState());
      world.setBlockState(pos.add(32, 8, 43), ((BlockColored)Blocks.STAINED_HARDENED_CLAY).getStateFromMeta(4));
      world.setBlockState(pos.add(37, 8, 43), ((BlockColored)Blocks.STAINED_HARDENED_CLAY).getStateFromMeta(4));
      world.setBlockState(pos.add(4, 8, 44), Blocks.STONE.getDefaultState());
      world.setBlockState(pos.add(8, 8, 44), Blocks.STONE.getDefaultState());
      world.setBlockState(pos.add(15, 8, 44), ((BlockColored)Blocks.STAINED_HARDENED_CLAY).getStateFromMeta(4));
      world.setBlockState(pos.add(20, 8, 44), ((BlockColored)Blocks.STAINED_HARDENED_CLAY).getStateFromMeta(4));
      world.setBlockState(pos.add(21, 8, 44), Blocks.QUARTZ_BLOCK.getDefaultState());
      world.setBlockState(pos.add(22, 8, 44), Blocks.QUARTZ_BLOCK.getDefaultState());
      world.setBlockState(pos.add(30, 8, 44), Blocks.QUARTZ_BLOCK.getDefaultState());
      world.setBlockState(pos.add(31, 8, 44), Blocks.QUARTZ_BLOCK.getDefaultState());
      world.setBlockState(pos.add(32, 8, 44), ((BlockColored)Blocks.STAINED_HARDENED_CLAY).getStateFromMeta(4));
      world.setBlockState(pos.add(37, 8, 44), ((BlockColored)Blocks.STAINED_HARDENED_CLAY).getStateFromMeta(4));
      world.setBlockState(pos.add(5, 8, 45), Blocks.STONE.getDefaultState());
      world.setBlockState(pos.add(6, 8, 45), Blocks.STONE.getDefaultState());
      world.setBlockState(pos.add(7, 8, 45), Blocks.STONE.getDefaultState());
      world.setBlockState(pos.add(15, 8, 45), ((BlockColored)Blocks.STAINED_HARDENED_CLAY).getStateFromMeta(4));
      world.setBlockState(pos.add(20, 8, 45), ((BlockColored)Blocks.STAINED_HARDENED_CLAY).getStateFromMeta(4));
      world.setBlockState(pos.add(21, 8, 45), Blocks.QUARTZ_BLOCK.getDefaultState());
      world.setBlockState(pos.add(22, 8, 45), Blocks.QUARTZ_BLOCK.getDefaultState());
      world.setBlockState(pos.add(23, 8, 45), ((BlockStaticLiquid)Blocks.LAVA).getStateFromMeta(10));
      world.setBlockState(pos.add(29, 8, 45), ((BlockStaticLiquid)Blocks.LAVA).getStateFromMeta(10));
      world.setBlockState(pos.add(30, 8, 45), Blocks.QUARTZ_BLOCK.getDefaultState());
      world.setBlockState(pos.add(31, 8, 45), Blocks.QUARTZ_BLOCK.getDefaultState());
      world.setBlockState(pos.add(32, 8, 45), ((BlockColored)Blocks.STAINED_HARDENED_CLAY).getStateFromMeta(4));
      world.setBlockState(pos.add(37, 8, 45), ((BlockColored)Blocks.STAINED_HARDENED_CLAY).getStateFromMeta(4));
      world.setBlockState(pos.add(16, 8, 46), Blocks.QUARTZ_BLOCK.getDefaultState());
      world.setBlockState(pos.add(17, 8, 46), Blocks.QUARTZ_BLOCK.getDefaultState());
      world.setBlockState(pos.add(18, 8, 46), Blocks.QUARTZ_BLOCK.getDefaultState());
      world.setBlockState(pos.add(19, 8, 46), Blocks.QUARTZ_BLOCK.getDefaultState());
      world.setBlockState(pos.add(20, 8, 46), Blocks.QUARTZ_BLOCK.getDefaultState());
      world.setBlockState(pos.add(21, 8, 46), Blocks.QUARTZ_BLOCK.getDefaultState());
      world.setBlockState(pos.add(22, 8, 46), Blocks.QUARTZ_BLOCK.getDefaultState());
      world.setBlockState(pos.add(23, 8, 46), Blocks.STONE.getDefaultState());
      world.setBlockState(pos.add(29, 8, 46), Blocks.STONE.getDefaultState());
      world.setBlockState(pos.add(30, 8, 46), Blocks.QUARTZ_BLOCK.getDefaultState());
      world.setBlockState(pos.add(31, 8, 46), Blocks.QUARTZ_BLOCK.getDefaultState());
      world.setBlockState(pos.add(32, 8, 46), Blocks.QUARTZ_BLOCK.getDefaultState());
      world.setBlockState(pos.add(36, 8, 46), Blocks.QUARTZ_BLOCK.getDefaultState());
      world.setBlockState(pos.add(16, 8, 47), Blocks.QUARTZ_BLOCK.getDefaultState());
      world.setBlockState(pos.add(17, 8, 47), Blocks.QUARTZ_BLOCK.getDefaultState());
      world.setBlockState(pos.add(18, 8, 47), Blocks.QUARTZ_BLOCK.getDefaultState());
      world.setBlockState(pos.add(19, 8, 47), Blocks.QUARTZ_BLOCK.getDefaultState());
      world.setBlockState(pos.add(20, 8, 47), Blocks.QUARTZ_BLOCK.getDefaultState());
      world.setBlockState(pos.add(21, 8, 47), Blocks.QUARTZ_BLOCK.getDefaultState());
      world.setBlockState(pos.add(22, 8, 47), Blocks.QUARTZ_BLOCK.getDefaultState());
      world.setBlockState(pos.add(23, 8, 47), Blocks.STONE.getDefaultState());
      world.setBlockState(pos.add(29, 8, 47), Blocks.STONE.getDefaultState());
      world.setBlockState(pos.add(30, 8, 47), Blocks.QUARTZ_BLOCK.getDefaultState());
      world.setBlockState(pos.add(31, 8, 47), Blocks.QUARTZ_BLOCK.getDefaultState());
      world.setBlockState(pos.add(32, 8, 47), Blocks.QUARTZ_BLOCK.getDefaultState());
      world.setBlockState(pos.add(36, 8, 47), Blocks.QUARTZ_BLOCK.getDefaultState());
      world.setBlockState(pos.add(15, 8, 48), ((BlockColored)Blocks.STAINED_HARDENED_CLAY).getStateFromMeta(4));
      world.setBlockState(pos.add(20, 8, 48), ((BlockColored)Blocks.STAINED_HARDENED_CLAY).getStateFromMeta(4));
      world.setBlockState(pos.add(21, 8, 48), Blocks.QUARTZ_BLOCK.getDefaultState());
      world.setBlockState(pos.add(22, 8, 48), Blocks.QUARTZ_BLOCK.getDefaultState());
      world.setBlockState(pos.add(23, 8, 48), ((BlockStaticLiquid)Blocks.LAVA).getStateFromMeta(10));
      world.setBlockState(pos.add(29, 8, 48), ((BlockStaticLiquid)Blocks.LAVA).getStateFromMeta(10));
      world.setBlockState(pos.add(30, 8, 48), Blocks.QUARTZ_BLOCK.getDefaultState());
      world.setBlockState(pos.add(31, 8, 48), Blocks.QUARTZ_BLOCK.getDefaultState());
      world.setBlockState(pos.add(32, 8, 48), ((BlockColored)Blocks.STAINED_HARDENED_CLAY).getStateFromMeta(4));
      world.setBlockState(pos.add(37, 8, 48), ((BlockColored)Blocks.STAINED_HARDENED_CLAY).getStateFromMeta(4));
      world.setBlockState(pos.add(15, 8, 49), ((BlockColored)Blocks.STAINED_HARDENED_CLAY).getStateFromMeta(4));
      world.setBlockState(pos.add(20, 8, 49), ((BlockColored)Blocks.STAINED_HARDENED_CLAY).getStateFromMeta(4));
      world.setBlockState(pos.add(21, 8, 49), Blocks.QUARTZ_BLOCK.getDefaultState());
      world.setBlockState(pos.add(22, 8, 49), Blocks.QUARTZ_BLOCK.getDefaultState());
      world.setBlockState(pos.add(30, 8, 49), Blocks.QUARTZ_BLOCK.getDefaultState());
      world.setBlockState(pos.add(31, 8, 49), Blocks.QUARTZ_BLOCK.getDefaultState());
      world.setBlockState(pos.add(32, 8, 49), ((BlockColored)Blocks.STAINED_HARDENED_CLAY).getStateFromMeta(4));
      world.setBlockState(pos.add(37, 8, 49), ((BlockColored)Blocks.STAINED_HARDENED_CLAY).getStateFromMeta(4));
      world.setBlockState(pos.add(15, 8, 50), ((BlockColored)Blocks.STAINED_HARDENED_CLAY).getStateFromMeta(4));
      world.setBlockState(pos.add(16, 8, 50), ((BlockColored)Blocks.STAINED_HARDENED_CLAY).getStateFromMeta(4));
      world.setBlockState(pos.add(17, 8, 50), ((BlockColored)Blocks.STAINED_HARDENED_CLAY).getStateFromMeta(4));
      world.setBlockState(pos.add(18, 8, 50), ((BlockColored)Blocks.STAINED_HARDENED_CLAY).getStateFromMeta(4));
      world.setBlockState(pos.add(19, 8, 50), ((BlockColored)Blocks.STAINED_HARDENED_CLAY).getStateFromMeta(4));
      world.setBlockState(pos.add(20, 8, 50), ((BlockColored)Blocks.STAINED_HARDENED_CLAY).getStateFromMeta(4));
      world.setBlockState(pos.add(21, 8, 50), Blocks.QUARTZ_BLOCK.getDefaultState());
      world.setBlockState(pos.add(22, 8, 50), Blocks.QUARTZ_BLOCK.getDefaultState());
      world.setBlockState(pos.add(30, 8, 50), Blocks.QUARTZ_BLOCK.getDefaultState());
      world.setBlockState(pos.add(31, 8, 50), Blocks.QUARTZ_BLOCK.getDefaultState());
      world.setBlockState(pos.add(32, 8, 50), ((BlockColored)Blocks.STAINED_HARDENED_CLAY).getStateFromMeta(4));
      world.setBlockState(pos.add(33, 8, 50), ((BlockColored)Blocks.STAINED_HARDENED_CLAY).getStateFromMeta(4));
      world.setBlockState(pos.add(34, 8, 50), ((BlockColored)Blocks.STAINED_HARDENED_CLAY).getStateFromMeta(4));
      world.setBlockState(pos.add(35, 8, 50), ((BlockColored)Blocks.STAINED_HARDENED_CLAY).getStateFromMeta(4));
      world.setBlockState(pos.add(36, 8, 50), ((BlockColored)Blocks.STAINED_HARDENED_CLAY).getStateFromMeta(4));
      world.setBlockState(pos.add(37, 8, 50), ((BlockColored)Blocks.STAINED_HARDENED_CLAY).getStateFromMeta(4));
      world.setBlockState(pos.add(18, 8, 51), ((BlockColored)Blocks.STAINED_HARDENED_CLAY).getStateFromMeta(4));
      world.setBlockState(pos.add(19, 8, 51), ((BlockColored)Blocks.STAINED_HARDENED_CLAY).getStateFromMeta(4));
      world.setBlockState(pos.add(20, 8, 51), ((BlockColored)Blocks.STAINED_HARDENED_CLAY).getStateFromMeta(4));
      world.setBlockState(pos.add(21, 8, 51), ((BlockColored)Blocks.STAINED_HARDENED_CLAY).getStateFromMeta(4));
      world.setBlockState(pos.add(30, 8, 51), ((BlockColored)Blocks.STAINED_HARDENED_CLAY).getStateFromMeta(4));
      world.setBlockState(pos.add(31, 8, 51), ((BlockColored)Blocks.STAINED_HARDENED_CLAY).getStateFromMeta(4));
      world.setBlockState(pos.add(32, 8, 51), ((BlockColored)Blocks.STAINED_HARDENED_CLAY).getStateFromMeta(4));
      world.setBlockState(pos.add(33, 8, 51), ((BlockColored)Blocks.STAINED_HARDENED_CLAY).getStateFromMeta(4));
      world.setBlockState(pos.add(34, 8, 51), ((BlockColored)Blocks.STAINED_HARDENED_CLAY).getStateFromMeta(4));
      world.setBlockState(pos.add(17, 8, 52), ((BlockColored)Blocks.STAINED_HARDENED_CLAY).getStateFromMeta(4));
      world.setBlockState(pos.add(18, 8, 52), ((BlockColored)Blocks.STAINED_HARDENED_CLAY).getStateFromMeta(4));
      world.setBlockState(pos.add(22, 8, 52), ((BlockColored)Blocks.STAINED_HARDENED_CLAY).getStateFromMeta(4));
      world.setBlockState(pos.add(29, 8, 52), ((BlockColored)Blocks.STAINED_HARDENED_CLAY).getStateFromMeta(4));
      world.setBlockState(pos.add(30, 8, 52), ((BlockColored)Blocks.STAINED_HARDENED_CLAY).getStateFromMeta(4));
      world.setBlockState(pos.add(34, 8, 52), ((BlockColored)Blocks.STAINED_HARDENED_CLAY).getStateFromMeta(4));
      world.setBlockState(pos.add(35, 8, 52), ((BlockColored)Blocks.STAINED_HARDENED_CLAY).getStateFromMeta(4));
      world.setBlockState(pos.add(16, 8, 53), ((BlockColored)Blocks.STAINED_HARDENED_CLAY).getStateFromMeta(4));
      world.setBlockState(pos.add(17, 8, 53), ((BlockColored)Blocks.STAINED_HARDENED_CLAY).getStateFromMeta(4));
      world.setBlockState(pos.add(23, 8, 53), ((BlockColored)Blocks.STAINED_HARDENED_CLAY).getStateFromMeta(4));
      world.setBlockState(pos.add(24, 8, 53), ((BlockColored)Blocks.STAINED_HARDENED_CLAY).getStateFromMeta(4));
      world.setBlockState(pos.add(25, 8, 53), ((BlockStairs)Blocks.NETHER_BRICK_STAIRS).getStateFromMeta(2));
      world.setBlockState(pos.add(26, 8, 53), ((BlockStairs)Blocks.NETHER_BRICK_STAIRS).getStateFromMeta(2));
      world.setBlockState(pos.add(27, 8, 53), ((BlockStairs)Blocks.NETHER_BRICK_STAIRS).getStateFromMeta(2));
      world.setBlockState(pos.add(28, 8, 53), ((BlockColored)Blocks.STAINED_HARDENED_CLAY).getStateFromMeta(4));
      world.setBlockState(pos.add(29, 8, 53), ((BlockColored)Blocks.STAINED_HARDENED_CLAY).getStateFromMeta(4));
      world.setBlockState(pos.add(35, 8, 53), ((BlockColored)Blocks.STAINED_HARDENED_CLAY).getStateFromMeta(4));
      world.setBlockState(pos.add(36, 8, 53), ((BlockColored)Blocks.STAINED_HARDENED_CLAY).getStateFromMeta(4));
      world.setBlockState(pos.add(16, 8, 54), ((BlockColored)Blocks.STAINED_HARDENED_CLAY).getStateFromMeta(4));
      world.setBlockState(pos.add(17, 8, 54), ((BlockColored)Blocks.STAINED_HARDENED_CLAY).getStateFromMeta(4));
      world.setBlockState(pos.add(23, 8, 54), ((BlockColored)Blocks.STAINED_HARDENED_CLAY).getStateFromMeta(4));
      world.setBlockState(pos.add(24, 8, 54), ((BlockColored)Blocks.STAINED_HARDENED_CLAY).getStateFromMeta(4));
      world.setBlockState(pos.add(28, 8, 54), ((BlockColored)Blocks.STAINED_HARDENED_CLAY).getStateFromMeta(4));
      world.setBlockState(pos.add(29, 8, 54), ((BlockColored)Blocks.STAINED_HARDENED_CLAY).getStateFromMeta(4));
      world.setBlockState(pos.add(35, 8, 54), ((BlockColored)Blocks.STAINED_HARDENED_CLAY).getStateFromMeta(4));
      world.setBlockState(pos.add(36, 8, 54), ((BlockColored)Blocks.STAINED_HARDENED_CLAY).getStateFromMeta(4));
      world.setBlockState(pos.add(16, 8, 55), ((BlockColored)Blocks.STAINED_HARDENED_CLAY).getStateFromMeta(4));
      world.setBlockState(pos.add(17, 8, 55), ((BlockColored)Blocks.STAINED_HARDENED_CLAY).getStateFromMeta(4));
      world.setBlockState(pos.add(23, 8, 55), ((BlockColored)Blocks.STAINED_HARDENED_CLAY).getStateFromMeta(4));
      world.setBlockState(pos.add(24, 8, 55), ((BlockColored)Blocks.STAINED_HARDENED_CLAY).getStateFromMeta(4));
      world.setBlockState(pos.add(28, 8, 55), ((BlockColored)Blocks.STAINED_HARDENED_CLAY).getStateFromMeta(4));
      world.setBlockState(pos.add(29, 8, 55), ((BlockColored)Blocks.STAINED_HARDENED_CLAY).getStateFromMeta(4));
      world.setBlockState(pos.add(35, 8, 55), ((BlockColored)Blocks.STAINED_HARDENED_CLAY).getStateFromMeta(4));
      world.setBlockState(pos.add(36, 8, 55), ((BlockColored)Blocks.STAINED_HARDENED_CLAY).getStateFromMeta(4));
      world.setBlockState(pos.add(37, 8, 55), ((BlockColored)Blocks.STAINED_HARDENED_CLAY).getStateFromMeta(4));
      world.setBlockState(pos.add(17, 8, 56), ((BlockColored)Blocks.STAINED_HARDENED_CLAY).getStateFromMeta(4));
      world.setBlockState(pos.add(18, 8, 56), ((BlockColored)Blocks.STAINED_HARDENED_CLAY).getStateFromMeta(4));
      world.setBlockState(pos.add(22, 8, 56), ((BlockColored)Blocks.STAINED_HARDENED_CLAY).getStateFromMeta(4));
      world.setBlockState(pos.add(23, 8, 56), ((BlockColored)Blocks.STAINED_HARDENED_CLAY).getStateFromMeta(4));
      world.setBlockState(pos.add(29, 8, 56), ((BlockColored)Blocks.STAINED_HARDENED_CLAY).getStateFromMeta(4));
      world.setBlockState(pos.add(30, 8, 56), ((BlockColored)Blocks.STAINED_HARDENED_CLAY).getStateFromMeta(4));
      world.setBlockState(pos.add(34, 8, 56), ((BlockColored)Blocks.STAINED_HARDENED_CLAY).getStateFromMeta(4));
      world.setBlockState(pos.add(35, 8, 56), ((BlockColored)Blocks.STAINED_HARDENED_CLAY).getStateFromMeta(4));
      world.setBlockState(pos.add(38, 8, 56), ((BlockColored)Blocks.STAINED_HARDENED_CLAY).getStateFromMeta(4));
      world.setBlockState(pos.add(39, 8, 56), ((BlockColored)Blocks.WOOL).getStateFromMeta(15));
      world.setBlockState(pos.add(40, 8, 56), ((BlockColored)Blocks.WOOL).getStateFromMeta(15));
      world.setBlockState(pos.add(18, 8, 57), ((BlockColored)Blocks.STAINED_HARDENED_CLAY).getStateFromMeta(4));
      world.setBlockState(pos.add(19, 8, 57), ((BlockColored)Blocks.STAINED_HARDENED_CLAY).getStateFromMeta(4));
      world.setBlockState(pos.add(20, 8, 57), ((BlockColored)Blocks.STAINED_HARDENED_CLAY).getStateFromMeta(4));
      world.setBlockState(pos.add(21, 8, 57), ((BlockColored)Blocks.STAINED_HARDENED_CLAY).getStateFromMeta(4));
      world.setBlockState(pos.add(22, 8, 57), ((BlockColored)Blocks.STAINED_HARDENED_CLAY).getStateFromMeta(4));
      world.setBlockState(pos.add(23, 8, 57), Blocks.GLOWSTONE.getDefaultState());
      world.setBlockState(pos.add(29, 8, 57), Blocks.GLOWSTONE.getDefaultState());
      world.setBlockState(pos.add(30, 8, 57), ((BlockColored)Blocks.STAINED_HARDENED_CLAY).getStateFromMeta(4));
      world.setBlockState(pos.add(31, 8, 57), ((BlockColored)Blocks.STAINED_HARDENED_CLAY).getStateFromMeta(4));
      world.setBlockState(pos.add(32, 8, 57), ((BlockColored)Blocks.STAINED_HARDENED_CLAY).getStateFromMeta(4));
      world.setBlockState(pos.add(33, 8, 57), ((BlockColored)Blocks.STAINED_HARDENED_CLAY).getStateFromMeta(4));
      world.setBlockState(pos.add(34, 8, 57), ((BlockColored)Blocks.STAINED_HARDENED_CLAY).getStateFromMeta(4));
      world.setBlockState(pos.add(39, 8, 57), ((BlockColored)Blocks.STAINED_HARDENED_CLAY).getStateFromMeta(4));
      world.setBlockState(pos.add(41, 8, 57), ((BlockColored)Blocks.WOOL).getStateFromMeta(15));
      world.setBlockState(pos.add(19, 8, 58), ((BlockColored)Blocks.STAINED_HARDENED_CLAY).getStateFromMeta(4));
      world.setBlockState(pos.add(20, 8, 58), ((BlockColored)Blocks.STAINED_HARDENED_CLAY).getStateFromMeta(4));
      world.setBlockState(pos.add(21, 8, 58), ((BlockColored)Blocks.STAINED_HARDENED_CLAY).getStateFromMeta(4));
      world.setBlockState(pos.add(22, 8, 58), ((BlockColored)Blocks.STAINED_HARDENED_CLAY).getStateFromMeta(4));
      world.setBlockState(pos.add(23, 8, 58), ((BlockColored)Blocks.STAINED_HARDENED_CLAY).getStateFromMeta(4));
      world.setBlockState(pos.add(24, 8, 58), ((BlockColored)Blocks.STAINED_HARDENED_CLAY).getStateFromMeta(4));
      world.setBlockState(pos.add(25, 8, 58), ((BlockColored)Blocks.STAINED_HARDENED_CLAY).getStateFromMeta(4));
      world.setBlockState(pos.add(26, 8, 58), ((BlockColored)Blocks.STAINED_HARDENED_CLAY).getStateFromMeta(4));
      world.setBlockState(pos.add(27, 8, 58), ((BlockColored)Blocks.STAINED_HARDENED_CLAY).getStateFromMeta(4));
      world.setBlockState(pos.add(28, 8, 58), ((BlockColored)Blocks.STAINED_HARDENED_CLAY).getStateFromMeta(4));
      world.setBlockState(pos.add(29, 8, 58), ((BlockColored)Blocks.STAINED_HARDENED_CLAY).getStateFromMeta(4));
      world.setBlockState(pos.add(30, 8, 58), ((BlockColored)Blocks.STAINED_HARDENED_CLAY).getStateFromMeta(4));
      world.setBlockState(pos.add(31, 8, 58), ((BlockColored)Blocks.STAINED_HARDENED_CLAY).getStateFromMeta(4));
      world.setBlockState(pos.add(32, 8, 58), ((BlockColored)Blocks.STAINED_HARDENED_CLAY).getStateFromMeta(4));
      world.setBlockState(pos.add(33, 8, 58), ((BlockColored)Blocks.STAINED_HARDENED_CLAY).getStateFromMeta(4));
      world.setBlockState(pos.add(40, 8, 58), ((BlockColored)Blocks.STAINED_HARDENED_CLAY).getStateFromMeta(4));
      world.setBlockState(pos.add(42, 8, 58), ((BlockColored)Blocks.WOOL).getStateFromMeta(15));
      world.setBlockState(pos.add(34, 8, 59), ((BlockColored)Blocks.WOOL).getStateFromMeta(15));
      world.setBlockState(pos.add(35, 8, 59), ((BlockColored)Blocks.WOOL).getStateFromMeta(15));
      world.setBlockState(pos.add(36, 8, 59), ((BlockColored)Blocks.WOOL).getStateFromMeta(15));
      world.setBlockState(pos.add(37, 8, 59), ((BlockColored)Blocks.WOOL).getStateFromMeta(15));
      world.setBlockState(pos.add(41, 8, 59), ((BlockColored)Blocks.STAINED_HARDENED_CLAY).getStateFromMeta(4));
      world.setBlockState(pos.add(42, 8, 59), ((BlockColored)Blocks.WOOL).getStateFromMeta(15));
      world.setBlockState(pos.add(33, 8, 60), ((BlockColored)Blocks.WOOL).getStateFromMeta(15));
      world.setBlockState(pos.add(38, 8, 60), ((BlockColored)Blocks.WOOL).getStateFromMeta(15));
      world.setBlockState(pos.add(42, 8, 60), Blocks.STONE.getDefaultState());
      world.setBlockState(pos.add(43, 8, 60), Blocks.STONE.getDefaultState());
      world.setBlockState(pos.add(44, 8, 60), Blocks.STONE.getDefaultState());
      world.setBlockState(pos.add(45, 8, 60), Blocks.STONE.getDefaultState());
      world.setBlockState(pos.add(32, 8, 61), ((BlockColored)Blocks.WOOL).getStateFromMeta(15));
      world.setBlockState(pos.add(39, 8, 61), ((BlockColored)Blocks.WOOL).getStateFromMeta(15));
      world.setBlockState(pos.add(41, 8, 61), Blocks.STONE.getDefaultState());
      world.setBlockState(pos.add(46, 8, 61), Blocks.STONE.getDefaultState());
      world.setBlockState(pos.add(32, 8, 62), ((BlockColored)Blocks.WOOL).getStateFromMeta(15));
      world.setBlockState(pos.add(39, 8, 62), ((BlockColored)Blocks.WOOL).getStateFromMeta(15));
      world.setBlockState(pos.add(40, 8, 62), Blocks.STONE.getDefaultState());
      world.setBlockState(pos.add(47, 8, 62), Blocks.STONE.getDefaultState());
      world.setBlockState(pos.add(19, 8, 63), Blocks.OBSIDIAN.getDefaultState());
      world.setBlockState(pos.add(32, 8, 63), ((BlockColored)Blocks.WOOL).getStateFromMeta(15));
      world.setBlockState(pos.add(39, 8, 63), ((BlockColored)Blocks.WOOL).getStateFromMeta(15));
      world.setBlockState(pos.add(40, 8, 63), Blocks.STONE.getDefaultState());
      world.setBlockState(pos.add(47, 8, 63), Blocks.STONE.getDefaultState());
      world.setBlockState(pos.add(19, 8, 64), Blocks.OBSIDIAN.getDefaultState());
      world.setBlockState(pos.add(32, 8, 64), ((BlockColored)Blocks.WOOL).getStateFromMeta(15));
      world.setBlockState(pos.add(39, 8, 64), ((BlockColored)Blocks.WOOL).getStateFromMeta(15));
      world.setBlockState(pos.add(40, 8, 64), Blocks.STONE.getDefaultState());
      world.setBlockState(pos.add(47, 8, 64), Blocks.STONE.getDefaultState());
      world.setBlockState(pos.add(23, 8, 65), Blocks.OBSIDIAN.getDefaultState());
      world.setBlockState(pos.add(24, 8, 65), Blocks.OBSIDIAN.getDefaultState());
      world.setBlockState(pos.add(33, 8, 65), ((BlockColored)Blocks.WOOL).getStateFromMeta(15));
      world.setBlockState(pos.add(38, 8, 65), ((BlockColored)Blocks.WOOL).getStateFromMeta(15));
      world.setBlockState(pos.add(40, 8, 65), Blocks.STONE.getDefaultState());
      world.setBlockState(pos.add(47, 8, 65), Blocks.STONE.getDefaultState());
      world.setBlockState(pos.add(34, 8, 66), ((BlockColored)Blocks.WOOL).getStateFromMeta(15));
      world.setBlockState(pos.add(35, 8, 66), ((BlockColored)Blocks.WOOL).getStateFromMeta(15));
      world.setBlockState(pos.add(36, 8, 66), ((BlockColored)Blocks.WOOL).getStateFromMeta(15));
      world.setBlockState(pos.add(37, 8, 66), ((BlockColored)Blocks.WOOL).getStateFromMeta(15));
      world.setBlockState(pos.add(41, 8, 66), Blocks.STONE.getDefaultState());
      world.setBlockState(pos.add(46, 8, 66), Blocks.STONE.getDefaultState());
      world.setBlockState(pos.add(42, 8, 67), Blocks.STONE.getDefaultState());
      world.setBlockState(pos.add(43, 8, 67), Blocks.STONE.getDefaultState());
      world.setBlockState(pos.add(44, 8, 67), Blocks.STONE.getDefaultState());
      world.setBlockState(pos.add(45, 8, 67), Blocks.STONE.getDefaultState());
      world.setBlockState(pos.add(23, 9, 36), ((BlockStairs)Blocks.QUARTZ_STAIRS).getStateFromMeta(2));
      world.setBlockState(pos.add(24, 9, 36), Blocks.QUARTZ_BLOCK.getDefaultState());
      world.setBlockState(pos.add(25, 9, 36), ((BlockColored)Blocks.STAINED_HARDENED_CLAY).getStateFromMeta(10));
      world.setBlockState(pos.add(27, 9, 36), ((BlockColored)Blocks.STAINED_HARDENED_CLAY).getStateFromMeta(10));
      world.setBlockState(pos.add(28, 9, 36), Blocks.QUARTZ_BLOCK.getDefaultState());
      world.setBlockState(pos.add(29, 9, 36), ((BlockStairs)Blocks.QUARTZ_STAIRS).getStateFromMeta(2));
      world.setBlockState(pos.add(41, 9, 36), ((BlockColored)Blocks.STAINED_HARDENED_CLAY).getStateFromMeta(4));
      world.setBlockState(pos.add(15, 9, 37), ((BlockColored)Blocks.STAINED_HARDENED_CLAY).getStateFromMeta(4));
      world.setBlockState(pos.add(16, 9, 37), ((BlockColored)Blocks.STAINED_HARDENED_CLAY).getStateFromMeta(4));
      world.setBlockState(pos.add(21, 9, 37), Blocks.QUARTZ_BLOCK.getDefaultState());
      world.setBlockState(pos.add(22, 9, 37), Blocks.QUARTZ_BLOCK.getDefaultState());
      world.setBlockState(pos.add(23, 9, 37), ((BlockColored)Blocks.STAINED_HARDENED_CLAY).getStateFromMeta(4));
      world.setBlockState(pos.add(29, 9, 37), ((BlockColored)Blocks.STAINED_HARDENED_CLAY).getStateFromMeta(4));
      world.setBlockState(pos.add(36, 9, 37), ((BlockColored)Blocks.STAINED_HARDENED_CLAY).getStateFromMeta(4));
      world.setBlockState(pos.add(37, 9, 37), ((BlockColored)Blocks.STAINED_HARDENED_CLAY).getStateFromMeta(4));
      world.setBlockState(pos.add(40, 9, 37), ((BlockColored)Blocks.STAINED_HARDENED_CLAY).getStateFromMeta(4));
      world.setBlockState(pos.add(41, 9, 37), ((BlockColored)Blocks.STAINED_HARDENED_CLAY).getStateFromMeta(4));
      world.setBlockState(pos.add(42, 9, 37), ((BlockColored)Blocks.STAINED_HARDENED_CLAY).getStateFromMeta(4));
      world.setBlockState(pos.add(15, 9, 38), ((BlockColored)Blocks.STAINED_HARDENED_CLAY).getStateFromMeta(4));
      world.setBlockState(pos.add(16, 9, 38), ((BlockColored)Blocks.STAINED_HARDENED_CLAY).getStateFromMeta(4));
      world.setBlockState(pos.add(17, 9, 38), ((BlockColored)Blocks.STAINED_HARDENED_CLAY).getStateFromMeta(7));
      world.setBlockState(pos.add(18, 9, 38), ((BlockColored)Blocks.STAINED_HARDENED_CLAY).getStateFromMeta(7));
      world.setBlockState(pos.add(19, 9, 38), ((BlockColored)Blocks.STAINED_HARDENED_CLAY).getStateFromMeta(7));
      world.setBlockState(pos.add(20, 9, 38), ((BlockColored)Blocks.STAINED_HARDENED_CLAY).getStateFromMeta(7));
      world.setBlockState(pos.add(21, 9, 38), Blocks.QUARTZ_BLOCK.getDefaultState());
      world.setBlockState(pos.add(22, 9, 38), Blocks.QUARTZ_BLOCK.getDefaultState());
      world.setBlockState(pos.add(30, 9, 38), Blocks.QUARTZ_BLOCK.getDefaultState());
      world.setBlockState(pos.add(31, 9, 38), Blocks.QUARTZ_BLOCK.getDefaultState());
      world.setBlockState(pos.add(32, 9, 38), ((BlockColored)Blocks.STAINED_HARDENED_CLAY).getStateFromMeta(7));
      world.setBlockState(pos.add(33, 9, 38), ((BlockColored)Blocks.STAINED_HARDENED_CLAY).getStateFromMeta(7));
      world.setBlockState(pos.add(34, 9, 38), ((BlockColored)Blocks.STAINED_HARDENED_CLAY).getStateFromMeta(7));
      world.setBlockState(pos.add(35, 9, 38), ((BlockColored)Blocks.STAINED_HARDENED_CLAY).getStateFromMeta(7));
      world.setBlockState(pos.add(36, 9, 38), ((BlockColored)Blocks.STAINED_HARDENED_CLAY).getStateFromMeta(4));
      world.setBlockState(pos.add(37, 9, 38), ((BlockColored)Blocks.STAINED_HARDENED_CLAY).getStateFromMeta(4));
      world.setBlockState(pos.add(39, 9, 38), ((BlockColored)Blocks.STAINED_HARDENED_CLAY).getStateFromMeta(4));
      world.setBlockState(pos.add(43, 9, 38), ((BlockColored)Blocks.STAINED_HARDENED_CLAY).getStateFromMeta(4));
      world.setBlockState(pos.add(15, 9, 39), ((BlockColored)Blocks.STAINED_HARDENED_CLAY).getStateFromMeta(4));
      world.setBlockState(pos.add(20, 9, 39), ((BlockColored)Blocks.STAINED_HARDENED_CLAY).getStateFromMeta(4));
      world.setBlockState(pos.add(21, 9, 39), Blocks.QUARTZ_BLOCK.getDefaultState());
      world.setBlockState(pos.add(22, 9, 39), Blocks.QUARTZ_BLOCK.getDefaultState());
      world.setBlockState(pos.add(30, 9, 39), Blocks.QUARTZ_BLOCK.getDefaultState());
      world.setBlockState(pos.add(31, 9, 39), Blocks.QUARTZ_BLOCK.getDefaultState());
      world.setBlockState(pos.add(32, 9, 39), ((BlockColored)Blocks.STAINED_HARDENED_CLAY).getStateFromMeta(4));
      world.setBlockState(pos.add(37, 9, 39), ((BlockColored)Blocks.STAINED_HARDENED_CLAY).getStateFromMeta(4));
      world.setBlockState(pos.add(39, 9, 39), ((BlockColored)Blocks.STAINED_HARDENED_CLAY).getStateFromMeta(4));
      world.setBlockState(pos.add(43, 9, 39), ((BlockColored)Blocks.STAINED_HARDENED_CLAY).getStateFromMeta(4));
      world.setBlockState(pos.add(15, 9, 40), ((BlockColored)Blocks.STAINED_HARDENED_CLAY).getStateFromMeta(4));
      world.setBlockState(pos.add(20, 9, 40), ((BlockColored)Blocks.STAINED_HARDENED_CLAY).getStateFromMeta(4));
      world.setBlockState(pos.add(21, 9, 40), Blocks.QUARTZ_BLOCK.getDefaultState());
      world.setBlockState(pos.add(22, 9, 40), Blocks.QUARTZ_BLOCK.getDefaultState());
      world.setBlockState(pos.add(23, 9, 40), ((BlockStaticLiquid)Blocks.LAVA).getStateFromMeta(10));
      world.setBlockState(pos.add(29, 9, 40), ((BlockStaticLiquid)Blocks.LAVA).getStateFromMeta(10));
      world.setBlockState(pos.add(30, 9, 40), Blocks.QUARTZ_BLOCK.getDefaultState());
      world.setBlockState(pos.add(31, 9, 40), Blocks.QUARTZ_BLOCK.getDefaultState());
      world.setBlockState(pos.add(32, 9, 40), ((BlockColored)Blocks.STAINED_HARDENED_CLAY).getStateFromMeta(4));
      world.setBlockState(pos.add(36, 9, 40), ((BlockColored)Blocks.STAINED_HARDENED_CLAY).getStateFromMeta(4));
      world.setBlockState(pos.add(37, 9, 40), ((BlockColored)Blocks.STAINED_HARDENED_CLAY).getStateFromMeta(4));
      world.setBlockState(pos.add(39, 9, 40), ((BlockColored)Blocks.STAINED_HARDENED_CLAY).getStateFromMeta(4));
      world.setBlockState(pos.add(43, 9, 40), ((BlockColored)Blocks.STAINED_HARDENED_CLAY).getStateFromMeta(4));
      world.setBlockState(pos.add(5, 9, 41), Blocks.STONE.getDefaultState());
      world.setBlockState(pos.add(6, 9, 41), Blocks.STONE.getDefaultState());
      world.setBlockState(pos.add(7, 9, 41), Blocks.STONE.getDefaultState());
      world.setBlockState(pos.add(16, 9, 41), Blocks.QUARTZ_BLOCK.getDefaultState());
      world.setBlockState(pos.add(20, 9, 41), Blocks.QUARTZ_BLOCK.getDefaultState());
      world.setBlockState(pos.add(21, 9, 41), Blocks.QUARTZ_BLOCK.getDefaultState());
      world.setBlockState(pos.add(22, 9, 41), Blocks.QUARTZ_BLOCK.getDefaultState());
      world.setBlockState(pos.add(23, 9, 41), Blocks.STONE.getDefaultState());
      world.setBlockState(pos.add(29, 9, 41), Blocks.STONE.getDefaultState());
      world.setBlockState(pos.add(30, 9, 41), Blocks.QUARTZ_BLOCK.getDefaultState());
      world.setBlockState(pos.add(31, 9, 41), Blocks.QUARTZ_BLOCK.getDefaultState());
      world.setBlockState(pos.add(32, 9, 41), Blocks.QUARTZ_BLOCK.getDefaultState());
      world.setBlockState(pos.add(36, 9, 41), Blocks.QUARTZ_BLOCK.getDefaultState());
      world.setBlockState(pos.add(40, 9, 41), ((BlockColored)Blocks.STAINED_HARDENED_CLAY).getStateFromMeta(4));
      world.setBlockState(pos.add(41, 9, 41), ((BlockColored)Blocks.STAINED_HARDENED_CLAY).getStateFromMeta(4));
      world.setBlockState(pos.add(42, 9, 41), ((BlockColored)Blocks.STAINED_HARDENED_CLAY).getStateFromMeta(4));
      world.setBlockState(pos.add(4, 9, 42), Blocks.STONE.getDefaultState());
      world.setBlockState(pos.add(8, 9, 42), Blocks.STONE.getDefaultState());
      world.setBlockState(pos.add(16, 9, 42), Blocks.QUARTZ_BLOCK.getDefaultState());
      world.setBlockState(pos.add(20, 9, 42), Blocks.QUARTZ_BLOCK.getDefaultState());
      world.setBlockState(pos.add(21, 9, 42), Blocks.QUARTZ_BLOCK.getDefaultState());
      world.setBlockState(pos.add(22, 9, 42), Blocks.QUARTZ_BLOCK.getDefaultState());
      world.setBlockState(pos.add(23, 9, 42), Blocks.STONE.getDefaultState());
      world.setBlockState(pos.add(29, 9, 42), Blocks.STONE.getDefaultState());
      world.setBlockState(pos.add(30, 9, 42), Blocks.QUARTZ_BLOCK.getDefaultState());
      world.setBlockState(pos.add(31, 9, 42), Blocks.QUARTZ_BLOCK.getDefaultState());
      world.setBlockState(pos.add(32, 9, 42), Blocks.QUARTZ_BLOCK.getDefaultState());
      world.setBlockState(pos.add(36, 9, 42), Blocks.QUARTZ_BLOCK.getDefaultState());
      world.setBlockState(pos.add(4, 9, 43), Blocks.STONE.getDefaultState());
      world.setBlockState(pos.add(8, 9, 43), Blocks.STONE.getDefaultState());
      world.setBlockState(pos.add(15, 9, 43), ((BlockColored)Blocks.STAINED_HARDENED_CLAY).getStateFromMeta(4));
      world.setBlockState(pos.add(20, 9, 43), ((BlockColored)Blocks.STAINED_HARDENED_CLAY).getStateFromMeta(4));
      world.setBlockState(pos.add(21, 9, 43), Blocks.QUARTZ_BLOCK.getDefaultState());
      world.setBlockState(pos.add(22, 9, 43), Blocks.QUARTZ_BLOCK.getDefaultState());
      world.setBlockState(pos.add(23, 9, 43), ((BlockStaticLiquid)Blocks.LAVA).getStateFromMeta(10));
      world.setBlockState(pos.add(29, 9, 43), ((BlockStaticLiquid)Blocks.LAVA).getStateFromMeta(10));
      world.setBlockState(pos.add(30, 9, 43), Blocks.QUARTZ_BLOCK.getDefaultState());
      world.setBlockState(pos.add(31, 9, 43), Blocks.QUARTZ_BLOCK.getDefaultState());
      world.setBlockState(pos.add(32, 9, 43), ((BlockColored)Blocks.STAINED_HARDENED_CLAY).getStateFromMeta(4));
      world.setBlockState(pos.add(37, 9, 43), ((BlockColored)Blocks.STAINED_HARDENED_CLAY).getStateFromMeta(4));
      world.setBlockState(pos.add(4, 9, 44), Blocks.STONE.getDefaultState());
      world.setBlockState(pos.add(8, 9, 44), Blocks.STONE.getDefaultState());
      world.setBlockState(pos.add(15, 9, 44), ((BlockColored)Blocks.STAINED_HARDENED_CLAY).getStateFromMeta(4));
      world.setBlockState(pos.add(20, 9, 44), ((BlockColored)Blocks.STAINED_HARDENED_CLAY).getStateFromMeta(4));
      world.setBlockState(pos.add(21, 9, 44), Blocks.QUARTZ_BLOCK.getDefaultState());
      world.setBlockState(pos.add(22, 9, 44), Blocks.QUARTZ_BLOCK.getDefaultState());
      world.setBlockState(pos.add(30, 9, 44), Blocks.QUARTZ_BLOCK.getDefaultState());
      world.setBlockState(pos.add(31, 9, 44), Blocks.QUARTZ_BLOCK.getDefaultState());
      world.setBlockState(pos.add(32, 9, 44), ((BlockColored)Blocks.STAINED_HARDENED_CLAY).getStateFromMeta(4));
      world.setBlockState(pos.add(37, 9, 44), ((BlockColored)Blocks.STAINED_HARDENED_CLAY).getStateFromMeta(4));
      world.setBlockState(pos.add(5, 9, 45), Blocks.STONE.getDefaultState());
      world.setBlockState(pos.add(6, 9, 45), Blocks.STONE.getDefaultState());
      world.setBlockState(pos.add(7, 9, 45), Blocks.STONE.getDefaultState());
      world.setBlockState(pos.add(15, 9, 45), ((BlockColored)Blocks.STAINED_HARDENED_CLAY).getStateFromMeta(4));
      world.setBlockState(pos.add(20, 9, 45), ((BlockColored)Blocks.STAINED_HARDENED_CLAY).getStateFromMeta(4));
      world.setBlockState(pos.add(21, 9, 45), Blocks.QUARTZ_BLOCK.getDefaultState());
      world.setBlockState(pos.add(22, 9, 45), Blocks.QUARTZ_BLOCK.getDefaultState());
      world.setBlockState(pos.add(23, 9, 45), ((BlockStaticLiquid)Blocks.LAVA).getStateFromMeta(10));
      world.setBlockState(pos.add(29, 9, 45), ((BlockStaticLiquid)Blocks.LAVA).getStateFromMeta(10));
      world.setBlockState(pos.add(30, 9, 45), Blocks.QUARTZ_BLOCK.getDefaultState());
      world.setBlockState(pos.add(31, 9, 45), Blocks.QUARTZ_BLOCK.getDefaultState());
      world.setBlockState(pos.add(32, 9, 45), ((BlockColored)Blocks.STAINED_HARDENED_CLAY).getStateFromMeta(4));
      world.setBlockState(pos.add(37, 9, 45), ((BlockColored)Blocks.STAINED_HARDENED_CLAY).getStateFromMeta(4));
      world.setBlockState(pos.add(16, 9, 46), Blocks.QUARTZ_BLOCK.getDefaultState());
      world.setBlockState(pos.add(17, 9, 46), Blocks.QUARTZ_BLOCK.getDefaultState());
      world.setBlockState(pos.add(18, 9, 46), Blocks.QUARTZ_BLOCK.getDefaultState());
      world.setBlockState(pos.add(19, 9, 46), Blocks.QUARTZ_BLOCK.getDefaultState());
      world.setBlockState(pos.add(20, 9, 46), Blocks.QUARTZ_BLOCK.getDefaultState());
      world.setBlockState(pos.add(21, 9, 46), Blocks.QUARTZ_BLOCK.getDefaultState());
      world.setBlockState(pos.add(22, 9, 46), Blocks.QUARTZ_BLOCK.getDefaultState());
      world.setBlockState(pos.add(23, 9, 46), Blocks.STONE.getDefaultState());
      world.setBlockState(pos.add(29, 9, 46), Blocks.STONE.getDefaultState());
      world.setBlockState(pos.add(30, 9, 46), Blocks.QUARTZ_BLOCK.getDefaultState());
      world.setBlockState(pos.add(31, 9, 46), Blocks.QUARTZ_BLOCK.getDefaultState());
      world.setBlockState(pos.add(32, 9, 46), Blocks.QUARTZ_BLOCK.getDefaultState());
      world.setBlockState(pos.add(36, 9, 46), Blocks.QUARTZ_BLOCK.getDefaultState());
      world.setBlockState(pos.add(16, 9, 47), Blocks.QUARTZ_BLOCK.getDefaultState());
      world.setBlockState(pos.add(17, 9, 47), Blocks.QUARTZ_BLOCK.getDefaultState());
      world.setBlockState(pos.add(18, 9, 47), Blocks.QUARTZ_BLOCK.getDefaultState());
      world.setBlockState(pos.add(19, 9, 47), Blocks.QUARTZ_BLOCK.getDefaultState());
      world.setBlockState(pos.add(20, 9, 47), Blocks.QUARTZ_BLOCK.getDefaultState());
      world.setBlockState(pos.add(21, 9, 47), Blocks.QUARTZ_BLOCK.getDefaultState());
      world.setBlockState(pos.add(22, 9, 47), Blocks.QUARTZ_BLOCK.getDefaultState());
      world.setBlockState(pos.add(23, 9, 47), Blocks.STONE.getDefaultState());
      world.setBlockState(pos.add(29, 9, 47), Blocks.STONE.getDefaultState());
      world.setBlockState(pos.add(30, 9, 47), Blocks.QUARTZ_BLOCK.getDefaultState());
      world.setBlockState(pos.add(31, 9, 47), Blocks.QUARTZ_BLOCK.getDefaultState());
      world.setBlockState(pos.add(32, 9, 47), Blocks.QUARTZ_BLOCK.getDefaultState());
      world.setBlockState(pos.add(36, 9, 47), Blocks.QUARTZ_BLOCK.getDefaultState());
      world.setBlockState(pos.add(15, 9, 48), ((BlockColored)Blocks.STAINED_HARDENED_CLAY).getStateFromMeta(4));
      world.setBlockState(pos.add(20, 9, 48), ((BlockColored)Blocks.STAINED_HARDENED_CLAY).getStateFromMeta(4));
      world.setBlockState(pos.add(21, 9, 48), Blocks.QUARTZ_BLOCK.getDefaultState());
      world.setBlockState(pos.add(22, 9, 48), Blocks.QUARTZ_BLOCK.getDefaultState());
      world.setBlockState(pos.add(23, 9, 48), ((BlockStaticLiquid)Blocks.LAVA).getStateFromMeta(10));
      world.setBlockState(pos.add(29, 9, 48), ((BlockStaticLiquid)Blocks.LAVA).getStateFromMeta(10));
      world.setBlockState(pos.add(30, 9, 48), Blocks.QUARTZ_BLOCK.getDefaultState());
      world.setBlockState(pos.add(31, 9, 48), Blocks.QUARTZ_BLOCK.getDefaultState());
      world.setBlockState(pos.add(32, 9, 48), ((BlockColored)Blocks.STAINED_HARDENED_CLAY).getStateFromMeta(4));
      world.setBlockState(pos.add(37, 9, 48), ((BlockColored)Blocks.STAINED_HARDENED_CLAY).getStateFromMeta(4));
      world.setBlockState(pos.add(15, 9, 49), ((BlockColored)Blocks.STAINED_HARDENED_CLAY).getStateFromMeta(4));
      world.setBlockState(pos.add(20, 9, 49), ((BlockColored)Blocks.STAINED_HARDENED_CLAY).getStateFromMeta(4));
      world.setBlockState(pos.add(21, 9, 49), Blocks.QUARTZ_BLOCK.getDefaultState());
      world.setBlockState(pos.add(22, 9, 49), Blocks.QUARTZ_BLOCK.getDefaultState());
      world.setBlockState(pos.add(30, 9, 49), Blocks.QUARTZ_BLOCK.getDefaultState());
      world.setBlockState(pos.add(31, 9, 49), Blocks.QUARTZ_BLOCK.getDefaultState());
      world.setBlockState(pos.add(32, 9, 49), ((BlockColored)Blocks.STAINED_HARDENED_CLAY).getStateFromMeta(4));
      world.setBlockState(pos.add(37, 9, 49), ((BlockColored)Blocks.STAINED_HARDENED_CLAY).getStateFromMeta(4));
      world.setBlockState(pos.add(15, 9, 50), ((BlockColored)Blocks.STAINED_HARDENED_CLAY).getStateFromMeta(4));
      world.setBlockState(pos.add(16, 9, 50), ((BlockColored)Blocks.STAINED_HARDENED_CLAY).getStateFromMeta(4));
      world.setBlockState(pos.add(17, 9, 50), ((BlockColored)Blocks.STAINED_HARDENED_CLAY).getStateFromMeta(4));
      world.setBlockState(pos.add(18, 9, 50), ((BlockColored)Blocks.STAINED_HARDENED_CLAY).getStateFromMeta(4));
      world.setBlockState(pos.add(19, 9, 50), ((BlockColored)Blocks.STAINED_HARDENED_CLAY).getStateFromMeta(4));
      world.setBlockState(pos.add(20, 9, 50), ((BlockColored)Blocks.STAINED_HARDENED_CLAY).getStateFromMeta(4));
      world.setBlockState(pos.add(21, 9, 50), Blocks.QUARTZ_BLOCK.getDefaultState());
      world.setBlockState(pos.add(22, 9, 50), Blocks.QUARTZ_BLOCK.getDefaultState());
      world.setBlockState(pos.add(30, 9, 50), Blocks.QUARTZ_BLOCK.getDefaultState());
      world.setBlockState(pos.add(31, 9, 50), Blocks.QUARTZ_BLOCK.getDefaultState());
      world.setBlockState(pos.add(32, 9, 50), ((BlockColored)Blocks.STAINED_HARDENED_CLAY).getStateFromMeta(4));
      world.setBlockState(pos.add(33, 9, 50), ((BlockColored)Blocks.STAINED_HARDENED_CLAY).getStateFromMeta(4));
      world.setBlockState(pos.add(34, 9, 50), ((BlockColored)Blocks.STAINED_HARDENED_CLAY).getStateFromMeta(4));
      world.setBlockState(pos.add(35, 9, 50), ((BlockColored)Blocks.STAINED_HARDENED_CLAY).getStateFromMeta(4));
      world.setBlockState(pos.add(36, 9, 50), ((BlockColored)Blocks.STAINED_HARDENED_CLAY).getStateFromMeta(4));
      world.setBlockState(pos.add(37, 9, 50), ((BlockColored)Blocks.STAINED_HARDENED_CLAY).getStateFromMeta(4));
      world.setBlockState(pos.add(18, 9, 51), ((BlockColored)Blocks.STAINED_HARDENED_CLAY).getStateFromMeta(4));
      world.setBlockState(pos.add(19, 9, 51), ((BlockColored)Blocks.STAINED_HARDENED_CLAY).getStateFromMeta(4));
      world.setBlockState(pos.add(20, 9, 51), ((BlockColored)Blocks.STAINED_HARDENED_CLAY).getStateFromMeta(4));
      world.setBlockState(pos.add(21, 9, 51), ((BlockColored)Blocks.STAINED_HARDENED_CLAY).getStateFromMeta(4));
      world.setBlockState(pos.add(30, 9, 51), ((BlockColored)Blocks.STAINED_HARDENED_CLAY).getStateFromMeta(4));
      world.setBlockState(pos.add(31, 9, 51), ((BlockColored)Blocks.STAINED_HARDENED_CLAY).getStateFromMeta(4));
      world.setBlockState(pos.add(32, 9, 51), ((BlockColored)Blocks.STAINED_HARDENED_CLAY).getStateFromMeta(4));
      world.setBlockState(pos.add(33, 9, 51), ((BlockColored)Blocks.STAINED_HARDENED_CLAY).getStateFromMeta(4));
      world.setBlockState(pos.add(34, 9, 51), ((BlockColored)Blocks.STAINED_HARDENED_CLAY).getStateFromMeta(4));
      world.setBlockState(pos.add(17, 9, 52), ((BlockColored)Blocks.STAINED_HARDENED_CLAY).getStateFromMeta(4));
      world.setBlockState(pos.add(18, 9, 52), ((BlockColored)Blocks.STAINED_HARDENED_CLAY).getStateFromMeta(4));
      world.setBlockState(pos.add(22, 9, 52), ((BlockColored)Blocks.STAINED_HARDENED_CLAY).getStateFromMeta(4));
      world.setBlockState(pos.add(29, 9, 52), ((BlockColored)Blocks.STAINED_HARDENED_CLAY).getStateFromMeta(4));
      world.setBlockState(pos.add(30, 9, 52), ((BlockColored)Blocks.STAINED_HARDENED_CLAY).getStateFromMeta(4));
      world.setBlockState(pos.add(34, 9, 52), ((BlockColored)Blocks.STAINED_HARDENED_CLAY).getStateFromMeta(4));
      world.setBlockState(pos.add(35, 9, 52), ((BlockColored)Blocks.STAINED_HARDENED_CLAY).getStateFromMeta(4));
      world.setBlockState(pos.add(16, 9, 53), ((BlockColored)Blocks.STAINED_HARDENED_CLAY).getStateFromMeta(4));
      world.setBlockState(pos.add(17, 9, 53), ((BlockColored)Blocks.STAINED_HARDENED_CLAY).getStateFromMeta(4));
      world.setBlockState(pos.add(23, 9, 53), ((BlockColored)Blocks.STAINED_HARDENED_CLAY).getStateFromMeta(4));
      world.setBlockState(pos.add(24, 9, 53), ((BlockColored)Blocks.STAINED_HARDENED_CLAY).getStateFromMeta(4));
      world.setBlockState(pos.add(28, 9, 53), ((BlockColored)Blocks.STAINED_HARDENED_CLAY).getStateFromMeta(4));
      world.setBlockState(pos.add(29, 9, 53), ((BlockColored)Blocks.STAINED_HARDENED_CLAY).getStateFromMeta(4));
      world.setBlockState(pos.add(35, 9, 53), ((BlockColored)Blocks.STAINED_HARDENED_CLAY).getStateFromMeta(4));
      world.setBlockState(pos.add(36, 9, 53), ((BlockColored)Blocks.STAINED_HARDENED_CLAY).getStateFromMeta(4));
      world.setBlockState(pos.add(16, 9, 54), ((BlockColored)Blocks.STAINED_HARDENED_CLAY).getStateFromMeta(4));
      world.setBlockState(pos.add(17, 9, 54), ((BlockColored)Blocks.STAINED_HARDENED_CLAY).getStateFromMeta(4));
      world.setBlockState(pos.add(23, 9, 54), ((BlockColored)Blocks.STAINED_HARDENED_CLAY).getStateFromMeta(4));
      world.setBlockState(pos.add(24, 9, 54), ((BlockColored)Blocks.STAINED_HARDENED_CLAY).getStateFromMeta(4));
      world.setBlockState(pos.add(25, 9, 54), ((BlockStairs)Blocks.NETHER_BRICK_STAIRS).getStateFromMeta(2));
      world.setBlockState(pos.add(26, 9, 54), ((BlockStairs)Blocks.NETHER_BRICK_STAIRS).getStateFromMeta(2));
      world.setBlockState(pos.add(27, 9, 54), ((BlockStairs)Blocks.NETHER_BRICK_STAIRS).getStateFromMeta(2));
      world.setBlockState(pos.add(28, 9, 54), ((BlockColored)Blocks.STAINED_HARDENED_CLAY).getStateFromMeta(4));
      world.setBlockState(pos.add(29, 9, 54), ((BlockColored)Blocks.STAINED_HARDENED_CLAY).getStateFromMeta(4));
      world.setBlockState(pos.add(35, 9, 54), ((BlockColored)Blocks.STAINED_HARDENED_CLAY).getStateFromMeta(4));
      world.setBlockState(pos.add(36, 9, 54), ((BlockColored)Blocks.STAINED_HARDENED_CLAY).getStateFromMeta(4));
      world.setBlockState(pos.add(16, 9, 55), ((BlockColored)Blocks.STAINED_HARDENED_CLAY).getStateFromMeta(4));
      world.setBlockState(pos.add(17, 9, 55), ((BlockColored)Blocks.STAINED_HARDENED_CLAY).getStateFromMeta(4));
      world.setBlockState(pos.add(23, 9, 55), ((BlockColored)Blocks.STAINED_HARDENED_CLAY).getStateFromMeta(4));
      world.setBlockState(pos.add(24, 9, 55), ((BlockColored)Blocks.STAINED_HARDENED_CLAY).getStateFromMeta(4));
      world.setBlockState(pos.add(28, 9, 55), ((BlockColored)Blocks.STAINED_HARDENED_CLAY).getStateFromMeta(4));
      world.setBlockState(pos.add(29, 9, 55), ((BlockColored)Blocks.STAINED_HARDENED_CLAY).getStateFromMeta(4));
      world.setBlockState(pos.add(35, 9, 55), ((BlockColored)Blocks.STAINED_HARDENED_CLAY).getStateFromMeta(4));
      world.setBlockState(pos.add(36, 9, 55), ((BlockColored)Blocks.STAINED_HARDENED_CLAY).getStateFromMeta(4));
      world.setBlockState(pos.add(37, 9, 55), ((BlockColored)Blocks.STAINED_HARDENED_CLAY).getStateFromMeta(4));
      world.setBlockState(pos.add(17, 9, 56), ((BlockColored)Blocks.STAINED_HARDENED_CLAY).getStateFromMeta(4));
      world.setBlockState(pos.add(18, 9, 56), ((BlockColored)Blocks.STAINED_HARDENED_CLAY).getStateFromMeta(4));
      world.setBlockState(pos.add(22, 9, 56), ((BlockColored)Blocks.STAINED_HARDENED_CLAY).getStateFromMeta(4));
      world.setBlockState(pos.add(23, 9, 56), ((BlockColored)Blocks.STAINED_HARDENED_CLAY).getStateFromMeta(4));
      world.setBlockState(pos.add(29, 9, 56), ((BlockColored)Blocks.STAINED_HARDENED_CLAY).getStateFromMeta(4));
      world.setBlockState(pos.add(30, 9, 56), ((BlockColored)Blocks.STAINED_HARDENED_CLAY).getStateFromMeta(4));
      world.setBlockState(pos.add(34, 9, 56), ((BlockColored)Blocks.STAINED_HARDENED_CLAY).getStateFromMeta(4));
      world.setBlockState(pos.add(35, 9, 56), ((BlockColored)Blocks.STAINED_HARDENED_CLAY).getStateFromMeta(4));
      world.setBlockState(pos.add(38, 9, 56), ((BlockColored)Blocks.STAINED_HARDENED_CLAY).getStateFromMeta(4));
      world.setBlockState(pos.add(39, 9, 56), ((BlockColored)Blocks.WOOL).getStateFromMeta(15));
      world.setBlockState(pos.add(40, 9, 56), ((BlockColored)Blocks.WOOL).getStateFromMeta(15));
      world.setBlockState(pos.add(18, 9, 57), ((BlockColored)Blocks.STAINED_HARDENED_CLAY).getStateFromMeta(4));
      world.setBlockState(pos.add(19, 9, 57), ((BlockColored)Blocks.STAINED_HARDENED_CLAY).getStateFromMeta(4));
      world.setBlockState(pos.add(20, 9, 57), ((BlockColored)Blocks.STAINED_HARDENED_CLAY).getStateFromMeta(4));
      world.setBlockState(pos.add(21, 9, 57), ((BlockColored)Blocks.STAINED_HARDENED_CLAY).getStateFromMeta(4));
      world.setBlockState(pos.add(22, 9, 57), ((BlockColored)Blocks.STAINED_HARDENED_CLAY).getStateFromMeta(4));
      world.setBlockState(pos.add(30, 9, 57), ((BlockColored)Blocks.STAINED_HARDENED_CLAY).getStateFromMeta(4));
      world.setBlockState(pos.add(31, 9, 57), ((BlockColored)Blocks.STAINED_HARDENED_CLAY).getStateFromMeta(4));
      world.setBlockState(pos.add(32, 9, 57), ((BlockColored)Blocks.STAINED_HARDENED_CLAY).getStateFromMeta(4));
      world.setBlockState(pos.add(33, 9, 57), ((BlockColored)Blocks.STAINED_HARDENED_CLAY).getStateFromMeta(4));
      world.setBlockState(pos.add(34, 9, 57), ((BlockColored)Blocks.STAINED_HARDENED_CLAY).getStateFromMeta(4));
      world.setBlockState(pos.add(39, 9, 57), ((BlockColored)Blocks.STAINED_HARDENED_CLAY).getStateFromMeta(4));
      world.setBlockState(pos.add(41, 9, 57), ((BlockColored)Blocks.WOOL).getStateFromMeta(15));
      world.setBlockState(pos.add(19, 9, 58), ((BlockColored)Blocks.STAINED_HARDENED_CLAY).getStateFromMeta(4));
      world.setBlockState(pos.add(20, 9, 58), ((BlockColored)Blocks.STAINED_HARDENED_CLAY).getStateFromMeta(4));
      world.setBlockState(pos.add(21, 9, 58), ((BlockColored)Blocks.STAINED_HARDENED_CLAY).getStateFromMeta(4));
      world.setBlockState(pos.add(22, 9, 58), ((BlockColored)Blocks.STAINED_HARDENED_CLAY).getStateFromMeta(4));
      world.setBlockState(pos.add(23, 9, 58), ((BlockColored)Blocks.STAINED_HARDENED_CLAY).getStateFromMeta(4));
      world.setBlockState(pos.add(24, 9, 58), ((BlockColored)Blocks.STAINED_HARDENED_CLAY).getStateFromMeta(4));
      world.setBlockState(pos.add(25, 9, 58), ((BlockColored)Blocks.STAINED_HARDENED_CLAY).getStateFromMeta(4));
      world.setBlockState(pos.add(26, 9, 58), ((BlockColored)Blocks.STAINED_HARDENED_CLAY).getStateFromMeta(4));
      world.setBlockState(pos.add(27, 9, 58), ((BlockColored)Blocks.STAINED_HARDENED_CLAY).getStateFromMeta(4));
      world.setBlockState(pos.add(28, 9, 58), ((BlockColored)Blocks.STAINED_HARDENED_CLAY).getStateFromMeta(4));
      world.setBlockState(pos.add(29, 9, 58), ((BlockColored)Blocks.STAINED_HARDENED_CLAY).getStateFromMeta(4));
      world.setBlockState(pos.add(30, 9, 58), ((BlockColored)Blocks.STAINED_HARDENED_CLAY).getStateFromMeta(4));
      world.setBlockState(pos.add(31, 9, 58), ((BlockColored)Blocks.STAINED_HARDENED_CLAY).getStateFromMeta(4));
      world.setBlockState(pos.add(32, 9, 58), ((BlockColored)Blocks.STAINED_HARDENED_CLAY).getStateFromMeta(4));
      world.setBlockState(pos.add(33, 9, 58), ((BlockColored)Blocks.STAINED_HARDENED_CLAY).getStateFromMeta(4));
      world.setBlockState(pos.add(40, 9, 58), ((BlockColored)Blocks.STAINED_HARDENED_CLAY).getStateFromMeta(4));
      world.setBlockState(pos.add(42, 9, 58), ((BlockColored)Blocks.WOOL).getStateFromMeta(15));
      world.setBlockState(pos.add(34, 9, 59), ((BlockColored)Blocks.WOOL).getStateFromMeta(15));
      world.setBlockState(pos.add(35, 9, 59), ((BlockColored)Blocks.WOOL).getStateFromMeta(15));
      world.setBlockState(pos.add(36, 9, 59), ((BlockColored)Blocks.WOOL).getStateFromMeta(15));
      world.setBlockState(pos.add(37, 9, 59), ((BlockColored)Blocks.WOOL).getStateFromMeta(15));
      world.setBlockState(pos.add(41, 9, 59), ((BlockColored)Blocks.STAINED_HARDENED_CLAY).getStateFromMeta(4));
      world.setBlockState(pos.add(42, 9, 59), ((BlockColored)Blocks.WOOL).getStateFromMeta(15));
      world.setBlockState(pos.add(33, 9, 60), ((BlockColored)Blocks.WOOL).getStateFromMeta(15));
      world.setBlockState(pos.add(38, 9, 60), ((BlockColored)Blocks.WOOL).getStateFromMeta(15));
      world.setBlockState(pos.add(42, 9, 60), Blocks.STONE.getDefaultState());
      world.setBlockState(pos.add(43, 9, 60), Blocks.STONE.getDefaultState());
      world.setBlockState(pos.add(44, 9, 60), Blocks.STONE.getDefaultState());
      world.setBlockState(pos.add(45, 9, 60), Blocks.STONE.getDefaultState());
      world.setBlockState(pos.add(32, 9, 61), ((BlockColored)Blocks.WOOL).getStateFromMeta(15));
      world.setBlockState(pos.add(39, 9, 61), ((BlockColored)Blocks.WOOL).getStateFromMeta(15));
      world.setBlockState(pos.add(41, 9, 61), Blocks.STONE.getDefaultState());
      world.setBlockState(pos.add(46, 9, 61), Blocks.STONE.getDefaultState());
      world.setBlockState(pos.add(32, 9, 62), ((BlockColored)Blocks.WOOL).getStateFromMeta(15));
      world.setBlockState(pos.add(39, 9, 62), ((BlockColored)Blocks.WOOL).getStateFromMeta(15));
      world.setBlockState(pos.add(40, 9, 62), Blocks.STONE.getDefaultState());
      world.setBlockState(pos.add(47, 9, 62), Blocks.STONE.getDefaultState());
      world.setBlockState(pos.add(19, 9, 63), Blocks.OBSIDIAN.getDefaultState());
      world.setBlockState(pos.add(32, 9, 63), ((BlockColored)Blocks.WOOL).getStateFromMeta(15));
      world.setBlockState(pos.add(39, 9, 63), ((BlockColored)Blocks.WOOL).getStateFromMeta(15));
      world.setBlockState(pos.add(40, 9, 63), Blocks.STONE.getDefaultState());
      world.setBlockState(pos.add(47, 9, 63), Blocks.STONE.getDefaultState());
      world.setBlockState(pos.add(19, 9, 64), Blocks.OBSIDIAN.getDefaultState());
      world.setBlockState(pos.add(32, 9, 64), ((BlockColored)Blocks.WOOL).getStateFromMeta(15));
      world.setBlockState(pos.add(39, 9, 64), ((BlockColored)Blocks.WOOL).getStateFromMeta(15));
      world.setBlockState(pos.add(40, 9, 64), Blocks.STONE.getDefaultState());
      world.setBlockState(pos.add(47, 9, 64), Blocks.STONE.getDefaultState());
      world.setBlockState(pos.add(23, 9, 65), Blocks.OBSIDIAN.getDefaultState());
      world.setBlockState(pos.add(24, 9, 65), Blocks.OBSIDIAN.getDefaultState());
      world.setBlockState(pos.add(33, 9, 65), ((BlockColored)Blocks.WOOL).getStateFromMeta(15));
      world.setBlockState(pos.add(38, 9, 65), ((BlockColored)Blocks.WOOL).getStateFromMeta(15));
      world.setBlockState(pos.add(40, 9, 65), Blocks.STONE.getDefaultState());
      world.setBlockState(pos.add(47, 9, 65), Blocks.STONE.getDefaultState());
      world.setBlockState(pos.add(34, 9, 66), ((BlockColored)Blocks.WOOL).getStateFromMeta(15));
      world.setBlockState(pos.add(35, 9, 66), ((BlockColored)Blocks.WOOL).getStateFromMeta(15));
      world.setBlockState(pos.add(36, 9, 66), ((BlockColored)Blocks.WOOL).getStateFromMeta(15));
      world.setBlockState(pos.add(37, 9, 66), ((BlockColored)Blocks.WOOL).getStateFromMeta(15));
      world.setBlockState(pos.add(41, 9, 66), Blocks.STONE.getDefaultState());
      world.setBlockState(pos.add(46, 9, 66), Blocks.STONE.getDefaultState());
      world.setBlockState(pos.add(42, 9, 67), Blocks.STONE.getDefaultState());
      world.setBlockState(pos.add(43, 9, 67), Blocks.STONE.getDefaultState());
      world.setBlockState(pos.add(44, 9, 67), Blocks.STONE.getDefaultState());
      world.setBlockState(pos.add(45, 9, 67), Blocks.STONE.getDefaultState());
      world.setBlockState(pos.add(24, 10, 36), Blocks.QUARTZ_BLOCK.getDefaultState());
      world.setBlockState(pos.add(25, 10, 36), ((BlockColored)Blocks.STAINED_HARDENED_CLAY).getStateFromMeta(10));
      world.setBlockState(pos.add(27, 10, 36), ((BlockColored)Blocks.STAINED_HARDENED_CLAY).getStateFromMeta(10));
      world.setBlockState(pos.add(28, 10, 36), Blocks.QUARTZ_BLOCK.getDefaultState());
      world.setBlockState(pos.add(15, 10, 37), ((BlockColored)Blocks.STAINED_HARDENED_CLAY).getStateFromMeta(4));
      world.setBlockState(pos.add(16, 10, 37), ((BlockColored)Blocks.STAINED_HARDENED_CLAY).getStateFromMeta(4));
      world.setBlockState(pos.add(21, 10, 37), Blocks.QUARTZ_BLOCK.getDefaultState());
      world.setBlockState(pos.add(22, 10, 37), Blocks.QUARTZ_BLOCK.getDefaultState());
      world.setBlockState(pos.add(23, 10, 37), ((BlockColored)Blocks.STAINED_HARDENED_CLAY).getStateFromMeta(4));
      world.setBlockState(pos.add(29, 10, 37), ((BlockColored)Blocks.STAINED_HARDENED_CLAY).getStateFromMeta(4));
      world.setBlockState(pos.add(36, 10, 37), ((BlockColored)Blocks.STAINED_HARDENED_CLAY).getStateFromMeta(4));
      world.setBlockState(pos.add(37, 10, 37), ((BlockColored)Blocks.STAINED_HARDENED_CLAY).getStateFromMeta(4));
      world.setBlockState(pos.add(15, 10, 38), ((BlockColored)Blocks.STAINED_HARDENED_CLAY).getStateFromMeta(4));
      world.setBlockState(pos.add(16, 10, 38), ((BlockColored)Blocks.STAINED_HARDENED_CLAY).getStateFromMeta(4));
      world.setBlockState(pos.add(17, 10, 38), ((BlockColored)Blocks.STAINED_HARDENED_CLAY).getStateFromMeta(7));
      world.setBlockState(pos.add(18, 10, 38), ((BlockColored)Blocks.STAINED_HARDENED_CLAY).getStateFromMeta(7));
      world.setBlockState(pos.add(19, 10, 38), ((BlockColored)Blocks.STAINED_HARDENED_CLAY).getStateFromMeta(7));
      world.setBlockState(pos.add(20, 10, 38), ((BlockColored)Blocks.STAINED_HARDENED_CLAY).getStateFromMeta(7));
      world.setBlockState(pos.add(21, 10, 38), Blocks.QUARTZ_BLOCK.getDefaultState());
      world.setBlockState(pos.add(22, 10, 38), Blocks.QUARTZ_BLOCK.getDefaultState());
      world.setBlockState(pos.add(30, 10, 38), Blocks.QUARTZ_BLOCK.getDefaultState());
      world.setBlockState(pos.add(31, 10, 38), Blocks.QUARTZ_BLOCK.getDefaultState());
      world.setBlockState(pos.add(32, 10, 38), ((BlockColored)Blocks.STAINED_HARDENED_CLAY).getStateFromMeta(7));
      world.setBlockState(pos.add(33, 10, 38), ((BlockColored)Blocks.STAINED_HARDENED_CLAY).getStateFromMeta(7));
      world.setBlockState(pos.add(34, 10, 38), ((BlockColored)Blocks.STAINED_HARDENED_CLAY).getStateFromMeta(7));
      world.setBlockState(pos.add(35, 10, 38), ((BlockColored)Blocks.STAINED_HARDENED_CLAY).getStateFromMeta(7));
      world.setBlockState(pos.add(36, 10, 38), ((BlockColored)Blocks.STAINED_HARDENED_CLAY).getStateFromMeta(4));
      world.setBlockState(pos.add(37, 10, 38), ((BlockColored)Blocks.STAINED_HARDENED_CLAY).getStateFromMeta(4));
      world.setBlockState(pos.add(40, 10, 38), Blocks.STONE.getDefaultState());
      world.setBlockState(pos.add(41, 10, 38), Blocks.STONE.getDefaultState());
      world.setBlockState(pos.add(42, 10, 38), Blocks.STONE.getDefaultState());
      world.setBlockState(pos.add(15, 10, 39), ((BlockColored)Blocks.STAINED_HARDENED_CLAY).getStateFromMeta(4));
      world.setBlockState(pos.add(20, 10, 39), ((BlockColored)Blocks.STAINED_HARDENED_CLAY).getStateFromMeta(4));
      world.setBlockState(pos.add(21, 10, 39), Blocks.QUARTZ_BLOCK.getDefaultState());
      world.setBlockState(pos.add(22, 10, 39), Blocks.QUARTZ_BLOCK.getDefaultState());
      world.setBlockState(pos.add(30, 10, 39), Blocks.QUARTZ_BLOCK.getDefaultState());
      world.setBlockState(pos.add(31, 10, 39), Blocks.QUARTZ_BLOCK.getDefaultState());
      world.setBlockState(pos.add(32, 10, 39), ((BlockColored)Blocks.STAINED_HARDENED_CLAY).getStateFromMeta(4));
      world.setBlockState(pos.add(37, 10, 39), ((BlockColored)Blocks.STAINED_HARDENED_CLAY).getStateFromMeta(4));
      world.setBlockState(pos.add(40, 10, 39), Blocks.STONE.getDefaultState());
      world.setBlockState(pos.add(42, 10, 39), Blocks.STONE.getDefaultState());
      world.setBlockState(pos.add(15, 10, 40), ((BlockColored)Blocks.STAINED_HARDENED_CLAY).getStateFromMeta(4));
      world.setBlockState(pos.add(20, 10, 40), ((BlockColored)Blocks.STAINED_HARDENED_CLAY).getStateFromMeta(4));
      world.setBlockState(pos.add(21, 10, 40), Blocks.QUARTZ_BLOCK.getDefaultState());
      world.setBlockState(pos.add(22, 10, 40), Blocks.QUARTZ_BLOCK.getDefaultState());
      world.setBlockState(pos.add(23, 10, 40), ((BlockStaticLiquid)Blocks.LAVA).getStateFromMeta(10));
      world.setBlockState(pos.add(29, 10, 40), ((BlockStaticLiquid)Blocks.LAVA).getStateFromMeta(10));
      world.setBlockState(pos.add(30, 10, 40), Blocks.QUARTZ_BLOCK.getDefaultState());
      world.setBlockState(pos.add(31, 10, 40), Blocks.QUARTZ_BLOCK.getDefaultState());
      world.setBlockState(pos.add(32, 10, 40), ((BlockColored)Blocks.STAINED_HARDENED_CLAY).getStateFromMeta(4));
      world.setBlockState(pos.add(36, 10, 40), ((BlockColored)Blocks.STAINED_HARDENED_CLAY).getStateFromMeta(4));
      world.setBlockState(pos.add(37, 10, 40), ((BlockColored)Blocks.STAINED_HARDENED_CLAY).getStateFromMeta(4));
      world.setBlockState(pos.add(40, 10, 40), Blocks.STONE.getDefaultState());
      world.setBlockState(pos.add(41, 10, 40), Blocks.STONE.getDefaultState());
      world.setBlockState(pos.add(42, 10, 40), Blocks.STONE.getDefaultState());
      world.setBlockState(pos.add(5, 10, 41), Blocks.STONE.getDefaultState());
      world.setBlockState(pos.add(6, 10, 41), Blocks.STONE.getDefaultState());
      world.setBlockState(pos.add(7, 10, 41), Blocks.STONE.getDefaultState());
      world.setBlockState(pos.add(16, 10, 41), Blocks.QUARTZ_BLOCK.getDefaultState());
      world.setBlockState(pos.add(20, 10, 41), Blocks.QUARTZ_BLOCK.getDefaultState());
      world.setBlockState(pos.add(21, 10, 41), Blocks.QUARTZ_BLOCK.getDefaultState());
      world.setBlockState(pos.add(22, 10, 41), Blocks.QUARTZ_BLOCK.getDefaultState());
      world.setBlockState(pos.add(23, 10, 41), Blocks.STONE.getDefaultState());
      world.setBlockState(pos.add(29, 10, 41), Blocks.STONE.getDefaultState());
      world.setBlockState(pos.add(30, 10, 41), Blocks.QUARTZ_BLOCK.getDefaultState());
      world.setBlockState(pos.add(31, 10, 41), Blocks.QUARTZ_BLOCK.getDefaultState());
      world.setBlockState(pos.add(32, 10, 41), Blocks.QUARTZ_BLOCK.getDefaultState());
      world.setBlockState(pos.add(36, 10, 41), Blocks.QUARTZ_BLOCK.getDefaultState());
      world.setBlockState(pos.add(4, 10, 42), Blocks.STONE.getDefaultState());
      world.setBlockState(pos.add(8, 10, 42), Blocks.STONE.getDefaultState());
      world.setBlockState(pos.add(16, 10, 42), Blocks.QUARTZ_BLOCK.getDefaultState());
      world.setBlockState(pos.add(20, 10, 42), Blocks.QUARTZ_BLOCK.getDefaultState());
      world.setBlockState(pos.add(21, 10, 42), Blocks.QUARTZ_BLOCK.getDefaultState());
      world.setBlockState(pos.add(22, 10, 42), Blocks.QUARTZ_BLOCK.getDefaultState());
      world.setBlockState(pos.add(23, 10, 42), Blocks.STONE.getDefaultState());
      world.setBlockState(pos.add(29, 10, 42), Blocks.STONE.getDefaultState());
      world.setBlockState(pos.add(30, 10, 42), Blocks.QUARTZ_BLOCK.getDefaultState());
      world.setBlockState(pos.add(31, 10, 42), Blocks.QUARTZ_BLOCK.getDefaultState());
      world.setBlockState(pos.add(32, 10, 42), Blocks.QUARTZ_BLOCK.getDefaultState());
      world.setBlockState(pos.add(36, 10, 42), Blocks.QUARTZ_BLOCK.getDefaultState());
      world.setBlockState(pos.add(4, 10, 43), Blocks.STONE.getDefaultState());
      world.setBlockState(pos.add(8, 10, 43), Blocks.STONE.getDefaultState());
      world.setBlockState(pos.add(15, 10, 43), ((BlockColored)Blocks.STAINED_HARDENED_CLAY).getStateFromMeta(4));
      world.setBlockState(pos.add(20, 10, 43), ((BlockColored)Blocks.STAINED_HARDENED_CLAY).getStateFromMeta(4));
      world.setBlockState(pos.add(21, 10, 43), Blocks.QUARTZ_BLOCK.getDefaultState());
      world.setBlockState(pos.add(22, 10, 43), Blocks.QUARTZ_BLOCK.getDefaultState());
      world.setBlockState(pos.add(23, 10, 43), ((BlockStaticLiquid)Blocks.LAVA).getStateFromMeta(10));
      world.setBlockState(pos.add(29, 10, 43), ((BlockStaticLiquid)Blocks.LAVA).getStateFromMeta(10));
      world.setBlockState(pos.add(30, 10, 43), Blocks.QUARTZ_BLOCK.getDefaultState());
      world.setBlockState(pos.add(31, 10, 43), Blocks.QUARTZ_BLOCK.getDefaultState());
      world.setBlockState(pos.add(32, 10, 43), ((BlockColored)Blocks.STAINED_HARDENED_CLAY).getStateFromMeta(4));
      world.setBlockState(pos.add(37, 10, 43), ((BlockColored)Blocks.STAINED_HARDENED_CLAY).getStateFromMeta(4));
      world.setBlockState(pos.add(4, 10, 44), Blocks.STONE.getDefaultState());
      world.setBlockState(pos.add(8, 10, 44), Blocks.STONE.getDefaultState());
      world.setBlockState(pos.add(15, 10, 44), ((BlockColored)Blocks.STAINED_HARDENED_CLAY).getStateFromMeta(4));
      world.setBlockState(pos.add(20, 10, 44), ((BlockColored)Blocks.STAINED_HARDENED_CLAY).getStateFromMeta(4));
      world.setBlockState(pos.add(21, 10, 44), Blocks.QUARTZ_BLOCK.getDefaultState());
      world.setBlockState(pos.add(22, 10, 44), Blocks.QUARTZ_BLOCK.getDefaultState());
      world.setBlockState(pos.add(30, 10, 44), Blocks.QUARTZ_BLOCK.getDefaultState());
      world.setBlockState(pos.add(31, 10, 44), Blocks.QUARTZ_BLOCK.getDefaultState());
      world.setBlockState(pos.add(32, 10, 44), ((BlockColored)Blocks.STAINED_HARDENED_CLAY).getStateFromMeta(4));
      world.setBlockState(pos.add(37, 10, 44), ((BlockColored)Blocks.STAINED_HARDENED_CLAY).getStateFromMeta(4));
      world.setBlockState(pos.add(5, 10, 45), Blocks.STONE.getDefaultState());
      world.setBlockState(pos.add(6, 10, 45), Blocks.STONE.getDefaultState());
      world.setBlockState(pos.add(7, 10, 45), Blocks.STONE.getDefaultState());
      world.setBlockState(pos.add(15, 10, 45), ((BlockColored)Blocks.STAINED_HARDENED_CLAY).getStateFromMeta(4));
      world.setBlockState(pos.add(20, 10, 45), ((BlockColored)Blocks.STAINED_HARDENED_CLAY).getStateFromMeta(4));
      world.setBlockState(pos.add(21, 10, 45), Blocks.QUARTZ_BLOCK.getDefaultState());
      world.setBlockState(pos.add(22, 10, 45), Blocks.QUARTZ_BLOCK.getDefaultState());
      world.setBlockState(pos.add(23, 10, 45), ((BlockStaticLiquid)Blocks.LAVA).getStateFromMeta(10));
      world.setBlockState(pos.add(29, 10, 45), ((BlockStaticLiquid)Blocks.LAVA).getStateFromMeta(10));
      world.setBlockState(pos.add(30, 10, 45), Blocks.QUARTZ_BLOCK.getDefaultState());
      world.setBlockState(pos.add(31, 10, 45), Blocks.QUARTZ_BLOCK.getDefaultState());
      world.setBlockState(pos.add(32, 10, 45), ((BlockColored)Blocks.STAINED_HARDENED_CLAY).getStateFromMeta(4));
      world.setBlockState(pos.add(37, 10, 45), ((BlockColored)Blocks.STAINED_HARDENED_CLAY).getStateFromMeta(4));
      world.setBlockState(pos.add(16, 10, 46), Blocks.QUARTZ_BLOCK.getDefaultState());
      world.setBlockState(pos.add(17, 10, 46), Blocks.QUARTZ_BLOCK.getDefaultState());
      world.setBlockState(pos.add(18, 10, 46), Blocks.QUARTZ_BLOCK.getDefaultState());
      world.setBlockState(pos.add(19, 10, 46), Blocks.QUARTZ_BLOCK.getDefaultState());
      world.setBlockState(pos.add(20, 10, 46), Blocks.QUARTZ_BLOCK.getDefaultState());
      world.setBlockState(pos.add(21, 10, 46), Blocks.QUARTZ_BLOCK.getDefaultState());
      world.setBlockState(pos.add(22, 10, 46), Blocks.QUARTZ_BLOCK.getDefaultState());
      world.setBlockState(pos.add(23, 10, 46), Blocks.STONE.getDefaultState());
      world.setBlockState(pos.add(29, 10, 46), Blocks.STONE.getDefaultState());
      world.setBlockState(pos.add(30, 10, 46), Blocks.QUARTZ_BLOCK.getDefaultState());
      world.setBlockState(pos.add(31, 10, 46), Blocks.QUARTZ_BLOCK.getDefaultState());
      world.setBlockState(pos.add(32, 10, 46), Blocks.QUARTZ_BLOCK.getDefaultState());
      world.setBlockState(pos.add(36, 10, 46), Blocks.QUARTZ_BLOCK.getDefaultState());
      world.setBlockState(pos.add(16, 10, 47), Blocks.QUARTZ_BLOCK.getDefaultState());
      world.setBlockState(pos.add(17, 10, 47), Blocks.QUARTZ_BLOCK.getDefaultState());
      world.setBlockState(pos.add(18, 10, 47), Blocks.QUARTZ_BLOCK.getDefaultState());
      world.setBlockState(pos.add(19, 10, 47), Blocks.QUARTZ_BLOCK.getDefaultState());
      world.setBlockState(pos.add(20, 10, 47), Blocks.QUARTZ_BLOCK.getDefaultState());
      world.setBlockState(pos.add(21, 10, 47), Blocks.QUARTZ_BLOCK.getDefaultState());
      world.setBlockState(pos.add(22, 10, 47), Blocks.QUARTZ_BLOCK.getDefaultState());
      world.setBlockState(pos.add(23, 10, 47), Blocks.STONE.getDefaultState());
      world.setBlockState(pos.add(29, 10, 47), Blocks.STONE.getDefaultState());
      world.setBlockState(pos.add(30, 10, 47), Blocks.QUARTZ_BLOCK.getDefaultState());
      world.setBlockState(pos.add(31, 10, 47), Blocks.QUARTZ_BLOCK.getDefaultState());
      world.setBlockState(pos.add(32, 10, 47), Blocks.QUARTZ_BLOCK.getDefaultState());
      world.setBlockState(pos.add(36, 10, 47), Blocks.QUARTZ_BLOCK.getDefaultState());
      world.setBlockState(pos.add(15, 10, 48), ((BlockColored)Blocks.STAINED_HARDENED_CLAY).getStateFromMeta(4));
      world.setBlockState(pos.add(20, 10, 48), ((BlockColored)Blocks.STAINED_HARDENED_CLAY).getStateFromMeta(4));
      world.setBlockState(pos.add(21, 10, 48), Blocks.QUARTZ_BLOCK.getDefaultState());
      world.setBlockState(pos.add(22, 10, 48), Blocks.QUARTZ_BLOCK.getDefaultState());
      world.setBlockState(pos.add(23, 10, 48), ((BlockStaticLiquid)Blocks.LAVA).getStateFromMeta(10));
      world.setBlockState(pos.add(29, 10, 48), ((BlockStaticLiquid)Blocks.LAVA).getStateFromMeta(10));
      world.setBlockState(pos.add(30, 10, 48), Blocks.QUARTZ_BLOCK.getDefaultState());
      world.setBlockState(pos.add(31, 10, 48), Blocks.QUARTZ_BLOCK.getDefaultState());
      world.setBlockState(pos.add(32, 10, 48), ((BlockColored)Blocks.STAINED_HARDENED_CLAY).getStateFromMeta(4));
      world.setBlockState(pos.add(37, 10, 48), ((BlockColored)Blocks.STAINED_HARDENED_CLAY).getStateFromMeta(4));
      world.setBlockState(pos.add(15, 10, 49), ((BlockColored)Blocks.STAINED_HARDENED_CLAY).getStateFromMeta(4));
      world.setBlockState(pos.add(20, 10, 49), ((BlockColored)Blocks.STAINED_HARDENED_CLAY).getStateFromMeta(4));
      world.setBlockState(pos.add(21, 10, 49), Blocks.QUARTZ_BLOCK.getDefaultState());
      world.setBlockState(pos.add(22, 10, 49), Blocks.QUARTZ_BLOCK.getDefaultState());
      world.setBlockState(pos.add(30, 10, 49), Blocks.QUARTZ_BLOCK.getDefaultState());
      world.setBlockState(pos.add(31, 10, 49), Blocks.QUARTZ_BLOCK.getDefaultState());
      world.setBlockState(pos.add(32, 10, 49), ((BlockColored)Blocks.STAINED_HARDENED_CLAY).getStateFromMeta(4));
      world.setBlockState(pos.add(37, 10, 49), ((BlockColored)Blocks.STAINED_HARDENED_CLAY).getStateFromMeta(4));
      world.setBlockState(pos.add(15, 10, 50), ((BlockColored)Blocks.STAINED_HARDENED_CLAY).getStateFromMeta(4));
      world.setBlockState(pos.add(16, 10, 50), ((BlockColored)Blocks.STAINED_HARDENED_CLAY).getStateFromMeta(4));
      world.setBlockState(pos.add(17, 10, 50), ((BlockColored)Blocks.STAINED_HARDENED_CLAY).getStateFromMeta(4));
      world.setBlockState(pos.add(18, 10, 50), ((BlockColored)Blocks.STAINED_HARDENED_CLAY).getStateFromMeta(4));
      world.setBlockState(pos.add(19, 10, 50), ((BlockColored)Blocks.STAINED_HARDENED_CLAY).getStateFromMeta(4));
      world.setBlockState(pos.add(20, 10, 50), ((BlockColored)Blocks.STAINED_HARDENED_CLAY).getStateFromMeta(4));
      world.setBlockState(pos.add(21, 10, 50), Blocks.QUARTZ_BLOCK.getDefaultState());
      world.setBlockState(pos.add(22, 10, 50), Blocks.QUARTZ_BLOCK.getDefaultState());
      world.setBlockState(pos.add(30, 10, 50), Blocks.QUARTZ_BLOCK.getDefaultState());
      world.setBlockState(pos.add(31, 10, 50), Blocks.QUARTZ_BLOCK.getDefaultState());
      world.setBlockState(pos.add(32, 10, 50), ((BlockColored)Blocks.STAINED_HARDENED_CLAY).getStateFromMeta(4));
      world.setBlockState(pos.add(33, 10, 50), ((BlockColored)Blocks.STAINED_HARDENED_CLAY).getStateFromMeta(4));
      world.setBlockState(pos.add(34, 10, 50), ((BlockColored)Blocks.STAINED_HARDENED_CLAY).getStateFromMeta(4));
      world.setBlockState(pos.add(35, 10, 50), ((BlockColored)Blocks.STAINED_HARDENED_CLAY).getStateFromMeta(4));
      world.setBlockState(pos.add(36, 10, 50), ((BlockColored)Blocks.STAINED_HARDENED_CLAY).getStateFromMeta(4));
      world.setBlockState(pos.add(37, 10, 50), ((BlockColored)Blocks.STAINED_HARDENED_CLAY).getStateFromMeta(4));
      world.setBlockState(pos.add(18, 10, 51), ((BlockColored)Blocks.STAINED_HARDENED_CLAY).getStateFromMeta(4));
      world.setBlockState(pos.add(19, 10, 51), ((BlockColored)Blocks.STAINED_HARDENED_CLAY).getStateFromMeta(4));
      world.setBlockState(pos.add(20, 10, 51), ((BlockColored)Blocks.STAINED_HARDENED_CLAY).getStateFromMeta(4));
      world.setBlockState(pos.add(21, 10, 51), ((BlockColored)Blocks.STAINED_HARDENED_CLAY).getStateFromMeta(4));
      world.setBlockState(pos.add(30, 10, 51), ((BlockColored)Blocks.STAINED_HARDENED_CLAY).getStateFromMeta(4));
      world.setBlockState(pos.add(31, 10, 51), ((BlockColored)Blocks.STAINED_HARDENED_CLAY).getStateFromMeta(4));
      world.setBlockState(pos.add(32, 10, 51), ((BlockColored)Blocks.STAINED_HARDENED_CLAY).getStateFromMeta(4));
      world.setBlockState(pos.add(33, 10, 51), ((BlockColored)Blocks.STAINED_HARDENED_CLAY).getStateFromMeta(4));
      world.setBlockState(pos.add(34, 10, 51), ((BlockColored)Blocks.STAINED_HARDENED_CLAY).getStateFromMeta(4));
      world.setBlockState(pos.add(17, 10, 52), ((BlockColored)Blocks.STAINED_HARDENED_CLAY).getStateFromMeta(4));
      world.setBlockState(pos.add(18, 10, 52), ((BlockColored)Blocks.STAINED_HARDENED_CLAY).getStateFromMeta(4));
      world.setBlockState(pos.add(22, 10, 52), ((BlockColored)Blocks.STAINED_HARDENED_CLAY).getStateFromMeta(4));
      world.setBlockState(pos.add(23, 10, 52), ((BlockColored)Blocks.STAINED_HARDENED_CLAY).getStateFromMeta(4));
      world.setBlockState(pos.add(24, 10, 52), ((BlockColored)Blocks.STAINED_HARDENED_CLAY).getStateFromMeta(4));
      world.setBlockState(pos.add(28, 10, 52), ((BlockColored)Blocks.STAINED_HARDENED_CLAY).getStateFromMeta(4));
      world.setBlockState(pos.add(29, 10, 52), ((BlockColored)Blocks.STAINED_HARDENED_CLAY).getStateFromMeta(4));
      world.setBlockState(pos.add(30, 10, 52), ((BlockColored)Blocks.STAINED_HARDENED_CLAY).getStateFromMeta(4));
      world.setBlockState(pos.add(34, 10, 52), ((BlockColored)Blocks.STAINED_HARDENED_CLAY).getStateFromMeta(4));
      world.setBlockState(pos.add(35, 10, 52), ((BlockColored)Blocks.STAINED_HARDENED_CLAY).getStateFromMeta(4));
      world.setBlockState(pos.add(16, 10, 53), ((BlockColored)Blocks.STAINED_HARDENED_CLAY).getStateFromMeta(4));
      world.setBlockState(pos.add(17, 10, 53), ((BlockColored)Blocks.STAINED_HARDENED_CLAY).getStateFromMeta(4));
      world.setBlockState(pos.add(23, 10, 53), ((BlockColored)Blocks.STAINED_HARDENED_CLAY).getStateFromMeta(4));
      world.setBlockState(pos.add(24, 10, 53), ((BlockColored)Blocks.STAINED_HARDENED_CLAY).getStateFromMeta(4));
      world.setBlockState(pos.add(28, 10, 53), ((BlockColored)Blocks.STAINED_HARDENED_CLAY).getStateFromMeta(4));
      world.setBlockState(pos.add(29, 10, 53), ((BlockColored)Blocks.STAINED_HARDENED_CLAY).getStateFromMeta(4));
      world.setBlockState(pos.add(35, 10, 53), ((BlockColored)Blocks.STAINED_HARDENED_CLAY).getStateFromMeta(4));
      world.setBlockState(pos.add(36, 10, 53), ((BlockColored)Blocks.STAINED_HARDENED_CLAY).getStateFromMeta(4));
      world.setBlockState(pos.add(16, 10, 54), ((BlockColored)Blocks.STAINED_HARDENED_CLAY).getStateFromMeta(4));
      world.setBlockState(pos.add(17, 10, 54), ((BlockColored)Blocks.STAINED_HARDENED_CLAY).getStateFromMeta(4));
      world.setBlockState(pos.add(23, 10, 54), ((BlockColored)Blocks.STAINED_HARDENED_CLAY).getStateFromMeta(4));
      world.setBlockState(pos.add(24, 10, 54), ((BlockColored)Blocks.STAINED_HARDENED_CLAY).getStateFromMeta(4));
      world.setBlockState(pos.add(28, 10, 54), ((BlockColored)Blocks.STAINED_HARDENED_CLAY).getStateFromMeta(4));
      world.setBlockState(pos.add(29, 10, 54), ((BlockColored)Blocks.STAINED_HARDENED_CLAY).getStateFromMeta(4));
      world.setBlockState(pos.add(35, 10, 54), ((BlockColored)Blocks.STAINED_HARDENED_CLAY).getStateFromMeta(4));
      world.setBlockState(pos.add(36, 10, 54), ((BlockColored)Blocks.STAINED_HARDENED_CLAY).getStateFromMeta(4));
      world.setBlockState(pos.add(16, 10, 55), ((BlockColored)Blocks.STAINED_HARDENED_CLAY).getStateFromMeta(4));
      world.setBlockState(pos.add(17, 10, 55), ((BlockColored)Blocks.STAINED_HARDENED_CLAY).getStateFromMeta(4));
      world.setBlockState(pos.add(23, 10, 55), ((BlockColored)Blocks.STAINED_HARDENED_CLAY).getStateFromMeta(4));
      world.setBlockState(pos.add(24, 10, 55), ((BlockColored)Blocks.STAINED_HARDENED_CLAY).getStateFromMeta(4));
      world.setBlockState(pos.add(25, 10, 55), ((BlockStairs)Blocks.NETHER_BRICK_STAIRS).getStateFromMeta(2));
      world.setBlockState(pos.add(26, 10, 55), ((BlockStairs)Blocks.NETHER_BRICK_STAIRS).getStateFromMeta(2));
      world.setBlockState(pos.add(27, 10, 55), ((BlockStairs)Blocks.NETHER_BRICK_STAIRS).getStateFromMeta(2));
      world.setBlockState(pos.add(28, 10, 55), ((BlockColored)Blocks.STAINED_HARDENED_CLAY).getStateFromMeta(4));
      world.setBlockState(pos.add(29, 10, 55), ((BlockColored)Blocks.STAINED_HARDENED_CLAY).getStateFromMeta(4));
      world.setBlockState(pos.add(35, 10, 55), ((BlockColored)Blocks.STAINED_HARDENED_CLAY).getStateFromMeta(4));
      world.setBlockState(pos.add(36, 10, 55), ((BlockColored)Blocks.STAINED_HARDENED_CLAY).getStateFromMeta(4));
      world.setBlockState(pos.add(37, 10, 55), ((BlockColored)Blocks.STAINED_HARDENED_CLAY).getStateFromMeta(4));
      world.setBlockState(pos.add(17, 10, 56), ((BlockColored)Blocks.STAINED_HARDENED_CLAY).getStateFromMeta(4));
      world.setBlockState(pos.add(18, 10, 56), ((BlockColored)Blocks.STAINED_HARDENED_CLAY).getStateFromMeta(4));
      world.setBlockState(pos.add(22, 10, 56), ((BlockColored)Blocks.STAINED_HARDENED_CLAY).getStateFromMeta(4));
      world.setBlockState(pos.add(23, 10, 56), ((BlockColored)Blocks.STAINED_HARDENED_CLAY).getStateFromMeta(4));
      world.setBlockState(pos.add(24, 10, 56), ((BlockColored)Blocks.STAINED_HARDENED_CLAY).getStateFromMeta(4));
      world.setBlockState(pos.add(25, 10, 56), ((BlockColored)Blocks.STAINED_HARDENED_CLAY).getStateFromMeta(4));
      world.setBlockState(pos.add(26, 10, 56), ((BlockColored)Blocks.STAINED_HARDENED_CLAY).getStateFromMeta(4));
      world.setBlockState(pos.add(27, 10, 56), ((BlockColored)Blocks.STAINED_HARDENED_CLAY).getStateFromMeta(4));
      world.setBlockState(pos.add(28, 10, 56), ((BlockColored)Blocks.STAINED_HARDENED_CLAY).getStateFromMeta(4));
      world.setBlockState(pos.add(29, 10, 56), ((BlockColored)Blocks.STAINED_HARDENED_CLAY).getStateFromMeta(4));
      world.setBlockState(pos.add(30, 10, 56), ((BlockColored)Blocks.STAINED_HARDENED_CLAY).getStateFromMeta(4));
      world.setBlockState(pos.add(34, 10, 56), ((BlockColored)Blocks.STAINED_HARDENED_CLAY).getStateFromMeta(4));
      world.setBlockState(pos.add(35, 10, 56), ((BlockColored)Blocks.STAINED_HARDENED_CLAY).getStateFromMeta(4));
      world.setBlockState(pos.add(38, 10, 56), ((BlockColored)Blocks.STAINED_HARDENED_CLAY).getStateFromMeta(4));
      world.setBlockState(pos.add(39, 10, 56), ((BlockColored)Blocks.WOOL).getStateFromMeta(15));
      world.setBlockState(pos.add(40, 10, 56), ((BlockColored)Blocks.WOOL).getStateFromMeta(15));
      world.setBlockState(pos.add(18, 10, 57), ((BlockColored)Blocks.STAINED_HARDENED_CLAY).getStateFromMeta(4));
      world.setBlockState(pos.add(19, 10, 57), ((BlockColored)Blocks.STAINED_HARDENED_CLAY).getStateFromMeta(4));
      world.setBlockState(pos.add(20, 10, 57), ((BlockColored)Blocks.STAINED_HARDENED_CLAY).getStateFromMeta(4));
      world.setBlockState(pos.add(21, 10, 57), ((BlockColored)Blocks.STAINED_HARDENED_CLAY).getStateFromMeta(4));
      world.setBlockState(pos.add(22, 10, 57), ((BlockColored)Blocks.STAINED_HARDENED_CLAY).getStateFromMeta(4));
      world.setBlockState(pos.add(23, 10, 57), ((BlockColored)Blocks.STAINED_HARDENED_CLAY).getStateFromMeta(4));
      world.setBlockState(pos.add(24, 10, 57), ((BlockColored)Blocks.STAINED_HARDENED_CLAY).getStateFromMeta(4));
      world.setBlockState(pos.add(25, 10, 57), ((BlockColored)Blocks.STAINED_HARDENED_CLAY).getStateFromMeta(4));
      world.setBlockState(pos.add(26, 10, 57), ((BlockColored)Blocks.STAINED_HARDENED_CLAY).getStateFromMeta(4));
      world.setBlockState(pos.add(27, 10, 57), ((BlockColored)Blocks.STAINED_HARDENED_CLAY).getStateFromMeta(4));
      world.setBlockState(pos.add(28, 10, 57), ((BlockColored)Blocks.STAINED_HARDENED_CLAY).getStateFromMeta(4));
      world.setBlockState(pos.add(29, 10, 57), ((BlockColored)Blocks.STAINED_HARDENED_CLAY).getStateFromMeta(4));
      world.setBlockState(pos.add(30, 10, 57), ((BlockColored)Blocks.STAINED_HARDENED_CLAY).getStateFromMeta(4));
      world.setBlockState(pos.add(31, 10, 57), ((BlockColored)Blocks.STAINED_HARDENED_CLAY).getStateFromMeta(4));
      world.setBlockState(pos.add(32, 10, 57), ((BlockColored)Blocks.STAINED_HARDENED_CLAY).getStateFromMeta(4));
      world.setBlockState(pos.add(33, 10, 57), ((BlockColored)Blocks.STAINED_HARDENED_CLAY).getStateFromMeta(4));
      world.setBlockState(pos.add(34, 10, 57), ((BlockColored)Blocks.STAINED_HARDENED_CLAY).getStateFromMeta(4));
      world.setBlockState(pos.add(39, 10, 57), ((BlockColored)Blocks.STAINED_HARDENED_CLAY).getStateFromMeta(4));
      world.setBlockState(pos.add(41, 10, 57), ((BlockColored)Blocks.WOOL).getStateFromMeta(15));
      world.setBlockState(pos.add(19, 10, 58), ((BlockColored)Blocks.STAINED_HARDENED_CLAY).getStateFromMeta(4));
      world.setBlockState(pos.add(20, 10, 58), ((BlockColored)Blocks.STAINED_HARDENED_CLAY).getStateFromMeta(4));
      world.setBlockState(pos.add(21, 10, 58), ((BlockColored)Blocks.STAINED_HARDENED_CLAY).getStateFromMeta(4));
      world.setBlockState(pos.add(22, 10, 58), ((BlockColored)Blocks.STAINED_HARDENED_CLAY).getStateFromMeta(4));
      world.setBlockState(pos.add(23, 10, 58), ((BlockColored)Blocks.STAINED_HARDENED_CLAY).getStateFromMeta(4));
      world.setBlockState(pos.add(24, 10, 58), ((BlockColored)Blocks.STAINED_HARDENED_CLAY).getStateFromMeta(4));
      world.setBlockState(pos.add(25, 10, 58), ((BlockColored)Blocks.STAINED_HARDENED_CLAY).getStateFromMeta(4));
      world.setBlockState(pos.add(26, 10, 58), ((BlockColored)Blocks.STAINED_HARDENED_CLAY).getStateFromMeta(4));
      world.setBlockState(pos.add(27, 10, 58), ((BlockColored)Blocks.STAINED_HARDENED_CLAY).getStateFromMeta(4));
      world.setBlockState(pos.add(28, 10, 58), ((BlockColored)Blocks.STAINED_HARDENED_CLAY).getStateFromMeta(4));
      world.setBlockState(pos.add(29, 10, 58), ((BlockColored)Blocks.STAINED_HARDENED_CLAY).getStateFromMeta(4));
      world.setBlockState(pos.add(30, 10, 58), ((BlockColored)Blocks.STAINED_HARDENED_CLAY).getStateFromMeta(4));
      world.setBlockState(pos.add(31, 10, 58), ((BlockColored)Blocks.STAINED_HARDENED_CLAY).getStateFromMeta(4));
      world.setBlockState(pos.add(32, 10, 58), ((BlockColored)Blocks.STAINED_HARDENED_CLAY).getStateFromMeta(4));
      world.setBlockState(pos.add(33, 10, 58), ((BlockColored)Blocks.STAINED_HARDENED_CLAY).getStateFromMeta(4));
      world.setBlockState(pos.add(40, 10, 58), ((BlockColored)Blocks.STAINED_HARDENED_CLAY).getStateFromMeta(4));
      world.setBlockState(pos.add(42, 10, 58), ((BlockColored)Blocks.WOOL).getStateFromMeta(15));
      world.setBlockState(pos.add(34, 10, 59), ((BlockColored)Blocks.WOOL).getStateFromMeta(15));
      world.setBlockState(pos.add(35, 10, 59), ((BlockColored)Blocks.WOOL).getStateFromMeta(15));
      world.setBlockState(pos.add(36, 10, 59), ((BlockColored)Blocks.WOOL).getStateFromMeta(15));
      world.setBlockState(pos.add(37, 10, 59), ((BlockColored)Blocks.WOOL).getStateFromMeta(15));
      world.setBlockState(pos.add(41, 10, 59), ((BlockColored)Blocks.STAINED_HARDENED_CLAY).getStateFromMeta(4));
      world.setBlockState(pos.add(42, 10, 59), ((BlockColored)Blocks.WOOL).getStateFromMeta(15));
      world.setBlockState(pos.add(33, 10, 60), ((BlockColored)Blocks.WOOL).getStateFromMeta(15));
      world.setBlockState(pos.add(38, 10, 60), ((BlockColored)Blocks.WOOL).getStateFromMeta(15));
      world.setBlockState(pos.add(42, 10, 60), Blocks.STONE.getDefaultState());
      world.setBlockState(pos.add(43, 10, 60), Blocks.STONE.getDefaultState());
      world.setBlockState(pos.add(44, 10, 60), Blocks.STONE.getDefaultState());
      world.setBlockState(pos.add(45, 10, 60), Blocks.STONE.getDefaultState());
      world.setBlockState(pos.add(32, 10, 61), ((BlockColored)Blocks.WOOL).getStateFromMeta(15));
      world.setBlockState(pos.add(39, 10, 61), ((BlockColored)Blocks.WOOL).getStateFromMeta(15));
      world.setBlockState(pos.add(41, 10, 61), Blocks.STONE.getDefaultState());
      world.setBlockState(pos.add(46, 10, 61), Blocks.STONE.getDefaultState());
      world.setBlockState(pos.add(32, 10, 62), ((BlockColored)Blocks.WOOL).getStateFromMeta(15));
      world.setBlockState(pos.add(39, 10, 62), ((BlockColored)Blocks.WOOL).getStateFromMeta(15));
      world.setBlockState(pos.add(40, 10, 62), Blocks.STONE.getDefaultState());
      world.setBlockState(pos.add(47, 10, 62), Blocks.STONE.getDefaultState());
      world.setBlockState(pos.add(19, 10, 63), Blocks.OBSIDIAN.getDefaultState());
      world.setBlockState(pos.add(32, 10, 63), ((BlockColored)Blocks.WOOL).getStateFromMeta(15));
      world.setBlockState(pos.add(39, 10, 63), ((BlockColored)Blocks.WOOL).getStateFromMeta(15));
      world.setBlockState(pos.add(40, 10, 63), Blocks.STONE.getDefaultState());
      world.setBlockState(pos.add(47, 10, 63), Blocks.STONE.getDefaultState());
      world.setBlockState(pos.add(19, 10, 64), Blocks.OBSIDIAN.getDefaultState());
      world.setBlockState(pos.add(32, 10, 64), ((BlockColored)Blocks.WOOL).getStateFromMeta(15));
      world.setBlockState(pos.add(39, 10, 64), ((BlockColored)Blocks.WOOL).getStateFromMeta(15));
      world.setBlockState(pos.add(40, 10, 64), Blocks.STONE.getDefaultState());
      world.setBlockState(pos.add(47, 10, 64), Blocks.STONE.getDefaultState());
      world.setBlockState(pos.add(23, 10, 65), Blocks.OBSIDIAN.getDefaultState());
      world.setBlockState(pos.add(24, 10, 65), Blocks.OBSIDIAN.getDefaultState());
      world.setBlockState(pos.add(33, 10, 65), ((BlockColored)Blocks.WOOL).getStateFromMeta(15));
      world.setBlockState(pos.add(38, 10, 65), ((BlockColored)Blocks.WOOL).getStateFromMeta(15));
      world.setBlockState(pos.add(40, 10, 65), Blocks.STONE.getDefaultState());
      world.setBlockState(pos.add(47, 10, 65), Blocks.STONE.getDefaultState());
      world.setBlockState(pos.add(34, 10, 66), ((BlockColored)Blocks.WOOL).getStateFromMeta(15));
      world.setBlockState(pos.add(35, 10, 66), ((BlockColored)Blocks.WOOL).getStateFromMeta(15));
      world.setBlockState(pos.add(36, 10, 66), ((BlockColored)Blocks.WOOL).getStateFromMeta(15));
      world.setBlockState(pos.add(37, 10, 66), ((BlockColored)Blocks.WOOL).getStateFromMeta(15));
      world.setBlockState(pos.add(41, 10, 66), Blocks.STONE.getDefaultState());
      world.setBlockState(pos.add(46, 10, 66), Blocks.STONE.getDefaultState());
      world.setBlockState(pos.add(42, 10, 67), Blocks.STONE.getDefaultState());
      world.setBlockState(pos.add(43, 10, 67), Blocks.STONE.getDefaultState());
      world.setBlockState(pos.add(44, 10, 67), Blocks.STONE.getDefaultState());
      world.setBlockState(pos.add(45, 10, 67), Blocks.STONE.getDefaultState());
      world.setBlockState(pos.add(24, 11, 36), Blocks.QUARTZ_BLOCK.getDefaultState());
      world.setBlockState(pos.add(25, 11, 36), ((BlockColored)Blocks.STAINED_HARDENED_CLAY).getStateFromMeta(10));
      world.setBlockState(pos.add(27, 11, 36), ((BlockColored)Blocks.STAINED_HARDENED_CLAY).getStateFromMeta(10));
      world.setBlockState(pos.add(28, 11, 36), Blocks.QUARTZ_BLOCK.getDefaultState());
      world.setBlockState(pos.add(15, 11, 37), ((BlockColored)Blocks.STAINED_HARDENED_CLAY).getStateFromMeta(4));
      world.setBlockState(pos.add(16, 11, 37), ((BlockColored)Blocks.STAINED_HARDENED_CLAY).getStateFromMeta(4));
      world.setBlockState(pos.add(17, 11, 37), ((BlockColored)Blocks.STAINED_HARDENED_CLAY).getStateFromMeta(4));
      world.setBlockState(pos.add(18, 11, 37), ((BlockColored)Blocks.STAINED_HARDENED_CLAY).getStateFromMeta(4));
      world.setBlockState(pos.add(19, 11, 37), ((BlockColored)Blocks.STAINED_HARDENED_CLAY).getStateFromMeta(4));
      world.setBlockState(pos.add(20, 11, 37), ((BlockColored)Blocks.STAINED_HARDENED_CLAY).getStateFromMeta(4));
      world.setBlockState(pos.add(21, 11, 37), Blocks.QUARTZ_BLOCK.getDefaultState());
      world.setBlockState(pos.add(22, 11, 37), Blocks.QUARTZ_BLOCK.getDefaultState());
      world.setBlockState(pos.add(23, 11, 37), ((BlockColored)Blocks.STAINED_HARDENED_CLAY).getStateFromMeta(4));
      world.setBlockState(pos.add(29, 11, 37), ((BlockColored)Blocks.STAINED_HARDENED_CLAY).getStateFromMeta(4));
      world.setBlockState(pos.add(32, 11, 37), ((BlockColored)Blocks.STAINED_HARDENED_CLAY).getStateFromMeta(4));
      world.setBlockState(pos.add(33, 11, 37), ((BlockColored)Blocks.STAINED_HARDENED_CLAY).getStateFromMeta(4));
      world.setBlockState(pos.add(34, 11, 37), ((BlockColored)Blocks.STAINED_HARDENED_CLAY).getStateFromMeta(4));
      world.setBlockState(pos.add(35, 11, 37), ((BlockColored)Blocks.STAINED_HARDENED_CLAY).getStateFromMeta(4));
      world.setBlockState(pos.add(36, 11, 37), ((BlockColored)Blocks.STAINED_HARDENED_CLAY).getStateFromMeta(4));
      world.setBlockState(pos.add(37, 11, 37), ((BlockColored)Blocks.STAINED_HARDENED_CLAY).getStateFromMeta(4));
      world.setBlockState(pos.add(15, 11, 38), ((BlockColored)Blocks.STAINED_HARDENED_CLAY).getStateFromMeta(4));
      world.setBlockState(pos.add(16, 11, 38), ((BlockColored)Blocks.STAINED_HARDENED_CLAY).getStateFromMeta(4));
      world.setBlockState(pos.add(17, 11, 38), ((BlockColored)Blocks.STAINED_HARDENED_CLAY).getStateFromMeta(4));
      world.setBlockState(pos.add(18, 11, 38), ((BlockColored)Blocks.STAINED_HARDENED_CLAY).getStateFromMeta(4));
      world.setBlockState(pos.add(19, 11, 38), ((BlockColored)Blocks.STAINED_HARDENED_CLAY).getStateFromMeta(4));
      world.setBlockState(pos.add(20, 11, 38), ((BlockColored)Blocks.STAINED_HARDENED_CLAY).getStateFromMeta(4));
      world.setBlockState(pos.add(21, 11, 38), Blocks.QUARTZ_BLOCK.getDefaultState());
      world.setBlockState(pos.add(22, 11, 38), Blocks.QUARTZ_BLOCK.getDefaultState());
      world.setBlockState(pos.add(30, 11, 38), Blocks.QUARTZ_BLOCK.getDefaultState());
      world.setBlockState(pos.add(31, 11, 38), Blocks.QUARTZ_BLOCK.getDefaultState());
      world.setBlockState(pos.add(32, 11, 38), ((BlockColored)Blocks.STAINED_HARDENED_CLAY).getStateFromMeta(4));
      world.setBlockState(pos.add(33, 11, 38), ((BlockColored)Blocks.STAINED_HARDENED_CLAY).getStateFromMeta(4));
      world.setBlockState(pos.add(34, 11, 38), ((BlockColored)Blocks.STAINED_HARDENED_CLAY).getStateFromMeta(4));
      world.setBlockState(pos.add(35, 11, 38), ((BlockColored)Blocks.STAINED_HARDENED_CLAY).getStateFromMeta(4));
      world.setBlockState(pos.add(36, 11, 38), ((BlockColored)Blocks.STAINED_HARDENED_CLAY).getStateFromMeta(4));
      world.setBlockState(pos.add(37, 11, 38), ((BlockColored)Blocks.STAINED_HARDENED_CLAY).getStateFromMeta(4));
      world.setBlockState(pos.add(15, 11, 39), ((BlockColored)Blocks.STAINED_HARDENED_CLAY).getStateFromMeta(4));
      world.setBlockState(pos.add(20, 11, 39), ((BlockColored)Blocks.STAINED_HARDENED_CLAY).getStateFromMeta(4));
      world.setBlockState(pos.add(21, 11, 39), Blocks.QUARTZ_BLOCK.getDefaultState());
      world.setBlockState(pos.add(22, 11, 39), Blocks.QUARTZ_BLOCK.getDefaultState());
      world.setBlockState(pos.add(30, 11, 39), Blocks.QUARTZ_BLOCK.getDefaultState());
      world.setBlockState(pos.add(31, 11, 39), Blocks.QUARTZ_BLOCK.getDefaultState());
      world.setBlockState(pos.add(32, 11, 39), ((BlockColored)Blocks.STAINED_HARDENED_CLAY).getStateFromMeta(4));
      world.setBlockState(pos.add(37, 11, 39), ((BlockColored)Blocks.STAINED_HARDENED_CLAY).getStateFromMeta(4));
      world.setBlockState(pos.add(41, 11, 39), Blocks.STONE.getDefaultState());
      world.setBlockState(pos.add(15, 11, 40), ((BlockColored)Blocks.STAINED_HARDENED_CLAY).getStateFromMeta(4));
      world.setBlockState(pos.add(20, 11, 40), ((BlockColored)Blocks.STAINED_HARDENED_CLAY).getStateFromMeta(4));
      world.setBlockState(pos.add(21, 11, 40), Blocks.QUARTZ_BLOCK.getDefaultState());
      world.setBlockState(pos.add(22, 11, 40), Blocks.QUARTZ_BLOCK.getDefaultState());
      world.setBlockState(pos.add(23, 11, 40), ((BlockStaticLiquid)Blocks.LAVA).getStateFromMeta(10));
      world.setBlockState(pos.add(29, 11, 40), ((BlockStaticLiquid)Blocks.LAVA).getStateFromMeta(10));
      world.setBlockState(pos.add(30, 11, 40), Blocks.QUARTZ_BLOCK.getDefaultState());
      world.setBlockState(pos.add(31, 11, 40), Blocks.QUARTZ_BLOCK.getDefaultState());
      world.setBlockState(pos.add(32, 11, 40), ((BlockColored)Blocks.STAINED_HARDENED_CLAY).getStateFromMeta(4));
      world.setBlockState(pos.add(36, 11, 40), ((BlockColored)Blocks.STAINED_HARDENED_CLAY).getStateFromMeta(4));
      world.setBlockState(pos.add(37, 11, 40), ((BlockColored)Blocks.STAINED_HARDENED_CLAY).getStateFromMeta(4));
      world.setBlockState(pos.add(5, 11, 41), Blocks.STONE.getDefaultState());
      world.setBlockState(pos.add(6, 11, 41), Blocks.STAINED_GLASS.getStateFromMeta(11));
      world.setBlockState(pos.add(7, 11, 41), Blocks.STONE.getDefaultState());
      world.setBlockState(pos.add(16, 11, 41), Blocks.QUARTZ_BLOCK.getDefaultState());
      world.setBlockState(pos.add(20, 11, 41), Blocks.QUARTZ_BLOCK.getDefaultState());
      world.setBlockState(pos.add(21, 11, 41), Blocks.QUARTZ_BLOCK.getDefaultState());
      world.setBlockState(pos.add(22, 11, 41), Blocks.QUARTZ_BLOCK.getDefaultState());
      world.setBlockState(pos.add(23, 11, 41), Blocks.STONE.getDefaultState());
      world.setBlockState(pos.add(29, 11, 41), Blocks.STONE.getDefaultState());
      world.setBlockState(pos.add(30, 11, 41), Blocks.QUARTZ_BLOCK.getDefaultState());
      world.setBlockState(pos.add(31, 11, 41), Blocks.QUARTZ_BLOCK.getDefaultState());
      world.setBlockState(pos.add(32, 11, 41), Blocks.QUARTZ_BLOCK.getDefaultState());
      world.setBlockState(pos.add(36, 11, 41), Blocks.QUARTZ_BLOCK.getDefaultState());
      world.setBlockState(pos.add(4, 11, 42), Blocks.STONE.getDefaultState());
      world.setBlockState(pos.add(6, 11, 42), Blocks.GLOWSTONE.getDefaultState());
      world.setBlockState(pos.add(8, 11, 42), Blocks.STONE.getDefaultState());
      world.setBlockState(pos.add(16, 11, 42), Blocks.QUARTZ_BLOCK.getDefaultState());
      world.setBlockState(pos.add(20, 11, 42), Blocks.QUARTZ_BLOCK.getDefaultState());
      world.setBlockState(pos.add(21, 11, 42), Blocks.QUARTZ_BLOCK.getDefaultState());
      world.setBlockState(pos.add(22, 11, 42), Blocks.QUARTZ_BLOCK.getDefaultState());
      world.setBlockState(pos.add(23, 11, 42), Blocks.STONE.getDefaultState());
      world.setBlockState(pos.add(29, 11, 42), Blocks.STONE.getDefaultState());
      world.setBlockState(pos.add(30, 11, 42), Blocks.QUARTZ_BLOCK.getDefaultState());
      world.setBlockState(pos.add(31, 11, 42), Blocks.QUARTZ_BLOCK.getDefaultState());
      world.setBlockState(pos.add(32, 11, 42), Blocks.QUARTZ_BLOCK.getDefaultState());
      world.setBlockState(pos.add(36, 11, 42), Blocks.QUARTZ_BLOCK.getDefaultState());
      world.setBlockState(pos.add(4, 11, 43), Blocks.STONE.getDefaultState());
      world.setBlockState(pos.add(8, 11, 43), Blocks.STONE.getDefaultState());
      world.setBlockState(pos.add(15, 11, 43), ((BlockColored)Blocks.STAINED_HARDENED_CLAY).getStateFromMeta(4));
      world.setBlockState(pos.add(20, 11, 43), ((BlockColored)Blocks.STAINED_HARDENED_CLAY).getStateFromMeta(4));
      world.setBlockState(pos.add(21, 11, 43), Blocks.QUARTZ_BLOCK.getDefaultState());
