package com.slugterra.world.greatForge;
import java.util.Random;

import net.minecraft.block.BlockColored;
import net.minecraft.block.BlockStairs;
import net.minecraft.block.BlockStaticLiquid;
import net.minecraft.init.Blocks;
import net.minecraft.util.math.BlockPos;
import net.minecraft.world.World;
public class GreatWesternForgeStructure5 {
public boolean generate(World world, Random par2Random, BlockPos pos) {
      world.setBlockState(pos.add(25, 4, 9), Blocks.GRASS.getDefaultState());
      world.setBlockState(pos.add(26, 4, 9), Blocks.GRASS.getDefaultState());
      world.setBlockState(pos.add(27, 4, 9), Blocks.GRASS.getDefaultState());
      world.setBlockState(pos.add(28, 4, 9), Blocks.GRASS.getDefaultState());
      world.setBlockState(pos.add(29, 4, 9), Blocks.GRASS.getDefaultState());
      world.setBlockState(pos.add(30, 4, 9), Blocks.GRASS.getDefaultState());
      world.setBlockState(pos.add(21, 4, 10), Blocks.GRASS.getDefaultState());
      world.setBlockState(pos.add(22, 4, 10), Blocks.GRASS.getDefaultState());
      world.setBlockState(pos.add(23, 4, 10), Blocks.GRASS.getDefaultState());
      world.setBlockState(pos.add(24, 4, 10), Blocks.GRASS.getDefaultState());
      world.setBlockState(pos.add(25, 4, 10), Blocks.GRASS.getDefaultState());
      world.setBlockState(pos.add(26, 4, 10), Blocks.GRASS.getDefaultState());
      world.setBlockState(pos.add(27, 4, 10), Blocks.GRASS.getDefaultState());
      world.setBlockState(pos.add(28, 4, 10), Blocks.GRASS.getDefaultState());
      world.setBlockState(pos.add(29, 4, 10), Blocks.GRASS.getDefaultState());
      world.setBlockState(pos.add(30, 4, 10), Blocks.GRASS.getDefaultState());
      world.setBlockState(pos.add(21, 4, 11), Blocks.GRASS.getDefaultState());
      world.setBlockState(pos.add(22, 4, 11), Blocks.GRASS.getDefaultState());
      world.setBlockState(pos.add(23, 4, 11), Blocks.GRASS.getDefaultState());
      world.setBlockState(pos.add(24, 4, 11), Blocks.GRASS.getDefaultState());
      world.setBlockState(pos.add(25, 4, 11), Blocks.GRASS.getDefaultState());
      world.setBlockState(pos.add(26, 4, 11), Blocks.GRASS.getDefaultState());
      world.setBlockState(pos.add(27, 4, 11), Blocks.GRASS.getDefaultState());
      world.setBlockState(pos.add(28, 4, 11), Blocks.GRASS.getDefaultState());
      world.setBlockState(pos.add(29, 4, 11), Blocks.GRASS.getDefaultState());
      world.setBlockState(pos.add(30, 4, 11), Blocks.GRASS.getDefaultState());
      world.setBlockState(pos.add(25, 4, 12), Blocks.PLANKS.getDefaultState());
      world.setBlockState(pos.add(26, 4, 12), Blocks.PLANKS.getDefaultState());
      world.setBlockState(pos.add(27, 4, 12), Blocks.PLANKS.getDefaultState());
      world.setBlockState(pos.add(25, 4, 13), Blocks.PLANKS.getDefaultState());
      world.setBlockState(pos.add(26, 4, 13), Blocks.PLANKS.getDefaultState());
      world.setBlockState(pos.add(27, 4, 13), Blocks.PLANKS.getDefaultState());
      world.setBlockState(pos.add(25, 4, 14), Blocks.PLANKS.getDefaultState());
      world.setBlockState(pos.add(26, 4, 14), Blocks.PLANKS.getDefaultState());
      world.setBlockState(pos.add(27, 4, 14), Blocks.PLANKS.getDefaultState());
      world.setBlockState(pos.add(25, 4, 15), Blocks.PLANKS.getDefaultState());
      world.setBlockState(pos.add(26, 4, 15), Blocks.PLANKS.getDefaultState());
      world.setBlockState(pos.add(27, 4, 15), Blocks.PLANKS.getDefaultState());
      world.setBlockState(pos.add(25, 4, 16), Blocks.PLANKS.getDefaultState());
      world.setBlockState(pos.add(26, 4, 16), Blocks.PLANKS.getDefaultState());
      world.setBlockState(pos.add(27, 4, 16), Blocks.PLANKS.getDefaultState());
      world.setBlockState(pos.add(25, 4, 17), Blocks.PLANKS.getDefaultState());
      world.setBlockState(pos.add(26, 4, 17), Blocks.PLANKS.getDefaultState());
      world.setBlockState(pos.add(27, 4, 17), Blocks.PLANKS.getDefaultState());
      world.setBlockState(pos.add(25, 4, 18), Blocks.PLANKS.getDefaultState());
      world.setBlockState(pos.add(26, 4, 18), Blocks.PLANKS.getDefaultState());
      world.setBlockState(pos.add(27, 4, 18), Blocks.PLANKS.getDefaultState());
      world.setBlockState(pos.add(25, 4, 19), Blocks.PLANKS.getDefaultState());
      world.setBlockState(pos.add(26, 4, 19), Blocks.PLANKS.getDefaultState());
      world.setBlockState(pos.add(27, 4, 19), Blocks.PLANKS.getDefaultState());
      world.setBlockState(pos.add(25, 4, 20), Blocks.PLANKS.getDefaultState());
      world.setBlockState(pos.add(26, 4, 20), Blocks.PLANKS.getDefaultState());
      world.setBlockState(pos.add(27, 4, 20), Blocks.PLANKS.getDefaultState());
      world.setBlockState(pos.add(25, 4, 21), Blocks.PLANKS.getDefaultState());
      world.setBlockState(pos.add(26, 4, 21), Blocks.PLANKS.getDefaultState());
      world.setBlockState(pos.add(27, 4, 21), Blocks.PLANKS.getDefaultState());
      world.setBlockState(pos.add(25, 4, 22), Blocks.PLANKS.getDefaultState());
      world.setBlockState(pos.add(26, 4, 22), Blocks.PLANKS.getDefaultState());
      world.setBlockState(pos.add(27, 4, 22), Blocks.PLANKS.getDefaultState());
      world.setBlockState(pos.add(25, 4, 23), Blocks.PLANKS.getDefaultState());
      world.setBlockState(pos.add(26, 4, 23), Blocks.PLANKS.getDefaultState());
      world.setBlockState(pos.add(27, 4, 23), Blocks.PLANKS.getDefaultState());
      world.setBlockState(pos.add(25, 4, 24), Blocks.PLANKS.getDefaultState());
      world.setBlockState(pos.add(26, 4, 24), Blocks.PLANKS.getDefaultState());
      world.setBlockState(pos.add(27, 4, 24), Blocks.PLANKS.getDefaultState());
      world.setBlockState(pos.add(25, 4, 25), Blocks.PLANKS.getDefaultState());
      world.setBlockState(pos.add(26, 4, 25), Blocks.PLANKS.getDefaultState());
      world.setBlockState(pos.add(27, 4, 25), Blocks.PLANKS.getDefaultState());
      world.setBlockState(pos.add(25, 4, 26), Blocks.PLANKS.getDefaultState());
      world.setBlockState(pos.add(26, 4, 26), Blocks.PLANKS.getDefaultState());
      world.setBlockState(pos.add(27, 4, 26), Blocks.PLANKS.getDefaultState());
      world.setBlockState(pos.add(25, 4, 27), Blocks.PLANKS.getDefaultState());
      world.setBlockState(pos.add(26, 4, 27), Blocks.PLANKS.getDefaultState());
      world.setBlockState(pos.add(27, 4, 27), Blocks.PLANKS.getDefaultState());
      world.setBlockState(pos.add(25, 4, 28), Blocks.PLANKS.getDefaultState());
      world.setBlockState(pos.add(26, 4, 28), Blocks.PLANKS.getDefaultState());
      world.setBlockState(pos.add(27, 4, 28), Blocks.PLANKS.getDefaultState());
      world.setBlockState(pos.add(25, 4, 29), Blocks.PLANKS.getDefaultState());
      world.setBlockState(pos.add(26, 4, 29), Blocks.PLANKS.getDefaultState());
      world.setBlockState(pos.add(27, 4, 29), Blocks.PLANKS.getDefaultState());
      world.setBlockState(pos.add(24, 4, 30), ((BlockColored)Blocks.STAINED_HARDENED_CLAY).getStateFromMeta(4));
      world.setBlockState(pos.add(25, 4, 30), Blocks.PLANKS.getDefaultState());
      world.setBlockState(pos.add(26, 4, 30), Blocks.PLANKS.getDefaultState());
      world.setBlockState(pos.add(27, 4, 30), Blocks.PLANKS.getDefaultState());
      world.setBlockState(pos.add(28, 4, 30), ((BlockColored)Blocks.STAINED_HARDENED_CLAY).getStateFromMeta(4));
      world.setBlockState(pos.add(24, 4, 31), ((BlockColored)Blocks.STAINED_HARDENED_CLAY).getStateFromMeta(4));
      world.setBlockState(pos.add(28, 4, 31), ((BlockColored)Blocks.STAINED_HARDENED_CLAY).getStateFromMeta(4));
      world.setBlockState(pos.add(24, 4, 32), ((BlockColored)Blocks.STAINED_HARDENED_CLAY).getStateFromMeta(4));
      world.setBlockState(pos.add(28, 4, 32), ((BlockColored)Blocks.STAINED_HARDENED_CLAY).getStateFromMeta(4));
      world.setBlockState(pos.add(32, 4, 32), Blocks.STONE.getDefaultState());
      world.setBlockState(pos.add(35, 4, 32), Blocks.STONE.getDefaultState());
      world.setBlockState(pos.add(38, 4, 32), Blocks.STONE.getDefaultState());
      world.setBlockState(pos.add(41, 4, 32), Blocks.STONE.getDefaultState());
      world.setBlockState(pos.add(32, 4, 33), Blocks.STONE.getDefaultState());
      world.setBlockState(pos.add(35, 4, 33), Blocks.STONE.getDefaultState());
      world.setBlockState(pos.add(38, 4, 33), Blocks.STONE.getDefaultState());
      world.setBlockState(pos.add(41, 4, 33), Blocks.STONE.getDefaultState());
      world.setBlockState(pos.add(32, 4, 34), Blocks.STONE.getDefaultState());
      world.setBlockState(pos.add(35, 4, 34), Blocks.STONE.getDefaultState());
      world.setBlockState(pos.add(38, 4, 34), Blocks.STONE.getDefaultState());
      world.setBlockState(pos.add(41, 4, 34), Blocks.STONE.getDefaultState());
      world.setBlockState(pos.add(32, 4, 35), Blocks.STONE.getDefaultState());
      world.setBlockState(pos.add(36, 4, 35), Blocks.STONE.getDefaultState());
      world.setBlockState(pos.add(37, 4, 35), Blocks.STONE.getDefaultState());
      world.setBlockState(pos.add(38, 4, 35), Blocks.STONE.getDefaultState());
      world.setBlockState(pos.add(41, 4, 35), Blocks.STONE.getDefaultState());
      world.setBlockState(pos.add(33, 4, 36), Blocks.STONE.getDefaultState());
      world.setBlockState(pos.add(36, 4, 36), ((BlockStaticLiquid)Blocks.WATER).getStateFromMeta(1));
      world.setBlockState(pos.add(37, 4, 36), Blocks.WATER.getDefaultState());
      world.setBlockState(pos.add(38, 4, 36), Blocks.STONE.getDefaultState());
      world.setBlockState(pos.add(41, 4, 36), Blocks.STONE.getDefaultState());
      world.setBlockState(pos.add(26, 4, 37), Blocks.STONE.getDefaultState());
      world.setBlockState(pos.add(34, 4, 37), Blocks.STONE.getDefaultState());
      world.setBlockState(pos.add(36, 4, 37), ((BlockStaticLiquid)Blocks.WATER).getStateFromMeta(1));
      world.setBlockState(pos.add(37, 4, 37), Blocks.WATER.getDefaultState());
      world.setBlockState(pos.add(38, 4, 37), Blocks.STONE.getDefaultState());
      world.setBlockState(pos.add(41, 4, 37), Blocks.STONE.getDefaultState());
      world.setBlockState(pos.add(25, 4, 38), Blocks.STONE.getDefaultState());
      world.setBlockState(pos.add(26, 4, 38), Blocks.STONE.getDefaultState());
      world.setBlockState(pos.add(27, 4, 38), Blocks.STONE.getDefaultState());
      world.setBlockState(pos.add(35, 4, 38), Blocks.STONE.getDefaultState());
      world.setBlockState(pos.add(36, 4, 38), Blocks.STONE.getDefaultState());
      world.setBlockState(pos.add(37, 4, 38), Blocks.STONE.getDefaultState());
      world.setBlockState(pos.add(38, 4, 38), Blocks.STONE.getDefaultState());
      world.setBlockState(pos.add(39, 4, 38), ((BlockStaticLiquid)Blocks.WATER).getStateFromMeta(9));
      world.setBlockState(pos.add(40, 4, 38), ((BlockStaticLiquid)Blocks.WATER).getStateFromMeta(9));
      world.setBlockState(pos.add(41, 4, 38), Blocks.STONE.getDefaultState());
      world.setBlockState(pos.add(25, 4, 39), Blocks.STONE.getDefaultState());
      world.setBlockState(pos.add(26, 4, 39), Blocks.STONE.getDefaultState());
      world.setBlockState(pos.add(27, 4, 39), Blocks.STONE.getDefaultState());
      world.setBlockState(pos.add(38, 4, 39), Blocks.STONE.getDefaultState());
      world.setBlockState(pos.add(39, 4, 39), ((BlockStaticLiquid)Blocks.WATER).getStateFromMeta(8));
      world.setBlockState(pos.add(40, 4, 39), ((BlockStaticLiquid)Blocks.WATER).getStateFromMeta(8));
      world.setBlockState(pos.add(41, 4, 39), Blocks.STONE.getDefaultState());
      world.setBlockState(pos.add(25, 4, 40), Blocks.STONE.getDefaultState());
      world.setBlockState(pos.add(26, 4, 40), Blocks.STONE.getDefaultState());
      world.setBlockState(pos.add(27, 4, 40), Blocks.STONE.getDefaultState());
      world.setBlockState(pos.add(39, 4, 40), Blocks.STONE.getDefaultState());
      world.setBlockState(pos.add(40, 4, 40), Blocks.STONE.getDefaultState());
      world.setBlockState(pos.add(5, 4, 41), Blocks.STONE.getDefaultState());
      world.setBlockState(pos.add(6, 4, 41), Blocks.STONE.getDefaultState());
      world.setBlockState(pos.add(7, 4, 41), Blocks.STONE.getDefaultState());
      world.setBlockState(pos.add(25, 4, 41), Blocks.STONE.getDefaultState());
      world.setBlockState(pos.add(26, 4, 41), Blocks.STONE.getDefaultState());
      world.setBlockState(pos.add(27, 4, 41), Blocks.STONE.getDefaultState());
      world.setBlockState(pos.add(4, 4, 42), Blocks.STONE.getDefaultState());
      world.setBlockState(pos.add(8, 4, 42), Blocks.STONE.getDefaultState());
      world.setBlockState(pos.add(25, 4, 42), Blocks.STONE.getDefaultState());
      world.setBlockState(pos.add(26, 4, 42), Blocks.STONE.getDefaultState());
      world.setBlockState(pos.add(27, 4, 42), Blocks.STONE.getDefaultState());
      world.setBlockState(pos.add(4, 4, 43), Blocks.STONE.getDefaultState());
      world.setBlockState(pos.add(8, 4, 43), Blocks.STONE.getDefaultState());
      world.setBlockState(pos.add(25, 4, 43), Blocks.STONE.getDefaultState());
      world.setBlockState(pos.add(26, 4, 43), Blocks.STONE.getDefaultState());
      world.setBlockState(pos.add(27, 4, 43), Blocks.STONE.getDefaultState());
      world.setBlockState(pos.add(4, 4, 44), Blocks.STONE.getDefaultState());
      world.setBlockState(pos.add(8, 4, 44), Blocks.STONE.getDefaultState());
      world.setBlockState(pos.add(25, 4, 44), Blocks.STONE.getDefaultState());
      world.setBlockState(pos.add(26, 4, 44), Blocks.STONE.getDefaultState());
      world.setBlockState(pos.add(27, 4, 44), Blocks.STONE.getDefaultState());
      world.setBlockState(pos.add(5, 4, 45), Blocks.STONE.getDefaultState());
      world.setBlockState(pos.add(6, 4, 45), Blocks.STONE.getDefaultState());
      world.setBlockState(pos.add(7, 4, 45), Blocks.STONE.getDefaultState());
      world.setBlockState(pos.add(25, 4, 45), Blocks.STONE.getDefaultState());
      world.setBlockState(pos.add(26, 4, 45), Blocks.STONE.getDefaultState());
      world.setBlockState(pos.add(27, 4, 45), Blocks.STONE.getDefaultState());
      world.setBlockState(pos.add(25, 4, 46), Blocks.STONE.getDefaultState());
      world.setBlockState(pos.add(26, 4, 46), Blocks.STONE.getDefaultState());
      world.setBlockState(pos.add(27, 4, 46), Blocks.STONE.getDefaultState());
      world.setBlockState(pos.add(25, 4, 47), Blocks.STONE.getDefaultState());
      world.setBlockState(pos.add(26, 4, 47), Blocks.STONE.getDefaultState());
      world.setBlockState(pos.add(27, 4, 47), Blocks.STONE.getDefaultState());
      world.setBlockState(pos.add(25, 4, 48), Blocks.STONE.getDefaultState());
      world.setBlockState(pos.add(26, 4, 48), Blocks.STONE.getDefaultState());
      world.setBlockState(pos.add(27, 4, 48), Blocks.STONE.getDefaultState());
      world.setBlockState(pos.add(25, 4, 49), Blocks.STONE.getDefaultState());
      world.setBlockState(pos.add(26, 4, 49), Blocks.STONE.getDefaultState());
      world.setBlockState(pos.add(27, 4, 49), Blocks.STONE.getDefaultState());
      world.setBlockState(pos.add(25, 4, 50), Blocks.STONE.getDefaultState());
      world.setBlockState(pos.add(26, 4, 50), Blocks.STONE.getDefaultState());
      world.setBlockState(pos.add(27, 4, 50), Blocks.STONE.getDefaultState());
      world.setBlockState(pos.add(26, 4, 51), Blocks.STONE.getDefaultState());
      world.setBlockState(pos.add(27, 5, 9), Blocks.OAK_FENCE.getDefaultState());
      world.setBlockState(pos.add(25, 5, 10), Blocks.OAK_FENCE.getDefaultState());
      world.setBlockState(pos.add(25, 5, 12), Blocks.OAK_FENCE.getDefaultState());
      world.setBlockState(pos.add(27, 5, 12), Blocks.OAK_FENCE.getDefaultState());
      world.setBlockState(pos.add(25, 5, 13), Blocks.OAK_FENCE.getDefaultState());
      world.setBlockState(pos.add(27, 5, 13), Blocks.OAK_FENCE.getDefaultState());
      world.setBlockState(pos.add(25, 5, 14), Blocks.OAK_FENCE.getDefaultState());
      world.setBlockState(pos.add(27, 5, 14), Blocks.OAK_FENCE.getDefaultState());
      world.setBlockState(pos.add(25, 5, 15), Blocks.OAK_FENCE.getDefaultState());
      world.setBlockState(pos.add(27, 5, 15), Blocks.OAK_FENCE.getDefaultState());
      world.setBlockState(pos.add(25, 5, 16), Blocks.OAK_FENCE.getDefaultState());
      world.setBlockState(pos.add(27, 5, 16), Blocks.OAK_FENCE.getDefaultState());
      world.setBlockState(pos.add(25, 5, 17), Blocks.OAK_FENCE.getDefaultState());
      world.setBlockState(pos.add(27, 5, 17), Blocks.OAK_FENCE.getDefaultState());
      world.setBlockState(pos.add(25, 5, 18), Blocks.OAK_FENCE.getDefaultState());
      world.setBlockState(pos.add(27, 5, 18), Blocks.OAK_FENCE.getDefaultState());
      world.setBlockState(pos.add(25, 5, 19), Blocks.OAK_FENCE.getDefaultState());
      world.setBlockState(pos.add(27, 5, 19), Blocks.OAK_FENCE.getDefaultState());
      world.setBlockState(pos.add(25, 5, 20), Blocks.OAK_FENCE.getDefaultState());
      world.setBlockState(pos.add(27, 5, 20), Blocks.OAK_FENCE.getDefaultState());
      world.setBlockState(pos.add(25, 5, 21), Blocks.OAK_FENCE.getDefaultState());
      world.setBlockState(pos.add(27, 5, 21), Blocks.OAK_FENCE.getDefaultState());
      world.setBlockState(pos.add(25, 5, 22), Blocks.OAK_FENCE.getDefaultState());
      world.setBlockState(pos.add(27, 5, 22), Blocks.OAK_FENCE.getDefaultState());
      world.setBlockState(pos.add(25, 5, 23), Blocks.OAK_FENCE.getDefaultState());
      world.setBlockState(pos.add(27, 5, 23), Blocks.OAK_FENCE.getDefaultState());
      world.setBlockState(pos.add(25, 5, 24), Blocks.OAK_FENCE.getDefaultState());
      world.setBlockState(pos.add(27, 5, 24), Blocks.OAK_FENCE.getDefaultState());
      world.setBlockState(pos.add(25, 5, 25), Blocks.OAK_FENCE.getDefaultState());
      world.setBlockState(pos.add(27, 5, 25), Blocks.OAK_FENCE.getDefaultState());
      world.setBlockState(pos.add(25, 5, 26), Blocks.OAK_FENCE.getDefaultState());
      world.setBlockState(pos.add(27, 5, 26), Blocks.OAK_FENCE.getDefaultState());
      world.setBlockState(pos.add(25, 5, 27), Blocks.OAK_FENCE.getDefaultState());
      world.setBlockState(pos.add(27, 5, 27), Blocks.OAK_FENCE.getDefaultState());
      world.setBlockState(pos.add(25, 5, 28), Blocks.OAK_FENCE.getDefaultState());
      world.setBlockState(pos.add(27, 5, 28), Blocks.OAK_FENCE.getDefaultState());
      world.setBlockState(pos.add(25, 5, 29), Blocks.OAK_FENCE.getDefaultState());
      world.setBlockState(pos.add(27, 5, 29), Blocks.OAK_FENCE.getDefaultState());
      world.setBlockState(pos.add(25, 5, 30), Blocks.OAK_FENCE.getDefaultState());
      world.setBlockState(pos.add(27, 5, 30), Blocks.OAK_FENCE.getDefaultState());
      world.setBlockState(pos.add(24, 5, 31), ((BlockColored)Blocks.STAINED_HARDENED_CLAY).getStateFromMeta(4));
      world.setBlockState(pos.add(25, 5, 31), ((BlockStairs)Blocks.NETHER_BRICK_STAIRS).getStateFromMeta(2));
      world.setBlockState(pos.add(26, 5, 31), ((BlockStairs)Blocks.NETHER_BRICK_STAIRS).getStateFromMeta(2));
      world.setBlockState(pos.add(27, 5, 31), ((BlockStairs)Blocks.NETHER_BRICK_STAIRS).getStateFromMeta(2));
      world.setBlockState(pos.add(28, 5, 31), ((BlockColored)Blocks.STAINED_HARDENED_CLAY).getStateFromMeta(4));
      world.setBlockState(pos.add(24, 5, 32), ((BlockColored)Blocks.STAINED_HARDENED_CLAY).getStateFromMeta(4));
      world.setBlockState(pos.add(28, 5, 32), ((BlockColored)Blocks.STAINED_HARDENED_CLAY).getStateFromMeta(4));
      world.setBlockState(pos.add(33, 5, 32), Blocks.STONE.getDefaultState());
      world.setBlockState(pos.add(34, 5, 32), Blocks.STONE.getDefaultState());
      world.setBlockState(pos.add(39, 5, 32), Blocks.STONE.getDefaultState());
      world.setBlockState(pos.add(40, 5, 32), Blocks.STONE.getDefaultState());
      world.setBlockState(pos.add(33, 5, 33), Blocks.STONE.getDefaultState());
      world.setBlockState(pos.add(34, 5, 33), Blocks.STONE.getDefaultState());
      world.setBlockState(pos.add(39, 5, 33), Blocks.STONE.getDefaultState());
      world.setBlockState(pos.add(40, 5, 33), Blocks.STONE.getDefaultState());
      world.setBlockState(pos.add(33, 5, 34), Blocks.STONE.getDefaultState());
      world.setBlockState(pos.add(34, 5, 34), Blocks.STONE.getDefaultState());
      world.setBlockState(pos.add(39, 5, 34), Blocks.STONE.getDefaultState());
      world.setBlockState(pos.add(40, 5, 34), Blocks.STONE.getDefaultState());
      world.setBlockState(pos.add(33, 5, 35), Blocks.STONE.getDefaultState());
      world.setBlockState(pos.add(34, 5, 35), Blocks.STONE.getDefaultState());
      world.setBlockState(pos.add(35, 5, 35), Blocks.STONE.getDefaultState());
      world.setBlockState(pos.add(39, 5, 35), Blocks.STONE.getDefaultState());
      world.setBlockState(pos.add(40, 5, 35), Blocks.STONE.getDefaultState());
      world.setBlockState(pos.add(26, 5, 36), Blocks.STONE.getDefaultState());
      world.setBlockState(pos.add(34, 5, 36), Blocks.STONE.getDefaultState());
      world.setBlockState(pos.add(35, 5, 36), Blocks.STONE.getDefaultState());
      world.setBlockState(pos.add(36, 5, 36), Blocks.STONE.getDefaultState());
      world.setBlockState(pos.add(37, 5, 36), Blocks.STONE.getDefaultState());
      world.setBlockState(pos.add(38, 5, 36), Blocks.STONE.getDefaultState());
      world.setBlockState(pos.add(39, 5, 36), Blocks.STONE.getDefaultState());
      world.setBlockState(pos.add(40, 5, 36), Blocks.STONE.getDefaultState());
      world.setBlockState(pos.add(23, 5, 37), Blocks.STAINED_GLASS.getStateFromMeta(1));
      world.setBlockState(pos.add(25, 5, 37), Blocks.STONE.getDefaultState());
      world.setBlockState(pos.add(26, 5, 37), Blocks.LAVA.getDefaultState());
      world.setBlockState(pos.add(27, 5, 37), Blocks.STONE.getDefaultState());
      world.setBlockState(pos.add(35, 5, 37), Blocks.STONE.getDefaultState());
      world.setBlockState(pos.add(36, 5, 37), Blocks.STONE.getDefaultState());
      world.setBlockState(pos.add(37, 5, 37), Blocks.STONE.getDefaultState());
      world.setBlockState(pos.add(38, 5, 37), Blocks.STONE.getDefaultState());
      world.setBlockState(pos.add(39, 5, 37), Blocks.STONE.getDefaultState());
      world.setBlockState(pos.add(40, 5, 37), Blocks.STONE.getDefaultState());
      world.setBlockState(pos.add(23, 5, 38), Blocks.STAINED_GLASS.getStateFromMeta(1));
      world.setBlockState(pos.add(24, 5, 38), Blocks.STONE.getDefaultState());
      world.setBlockState(pos.add(25, 5, 38), Blocks.LAVA.getDefaultState());
      world.setBlockState(pos.add(26, 5, 38), ((BlockStaticLiquid)Blocks.LAVA).getStateFromMeta(2));
      world.setBlockState(pos.add(27, 5, 38), Blocks.LAVA.getDefaultState());
      world.setBlockState(pos.add(28, 5, 38), Blocks.STONE.getDefaultState());
      world.setBlockState(pos.add(29, 5, 38), Blocks.STAINED_GLASS.getStateFromMeta(14));
      world.setBlockState(pos.add(38, 5, 38), Blocks.STONE.getDefaultState());
      world.setBlockState(pos.add(39, 5, 38), ((BlockStaticLiquid)Blocks.WATER).getStateFromMeta(1));
      world.setBlockState(pos.add(40, 5, 38), ((BlockStaticLiquid)Blocks.WATER).getStateFromMeta(1));
      world.setBlockState(pos.add(41, 5, 38), Blocks.STONE.getDefaultState());
      world.setBlockState(pos.add(23, 5, 39), Blocks.STAINED_GLASS.getStateFromMeta(1));
      world.setBlockState(pos.add(24, 5, 39), Blocks.STONE.getDefaultState());
      world.setBlockState(pos.add(25, 5, 39), Blocks.LAVA.getDefaultState());
      world.setBlockState(pos.add(26, 5, 39), ((BlockStaticLiquid)Blocks.LAVA).getStateFromMeta(2));
      world.setBlockState(pos.add(27, 5, 39), Blocks.LAVA.getDefaultState());
      world.setBlockState(pos.add(28, 5, 39), Blocks.STONE.getDefaultState());
      world.setBlockState(pos.add(29, 5, 39), Blocks.STAINED_GLASS.getStateFromMeta(14));
      world.setBlockState(pos.add(38, 5, 39), Blocks.STONE.getDefaultState());
      world.setBlockState(pos.add(39, 5, 39), Blocks.WATER.getDefaultState());
      world.setBlockState(pos.add(40, 5, 39), Blocks.WATER.getDefaultState());
      world.setBlockState(pos.add(41, 5, 39), Blocks.STONE.getDefaultState());
      world.setBlockState(pos.add(23, 5, 40), Blocks.STAINED_GLASS.getStateFromMeta(1));
      world.setBlockState(pos.add(24, 5, 40), Blocks.STONE.getDefaultState());
      world.setBlockState(pos.add(25, 5, 40), Blocks.LAVA.getDefaultState());
      world.setBlockState(pos.add(26, 5, 40), ((BlockStaticLiquid)Blocks.LAVA).getStateFromMeta(2));
      world.setBlockState(pos.add(27, 5, 40), Blocks.LAVA.getDefaultState());
      world.setBlockState(pos.add(28, 5, 40), Blocks.STONE.getDefaultState());
      world.setBlockState(pos.add(29, 5, 40), Blocks.STAINED_GLASS.getStateFromMeta(14));
      world.setBlockState(pos.add(39, 5, 40), Blocks.STONE.getDefaultState());
      world.setBlockState(pos.add(40, 5, 40), Blocks.STONE.getDefaultState());
      world.setBlockState(pos.add(5, 5, 41), Blocks.STONE.getDefaultState());
      world.setBlockState(pos.add(6, 5, 41), Blocks.STONE.getDefaultState());
      world.setBlockState(pos.add(7, 5, 41), Blocks.STONE.getDefaultState());
      world.setBlockState(pos.add(24, 5, 41), Blocks.STONE.getDefaultState());
      world.setBlockState(pos.add(25, 5, 41), Blocks.LAVA.getDefaultState());
      world.setBlockState(pos.add(26, 5, 41), ((BlockStaticLiquid)Blocks.LAVA).getStateFromMeta(2));
      world.setBlockState(pos.add(27, 5, 41), Blocks.LAVA.getDefaultState());
      world.setBlockState(pos.add(28, 5, 41), Blocks.STONE.getDefaultState());
      world.setBlockState(pos.add(4, 5, 42), Blocks.STONE.getDefaultState());
      world.setBlockState(pos.add(8, 5, 42), Blocks.STONE.getDefaultState());
      world.setBlockState(pos.add(24, 5, 42), Blocks.STONE.getDefaultState());
      world.setBlockState(pos.add(25, 5, 42), Blocks.LAVA.getDefaultState());
      world.setBlockState(pos.add(26, 5, 42), ((BlockStaticLiquid)Blocks.LAVA).getStateFromMeta(2));
      world.setBlockState(pos.add(27, 5, 42), Blocks.LAVA.getDefaultState());
      world.setBlockState(pos.add(28, 5, 42), Blocks.STONE.getDefaultState());
      world.setBlockState(pos.add(4, 5, 43), Blocks.STONE.getDefaultState());
      world.setBlockState(pos.add(8, 5, 43), Blocks.STONE.getDefaultState());
      world.setBlockState(pos.add(23, 5, 43), Blocks.STAINED_GLASS.getStateFromMeta(1));
      world.setBlockState(pos.add(24, 5, 43), Blocks.STONE.getDefaultState());
      world.setBlockState(pos.add(25, 5, 43), Blocks.LAVA.getDefaultState());
      world.setBlockState(pos.add(26, 5, 43), ((BlockStaticLiquid)Blocks.LAVA).getStateFromMeta(2));
      world.setBlockState(pos.add(27, 5, 43), Blocks.LAVA.getDefaultState());
      world.setBlockState(pos.add(28, 5, 43), Blocks.STONE.getDefaultState());
      world.setBlockState(pos.add(29, 5, 43), Blocks.STAINED_GLASS.getStateFromMeta(14));
      world.setBlockState(pos.add(4, 5, 44), Blocks.STONE.getDefaultState());
      world.setBlockState(pos.add(8, 5, 44), Blocks.STONE.getDefaultState());
      world.setBlockState(pos.add(22, 5, 44), ((BlockColored)Blocks.STAINED_HARDENED_CLAY).getStateFromMeta(4));
      world.setBlockState(pos.add(23, 5, 44), Blocks.STAINED_GLASS.getStateFromMeta(1));
      world.setBlockState(pos.add(24, 5, 44), Blocks.STONE.getDefaultState());
      world.setBlockState(pos.add(25, 5, 44), Blocks.LAVA.getDefaultState());
      world.setBlockState(pos.add(26, 5, 44), ((BlockStaticLiquid)Blocks.LAVA).getStateFromMeta(2));
      world.setBlockState(pos.add(27, 5, 44), Blocks.LAVA.getDefaultState());
      world.setBlockState(pos.add(28, 5, 44), Blocks.STONE.getDefaultState());
      world.setBlockState(pos.add(29, 5, 44), Blocks.STAINED_GLASS.getStateFromMeta(14));
      world.setBlockState(pos.add(5, 5, 45), Blocks.STONE.getDefaultState());
      world.setBlockState(pos.add(6, 5, 45), Blocks.STONE.getDefaultState());
      world.setBlockState(pos.add(7, 5, 45), Blocks.STONE.getDefaultState());
      world.setBlockState(pos.add(23, 5, 45), Blocks.STAINED_GLASS.getStateFromMeta(1));
      world.setBlockState(pos.add(24, 5, 45), Blocks.STONE.getDefaultState());
      world.setBlockState(pos.add(25, 5, 45), Blocks.LAVA.getDefaultState());
      world.setBlockState(pos.add(26, 5, 45), ((BlockStaticLiquid)Blocks.LAVA).getStateFromMeta(2));
      world.setBlockState(pos.add(27, 5, 45), Blocks.LAVA.getDefaultState());
      world.setBlockState(pos.add(28, 5, 45), Blocks.STONE.getDefaultState());
      world.setBlockState(pos.add(29, 5, 45), Blocks.STAINED_GLASS.getStateFromMeta(14));
      world.setBlockState(pos.add(23, 5, 46), Blocks.STAINED_GLASS.getStateFromMeta(1));
      world.setBlockState(pos.add(24, 5, 46), Blocks.STONE.getDefaultState());
      world.setBlockState(pos.add(25, 5, 46), Blocks.LAVA.getDefaultState());
      world.setBlockState(pos.add(26, 5, 46), ((BlockStaticLiquid)Blocks.LAVA).getStateFromMeta(2));
      world.setBlockState(pos.add(27, 5, 46), Blocks.LAVA.getDefaultState());
      world.setBlockState(pos.add(28, 5, 46), Blocks.STONE.getDefaultState());
      world.setBlockState(pos.add(24, 5, 47), Blocks.STONE.getDefaultState());
      world.setBlockState(pos.add(25, 5, 47), Blocks.LAVA.getDefaultState());
      world.setBlockState(pos.add(26, 5, 47), ((BlockStaticLiquid)Blocks.LAVA).getStateFromMeta(2));
      world.setBlockState(pos.add(27, 5, 47), Blocks.LAVA.getDefaultState());
      world.setBlockState(pos.add(28, 5, 47), Blocks.STONE.getDefaultState());
      world.setBlockState(pos.add(23, 5, 48), Blocks.STAINED_GLASS.getStateFromMeta(1));
      world.setBlockState(pos.add(24, 5, 48), Blocks.STONE.getDefaultState());
      world.setBlockState(pos.add(25, 5, 48), Blocks.LAVA.getDefaultState());
      world.setBlockState(pos.add(26, 5, 48), ((BlockStaticLiquid)Blocks.LAVA).getStateFromMeta(2));
      world.setBlockState(pos.add(27, 5, 48), Blocks.LAVA.getDefaultState());
      world.setBlockState(pos.add(28, 5, 48), Blocks.STONE.getDefaultState());
      world.setBlockState(pos.add(29, 5, 48), Blocks.STAINED_GLASS.getStateFromMeta(14));
      world.setBlockState(pos.add(23, 5, 49), Blocks.STAINED_GLASS.getStateFromMeta(1));
      world.setBlockState(pos.add(24, 5, 49), Blocks.STONE.getDefaultState());
      world.setBlockState(pos.add(25, 5, 49), Blocks.LAVA.getDefaultState());
      world.setBlockState(pos.add(26, 5, 49), ((BlockStaticLiquid)Blocks.LAVA).getStateFromMeta(2));
      world.setBlockState(pos.add(27, 5, 49), Blocks.LAVA.getDefaultState());
      world.setBlockState(pos.add(28, 5, 49), Blocks.STONE.getDefaultState());
      world.setBlockState(pos.add(29, 5, 49), Blocks.STAINED_GLASS.getStateFromMeta(14));
      world.setBlockState(pos.add(23, 5, 50), Blocks.STAINED_GLASS.getStateFromMeta(1));
      world.setBlockState(pos.add(24, 5, 50), Blocks.STONE.getDefaultState());
      world.setBlockState(pos.add(25, 5, 50), Blocks.LAVA.getDefaultState());
      world.setBlockState(pos.add(26, 5, 50), ((BlockStaticLiquid)Blocks.LAVA).getStateFromMeta(2));
      world.setBlockState(pos.add(27, 5, 50), Blocks.LAVA.getDefaultState());
      world.setBlockState(pos.add(28, 5, 50), Blocks.STONE.getDefaultState());
      world.setBlockState(pos.add(29, 5, 50), Blocks.STAINED_GLASS.getStateFromMeta(14));
      world.setBlockState(pos.add(25, 5, 51), Blocks.STONE.getDefaultState());
      world.setBlockState(pos.add(26, 5, 51), Blocks.LAVA.getDefaultState());
      world.setBlockState(pos.add(27, 5, 51), Blocks.STONE.getDefaultState());
      world.setBlockState(pos.add(26, 5, 52), Blocks.STONE.getDefaultState());
      world.setBlockState(pos.add(24, 6, 32), ((BlockColored)Blocks.STAINED_HARDENED_CLAY).getStateFromMeta(4));
      world.setBlockState(pos.add(25, 6, 32), ((BlockStairs)Blocks.NETHER_BRICK_STAIRS).getStateFromMeta(2));
      world.setBlockState(pos.add(26, 6, 32), ((BlockStairs)Blocks.NETHER_BRICK_STAIRS).getStateFromMeta(2));
      world.setBlockState(pos.add(27, 6, 32), ((BlockStairs)Blocks.NETHER_BRICK_STAIRS).getStateFromMeta(2));
      world.setBlockState(pos.add(28, 6, 32), ((BlockColored)Blocks.STAINED_HARDENED_CLAY).getStateFromMeta(4));
      world.setBlockState(pos.add(13, 6, 33), ((BlockColored)Blocks.STAINED_HARDENED_CLAY).getStateFromMeta(4));
      world.setBlockState(pos.add(14, 6, 33), ((BlockColored)Blocks.STAINED_HARDENED_CLAY).getStateFromMeta(4));
      world.setBlockState(pos.add(15, 6, 33), ((BlockColored)Blocks.STAINED_HARDENED_CLAY).getStateFromMeta(4));
      world.setBlockState(pos.add(16, 6, 33), ((BlockColored)Blocks.STAINED_HARDENED_CLAY).getStateFromMeta(4));
      world.setBlockState(pos.add(17, 6, 33), ((BlockColored)Blocks.STAINED_HARDENED_CLAY).getStateFromMeta(4));
      world.setBlockState(pos.add(18, 6, 33), ((BlockColored)Blocks.STAINED_HARDENED_CLAY).getStateFromMeta(4));
      world.setBlockState(pos.add(19, 6, 33), ((BlockColored)Blocks.STAINED_HARDENED_CLAY).getStateFromMeta(4));
      world.setBlockState(pos.add(20, 6, 33), ((BlockColored)Blocks.STAINED_HARDENED_CLAY).getStateFromMeta(4));
      world.setBlockState(pos.add(21, 6, 33), ((BlockColored)Blocks.STAINED_HARDENED_CLAY).getStateFromMeta(4));
      world.setBlockState(pos.add(22, 6, 33), ((BlockColored)Blocks.STAINED_HARDENED_CLAY).getStateFromMeta(4));
      world.setBlockState(pos.add(23, 6, 33), ((BlockColored)Blocks.STAINED_HARDENED_CLAY).getStateFromMeta(4));
      world.setBlockState(pos.add(24, 6, 33), ((BlockColored)Blocks.STAINED_HARDENED_CLAY).getStateFromMeta(4));
      world.setBlockState(pos.add(25, 6, 33), Blocks.STONE.getDefaultState());
      world.setBlockState(pos.add(26, 6, 33), Blocks.STONE.getDefaultState());
      world.setBlockState(pos.add(27, 6, 33), Blocks.STONE.getDefaultState());
      world.setBlockState(pos.add(28, 6, 33), Blocks.STONE.getDefaultState());
      world.setBlockState(pos.add(29, 6, 33), ((BlockColored)Blocks.STAINED_HARDENED_CLAY).getStateFromMeta(4));
      world.setBlockState(pos.add(30, 6, 33), ((BlockColored)Blocks.STAINED_HARDENED_CLAY).getStateFromMeta(4));
      world.setBlockState(pos.add(31, 6, 33), ((BlockColored)Blocks.STAINED_HARDENED_CLAY).getStateFromMeta(4));
      world.setBlockState(pos.add(32, 6, 33), ((BlockColored)Blocks.STAINED_HARDENED_CLAY).getStateFromMeta(4));
      world.setBlockState(pos.add(33, 6, 33), ((BlockColored)Blocks.STAINED_HARDENED_CLAY).getStateFromMeta(4));
      world.setBlockState(pos.add(34, 6, 33), ((BlockColored)Blocks.STAINED_HARDENED_CLAY).getStateFromMeta(4));
      world.setBlockState(pos.add(35, 6, 33), ((BlockColored)Blocks.STAINED_HARDENED_CLAY).getStateFromMeta(4));
      world.setBlockState(pos.add(36, 6, 33), ((BlockColored)Blocks.STAINED_HARDENED_CLAY).getStateFromMeta(4));
      world.setBlockState(pos.add(37, 6, 33), ((BlockColored)Blocks.STAINED_HARDENED_CLAY).getStateFromMeta(4));
      world.setBlockState(pos.add(38, 6, 33), ((BlockColored)Blocks.STAINED_HARDENED_CLAY).getStateFromMeta(4));
      world.setBlockState(pos.add(39, 6, 33), ((BlockColored)Blocks.STAINED_HARDENED_CLAY).getStateFromMeta(4));
      world.setBlockState(pos.add(40, 6, 33), ((BlockColored)Blocks.STAINED_HARDENED_CLAY).getStateFromMeta(4));
      world.setBlockState(pos.add(41, 6, 33), ((BlockColored)Blocks.STAINED_HARDENED_CLAY).getStateFromMeta(4));
      world.setBlockState(pos.add(42, 6, 33), ((BlockColored)Blocks.STAINED_HARDENED_CLAY).getStateFromMeta(4));
      world.setBlockState(pos.add(43, 6, 33), ((BlockColored)Blocks.STAINED_HARDENED_CLAY).getStateFromMeta(4));
      world.setBlockState(pos.add(44, 6, 33), ((BlockColored)Blocks.STAINED_HARDENED_CLAY).getStateFromMeta(4));
      world.setBlockState(pos.add(45, 6, 33), ((BlockColored)Blocks.STAINED_HARDENED_CLAY).getStateFromMeta(4));
      world.setBlockState(pos.add(46, 6, 33), ((BlockColored)Blocks.STAINED_HARDENED_CLAY).getStateFromMeta(4));
      world.setBlockState(pos.add(47, 6, 33), ((BlockColored)Blocks.STAINED_HARDENED_CLAY).getStateFromMeta(4));
      world.setBlockState(pos.add(13, 6, 34), ((BlockColored)Blocks.STAINED_HARDENED_CLAY).getStateFromMeta(4));
      world.setBlockState(pos.add(14, 6, 34), Blocks.STONE.getDefaultState());
      world.setBlockState(pos.add(15, 6, 34), Blocks.STONE.getDefaultState());
      world.setBlockState(pos.add(16, 6, 34), Blocks.STONE.getDefaultState());
      world.setBlockState(pos.add(17, 6, 34), Blocks.STONE.getDefaultState());
      world.setBlockState(pos.add(18, 6, 34), Blocks.STONE.getDefaultState());
      world.setBlockState(pos.add(19, 6, 34), Blocks.STONE.getDefaultState());
      world.setBlockState(pos.add(20, 6, 34), Blocks.STONE.getDefaultState());
      world.setBlockState(pos.add(21, 6, 34), Blocks.STONE.getDefaultState());
      world.setBlockState(pos.add(22, 6, 34), Blocks.STONE.getDefaultState());
      world.setBlockState(pos.add(23, 6, 34), ((BlockColored)Blocks.STAINED_HARDENED_CLAY).getStateFromMeta(4));
      world.setBlockState(pos.add(24, 6, 34), Blocks.STONE.getDefaultState());
      world.setBlockState(pos.add(25, 6, 34), Blocks.STONE.getDefaultState());
      world.setBlockState(pos.add(26, 6, 34), Blocks.STONE.getDefaultState());
      world.setBlockState(pos.add(27, 6, 34), Blocks.STONE.getDefaultState());
      world.setBlockState(pos.add(28, 6, 34), Blocks.STONE.getDefaultState());
      world.setBlockState(pos.add(29, 6, 34), ((BlockColored)Blocks.STAINED_HARDENED_CLAY).getStateFromMeta(4));
      world.setBlockState(pos.add(30, 6, 34), Blocks.STONE.getDefaultState());
      world.setBlockState(pos.add(31, 6, 34), Blocks.STONE.getDefaultState());
      world.setBlockState(pos.add(32, 6, 34), Blocks.STONE.getDefaultState());
      world.setBlockState(pos.add(33, 6, 34), Blocks.STONE.getDefaultState());
      world.setBlockState(pos.add(34, 6, 34), Blocks.STONE.getDefaultState());
      world.setBlockState(pos.add(35, 6, 34), Blocks.STONE.getDefaultState());
      world.setBlockState(pos.add(36, 6, 34), Blocks.STONE.getDefaultState());
      world.setBlockState(pos.add(37, 6, 34), Blocks.STONE.getDefaultState());
      world.setBlockState(pos.add(38, 6, 34), Blocks.STONE.getDefaultState());
      world.setBlockState(pos.add(39, 6, 34), Blocks.STONE.getDefaultState());
      world.setBlockState(pos.add(40, 6, 34), Blocks.STONE.getDefaultState());
      world.setBlockState(pos.add(41, 6, 34), Blocks.STONE.getDefaultState());
      world.setBlockState(pos.add(42, 6, 34), Blocks.STONE.getDefaultState());
      world.setBlockState(pos.add(43, 6, 34), Blocks.STONE.getDefaultState());
      world.setBlockState(pos.add(44, 6, 34), Blocks.STONE.getDefaultState());
      world.setBlockState(pos.add(45, 6, 34), Blocks.STONE.getDefaultState());
      world.setBlockState(pos.add(46, 6, 34), Blocks.STONE.getDefaultState());
      world.setBlockState(pos.add(47, 6, 34), ((BlockColored)Blocks.STAINED_HARDENED_CLAY).getStateFromMeta(4));
      world.setBlockState(pos.add(13, 6, 35), ((BlockColored)Blocks.STAINED_HARDENED_CLAY).getStateFromMeta(4));
      world.setBlockState(pos.add(14, 6, 35), Blocks.STONE.getDefaultState());
      world.setBlockState(pos.add(15, 6, 35), Blocks.STONE.getDefaultState());
      world.setBlockState(pos.add(16, 6, 35), Blocks.STONE.getDefaultState());
      world.setBlockState(pos.add(17, 6, 35), Blocks.STONE.getDefaultState());
      world.setBlockState(pos.add(18, 6, 35), Blocks.STONE.getDefaultState());
      world.setBlockState(pos.add(19, 6, 35), Blocks.STONE.getDefaultState());
      world.setBlockState(pos.add(20, 6, 35), Blocks.STONE.getDefaultState());
      world.setBlockState(pos.add(21, 6, 35), Blocks.STONE.getDefaultState());
      world.setBlockState(pos.add(22, 6, 35), Blocks.STONE.getDefaultState());
      world.setBlockState(pos.add(23, 6, 35), ((BlockColored)Blocks.STAINED_HARDENED_CLAY).getStateFromMeta(4));
      world.setBlockState(pos.add(24, 6, 35), Blocks.STONE.getDefaultState());
      world.setBlockState(pos.add(25, 6, 35), Blocks.STONE.getDefaultState());
      world.setBlockState(pos.add(26, 6, 35), Blocks.STONE.getDefaultState());
      world.setBlockState(pos.add(27, 6, 35), Blocks.STONE.getDefaultState());
      world.setBlockState(pos.add(28, 6, 35), Blocks.STONE.getDefaultState());
      world.setBlockState(pos.add(29, 6, 35), ((BlockColored)Blocks.STAINED_HARDENED_CLAY).getStateFromMeta(4));
      world.setBlockState(pos.add(30, 6, 35), Blocks.STONE.getDefaultState());
      world.setBlockState(pos.add(31, 6, 35), Blocks.STONE.getDefaultState());
      world.setBlockState(pos.add(32, 6, 35), Blocks.STONE.getDefaultState());
      world.setBlockState(pos.add(33, 6, 35), Blocks.STONE.getDefaultState());
      world.setBlockState(pos.add(34, 6, 35), Blocks.STONE.getDefaultState());
      world.setBlockState(pos.add(35, 6, 35), Blocks.STONE.getDefaultState());
      world.setBlockState(pos.add(36, 6, 35), Blocks.STONE.getDefaultState());
      world.setBlockState(pos.add(37, 6, 35), Blocks.STONE.getDefaultState());
      world.setBlockState(pos.add(38, 6, 35), Blocks.STONE.getDefaultState());
      world.setBlockState(pos.add(39, 6, 35), Blocks.STONE.getDefaultState());
      world.setBlockState(pos.add(40, 6, 35), Blocks.STONE.getDefaultState());
      world.setBlockState(pos.add(41, 6, 35), Blocks.STONE.getDefaultState());
      world.setBlockState(pos.add(42, 6, 35), Blocks.STONE.getDefaultState());
      world.setBlockState(pos.add(43, 6, 35), Blocks.STONE.getDefaultState());
      world.setBlockState(pos.add(44, 6, 35), Blocks.STONE.getDefaultState());
      world.setBlockState(pos.add(45, 6, 35), Blocks.STONE.getDefaultState());
      world.setBlockState(pos.add(46, 6, 35), Blocks.STONE.getDefaultState());
      world.setBlockState(pos.add(47, 6, 35), ((BlockColored)Blocks.STAINED_HARDENED_CLAY).getStateFromMeta(4));
      world.setBlockState(pos.add(13, 6, 36), ((BlockColored)Blocks.STAINED_HARDENED_CLAY).getStateFromMeta(4));
      world.setBlockState(pos.add(14, 6, 36), Blocks.STONE.getDefaultState());
      world.setBlockState(pos.add(15, 6, 36), Blocks.STONE.getDefaultState());
      world.setBlockState(pos.add(16, 6, 36), Blocks.STONE.getDefaultState());
      world.setBlockState(pos.add(17, 6, 36), Blocks.STONE.getDefaultState());
      world.setBlockState(pos.add(18, 6, 36), Blocks.STONE.getDefaultState());
      world.setBlockState(pos.add(19, 6, 36), Blocks.STONE.getDefaultState());
      world.setBlockState(pos.add(20, 6, 36), Blocks.STONE.getDefaultState());
      world.setBlockState(pos.add(21, 6, 36), Blocks.STONE.getDefaultState());
      world.setBlockState(pos.add(22, 6, 36), Blocks.STONE.getDefaultState());
      world.setBlockState(pos.add(23, 6, 36), ((BlockColored)Blocks.STAINED_HARDENED_CLAY).getStateFromMeta(4));
      world.setBlockState(pos.add(24, 6, 36), ((BlockColored)Blocks.STAINED_HARDENED_CLAY).getStateFromMeta(4));
      world.setBlockState(pos.add(25, 6, 36), ((BlockColored)Blocks.STAINED_HARDENED_CLAY).getStateFromMeta(4));
      world.setBlockState(pos.add(26, 6, 36), ((BlockColored)Blocks.STAINED_HARDENED_CLAY).getStateFromMeta(4));
      world.setBlockState(pos.add(27, 6, 36), ((BlockColored)Blocks.STAINED_HARDENED_CLAY).getStateFromMeta(4));
      world.setBlockState(pos.add(28, 6, 36), ((BlockColored)Blocks.STAINED_HARDENED_CLAY).getStateFromMeta(4));
      world.setBlockState(pos.add(29, 6, 36), ((BlockColored)Blocks.STAINED_HARDENED_CLAY).getStateFromMeta(4));
      world.setBlockState(pos.add(30, 6, 36), Blocks.STONE.getDefaultState());
      world.setBlockState(pos.add(31, 6, 36), Blocks.STONE.getDefaultState());
      world.setBlockState(pos.add(32, 6, 36), Blocks.STONE.getDefaultState());
      world.setBlockState(pos.add(33, 6, 36), Blocks.STONE.getDefaultState());
      world.setBlockState(pos.add(34, 6, 36), Blocks.STONE.getDefaultState());
      world.setBlockState(pos.add(35, 6, 36), Blocks.STONE.getDefaultState());
      world.setBlockState(pos.add(36, 6, 36), Blocks.STONE.getDefaultState());
      world.setBlockState(pos.add(37, 6, 36), Blocks.STONE.getDefaultState());
      world.setBlockState(pos.add(38, 6, 36), Blocks.STONE.getDefaultState());
      world.setBlockState(pos.add(39, 6, 36), Blocks.STONE.getDefaultState());
      world.setBlockState(pos.add(40, 6, 36), ((BlockColored)Blocks.STAINED_HARDENED_CLAY).getStateFromMeta(4));
      world.setBlockState(pos.add(41, 6, 36), Blocks.STONE.getDefaultState());
      world.setBlockState(pos.add(42, 6, 36), ((BlockColored)Blocks.STAINED_HARDENED_CLAY).getStateFromMeta(4));
      world.setBlockState(pos.add(43, 6, 36), Blocks.STONE.getDefaultState());
      world.setBlockState(pos.add(44, 6, 36), Blocks.STONE.getDefaultState());
      world.setBlockState(pos.add(45, 6, 36), Blocks.STONE.getDefaultState());
      world.setBlockState(pos.add(46, 6, 36), Blocks.STONE.getDefaultState());
      world.setBlockState(pos.add(47, 6, 36), ((BlockColored)Blocks.STAINED_HARDENED_CLAY).getStateFromMeta(4));
      world.setBlockState(pos.add(13, 6, 37), ((BlockColored)Blocks.STAINED_HARDENED_CLAY).getStateFromMeta(4));
      world.setBlockState(pos.add(14, 6, 37), Blocks.STONE.getDefaultState());
      world.setBlockState(pos.add(15, 6, 37), ((BlockColored)Blocks.STAINED_HARDENED_CLAY).getStateFromMeta(4));
      world.setBlockState(pos.add(16, 6, 37), ((BlockColored)Blocks.STAINED_HARDENED_CLAY).getStateFromMeta(4));
      world.setBlockState(pos.add(17, 6, 37), ((BlockColored)Blocks.STAINED_HARDENED_CLAY).getStateFromMeta(4));
      world.setBlockState(pos.add(18, 6, 37), ((BlockColored)Blocks.STAINED_HARDENED_CLAY).getStateFromMeta(4));
      world.setBlockState(pos.add(19, 6, 37), ((BlockColored)Blocks.STAINED_HARDENED_CLAY).getStateFromMeta(4));
      world.setBlockState(pos.add(20, 6, 37), ((BlockColored)Blocks.STAINED_HARDENED_CLAY).getStateFromMeta(4));
      world.setBlockState(pos.add(22, 6, 37), ((BlockColored)Blocks.STAINED_HARDENED_CLAY).getStateFromMeta(4));
      world.setBlockState(pos.add(23, 6, 37), ((BlockColored)Blocks.STAINED_HARDENED_CLAY).getStateFromMeta(4));
      world.setBlockState(pos.add(24, 6, 37), ((BlockColored)Blocks.STAINED_HARDENED_CLAY).getStateFromMeta(4));
      world.setBlockState(pos.add(25, 6, 37), ((BlockColored)Blocks.STAINED_HARDENED_CLAY).getStateFromMeta(4));
      world.setBlockState(pos.add(26, 6, 37), Blocks.STAINED_GLASS.getStateFromMeta(1));
      world.setBlockState(pos.add(27, 6, 37), ((BlockColored)Blocks.STAINED_HARDENED_CLAY).getStateFromMeta(4));
      world.setBlockState(pos.add(28, 6, 37), ((BlockColored)Blocks.STAINED_HARDENED_CLAY).getStateFromMeta(4));
      world.setBlockState(pos.add(29, 6, 37), ((BlockColored)Blocks.STAINED_HARDENED_CLAY).getStateFromMeta(4));
      world.setBlockState(pos.add(30, 6, 37), Blocks.STONE.getDefaultState());
      world.setBlockState(pos.add(31, 6, 37), Blocks.STONE.getDefaultState());
      world.setBlockState(pos.add(32, 6, 37), ((BlockColored)Blocks.STAINED_HARDENED_CLAY).getStateFromMeta(4));
      world.setBlockState(pos.add(33, 6, 37), ((BlockColored)Blocks.STAINED_HARDENED_CLAY).getStateFromMeta(4));
      world.setBlockState(pos.add(34, 6, 37), ((BlockColored)Blocks.STAINED_HARDENED_CLAY).getStateFromMeta(4));
      world.setBlockState(pos.add(35, 6, 37), ((BlockColored)Blocks.STAINED_HARDENED_CLAY).getStateFromMeta(4));
      world.setBlockState(pos.add(36, 6, 37), ((BlockColored)Blocks.STAINED_HARDENED_CLAY).getStateFromMeta(4));
      world.setBlockState(pos.add(37, 6, 37), ((BlockColored)Blocks.STAINED_HARDENED_CLAY).getStateFromMeta(4));
      world.setBlockState(pos.add(38, 6, 37), Blocks.STONE.getDefaultState());
      world.setBlockState(pos.add(39, 6, 37), ((BlockColored)Blocks.STAINED_HARDENED_CLAY).getStateFromMeta(4));
      world.setBlockState(pos.add(40, 6, 37), Blocks.STONE.getDefaultState());
      world.setBlockState(pos.add(41, 6, 37), Blocks.STONE.getDefaultState());
      world.setBlockState(pos.add(42, 6, 37), Blocks.STONE.getDefaultState());
      world.setBlockState(pos.add(43, 6, 37), ((BlockColored)Blocks.STAINED_HARDENED_CLAY).getStateFromMeta(4));
      world.setBlockState(pos.add(44, 6, 37), Blocks.STONE.getDefaultState());
      world.setBlockState(pos.add(45, 6, 37), Blocks.STONE.getDefaultState());
      world.setBlockState(pos.add(46, 6, 37), Blocks.STONE.getDefaultState());
      world.setBlockState(pos.add(47, 6, 37), ((BlockColored)Blocks.STAINED_HARDENED_CLAY).getStateFromMeta(4));
      world.setBlockState(pos.add(13, 6, 38), ((BlockColored)Blocks.STAINED_HARDENED_CLAY).getStateFromMeta(4));
      world.setBlockState(pos.add(14, 6, 38), Blocks.STONE.getDefaultState());
      world.setBlockState(pos.add(15, 6, 38), ((BlockColored)Blocks.STAINED_HARDENED_CLAY).getStateFromMeta(4));
      world.setBlockState(pos.add(16, 6, 38), ((BlockColored)Blocks.STAINED_HARDENED_CLAY).getStateFromMeta(4));
      world.setBlockState(pos.add(17, 6, 38), ((BlockColored)Blocks.STAINED_HARDENED_CLAY).getStateFromMeta(4));
      world.setBlockState(pos.add(18, 6, 38), ((BlockColored)Blocks.STAINED_HARDENED_CLAY).getStateFromMeta(4));
      world.setBlockState(pos.add(19, 6, 38), ((BlockColored)Blocks.STAINED_HARDENED_CLAY).getStateFromMeta(4));
      world.setBlockState(pos.add(20, 6, 38), ((BlockColored)Blocks.STAINED_HARDENED_CLAY).getStateFromMeta(4));
      world.setBlockState(pos.add(21, 6, 38), ((BlockColored)Blocks.STAINED_HARDENED_CLAY).getStateFromMeta(4));
      world.setBlockState(pos.add(22, 6, 38), ((BlockColored)Blocks.STAINED_HARDENED_CLAY).getStateFromMeta(4));
      world.setBlockState(pos.add(23, 6, 38), ((BlockStaticLiquid)Blocks.LAVA).getStateFromMeta(4));
      world.setBlockState(pos.add(24, 6, 38), ((BlockColored)Blocks.STAINED_HARDENED_CLAY).getStateFromMeta(4));
      world.setBlockState(pos.add(25, 6, 38), Blocks.GLASS.getDefaultState());
      world.setBlockState(pos.add(26, 6, 38), Blocks.STAINED_GLASS.getStateFromMeta(1));
      world.setBlockState(pos.add(27, 6, 38), Blocks.GLASS.getDefaultState());
      world.setBlockState(pos.add(28, 6, 38), ((BlockColored)Blocks.STAINED_HARDENED_CLAY).getStateFromMeta(4));
      world.setBlockState(pos.add(29, 6, 38), ((BlockStaticLiquid)Blocks.LAVA).getStateFromMeta(4));
      world.setBlockState(pos.add(30, 6, 38), ((BlockColored)Blocks.STAINED_HARDENED_CLAY).getStateFromMeta(4));
      world.setBlockState(pos.add(31, 6, 38), ((BlockColored)Blocks.STAINED_HARDENED_CLAY).getStateFromMeta(4));
      world.setBlockState(pos.add(32, 6, 38), ((BlockColored)Blocks.STAINED_HARDENED_CLAY).getStateFromMeta(4));
      world.setBlockState(pos.add(33, 6, 38), ((BlockColored)Blocks.STAINED_HARDENED_CLAY).getStateFromMeta(4));
      world.setBlockState(pos.add(34, 6, 38), ((BlockColored)Blocks.STAINED_HARDENED_CLAY).getStateFromMeta(4));
      world.setBlockState(pos.add(35, 6, 38), ((BlockColored)Blocks.STAINED_HARDENED_CLAY).getStateFromMeta(4));
      world.setBlockState(pos.add(36, 6, 38), ((BlockColored)Blocks.STAINED_HARDENED_CLAY).getStateFromMeta(4));
      world.setBlockState(pos.add(37, 6, 38), ((BlockColored)Blocks.STAINED_HARDENED_CLAY).getStateFromMeta(4));
      world.setBlockState(pos.add(38, 6, 38), ((BlockColored)Blocks.STAINED_HARDENED_CLAY).getStateFromMeta(4));
      world.setBlockState(pos.add(39, 6, 38), Blocks.STONE.getDefaultState());
      world.setBlockState(pos.add(40, 6, 38), Blocks.STONE.getDefaultState());
      world.setBlockState(pos.add(41, 6, 38), Blocks.STONE.getDefaultState());
      world.setBlockState(pos.add(42, 6, 38), Blocks.STONE.getDefaultState());
      world.setBlockState(pos.add(43, 6, 38), Blocks.STONE.getDefaultState());
      world.setBlockState(pos.add(44, 6, 38), ((BlockColored)Blocks.STAINED_HARDENED_CLAY).getStateFromMeta(4));
      world.setBlockState(pos.add(45, 6, 38), Blocks.STONE.getDefaultState());
      world.setBlockState(pos.add(46, 6, 38), Blocks.STONE.getDefaultState());
      world.setBlockState(pos.add(47, 6, 38), ((BlockColored)Blocks.STAINED_HARDENED_CLAY).getStateFromMeta(4));
      world.setBlockState(pos.add(13, 6, 39), ((BlockColored)Blocks.STAINED_HARDENED_CLAY).getStateFromMeta(4));
      world.setBlockState(pos.add(14, 6, 39), Blocks.STONE.getDefaultState());
      world.setBlockState(pos.add(15, 6, 39), ((BlockColored)Blocks.STAINED_HARDENED_CLAY).getStateFromMeta(4));
      world.setBlockState(pos.add(16, 6, 39), ((BlockColored)Blocks.STAINED_HARDENED_CLAY).getStateFromMeta(4));
      world.setBlockState(pos.add(17, 6, 39), ((BlockColored)Blocks.STAINED_HARDENED_CLAY).getStateFromMeta(4));
      world.setBlockState(pos.add(18, 6, 39), ((BlockColored)Blocks.STAINED_HARDENED_CLAY).getStateFromMeta(4));
      world.setBlockState(pos.add(19, 6, 39), ((BlockColored)Blocks.STAINED_HARDENED_CLAY).getStateFromMeta(4));
      world.setBlockState(pos.add(20, 6, 39), ((BlockColored)Blocks.STAINED_HARDENED_CLAY).getStateFromMeta(4));
      world.setBlockState(pos.add(21, 6, 39), ((BlockColored)Blocks.STAINED_HARDENED_CLAY).getStateFromMeta(4));
      world.setBlockState(pos.add(22, 6, 39), ((BlockColored)Blocks.STAINED_HARDENED_CLAY).getStateFromMeta(4));
      world.setBlockState(pos.add(23, 6, 39), ((BlockStaticLiquid)Blocks.LAVA).getStateFromMeta(2));
      world.setBlockState(pos.add(24, 6, 39), Blocks.GLOWSTONE.getDefaultState());
      world.setBlockState(pos.add(25, 6, 39), Blocks.GLASS.getDefaultState());
      world.setBlockState(pos.add(26, 6, 39), Blocks.STAINED_GLASS.getStateFromMeta(1));
      world.setBlockState(pos.add(27, 6, 39), Blocks.GLASS.getDefaultState());
      world.setBlockState(pos.add(28, 6, 39), Blocks.GLOWSTONE.getDefaultState());
      world.setBlockState(pos.add(29, 6, 39), ((BlockStaticLiquid)Blocks.LAVA).getStateFromMeta(2));
      world.setBlockState(pos.add(30, 6, 39), ((BlockColored)Blocks.STAINED_HARDENED_CLAY).getStateFromMeta(4));
      world.setBlockState(pos.add(31, 6, 39), ((BlockColored)Blocks.STAINED_HARDENED_CLAY).getStateFromMeta(4));
      world.setBlockState(pos.add(32, 6, 39), ((BlockColored)Blocks.STAINED_HARDENED_CLAY).getStateFromMeta(4));
      world.setBlockState(pos.add(33, 6, 39), ((BlockColored)Blocks.STAINED_HARDENED_CLAY).getStateFromMeta(4));
      world.setBlockState(pos.add(34, 6, 39), ((BlockColored)Blocks.STAINED_HARDENED_CLAY).getStateFromMeta(4));
      world.setBlockState(pos.add(35, 6, 39), ((BlockColored)Blocks.STAINED_HARDENED_CLAY).getStateFromMeta(4));
      world.setBlockState(pos.add(36, 6, 39), ((BlockColored)Blocks.STAINED_HARDENED_CLAY).getStateFromMeta(4));
      world.setBlockState(pos.add(37, 6, 39), ((BlockColored)Blocks.STAINED_HARDENED_CLAY).getStateFromMeta(4));
      world.setBlockState(pos.add(38, 6, 39), ((BlockColored)Blocks.STAINED_HARDENED_CLAY).getStateFromMeta(4));
      world.setBlockState(pos.add(39, 6, 39), Blocks.STONE.getDefaultState());
      world.setBlockState(pos.add(40, 6, 39), Blocks.STONE.getDefaultState());
      world.setBlockState(pos.add(41, 6, 39), Blocks.STONE.getDefaultState());
      world.setBlockState(pos.add(42, 6, 39), Blocks.STONE.getDefaultState());
      world.setBlockState(pos.add(43, 6, 39), Blocks.STONE.getDefaultState());
      world.setBlockState(pos.add(44, 6, 39), ((BlockColored)Blocks.STAINED_HARDENED_CLAY).getStateFromMeta(4));
      world.setBlockState(pos.add(45, 6, 39), Blocks.STONE.getDefaultState());
      world.setBlockState(pos.add(46, 6, 39), Blocks.STONE.getDefaultState());
      world.setBlockState(pos.add(47, 6, 39), ((BlockColored)Blocks.STAINED_HARDENED_CLAY).getStateFromMeta(4));
      world.setBlockState(pos.add(13, 6, 40), ((BlockColored)Blocks.STAINED_HARDENED_CLAY).getStateFromMeta(4));
      world.setBlockState(pos.add(14, 6, 40), Blocks.STONE.getDefaultState());
      world.setBlockState(pos.add(15, 6, 40), ((BlockColored)Blocks.STAINED_HARDENED_CLAY).getStateFromMeta(4));
      world.setBlockState(pos.add(16, 6, 40), ((BlockColored)Blocks.STAINED_HARDENED_CLAY).getStateFromMeta(4));
      world.setBlockState(pos.add(17, 6, 40), ((BlockColored)Blocks.STAINED_HARDENED_CLAY).getStateFromMeta(4));
      world.setBlockState(pos.add(18, 6, 40), ((BlockColored)Blocks.STAINED_HARDENED_CLAY).getStateFromMeta(4));
      world.setBlockState(pos.add(19, 6, 40), ((BlockColored)Blocks.STAINED_HARDENED_CLAY).getStateFromMeta(4));
      world.setBlockState(pos.add(20, 6, 40), ((BlockColored)Blocks.STAINED_HARDENED_CLAY).getStateFromMeta(4));
      world.setBlockState(pos.add(21, 6, 40), ((BlockColored)Blocks.STAINED_HARDENED_CLAY).getStateFromMeta(4));
      world.setBlockState(pos.add(22, 6, 40), ((BlockColored)Blocks.STAINED_HARDENED_CLAY).getStateFromMeta(4));
      world.setBlockState(pos.add(23, 6, 40), ((BlockStaticLiquid)Blocks.LAVA).getStateFromMeta(10));
      world.setBlockState(pos.add(24, 6, 40), Blocks.GLOWSTONE.getDefaultState());
      world.setBlockState(pos.add(25, 6, 40), Blocks.GLASS.getDefaultState());
      world.setBlockState(pos.add(26, 6, 40), Blocks.STAINED_GLASS.getStateFromMeta(1));
      world.setBlockState(pos.add(27, 6, 40), Blocks.GLASS.getDefaultState());
      world.setBlockState(pos.add(28, 6, 40), Blocks.GLOWSTONE.getDefaultState());
      world.setBlockState(pos.add(29, 6, 40), ((BlockStaticLiquid)Blocks.LAVA).getStateFromMeta(10));
      world.setBlockState(pos.add(30, 6, 40), ((BlockColored)Blocks.STAINED_HARDENED_CLAY).getStateFromMeta(4));
      world.setBlockState(pos.add(31, 6, 40), ((BlockColored)Blocks.STAINED_HARDENED_CLAY).getStateFromMeta(4));
      world.setBlockState(pos.add(32, 6, 40), ((BlockColored)Blocks.STAINED_HARDENED_CLAY).getStateFromMeta(4));
      world.setBlockState(pos.add(33, 6, 40), ((BlockColored)Blocks.STAINED_HARDENED_CLAY).getStateFromMeta(4));
      world.setBlockState(pos.add(34, 6, 40), ((BlockColored)Blocks.STAINED_HARDENED_CLAY).getStateFromMeta(4));
      world.setBlockState(pos.add(35, 6, 40), ((BlockColored)Blocks.STAINED_HARDENED_CLAY).getStateFromMeta(4));
      world.setBlockState(pos.add(36, 6, 40), ((BlockColored)Blocks.STAINED_HARDENED_CLAY).getStateFromMeta(4));
      world.setBlockState(pos.add(37, 6, 40), ((BlockColored)Blocks.STAINED_HARDENED_CLAY).getStateFromMeta(4));
      world.setBlockState(pos.add(38, 6, 40), ((BlockColored)Blocks.STAINED_HARDENED_CLAY).getStateFromMeta(4));
      world.setBlockState(pos.add(39, 6, 40), Blocks.STONE.getDefaultState());
      world.setBlockState(pos.add(40, 6, 40), Blocks.STONE.getDefaultState());
      world.setBlockState(pos.add(41, 6, 40), Blocks.STONE.getDefaultState());
      world.setBlockState(pos.add(42, 6, 40), Blocks.STONE.getDefaultState());
      world.setBlockState(pos.add(43, 6, 40), Blocks.STONE.getDefaultState());
      world.setBlockState(pos.add(44, 6, 40), ((BlockColored)Blocks.STAINED_HARDENED_CLAY).getStateFromMeta(4));
      world.setBlockState(pos.add(45, 6, 40), Blocks.STONE.getDefaultState());
      world.setBlockState(pos.add(46, 6, 40), Blocks.STONE.getDefaultState());
      world.setBlockState(pos.add(47, 6, 40), ((BlockColored)Blocks.STAINED_HARDENED_CLAY).getStateFromMeta(4));
      world.setBlockState(pos.add(5, 6, 41), Blocks.STONE.getDefaultState());
      world.setBlockState(pos.add(6, 6, 41), Blocks.STONE.getDefaultState());
      world.setBlockState(pos.add(7, 6, 41), Blocks.STONE.getDefaultState());
      world.setBlockState(pos.add(13, 6, 41), ((BlockColored)Blocks.STAINED_HARDENED_CLAY).getStateFromMeta(4));
      world.setBlockState(pos.add(14, 6, 41), Blocks.STONE.getDefaultState());
      world.setBlockState(pos.add(15, 6, 41), Blocks.STONE.getDefaultState());
      world.setBlockState(pos.add(16, 6, 41), Blocks.STONE.getDefaultState());
      world.setBlockState(pos.add(17, 6, 41), ((BlockColored)Blocks.STAINED_HARDENED_CLAY).getStateFromMeta(4));
      world.setBlockState(pos.add(18, 6, 41), ((BlockColored)Blocks.STAINED_HARDENED_CLAY).getStateFromMeta(4));
      world.setBlockState(pos.add(19, 6, 41), ((BlockColored)Blocks.STAINED_HARDENED_CLAY).getStateFromMeta(4));
      world.setBlockState(pos.add(20, 6, 41), ((BlockColored)Blocks.STAINED_HARDENED_CLAY).getStateFromMeta(4));
      world.setBlockState(pos.add(21, 6, 41), ((BlockColored)Blocks.STAINED_HARDENED_CLAY).getStateFromMeta(4));
      world.setBlockState(pos.add(22, 6, 41), ((BlockColored)Blocks.STAINED_HARDENED_CLAY).getStateFromMeta(4));
      world.setBlockState(pos.add(23, 6, 41), ((BlockColored)Blocks.STAINED_HARDENED_CLAY).getStateFromMeta(4));
      world.setBlockState(pos.add(24, 6, 41), Blocks.GLOWSTONE.getDefaultState());
      world.setBlockState(pos.add(25, 6, 41), Blocks.GLASS.getDefaultState());
      world.setBlockState(pos.add(26, 6, 41), Blocks.STAINED_GLASS.getStateFromMeta(1));
      world.setBlockState(pos.add(27, 6, 41), Blocks.GLASS.getDefaultState());
      world.setBlockState(pos.add(28, 6, 41), Blocks.GLOWSTONE.getDefaultState());
      world.setBlockState(pos.add(29, 6, 41), ((BlockColored)Blocks.STAINED_HARDENED_CLAY).getStateFromMeta(4));
      world.setBlockState(pos.add(30, 6, 41), ((BlockColored)Blocks.STAINED_HARDENED_CLAY).getStateFromMeta(4));
      world.setBlockState(pos.add(31, 6, 41), ((BlockColored)Blocks.STAINED_HARDENED_CLAY).getStateFromMeta(4));
      world.setBlockState(pos.add(32, 6, 41), ((BlockColored)Blocks.STAINED_HARDENED_CLAY).getStateFromMeta(4));
      world.setBlockState(pos.add(33, 6, 41), ((BlockColored)Blocks.STAINED_HARDENED_CLAY).getStateFromMeta(4));
      world.setBlockState(pos.add(34, 6, 41), ((BlockColored)Blocks.STAINED_HARDENED_CLAY).getStateFromMeta(4));
      world.setBlockState(pos.add(35, 6, 41), ((BlockColored)Blocks.STAINED_HARDENED_CLAY).getStateFromMeta(4));
      world.setBlockState(pos.add(36, 6, 41), ((BlockColored)Blocks.STAINED_HARDENED_CLAY).getStateFromMeta(4));
      world.setBlockState(pos.add(37, 6, 41), Blocks.STONE.getDefaultState());
      world.setBlockState(pos.add(38, 6, 41), Blocks.STONE.getDefaultState());
      world.setBlockState(pos.add(39, 6, 41), ((BlockColored)Blocks.STAINED_HARDENED_CLAY).getStateFromMeta(4));
      world.setBlockState(pos.add(40, 6, 41), Blocks.STONE.getDefaultState());
      world.setBlockState(pos.add(41, 6, 41), Blocks.STONE.getDefaultState());
      world.setBlockState(pos.add(42, 6, 41), Blocks.STONE.getDefaultState());
      world.setBlockState(pos.add(43, 6, 41), ((BlockColored)Blocks.STAINED_HARDENED_CLAY).getStateFromMeta(4));
      world.setBlockState(pos.add(44, 6, 41), Blocks.STONE.getDefaultState());
      world.setBlockState(pos.add(45, 6, 41), Blocks.STONE.getDefaultState());
      world.setBlockState(pos.add(46, 6, 41), Blocks.STONE.getDefaultState());
      world.setBlockState(pos.add(47, 6, 41), ((BlockColored)Blocks.STAINED_HARDENED_CLAY).getStateFromMeta(4));
      world.setBlockState(pos.add(4, 6, 42), Blocks.STONE.getDefaultState());
      world.setBlockState(pos.add(8, 6, 42), Blocks.STONE.getDefaultState());
      world.setBlockState(pos.add(13, 6, 42), ((BlockColored)Blocks.STAINED_HARDENED_CLAY).getStateFromMeta(4));
      world.setBlockState(pos.add(14, 6, 42), Blocks.STONE.getDefaultState());
      world.setBlockState(pos.add(15, 6, 42), Blocks.STONE.getDefaultState());
      world.setBlockState(pos.add(16, 6, 42), ((BlockColored)Blocks.STAINED_HARDENED_CLAY).getStateFromMeta(4));
      world.setBlockState(pos.add(17, 6, 42), ((BlockColored)Blocks.STAINED_HARDENED_CLAY).getStateFromMeta(4));
      world.setBlockState(pos.add(18, 6, 42), ((BlockColored)Blocks.STAINED_HARDENED_CLAY).getStateFromMeta(4));
      world.setBlockState(pos.add(19, 6, 42), ((BlockColored)Blocks.STAINED_HARDENED_CLAY).getStateFromMeta(4));
      world.setBlockState(pos.add(20, 6, 42), ((BlockColored)Blocks.STAINED_HARDENED_CLAY).getStateFromMeta(4));
      world.setBlockState(pos.add(21, 6, 42), ((BlockColored)Blocks.STAINED_HARDENED_CLAY).getStateFromMeta(4));
      world.setBlockState(pos.add(22, 6, 42), ((BlockColored)Blocks.STAINED_HARDENED_CLAY).getStateFromMeta(4));
      world.setBlockState(pos.add(23, 6, 42), ((BlockColored)Blocks.STAINED_HARDENED_CLAY).getStateFromMeta(4));
      world.setBlockState(pos.add(24, 6, 42), Blocks.GLOWSTONE.getDefaultState());
      world.setBlockState(pos.add(25, 6, 42), Blocks.GLASS.getDefaultState());
      world.setBlockState(pos.add(26, 6, 42), Blocks.STAINED_GLASS.getStateFromMeta(1));
      world.setBlockState(pos.add(27, 6, 42), Blocks.GLASS.getDefaultState());
      world.setBlockState(pos.add(28, 6, 42), Blocks.GLOWSTONE.getDefaultState());
      world.setBlockState(pos.add(29, 6, 42), ((BlockColored)Blocks.STAINED_HARDENED_CLAY).getStateFromMeta(4));
      world.setBlockState(pos.add(30, 6, 42), ((BlockColored)Blocks.STAINED_HARDENED_CLAY).getStateFromMeta(4));
      world.setBlockState(pos.add(31, 6, 42), ((BlockColored)Blocks.STAINED_HARDENED_CLAY).getStateFromMeta(4));
      world.setBlockState(pos.add(32, 6, 42), ((BlockColored)Blocks.STAINED_HARDENED_CLAY).getStateFromMeta(4));
      world.setBlockState(pos.add(33, 6, 42), ((BlockColored)Blocks.STAINED_HARDENED_CLAY).getStateFromMeta(4));
      world.setBlockState(pos.add(34, 6, 42), ((BlockColored)Blocks.STAINED_HARDENED_CLAY).getStateFromMeta(4));
      world.setBlockState(pos.add(35, 6, 42), ((BlockColored)Blocks.STAINED_HARDENED_CLAY).getStateFromMeta(4));
      world.setBlockState(pos.add(36, 6, 42), ((BlockColored)Blocks.STAINED_HARDENED_CLAY).getStateFromMeta(4));
      world.setBlockState(pos.add(37, 6, 42), Blocks.STONE.getDefaultState());
      world.setBlockState(pos.add(38, 6, 42), Blocks.STONE.getDefaultState());
      world.setBlockState(pos.add(39, 6, 42), Blocks.STONE.getDefaultState());
      world.setBlockState(pos.add(40, 6, 42), ((BlockColored)Blocks.STAINED_HARDENED_CLAY).getStateFromMeta(4));
      world.setBlockState(pos.add(41, 6, 42), ((BlockColored)Blocks.STAINED_HARDENED_CLAY).getStateFromMeta(4));
      world.setBlockState(pos.add(42, 6, 42), ((BlockColored)Blocks.STAINED_HARDENED_CLAY).getStateFromMeta(4));
      world.setBlockState(pos.add(43, 6, 42), Blocks.STONE.getDefaultState());
      world.setBlockState(pos.add(44, 6, 42), Blocks.STONE.getDefaultState());
      world.setBlockState(pos.add(45, 6, 42), Blocks.STONE.getDefaultState());
      world.setBlockState(pos.add(46, 6, 42), Blocks.STONE.getDefaultState());
      world.setBlockState(pos.add(47, 6, 42), ((BlockColored)Blocks.STAINED_HARDENED_CLAY).getStateFromMeta(4));
      world.setBlockState(pos.add(4, 6, 43), Blocks.STONE.getDefaultState());
      world.setBlockState(pos.add(8, 6, 43), Blocks.STONE.getDefaultState());
      world.setBlockState(pos.add(13, 6, 43), ((BlockColored)Blocks.STAINED_HARDENED_CLAY).getStateFromMeta(4));
      world.setBlockState(pos.add(14, 6, 43), Blocks.STONE.getDefaultState());
      world.setBlockState(pos.add(15, 6, 43), ((BlockColored)Blocks.STAINED_HARDENED_CLAY).getStateFromMeta(4));
      world.setBlockState(pos.add(16, 6, 43), ((BlockColored)Blocks.STAINED_HARDENED_CLAY).getStateFromMeta(4));
      world.setBlockState(pos.add(17, 6, 43), ((BlockColored)Blocks.STAINED_HARDENED_CLAY).getStateFromMeta(4));
      world.setBlockState(pos.add(18, 6, 43), ((BlockColored)Blocks.STAINED_HARDENED_CLAY).getStateFromMeta(4));
      world.setBlockState(pos.add(19, 6, 43), ((BlockColored)Blocks.STAINED_HARDENED_CLAY).getStateFromMeta(4));
      world.setBlockState(pos.add(20, 6, 43), ((BlockColored)Blocks.STAINED_HARDENED_CLAY).getStateFromMeta(4));
      world.setBlockState(pos.add(21, 6, 43), ((BlockColored)Blocks.STAINED_HARDENED_CLAY).getStateFromMeta(4));
      world.setBlockState(pos.add(22, 6, 43), ((BlockColored)Blocks.STAINED_HARDENED_CLAY).getStateFromMeta(4));
      world.setBlockState(pos.add(23, 6, 43), ((BlockStaticLiquid)Blocks.LAVA).getStateFromMeta(10));
      world.setBlockState(pos.add(24, 6, 43), Blocks.GLOWSTONE.getDefaultState());
      world.setBlockState(pos.add(25, 6, 43), Blocks.GLASS.getDefaultState());
      world.setBlockState(pos.add(26, 6, 43), Blocks.STAINED_GLASS.getStateFromMeta(1));
      world.setBlockState(pos.add(27, 6, 43), Blocks.GLASS.getDefaultState());
      world.setBlockState(pos.add(28, 6, 43), Blocks.GLOWSTONE.getDefaultState());
      world.setBlockState(pos.add(29, 6, 43), ((BlockStaticLiquid)Blocks.LAVA).getStateFromMeta(10));
      world.setBlockState(pos.add(30, 6, 43), ((BlockColored)Blocks.STAINED_HARDENED_CLAY).getStateFromMeta(4));
      world.setBlockState(pos.add(31, 6, 43), ((BlockColored)Blocks.STAINED_HARDENED_CLAY).getStateFromMeta(4));
      world.setBlockState(pos.add(32, 6, 43), ((BlockColored)Blocks.STAINED_HARDENED_CLAY).getStateFromMeta(4));
      world.setBlockState(pos.add(33, 6, 43), ((BlockColored)Blocks.STAINED_HARDENED_CLAY).getStateFromMeta(4));
      world.setBlockState(pos.add(34, 6, 43), ((BlockColored)Blocks.STAINED_HARDENED_CLAY).getStateFromMeta(4));
      world.setBlockState(pos.add(35, 6, 43), ((BlockColored)Blocks.STAINED_HARDENED_CLAY).getStateFromMeta(4));
      world.setBlockState(pos.add(36, 6, 43), ((BlockColored)Blocks.STAINED_HARDENED_CLAY).getStateFromMeta(4));
      world.setBlockState(pos.add(37, 6, 43), ((BlockColored)Blocks.STAINED_HARDENED_CLAY).getStateFromMeta(4));
      world.setBlockState(pos.add(38, 6, 43), Blocks.STONE.getDefaultState());
      world.setBlockState(pos.add(39, 6, 43), Blocks.STONE.getDefaultState());
      world.setBlockState(pos.add(40, 6, 43), Blocks.STONE.getDefaultState());
      world.setBlockState(pos.add(41, 6, 43), Blocks.STONE.getDefaultState());
      world.setBlockState(pos.add(42, 6, 43), Blocks.STONE.getDefaultState());
      world.setBlockState(pos.add(43, 6, 43), Blocks.STONE.getDefaultState());
      world.setBlockState(pos.add(44, 6, 43), Blocks.STONE.getDefaultState());
      world.setBlockState(pos.add(45, 6, 43), Blocks.STONE.getDefaultState());
      world.setBlockState(pos.add(46, 6, 43), Blocks.STONE.getDefaultState());
      world.setBlockState(pos.add(47, 6, 43), ((BlockColored)Blocks.STAINED_HARDENED_CLAY).getStateFromMeta(4));
      world.setBlockState(pos.add(4, 6, 44), Blocks.STONE.getDefaultState());
      world.setBlockState(pos.add(8, 6, 44), Blocks.STONE.getDefaultState());
      world.setBlockState(pos.add(13, 6, 44), ((BlockColored)Blocks.STAINED_HARDENED_CLAY).getStateFromMeta(4));
      world.setBlockState(pos.add(14, 6, 44), Blocks.STONE.getDefaultState());
      world.setBlockState(pos.add(15, 6, 44), ((BlockColored)Blocks.STAINED_HARDENED_CLAY).getStateFromMeta(4));
      world.setBlockState(pos.add(16, 6, 44), ((BlockColored)Blocks.STAINED_HARDENED_CLAY).getStateFromMeta(4));
      world.setBlockState(pos.add(17, 6, 44), ((BlockColored)Blocks.STAINED_HARDENED_CLAY).getStateFromMeta(4));
      world.setBlockState(pos.add(18, 6, 44), ((BlockColored)Blocks.STAINED_HARDENED_CLAY).getStateFromMeta(4));
      world.setBlockState(pos.add(19, 6, 44), ((BlockColored)Blocks.STAINED_HARDENED_CLAY).getStateFromMeta(4));
      world.setBlockState(pos.add(20, 6, 44), ((BlockColored)Blocks.STAINED_HARDENED_CLAY).getStateFromMeta(4));
      world.setBlockState(pos.add(21, 6, 44), ((BlockColored)Blocks.STAINED_HARDENED_CLAY).getStateFromMeta(4));
      world.setBlockState(pos.add(22, 6, 44), ((BlockColored)Blocks.STAINED_HARDENED_CLAY).getStateFromMeta(4));
      world.setBlockState(pos.add(23, 6, 44), ((BlockStaticLiquid)Blocks.LAVA).getStateFromMeta(2));
      world.setBlockState(pos.add(24, 6, 44), Blocks.GLOWSTONE.getDefaultState());
      world.setBlockState(pos.add(25, 6, 44), Blocks.GLASS.getDefaultState());
      world.setBlockState(pos.add(26, 6, 44), Blocks.STAINED_GLASS.getStateFromMeta(1));
      world.setBlockState(pos.add(27, 6, 44), Blocks.GLASS.getDefaultState());
      world.setBlockState(pos.add(28, 6, 44), Blocks.GLOWSTONE.getDefaultState());
      world.setBlockState(pos.add(29, 6, 44), ((BlockStaticLiquid)Blocks.LAVA).getStateFromMeta(2));
      world.setBlockState(pos.add(30, 6, 44), ((BlockColored)Blocks.STAINED_HARDENED_CLAY).getStateFromMeta(4));
      world.setBlockState(pos.add(31, 6, 44), ((BlockColored)Blocks.STAINED_HARDENED_CLAY).getStateFromMeta(4));
      world.setBlockState(pos.add(32, 6, 44), ((BlockColored)Blocks.STAINED_HARDENED_CLAY).getStateFromMeta(4));
      world.setBlockState(pos.add(33, 6, 44), ((BlockColored)Blocks.STAINED_HARDENED_CLAY).getStateFromMeta(4));
      world.setBlockState(pos.add(34, 6, 44), ((BlockColored)Blocks.STAINED_HARDENED_CLAY).getStateFromMeta(4));
      world.setBlockState(pos.add(35, 6, 44), ((BlockColored)Blocks.STAINED_HARDENED_CLAY).getStateFromMeta(4));
      world.setBlockState(pos.add(36, 6, 44), ((BlockColored)Blocks.STAINED_HARDENED_CLAY).getStateFromMeta(4));
      world.setBlockState(pos.add(37, 6, 44), ((BlockColored)Blocks.STAINED_HARDENED_CLAY).getStateFromMeta(4));
      world.setBlockState(pos.add(38, 6, 44), Blocks.STONE.getDefaultState());
      world.setBlockState(pos.add(39, 6, 44), Blocks.STONE.getDefaultState());
      world.setBlockState(pos.add(40, 6, 44), Blocks.STONE.getDefaultState());
      world.setBlockState(pos.add(41, 6, 44), Blocks.STONE.getDefaultState());
      world.setBlockState(pos.add(42, 6, 44), Blocks.STONE.getDefaultState());
      world.setBlockState(pos.add(43, 6, 44), Blocks.STONE.getDefaultState());
      world.setBlockState(pos.add(44, 6, 44), Blocks.STONE.getDefaultState());
      world.setBlockState(pos.add(45, 6, 44), Blocks.STONE.getDefaultState());
      world.setBlockState(pos.add(46, 6, 44), Blocks.STONE.getDefaultState());
      world.setBlockState(pos.add(47, 6, 44), ((BlockColored)Blocks.STAINED_HARDENED_CLAY).getStateFromMeta(4));
      world.setBlockState(pos.add(5, 6, 45), Blocks.STONE.getDefaultState());
      world.setBlockState(pos.add(6, 6, 45), Blocks.STONE.getDefaultState());
      world.setBlockState(pos.add(7, 6, 45), Blocks.STONE.getDefaultState());
      world.setBlockState(pos.add(13, 6, 45), ((BlockColored)Blocks.STAINED_HARDENED_CLAY).getStateFromMeta(4));
      world.setBlockState(pos.add(14, 6, 45), Blocks.STONE.getDefaultState());
      world.setBlockState(pos.add(15, 6, 45), ((BlockColored)Blocks.STAINED_HARDENED_CLAY).getStateFromMeta(4));
      world.setBlockState(pos.add(16, 6, 45), ((BlockColored)Blocks.STAINED_HARDENED_CLAY).getStateFromMeta(4));
      world.setBlockState(pos.add(17, 6, 45), ((BlockColored)Blocks.STAINED_HARDENED_CLAY).getStateFromMeta(4));
      world.setBlockState(pos.add(18, 6, 45), ((BlockColored)Blocks.STAINED_HARDENED_CLAY).getStateFromMeta(4));
      world.setBlockState(pos.add(19, 6, 45), ((BlockColored)Blocks.STAINED_HARDENED_CLAY).getStateFromMeta(4));
      world.setBlockState(pos.add(20, 6, 45), ((BlockColored)Blocks.STAINED_HARDENED_CLAY).getStateFromMeta(4));
      world.setBlockState(pos.add(21, 6, 45), ((BlockColored)Blocks.STAINED_HARDENED_CLAY).getStateFromMeta(4));
      world.setBlockState(pos.add(22, 6, 45), ((BlockColored)Blocks.STAINED_HARDENED_CLAY).getStateFromMeta(4));
      world.setBlockState(pos.add(23, 6, 45), ((BlockStaticLiquid)Blocks.LAVA).getStateFromMeta(10));
      world.setBlockState(pos.add(24, 6, 45), Blocks.GLOWSTONE.getDefaultState());
      world.setBlockState(pos.add(25, 6, 45), Blocks.GLASS.getDefaultState());
      world.setBlockState(pos.add(26, 6, 45), Blocks.STAINED_GLASS.getStateFromMeta(1));
      world.setBlockState(pos.add(27, 6, 45), Blocks.GLASS.getDefaultState());
      world.setBlockState(pos.add(28, 6, 45), Blocks.GLOWSTONE.getDefaultState());
      world.setBlockState(pos.add(29, 6, 45), ((BlockStaticLiquid)Blocks.LAVA).getStateFromMeta(10));
      world.setBlockState(pos.add(30, 6, 45), ((BlockColored)Blocks.STAINED_HARDENED_CLAY).getStateFromMeta(4));
      world.setBlockState(pos.add(31, 6, 45), ((BlockColored)Blocks.STAINED_HARDENED_CLAY).getStateFromMeta(4));
      world.setBlockState(pos.add(32, 6, 45), ((BlockColored)Blocks.STAINED_HARDENED_CLAY).getStateFromMeta(4));
      world.setBlockState(pos.add(33, 6, 45), ((BlockColored)Blocks.STAINED_HARDENED_CLAY).getStateFromMeta(4));
      world.setBlockState(pos.add(34, 6, 45), ((BlockColored)Blocks.STAINED_HARDENED_CLAY).getStateFromMeta(4));
      world.setBlockState(pos.add(35, 6, 45), ((BlockColored)Blocks.STAINED_HARDENED_CLAY).getStateFromMeta(4));
      world.setBlockState(pos.add(36, 6, 45), ((BlockColored)Blocks.STAINED_HARDENED_CLAY).getStateFromMeta(4));
      world.setBlockState(pos.add(37, 6, 45), ((BlockColored)Blocks.STAINED_HARDENED_CLAY).getStateFromMeta(4));
      world.setBlockState(pos.add(38, 6, 45), Blocks.STONE.getDefaultState());
      world.setBlockState(pos.add(39, 6, 45), Blocks.STONE.getDefaultState());
      world.setBlockState(pos.add(40, 6, 45), Blocks.STONE.getDefaultState());
      world.setBlockState(pos.add(41, 6, 45), Blocks.STONE.getDefaultState());
      world.setBlockState(pos.add(42, 6, 45), Blocks.STONE.getDefaultState());
      world.setBlockState(pos.add(43, 6, 45), Blocks.STONE.getDefaultState());
      world.setBlockState(pos.add(44, 6, 45), Blocks.STONE.getDefaultState());
      world.setBlockState(pos.add(45, 6, 45), Blocks.STONE.getDefaultState());
      world.setBlockState(pos.add(46, 6, 45), Blocks.STONE.getDefaultState());
      world.setBlockState(pos.add(47, 6, 45), ((BlockColored)Blocks.STAINED_HARDENED_CLAY).getStateFromMeta(4));
      world.setBlockState(pos.add(13, 6, 46), ((BlockColored)Blocks.STAINED_HARDENED_CLAY).getStateFromMeta(4));
      world.setBlockState(pos.add(14, 6, 46), Blocks.STONE.getDefaultState());
      world.setBlockState(pos.add(15, 6, 46), Blocks.STONE.getDefaultState());
      world.setBlockState(pos.add(16, 6, 46), ((BlockColored)Blocks.STAINED_HARDENED_CLAY).getStateFromMeta(4));
      world.setBlockState(pos.add(17, 6, 46), ((BlockColored)Blocks.STAINED_HARDENED_CLAY).getStateFromMeta(4));
      world.setBlockState(pos.add(18, 6, 46), ((BlockColored)Blocks.STAINED_HARDENED_CLAY).getStateFromMeta(4));
      world.setBlockState(pos.add(19, 6, 46), ((BlockColored)Blocks.STAINED_HARDENED_CLAY).getStateFromMeta(4));
      world.setBlockState(pos.add(20, 6, 46), ((BlockColored)Blocks.STAINED_HARDENED_CLAY).getStateFromMeta(4));
      world.setBlockState(pos.add(21, 6, 46), ((BlockColored)Blocks.STAINED_HARDENED_CLAY).getStateFromMeta(4));
      world.setBlockState(pos.add(22, 6, 46), ((BlockColored)Blocks.STAINED_HARDENED_CLAY).getStateFromMeta(4));
      world.setBlockState(pos.add(23, 6, 46), ((BlockColored)Blocks.STAINED_HARDENED_CLAY).getStateFromMeta(4));
      world.setBlockState(pos.add(24, 6, 46), Blocks.GLOWSTONE.getDefaultState());
      world.setBlockState(pos.add(25, 6, 46), Blocks.GLASS.getDefaultState());
      world.setBlockState(pos.add(26, 6, 46), Blocks.STAINED_GLASS.getStateFromMeta(1));
      world.setBlockState(pos.add(27, 6, 46), Blocks.GLASS.getDefaultState());
      world.setBlockState(pos.add(28, 6, 46), Blocks.GLOWSTONE.getDefaultState());
      world.setBlockState(pos.add(29, 6, 46), ((BlockColored)Blocks.STAINED_HARDENED_CLAY).getStateFromMeta(4));
      world.setBlockState(pos.add(30, 6, 46), ((BlockColored)Blocks.STAINED_HARDENED_CLAY).getStateFromMeta(4));
      world.setBlockState(pos.add(31, 6, 46), ((BlockColored)Blocks.STAINED_HARDENED_CLAY).getStateFromMeta(4));
      world.setBlockState(pos.add(32, 6, 46), ((BlockColored)Blocks.STAINED_HARDENED_CLAY).getStateFromMeta(4));
      world.setBlockState(pos.add(33, 6, 46), ((BlockColored)Blocks.STAINED_HARDENED_CLAY).getStateFromMeta(4));
      world.setBlockState(pos.add(34, 6, 46), ((BlockColored)Blocks.STAINED_HARDENED_CLAY).getStateFromMeta(4));
      world.setBlockState(pos.add(35, 6, 46), ((BlockColored)Blocks.STAINED_HARDENED_CLAY).getStateFromMeta(4));
      world.setBlockState(pos.add(36, 6, 46), ((BlockColored)Blocks.STAINED_HARDENED_CLAY).getStateFromMeta(4));
      world.setBlockState(pos.add(37, 6, 46), Blocks.STONE.getDefaultState());
      world.setBlockState(pos.add(38, 6, 46), Blocks.STONE.getDefaultState());
      world.setBlockState(pos.add(39, 6, 46), Blocks.STONE.getDefaultState());
      world.setBlockState(pos.add(40, 6, 46), Blocks.STONE.getDefaultState());
      world.setBlockState(pos.add(41, 6, 46), Blocks.STONE.getDefaultState());
      world.setBlockState(pos.add(42, 6, 46), Blocks.STONE.getDefaultState());
      world.setBlockState(pos.add(43, 6, 46), Blocks.STONE.getDefaultState());
      world.setBlockState(pos.add(44, 6, 46), Blocks.STONE.getDefaultState());
      world.setBlockState(pos.add(45, 6, 46), Blocks.STONE.getDefaultState());
      world.setBlockState(pos.add(46, 6, 46), Blocks.STONE.getDefaultState());
      world.setBlockState(pos.add(47, 6, 46), ((BlockColored)Blocks.STAINED_HARDENED_CLAY).getStateFromMeta(4));
      world.setBlockState(pos.add(13, 6, 47), ((BlockColored)Blocks.STAINED_HARDENED_CLAY).getStateFromMeta(4));
      world.setBlockState(pos.add(14, 6, 47), Blocks.STONE.getDefaultState());
      world.setBlockState(pos.add(15, 6, 47), Blocks.STONE.getDefaultState());
      world.setBlockState(pos.add(16, 6, 47), ((BlockColored)Blocks.STAINED_HARDENED_CLAY).getStateFromMeta(4));
      world.setBlockState(pos.add(17, 6, 47), ((BlockColored)Blocks.STAINED_HARDENED_CLAY).getStateFromMeta(4));
      world.setBlockState(pos.add(18, 6, 47), ((BlockColored)Blocks.STAINED_HARDENED_CLAY).getStateFromMeta(4));
      world.setBlockState(pos.add(19, 6, 47), ((BlockColored)Blocks.STAINED_HARDENED_CLAY).getStateFromMeta(4));
      world.setBlockState(pos.add(20, 6, 47), ((BlockColored)Blocks.STAINED_HARDENED_CLAY).getStateFromMeta(4));
      world.setBlockState(pos.add(21, 6, 47), ((BlockColored)Blocks.STAINED_HARDENED_CLAY).getStateFromMeta(4));
      world.setBlockState(pos.add(22, 6, 47), ((BlockColored)Blocks.STAINED_HARDENED_CLAY).getStateFromMeta(4));
      world.setBlockState(pos.add(23, 6, 47), ((BlockColored)Blocks.STAINED_HARDENED_CLAY).getStateFromMeta(4));
      world.setBlockState(pos.add(24, 6, 47), Blocks.GLOWSTONE.getDefaultState());
      world.setBlockState(pos.add(25, 6, 47), Blocks.GLASS.getDefaultState());
      world.setBlockState(pos.add(26, 6, 47), Blocks.STAINED_GLASS.getStateFromMeta(1));
      world.setBlockState(pos.add(27, 6, 47), Blocks.GLASS.getDefaultState());
      world.setBlockState(pos.add(28, 6, 47), Blocks.GLOWSTONE.getDefaultState());
      world.setBlockState(pos.add(29, 6, 47), ((BlockColored)Blocks.STAINED_HARDENED_CLAY).getStateFromMeta(4));
      world.setBlockState(pos.add(30, 6, 47), ((BlockColored)Blocks.STAINED_HARDENED_CLAY).getStateFromMeta(4));
      world.setBlockState(pos.add(31, 6, 47), ((BlockColored)Blocks.STAINED_HARDENED_CLAY).getStateFromMeta(4));
      world.setBlockState(pos.add(32, 6, 47), ((BlockColored)Blocks.STAINED_HARDENED_CLAY).getStateFromMeta(4));
      world.setBlockState(pos.add(33, 6, 47), ((BlockColored)Blocks.STAINED_HARDENED_CLAY).getStateFromMeta(4));
      world.setBlockState(pos.add(34, 6, 47), ((BlockColored)Blocks.STAINED_HARDENED_CLAY).getStateFromMeta(4));
      world.setBlockState(pos.add(35, 6, 47), ((BlockColored)Blocks.STAINED_HARDENED_CLAY).getStateFromMeta(4));
      world.setBlockState(pos.add(36, 6, 47), ((BlockColored)Blocks.STAINED_HARDENED_CLAY).getStateFromMeta(4));
      world.setBlockState(pos.add(37, 6, 47), Blocks.STONE.getDefaultState());
      world.setBlockState(pos.add(38, 6, 47), Blocks.STONE.getDefaultState());
      world.setBlockState(pos.add(39, 6, 47), Blocks.STONE.getDefaultState());
      world.setBlockState(pos.add(40, 6, 47), Blocks.STONE.getDefaultState());
      world.setBlockState(pos.add(41, 6, 47), Blocks.STONE.getDefaultState());
      world.setBlockState(pos.add(42, 6, 47), Blocks.STONE.getDefaultState());
      world.setBlockState(pos.add(43, 6, 47), Blocks.STONE.getDefaultState());
      world.setBlockState(pos.add(44, 6, 47), Blocks.STONE.getDefaultState());
      world.setBlockState(pos.add(45, 6, 47), Blocks.STONE.getDefaultState());
      world.setBlockState(pos.add(46, 6, 47), Blocks.STONE.getDefaultState());
      world.setBlockState(pos.add(47, 6, 47), ((BlockColored)Blocks.STAINED_HARDENED_CLAY).getStateFromMeta(4));
      world.setBlockState(pos.add(13, 6, 48), ((BlockColored)Blocks.STAINED_HARDENED_CLAY).getStateFromMeta(4));
      world.setBlockState(pos.add(14, 6, 48), Blocks.STONE.getDefaultState());
      world.setBlockState(pos.add(15, 6, 48), ((BlockColored)Blocks.STAINED_HARDENED_CLAY).getStateFromMeta(4));
      world.setBlockState(pos.add(16, 6, 48), ((BlockColored)Blocks.STAINED_HARDENED_CLAY).getStateFromMeta(4));
      world.setBlockState(pos.add(17, 6, 48), ((BlockColored)Blocks.STAINED_HARDENED_CLAY).getStateFromMeta(4));
      world.setBlockState(pos.add(18, 6, 48), ((BlockColored)Blocks.STAINED_HARDENED_CLAY).getStateFromMeta(4));
      world.setBlockState(pos.add(19, 6, 48), ((BlockColored)Blocks.STAINED_HARDENED_CLAY).getStateFromMeta(4));
      world.setBlockState(pos.add(20, 6, 48), ((BlockColored)Blocks.STAINED_HARDENED_CLAY).getStateFromMeta(4));
      world.setBlockState(pos.add(21, 6, 48), ((BlockColored)Blocks.STAINED_HARDENED_CLAY).getStateFromMeta(4));
      world.setBlockState(pos.add(22, 6, 48), ((BlockColored)Blocks.STAINED_HARDENED_CLAY).getStateFromMeta(4));
      world.setBlockState(pos.add(23, 6, 48), ((BlockStaticLiquid)Blocks.LAVA).getStateFromMeta(10));
      world.setBlockState(pos.add(24, 6, 48), Blocks.GLOWSTONE.getDefaultState());
      world.setBlockState(pos.add(25, 6, 48), Blocks.GLASS.getDefaultState());
      world.setBlockState(pos.add(26, 6, 48), Blocks.STAINED_GLASS.getStateFromMeta(1));
      world.setBlockState(pos.add(27, 6, 48), Blocks.GLASS.getDefaultState());
      world.setBlockState(pos.add(28, 6, 48), Blocks.GLOWSTONE.getDefaultState());
      world.setBlockState(pos.add(29, 6, 48), ((BlockStaticLiquid)Blocks.LAVA).getStateFromMeta(10));
      world.setBlockState(pos.add(30, 6, 48), ((BlockColored)Blocks.STAINED_HARDENED_CLAY).getStateFromMeta(4));
      world.setBlockState(pos.add(31, 6, 48), ((BlockColored)Blocks.STAINED_HARDENED_CLAY).getStateFromMeta(4));
      world.setBlockState(pos.add(32, 6, 48), ((BlockColored)Blocks.STAINED_HARDENED_CLAY).getStateFromMeta(4));
      world.setBlockState(pos.add(33, 6, 48), ((BlockColored)Blocks.STAINED_HARDENED_CLAY).getStateFromMeta(4));
      world.setBlockState(pos.add(34, 6, 48), ((BlockColored)Blocks.STAINED_HARDENED_CLAY).getStateFromMeta(4));
      world.setBlockState(pos.add(35, 6, 48), ((BlockColored)Blocks.STAINED_HARDENED_CLAY).getStateFromMeta(4));
      world.setBlockState(pos.add(36, 6, 48), ((BlockColored)Blocks.STAINED_HARDENED_CLAY).getStateFromMeta(4));
      world.setBlockState(pos.add(37, 6, 48), ((BlockColored)Blocks.STAINED_HARDENED_CLAY).getStateFromMeta(4));
      world.setBlockState(pos.add(38, 6, 48), Blocks.STONE.getDefaultState());
      world.setBlockState(pos.add(39, 6, 48), Blocks.STONE.getDefaultState());
      world.setBlockState(pos.add(40, 6, 48), Blocks.STONE.getDefaultState());
      world.setBlockState(pos.add(41, 6, 48), Blocks.STONE.getDefaultState());
      world.setBlockState(pos.add(42, 6, 48), Blocks.STONE.getDefaultState());
      world.setBlockState(pos.add(43, 6, 48), Blocks.STONE.getDefaultState());
      world.setBlockState(pos.add(44, 6, 48), Blocks.STONE.getDefaultState());
      world.setBlockState(pos.add(45, 6, 48), Blocks.STONE.getDefaultState());
      world.setBlockState(pos.add(46, 6, 48), Blocks.STONE.getDefaultState());
      world.setBlockState(pos.add(47, 6, 48), ((BlockColored)Blocks.STAINED_HARDENED_CLAY).getStateFromMeta(4));
      world.setBlockState(pos.add(13, 6, 49), ((BlockColored)Blocks.STAINED_HARDENED_CLAY).getStateFromMeta(4));
      world.setBlockState(pos.add(14, 6, 49), Blocks.STONE.getDefaultState());
      world.setBlockState(pos.add(15, 6, 49), ((BlockColored)Blocks.STAINED_HARDENED_CLAY).getStateFromMeta(4));
      world.setBlockState(pos.add(16, 6, 49), ((BlockColored)Blocks.STAINED_HARDENED_CLAY).getStateFromMeta(4));
      world.setBlockState(pos.add(17, 6, 49), ((BlockColored)Blocks.STAINED_HARDENED_CLAY).getStateFromMeta(4));
      world.setBlockState(pos.add(18, 6, 49), ((BlockColored)Blocks.STAINED_HARDENED_CLAY).getStateFromMeta(4));
      world.setBlockState(pos.add(19, 6, 49), ((BlockColored)Blocks.STAINED_HARDENED_CLAY).getStateFromMeta(4));
      world.setBlockState(pos.add(20, 6, 49), ((BlockColored)Blocks.STAINED_HARDENED_CLAY).getStateFromMeta(4));
      world.setBlockState(pos.add(21, 6, 49), ((BlockColored)Blocks.STAINED_HARDENED_CLAY).getStateFromMeta(4));
      world.setBlockState(pos.add(22, 6, 49), ((BlockColored)Blocks.STAINED_HARDENED_CLAY).getStateFromMeta(4));
      world.setBlockState(pos.add(23, 6, 49), ((BlockStaticLiquid)Blocks.LAVA).getStateFromMeta(2));
      world.setBlockState(pos.add(24, 6, 49), Blocks.GLOWSTONE.getDefaultState());
      world.setBlockState(pos.add(25, 6, 49), Blocks.GLASS.getDefaultState());
      world.setBlockState(pos.add(26, 6, 49), Blocks.STAINED_GLASS.getStateFromMeta(1));
      world.setBlockState(pos.add(27, 6, 49), Blocks.GLASS.getDefaultState());
      world.setBlockState(pos.add(28, 6, 49), Blocks.GLOWSTONE.getDefaultState());
      world.setBlockState(pos.add(29, 6, 49), ((BlockStaticLiquid)Blocks.LAVA).getStateFromMeta(2));
      world.setBlockState(pos.add(30, 6, 49), ((BlockColored)Blocks.STAINED_HARDENED_CLAY).getStateFromMeta(4));
      world.setBlockState(pos.add(31, 6, 49), ((BlockColored)Blocks.STAINED_HARDENED_CLAY).getStateFromMeta(4));
      world.setBlockState(pos.add(32, 6, 49), ((BlockColored)Blocks.STAINED_HARDENED_CLAY).getStateFromMeta(4));
      world.setBlockState(pos.add(33, 6, 49), ((BlockColored)Blocks.STAINED_HARDENED_CLAY).getStateFromMeta(4));
      world.setBlockState(pos.add(34, 6, 49), ((BlockColored)Blocks.STAINED_HARDENED_CLAY).getStateFromMeta(4));
      world.setBlockState(pos.add(35, 6, 49), ((BlockColored)Blocks.STAINED_HARDENED_CLAY).getStateFromMeta(4));
      world.setBlockState(pos.add(36, 6, 49), ((BlockColored)Blocks.STAINED_HARDENED_CLAY).getStateFromMeta(4));
      world.setBlockState(pos.add(37, 6, 49), ((BlockColored)Blocks.STAINED_HARDENED_CLAY).getStateFromMeta(4));
      world.setBlockState(pos.add(38, 6, 49), Blocks.STONE.getDefaultState());
      world.setBlockState(pos.add(39, 6, 49), Blocks.STONE.getDefaultState());
      world.setBlockState(pos.add(40, 6, 49), Blocks.STONE.getDefaultState());
      world.setBlockState(pos.add(41, 6, 49), Blocks.STONE.getDefaultState());
      world.setBlockState(pos.add(42, 6, 49), Blocks.STONE.getDefaultState());
      world.setBlockState(pos.add(43, 6, 49), Blocks.STONE.getDefaultState());
      world.setBlockState(pos.add(44, 6, 49), Blocks.STONE.getDefaultState());
      world.setBlockState(pos.add(45, 6, 49), Blocks.STONE.getDefaultState());
      world.setBlockState(pos.add(46, 6, 49), Blocks.STONE.getDefaultState());
      world.setBlockState(pos.add(47, 6, 49), ((BlockColored)Blocks.STAINED_HARDENED_CLAY).getStateFromMeta(4));
      world.setBlockState(pos.add(13, 6, 50), ((BlockColored)Blocks.STAINED_HARDENED_CLAY).getStateFromMeta(4));
      world.setBlockState(pos.add(14, 6, 50), Blocks.STONE.getDefaultState());
      world.setBlockState(pos.add(15, 6, 50), ((BlockColored)Blocks.STAINED_HARDENED_CLAY).getStateFromMeta(4));
      world.setBlockState(pos.add(16, 6, 50), ((BlockColored)Blocks.STAINED_HARDENED_CLAY).getStateFromMeta(4));
      world.setBlockState(pos.add(17, 6, 50), ((BlockColored)Blocks.STAINED_HARDENED_CLAY).getStateFromMeta(4));
      world.setBlockState(pos.add(18, 6, 50), ((BlockColored)Blocks.STAINED_HARDENED_CLAY).getStateFromMeta(4));
      world.setBlockState(pos.add(19, 6, 50), ((BlockColored)Blocks.STAINED_HARDENED_CLAY).getStateFromMeta(4));
      world.setBlockState(pos.add(20, 6, 50), ((BlockColored)Blocks.STAINED_HARDENED_CLAY).getStateFromMeta(4));
      world.setBlockState(pos.add(21, 6, 50), ((BlockColored)Blocks.STAINED_HARDENED_CLAY).getStateFromMeta(4));
      world.setBlockState(pos.add(22, 6, 50), ((BlockColored)Blocks.STAINED_HARDENED_CLAY).getStateFromMeta(4));
      world.setBlockState(pos.add(23, 6, 50), ((BlockStaticLiquid)Blocks.LAVA).getStateFromMeta(4));
      world.setBlockState(pos.add(24, 6, 50), ((BlockColored)Blocks.STAINED_HARDENED_CLAY).getStateFromMeta(4));
      world.setBlockState(pos.add(25, 6, 50), Blocks.GLASS.getDefaultState());
      world.setBlockState(pos.add(26, 6, 50), Blocks.STAINED_GLASS.getStateFromMeta(1));
return true;
  }
}
