package com.slugterra.world.greatForge;
import java.util.Random;

import net.minecraft.block.BlockColored;
import net.minecraft.init.Blocks;
import net.minecraft.util.math.BlockPos;
import net.minecraft.world.World;
public class GreatWesternForgeStructure11 {
public boolean generate(World world, Random par2Random, BlockPos pos) {
      world.setBlockState(pos.add(20, 20, 50), ((BlockColored)Blocks.STAINED_HARDENED_CLAY).getStateFromMeta(4));
      world.setBlockState(pos.add(21, 20, 50), ((BlockColored)Blocks.STAINED_HARDENED_CLAY).getStateFromMeta(4));
      world.setBlockState(pos.add(23, 20, 50), Blocks.DIAMOND_BLOCK.getDefaultState());
      world.setBlockState(pos.add(29, 20, 50), Blocks.DIAMOND_BLOCK.getDefaultState());
      world.setBlockState(pos.add(31, 20, 50), ((BlockColored)Blocks.STAINED_HARDENED_CLAY).getStateFromMeta(4));
      world.setBlockState(pos.add(32, 20, 50), ((BlockColored)Blocks.STAINED_HARDENED_CLAY).getStateFromMeta(4));
      world.setBlockState(pos.add(33, 20, 50), ((BlockColored)Blocks.STAINED_HARDENED_CLAY).getStateFromMeta(4));
      world.setBlockState(pos.add(34, 20, 50), ((BlockColored)Blocks.STAINED_HARDENED_CLAY).getStateFromMeta(4));
      world.setBlockState(pos.add(35, 20, 50), ((BlockColored)Blocks.STAINED_HARDENED_CLAY).getStateFromMeta(4));
      world.setBlockState(pos.add(18, 20, 51), ((BlockColored)Blocks.STAINED_HARDENED_CLAY).getStateFromMeta(4));
      world.setBlockState(pos.add(19, 20, 51), ((BlockColored)Blocks.STAINED_HARDENED_CLAY).getStateFromMeta(4));
      world.setBlockState(pos.add(20, 20, 51), ((BlockColored)Blocks.STAINED_HARDENED_CLAY).getStateFromMeta(4));
      world.setBlockState(pos.add(21, 20, 51), ((BlockColored)Blocks.STAINED_HARDENED_CLAY).getStateFromMeta(4));
      world.setBlockState(pos.add(22, 20, 51), ((BlockColored)Blocks.STAINED_HARDENED_CLAY).getStateFromMeta(4));
      world.setBlockState(pos.add(23, 20, 51), ((BlockColored)Blocks.STAINED_HARDENED_CLAY).getStateFromMeta(4));
      world.setBlockState(pos.add(24, 20, 51), ((BlockColored)Blocks.STAINED_HARDENED_CLAY).getStateFromMeta(4));
      world.setBlockState(pos.add(25, 20, 51), ((BlockColored)Blocks.STAINED_HARDENED_CLAY).getStateFromMeta(4));
      world.setBlockState(pos.add(26, 20, 51), ((BlockColored)Blocks.STAINED_HARDENED_CLAY).getStateFromMeta(4));
      world.setBlockState(pos.add(27, 20, 51), ((BlockColored)Blocks.STAINED_HARDENED_CLAY).getStateFromMeta(4));
      world.setBlockState(pos.add(28, 20, 51), ((BlockColored)Blocks.STAINED_HARDENED_CLAY).getStateFromMeta(4));
      world.setBlockState(pos.add(29, 20, 51), ((BlockColored)Blocks.STAINED_HARDENED_CLAY).getStateFromMeta(4));
      world.setBlockState(pos.add(30, 20, 51), ((BlockColored)Blocks.STAINED_HARDENED_CLAY).getStateFromMeta(4));
      world.setBlockState(pos.add(31, 20, 51), ((BlockColored)Blocks.STAINED_HARDENED_CLAY).getStateFromMeta(4));
      world.setBlockState(pos.add(32, 20, 51), ((BlockColored)Blocks.STAINED_HARDENED_CLAY).getStateFromMeta(4));
      world.setBlockState(pos.add(33, 20, 51), ((BlockColored)Blocks.STAINED_HARDENED_CLAY).getStateFromMeta(4));
      world.setBlockState(pos.add(34, 20, 51), ((BlockColored)Blocks.STAINED_HARDENED_CLAY).getStateFromMeta(4));
      world.setBlockState(pos.add(17, 20, 52), ((BlockColored)Blocks.STAINED_HARDENED_CLAY).getStateFromMeta(4));
      world.setBlockState(pos.add(18, 20, 52), ((BlockColored)Blocks.STAINED_HARDENED_CLAY).getStateFromMeta(4));
      world.setBlockState(pos.add(22, 20, 52), ((BlockColored)Blocks.STAINED_HARDENED_CLAY).getStateFromMeta(4));
      world.setBlockState(pos.add(23, 20, 52), ((BlockColored)Blocks.STAINED_HARDENED_CLAY).getStateFromMeta(4));
      world.setBlockState(pos.add(29, 20, 52), ((BlockColored)Blocks.STAINED_HARDENED_CLAY).getStateFromMeta(4));
      world.setBlockState(pos.add(30, 20, 52), ((BlockColored)Blocks.STAINED_HARDENED_CLAY).getStateFromMeta(4));
      world.setBlockState(pos.add(34, 20, 52), ((BlockColored)Blocks.STAINED_HARDENED_CLAY).getStateFromMeta(4));
      world.setBlockState(pos.add(35, 20, 52), ((BlockColored)Blocks.STAINED_HARDENED_CLAY).getStateFromMeta(4));
      world.setBlockState(pos.add(16, 20, 53), ((BlockColored)Blocks.STAINED_HARDENED_CLAY).getStateFromMeta(4));
      world.setBlockState(pos.add(17, 20, 53), ((BlockColored)Blocks.STAINED_HARDENED_CLAY).getStateFromMeta(4));
      world.setBlockState(pos.add(23, 20, 53), ((BlockColored)Blocks.STAINED_HARDENED_CLAY).getStateFromMeta(4));
      world.setBlockState(pos.add(24, 20, 53), ((BlockColored)Blocks.STAINED_HARDENED_CLAY).getStateFromMeta(4));
      world.setBlockState(pos.add(28, 20, 53), ((BlockColored)Blocks.STAINED_HARDENED_CLAY).getStateFromMeta(4));
      world.setBlockState(pos.add(29, 20, 53), ((BlockColored)Blocks.STAINED_HARDENED_CLAY).getStateFromMeta(4));
      world.setBlockState(pos.add(35, 20, 53), ((BlockColored)Blocks.STAINED_HARDENED_CLAY).getStateFromMeta(4));
      world.setBlockState(pos.add(36, 20, 53), ((BlockColored)Blocks.STAINED_HARDENED_CLAY).getStateFromMeta(4));
      world.setBlockState(pos.add(16, 20, 54), ((BlockColored)Blocks.STAINED_HARDENED_CLAY).getStateFromMeta(4));
      world.setBlockState(pos.add(17, 20, 54), ((BlockColored)Blocks.STAINED_HARDENED_CLAY).getStateFromMeta(4));
      world.setBlockState(pos.add(23, 20, 54), ((BlockColored)Blocks.STAINED_HARDENED_CLAY).getStateFromMeta(4));
      world.setBlockState(pos.add(24, 20, 54), ((BlockColored)Blocks.STAINED_HARDENED_CLAY).getStateFromMeta(4));
      world.setBlockState(pos.add(28, 20, 54), ((BlockColored)Blocks.STAINED_HARDENED_CLAY).getStateFromMeta(4));
      world.setBlockState(pos.add(29, 20, 54), ((BlockColored)Blocks.STAINED_HARDENED_CLAY).getStateFromMeta(4));
      world.setBlockState(pos.add(35, 20, 54), ((BlockColored)Blocks.STAINED_HARDENED_CLAY).getStateFromMeta(4));
      world.setBlockState(pos.add(36, 20, 54), ((BlockColored)Blocks.STAINED_HARDENED_CLAY).getStateFromMeta(4));
      world.setBlockState(pos.add(16, 20, 55), ((BlockColored)Blocks.STAINED_HARDENED_CLAY).getStateFromMeta(4));
      world.setBlockState(pos.add(17, 20, 55), ((BlockColored)Blocks.STAINED_HARDENED_CLAY).getStateFromMeta(4));
      world.setBlockState(pos.add(23, 20, 55), ((BlockColored)Blocks.STAINED_HARDENED_CLAY).getStateFromMeta(4));
      world.setBlockState(pos.add(24, 20, 55), ((BlockColored)Blocks.STAINED_HARDENED_CLAY).getStateFromMeta(4));
      world.setBlockState(pos.add(28, 20, 55), ((BlockColored)Blocks.STAINED_HARDENED_CLAY).getStateFromMeta(4));
      world.setBlockState(pos.add(29, 20, 55), ((BlockColored)Blocks.STAINED_HARDENED_CLAY).getStateFromMeta(4));
      world.setBlockState(pos.add(35, 20, 55), ((BlockColored)Blocks.STAINED_HARDENED_CLAY).getStateFromMeta(4));
      world.setBlockState(pos.add(36, 20, 55), ((BlockColored)Blocks.STAINED_HARDENED_CLAY).getStateFromMeta(4));
      world.setBlockState(pos.add(37, 20, 55), ((BlockColored)Blocks.STAINED_HARDENED_CLAY).getStateFromMeta(4));
      world.setBlockState(pos.add(39, 20, 55), Blocks.NETHER_BRICK_FENCE.getDefaultState());
      world.setBlockState(pos.add(40, 20, 55), Blocks.NETHER_BRICK_FENCE.getDefaultState());
      world.setBlockState(pos.add(41, 20, 55), Blocks.NETHER_BRICK_FENCE.getDefaultState());
      world.setBlockState(pos.add(17, 20, 56), ((BlockColored)Blocks.STAINED_HARDENED_CLAY).getStateFromMeta(4));
      world.setBlockState(pos.add(18, 20, 56), ((BlockColored)Blocks.STAINED_HARDENED_CLAY).getStateFromMeta(4));
      world.setBlockState(pos.add(22, 20, 56), ((BlockColored)Blocks.STAINED_HARDENED_CLAY).getStateFromMeta(4));
      world.setBlockState(pos.add(23, 20, 56), ((BlockColored)Blocks.STAINED_HARDENED_CLAY).getStateFromMeta(4));
      world.setBlockState(pos.add(29, 20, 56), ((BlockColored)Blocks.STAINED_HARDENED_CLAY).getStateFromMeta(4));
      world.setBlockState(pos.add(30, 20, 56), ((BlockColored)Blocks.STAINED_HARDENED_CLAY).getStateFromMeta(4));
      world.setBlockState(pos.add(34, 20, 56), ((BlockColored)Blocks.STAINED_HARDENED_CLAY).getStateFromMeta(4));
      world.setBlockState(pos.add(35, 20, 56), ((BlockColored)Blocks.STAINED_HARDENED_CLAY).getStateFromMeta(4));
      world.setBlockState(pos.add(38, 20, 56), ((BlockColored)Blocks.STAINED_HARDENED_CLAY).getStateFromMeta(4));
      world.setBlockState(pos.add(39, 20, 56), Blocks.REDSTONE_BLOCK.getDefaultState());
      world.setBlockState(pos.add(40, 20, 56), Blocks.REDSTONE_BLOCK.getDefaultState());
      world.setBlockState(pos.add(41, 20, 56), Blocks.NETHER_BRICK_FENCE.getDefaultState());
      world.setBlockState(pos.add(42, 20, 56), Blocks.NETHER_BRICK_FENCE.getDefaultState());
      world.setBlockState(pos.add(18, 20, 57), ((BlockColored)Blocks.STAINED_HARDENED_CLAY).getStateFromMeta(4));
      world.setBlockState(pos.add(19, 20, 57), ((BlockColored)Blocks.STAINED_HARDENED_CLAY).getStateFromMeta(4));
      world.setBlockState(pos.add(20, 20, 57), ((BlockColored)Blocks.STAINED_HARDENED_CLAY).getStateFromMeta(4));
      world.setBlockState(pos.add(21, 20, 57), ((BlockColored)Blocks.STAINED_HARDENED_CLAY).getStateFromMeta(4));
      world.setBlockState(pos.add(22, 20, 57), ((BlockColored)Blocks.STAINED_HARDENED_CLAY).getStateFromMeta(4));
      world.setBlockState(pos.add(30, 20, 57), ((BlockColored)Blocks.STAINED_HARDENED_CLAY).getStateFromMeta(4));
      world.setBlockState(pos.add(31, 20, 57), ((BlockColored)Blocks.STAINED_HARDENED_CLAY).getStateFromMeta(4));
      world.setBlockState(pos.add(32, 20, 57), ((BlockColored)Blocks.STAINED_HARDENED_CLAY).getStateFromMeta(4));
      world.setBlockState(pos.add(33, 20, 57), ((BlockColored)Blocks.STAINED_HARDENED_CLAY).getStateFromMeta(4));
      world.setBlockState(pos.add(34, 20, 57), ((BlockColored)Blocks.STAINED_HARDENED_CLAY).getStateFromMeta(4));
      world.setBlockState(pos.add(39, 20, 57), ((BlockColored)Blocks.STAINED_HARDENED_CLAY).getStateFromMeta(4));
      world.setBlockState(pos.add(41, 20, 57), Blocks.REDSTONE_BLOCK.getDefaultState());
      world.setBlockState(pos.add(42, 20, 57), Blocks.NETHER_BRICK_FENCE.getDefaultState());
      world.setBlockState(pos.add(43, 20, 57), Blocks.NETHER_BRICK_FENCE.getDefaultState());
      world.setBlockState(pos.add(19, 20, 58), ((BlockColored)Blocks.STAINED_HARDENED_CLAY).getStateFromMeta(4));
      world.setBlockState(pos.add(20, 20, 58), ((BlockColored)Blocks.STAINED_HARDENED_CLAY).getStateFromMeta(4));
      world.setBlockState(pos.add(21, 20, 58), ((BlockColored)Blocks.STAINED_HARDENED_CLAY).getStateFromMeta(4));
      world.setBlockState(pos.add(31, 20, 58), ((BlockColored)Blocks.STAINED_HARDENED_CLAY).getStateFromMeta(4));
      world.setBlockState(pos.add(32, 20, 58), ((BlockColored)Blocks.STAINED_HARDENED_CLAY).getStateFromMeta(4));
      world.setBlockState(pos.add(33, 20, 58), ((BlockColored)Blocks.STAINED_HARDENED_CLAY).getStateFromMeta(4));
      world.setBlockState(pos.add(40, 20, 58), ((BlockColored)Blocks.STAINED_HARDENED_CLAY).getStateFromMeta(4));
      world.setBlockState(pos.add(42, 20, 58), Blocks.REDSTONE_BLOCK.getDefaultState());
      world.setBlockState(pos.add(43, 20, 58), Blocks.NETHER_BRICK_FENCE.getDefaultState());
      world.setBlockState(pos.add(34, 20, 59), Blocks.REDSTONE_BLOCK.getDefaultState());
      world.setBlockState(pos.add(35, 20, 59), Blocks.REDSTONE_BLOCK.getDefaultState());
      world.setBlockState(pos.add(36, 20, 59), Blocks.REDSTONE_BLOCK.getDefaultState());
      world.setBlockState(pos.add(37, 20, 59), Blocks.REDSTONE_BLOCK.getDefaultState());
      world.setBlockState(pos.add(41, 20, 59), ((BlockColored)Blocks.STAINED_HARDENED_CLAY).getStateFromMeta(4));
      world.setBlockState(pos.add(42, 20, 59), Blocks.REDSTONE_BLOCK.getDefaultState());
      world.setBlockState(pos.add(43, 20, 59), Blocks.NETHER_BRICK_FENCE.getDefaultState());
      world.setBlockState(pos.add(33, 20, 60), Blocks.REDSTONE_BLOCK.getDefaultState());
      world.setBlockState(pos.add(38, 20, 60), Blocks.REDSTONE_BLOCK.getDefaultState());
      world.setBlockState(pos.add(42, 20, 60), Blocks.STONE.getDefaultState());
      world.setBlockState(pos.add(43, 20, 60), Blocks.STONE.getDefaultState());
      world.setBlockState(pos.add(44, 20, 60), Blocks.STONE.getDefaultState());
      world.setBlockState(pos.add(45, 20, 60), Blocks.STONE.getDefaultState());
      world.setBlockState(pos.add(32, 20, 61), Blocks.REDSTONE_BLOCK.getDefaultState());
      world.setBlockState(pos.add(39, 20, 61), Blocks.REDSTONE_BLOCK.getDefaultState());
      world.setBlockState(pos.add(41, 20, 61), Blocks.STONE.getDefaultState());
      world.setBlockState(pos.add(46, 20, 61), Blocks.STONE.getDefaultState());
      world.setBlockState(pos.add(32, 20, 62), Blocks.REDSTONE_BLOCK.getDefaultState());
      world.setBlockState(pos.add(39, 20, 62), Blocks.REDSTONE_BLOCK.getDefaultState());
      world.setBlockState(pos.add(40, 20, 62), Blocks.STONE.getDefaultState());
      world.setBlockState(pos.add(47, 20, 62), Blocks.STONE.getDefaultState());
      world.setBlockState(pos.add(32, 20, 63), Blocks.REDSTONE_BLOCK.getDefaultState());
      world.setBlockState(pos.add(39, 20, 63), Blocks.REDSTONE_BLOCK.getDefaultState());
      world.setBlockState(pos.add(40, 20, 63), Blocks.STONE.getDefaultState());
      world.setBlockState(pos.add(47, 20, 63), Blocks.STONE.getDefaultState());
      world.setBlockState(pos.add(32, 20, 64), Blocks.REDSTONE_BLOCK.getDefaultState());
      world.setBlockState(pos.add(39, 20, 64), Blocks.REDSTONE_BLOCK.getDefaultState());
      world.setBlockState(pos.add(40, 20, 64), Blocks.STONE.getDefaultState());
      world.setBlockState(pos.add(47, 20, 64), Blocks.STONE.getDefaultState());
      world.setBlockState(pos.add(33, 20, 65), Blocks.REDSTONE_BLOCK.getDefaultState());
      world.setBlockState(pos.add(38, 20, 65), Blocks.REDSTONE_BLOCK.getDefaultState());
      world.setBlockState(pos.add(40, 20, 65), Blocks.STONE.getDefaultState());
      world.setBlockState(pos.add(47, 20, 65), Blocks.STONE.getDefaultState());
      world.setBlockState(pos.add(34, 20, 66), Blocks.REDSTONE_BLOCK.getDefaultState());
      world.setBlockState(pos.add(35, 20, 66), Blocks.REDSTONE_BLOCK.getDefaultState());
      world.setBlockState(pos.add(36, 20, 66), Blocks.REDSTONE_BLOCK.getDefaultState());
      world.setBlockState(pos.add(37, 20, 66), Blocks.REDSTONE_BLOCK.getDefaultState());
      world.setBlockState(pos.add(41, 20, 66), Blocks.STONE.getDefaultState());
      world.setBlockState(pos.add(46, 20, 66), Blocks.STONE.getDefaultState());
      world.setBlockState(pos.add(42, 20, 67), Blocks.STONE.getDefaultState());
      world.setBlockState(pos.add(43, 20, 67), Blocks.STONE.getDefaultState());
      world.setBlockState(pos.add(44, 20, 67), Blocks.STONE.getDefaultState());
      world.setBlockState(pos.add(45, 20, 67), Blocks.STONE.getDefaultState());
      world.setBlockState(pos.add(17, 21, 37), ((BlockColored)Blocks.STAINED_HARDENED_CLAY).getStateFromMeta(4));
      world.setBlockState(pos.add(18, 21, 37), ((BlockColored)Blocks.STAINED_HARDENED_CLAY).getStateFromMeta(4));
      world.setBlockState(pos.add(23, 21, 37), ((BlockColored)Blocks.STAINED_HARDENED_CLAY).getStateFromMeta(4));
      world.setBlockState(pos.add(24, 21, 37), ((BlockColored)Blocks.STAINED_HARDENED_CLAY).getStateFromMeta(4));
      world.setBlockState(pos.add(25, 21, 37), Blocks.DIAMOND_BLOCK.getDefaultState());
      world.setBlockState(pos.add(26, 21, 37), Blocks.DIAMOND_BLOCK.getDefaultState());
      world.setBlockState(pos.add(27, 21, 37), Blocks.DIAMOND_BLOCK.getDefaultState());
      world.setBlockState(pos.add(28, 21, 37), ((BlockColored)Blocks.STAINED_HARDENED_CLAY).getStateFromMeta(4));
      world.setBlockState(pos.add(29, 21, 37), ((BlockColored)Blocks.STAINED_HARDENED_CLAY).getStateFromMeta(4));
      world.setBlockState(pos.add(34, 21, 37), ((BlockColored)Blocks.STAINED_HARDENED_CLAY).getStateFromMeta(4));
      world.setBlockState(pos.add(35, 21, 37), ((BlockColored)Blocks.STAINED_HARDENED_CLAY).getStateFromMeta(4));
      world.setBlockState(pos.add(17, 21, 38), ((BlockColored)Blocks.STAINED_HARDENED_CLAY).getStateFromMeta(4));
      world.setBlockState(pos.add(18, 21, 38), ((BlockColored)Blocks.STAINED_HARDENED_CLAY).getStateFromMeta(4));
      world.setBlockState(pos.add(19, 21, 38), ((BlockColored)Blocks.STAINED_HARDENED_CLAY).getStateFromMeta(7));
      world.setBlockState(pos.add(20, 21, 38), ((BlockColored)Blocks.STAINED_HARDENED_CLAY).getStateFromMeta(7));
      world.setBlockState(pos.add(23, 21, 38), Blocks.DIAMOND_BLOCK.getDefaultState());
      world.setBlockState(pos.add(29, 21, 38), Blocks.DIAMOND_BLOCK.getDefaultState());
      world.setBlockState(pos.add(32, 21, 38), ((BlockColored)Blocks.STAINED_HARDENED_CLAY).getStateFromMeta(7));
      world.setBlockState(pos.add(33, 21, 38), ((BlockColored)Blocks.STAINED_HARDENED_CLAY).getStateFromMeta(7));
      world.setBlockState(pos.add(34, 21, 38), ((BlockColored)Blocks.STAINED_HARDENED_CLAY).getStateFromMeta(4));
      world.setBlockState(pos.add(35, 21, 38), ((BlockColored)Blocks.STAINED_HARDENED_CLAY).getStateFromMeta(4));
      world.setBlockState(pos.add(17, 21, 39), ((BlockColored)Blocks.STAINED_HARDENED_CLAY).getStateFromMeta(4));
      world.setBlockState(pos.add(20, 21, 39), ((BlockColored)Blocks.STAINED_HARDENED_CLAY).getStateFromMeta(4));
      world.setBlockState(pos.add(23, 21, 39), Blocks.DIAMOND_BLOCK.getDefaultState());
      world.setBlockState(pos.add(29, 21, 39), Blocks.DIAMOND_BLOCK.getDefaultState());
      world.setBlockState(pos.add(32, 21, 39), ((BlockColored)Blocks.STAINED_HARDENED_CLAY).getStateFromMeta(4));
      world.setBlockState(pos.add(35, 21, 39), ((BlockColored)Blocks.STAINED_HARDENED_CLAY).getStateFromMeta(4));
      world.setBlockState(pos.add(17, 21, 40), ((BlockColored)Blocks.STAINED_HARDENED_CLAY).getStateFromMeta(4));
      world.setBlockState(pos.add(20, 21, 40), ((BlockColored)Blocks.STAINED_HARDENED_CLAY).getStateFromMeta(4));
      world.setBlockState(pos.add(23, 21, 40), Blocks.DIAMOND_BLOCK.getDefaultState());
      world.setBlockState(pos.add(29, 21, 40), Blocks.DIAMOND_BLOCK.getDefaultState());
      world.setBlockState(pos.add(32, 21, 40), ((BlockColored)Blocks.STAINED_HARDENED_CLAY).getStateFromMeta(4));
      world.setBlockState(pos.add(34, 21, 40), ((BlockColored)Blocks.STAINED_HARDENED_CLAY).getStateFromMeta(4));
      world.setBlockState(pos.add(35, 21, 40), ((BlockColored)Blocks.STAINED_HARDENED_CLAY).getStateFromMeta(4));
      world.setBlockState(pos.add(18, 21, 41), Blocks.QUARTZ_BLOCK.getDefaultState());
      world.setBlockState(pos.add(20, 21, 41), Blocks.QUARTZ_BLOCK.getDefaultState());
      world.setBlockState(pos.add(23, 21, 41), ((BlockColored)Blocks.STAINED_HARDENED_CLAY).getStateFromMeta(4));
      world.setBlockState(pos.add(26, 21, 41), Blocks.STONE.getDefaultState());
      world.setBlockState(pos.add(27, 21, 41), Blocks.STONE.getDefaultState());
      world.setBlockState(pos.add(29, 21, 41), ((BlockColored)Blocks.STAINED_HARDENED_CLAY).getStateFromMeta(4));
      world.setBlockState(pos.add(32, 21, 41), Blocks.QUARTZ_BLOCK.getDefaultState());
      world.setBlockState(pos.add(34, 21, 41), Blocks.QUARTZ_BLOCK.getDefaultState());
      world.setBlockState(pos.add(18, 21, 42), Blocks.QUARTZ_BLOCK.getDefaultState());
      world.setBlockState(pos.add(20, 21, 42), Blocks.QUARTZ_BLOCK.getDefaultState());
      world.setBlockState(pos.add(23, 21, 42), ((BlockColored)Blocks.STAINED_HARDENED_CLAY).getStateFromMeta(4));
      world.setBlockState(pos.add(26, 21, 42), Blocks.STONE.getDefaultState());
      world.setBlockState(pos.add(27, 21, 42), Blocks.STONE.getDefaultState());
      world.setBlockState(pos.add(29, 21, 42), ((BlockColored)Blocks.STAINED_HARDENED_CLAY).getStateFromMeta(4));
      world.setBlockState(pos.add(32, 21, 42), Blocks.QUARTZ_BLOCK.getDefaultState());
      world.setBlockState(pos.add(34, 21, 42), Blocks.QUARTZ_BLOCK.getDefaultState());
      world.setBlockState(pos.add(17, 21, 43), ((BlockColored)Blocks.STAINED_HARDENED_CLAY).getStateFromMeta(4));
      world.setBlockState(pos.add(20, 21, 43), ((BlockColored)Blocks.STAINED_HARDENED_CLAY).getStateFromMeta(4));
      world.setBlockState(pos.add(23, 21, 43), Blocks.DIAMOND_BLOCK.getDefaultState());
      world.setBlockState(pos.add(29, 21, 43), Blocks.DIAMOND_BLOCK.getDefaultState());
      world.setBlockState(pos.add(32, 21, 43), ((BlockColored)Blocks.STAINED_HARDENED_CLAY).getStateFromMeta(4));
      world.setBlockState(pos.add(35, 21, 43), ((BlockColored)Blocks.STAINED_HARDENED_CLAY).getStateFromMeta(4));
      world.setBlockState(pos.add(17, 21, 44), ((BlockColored)Blocks.STAINED_HARDENED_CLAY).getStateFromMeta(4));
      world.setBlockState(pos.add(20, 21, 44), ((BlockColored)Blocks.STAINED_HARDENED_CLAY).getStateFromMeta(4));
      world.setBlockState(pos.add(23, 21, 44), Blocks.DIAMOND_BLOCK.getDefaultState());
      world.setBlockState(pos.add(29, 21, 44), Blocks.DIAMOND_BLOCK.getDefaultState());
      world.setBlockState(pos.add(32, 21, 44), ((BlockColored)Blocks.STAINED_HARDENED_CLAY).getStateFromMeta(4));
      world.setBlockState(pos.add(35, 21, 44), ((BlockColored)Blocks.STAINED_HARDENED_CLAY).getStateFromMeta(4));
      world.setBlockState(pos.add(17, 21, 45), ((BlockColored)Blocks.STAINED_HARDENED_CLAY).getStateFromMeta(4));
      world.setBlockState(pos.add(20, 21, 45), ((BlockColored)Blocks.STAINED_HARDENED_CLAY).getStateFromMeta(4));
      world.setBlockState(pos.add(23, 21, 45), Blocks.DIAMOND_BLOCK.getDefaultState());
      world.setBlockState(pos.add(29, 21, 45), Blocks.DIAMOND_BLOCK.getDefaultState());
      world.setBlockState(pos.add(32, 21, 45), ((BlockColored)Blocks.STAINED_HARDENED_CLAY).getStateFromMeta(4));
      world.setBlockState(pos.add(35, 21, 45), ((BlockColored)Blocks.STAINED_HARDENED_CLAY).getStateFromMeta(4));
      world.setBlockState(pos.add(18, 21, 46), Blocks.QUARTZ_BLOCK.getDefaultState());
      world.setBlockState(pos.add(19, 21, 46), Blocks.QUARTZ_BLOCK.getDefaultState());
      world.setBlockState(pos.add(20, 21, 46), Blocks.QUARTZ_BLOCK.getDefaultState());
      world.setBlockState(pos.add(23, 21, 46), ((BlockColored)Blocks.STAINED_HARDENED_CLAY).getStateFromMeta(4));
      world.setBlockState(pos.add(25, 21, 46), Blocks.STONE.getDefaultState());
      world.setBlockState(pos.add(26, 21, 46), Blocks.STONE.getDefaultState());
      world.setBlockState(pos.add(29, 21, 46), ((BlockColored)Blocks.STAINED_HARDENED_CLAY).getStateFromMeta(4));
      world.setBlockState(pos.add(32, 21, 46), Blocks.QUARTZ_BLOCK.getDefaultState());
      world.setBlockState(pos.add(34, 21, 46), Blocks.QUARTZ_BLOCK.getDefaultState());
      world.setBlockState(pos.add(18, 21, 47), Blocks.QUARTZ_BLOCK.getDefaultState());
      world.setBlockState(pos.add(19, 21, 47), Blocks.QUARTZ_BLOCK.getDefaultState());
      world.setBlockState(pos.add(20, 21, 47), Blocks.QUARTZ_BLOCK.getDefaultState());
      world.setBlockState(pos.add(23, 21, 47), ((BlockColored)Blocks.STAINED_HARDENED_CLAY).getStateFromMeta(4));
      world.setBlockState(pos.add(25, 21, 47), Blocks.STONE.getDefaultState());
      world.setBlockState(pos.add(26, 21, 47), Blocks.STONE.getDefaultState());
      world.setBlockState(pos.add(29, 21, 47), ((BlockColored)Blocks.STAINED_HARDENED_CLAY).getStateFromMeta(4));
      world.setBlockState(pos.add(32, 21, 47), Blocks.QUARTZ_BLOCK.getDefaultState());
      world.setBlockState(pos.add(34, 21, 47), Blocks.QUARTZ_BLOCK.getDefaultState());
      world.setBlockState(pos.add(17, 21, 48), ((BlockColored)Blocks.STAINED_HARDENED_CLAY).getStateFromMeta(4));
      world.setBlockState(pos.add(20, 21, 48), ((BlockColored)Blocks.STAINED_HARDENED_CLAY).getStateFromMeta(4));
      world.setBlockState(pos.add(23, 21, 48), Blocks.DIAMOND_BLOCK.getDefaultState());
      world.setBlockState(pos.add(29, 21, 48), Blocks.DIAMOND_BLOCK.getDefaultState());
      world.setBlockState(pos.add(32, 21, 48), ((BlockColored)Blocks.STAINED_HARDENED_CLAY).getStateFromMeta(4));
      world.setBlockState(pos.add(35, 21, 48), ((BlockColored)Blocks.STAINED_HARDENED_CLAY).getStateFromMeta(4));
      world.setBlockState(pos.add(17, 21, 49), ((BlockColored)Blocks.STAINED_HARDENED_CLAY).getStateFromMeta(4));
      world.setBlockState(pos.add(20, 21, 49), ((BlockColored)Blocks.STAINED_HARDENED_CLAY).getStateFromMeta(4));
      world.setBlockState(pos.add(23, 21, 49), Blocks.DIAMOND_BLOCK.getDefaultState());
      world.setBlockState(pos.add(29, 21, 49), Blocks.DIAMOND_BLOCK.getDefaultState());
      world.setBlockState(pos.add(32, 21, 49), ((BlockColored)Blocks.STAINED_HARDENED_CLAY).getStateFromMeta(4));
      world.setBlockState(pos.add(35, 21, 49), ((BlockColored)Blocks.STAINED_HARDENED_CLAY).getStateFromMeta(4));
      world.setBlockState(pos.add(17, 21, 50), ((BlockColored)Blocks.STAINED_HARDENED_CLAY).getStateFromMeta(4));
      world.setBlockState(pos.add(18, 21, 50), ((BlockColored)Blocks.STAINED_HARDENED_CLAY).getStateFromMeta(4));
      world.setBlockState(pos.add(19, 21, 50), ((BlockColored)Blocks.STAINED_HARDENED_CLAY).getStateFromMeta(4));
      world.setBlockState(pos.add(20, 21, 50), ((BlockColored)Blocks.STAINED_HARDENED_CLAY).getStateFromMeta(4));
      world.setBlockState(pos.add(21, 21, 50), ((BlockColored)Blocks.STAINED_HARDENED_CLAY).getStateFromMeta(4));
      world.setBlockState(pos.add(23, 21, 50), Blocks.DIAMOND_BLOCK.getDefaultState());
      world.setBlockState(pos.add(29, 21, 50), Blocks.DIAMOND_BLOCK.getDefaultState());
      world.setBlockState(pos.add(31, 21, 50), ((BlockColored)Blocks.STAINED_HARDENED_CLAY).getStateFromMeta(4));
      world.setBlockState(pos.add(32, 21, 50), ((BlockColored)Blocks.STAINED_HARDENED_CLAY).getStateFromMeta(4));
      world.setBlockState(pos.add(33, 21, 50), ((BlockColored)Blocks.STAINED_HARDENED_CLAY).getStateFromMeta(4));
      world.setBlockState(pos.add(34, 21, 50), ((BlockColored)Blocks.STAINED_HARDENED_CLAY).getStateFromMeta(4));
      world.setBlockState(pos.add(35, 21, 50), ((BlockColored)Blocks.STAINED_HARDENED_CLAY).getStateFromMeta(4));
      world.setBlockState(pos.add(18, 21, 51), ((BlockColored)Blocks.STAINED_HARDENED_CLAY).getStateFromMeta(4));
      world.setBlockState(pos.add(19, 21, 51), ((BlockColored)Blocks.STAINED_HARDENED_CLAY).getStateFromMeta(4));
      world.setBlockState(pos.add(20, 21, 51), ((BlockColored)Blocks.STAINED_HARDENED_CLAY).getStateFromMeta(4));
      world.setBlockState(pos.add(21, 21, 51), ((BlockColored)Blocks.STAINED_HARDENED_CLAY).getStateFromMeta(4));
      world.setBlockState(pos.add(22, 21, 51), ((BlockColored)Blocks.STAINED_HARDENED_CLAY).getStateFromMeta(4));
      world.setBlockState(pos.add(23, 21, 51), ((BlockColored)Blocks.STAINED_HARDENED_CLAY).getStateFromMeta(4));
      world.setBlockState(pos.add(24, 21, 51), ((BlockColored)Blocks.STAINED_HARDENED_CLAY).getStateFromMeta(4));
      world.setBlockState(pos.add(25, 21, 51), ((BlockColored)Blocks.STAINED_HARDENED_CLAY).getStateFromMeta(4));
      world.setBlockState(pos.add(26, 21, 51), ((BlockColored)Blocks.STAINED_HARDENED_CLAY).getStateFromMeta(4));
      world.setBlockState(pos.add(27, 21, 51), ((BlockColored)Blocks.STAINED_HARDENED_CLAY).getStateFromMeta(4));
      world.setBlockState(pos.add(28, 21, 51), ((BlockColored)Blocks.STAINED_HARDENED_CLAY).getStateFromMeta(4));
      world.setBlockState(pos.add(29, 21, 51), ((BlockColored)Blocks.STAINED_HARDENED_CLAY).getStateFromMeta(4));
      world.setBlockState(pos.add(30, 21, 51), ((BlockColored)Blocks.STAINED_HARDENED_CLAY).getStateFromMeta(4));
      world.setBlockState(pos.add(31, 21, 51), ((BlockColored)Blocks.STAINED_HARDENED_CLAY).getStateFromMeta(4));
      world.setBlockState(pos.add(32, 21, 51), ((BlockColored)Blocks.STAINED_HARDENED_CLAY).getStateFromMeta(4));
      world.setBlockState(pos.add(33, 21, 51), ((BlockColored)Blocks.STAINED_HARDENED_CLAY).getStateFromMeta(4));
      world.setBlockState(pos.add(34, 21, 51), ((BlockColored)Blocks.STAINED_HARDENED_CLAY).getStateFromMeta(4));
      world.setBlockState(pos.add(17, 21, 52), ((BlockColored)Blocks.STAINED_HARDENED_CLAY).getStateFromMeta(4));
      world.setBlockState(pos.add(18, 21, 52), ((BlockColored)Blocks.STAINED_HARDENED_CLAY).getStateFromMeta(4));
      world.setBlockState(pos.add(22, 21, 52), ((BlockColored)Blocks.STAINED_HARDENED_CLAY).getStateFromMeta(4));
      world.setBlockState(pos.add(23, 21, 52), ((BlockColored)Blocks.STAINED_HARDENED_CLAY).getStateFromMeta(4));
      world.setBlockState(pos.add(29, 21, 52), ((BlockColored)Blocks.STAINED_HARDENED_CLAY).getStateFromMeta(4));
      world.setBlockState(pos.add(30, 21, 52), ((BlockColored)Blocks.STAINED_HARDENED_CLAY).getStateFromMeta(4));
      world.setBlockState(pos.add(34, 21, 52), ((BlockColored)Blocks.STAINED_HARDENED_CLAY).getStateFromMeta(4));
      world.setBlockState(pos.add(35, 21, 52), ((BlockColored)Blocks.STAINED_HARDENED_CLAY).getStateFromMeta(4));
      world.setBlockState(pos.add(16, 21, 53), ((BlockColored)Blocks.STAINED_HARDENED_CLAY).getStateFromMeta(4));
      world.setBlockState(pos.add(17, 21, 53), ((BlockColored)Blocks.STAINED_HARDENED_CLAY).getStateFromMeta(4));
      world.setBlockState(pos.add(23, 21, 53), ((BlockColored)Blocks.STAINED_HARDENED_CLAY).getStateFromMeta(4));
      world.setBlockState(pos.add(24, 21, 53), ((BlockColored)Blocks.STAINED_HARDENED_CLAY).getStateFromMeta(4));
      world.setBlockState(pos.add(28, 21, 53), ((BlockColored)Blocks.STAINED_HARDENED_CLAY).getStateFromMeta(4));
      world.setBlockState(pos.add(29, 21, 53), ((BlockColored)Blocks.STAINED_HARDENED_CLAY).getStateFromMeta(4));
      world.setBlockState(pos.add(35, 21, 53), ((BlockColored)Blocks.STAINED_HARDENED_CLAY).getStateFromMeta(4));
      world.setBlockState(pos.add(36, 21, 53), ((BlockColored)Blocks.STAINED_HARDENED_CLAY).getStateFromMeta(4));
      world.setBlockState(pos.add(16, 21, 54), ((BlockColored)Blocks.STAINED_HARDENED_CLAY).getStateFromMeta(4));
      world.setBlockState(pos.add(17, 21, 54), ((BlockColored)Blocks.STAINED_HARDENED_CLAY).getStateFromMeta(4));
      world.setBlockState(pos.add(23, 21, 54), ((BlockColored)Blocks.STAINED_HARDENED_CLAY).getStateFromMeta(4));
      world.setBlockState(pos.add(24, 21, 54), ((BlockColored)Blocks.STAINED_HARDENED_CLAY).getStateFromMeta(4));
      world.setBlockState(pos.add(28, 21, 54), ((BlockColored)Blocks.STAINED_HARDENED_CLAY).getStateFromMeta(4));
      world.setBlockState(pos.add(29, 21, 54), ((BlockColored)Blocks.STAINED_HARDENED_CLAY).getStateFromMeta(4));
      world.setBlockState(pos.add(35, 21, 54), ((BlockColored)Blocks.STAINED_HARDENED_CLAY).getStateFromMeta(4));
      world.setBlockState(pos.add(36, 21, 54), ((BlockColored)Blocks.STAINED_HARDENED_CLAY).getStateFromMeta(4));
      world.setBlockState(pos.add(16, 21, 55), ((BlockColored)Blocks.STAINED_HARDENED_CLAY).getStateFromMeta(4));
      world.setBlockState(pos.add(17, 21, 55), ((BlockColored)Blocks.STAINED_HARDENED_CLAY).getStateFromMeta(4));
      world.setBlockState(pos.add(23, 21, 55), ((BlockColored)Blocks.STAINED_HARDENED_CLAY).getStateFromMeta(4));
      world.setBlockState(pos.add(24, 21, 55), ((BlockColored)Blocks.STAINED_HARDENED_CLAY).getStateFromMeta(4));
      world.setBlockState(pos.add(28, 21, 55), ((BlockColored)Blocks.STAINED_HARDENED_CLAY).getStateFromMeta(4));
      world.setBlockState(pos.add(29, 21, 55), ((BlockColored)Blocks.STAINED_HARDENED_CLAY).getStateFromMeta(4));
      world.setBlockState(pos.add(35, 21, 55), ((BlockColored)Blocks.STAINED_HARDENED_CLAY).getStateFromMeta(4));
      world.setBlockState(pos.add(36, 21, 55), ((BlockColored)Blocks.STAINED_HARDENED_CLAY).getStateFromMeta(4));
      world.setBlockState(pos.add(37, 21, 55), ((BlockColored)Blocks.STAINED_HARDENED_CLAY).getStateFromMeta(4));
      world.setBlockState(pos.add(39, 21, 55), Blocks.NETHER_BRICK_FENCE.getDefaultState());
      world.setBlockState(pos.add(40, 21, 55), Blocks.NETHER_BRICK_FENCE.getDefaultState());
      world.setBlockState(pos.add(41, 21, 55), Blocks.NETHER_BRICK_FENCE.getDefaultState());
      world.setBlockState(pos.add(17, 21, 56), ((BlockColored)Blocks.STAINED_HARDENED_CLAY).getStateFromMeta(4));
      world.setBlockState(pos.add(18, 21, 56), ((BlockColored)Blocks.STAINED_HARDENED_CLAY).getStateFromMeta(4));
      world.setBlockState(pos.add(22, 21, 56), ((BlockColored)Blocks.STAINED_HARDENED_CLAY).getStateFromMeta(4));
      world.setBlockState(pos.add(23, 21, 56), ((BlockColored)Blocks.STAINED_HARDENED_CLAY).getStateFromMeta(4));
      world.setBlockState(pos.add(29, 21, 56), ((BlockColored)Blocks.STAINED_HARDENED_CLAY).getStateFromMeta(4));
      world.setBlockState(pos.add(30, 21, 56), ((BlockColored)Blocks.STAINED_HARDENED_CLAY).getStateFromMeta(4));
      world.setBlockState(pos.add(34, 21, 56), ((BlockColored)Blocks.STAINED_HARDENED_CLAY).getStateFromMeta(4));
      world.setBlockState(pos.add(35, 21, 56), ((BlockColored)Blocks.STAINED_HARDENED_CLAY).getStateFromMeta(4));
      world.setBlockState(pos.add(38, 21, 56), ((BlockColored)Blocks.STAINED_HARDENED_CLAY).getStateFromMeta(4));
      world.setBlockState(pos.add(39, 21, 56), Blocks.REDSTONE_BLOCK.getDefaultState());
      world.setBlockState(pos.add(40, 21, 56), Blocks.REDSTONE_BLOCK.getDefaultState());
      world.setBlockState(pos.add(41, 21, 56), Blocks.NETHER_BRICK_FENCE.getDefaultState());
      world.setBlockState(pos.add(42, 21, 56), Blocks.NETHER_BRICK_FENCE.getDefaultState());
      world.setBlockState(pos.add(18, 21, 57), ((BlockColored)Blocks.STAINED_HARDENED_CLAY).getStateFromMeta(4));
      world.setBlockState(pos.add(19, 21, 57), ((BlockColored)Blocks.STAINED_HARDENED_CLAY).getStateFromMeta(4));
      world.setBlockState(pos.add(20, 21, 57), ((BlockColored)Blocks.STAINED_HARDENED_CLAY).getStateFromMeta(4));
      world.setBlockState(pos.add(21, 21, 57), ((BlockColored)Blocks.STAINED_HARDENED_CLAY).getStateFromMeta(4));
      world.setBlockState(pos.add(22, 21, 57), ((BlockColored)Blocks.STAINED_HARDENED_CLAY).getStateFromMeta(4));
      world.setBlockState(pos.add(30, 21, 57), ((BlockColored)Blocks.STAINED_HARDENED_CLAY).getStateFromMeta(4));
      world.setBlockState(pos.add(31, 21, 57), ((BlockColored)Blocks.STAINED_HARDENED_CLAY).getStateFromMeta(4));
      world.setBlockState(pos.add(32, 21, 57), ((BlockColored)Blocks.STAINED_HARDENED_CLAY).getStateFromMeta(4));
      world.setBlockState(pos.add(33, 21, 57), ((BlockColored)Blocks.STAINED_HARDENED_CLAY).getStateFromMeta(4));
      world.setBlockState(pos.add(34, 21, 57), ((BlockColored)Blocks.STAINED_HARDENED_CLAY).getStateFromMeta(4));
      world.setBlockState(pos.add(39, 21, 57), ((BlockColored)Blocks.STAINED_HARDENED_CLAY).getStateFromMeta(4));
      world.setBlockState(pos.add(41, 21, 57), Blocks.REDSTONE_BLOCK.getDefaultState());
      world.setBlockState(pos.add(42, 21, 57), Blocks.NETHER_BRICK_FENCE.getDefaultState());
      world.setBlockState(pos.add(43, 21, 57), Blocks.NETHER_BRICK_FENCE.getDefaultState());
      world.setBlockState(pos.add(19, 21, 58), ((BlockColored)Blocks.STAINED_HARDENED_CLAY).getStateFromMeta(4));
      world.setBlockState(pos.add(20, 21, 58), ((BlockColored)Blocks.STAINED_HARDENED_CLAY).getStateFromMeta(4));
      world.setBlockState(pos.add(21, 21, 58), ((BlockColored)Blocks.STAINED_HARDENED_CLAY).getStateFromMeta(4));
      world.setBlockState(pos.add(31, 21, 58), ((BlockColored)Blocks.STAINED_HARDENED_CLAY).getStateFromMeta(4));
      world.setBlockState(pos.add(32, 21, 58), ((BlockColored)Blocks.STAINED_HARDENED_CLAY).getStateFromMeta(4));
      world.setBlockState(pos.add(33, 21, 58), ((BlockColored)Blocks.STAINED_HARDENED_CLAY).getStateFromMeta(4));
      world.setBlockState(pos.add(40, 21, 58), ((BlockColored)Blocks.STAINED_HARDENED_CLAY).getStateFromMeta(4));
      world.setBlockState(pos.add(42, 21, 58), Blocks.REDSTONE_BLOCK.getDefaultState());
      world.setBlockState(pos.add(43, 21, 58), Blocks.NETHER_BRICK_FENCE.getDefaultState());
      world.setBlockState(pos.add(34, 21, 59), ((BlockColored)Blocks.WOOL).getStateFromMeta(15));
      world.setBlockState(pos.add(35, 21, 59), ((BlockColored)Blocks.WOOL).getStateFromMeta(15));
      world.setBlockState(pos.add(36, 21, 59), ((BlockColored)Blocks.WOOL).getStateFromMeta(15));
      world.setBlockState(pos.add(37, 21, 59), ((BlockColored)Blocks.WOOL).getStateFromMeta(15));
      world.setBlockState(pos.add(41, 21, 59), ((BlockColored)Blocks.STAINED_HARDENED_CLAY).getStateFromMeta(4));
      world.setBlockState(pos.add(42, 21, 59), Blocks.REDSTONE_BLOCK.getDefaultState());
      world.setBlockState(pos.add(43, 21, 59), Blocks.NETHER_BRICK_FENCE.getDefaultState());
      world.setBlockState(pos.add(33, 21, 60), ((BlockColored)Blocks.WOOL).getStateFromMeta(15));
      world.setBlockState(pos.add(38, 21, 60), ((BlockColored)Blocks.WOOL).getStateFromMeta(15));
      world.setBlockState(pos.add(42, 21, 60), Blocks.STONE.getDefaultState());
      world.setBlockState(pos.add(43, 21, 60), Blocks.STONE.getDefaultState());
      world.setBlockState(pos.add(44, 21, 60), Blocks.STONE.getDefaultState());
      world.setBlockState(pos.add(45, 21, 60), Blocks.STONE.getDefaultState());
      world.setBlockState(pos.add(32, 21, 61), ((BlockColored)Blocks.WOOL).getStateFromMeta(15));
      world.setBlockState(pos.add(39, 21, 61), ((BlockColored)Blocks.WOOL).getStateFromMeta(15));
      world.setBlockState(pos.add(41, 21, 61), Blocks.STONE.getDefaultState());
      world.setBlockState(pos.add(46, 21, 61), Blocks.STONE.getDefaultState());
      world.setBlockState(pos.add(32, 21, 62), ((BlockColored)Blocks.WOOL).getStateFromMeta(15));
      world.setBlockState(pos.add(39, 21, 62), ((BlockColored)Blocks.WOOL).getStateFromMeta(15));
      world.setBlockState(pos.add(40, 21, 62), Blocks.STONE.getDefaultState());
      world.setBlockState(pos.add(47, 21, 62), Blocks.STONE.getDefaultState());
      world.setBlockState(pos.add(32, 21, 63), ((BlockColored)Blocks.WOOL).getStateFromMeta(15));
      world.setBlockState(pos.add(39, 21, 63), ((BlockColored)Blocks.WOOL).getStateFromMeta(15));
      world.setBlockState(pos.add(40, 21, 63), Blocks.STONE.getDefaultState());
      world.setBlockState(pos.add(47, 21, 63), Blocks.STONE.getDefaultState());
      world.setBlockState(pos.add(32, 21, 64), ((BlockColored)Blocks.WOOL).getStateFromMeta(15));
      world.setBlockState(pos.add(39, 21, 64), ((BlockColored)Blocks.WOOL).getStateFromMeta(15));
      world.setBlockState(pos.add(40, 21, 64), Blocks.STONE.getDefaultState());
      world.setBlockState(pos.add(47, 21, 64), Blocks.STONE.getDefaultState());
      world.setBlockState(pos.add(33, 21, 65), ((BlockColored)Blocks.WOOL).getStateFromMeta(15));
      world.setBlockState(pos.add(38, 21, 65), ((BlockColored)Blocks.WOOL).getStateFromMeta(15));
      world.setBlockState(pos.add(40, 21, 65), Blocks.STONE.getDefaultState());
      world.setBlockState(pos.add(47, 21, 65), Blocks.STONE.getDefaultState());
      world.setBlockState(pos.add(34, 21, 66), ((BlockColored)Blocks.WOOL).getStateFromMeta(15));
      world.setBlockState(pos.add(35, 21, 66), ((BlockColored)Blocks.WOOL).getStateFromMeta(15));
      world.setBlockState(pos.add(36, 21, 66), ((BlockColored)Blocks.WOOL).getStateFromMeta(15));
      world.setBlockState(pos.add(37, 21, 66), ((BlockColored)Blocks.WOOL).getStateFromMeta(15));
      world.setBlockState(pos.add(41, 21, 66), Blocks.STONE.getDefaultState());
      world.setBlockState(pos.add(46, 21, 66), Blocks.STONE.getDefaultState());
      world.setBlockState(pos.add(42, 21, 67), Blocks.STONE.getDefaultState());
      world.setBlockState(pos.add(43, 21, 67), Blocks.STONE.getDefaultState());
      world.setBlockState(pos.add(44, 21, 67), Blocks.STONE.getDefaultState());
      world.setBlockState(pos.add(45, 21, 67), Blocks.STONE.getDefaultState());
      world.setBlockState(pos.add(17, 22, 37), ((BlockColored)Blocks.STAINED_HARDENED_CLAY).getStateFromMeta(4));
      world.setBlockState(pos.add(18, 22, 37), ((BlockColored)Blocks.STAINED_HARDENED_CLAY).getStateFromMeta(4));
      world.setBlockState(pos.add(19, 22, 37), ((BlockColored)Blocks.STAINED_HARDENED_CLAY).getStateFromMeta(4));
      world.setBlockState(pos.add(20, 22, 37), ((BlockColored)Blocks.STAINED_HARDENED_CLAY).getStateFromMeta(4));
      world.setBlockState(pos.add(23, 22, 37), ((BlockColored)Blocks.STAINED_HARDENED_CLAY).getStateFromMeta(4));
      world.setBlockState(pos.add(24, 22, 37), Blocks.DIAMOND_BLOCK.getDefaultState());
      world.setBlockState(pos.add(25, 22, 37), Blocks.DIAMOND_BLOCK.getDefaultState());
      world.setBlockState(pos.add(26, 22, 37), Blocks.STAINED_GLASS.getStateFromMeta(11));
      world.setBlockState(pos.add(27, 22, 37), Blocks.DIAMOND_BLOCK.getDefaultState());
      world.setBlockState(pos.add(28, 22, 37), Blocks.DIAMOND_BLOCK.getDefaultState());
      world.setBlockState(pos.add(29, 22, 37), ((BlockColored)Blocks.STAINED_HARDENED_CLAY).getStateFromMeta(4));
      world.setBlockState(pos.add(32, 22, 37), ((BlockColored)Blocks.STAINED_HARDENED_CLAY).getStateFromMeta(4));
      world.setBlockState(pos.add(33, 22, 37), ((BlockColored)Blocks.STAINED_HARDENED_CLAY).getStateFromMeta(4));
      world.setBlockState(pos.add(34, 22, 37), ((BlockColored)Blocks.STAINED_HARDENED_CLAY).getStateFromMeta(4));
      world.setBlockState(pos.add(35, 22, 37), ((BlockColored)Blocks.STAINED_HARDENED_CLAY).getStateFromMeta(4));
      world.setBlockState(pos.add(17, 22, 38), ((BlockColored)Blocks.STAINED_HARDENED_CLAY).getStateFromMeta(4));
      world.setBlockState(pos.add(18, 22, 38), ((BlockColored)Blocks.STAINED_HARDENED_CLAY).getStateFromMeta(4));
      world.setBlockState(pos.add(19, 22, 38), ((BlockColored)Blocks.STAINED_HARDENED_CLAY).getStateFromMeta(4));
      world.setBlockState(pos.add(20, 22, 38), ((BlockColored)Blocks.STAINED_HARDENED_CLAY).getStateFromMeta(4));
      world.setBlockState(pos.add(23, 22, 38), Blocks.DIAMOND_BLOCK.getDefaultState());
      world.setBlockState(pos.add(26, 22, 38), Blocks.GLOWSTONE.getDefaultState());
      world.setBlockState(pos.add(29, 22, 38), Blocks.DIAMOND_BLOCK.getDefaultState());
      world.setBlockState(pos.add(32, 22, 38), ((BlockColored)Blocks.STAINED_HARDENED_CLAY).getStateFromMeta(4));
      world.setBlockState(pos.add(33, 22, 38), ((BlockColored)Blocks.STAINED_HARDENED_CLAY).getStateFromMeta(4));
      world.setBlockState(pos.add(34, 22, 38), ((BlockColored)Blocks.STAINED_HARDENED_CLAY).getStateFromMeta(4));
      world.setBlockState(pos.add(35, 22, 38), ((BlockColored)Blocks.STAINED_HARDENED_CLAY).getStateFromMeta(4));
      world.setBlockState(pos.add(17, 22, 39), ((BlockColored)Blocks.STAINED_HARDENED_CLAY).getStateFromMeta(4));
      world.setBlockState(pos.add(20, 22, 39), ((BlockColored)Blocks.STAINED_HARDENED_CLAY).getStateFromMeta(4));
      world.setBlockState(pos.add(23, 22, 39), Blocks.DIAMOND_BLOCK.getDefaultState());
      world.setBlockState(pos.add(29, 22, 39), Blocks.DIAMOND_BLOCK.getDefaultState());
      world.setBlockState(pos.add(32, 22, 39), ((BlockColored)Blocks.STAINED_HARDENED_CLAY).getStateFromMeta(4));
      world.setBlockState(pos.add(35, 22, 39), ((BlockColored)Blocks.STAINED_HARDENED_CLAY).getStateFromMeta(4));
      world.setBlockState(pos.add(17, 22, 40), ((BlockColored)Blocks.STAINED_HARDENED_CLAY).getStateFromMeta(4));
      world.setBlockState(pos.add(20, 22, 40), ((BlockColored)Blocks.STAINED_HARDENED_CLAY).getStateFromMeta(4));
      world.setBlockState(pos.add(23, 22, 40), Blocks.DIAMOND_BLOCK.getDefaultState());
      world.setBlockState(pos.add(29, 22, 40), Blocks.DIAMOND_BLOCK.getDefaultState());
      world.setBlockState(pos.add(32, 22, 40), ((BlockColored)Blocks.STAINED_HARDENED_CLAY).getStateFromMeta(4));
      world.setBlockState(pos.add(33, 22, 40), ((BlockColored)Blocks.STAINED_HARDENED_CLAY).getStateFromMeta(4));
      world.setBlockState(pos.add(34, 22, 40), ((BlockColored)Blocks.STAINED_HARDENED_CLAY).getStateFromMeta(4));
      world.setBlockState(pos.add(35, 22, 40), ((BlockColored)Blocks.STAINED_HARDENED_CLAY).getStateFromMeta(4));
      world.setBlockState(pos.add(18, 22, 41), Blocks.QUARTZ_BLOCK.getDefaultState());
      world.setBlockState(pos.add(19, 22, 41), Blocks.QUARTZ_BLOCK.getDefaultState());
      world.setBlockState(pos.add(20, 22, 41), Blocks.QUARTZ_BLOCK.getDefaultState());
      world.setBlockState(pos.add(23, 22, 41), ((BlockColored)Blocks.STAINED_HARDENED_CLAY).getStateFromMeta(4));
      world.setBlockState(pos.add(26, 22, 41), Blocks.STONE.getDefaultState());
      world.setBlockState(pos.add(27, 22, 41), Blocks.STONE.getDefaultState());
      world.setBlockState(pos.add(29, 22, 41), ((BlockColored)Blocks.STAINED_HARDENED_CLAY).getStateFromMeta(4));
      world.setBlockState(pos.add(32, 22, 41), Blocks.QUARTZ_BLOCK.getDefaultState());
      world.setBlockState(pos.add(34, 22, 41), Blocks.QUARTZ_BLOCK.getDefaultState());
      world.setBlockState(pos.add(18, 22, 42), Blocks.QUARTZ_BLOCK.getDefaultState());
      world.setBlockState(pos.add(20, 22, 42), Blocks.QUARTZ_BLOCK.getDefaultState());
      world.setBlockState(pos.add(23, 22, 42), ((BlockColored)Blocks.STAINED_HARDENED_CLAY).getStateFromMeta(4));
      world.setBlockState(pos.add(26, 22, 42), Blocks.STONE.getDefaultState());
      world.setBlockState(pos.add(27, 22, 42), Blocks.STONE.getDefaultState());
      world.setBlockState(pos.add(29, 22, 42), ((BlockColored)Blocks.STAINED_HARDENED_CLAY).getStateFromMeta(4));
      world.setBlockState(pos.add(32, 22, 42), Blocks.QUARTZ_BLOCK.getDefaultState());
      world.setBlockState(pos.add(34, 22, 42), Blocks.QUARTZ_BLOCK.getDefaultState());
      world.setBlockState(pos.add(17, 22, 43), ((BlockColored)Blocks.STAINED_HARDENED_CLAY).getStateFromMeta(4));
      world.setBlockState(pos.add(18, 22, 43), ((BlockColored)Blocks.STAINED_HARDENED_CLAY).getStateFromMeta(4));
      world.setBlockState(pos.add(20, 22, 43), ((BlockColored)Blocks.STAINED_HARDENED_CLAY).getStateFromMeta(4));
      world.setBlockState(pos.add(23, 22, 43), Blocks.DIAMOND_BLOCK.getDefaultState());
      world.setBlockState(pos.add(29, 22, 43), Blocks.DIAMOND_BLOCK.getDefaultState());
      world.setBlockState(pos.add(32, 22, 43), ((BlockColored)Blocks.STAINED_HARDENED_CLAY).getStateFromMeta(4));
      world.setBlockState(pos.add(35, 22, 43), ((BlockColored)Blocks.STAINED_HARDENED_CLAY).getStateFromMeta(4));
      world.setBlockState(pos.add(17, 22, 44), ((BlockColored)Blocks.STAINED_HARDENED_CLAY).getStateFromMeta(4));
      world.setBlockState(pos.add(20, 22, 44), ((BlockColored)Blocks.STAINED_HARDENED_CLAY).getStateFromMeta(4));
      world.setBlockState(pos.add(23, 22, 44), Blocks.DIAMOND_BLOCK.getDefaultState());
      world.setBlockState(pos.add(29, 22, 44), Blocks.DIAMOND_BLOCK.getDefaultState());
      world.setBlockState(pos.add(32, 22, 44), ((BlockColored)Blocks.STAINED_HARDENED_CLAY).getStateFromMeta(4));
      world.setBlockState(pos.add(35, 22, 44), ((BlockColored)Blocks.STAINED_HARDENED_CLAY).getStateFromMeta(4));
      world.setBlockState(pos.add(17, 22, 45), ((BlockColored)Blocks.STAINED_HARDENED_CLAY).getStateFromMeta(4));
      world.setBlockState(pos.add(20, 22, 45), ((BlockColored)Blocks.STAINED_HARDENED_CLAY).getStateFromMeta(4));
      world.setBlockState(pos.add(23, 22, 45), Blocks.DIAMOND_BLOCK.getDefaultState());
      world.setBlockState(pos.add(29, 22, 45), Blocks.DIAMOND_BLOCK.getDefaultState());
      world.setBlockState(pos.add(32, 22, 45), ((BlockColored)Blocks.STAINED_HARDENED_CLAY).getStateFromMeta(4));
      world.setBlockState(pos.add(35, 22, 45), ((BlockColored)Blocks.STAINED_HARDENED_CLAY).getStateFromMeta(4));
      world.setBlockState(pos.add(18, 22, 46), Blocks.QUARTZ_BLOCK.getDefaultState());
      world.setBlockState(pos.add(19, 22, 46), Blocks.QUARTZ_BLOCK.getDefaultState());
      world.setBlockState(pos.add(20, 22, 46), Blocks.QUARTZ_BLOCK.getDefaultState());
      world.setBlockState(pos.add(23, 22, 46), ((BlockColored)Blocks.STAINED_HARDENED_CLAY).getStateFromMeta(4));
      world.setBlockState(pos.add(25, 22, 46), Blocks.STONE.getDefaultState());
      world.setBlockState(pos.add(26, 22, 46), Blocks.STONE.getDefaultState());
      world.setBlockState(pos.add(29, 22, 46), ((BlockColored)Blocks.STAINED_HARDENED_CLAY).getStateFromMeta(4));
      world.setBlockState(pos.add(32, 22, 46), Blocks.QUARTZ_BLOCK.getDefaultState());
      world.setBlockState(pos.add(33, 22, 46), Blocks.QUARTZ_BLOCK.getDefaultState());
      world.setBlockState(pos.add(34, 22, 46), Blocks.QUARTZ_BLOCK.getDefaultState());
      world.setBlockState(pos.add(18, 22, 47), Blocks.QUARTZ_BLOCK.getDefaultState());
      world.setBlockState(pos.add(19, 22, 47), Blocks.QUARTZ_BLOCK.getDefaultState());
      world.setBlockState(pos.add(20, 22, 47), Blocks.QUARTZ_BLOCK.getDefaultState());
      world.setBlockState(pos.add(23, 22, 47), ((BlockColored)Blocks.STAINED_HARDENED_CLAY).getStateFromMeta(4));
      world.setBlockState(pos.add(25, 22, 47), Blocks.STONE.getDefaultState());
      world.setBlockState(pos.add(26, 22, 47), Blocks.STONE.getDefaultState());
      world.setBlockState(pos.add(29, 22, 47), ((BlockColored)Blocks.STAINED_HARDENED_CLAY).getStateFromMeta(4));
      world.setBlockState(pos.add(32, 22, 47), Blocks.QUARTZ_BLOCK.getDefaultState());
      world.setBlockState(pos.add(33, 22, 47), Blocks.QUARTZ_BLOCK.getDefaultState());
      world.setBlockState(pos.add(34, 22, 47), Blocks.QUARTZ_BLOCK.getDefaultState());
      world.setBlockState(pos.add(17, 22, 48), ((BlockColored)Blocks.STAINED_HARDENED_CLAY).getStateFromMeta(4));
      world.setBlockState(pos.add(20, 22, 48), ((BlockColored)Blocks.STAINED_HARDENED_CLAY).getStateFromMeta(4));
      world.setBlockState(pos.add(23, 22, 48), Blocks.DIAMOND_BLOCK.getDefaultState());
      world.setBlockState(pos.add(29, 22, 48), Blocks.DIAMOND_BLOCK.getDefaultState());
      world.setBlockState(pos.add(32, 22, 48), ((BlockColored)Blocks.STAINED_HARDENED_CLAY).getStateFromMeta(4));
      world.setBlockState(pos.add(34, 22, 48), ((BlockColored)Blocks.STAINED_HARDENED_CLAY).getStateFromMeta(4));
      world.setBlockState(pos.add(35, 22, 48), ((BlockColored)Blocks.STAINED_HARDENED_CLAY).getStateFromMeta(4));
      world.setBlockState(pos.add(17, 22, 49), ((BlockColored)Blocks.STAINED_HARDENED_CLAY).getStateFromMeta(4));
      world.setBlockState(pos.add(20, 22, 49), ((BlockColored)Blocks.STAINED_HARDENED_CLAY).getStateFromMeta(4));
      world.setBlockState(pos.add(23, 22, 49), Blocks.DIAMOND_BLOCK.getDefaultState());
      world.setBlockState(pos.add(29, 22, 49), Blocks.DIAMOND_BLOCK.getDefaultState());
      world.setBlockState(pos.add(32, 22, 49), ((BlockColored)Blocks.STAINED_HARDENED_CLAY).getStateFromMeta(4));
      world.setBlockState(pos.add(35, 22, 49), ((BlockColored)Blocks.STAINED_HARDENED_CLAY).getStateFromMeta(4));
      world.setBlockState(pos.add(17, 22, 50), ((BlockColored)Blocks.STAINED_HARDENED_CLAY).getStateFromMeta(4));
      world.setBlockState(pos.add(18, 22, 50), ((BlockColored)Blocks.STAINED_HARDENED_CLAY).getStateFromMeta(4));
      world.setBlockState(pos.add(19, 22, 50), ((BlockColored)Blocks.STAINED_HARDENED_CLAY).getStateFromMeta(4));
      world.setBlockState(pos.add(20, 22, 50), ((BlockColored)Blocks.STAINED_HARDENED_CLAY).getStateFromMeta(4));
      world.setBlockState(pos.add(21, 22, 50), ((BlockColored)Blocks.STAINED_HARDENED_CLAY).getStateFromMeta(4));
      world.setBlockState(pos.add(23, 22, 50), Blocks.DIAMOND_BLOCK.getDefaultState());
      world.setBlockState(pos.add(29, 22, 50), Blocks.DIAMOND_BLOCK.getDefaultState());
      world.setBlockState(pos.add(31, 22, 50), ((BlockColored)Blocks.STAINED_HARDENED_CLAY).getStateFromMeta(4));
      world.setBlockState(pos.add(32, 22, 50), ((BlockColored)Blocks.STAINED_HARDENED_CLAY).getStateFromMeta(4));
      world.setBlockState(pos.add(33, 22, 50), ((BlockColored)Blocks.STAINED_HARDENED_CLAY).getStateFromMeta(4));
      world.setBlockState(pos.add(34, 22, 50), ((BlockColored)Blocks.STAINED_HARDENED_CLAY).getStateFromMeta(4));
      world.setBlockState(pos.add(35, 22, 50), ((BlockColored)Blocks.STAINED_HARDENED_CLAY).getStateFromMeta(4));
      world.setBlockState(pos.add(18, 22, 51), ((BlockColored)Blocks.STAINED_HARDENED_CLAY).getStateFromMeta(4));
      world.setBlockState(pos.add(19, 22, 51), ((BlockColored)Blocks.STAINED_HARDENED_CLAY).getStateFromMeta(4));
      world.setBlockState(pos.add(20, 22, 51), ((BlockColored)Blocks.STAINED_HARDENED_CLAY).getStateFromMeta(4));
      world.setBlockState(pos.add(21, 22, 51), ((BlockColored)Blocks.STAINED_HARDENED_CLAY).getStateFromMeta(4));
      world.setBlockState(pos.add(22, 22, 51), ((BlockColored)Blocks.STAINED_HARDENED_CLAY).getStateFromMeta(4));
      world.setBlockState(pos.add(23, 22, 51), ((BlockColored)Blocks.STAINED_HARDENED_CLAY).getStateFromMeta(4));
      world.setBlockState(pos.add(24, 22, 51), ((BlockColored)Blocks.STAINED_HARDENED_CLAY).getStateFromMeta(4));
      world.setBlockState(pos.add(25, 22, 51), ((BlockColored)Blocks.STAINED_HARDENED_CLAY).getStateFromMeta(4));
      world.setBlockState(pos.add(26, 22, 51), ((BlockColored)Blocks.STAINED_HARDENED_CLAY).getStateFromMeta(4));
      world.setBlockState(pos.add(27, 22, 51), ((BlockColored)Blocks.STAINED_HARDENED_CLAY).getStateFromMeta(4));
      world.setBlockState(pos.add(28, 22, 51), ((BlockColored)Blocks.STAINED_HARDENED_CLAY).getStateFromMeta(4));
      world.setBlockState(pos.add(29, 22, 51), ((BlockColored)Blocks.STAINED_HARDENED_CLAY).getStateFromMeta(4));
      world.setBlockState(pos.add(30, 22, 51), ((BlockColored)Blocks.STAINED_HARDENED_CLAY).getStateFromMeta(4));
      world.setBlockState(pos.add(31, 22, 51), ((BlockColored)Blocks.STAINED_HARDENED_CLAY).getStateFromMeta(4));
      world.setBlockState(pos.add(32, 22, 51), ((BlockColored)Blocks.STAINED_HARDENED_CLAY).getStateFromMeta(4));
      world.setBlockState(pos.add(33, 22, 51), ((BlockColored)Blocks.STAINED_HARDENED_CLAY).getStateFromMeta(4));
      world.setBlockState(pos.add(34, 22, 51), ((BlockColored)Blocks.STAINED_HARDENED_CLAY).getStateFromMeta(4));
      world.setBlockState(pos.add(17, 22, 52), ((BlockColored)Blocks.STAINED_HARDENED_CLAY).getStateFromMeta(4));
      world.setBlockState(pos.add(18, 22, 52), ((BlockColored)Blocks.STAINED_HARDENED_CLAY).getStateFromMeta(4));
      world.setBlockState(pos.add(22, 22, 52), ((BlockColored)Blocks.STAINED_HARDENED_CLAY).getStateFromMeta(4));
      world.setBlockState(pos.add(23, 22, 52), ((BlockColored)Blocks.STAINED_HARDENED_CLAY).getStateFromMeta(4));
      world.setBlockState(pos.add(29, 22, 52), ((BlockColored)Blocks.STAINED_HARDENED_CLAY).getStateFromMeta(4));
      world.setBlockState(pos.add(30, 22, 52), ((BlockColored)Blocks.STAINED_HARDENED_CLAY).getStateFromMeta(4));
      world.setBlockState(pos.add(34, 22, 52), ((BlockColored)Blocks.STAINED_HARDENED_CLAY).getStateFromMeta(4));
      world.setBlockState(pos.add(35, 22, 52), ((BlockColored)Blocks.STAINED_HARDENED_CLAY).getStateFromMeta(4));
      world.setBlockState(pos.add(16, 22, 53), ((BlockColored)Blocks.STAINED_HARDENED_CLAY).getStateFromMeta(4));
      world.setBlockState(pos.add(17, 22, 53), ((BlockColored)Blocks.STAINED_HARDENED_CLAY).getStateFromMeta(4));
      world.setBlockState(pos.add(23, 22, 53), ((BlockColored)Blocks.STAINED_HARDENED_CLAY).getStateFromMeta(4));
      world.setBlockState(pos.add(24, 22, 53), ((BlockColored)Blocks.STAINED_HARDENED_CLAY).getStateFromMeta(4));
      world.setBlockState(pos.add(28, 22, 53), ((BlockColored)Blocks.STAINED_HARDENED_CLAY).getStateFromMeta(4));
      world.setBlockState(pos.add(29, 22, 53), ((BlockColored)Blocks.STAINED_HARDENED_CLAY).getStateFromMeta(4));
      world.setBlockState(pos.add(35, 22, 53), ((BlockColored)Blocks.STAINED_HARDENED_CLAY).getStateFromMeta(4));
      world.setBlockState(pos.add(36, 22, 53), ((BlockColored)Blocks.STAINED_HARDENED_CLAY).getStateFromMeta(4));
      world.setBlockState(pos.add(16, 22, 54), ((BlockColored)Blocks.STAINED_HARDENED_CLAY).getStateFromMeta(4));
      world.setBlockState(pos.add(17, 22, 54), ((BlockColored)Blocks.STAINED_HARDENED_CLAY).getStateFromMeta(4));
      world.setBlockState(pos.add(23, 22, 54), ((BlockColored)Blocks.STAINED_HARDENED_CLAY).getStateFromMeta(4));
      world.setBlockState(pos.add(24, 22, 54), ((BlockColored)Blocks.STAINED_HARDENED_CLAY).getStateFromMeta(4));
      world.setBlockState(pos.add(28, 22, 54), ((BlockColored)Blocks.STAINED_HARDENED_CLAY).getStateFromMeta(4));
      world.setBlockState(pos.add(29, 22, 54), ((BlockColored)Blocks.STAINED_HARDENED_CLAY).getStateFromMeta(4));
      world.setBlockState(pos.add(35, 22, 54), ((BlockColored)Blocks.STAINED_HARDENED_CLAY).getStateFromMeta(4));
      world.setBlockState(pos.add(36, 22, 54), ((BlockColored)Blocks.STAINED_HARDENED_CLAY).getStateFromMeta(4));
      world.setBlockState(pos.add(16, 22, 55), ((BlockColored)Blocks.STAINED_HARDENED_CLAY).getStateFromMeta(4));
      world.setBlockState(pos.add(17, 22, 55), ((BlockColored)Blocks.STAINED_HARDENED_CLAY).getStateFromMeta(4));
      world.setBlockState(pos.add(23, 22, 55), ((BlockColored)Blocks.STAINED_HARDENED_CLAY).getStateFromMeta(4));
      world.setBlockState(pos.add(24, 22, 55), ((BlockColored)Blocks.STAINED_HARDENED_CLAY).getStateFromMeta(4));
      world.setBlockState(pos.add(28, 22, 55), ((BlockColored)Blocks.STAINED_HARDENED_CLAY).getStateFromMeta(4));
      world.setBlockState(pos.add(29, 22, 55), ((BlockColored)Blocks.STAINED_HARDENED_CLAY).getStateFromMeta(4));
      world.setBlockState(pos.add(35, 22, 55), ((BlockColored)Blocks.STAINED_HARDENED_CLAY).getStateFromMeta(4));
      world.setBlockState(pos.add(36, 22, 55), ((BlockColored)Blocks.STAINED_HARDENED_CLAY).getStateFromMeta(4));
      world.setBlockState(pos.add(37, 22, 55), ((BlockColored)Blocks.STAINED_HARDENED_CLAY).getStateFromMeta(4));
      world.setBlockState(pos.add(39, 22, 55), Blocks.NETHER_BRICK_FENCE.getDefaultState());
      world.setBlockState(pos.add(40, 22, 55), Blocks.NETHER_BRICK_FENCE.getDefaultState());
      world.setBlockState(pos.add(41, 22, 55), Blocks.NETHER_BRICK_FENCE.getDefaultState());
      world.setBlockState(pos.add(17, 22, 56), ((BlockColored)Blocks.STAINED_HARDENED_CLAY).getStateFromMeta(4));
      world.setBlockState(pos.add(18, 22, 56), ((BlockColored)Blocks.STAINED_HARDENED_CLAY).getStateFromMeta(4));
      world.setBlockState(pos.add(22, 22, 56), ((BlockColored)Blocks.STAINED_HARDENED_CLAY).getStateFromMeta(4));
      world.setBlockState(pos.add(23, 22, 56), ((BlockColored)Blocks.STAINED_HARDENED_CLAY).getStateFromMeta(4));
      world.setBlockState(pos.add(29, 22, 56), ((BlockColored)Blocks.STAINED_HARDENED_CLAY).getStateFromMeta(4));
      world.setBlockState(pos.add(30, 22, 56), ((BlockColored)Blocks.STAINED_HARDENED_CLAY).getStateFromMeta(4));
      world.setBlockState(pos.add(34, 22, 56), ((BlockColored)Blocks.STAINED_HARDENED_CLAY).getStateFromMeta(4));
      world.setBlockState(pos.add(35, 22, 56), ((BlockColored)Blocks.STAINED_HARDENED_CLAY).getStateFromMeta(4));
      world.setBlockState(pos.add(38, 22, 56), ((BlockColored)Blocks.STAINED_HARDENED_CLAY).getStateFromMeta(4));
      world.setBlockState(pos.add(39, 22, 56), Blocks.REDSTONE_BLOCK.getDefaultState());
      world.setBlockState(pos.add(40, 22, 56), Blocks.REDSTONE_BLOCK.getDefaultState());
      world.setBlockState(pos.add(41, 22, 56), Blocks.NETHER_BRICK_FENCE.getDefaultState());
      world.setBlockState(pos.add(42, 22, 56), Blocks.NETHER_BRICK_FENCE.getDefaultState());
      world.setBlockState(pos.add(18, 22, 57), ((BlockColored)Blocks.STAINED_HARDENED_CLAY).getStateFromMeta(4));
      world.setBlockState(pos.add(19, 22, 57), ((BlockColored)Blocks.STAINED_HARDENED_CLAY).getStateFromMeta(4));
      world.setBlockState(pos.add(20, 22, 57), ((BlockColored)Blocks.STAINED_HARDENED_CLAY).getStateFromMeta(4));
      world.setBlockState(pos.add(21, 22, 57), ((BlockColored)Blocks.STAINED_HARDENED_CLAY).getStateFromMeta(4));
      world.setBlockState(pos.add(22, 22, 57), ((BlockColored)Blocks.STAINED_HARDENED_CLAY).getStateFromMeta(4));
      world.setBlockState(pos.add(30, 22, 57), ((BlockColored)Blocks.STAINED_HARDENED_CLAY).getStateFromMeta(4));
      world.setBlockState(pos.add(31, 22, 57), ((BlockColored)Blocks.STAINED_HARDENED_CLAY).getStateFromMeta(4));
      world.setBlockState(pos.add(32, 22, 57), ((BlockColored)Blocks.STAINED_HARDENED_CLAY).getStateFromMeta(4));
      world.setBlockState(pos.add(33, 22, 57), ((BlockColored)Blocks.STAINED_HARDENED_CLAY).getStateFromMeta(4));
      world.setBlockState(pos.add(34, 22, 57), ((BlockColored)Blocks.STAINED_HARDENED_CLAY).getStateFromMeta(4));
      world.setBlockState(pos.add(39, 22, 57), ((BlockColored)Blocks.STAINED_HARDENED_CLAY).getStateFromMeta(4));
      world.setBlockState(pos.add(41, 22, 57), Blocks.REDSTONE_BLOCK.getDefaultState());
      world.setBlockState(pos.add(42, 22, 57), Blocks.NETHER_BRICK_FENCE.getDefaultState());
      world.setBlockState(pos.add(43, 22, 57), Blocks.NETHER_BRICK_FENCE.getDefaultState());
      world.setBlockState(pos.add(19, 22, 58), ((BlockColored)Blocks.STAINED_HARDENED_CLAY).getStateFromMeta(4));
      world.setBlockState(pos.add(20, 22, 58), ((BlockColored)Blocks.STAINED_HARDENED_CLAY).getStateFromMeta(4));
      world.setBlockState(pos.add(21, 22, 58), ((BlockColored)Blocks.STAINED_HARDENED_CLAY).getStateFromMeta(4));
      world.setBlockState(pos.add(31, 22, 58), ((BlockColored)Blocks.STAINED_HARDENED_CLAY).getStateFromMeta(4));
      world.setBlockState(pos.add(32, 22, 58), ((BlockColored)Blocks.STAINED_HARDENED_CLAY).getStateFromMeta(4));
      world.setBlockState(pos.add(33, 22, 58), ((BlockColored)Blocks.STAINED_HARDENED_CLAY).getStateFromMeta(4));
      world.setBlockState(pos.add(40, 22, 58), ((BlockColored)Blocks.STAINED_HARDENED_CLAY).getStateFromMeta(4));
      world.setBlockState(pos.add(42, 22, 58), Blocks.REDSTONE_BLOCK.getDefaultState());
      world.setBlockState(pos.add(43, 22, 58), Blocks.NETHER_BRICK_FENCE.getDefaultState());
      world.setBlockState(pos.add(34, 22, 59), Blocks.REDSTONE_BLOCK.getDefaultState());
      world.setBlockState(pos.add(35, 22, 59), Blocks.REDSTONE_BLOCK.getDefaultState());
      world.setBlockState(pos.add(36, 22, 59), Blocks.REDSTONE_BLOCK.getDefaultState());
      world.setBlockState(pos.add(37, 22, 59), Blocks.REDSTONE_BLOCK.getDefaultState());
      world.setBlockState(pos.add(41, 22, 59), ((BlockColored)Blocks.STAINED_HARDENED_CLAY).getStateFromMeta(4));
      world.setBlockState(pos.add(42, 22, 59), Blocks.REDSTONE_BLOCK.getDefaultState());
      world.setBlockState(pos.add(43, 22, 59), Blocks.NETHER_BRICK_FENCE.getDefaultState());
      world.setBlockState(pos.add(33, 22, 60), Blocks.REDSTONE_BLOCK.getDefaultState());
      world.setBlockState(pos.add(38, 22, 60), Blocks.REDSTONE_BLOCK.getDefaultState());
      world.setBlockState(pos.add(42, 22, 60), Blocks.STONE.getDefaultState());
      world.setBlockState(pos.add(43, 22, 60), Blocks.STONE.getDefaultState());
      world.setBlockState(pos.add(44, 22, 60), Blocks.STONE.getDefaultState());
      world.setBlockState(pos.add(45, 22, 60), Blocks.STONE.getDefaultState());
      world.setBlockState(pos.add(32, 22, 61), Blocks.REDSTONE_BLOCK.getDefaultState());
      world.setBlockState(pos.add(39, 22, 61), Blocks.REDSTONE_BLOCK.getDefaultState());
      world.setBlockState(pos.add(41, 22, 61), Blocks.STONE.getDefaultState());
      world.setBlockState(pos.add(46, 22, 61), Blocks.STONE.getDefaultState());
      world.setBlockState(pos.add(32, 22, 62), Blocks.REDSTONE_BLOCK.getDefaultState());
      world.setBlockState(pos.add(39, 22, 62), Blocks.REDSTONE_BLOCK.getDefaultState());
      world.setBlockState(pos.add(40, 22, 62), Blocks.STONE.getDefaultState());
      world.setBlockState(pos.add(47, 22, 62), Blocks.STONE.getDefaultState());
      world.setBlockState(pos.add(32, 22, 63), Blocks.REDSTONE_BLOCK.getDefaultState());
      world.setBlockState(pos.add(39, 22, 63), Blocks.REDSTONE_BLOCK.getDefaultState());
      world.setBlockState(pos.add(40, 22, 63), Blocks.STONE.getDefaultState());
      world.setBlockState(pos.add(47, 22, 63), Blocks.STONE.getDefaultState());
      world.setBlockState(pos.add(32, 22, 64), Blocks.REDSTONE_BLOCK.getDefaultState());
      world.setBlockState(pos.add(39, 22, 64), Blocks.REDSTONE_BLOCK.getDefaultState());
      world.setBlockState(pos.add(40, 22, 64), Blocks.STONE.getDefaultState());
      world.setBlockState(pos.add(47, 22, 64), Blocks.STONE.getDefaultState());
      world.setBlockState(pos.add(33, 22, 65), Blocks.REDSTONE_BLOCK.getDefaultState());
      world.setBlockState(pos.add(38, 22, 65), Blocks.REDSTONE_BLOCK.getDefaultState());
      world.setBlockState(pos.add(40, 22, 65), Blocks.STONE.getDefaultState());
      world.setBlockState(pos.add(47, 22, 65), Blocks.STONE.getDefaultState());
      world.setBlockState(pos.add(34, 22, 66), Blocks.REDSTONE_BLOCK.getDefaultState());
      world.setBlockState(pos.add(35, 22, 66), Blocks.REDSTONE_BLOCK.getDefaultState());
      world.setBlockState(pos.add(36, 22, 66), Blocks.REDSTONE_BLOCK.getDefaultState());
      world.setBlockState(pos.add(37, 22, 66), Blocks.REDSTONE_BLOCK.getDefaultState());
      world.setBlockState(pos.add(41, 22, 66), Blocks.STONE.getDefaultState());
      world.setBlockState(pos.add(46, 22, 66), Blocks.STONE.getDefaultState());
      world.setBlockState(pos.add(42, 22, 67), Blocks.STONE.getDefaultState());
      world.setBlockState(pos.add(43, 22, 67), Blocks.STONE.getDefaultState());
      world.setBlockState(pos.add(44, 22, 67), Blocks.STONE.getDefaultState());
      world.setBlockState(pos.add(45, 22, 67), Blocks.STONE.getDefaultState());
      world.setBlockState(pos.add(18, 23, 37), ((BlockColored)Blocks.STAINED_HARDENED_CLAY).getStateFromMeta(4));
      world.setBlockState(pos.add(19, 23, 37), ((BlockColored)Blocks.STAINED_HARDENED_CLAY).getStateFromMeta(4));
      world.setBlockState(pos.add(20, 23, 37), ((BlockColored)Blocks.STAINED_HARDENED_CLAY).getStateFromMeta(4));
      world.setBlockState(pos.add(23, 23, 37), ((BlockColored)Blocks.STAINED_HARDENED_CLAY).getStateFromMeta(4));
      world.setBlockState(pos.add(24, 23, 37), ((BlockColored)Blocks.STAINED_HARDENED_CLAY).getStateFromMeta(4));
      world.setBlockState(pos.add(25, 23, 37), Blocks.DIAMOND_BLOCK.getDefaultState());
      world.setBlockState(pos.add(26, 23, 37), Blocks.DIAMOND_BLOCK.getDefaultState());
      world.setBlockState(pos.add(27, 23, 37), Blocks.DIAMOND_BLOCK.getDefaultState());
      world.setBlockState(pos.add(28, 23, 37), ((BlockColored)Blocks.STAINED_HARDENED_CLAY).getStateFromMeta(4));
      world.setBlockState(pos.add(29, 23, 37), ((BlockColored)Blocks.STAINED_HARDENED_CLAY).getStateFromMeta(4));
      world.setBlockState(pos.add(32, 23, 37), ((BlockColored)Blocks.STAINED_HARDENED_CLAY).getStateFromMeta(4));
      world.setBlockState(pos.add(33, 23, 37), ((BlockColored)Blocks.STAINED_HARDENED_CLAY).getStateFromMeta(4));
      world.setBlockState(pos.add(34, 23, 37), ((BlockColored)Blocks.STAINED_HARDENED_CLAY).getStateFromMeta(4));
      world.setBlockState(pos.add(18, 23, 38), ((BlockColored)Blocks.STAINED_HARDENED_CLAY).getStateFromMeta(4));
      world.setBlockState(pos.add(19, 23, 38), ((BlockColored)Blocks.STAINED_HARDENED_CLAY).getStateFromMeta(4));
      world.setBlockState(pos.add(20, 23, 38), ((BlockColored)Blocks.STAINED_HARDENED_CLAY).getStateFromMeta(4));
      world.setBlockState(pos.add(23, 23, 38), Blocks.DIAMOND_BLOCK.getDefaultState());
      world.setBlockState(pos.add(29, 23, 38), Blocks.DIAMOND_BLOCK.getDefaultState());
      world.setBlockState(pos.add(32, 23, 38), ((BlockColored)Blocks.STAINED_HARDENED_CLAY).getStateFromMeta(4));
      world.setBlockState(pos.add(33, 23, 38), ((BlockColored)Blocks.STAINED_HARDENED_CLAY).getStateFromMeta(4));
      world.setBlockState(pos.add(34, 23, 38), ((BlockColored)Blocks.STAINED_HARDENED_CLAY).getStateFromMeta(4));
      world.setBlockState(pos.add(18, 23, 39), ((BlockColored)Blocks.STAINED_HARDENED_CLAY).getStateFromMeta(4));
      world.setBlockState(pos.add(20, 23, 39), ((BlockColored)Blocks.STAINED_HARDENED_CLAY).getStateFromMeta(4));
      world.setBlockState(pos.add(23, 23, 39), Blocks.DIAMOND_BLOCK.getDefaultState());
      world.setBlockState(pos.add(29, 23, 39), Blocks.DIAMOND_BLOCK.getDefaultState());
      world.setBlockState(pos.add(32, 23, 39), ((BlockColored)Blocks.STAINED_HARDENED_CLAY).getStateFromMeta(4));
      world.setBlockState(pos.add(34, 23, 39), ((BlockColored)Blocks.STAINED_HARDENED_CLAY).getStateFromMeta(4));
      world.setBlockState(pos.add(18, 23, 40), ((BlockColored)Blocks.STAINED_HARDENED_CLAY).getStateFromMeta(4));
      world.setBlockState(pos.add(20, 23, 40), ((BlockColored)Blocks.STAINED_HARDENED_CLAY).getStateFromMeta(4));
      world.setBlockState(pos.add(23, 23, 40), Blocks.DIAMOND_BLOCK.getDefaultState());
      world.setBlockState(pos.add(29, 23, 40), Blocks.DIAMOND_BLOCK.getDefaultState());
      world.setBlockState(pos.add(32, 23, 40), ((BlockColored)Blocks.STAINED_HARDENED_CLAY).getStateFromMeta(4));
      world.setBlockState(pos.add(33, 23, 40), ((BlockColored)Blocks.STAINED_HARDENED_CLAY).getStateFromMeta(4));
      world.setBlockState(pos.add(34, 23, 40), ((BlockColored)Blocks.STAINED_HARDENED_CLAY).getStateFromMeta(4));
      world.setBlockState(pos.add(19, 23, 41), Blocks.QUARTZ_BLOCK.getDefaultState());
      world.setBlockState(pos.add(20, 23, 41), Blocks.QUARTZ_BLOCK.getDefaultState());
      world.setBlockState(pos.add(23, 23, 41), ((BlockColored)Blocks.STAINED_HARDENED_CLAY).getStateFromMeta(4));
      world.setBlockState(pos.add(26, 23, 41), Blocks.STONE.getDefaultState());
      world.setBlockState(pos.add(27, 23, 41), Blocks.STONE.getDefaultState());
      world.setBlockState(pos.add(29, 23, 41), ((BlockColored)Blocks.STAINED_HARDENED_CLAY).getStateFromMeta(4));
      world.setBlockState(pos.add(32, 23, 41), Blocks.QUARTZ_BLOCK.getDefaultState());
      world.setBlockState(pos.add(33, 23, 41), Blocks.QUARTZ_BLOCK.getDefaultState());
      world.setBlockState(pos.add(19, 23, 42), Blocks.QUARTZ_BLOCK.getDefaultState());
      world.setBlockState(pos.add(20, 23, 42), Blocks.QUARTZ_BLOCK.getDefaultState());
      world.setBlockState(pos.add(23, 23, 42), ((BlockColored)Blocks.STAINED_HARDENED_CLAY).getStateFromMeta(4));
      world.setBlockState(pos.add(26, 23, 42), Blocks.STONE.getDefaultState());
      world.setBlockState(pos.add(27, 23, 42), Blocks.STONE.getDefaultState());
      world.setBlockState(pos.add(29, 23, 42), ((BlockColored)Blocks.STAINED_HARDENED_CLAY).getStateFromMeta(4));
      world.setBlockState(pos.add(32, 23, 42), Blocks.QUARTZ_BLOCK.getDefaultState());
      world.setBlockState(pos.add(33, 23, 42), Blocks.QUARTZ_BLOCK.getDefaultState());
      world.setBlockState(pos.add(18, 23, 43), ((BlockColored)Blocks.STAINED_HARDENED_CLAY).getStateFromMeta(4));
      world.setBlockState(pos.add(20, 23, 43), ((BlockColored)Blocks.STAINED_HARDENED_CLAY).getStateFromMeta(4));
      world.setBlockState(pos.add(23, 23, 43), Blocks.DIAMOND_BLOCK.getDefaultState());
      world.setBlockState(pos.add(29, 23, 43), Blocks.DIAMOND_BLOCK.getDefaultState());
      world.setBlockState(pos.add(32, 23, 43), ((BlockColored)Blocks.STAINED_HARDENED_CLAY).getStateFromMeta(4));
      world.setBlockState(pos.add(34, 23, 43), ((BlockColored)Blocks.STAINED_HARDENED_CLAY).getStateFromMeta(4));
      world.setBlockState(pos.add(18, 23, 44), ((BlockColored)Blocks.STAINED_HARDENED_CLAY).getStateFromMeta(4));
      world.setBlockState(pos.add(20, 23, 44), ((BlockColored)Blocks.STAINED_HARDENED_CLAY).getStateFromMeta(4));
      world.setBlockState(pos.add(23, 23, 44), Blocks.DIAMOND_BLOCK.getDefaultState());
      world.setBlockState(pos.add(29, 23, 44), Blocks.DIAMOND_BLOCK.getDefaultState());
      world.setBlockState(pos.add(32, 23, 44), ((BlockColored)Blocks.STAINED_HARDENED_CLAY).getStateFromMeta(4));
      world.setBlockState(pos.add(34, 23, 44), ((BlockColored)Blocks.STAINED_HARDENED_CLAY).getStateFromMeta(4));
      world.setBlockState(pos.add(18, 23, 45), ((BlockColored)Blocks.STAINED_HARDENED_CLAY).getStateFromMeta(4));
      world.setBlockState(pos.add(20, 23, 45), ((BlockColored)Blocks.STAINED_HARDENED_CLAY).getStateFromMeta(4));
      world.setBlockState(pos.add(23, 23, 45), Blocks.DIAMOND_BLOCK.getDefaultState());
      world.setBlockState(pos.add(29, 23, 45), Blocks.DIAMOND_BLOCK.getDefaultState());
      world.setBlockState(pos.add(32, 23, 45), ((BlockColored)Blocks.STAINED_HARDENED_CLAY).getStateFromMeta(4));
      world.setBlockState(pos.add(34, 23, 45), ((BlockColored)Blocks.STAINED_HARDENED_CLAY).getStateFromMeta(4));
      world.setBlockState(pos.add(19, 23, 46), Blocks.QUARTZ_BLOCK.getDefaultState());
      world.setBlockState(pos.add(20, 23, 46), Blocks.QUARTZ_BLOCK.getDefaultState());
      world.setBlockState(pos.add(23, 23, 46), ((BlockColored)Blocks.STAINED_HARDENED_CLAY).getStateFromMeta(4));
      world.setBlockState(pos.add(25, 23, 46), Blocks.STONE.getDefaultState());
      world.setBlockState(pos.add(26, 23, 46), Blocks.STONE.getDefaultState());
      world.setBlockState(pos.add(29, 23, 46), ((BlockColored)Blocks.STAINED_HARDENED_CLAY).getStateFromMeta(4));
      world.setBlockState(pos.add(32, 23, 46), Blocks.QUARTZ_BLOCK.getDefaultState());
      world.setBlockState(pos.add(33, 23, 46), Blocks.QUARTZ_BLOCK.getDefaultState());
      world.setBlockState(pos.add(19, 23, 47), Blocks.QUARTZ_BLOCK.getDefaultState());
      world.setBlockState(pos.add(20, 23, 47), Blocks.QUARTZ_BLOCK.getDefaultState());
      world.setBlockState(pos.add(23, 23, 47), ((BlockColored)Blocks.STAINED_HARDENED_CLAY).getStateFromMeta(4));
      world.setBlockState(pos.add(25, 23, 47), Blocks.STONE.getDefaultState());
      world.setBlockState(pos.add(26, 23, 47), Blocks.STONE.getDefaultState());
      world.setBlockState(pos.add(29, 23, 47), ((BlockColored)Blocks.STAINED_HARDENED_CLAY).getStateFromMeta(4));
      world.setBlockState(pos.add(32, 23, 47), Blocks.QUARTZ_BLOCK.getDefaultState());
      world.setBlockState(pos.add(33, 23, 47), Blocks.QUARTZ_BLOCK.getDefaultState());
      world.setBlockState(pos.add(18, 23, 48), ((BlockColored)Blocks.STAINED_HARDENED_CLAY).getStateFromMeta(4));
      world.setBlockState(pos.add(20, 23, 48), ((BlockColored)Blocks.STAINED_HARDENED_CLAY).getStateFromMeta(4));
      world.setBlockState(pos.add(23, 23, 48), Blocks.DIAMOND_BLOCK.getDefaultState());
      world.setBlockState(pos.add(29, 23, 48), Blocks.DIAMOND_BLOCK.getDefaultState());
      world.setBlockState(pos.add(32, 23, 48), ((BlockColored)Blocks.STAINED_HARDENED_CLAY).getStateFromMeta(4));
      world.setBlockState(pos.add(34, 23, 48), ((BlockColored)Blocks.STAINED_HARDENED_CLAY).getStateFromMeta(4));
      world.setBlockState(pos.add(18, 23, 49), ((BlockColored)Blocks.STAINED_HARDENED_CLAY).getStateFromMeta(4));
      world.setBlockState(pos.add(20, 23, 49), ((BlockColored)Blocks.STAINED_HARDENED_CLAY).getStateFromMeta(4));
      world.setBlockState(pos.add(23, 23, 49), Blocks.DIAMOND_BLOCK.getDefaultState());
      world.setBlockState(pos.add(29, 23, 49), Blocks.DIAMOND_BLOCK.getDefaultState());
      world.setBlockState(pos.add(32, 23, 49), ((BlockColored)Blocks.STAINED_HARDENED_CLAY).getStateFromMeta(4));
      world.setBlockState(pos.add(34, 23, 49), ((BlockColored)Blocks.STAINED_HARDENED_CLAY).getStateFromMeta(4));
      world.setBlockState(pos.add(18, 23, 50), ((BlockColored)Blocks.STAINED_HARDENED_CLAY).getStateFromMeta(4));
      world.setBlockState(pos.add(19, 23, 50), ((BlockColored)Blocks.STAINED_HARDENED_CLAY).getStateFromMeta(4));
      world.setBlockState(pos.add(20, 23, 50), ((BlockColored)Blocks.STAINED_HARDENED_CLAY).getStateFromMeta(4));
      world.setBlockState(pos.add(21, 23, 50), ((BlockColored)Blocks.STAINED_HARDENED_CLAY).getStateFromMeta(4));
      world.setBlockState(pos.add(23, 23, 50), Blocks.DIAMOND_BLOCK.getDefaultState());
      world.setBlockState(pos.add(29, 23, 50), Blocks.DIAMOND_BLOCK.getDefaultState());
      world.setBlockState(pos.add(31, 23, 50), ((BlockColored)Blocks.STAINED_HARDENED_CLAY).getStateFromMeta(4));
      world.setBlockState(pos.add(32, 23, 50), ((BlockColored)Blocks.STAINED_HARDENED_CLAY).getStateFromMeta(4));
      world.setBlockState(pos.add(33, 23, 50), ((BlockColored)Blocks.STAINED_HARDENED_CLAY).getStateFromMeta(4));
      world.setBlockState(pos.add(34, 23, 50), ((BlockColored)Blocks.STAINED_HARDENED_CLAY).getStateFromMeta(4));
      world.setBlockState(pos.add(18, 23, 51), ((BlockColored)Blocks.STAINED_HARDENED_CLAY).getStateFromMeta(4));
      world.setBlockState(pos.add(19, 23, 51), ((BlockColored)Blocks.STAINED_HARDENED_CLAY).getStateFromMeta(4));
      world.setBlockState(pos.add(20, 23, 51), ((BlockColored)Blocks.STAINED_HARDENED_CLAY).getStateFromMeta(4));
      world.setBlockState(pos.add(21, 23, 51), ((BlockColored)Blocks.STAINED_HARDENED_CLAY).getStateFromMeta(4));
      world.setBlockState(pos.add(22, 23, 51), ((BlockColored)Blocks.STAINED_HARDENED_CLAY).getStateFromMeta(4));
      world.setBlockState(pos.add(23, 23, 51), ((BlockColored)Blocks.STAINED_HARDENED_CLAY).getStateFromMeta(4));
      world.setBlockState(pos.add(24, 23, 51), ((BlockColored)Blocks.STAINED_HARDENED_CLAY).getStateFromMeta(4));
      world.setBlockState(pos.add(25, 23, 51), ((BlockColored)Blocks.STAINED_HARDENED_CLAY).getStateFromMeta(4));
      world.setBlockState(pos.add(26, 23, 51), ((BlockColored)Blocks.STAINED_HARDENED_CLAY).getStateFromMeta(4));
      world.setBlockState(pos.add(27, 23, 51), ((BlockColored)Blocks.STAINED_HARDENED_CLAY).getStateFromMeta(4));
      world.setBlockState(pos.add(28, 23, 51), ((BlockColored)Blocks.STAINED_HARDENED_CLAY).getStateFromMeta(4));
      world.setBlockState(pos.add(29, 23, 51), ((BlockColored)Blocks.STAINED_HARDENED_CLAY).getStateFromMeta(4));
      world.setBlockState(pos.add(30, 23, 51), ((BlockColored)Blocks.STAINED_HARDENED_CLAY).getStateFromMeta(4));
      world.setBlockState(pos.add(31, 23, 51), ((BlockColored)Blocks.STAINED_HARDENED_CLAY).getStateFromMeta(4));
      world.setBlockState(pos.add(32, 23, 51), ((BlockColored)Blocks.STAINED_HARDENED_CLAY).getStateFromMeta(4));
      world.setBlockState(pos.add(33, 23, 51), ((BlockColored)Blocks.STAINED_HARDENED_CLAY).getStateFromMeta(4));
      world.setBlockState(pos.add(34, 23, 51), ((BlockColored)Blocks.STAINED_HARDENED_CLAY).getStateFromMeta(4));
      world.setBlockState(pos.add(17, 23, 52), ((BlockColored)Blocks.STAINED_HARDENED_CLAY).getStateFromMeta(4));
      world.setBlockState(pos.add(18, 23, 52), ((BlockColored)Blocks.STAINED_HARDENED_CLAY).getStateFromMeta(4));
      world.setBlockState(pos.add(22, 23, 52), ((BlockColored)Blocks.STAINED_HARDENED_CLAY).getStateFromMeta(4));
      world.setBlockState(pos.add(23, 23, 52), ((BlockColored)Blocks.STAINED_HARDENED_CLAY).getStateFromMeta(4));
      world.setBlockState(pos.add(29, 23, 52), ((BlockColored)Blocks.STAINED_HARDENED_CLAY).getStateFromMeta(4));
      world.setBlockState(pos.add(30, 23, 52), ((BlockColored)Blocks.STAINED_HARDENED_CLAY).getStateFromMeta(4));
      world.setBlockState(pos.add(34, 23, 52), ((BlockColored)Blocks.STAINED_HARDENED_CLAY).getStateFromMeta(4));
      world.setBlockState(pos.add(35, 23, 52), ((BlockColored)Blocks.STAINED_HARDENED_CLAY).getStateFromMeta(4));
      world.setBlockState(pos.add(16, 23, 53), ((BlockColored)Blocks.STAINED_HARDENED_CLAY).getStateFromMeta(4));
      world.setBlockState(pos.add(17, 23, 53), ((BlockColored)Blocks.STAINED_HARDENED_CLAY).getStateFromMeta(4));
      world.setBlockState(pos.add(23, 23, 53), ((BlockColored)Blocks.STAINED_HARDENED_CLAY).getStateFromMeta(4));
      world.setBlockState(pos.add(24, 23, 53), ((BlockColored)Blocks.STAINED_HARDENED_CLAY).getStateFromMeta(4));
      world.setBlockState(pos.add(28, 23, 53), ((BlockColored)Blocks.STAINED_HARDENED_CLAY).getStateFromMeta(4));
      world.setBlockState(pos.add(29, 23, 53), ((BlockColored)Blocks.STAINED_HARDENED_CLAY).getStateFromMeta(4));
      world.setBlockState(pos.add(35, 23, 53), ((BlockColored)Blocks.STAINED_HARDENED_CLAY).getStateFromMeta(4));
      world.setBlockState(pos.add(36, 23, 53), ((BlockColored)Blocks.STAINED_HARDENED_CLAY).getStateFromMeta(4));
      world.setBlockState(pos.add(16, 23, 54), ((BlockColored)Blocks.STAINED_HARDENED_CLAY).getStateFromMeta(4));
      world.setBlockState(pos.add(17, 23, 54), ((BlockColored)Blocks.STAINED_HARDENED_CLAY).getStateFromMeta(4));
      world.setBlockState(pos.add(23, 23, 54), ((BlockColored)Blocks.STAINED_HARDENED_CLAY).getStateFromMeta(4));
      world.setBlockState(pos.add(24, 23, 54), ((BlockColored)Blocks.STAINED_HARDENED_CLAY).getStateFromMeta(4));
      world.setBlockState(pos.add(28, 23, 54), ((BlockColored)Blocks.STAINED_HARDENED_CLAY).getStateFromMeta(4));
      world.setBlockState(pos.add(29, 23, 54), ((BlockColored)Blocks.STAINED_HARDENED_CLAY).getStateFromMeta(4));
      world.setBlockState(pos.add(35, 23, 54), ((BlockColored)Blocks.STAINED_HARDENED_CLAY).getStateFromMeta(4));
      world.setBlockState(pos.add(36, 23, 54), ((BlockColored)Blocks.WOOL).getStateFromMeta(15));
      world.setBlockState(pos.add(16, 23, 55), ((BlockColored)Blocks.STAINED_HARDENED_CLAY).getStateFromMeta(4));
      world.setBlockState(pos.add(17, 23, 55), ((BlockColored)Blocks.STAINED_HARDENED_CLAY).getStateFromMeta(4));
      world.setBlockState(pos.add(23, 23, 55), ((BlockColored)Blocks.STAINED_HARDENED_CLAY).getStateFromMeta(4));
      world.setBlockState(pos.add(24, 23, 55), ((BlockColored)Blocks.STAINED_HARDENED_CLAY).getStateFromMeta(4));
      world.setBlockState(pos.add(28, 23, 55), ((BlockColored)Blocks.STAINED_HARDENED_CLAY).getStateFromMeta(4));
      world.setBlockState(pos.add(29, 23, 55), ((BlockColored)Blocks.STAINED_HARDENED_CLAY).getStateFromMeta(4));
      world.setBlockState(pos.add(35, 23, 55), ((BlockColored)Blocks.STAINED_HARDENED_CLAY).getStateFromMeta(4));
      world.setBlockState(pos.add(36, 23, 55), ((BlockColored)Blocks.STAINED_HARDENED_CLAY).getStateFromMeta(4));
      world.setBlockState(pos.add(37, 23, 55), ((BlockColored)Blocks.STAINED_HARDENED_CLAY).getStateFromMeta(4));
      world.setBlockState(pos.add(39, 23, 55), Blocks.NETHER_BRICK_FENCE.getDefaultState());
      world.setBlockState(pos.add(40, 23, 55), Blocks.NETHER_BRICK_FENCE.getDefaultState());
      world.setBlockState(pos.add(41, 23, 55), Blocks.NETHER_BRICK_FENCE.getDefaultState());
      world.setBlockState(pos.add(17, 23, 56), ((BlockColored)Blocks.STAINED_HARDENED_CLAY).getStateFromMeta(4));
      world.setBlockState(pos.add(18, 23, 56), ((BlockColored)Blocks.STAINED_HARDENED_CLAY).getStateFromMeta(4));
      world.setBlockState(pos.add(22, 23, 56), ((BlockColored)Blocks.STAINED_HARDENED_CLAY).getStateFromMeta(4));
      world.setBlockState(pos.add(23, 23, 56), ((BlockColored)Blocks.STAINED_HARDENED_CLAY).getStateFromMeta(4));
      world.setBlockState(pos.add(29, 23, 56), ((BlockColored)Blocks.STAINED_HARDENED_CLAY).getStateFromMeta(4));
      world.setBlockState(pos.add(30, 23, 56), ((BlockColored)Blocks.STAINED_HARDENED_CLAY).getStateFromMeta(4));
      world.setBlockState(pos.add(34, 23, 56), ((BlockColored)Blocks.STAINED_HARDENED_CLAY).getStateFromMeta(4));
      world.setBlockState(pos.add(35, 23, 56), ((BlockColored)Blocks.STAINED_HARDENED_CLAY).getStateFromMeta(4));
      world.setBlockState(pos.add(38, 23, 56), ((BlockColored)Blocks.STAINED_HARDENED_CLAY).getStateFromMeta(4));
      world.setBlockState(pos.add(39, 23, 56), Blocks.REDSTONE_BLOCK.getDefaultState());
      world.setBlockState(pos.add(40, 23, 56), Blocks.REDSTONE_BLOCK.getDefaultState());
      world.setBlockState(pos.add(41, 23, 56), Blocks.NETHER_BRICK_FENCE.getDefaultState());
      world.setBlockState(pos.add(42, 23, 56), Blocks.NETHER_BRICK_FENCE.getDefaultState());
      world.setBlockState(pos.add(18, 23, 57), ((BlockColored)Blocks.STAINED_HARDENED_CLAY).getStateFromMeta(4));
      world.setBlockState(pos.add(19, 23, 57), ((BlockColored)Blocks.STAINED_HARDENED_CLAY).getStateFromMeta(4));
      world.setBlockState(pos.add(20, 23, 57), ((BlockColored)Blocks.STAINED_HARDENED_CLAY).getStateFromMeta(4));
      world.setBlockState(pos.add(21, 23, 57), ((BlockColored)Blocks.STAINED_HARDENED_CLAY).getStateFromMeta(4));
      world.setBlockState(pos.add(22, 23, 57), ((BlockColored)Blocks.STAINED_HARDENED_CLAY).getStateFromMeta(4));
      world.setBlockState(pos.add(30, 23, 57), ((BlockColored)Blocks.STAINED_HARDENED_CLAY).getStateFromMeta(4));
      world.setBlockState(pos.add(31, 23, 57), ((BlockColored)Blocks.STAINED_HARDENED_CLAY).getStateFromMeta(4));
      world.setBlockState(pos.add(32, 23, 57), ((BlockColored)Blocks.STAINED_HARDENED_CLAY).getStateFromMeta(4));
      world.setBlockState(pos.add(33, 23, 57), ((BlockColored)Blocks.STAINED_HARDENED_CLAY).getStateFromMeta(4));
      world.setBlockState(pos.add(34, 23, 57), ((BlockColored)Blocks.STAINED_HARDENED_CLAY).getStateFromMeta(4));
      world.setBlockState(pos.add(39, 23, 57), ((BlockColored)Blocks.STAINED_HARDENED_CLAY).getStateFromMeta(4));
      world.setBlockState(pos.add(41, 23, 57), Blocks.REDSTONE_BLOCK.getDefaultState());
      world.setBlockState(pos.add(42, 23, 57), Blocks.NETHER_BRICK_FENCE.getDefaultState());
      world.setBlockState(pos.add(43, 23, 57), Blocks.NETHER_BRICK_FENCE.getDefaultState());
      world.setBlockState(pos.add(19, 23, 58), ((BlockColored)Blocks.STAINED_HARDENED_CLAY).getStateFromMeta(4));
      world.setBlockState(pos.add(20, 23, 58), ((BlockColored)Blocks.STAINED_HARDENED_CLAY).getStateFromMeta(4));
      world.setBlockState(pos.add(21, 23, 58), ((BlockColored)Blocks.STAINED_HARDENED_CLAY).getStateFromMeta(4));
      world.setBlockState(pos.add(31, 23, 58), ((BlockColored)Blocks.STAINED_HARDENED_CLAY).getStateFromMeta(4));
      world.setBlockState(pos.add(32, 23, 58), ((BlockColored)Blocks.STAINED_HARDENED_CLAY).getStateFromMeta(4));
      world.setBlockState(pos.add(33, 23, 58), ((BlockColored)Blocks.STAINED_HARDENED_CLAY).getStateFromMeta(4));
      world.setBlockState(pos.add(40, 23, 58), ((BlockColored)Blocks.STAINED_HARDENED_CLAY).getStateFromMeta(4));
      world.setBlockState(pos.add(42, 23, 58), Blocks.REDSTONE_BLOCK.getDefaultState());
      world.setBlockState(pos.add(43, 23, 58), Blocks.NETHER_BRICK_FENCE.getDefaultState());
      world.setBlockState(pos.add(34, 23, 59), ((BlockColored)Blocks.WOOL).getStateFromMeta(15));
      world.setBlockState(pos.add(35, 23, 59), ((BlockColored)Blocks.WOOL).getStateFromMeta(15));
      world.setBlockState(pos.add(36, 23, 59), ((BlockColored)Blocks.WOOL).getStateFromMeta(15));
      world.setBlockState(pos.add(37, 23, 59), ((BlockColored)Blocks.WOOL).getStateFromMeta(15));
      world.setBlockState(pos.add(41, 23, 59), ((BlockColored)Blocks.STAINED_HARDENED_CLAY).getStateFromMeta(4));
      world.setBlockState(pos.add(42, 23, 59), Blocks.REDSTONE_BLOCK.getDefaultState());
      world.setBlockState(pos.add(43, 23, 59), Blocks.NETHER_BRICK_FENCE.getDefaultState());
      world.setBlockState(pos.add(33, 23, 60), ((BlockColored)Blocks.WOOL).getStateFromMeta(15));
      world.setBlockState(pos.add(38, 23, 60), ((BlockColored)Blocks.WOOL).getStateFromMeta(15));
      world.setBlockState(pos.add(42, 23, 60), Blocks.STONE.getDefaultState());
      world.setBlockState(pos.add(43, 23, 60), Blocks.STONE.getDefaultState());
      world.setBlockState(pos.add(44, 23, 60), Blocks.STONE.getDefaultState());
      world.setBlockState(pos.add(45, 23, 60), Blocks.STONE.getDefaultState());
      world.setBlockState(pos.add(32, 23, 61), ((BlockColored)Blocks.WOOL).getStateFromMeta(15));
      world.setBlockState(pos.add(39, 23, 61), ((BlockColored)Blocks.WOOL).getStateFromMeta(15));
      world.setBlockState(pos.add(41, 23, 61), Blocks.STONE.getDefaultState());
      world.setBlockState(pos.add(46, 23, 61), Blocks.STONE.getDefaultState());
      world.setBlockState(pos.add(32, 23, 62), ((BlockColored)Blocks.WOOL).getStateFromMeta(15));
      world.setBlockState(pos.add(39, 23, 62), ((BlockColored)Blocks.WOOL).getStateFromMeta(15));
      world.setBlockState(pos.add(40, 23, 62), Blocks.STONE.getDefaultState());
      world.setBlockState(pos.add(47, 23, 62), Blocks.STONE.getDefaultState());
      world.setBlockState(pos.add(32, 23, 63), ((BlockColored)Blocks.WOOL).getStateFromMeta(15));
      world.setBlockState(pos.add(39, 23, 63), ((BlockColored)Blocks.WOOL).getStateFromMeta(15));
      world.setBlockState(pos.add(40, 23, 63), Blocks.STONE.getDefaultState());
      world.setBlockState(pos.add(47, 23, 63), Blocks.STONE.getDefaultState());
      world.setBlockState(pos.add(32, 23, 64), ((BlockColored)Blocks.WOOL).getStateFromMeta(15));
      world.setBlockState(pos.add(39, 23, 64), ((BlockColored)Blocks.WOOL).getStateFromMeta(15));
      world.setBlockState(pos.add(40, 23, 64), Blocks.STONE.getDefaultState());
      world.setBlockState(pos.add(47, 23, 64), Blocks.STONE.getDefaultState());
      world.setBlockState(pos.add(33, 23, 65), ((BlockColored)Blocks.WOOL).getStateFromMeta(15));
      world.setBlockState(pos.add(38, 23, 65), ((BlockColored)Blocks.WOOL).getStateFromMeta(15));
      world.setBlockState(pos.add(40, 23, 65), Blocks.STONE.getDefaultState());
      world.setBlockState(pos.add(47, 23, 65), Blocks.STONE.getDefaultState());
      world.setBlockState(pos.add(34, 23, 66), ((BlockColored)Blocks.WOOL).getStateFromMeta(15));
      world.setBlockState(pos.add(35, 23, 66), ((BlockColored)Blocks.WOOL).getStateFromMeta(15));
      world.setBlockState(pos.add(36, 23, 66), ((BlockColored)Blocks.WOOL).getStateFromMeta(15));
      world.setBlockState(pos.add(37, 23, 66), ((BlockColored)Blocks.WOOL).getStateFromMeta(15));
      world.setBlockState(pos.add(41, 23, 66), Blocks.STONE.getDefaultState());
      world.setBlockState(pos.add(46, 23, 66), Blocks.STONE.getDefaultState());
      world.setBlockState(pos.add(42, 23, 67), Blocks.STONE.getDefaultState());
      world.setBlockState(pos.add(43, 23, 67), Blocks.STONE.getDefaultState());
      world.setBlockState(pos.add(44, 23, 67), Blocks.STONE.getDefaultState());
      world.setBlockState(pos.add(45, 23, 67), Blocks.STONE.getDefaultState());
      world.setBlockState(pos.add(18, 24, 37), ((BlockColored)Blocks.STAINED_HARDENED_CLAY).getStateFromMeta(4));
      world.setBlockState(pos.add(19, 24, 37), ((BlockColored)Blocks.STAINED_HARDENED_CLAY).getStateFromMeta(4));
      world.setBlockState(pos.add(23, 24, 37), ((BlockColored)Blocks.STAINED_HARDENED_CLAY).getStateFromMeta(4));
      world.setBlockState(pos.add(24, 24, 37), ((BlockColored)Blocks.STAINED_HARDENED_CLAY).getStateFromMeta(4));
      world.setBlockState(pos.add(25, 24, 37), ((BlockColored)Blocks.STAINED_HARDENED_CLAY).getStateFromMeta(4));
      world.setBlockState(pos.add(26, 24, 37), Blocks.DIAMOND_BLOCK.getDefaultState());
      world.setBlockState(pos.add(27, 24, 37), ((BlockColored)Blocks.STAINED_HARDENED_CLAY).getStateFromMeta(4));
      world.setBlockState(pos.add(28, 24, 37), ((BlockColored)Blocks.STAINED_HARDENED_CLAY).getStateFromMeta(4));
      world.setBlockState(pos.add(29, 24, 37), ((BlockColored)Blocks.STAINED_HARDENED_CLAY).getStateFromMeta(4));
      world.setBlockState(pos.add(33, 24, 37), ((BlockColored)Blocks.STAINED_HARDENED_CLAY).getStateFromMeta(4));
      world.setBlockState(pos.add(34, 24, 37), ((BlockColored)Blocks.STAINED_HARDENED_CLAY).getStateFromMeta(4));
      world.setBlockState(pos.add(18, 24, 38), ((BlockColored)Blocks.STAINED_HARDENED_CLAY).getStateFromMeta(4));
      world.setBlockState(pos.add(19, 24, 38), ((BlockColored)Blocks.STAINED_HARDENED_CLAY).getStateFromMeta(4));
      world.setBlockState(pos.add(20, 24, 38), ((BlockColored)Blocks.STAINED_HARDENED_CLAY).getStateFromMeta(7));
      world.setBlockState(pos.add(23, 24, 38), Blocks.DIAMOND_BLOCK.getDefaultState());
      world.setBlockState(pos.add(29, 24, 38), Blocks.DIAMOND_BLOCK.getDefaultState());
      world.setBlockState(pos.add(32, 24, 38), ((BlockColored)Blocks.STAINED_HARDENED_CLAY).getStateFromMeta(7));
      world.setBlockState(pos.add(33, 24, 38), ((BlockColored)Blocks.STAINED_HARDENED_CLAY).getStateFromMeta(4));
      world.setBlockState(pos.add(34, 24, 38), ((BlockColored)Blocks.STAINED_HARDENED_CLAY).getStateFromMeta(4));
      world.setBlockState(pos.add(18, 24, 39), ((BlockColored)Blocks.STAINED_HARDENED_CLAY).getStateFromMeta(4));
      world.setBlockState(pos.add(20, 24, 39), ((BlockColored)Blocks.STAINED_HARDENED_CLAY).getStateFromMeta(4));
      world.setBlockState(pos.add(23, 24, 39), Blocks.DIAMOND_BLOCK.getDefaultState());
      world.setBlockState(pos.add(29, 24, 39), Blocks.DIAMOND_BLOCK.getDefaultState());
      world.setBlockState(pos.add(32, 24, 39), ((BlockColored)Blocks.STAINED_HARDENED_CLAY).getStateFromMeta(4));
      world.setBlockState(pos.add(34, 24, 39), ((BlockColored)Blocks.STAINED_HARDENED_CLAY).getStateFromMeta(4));
      world.setBlockState(pos.add(18, 24, 40), ((BlockColored)Blocks.STAINED_HARDENED_CLAY).getStateFromMeta(4));
      world.setBlockState(pos.add(20, 24, 40), ((BlockColored)Blocks.STAINED_HARDENED_CLAY).getStateFromMeta(4));
      world.setBlockState(pos.add(23, 24, 40), Blocks.DIAMOND_BLOCK.getDefaultState());
      world.setBlockState(pos.add(29, 24, 40), Blocks.DIAMOND_BLOCK.getDefaultState());
      world.setBlockState(pos.add(32, 24, 40), ((BlockColored)Blocks.STAINED_HARDENED_CLAY).getStateFromMeta(4));
      world.setBlockState(pos.add(33, 24, 40), ((BlockColored)Blocks.STAINED_HARDENED_CLAY).getStateFromMeta(4));
      world.setBlockState(pos.add(34, 24, 40), ((BlockColored)Blocks.STAINED_HARDENED_CLAY).getStateFromMeta(4));
      world.setBlockState(pos.add(19, 24, 41), Blocks.QUARTZ_BLOCK.getDefaultState());
      world.setBlockState(pos.add(20, 24, 41), Blocks.QUARTZ_BLOCK.getDefaultState());
      world.setBlockState(pos.add(23, 24, 41), ((BlockColored)Blocks.STAINED_HARDENED_CLAY).getStateFromMeta(4));
      world.setBlockState(pos.add(26, 24, 41), Blocks.STONE.getDefaultState());
      world.setBlockState(pos.add(27, 24, 41), Blocks.STONE.getDefaultState());
      world.setBlockState(pos.add(29, 24, 41), ((BlockColored)Blocks.STAINED_HARDENED_CLAY).getStateFromMeta(4));
      world.setBlockState(pos.add(32, 24, 41), Blocks.QUARTZ_BLOCK.getDefaultState());
      world.setBlockState(pos.add(33, 24, 41), Blocks.QUARTZ_BLOCK.getDefaultState());
      world.setBlockState(pos.add(19, 24, 42), Blocks.QUARTZ_BLOCK.getDefaultState());
      world.setBlockState(pos.add(20, 24, 42), Blocks.QUARTZ_BLOCK.getDefaultState());
      world.setBlockState(pos.add(23, 24, 42), ((BlockColored)Blocks.STAINED_HARDENED_CLAY).getStateFromMeta(4));
      world.setBlockState(pos.add(26, 24, 42), Blocks.STONE.getDefaultState());
      world.setBlockState(pos.add(27, 24, 42), Blocks.STONE.getDefaultState());
      world.setBlockState(pos.add(29, 24, 42), ((BlockColored)Blocks.STAINED_HARDENED_CLAY).getStateFromMeta(4));
      world.setBlockState(pos.add(32, 24, 42), Blocks.QUARTZ_BLOCK.getDefaultState());
      world.setBlockState(pos.add(33, 24, 42), Blocks.QUARTZ_BLOCK.getDefaultState());
      world.setBlockState(pos.add(18, 24, 43), ((BlockColored)Blocks.STAINED_HARDENED_CLAY).getStateFromMeta(4));
      world.setBlockState(pos.add(20, 24, 43), ((BlockColored)Blocks.STAINED_HARDENED_CLAY).getStateFromMeta(4));
      world.setBlockState(pos.add(23, 24, 43), Blocks.DIAMOND_BLOCK.getDefaultState());
      world.setBlockState(pos.add(29, 24, 43), Blocks.DIAMOND_BLOCK.getDefaultState());
      world.setBlockState(pos.add(32, 24, 43), ((BlockColored)Blocks.STAINED_HARDENED_CLAY).getStateFromMeta(4));
      world.setBlockState(pos.add(34, 24, 43), ((BlockColored)Blocks.STAINED_HARDENED_CLAY).getStateFromMeta(4));
      world.setBlockState(pos.add(18, 24, 44), ((BlockColored)Blocks.STAINED_HARDENED_CLAY).getStateFromMeta(4));
      world.setBlockState(pos.add(20, 24, 44), ((BlockColored)Blocks.STAINED_HARDENED_CLAY).getStateFromMeta(4));
      world.setBlockState(pos.add(23, 24, 44), Blocks.DIAMOND_BLOCK.getDefaultState());
      world.setBlockState(pos.add(29, 24, 44), Blocks.DIAMOND_BLOCK.getDefaultState());
      world.setBlockState(pos.add(32, 24, 44), ((BlockColored)Blocks.STAINED_HARDENED_CLAY).getStateFromMeta(4));
      world.setBlockState(pos.add(34, 24, 44), ((BlockColored)Blocks.STAINED_HARDENED_CLAY).getStateFromMeta(4));
      world.setBlockState(pos.add(18, 24, 45), ((BlockColored)Blocks.STAINED_HARDENED_CLAY).getStateFromMeta(4));
      world.setBlockState(pos.add(20, 24, 45), ((BlockColored)Blocks.STAINED_HARDENED_CLAY).getStateFromMeta(4));
      world.setBlockState(pos.add(23, 24, 45), Blocks.DIAMOND_BLOCK.getDefaultState());
      world.setBlockState(pos.add(29, 24, 45), Blocks.DIAMOND_BLOCK.getDefaultState());
      world.setBlockState(pos.add(32, 24, 45), ((BlockColored)Blocks.STAINED_HARDENED_CLAY).getStateFromMeta(4));
      world.setBlockState(pos.add(34, 24, 45), ((BlockColored)Blocks.STAINED_HARDENED_CLAY).getStateFromMeta(4));
      world.setBlockState(pos.add(19, 24, 46), Blocks.QUARTZ_BLOCK.getDefaultState());
      world.setBlockState(pos.add(20, 24, 46), Blocks.QUARTZ_BLOCK.getDefaultState());
      world.setBlockState(pos.add(23, 24, 46), ((BlockColored)Blocks.STAINED_HARDENED_CLAY).getStateFromMeta(4));
      world.setBlockState(pos.add(25, 24, 46), Blocks.STONE.getDefaultState());
      world.setBlockState(pos.add(26, 24, 46), Blocks.STONE.getDefaultState());
      world.setBlockState(pos.add(29, 24, 46), ((BlockColored)Blocks.STAINED_HARDENED_CLAY).getStateFromMeta(4));
      world.setBlockState(pos.add(32, 24, 46), Blocks.QUARTZ_BLOCK.getDefaultState());
      world.setBlockState(pos.add(33, 24, 46), Blocks.QUARTZ_BLOCK.getDefaultState());
      world.setBlockState(pos.add(19, 24, 47), Blocks.QUARTZ_BLOCK.getDefaultState());
      world.setBlockState(pos.add(20, 24, 47), Blocks.QUARTZ_BLOCK.getDefaultState());
      world.setBlockState(pos.add(23, 24, 47), ((BlockColored)Blocks.STAINED_HARDENED_CLAY).getStateFromMeta(4));
      world.setBlockState(pos.add(25, 24, 47), Blocks.STONE.getDefaultState());
      world.setBlockState(pos.add(26, 24, 47), Blocks.STONE.getDefaultState());
      world.setBlockState(pos.add(29, 24, 47), ((BlockColored)Blocks.STAINED_HARDENED_CLAY).getStateFromMeta(4));
      world.setBlockState(pos.add(32, 24, 47), Blocks.QUARTZ_BLOCK.getDefaultState());
      world.setBlockState(pos.add(33, 24, 47), Blocks.QUARTZ_BLOCK.getDefaultState());
      world.setBlockState(pos.add(18, 24, 48), ((BlockColored)Blocks.STAINED_HARDENED_CLAY).getStateFromMeta(4));
      world.setBlockState(pos.add(20, 24, 48), ((BlockColored)Blocks.STAINED_HARDENED_CLAY).getStateFromMeta(4));
      world.setBlockState(pos.add(23, 24, 48), Blocks.DIAMOND_BLOCK.getDefaultState());
      world.setBlockState(pos.add(29, 24, 48), Blocks.DIAMOND_BLOCK.getDefaultState());
