package com.slugterra.world.greatForge;
import java.util.Random;

import net.minecraft.world.World;
import net.minecraft.init.Blocks;

public class GreatWesternForgeStructure8 {
public boolean generate(World world, Random par2Random, int xco, int yco, int zco) {
      world.setBlock(xco + 20, yco + 11, zco + 44, Blocks.stained_hardened_clay, 4, 1);
      world.setBlock(xco + 21, yco + 11, zco + 44, Blocks.quartz_block, 0, 1);
      world.setBlock(xco + 22, yco + 11, zco + 44, Blocks.quartz_block, 0, 1);
      world.setBlock(xco + 30, yco + 11, zco + 44, Blocks.quartz_block, 0, 1);
      world.setBlock(xco + 31, yco + 11, zco + 44, Blocks.quartz_block, 0, 1);
      world.setBlock(xco + 32, yco + 11, zco + 44, Blocks.stained_hardened_clay, 4, 1);
      world.setBlock(xco + 37, yco + 11, zco + 44, Blocks.stained_hardened_clay, 4, 1);
      world.setBlock(xco + 5, yco + 11, zco + 45, Blocks.stone, 0, 1);
      world.setBlock(xco + 6, yco + 11, zco + 45, Blocks.stone, 0, 1);
      world.setBlock(xco + 7, yco + 11, zco + 45, Blocks.stone, 0, 1);
      world.setBlock(xco + 15, yco + 11, zco + 45, Blocks.stained_hardened_clay, 4, 1);
      world.setBlock(xco + 20, yco + 11, zco + 45, Blocks.stained_hardened_clay, 4, 1);
      world.setBlock(xco + 21, yco + 11, zco + 45, Blocks.quartz_block, 0, 1);
      world.setBlock(xco + 22, yco + 11, zco + 45, Blocks.quartz_block, 0, 1);
      world.setBlock(xco + 23, yco + 11, zco + 45, Blocks.lava, 10, 1);
      world.setBlock(xco + 29, yco + 11, zco + 45, Blocks.lava, 10, 1);
      world.setBlock(xco + 30, yco + 11, zco + 45, Blocks.quartz_block, 0, 1);
      world.setBlock(xco + 31, yco + 11, zco + 45, Blocks.quartz_block, 0, 1);
      world.setBlock(xco + 32, yco + 11, zco + 45, Blocks.stained_hardened_clay, 4, 1);
      world.setBlock(xco + 37, yco + 11, zco + 45, Blocks.stained_hardened_clay, 4, 1);
      world.setBlock(xco + 16, yco + 11, zco + 46, Blocks.quartz_block, 0, 1);
      world.setBlock(xco + 17, yco + 11, zco + 46, Blocks.quartz_block, 0, 1);
      world.setBlock(xco + 18, yco + 11, zco + 46, Blocks.quartz_block, 0, 1);
      world.setBlock(xco + 19, yco + 11, zco + 46, Blocks.quartz_block, 0, 1);
      world.setBlock(xco + 20, yco + 11, zco + 46, Blocks.quartz_block, 0, 1);
      world.setBlock(xco + 21, yco + 11, zco + 46, Blocks.quartz_block, 0, 1);
      world.setBlock(xco + 22, yco + 11, zco + 46, Blocks.quartz_block, 0, 1);
      world.setBlock(xco + 23, yco + 11, zco + 46, Blocks.stone, 0, 1);
      world.setBlock(xco + 29, yco + 11, zco + 46, Blocks.stone, 0, 1);
      world.setBlock(xco + 30, yco + 11, zco + 46, Blocks.quartz_block, 0, 1);
      world.setBlock(xco + 31, yco + 11, zco + 46, Blocks.quartz_block, 0, 1);
      world.setBlock(xco + 32, yco + 11, zco + 46, Blocks.quartz_block, 0, 1);
      world.setBlock(xco + 36, yco + 11, zco + 46, Blocks.quartz_block, 0, 1);
      world.setBlock(xco + 16, yco + 11, zco + 47, Blocks.quartz_block, 0, 1);
      world.setBlock(xco + 17, yco + 11, zco + 47, Blocks.quartz_block, 0, 1);
      world.setBlock(xco + 18, yco + 11, zco + 47, Blocks.quartz_block, 0, 1);
      world.setBlock(xco + 19, yco + 11, zco + 47, Blocks.quartz_block, 0, 1);
      world.setBlock(xco + 20, yco + 11, zco + 47, Blocks.quartz_block, 0, 1);
      world.setBlock(xco + 21, yco + 11, zco + 47, Blocks.quartz_block, 0, 1);
      world.setBlock(xco + 22, yco + 11, zco + 47, Blocks.quartz_block, 0, 1);
      world.setBlock(xco + 23, yco + 11, zco + 47, Blocks.stone, 0, 1);
      world.setBlock(xco + 29, yco + 11, zco + 47, Blocks.stone, 0, 1);
      world.setBlock(xco + 30, yco + 11, zco + 47, Blocks.quartz_block, 0, 1);
      world.setBlock(xco + 31, yco + 11, zco + 47, Blocks.quartz_block, 0, 1);
      world.setBlock(xco + 32, yco + 11, zco + 47, Blocks.quartz_block, 0, 1);
      world.setBlock(xco + 36, yco + 11, zco + 47, Blocks.quartz_block, 0, 1);
      world.setBlock(xco + 15, yco + 11, zco + 48, Blocks.stained_hardened_clay, 4, 1);
      world.setBlock(xco + 20, yco + 11, zco + 48, Blocks.stained_hardened_clay, 4, 1);
      world.setBlock(xco + 21, yco + 11, zco + 48, Blocks.quartz_block, 0, 1);
      world.setBlock(xco + 22, yco + 11, zco + 48, Blocks.quartz_block, 0, 1);
      world.setBlock(xco + 23, yco + 11, zco + 48, Blocks.lava, 10, 1);
      world.setBlock(xco + 29, yco + 11, zco + 48, Blocks.lava, 10, 1);
      world.setBlock(xco + 30, yco + 11, zco + 48, Blocks.quartz_block, 0, 1);
      world.setBlock(xco + 31, yco + 11, zco + 48, Blocks.quartz_block, 0, 1);
      world.setBlock(xco + 32, yco + 11, zco + 48, Blocks.stained_hardened_clay, 4, 1);
      world.setBlock(xco + 37, yco + 11, zco + 48, Blocks.stained_hardened_clay, 4, 1);
      world.setBlock(xco + 15, yco + 11, zco + 49, Blocks.stained_hardened_clay, 4, 1);
      world.setBlock(xco + 20, yco + 11, zco + 49, Blocks.stained_hardened_clay, 4, 1);
      world.setBlock(xco + 21, yco + 11, zco + 49, Blocks.quartz_block, 0, 1);
      world.setBlock(xco + 22, yco + 11, zco + 49, Blocks.quartz_block, 0, 1);
      world.setBlock(xco + 30, yco + 11, zco + 49, Blocks.quartz_block, 0, 1);
      world.setBlock(xco + 31, yco + 11, zco + 49, Blocks.quartz_block, 0, 1);
      world.setBlock(xco + 32, yco + 11, zco + 49, Blocks.stained_hardened_clay, 4, 1);
      world.setBlock(xco + 37, yco + 11, zco + 49, Blocks.stained_hardened_clay, 4, 1);
      world.setBlock(xco + 15, yco + 11, zco + 50, Blocks.stained_hardened_clay, 4, 1);
      world.setBlock(xco + 16, yco + 11, zco + 50, Blocks.stained_hardened_clay, 4, 1);
      world.setBlock(xco + 17, yco + 11, zco + 50, Blocks.stained_hardened_clay, 4, 1);
      world.setBlock(xco + 18, yco + 11, zco + 50, Blocks.stained_hardened_clay, 4, 1);
      world.setBlock(xco + 19, yco + 11, zco + 50, Blocks.stained_hardened_clay, 4, 1);
      world.setBlock(xco + 20, yco + 11, zco + 50, Blocks.stained_hardened_clay, 4, 1);
      world.setBlock(xco + 21, yco + 11, zco + 50, Blocks.quartz_block, 0, 1);
      world.setBlock(xco + 22, yco + 11, zco + 50, Blocks.quartz_block, 0, 1);
      world.setBlock(xco + 30, yco + 11, zco + 50, Blocks.quartz_block, 0, 1);
      world.setBlock(xco + 31, yco + 11, zco + 50, Blocks.quartz_block, 0, 1);
      world.setBlock(xco + 32, yco + 11, zco + 50, Blocks.stained_hardened_clay, 4, 1);
      world.setBlock(xco + 33, yco + 11, zco + 50, Blocks.stained_hardened_clay, 4, 1);
      world.setBlock(xco + 34, yco + 11, zco + 50, Blocks.stained_hardened_clay, 4, 1);
      world.setBlock(xco + 35, yco + 11, zco + 50, Blocks.stained_hardened_clay, 4, 1);
      world.setBlock(xco + 36, yco + 11, zco + 50, Blocks.stained_hardened_clay, 4, 1);
      world.setBlock(xco + 37, yco + 11, zco + 50, Blocks.stained_hardened_clay, 4, 1);
      world.setBlock(xco + 18, yco + 11, zco + 51, Blocks.stained_hardened_clay, 4, 1);
      world.setBlock(xco + 19, yco + 11, zco + 51, Blocks.stained_hardened_clay, 4, 1);
      world.setBlock(xco + 20, yco + 11, zco + 51, Blocks.stained_hardened_clay, 4, 1);
      world.setBlock(xco + 21, yco + 11, zco + 51, Blocks.stained_hardened_clay, 4, 1);
      world.setBlock(xco + 30, yco + 11, zco + 51, Blocks.stained_hardened_clay, 4, 1);
      world.setBlock(xco + 31, yco + 11, zco + 51, Blocks.stained_hardened_clay, 4, 1);
      world.setBlock(xco + 32, yco + 11, zco + 51, Blocks.stained_hardened_clay, 4, 1);
      world.setBlock(xco + 33, yco + 11, zco + 51, Blocks.stained_hardened_clay, 4, 1);
      world.setBlock(xco + 34, yco + 11, zco + 51, Blocks.stained_hardened_clay, 4, 1);
      world.setBlock(xco + 17, yco + 11, zco + 52, Blocks.stained_hardened_clay, 4, 1);
      world.setBlock(xco + 18, yco + 11, zco + 52, Blocks.stained_hardened_clay, 4, 1);
      world.setBlock(xco + 22, yco + 11, zco + 52, Blocks.stained_hardened_clay, 4, 1);
      world.setBlock(xco + 29, yco + 11, zco + 52, Blocks.stained_hardened_clay, 4, 1);
      world.setBlock(xco + 30, yco + 11, zco + 52, Blocks.stained_hardened_clay, 4, 1);
      world.setBlock(xco + 34, yco + 11, zco + 52, Blocks.stained_hardened_clay, 4, 1);
      world.setBlock(xco + 35, yco + 11, zco + 52, Blocks.stained_hardened_clay, 4, 1);
      world.setBlock(xco + 16, yco + 11, zco + 53, Blocks.stained_hardened_clay, 4, 1);
      world.setBlock(xco + 17, yco + 11, zco + 53, Blocks.stained_hardened_clay, 4, 1);
      world.setBlock(xco + 23, yco + 11, zco + 53, Blocks.stained_hardened_clay, 4, 1);
      world.setBlock(xco + 24, yco + 11, zco + 53, Blocks.stained_hardened_clay, 4, 1);
      world.setBlock(xco + 25, yco + 11, zco + 53, Blocks.redstone_torch, 1, 1);
      world.setBlock(xco + 27, yco + 11, zco + 53, Blocks.redstone_torch, 2, 1);
      world.setBlock(xco + 28, yco + 11, zco + 53, Blocks.stained_hardened_clay, 4, 1);
      world.setBlock(xco + 29, yco + 11, zco + 53, Blocks.stained_hardened_clay, 4, 1);
      world.setBlock(xco + 35, yco + 11, zco + 53, Blocks.stained_hardened_clay, 4, 1);
      world.setBlock(xco + 36, yco + 11, zco + 53, Blocks.stained_hardened_clay, 4, 1);
      world.setBlock(xco + 16, yco + 11, zco + 54, Blocks.stained_hardened_clay, 4, 1);
      world.setBlock(xco + 17, yco + 11, zco + 54, Blocks.stained_hardened_clay, 4, 1);
      world.setBlock(xco + 23, yco + 11, zco + 54, Blocks.stained_hardened_clay, 4, 1);
      world.setBlock(xco + 24, yco + 11, zco + 54, Blocks.stained_hardened_clay, 4, 1);
      world.setBlock(xco + 28, yco + 11, zco + 54, Blocks.stained_hardened_clay, 4, 1);
      world.setBlock(xco + 29, yco + 11, zco + 54, Blocks.stained_hardened_clay, 4, 1);
      world.setBlock(xco + 35, yco + 11, zco + 54, Blocks.stained_hardened_clay, 4, 1);
      world.setBlock(xco + 36, yco + 11, zco + 54, Blocks.stained_hardened_clay, 4, 1);
      world.setBlock(xco + 16, yco + 11, zco + 55, Blocks.stained_hardened_clay, 4, 1);
      world.setBlock(xco + 17, yco + 11, zco + 55, Blocks.stained_hardened_clay, 4, 1);
      world.setBlock(xco + 23, yco + 11, zco + 55, Blocks.stained_hardened_clay, 4, 1);
      world.setBlock(xco + 24, yco + 11, zco + 55, Blocks.stained_hardened_clay, 4, 1);
      world.setBlock(xco + 28, yco + 11, zco + 55, Blocks.stained_hardened_clay, 4, 1);
      world.setBlock(xco + 29, yco + 11, zco + 55, Blocks.stained_hardened_clay, 4, 1);
      world.setBlock(xco + 35, yco + 11, zco + 55, Blocks.stained_hardened_clay, 4, 1);
      world.setBlock(xco + 36, yco + 11, zco + 55, Blocks.stained_hardened_clay, 4, 1);
      world.setBlock(xco + 37, yco + 11, zco + 55, Blocks.stained_hardened_clay, 4, 1);
      world.setBlock(xco + 17, yco + 11, zco + 56, Blocks.stained_hardened_clay, 4, 1);
      world.setBlock(xco + 18, yco + 11, zco + 56, Blocks.stained_hardened_clay, 4, 1);
      world.setBlock(xco + 22, yco + 11, zco + 56, Blocks.stained_hardened_clay, 4, 1);
      world.setBlock(xco + 23, yco + 11, zco + 56, Blocks.stained_hardened_clay, 4, 1);
      world.setBlock(xco + 24, yco + 11, zco + 56, Blocks.nether_brick_fence, 0, 1);
      world.setBlock(xco + 25, yco + 11, zco + 56, Blocks.nether_brick_stairs, 2, 1);
      world.setBlock(xco + 26, yco + 11, zco + 56, Blocks.nether_brick_stairs, 2, 1);
      world.setBlock(xco + 27, yco + 11, zco + 56, Blocks.nether_brick_stairs, 2, 1);
      world.setBlock(xco + 28, yco + 11, zco + 56, Blocks.nether_brick_fence, 0, 1);
      world.setBlock(xco + 29, yco + 11, zco + 56, Blocks.stained_hardened_clay, 4, 1);
      world.setBlock(xco + 30, yco + 11, zco + 56, Blocks.stained_hardened_clay, 4, 1);
      world.setBlock(xco + 34, yco + 11, zco + 56, Blocks.stained_hardened_clay, 4, 1);
      world.setBlock(xco + 35, yco + 11, zco + 56, Blocks.stained_hardened_clay, 4, 1);
      world.setBlock(xco + 38, yco + 11, zco + 56, Blocks.stained_hardened_clay, 4, 1);
      world.setBlock(xco + 39, yco + 11, zco + 56, Blocks.wool, 15, 1);
      world.setBlock(xco + 40, yco + 11, zco + 56, Blocks.wool, 15, 1);
      world.setBlock(xco + 18, yco + 11, zco + 57, Blocks.stained_hardened_clay, 4, 1);
      world.setBlock(xco + 19, yco + 11, zco + 57, Blocks.stained_hardened_clay, 4, 1);
      world.setBlock(xco + 20, yco + 11, zco + 57, Blocks.stained_hardened_clay, 4, 1);
      world.setBlock(xco + 21, yco + 11, zco + 57, Blocks.stained_hardened_clay, 4, 1);
      world.setBlock(xco + 22, yco + 11, zco + 57, Blocks.stained_hardened_clay, 4, 1);
      world.setBlock(xco + 29, yco + 11, zco + 57, Blocks.stone, 0, 1);
      world.setBlock(xco + 30, yco + 11, zco + 57, Blocks.stained_hardened_clay, 4, 1);
      world.setBlock(xco + 31, yco + 11, zco + 57, Blocks.stained_hardened_clay, 4, 1);
      world.setBlock(xco + 32, yco + 11, zco + 57, Blocks.stained_hardened_clay, 4, 1);
      world.setBlock(xco + 33, yco + 11, zco + 57, Blocks.stained_hardened_clay, 4, 1);
      world.setBlock(xco + 34, yco + 11, zco + 57, Blocks.stained_hardened_clay, 4, 1);
      world.setBlock(xco + 39, yco + 11, zco + 57, Blocks.stained_hardened_clay, 4, 1);
      world.setBlock(xco + 41, yco + 11, zco + 57, Blocks.wool, 15, 1);
      world.setBlock(xco + 19, yco + 11, zco + 58, Blocks.stained_hardened_clay, 4, 1);
      world.setBlock(xco + 20, yco + 11, zco + 58, Blocks.stained_hardened_clay, 4, 1);
      world.setBlock(xco + 21, yco + 11, zco + 58, Blocks.stained_hardened_clay, 4, 1);
      world.setBlock(xco + 31, yco + 11, zco + 58, Blocks.stained_hardened_clay, 4, 1);
      world.setBlock(xco + 32, yco + 11, zco + 58, Blocks.stained_hardened_clay, 4, 1);
      world.setBlock(xco + 33, yco + 11, zco + 58, Blocks.stained_hardened_clay, 4, 1);
      world.setBlock(xco + 40, yco + 11, zco + 58, Blocks.stained_hardened_clay, 4, 1);
      world.setBlock(xco + 42, yco + 11, zco + 58, Blocks.wool, 15, 1);
      world.setBlock(xco + 34, yco + 11, zco + 59, Blocks.wool, 15, 1);
      world.setBlock(xco + 35, yco + 11, zco + 59, Blocks.wool, 15, 1);
      world.setBlock(xco + 36, yco + 11, zco + 59, Blocks.wool, 15, 1);
      world.setBlock(xco + 37, yco + 11, zco + 59, Blocks.wool, 15, 1);
      world.setBlock(xco + 41, yco + 11, zco + 59, Blocks.stained_hardened_clay, 4, 1);
      world.setBlock(xco + 42, yco + 11, zco + 59, Blocks.wool, 15, 1);
      world.setBlock(xco + 33, yco + 11, zco + 60, Blocks.wool, 15, 1);
      world.setBlock(xco + 38, yco + 11, zco + 60, Blocks.wool, 15, 1);
      world.setBlock(xco + 42, yco + 11, zco + 60, Blocks.stone, 0, 1);
      world.setBlock(xco + 43, yco + 11, zco + 60, Blocks.stone, 0, 1);
      world.setBlock(xco + 44, yco + 11, zco + 60, Blocks.stone, 0, 1);
      world.setBlock(xco + 45, yco + 11, zco + 60, Blocks.stone, 0, 1);
      world.setBlock(xco + 32, yco + 11, zco + 61, Blocks.wool, 15, 1);
      world.setBlock(xco + 39, yco + 11, zco + 61, Blocks.wool, 15, 1);
      world.setBlock(xco + 41, yco + 11, zco + 61, Blocks.stone, 0, 1);
      world.setBlock(xco + 46, yco + 11, zco + 61, Blocks.stone, 0, 1);
      world.setBlock(xco + 32, yco + 11, zco + 62, Blocks.wool, 15, 1);
      world.setBlock(xco + 39, yco + 11, zco + 62, Blocks.wool, 15, 1);
      world.setBlock(xco + 40, yco + 11, zco + 62, Blocks.stone, 0, 1);
      world.setBlock(xco + 47, yco + 11, zco + 62, Blocks.stone, 0, 1);
      world.setBlock(xco + 19, yco + 11, zco + 63, Blocks.obsidian, 0, 1);
      world.setBlock(xco + 32, yco + 11, zco + 63, Blocks.wool, 15, 1);
      world.setBlock(xco + 39, yco + 11, zco + 63, Blocks.wool, 15, 1);
      world.setBlock(xco + 40, yco + 11, zco + 63, Blocks.stone, 0, 1);
      world.setBlock(xco + 47, yco + 11, zco + 63, Blocks.stone, 0, 1);
      world.setBlock(xco + 19, yco + 11, zco + 64, Blocks.obsidian, 0, 1);
      world.setBlock(xco + 32, yco + 11, zco + 64, Blocks.wool, 15, 1);
      world.setBlock(xco + 39, yco + 11, zco + 64, Blocks.wool, 15, 1);
      world.setBlock(xco + 40, yco + 11, zco + 64, Blocks.stone, 0, 1);
      world.setBlock(xco + 47, yco + 11, zco + 64, Blocks.stone, 0, 1);
      world.setBlock(xco + 23, yco + 11, zco + 65, Blocks.obsidian, 0, 1);
      world.setBlock(xco + 24, yco + 11, zco + 65, Blocks.obsidian, 0, 1);
      world.setBlock(xco + 33, yco + 11, zco + 65, Blocks.wool, 15, 1);
      world.setBlock(xco + 38, yco + 11, zco + 65, Blocks.wool, 15, 1);
      world.setBlock(xco + 40, yco + 11, zco + 65, Blocks.stone, 0, 1);
      world.setBlock(xco + 47, yco + 11, zco + 65, Blocks.stone, 0, 1);
      world.setBlock(xco + 34, yco + 11, zco + 66, Blocks.wool, 15, 1);
      world.setBlock(xco + 35, yco + 11, zco + 66, Blocks.wool, 15, 1);
      world.setBlock(xco + 36, yco + 11, zco + 66, Blocks.wool, 15, 1);
      world.setBlock(xco + 37, yco + 11, zco + 66, Blocks.wool, 15, 1);
      world.setBlock(xco + 41, yco + 11, zco + 66, Blocks.stone, 0, 1);
      world.setBlock(xco + 46, yco + 11, zco + 66, Blocks.stone, 0, 1);
      world.setBlock(xco + 42, yco + 11, zco + 67, Blocks.stone, 0, 1);
      world.setBlock(xco + 43, yco + 11, zco + 67, Blocks.stone, 0, 1);
      world.setBlock(xco + 44, yco + 11, zco + 67, Blocks.stone, 0, 1);
      world.setBlock(xco + 45, yco + 11, zco + 67, Blocks.stone, 0, 1);
      world.setBlock(xco + 24, yco + 12, zco + 36, Blocks.quartz_block, 0, 1);
      world.setBlock(xco + 25, yco + 12, zco + 36, Blocks.stained_hardened_clay, 10, 1);
      world.setBlock(xco + 27, yco + 12, zco + 36, Blocks.stained_hardened_clay, 10, 1);
      world.setBlock(xco + 28, yco + 12, zco + 36, Blocks.quartz_block, 0, 1);
      world.setBlock(xco + 15, yco + 12, zco + 37, Blocks.stained_hardened_clay, 4, 1);
      world.setBlock(xco + 16, yco + 12, zco + 37, Blocks.stained_hardened_clay, 4, 1);
      world.setBlock(xco + 17, yco + 12, zco + 37, Blocks.stained_hardened_clay, 4, 1);
      world.setBlock(xco + 18, yco + 12, zco + 37, Blocks.stained_hardened_clay, 4, 1);
      world.setBlock(xco + 19, yco + 12, zco + 37, Blocks.stained_hardened_clay, 4, 1);
      world.setBlock(xco + 20, yco + 12, zco + 37, Blocks.stained_hardened_clay, 4, 1);
      world.setBlock(xco + 21, yco + 12, zco + 37, Blocks.quartz_block, 0, 1);
      world.setBlock(xco + 22, yco + 12, zco + 37, Blocks.quartz_block, 0, 1);
      world.setBlock(xco + 23, yco + 12, zco + 37, Blocks.stained_hardened_clay, 4, 1);
      world.setBlock(xco + 29, yco + 12, zco + 37, Blocks.stained_hardened_clay, 4, 1);
      world.setBlock(xco + 32, yco + 12, zco + 37, Blocks.stained_hardened_clay, 4, 1);
      world.setBlock(xco + 33, yco + 12, zco + 37, Blocks.stained_hardened_clay, 4, 1);
      world.setBlock(xco + 34, yco + 12, zco + 37, Blocks.stained_hardened_clay, 4, 1);
      world.setBlock(xco + 35, yco + 12, zco + 37, Blocks.stained_hardened_clay, 4, 1);
      world.setBlock(xco + 36, yco + 12, zco + 37, Blocks.stained_hardened_clay, 4, 1);
      world.setBlock(xco + 37, yco + 12, zco + 37, Blocks.stained_hardened_clay, 4, 1);
      world.setBlock(xco + 15, yco + 12, zco + 38, Blocks.stained_hardened_clay, 4, 1);
      world.setBlock(xco + 16, yco + 12, zco + 38, Blocks.stained_hardened_clay, 4, 1);
      world.setBlock(xco + 17, yco + 12, zco + 38, Blocks.stained_hardened_clay, 4, 1);
      world.setBlock(xco + 18, yco + 12, zco + 38, Blocks.stained_hardened_clay, 4, 1);
      world.setBlock(xco + 19, yco + 12, zco + 38, Blocks.stained_hardened_clay, 4, 1);
      world.setBlock(xco + 20, yco + 12, zco + 38, Blocks.stained_hardened_clay, 4, 1);
      world.setBlock(xco + 21, yco + 12, zco + 38, Blocks.quartz_block, 0, 1);
      world.setBlock(xco + 22, yco + 12, zco + 38, Blocks.quartz_block, 0, 1);
      world.setBlock(xco + 30, yco + 12, zco + 38, Blocks.quartz_block, 0, 1);
      world.setBlock(xco + 31, yco + 12, zco + 38, Blocks.quartz_block, 0, 1);
      world.setBlock(xco + 32, yco + 12, zco + 38, Blocks.stained_hardened_clay, 4, 1);
      world.setBlock(xco + 33, yco + 12, zco + 38, Blocks.stained_hardened_clay, 4, 1);
      world.setBlock(xco + 34, yco + 12, zco + 38, Blocks.stained_hardened_clay, 4, 1);
      world.setBlock(xco + 35, yco + 12, zco + 38, Blocks.stained_hardened_clay, 4, 1);
      world.setBlock(xco + 36, yco + 12, zco + 38, Blocks.stained_hardened_clay, 4, 1);
      world.setBlock(xco + 37, yco + 12, zco + 38, Blocks.stained_hardened_clay, 4, 1);
      world.setBlock(xco + 15, yco + 12, zco + 39, Blocks.stained_hardened_clay, 4, 1);
      world.setBlock(xco + 20, yco + 12, zco + 39, Blocks.stained_hardened_clay, 4, 1);
      world.setBlock(xco + 21, yco + 12, zco + 39, Blocks.quartz_block, 0, 1);
      world.setBlock(xco + 22, yco + 12, zco + 39, Blocks.quartz_block, 0, 1);
      world.setBlock(xco + 30, yco + 12, zco + 39, Blocks.quartz_block, 0, 1);
      world.setBlock(xco + 31, yco + 12, zco + 39, Blocks.quartz_block, 0, 1);
      world.setBlock(xco + 32, yco + 12, zco + 39, Blocks.stained_hardened_clay, 4, 1);
      world.setBlock(xco + 37, yco + 12, zco + 39, Blocks.stained_hardened_clay, 4, 1);
      world.setBlock(xco + 15, yco + 12, zco + 40, Blocks.stained_hardened_clay, 4, 1);
      world.setBlock(xco + 20, yco + 12, zco + 40, Blocks.stained_hardened_clay, 4, 1);
      world.setBlock(xco + 21, yco + 12, zco + 40, Blocks.quartz_block, 0, 1);
      world.setBlock(xco + 22, yco + 12, zco + 40, Blocks.quartz_block, 0, 1);
      world.setBlock(xco + 23, yco + 12, zco + 40, Blocks.lava, 10, 1);
      world.setBlock(xco + 29, yco + 12, zco + 40, Blocks.lava, 10, 1);
      world.setBlock(xco + 30, yco + 12, zco + 40, Blocks.quartz_block, 0, 1);
      world.setBlock(xco + 31, yco + 12, zco + 40, Blocks.quartz_block, 0, 1);
      world.setBlock(xco + 32, yco + 12, zco + 40, Blocks.stained_hardened_clay, 4, 1);
      world.setBlock(xco + 35, yco + 12, zco + 40, Blocks.stained_hardened_clay, 4, 1);
      world.setBlock(xco + 36, yco + 12, zco + 40, Blocks.stained_hardened_clay, 4, 1);
      world.setBlock(xco + 37, yco + 12, zco + 40, Blocks.stained_hardened_clay, 4, 1);
      world.setBlock(xco + 5, yco + 12, zco + 41, Blocks.stone, 0, 1);
      world.setBlock(xco + 6, yco + 12, zco + 41, Blocks.stone, 0, 1);
      world.setBlock(xco + 7, yco + 12, zco + 41, Blocks.stone, 0, 1);
      world.setBlock(xco + 16, yco + 12, zco + 41, Blocks.quartz_block, 0, 1);
      world.setBlock(xco + 17, yco + 12, zco + 41, Blocks.quartz_block, 0, 1);
      world.setBlock(xco + 20, yco + 12, zco + 41, Blocks.quartz_block, 0, 1);
      world.setBlock(xco + 21, yco + 12, zco + 41, Blocks.quartz_block, 0, 1);
      world.setBlock(xco + 22, yco + 12, zco + 41, Blocks.quartz_block, 0, 1);
      world.setBlock(xco + 23, yco + 12, zco + 41, Blocks.stone, 0, 1);
      world.setBlock(xco + 29, yco + 12, zco + 41, Blocks.stone, 0, 1);
      world.setBlock(xco + 30, yco + 12, zco + 41, Blocks.quartz_block, 0, 1);
      world.setBlock(xco + 31, yco + 12, zco + 41, Blocks.quartz_block, 0, 1);
      world.setBlock(xco + 32, yco + 12, zco + 41, Blocks.quartz_block, 0, 1);
      world.setBlock(xco + 36, yco + 12, zco + 41, Blocks.quartz_block, 0, 1);
      world.setBlock(xco + 4, yco + 12, zco + 42, Blocks.stone, 0, 1);
      world.setBlock(xco + 7, yco + 12, zco + 42, Blocks.stone, 0, 1);
      world.setBlock(xco + 8, yco + 12, zco + 42, Blocks.stone, 0, 1);
      world.setBlock(xco + 16, yco + 12, zco + 42, Blocks.quartz_block, 0, 1);
      world.setBlock(xco + 17, yco + 12, zco + 42, Blocks.quartz_block, 0, 1);
      world.setBlock(xco + 20, yco + 12, zco + 42, Blocks.quartz_block, 0, 1);
      world.setBlock(xco + 21, yco + 12, zco + 42, Blocks.quartz_block, 0, 1);
      world.setBlock(xco + 22, yco + 12, zco + 42, Blocks.quartz_block, 0, 1);
      world.setBlock(xco + 23, yco + 12, zco + 42, Blocks.stone, 0, 1);
      world.setBlock(xco + 29, yco + 12, zco + 42, Blocks.stone, 0, 1);
      world.setBlock(xco + 30, yco + 12, zco + 42, Blocks.quartz_block, 0, 1);
      world.setBlock(xco + 31, yco + 12, zco + 42, Blocks.quartz_block, 0, 1);
      world.setBlock(xco + 32, yco + 12, zco + 42, Blocks.quartz_block, 0, 1);
      world.setBlock(xco + 36, yco + 12, zco + 42, Blocks.quartz_block, 0, 1);
      world.setBlock(xco + 4, yco + 12, zco + 43, Blocks.stone, 0, 1);
      world.setBlock(xco + 8, yco + 12, zco + 43, Blocks.stone, 0, 1);
      world.setBlock(xco + 15, yco + 12, zco + 43, Blocks.stained_hardened_clay, 4, 1);
      world.setBlock(xco + 16, yco + 12, zco + 43, Blocks.stained_hardened_clay, 4, 1);
      world.setBlock(xco + 20, yco + 12, zco + 43, Blocks.stained_hardened_clay, 4, 1);
      world.setBlock(xco + 21, yco + 12, zco + 43, Blocks.quartz_block, 0, 1);
      world.setBlock(xco + 22, yco + 12, zco + 43, Blocks.quartz_block, 0, 1);
      world.setBlock(xco + 23, yco + 12, zco + 43, Blocks.lava, 10, 1);
      world.setBlock(xco + 29, yco + 12, zco + 43, Blocks.lava, 10, 1);
      world.setBlock(xco + 30, yco + 12, zco + 43, Blocks.quartz_block, 0, 1);
      world.setBlock(xco + 31, yco + 12, zco + 43, Blocks.quartz_block, 0, 1);
      world.setBlock(xco + 32, yco + 12, zco + 43, Blocks.stained_hardened_clay, 4, 1);
      world.setBlock(xco + 36, yco + 12, zco + 43, Blocks.stained_hardened_clay, 4, 1);
      world.setBlock(xco + 37, yco + 12, zco + 43, Blocks.stained_hardened_clay, 4, 1);
      world.setBlock(xco + 4, yco + 12, zco + 44, Blocks.stone, 0, 1);
      world.setBlock(xco + 5, yco + 12, zco + 44, Blocks.stone, 0, 1);
      world.setBlock(xco + 7, yco + 12, zco + 44, Blocks.stone, 0, 1);
      world.setBlock(xco + 8, yco + 12, zco + 44, Blocks.stone, 0, 1);
      world.setBlock(xco + 15, yco + 12, zco + 44, Blocks.stained_hardened_clay, 4, 1);
      world.setBlock(xco + 20, yco + 12, zco + 44, Blocks.stained_hardened_clay, 4, 1);
      world.setBlock(xco + 21, yco + 12, zco + 44, Blocks.quartz_block, 0, 1);
      world.setBlock(xco + 22, yco + 12, zco + 44, Blocks.quartz_block, 0, 1);
      world.setBlock(xco + 30, yco + 12, zco + 44, Blocks.quartz_block, 0, 1);
      world.setBlock(xco + 31, yco + 12, zco + 44, Blocks.quartz_block, 0, 1);
      world.setBlock(xco + 32, yco + 12, zco + 44, Blocks.stained_hardened_clay, 4, 1);
      world.setBlock(xco + 37, yco + 12, zco + 44, Blocks.stained_hardened_clay, 4, 1);
      world.setBlock(xco + 5, yco + 12, zco + 45, Blocks.stone, 0, 1);
      world.setBlock(xco + 6, yco + 12, zco + 45, Blocks.stone, 0, 1);
      world.setBlock(xco + 7, yco + 12, zco + 45, Blocks.stone, 0, 1);
      world.setBlock(xco + 15, yco + 12, zco + 45, Blocks.stained_hardened_clay, 4, 1);
      world.setBlock(xco + 20, yco + 12, zco + 45, Blocks.stained_hardened_clay, 4, 1);
      world.setBlock(xco + 21, yco + 12, zco + 45, Blocks.quartz_block, 0, 1);
      world.setBlock(xco + 22, yco + 12, zco + 45, Blocks.quartz_block, 0, 1);
      world.setBlock(xco + 23, yco + 12, zco + 45, Blocks.lava, 10, 1);
      world.setBlock(xco + 29, yco + 12, zco + 45, Blocks.lava, 10, 1);
      world.setBlock(xco + 30, yco + 12, zco + 45, Blocks.quartz_block, 0, 1);
      world.setBlock(xco + 31, yco + 12, zco + 45, Blocks.quartz_block, 0, 1);
      world.setBlock(xco + 32, yco + 12, zco + 45, Blocks.stained_hardened_clay, 4, 1);
      world.setBlock(xco + 37, yco + 12, zco + 45, Blocks.stained_hardened_clay, 4, 1);
      world.setBlock(xco + 16, yco + 12, zco + 46, Blocks.quartz_block, 0, 1);
      world.setBlock(xco + 17, yco + 12, zco + 46, Blocks.quartz_block, 0, 1);
      world.setBlock(xco + 18, yco + 12, zco + 46, Blocks.quartz_block, 0, 1);
      world.setBlock(xco + 19, yco + 12, zco + 46, Blocks.quartz_block, 0, 1);
      world.setBlock(xco + 20, yco + 12, zco + 46, Blocks.quartz_block, 0, 1);
      world.setBlock(xco + 21, yco + 12, zco + 46, Blocks.quartz_block, 0, 1);
      world.setBlock(xco + 22, yco + 12, zco + 46, Blocks.quartz_block, 0, 1);
      world.setBlock(xco + 23, yco + 12, zco + 46, Blocks.stone, 0, 1);
      world.setBlock(xco + 29, yco + 12, zco + 46, Blocks.stone, 0, 1);
      world.setBlock(xco + 30, yco + 12, zco + 46, Blocks.quartz_block, 0, 1);
      world.setBlock(xco + 31, yco + 12, zco + 46, Blocks.quartz_block, 0, 1);
      world.setBlock(xco + 32, yco + 12, zco + 46, Blocks.quartz_block, 0, 1);
      world.setBlock(xco + 35, yco + 12, zco + 46, Blocks.quartz_block, 0, 1);
      world.setBlock(xco + 36, yco + 12, zco + 46, Blocks.quartz_block, 0, 1);
      world.setBlock(xco + 16, yco + 12, zco + 47, Blocks.quartz_block, 0, 1);
      world.setBlock(xco + 17, yco + 12, zco + 47, Blocks.quartz_block, 0, 1);
      world.setBlock(xco + 18, yco + 12, zco + 47, Blocks.quartz_block, 0, 1);
      world.setBlock(xco + 19, yco + 12, zco + 47, Blocks.quartz_block, 0, 1);
      world.setBlock(xco + 20, yco + 12, zco + 47, Blocks.quartz_block, 0, 1);
      world.setBlock(xco + 21, yco + 12, zco + 47, Blocks.quartz_block, 0, 1);
      world.setBlock(xco + 22, yco + 12, zco + 47, Blocks.quartz_block, 0, 1);
      world.setBlock(xco + 23, yco + 12, zco + 47, Blocks.stone, 0, 1);
      world.setBlock(xco + 29, yco + 12, zco + 47, Blocks.stone, 0, 1);
      world.setBlock(xco + 30, yco + 12, zco + 47, Blocks.quartz_block, 0, 1);
      world.setBlock(xco + 31, yco + 12, zco + 47, Blocks.quartz_block, 0, 1);
      world.setBlock(xco + 32, yco + 12, zco + 47, Blocks.quartz_block, 0, 1);
      world.setBlock(xco + 35, yco + 12, zco + 47, Blocks.quartz_block, 0, 1);
      world.setBlock(xco + 36, yco + 12, zco + 47, Blocks.quartz_block, 0, 1);
      world.setBlock(xco + 15, yco + 12, zco + 48, Blocks.stained_hardened_clay, 4, 1);
      world.setBlock(xco + 20, yco + 12, zco + 48, Blocks.stained_hardened_clay, 4, 1);
      world.setBlock(xco + 21, yco + 12, zco + 48, Blocks.quartz_block, 0, 1);
      world.setBlock(xco + 22, yco + 12, zco + 48, Blocks.quartz_block, 0, 1);
      world.setBlock(xco + 23, yco + 12, zco + 48, Blocks.lava, 10, 1);
      world.setBlock(xco + 29, yco + 12, zco + 48, Blocks.lava, 10, 1);
      world.setBlock(xco + 30, yco + 12, zco + 48, Blocks.quartz_block, 0, 1);
      world.setBlock(xco + 31, yco + 12, zco + 48, Blocks.quartz_block, 0, 1);
      world.setBlock(xco + 32, yco + 12, zco + 48, Blocks.stained_hardened_clay, 4, 1);
      world.setBlock(xco + 36, yco + 12, zco + 48, Blocks.stained_hardened_clay, 4, 1);
      world.setBlock(xco + 37, yco + 12, zco + 48, Blocks.stained_hardened_clay, 4, 1);
      world.setBlock(xco + 15, yco + 12, zco + 49, Blocks.stained_hardened_clay, 4, 1);
      world.setBlock(xco + 20, yco + 12, zco + 49, Blocks.stained_hardened_clay, 4, 1);
      world.setBlock(xco + 21, yco + 12, zco + 49, Blocks.quartz_block, 0, 1);
      world.setBlock(xco + 22, yco + 12, zco + 49, Blocks.quartz_block, 0, 1);
      world.setBlock(xco + 30, yco + 12, zco + 49, Blocks.quartz_block, 0, 1);
      world.setBlock(xco + 31, yco + 12, zco + 49, Blocks.quartz_block, 0, 1);
      world.setBlock(xco + 32, yco + 12, zco + 49, Blocks.stained_hardened_clay, 4, 1);
      world.setBlock(xco + 37, yco + 12, zco + 49, Blocks.stained_hardened_clay, 4, 1);
      world.setBlock(xco + 15, yco + 12, zco + 50, Blocks.stained_hardened_clay, 4, 1);
      world.setBlock(xco + 16, yco + 12, zco + 50, Blocks.stained_hardened_clay, 4, 1);
      world.setBlock(xco + 17, yco + 12, zco + 50, Blocks.stained_hardened_clay, 4, 1);
      world.setBlock(xco + 18, yco + 12, zco + 50, Blocks.stained_hardened_clay, 4, 1);
      world.setBlock(xco + 19, yco + 12, zco + 50, Blocks.stained_hardened_clay, 4, 1);
      world.setBlock(xco + 20, yco + 12, zco + 50, Blocks.stained_hardened_clay, 4, 1);
      world.setBlock(xco + 21, yco + 12, zco + 50, Blocks.quartz_block, 0, 1);
      world.setBlock(xco + 22, yco + 12, zco + 50, Blocks.quartz_block, 0, 1);
      world.setBlock(xco + 30, yco + 12, zco + 50, Blocks.quartz_block, 0, 1);
      world.setBlock(xco + 31, yco + 12, zco + 50, Blocks.quartz_block, 0, 1);
      world.setBlock(xco + 32, yco + 12, zco + 50, Blocks.stained_hardened_clay, 4, 1);
      world.setBlock(xco + 33, yco + 12, zco + 50, Blocks.stained_hardened_clay, 4, 1);
      world.setBlock(xco + 34, yco + 12, zco + 50, Blocks.stained_hardened_clay, 4, 1);
      world.setBlock(xco + 35, yco + 12, zco + 50, Blocks.stained_hardened_clay, 4, 1);
      world.setBlock(xco + 36, yco + 12, zco + 50, Blocks.stained_hardened_clay, 4, 1);
      world.setBlock(xco + 37, yco + 12, zco + 50, Blocks.stained_hardened_clay, 4, 1);
      world.setBlock(xco + 18, yco + 12, zco + 51, Blocks.stained_hardened_clay, 4, 1);
      world.setBlock(xco + 19, yco + 12, zco + 51, Blocks.stained_hardened_clay, 4, 1);
      world.setBlock(xco + 20, yco + 12, zco + 51, Blocks.stained_hardened_clay, 4, 1);
      world.setBlock(xco + 21, yco + 12, zco + 51, Blocks.stained_hardened_clay, 4, 1);
      world.setBlock(xco + 30, yco + 12, zco + 51, Blocks.stained_hardened_clay, 4, 1);
      world.setBlock(xco + 31, yco + 12, zco + 51, Blocks.stained_hardened_clay, 4, 1);
      world.setBlock(xco + 32, yco + 12, zco + 51, Blocks.stained_hardened_clay, 4, 1);
      world.setBlock(xco + 33, yco + 12, zco + 51, Blocks.stained_hardened_clay, 4, 1);
      world.setBlock(xco + 34, yco + 12, zco + 51, Blocks.stained_hardened_clay, 4, 1);
      world.setBlock(xco + 17, yco + 12, zco + 52, Blocks.stained_hardened_clay, 4, 1);
      world.setBlock(xco + 18, yco + 12, zco + 52, Blocks.stained_hardened_clay, 4, 1);
      world.setBlock(xco + 22, yco + 12, zco + 52, Blocks.stained_hardened_clay, 4, 1);
      world.setBlock(xco + 29, yco + 12, zco + 52, Blocks.stained_hardened_clay, 4, 1);
      world.setBlock(xco + 30, yco + 12, zco + 52, Blocks.stained_hardened_clay, 4, 1);
      world.setBlock(xco + 34, yco + 12, zco + 52, Blocks.stained_hardened_clay, 4, 1);
      world.setBlock(xco + 35, yco + 12, zco + 52, Blocks.stained_hardened_clay, 4, 1);
      world.setBlock(xco + 16, yco + 12, zco + 53, Blocks.stained_hardened_clay, 4, 1);
      world.setBlock(xco + 17, yco + 12, zco + 53, Blocks.stained_hardened_clay, 4, 1);
      world.setBlock(xco + 23, yco + 12, zco + 53, Blocks.stained_hardened_clay, 4, 1);
      world.setBlock(xco + 24, yco + 12, zco + 53, Blocks.stained_hardened_clay, 4, 1);
      world.setBlock(xco + 28, yco + 12, zco + 53, Blocks.stained_hardened_clay, 4, 1);
      world.setBlock(xco + 29, yco + 12, zco + 53, Blocks.stained_hardened_clay, 4, 1);
      world.setBlock(xco + 35, yco + 12, zco + 53, Blocks.stained_hardened_clay, 4, 1);
      world.setBlock(xco + 36, yco + 12, zco + 53, Blocks.stained_hardened_clay, 4, 1);
      world.setBlock(xco + 16, yco + 12, zco + 54, Blocks.stained_hardened_clay, 4, 1);
      world.setBlock(xco + 17, yco + 12, zco + 54, Blocks.stained_hardened_clay, 4, 1);
      world.setBlock(xco + 23, yco + 12, zco + 54, Blocks.stained_hardened_clay, 4, 1);
      world.setBlock(xco + 24, yco + 12, zco + 54, Blocks.stained_hardened_clay, 4, 1);
      world.setBlock(xco + 25, yco + 12, zco + 54, Blocks.redstone_torch, 1, 1);
      world.setBlock(xco + 27, yco + 12, zco + 54, Blocks.redstone_torch, 2, 1);
      world.setBlock(xco + 28, yco + 12, zco + 54, Blocks.stained_hardened_clay, 4, 1);
      world.setBlock(xco + 29, yco + 12, zco + 54, Blocks.stained_hardened_clay, 4, 1);
      world.setBlock(xco + 35, yco + 12, zco + 54, Blocks.stained_hardened_clay, 4, 1);
      world.setBlock(xco + 36, yco + 12, zco + 54, Blocks.stained_hardened_clay, 4, 1);
      world.setBlock(xco + 16, yco + 12, zco + 55, Blocks.stained_hardened_clay, 4, 1);
      world.setBlock(xco + 17, yco + 12, zco + 55, Blocks.stained_hardened_clay, 4, 1);
      world.setBlock(xco + 23, yco + 12, zco + 55, Blocks.stained_hardened_clay, 4, 1);
      world.setBlock(xco + 24, yco + 12, zco + 55, Blocks.stained_hardened_clay, 4, 1);
      world.setBlock(xco + 28, yco + 12, zco + 55, Blocks.stained_hardened_clay, 4, 1);
      world.setBlock(xco + 29, yco + 12, zco + 55, Blocks.stained_hardened_clay, 4, 1);
      world.setBlock(xco + 35, yco + 12, zco + 55, Blocks.stained_hardened_clay, 4, 1);
      world.setBlock(xco + 36, yco + 12, zco + 55, Blocks.stained_hardened_clay, 4, 1);
      world.setBlock(xco + 37, yco + 12, zco + 55, Blocks.stained_hardened_clay, 4, 1);
      world.setBlock(xco + 17, yco + 12, zco + 56, Blocks.stained_hardened_clay, 4, 1);
      world.setBlock(xco + 18, yco + 12, zco + 56, Blocks.stained_hardened_clay, 4, 1);
      world.setBlock(xco + 22, yco + 12, zco + 56, Blocks.stained_hardened_clay, 4, 1);
      world.setBlock(xco + 23, yco + 12, zco + 56, Blocks.stained_hardened_clay, 4, 1);
      world.setBlock(xco + 24, yco + 12, zco + 56, Blocks.nether_brick_fence, 0, 1);
      world.setBlock(xco + 28, yco + 12, zco + 56, Blocks.nether_brick_fence, 0, 1);
      world.setBlock(xco + 29, yco + 12, zco + 56, Blocks.stained_hardened_clay, 4, 1);
      world.setBlock(xco + 30, yco + 12, zco + 56, Blocks.stained_hardened_clay, 4, 1);
      world.setBlock(xco + 34, yco + 12, zco + 56, Blocks.stained_hardened_clay, 4, 1);
      world.setBlock(xco + 35, yco + 12, zco + 56, Blocks.stained_hardened_clay, 4, 1);
      world.setBlock(xco + 38, yco + 12, zco + 56, Blocks.stained_hardened_clay, 4, 1);
      world.setBlock(xco + 39, yco + 12, zco + 56, Blocks.wool, 15, 1);
      world.setBlock(xco + 40, yco + 12, zco + 56, Blocks.wool, 15, 1);
      world.setBlock(xco + 18, yco + 12, zco + 57, Blocks.stained_hardened_clay, 4, 1);
      world.setBlock(xco + 19, yco + 12, zco + 57, Blocks.stained_hardened_clay, 4, 1);
      world.setBlock(xco + 20, yco + 12, zco + 57, Blocks.stained_hardened_clay, 4, 1);
      world.setBlock(xco + 21, yco + 12, zco + 57, Blocks.stained_hardened_clay, 4, 1);
      world.setBlock(xco + 22, yco + 12, zco + 57, Blocks.stained_hardened_clay, 4, 1);
      world.setBlock(xco + 24, yco + 12, zco + 57, Blocks.nether_brick_fence, 0, 1);
      world.setBlock(xco + 25, yco + 12, zco + 57, Blocks.nether_brick_stairs, 2, 1);
      world.setBlock(xco + 26, yco + 12, zco + 57, Blocks.nether_brick_stairs, 2, 1);
      world.setBlock(xco + 27, yco + 12, zco + 57, Blocks.nether_brick_stairs, 2, 1);
      world.setBlock(xco + 28, yco + 12, zco + 57, Blocks.nether_brick_fence, 0, 1);
      world.setBlock(xco + 29, yco + 12, zco + 57, Blocks.stone, 0, 1);
      world.setBlock(xco + 30, yco + 12, zco + 57, Blocks.stained_hardened_clay, 4, 1);
      world.setBlock(xco + 31, yco + 12, zco + 57, Blocks.stained_hardened_clay, 4, 1);
      world.setBlock(xco + 32, yco + 12, zco + 57, Blocks.stained_hardened_clay, 4, 1);
      world.setBlock(xco + 33, yco + 12, zco + 57, Blocks.stained_hardened_clay, 4, 1);
      world.setBlock(xco + 34, yco + 12, zco + 57, Blocks.stained_hardened_clay, 4, 1);
      world.setBlock(xco + 39, yco + 12, zco + 57, Blocks.stained_hardened_clay, 4, 1);
      world.setBlock(xco + 41, yco + 12, zco + 57, Blocks.wool, 15, 1);
      world.setBlock(xco + 19, yco + 12, zco + 58, Blocks.stained_hardened_clay, 4, 1);
      world.setBlock(xco + 20, yco + 12, zco + 58, Blocks.stained_hardened_clay, 4, 1);
      world.setBlock(xco + 21, yco + 12, zco + 58, Blocks.stained_hardened_clay, 4, 1);
      world.setBlock(xco + 24, yco + 12, zco + 58, Blocks.stone, 0, 1);
      world.setBlock(xco + 25, yco + 12, zco + 58, Blocks.stone, 0, 1);
      world.setBlock(xco + 26, yco + 12, zco + 58, Blocks.stone, 0, 1);
      world.setBlock(xco + 27, yco + 12, zco + 58, Blocks.stone, 0, 1);
      world.setBlock(xco + 28, yco + 12, zco + 58, Blocks.stone, 0, 1);
      world.setBlock(xco + 31, yco + 12, zco + 58, Blocks.stained_hardened_clay, 4, 1);
      world.setBlock(xco + 32, yco + 12, zco + 58, Blocks.stained_hardened_clay, 4, 1);
      world.setBlock(xco + 33, yco + 12, zco + 58, Blocks.stained_hardened_clay, 4, 1);
      world.setBlock(xco + 40, yco + 12, zco + 58, Blocks.stained_hardened_clay, 4, 1);
      world.setBlock(xco + 42, yco + 12, zco + 58, Blocks.wool, 15, 1);
      world.setBlock(xco + 23, yco + 12, zco + 59, Blocks.stone, 0, 1);
      world.setBlock(xco + 24, yco + 12, zco + 59, Blocks.stone, 0, 1);
      world.setBlock(xco + 25, yco + 12, zco + 59, Blocks.stone, 0, 1);
      world.setBlock(xco + 26, yco + 12, zco + 59, Blocks.stone, 0, 1);
      world.setBlock(xco + 27, yco + 12, zco + 59, Blocks.stone, 0, 1);
      world.setBlock(xco + 28, yco + 12, zco + 59, Blocks.stone, 0, 1);
      world.setBlock(xco + 34, yco + 12, zco + 59, Blocks.wool, 15, 1);
      world.setBlock(xco + 35, yco + 12, zco + 59, Blocks.wool, 15, 1);
      world.setBlock(xco + 36, yco + 12, zco + 59, Blocks.wool, 15, 1);
      world.setBlock(xco + 37, yco + 12, zco + 59, Blocks.wool, 15, 1);
      world.setBlock(xco + 41, yco + 12, zco + 59, Blocks.stained_hardened_clay, 4, 1);
      world.setBlock(xco + 42, yco + 12, zco + 59, Blocks.wool, 15, 1);
      world.setBlock(xco + 18, yco + 12, zco + 60, Blocks.stone, 0, 1);
      world.setBlock(xco + 19, yco + 12, zco + 60, Blocks.stone, 0, 1);
      world.setBlock(xco + 20, yco + 12, zco + 60, Blocks.stone, 0, 1);
      world.setBlock(xco + 21, yco + 12, zco + 60, Blocks.stone, 0, 1);
      world.setBlock(xco + 22, yco + 12, zco + 60, Blocks.stone, 0, 1);
      world.setBlock(xco + 23, yco + 12, zco + 60, Blocks.stone, 0, 1);
      world.setBlock(xco + 24, yco + 12, zco + 60, Blocks.stone, 0, 1);
      world.setBlock(xco + 25, yco + 12, zco + 60, Blocks.stone, 0, 1);
      world.setBlock(xco + 26, yco + 12, zco + 60, Blocks.stone, 0, 1);
      world.setBlock(xco + 27, yco + 12, zco + 60, Blocks.stone, 0, 1);
      world.setBlock(xco + 28, yco + 12, zco + 60, Blocks.stone, 0, 1);
      world.setBlock(xco + 33, yco + 12, zco + 60, Blocks.wool, 15, 1);
      world.setBlock(xco + 38, yco + 12, zco + 60, Blocks.wool, 15, 1);
      world.setBlock(xco + 42, yco + 12, zco + 60, Blocks.stone, 0, 1);
      world.setBlock(xco + 43, yco + 12, zco + 60, Blocks.stone, 0, 1);
      world.setBlock(xco + 44, yco + 12, zco + 60, Blocks.stone, 0, 1);
      world.setBlock(xco + 45, yco + 12, zco + 60, Blocks.stone, 0, 1);
      world.setBlock(xco + 18, yco + 12, zco + 61, Blocks.stone, 0, 1);
      world.setBlock(xco + 19, yco + 12, zco + 61, Blocks.netherrack, 0, 1);
      world.setBlock(xco + 20, yco + 12, zco + 61, Blocks.netherrack, 0, 1);
      world.setBlock(xco + 21, yco + 12, zco + 61, Blocks.stone, 0, 1);
      world.setBlock(xco + 22, yco + 12, zco + 61, Blocks.stone, 0, 1);
      world.setBlock(xco + 23, yco + 12, zco + 61, Blocks.stone, 0, 1);
      world.setBlock(xco + 24, yco + 12, zco + 61, Blocks.stone, 0, 1);
      world.setBlock(xco + 25, yco + 12, zco + 61, Blocks.stone, 0, 1);
      world.setBlock(xco + 26, yco + 12, zco + 61, Blocks.stone, 0, 1);
      world.setBlock(xco + 27, yco + 12, zco + 61, Blocks.stone, 0, 1);
      world.setBlock(xco + 28, yco + 12, zco + 61, Blocks.stone, 0, 1);
      world.setBlock(xco + 32, yco + 12, zco + 61, Blocks.wool, 15, 1);
      world.setBlock(xco + 39, yco + 12, zco + 61, Blocks.wool, 15, 1);
      world.setBlock(xco + 41, yco + 12, zco + 61, Blocks.stone, 0, 1);
      world.setBlock(xco + 46, yco + 12, zco + 61, Blocks.stone, 0, 1);
      world.setBlock(xco + 18, yco + 12, zco + 62, Blocks.stone, 0, 1);
      world.setBlock(xco + 19, yco + 12, zco + 62, Blocks.netherrack, 0, 1);
      world.setBlock(xco + 20, yco + 12, zco + 62, Blocks.netherrack, 0, 1);
      world.setBlock(xco + 21, yco + 12, zco + 62, Blocks.stone, 0, 1);
      world.setBlock(xco + 22, yco + 12, zco + 62, Blocks.stone, 0, 1);
      world.setBlock(xco + 23, yco + 12, zco + 62, Blocks.stone, 0, 1);
      world.setBlock(xco + 24, yco + 12, zco + 62, Blocks.stone, 0, 1);
      world.setBlock(xco + 25, yco + 12, zco + 62, Blocks.stone, 0, 1);
      world.setBlock(xco + 26, yco + 12, zco + 62, Blocks.stone, 0, 1);
      world.setBlock(xco + 27, yco + 12, zco + 62, Blocks.stone, 0, 1);
      world.setBlock(xco + 28, yco + 12, zco + 62, Blocks.stone, 0, 1);
      world.setBlock(xco + 32, yco + 12, zco + 62, Blocks.wool, 15, 1);
      world.setBlock(xco + 39, yco + 12, zco + 62, Blocks.wool, 15, 1);
      world.setBlock(xco + 40, yco + 12, zco + 62, Blocks.stone, 0, 1);
      world.setBlock(xco + 47, yco + 12, zco + 62, Blocks.stone, 0, 1);
      world.setBlock(xco + 18, yco + 12, zco + 63, Blocks.stone, 0, 1);
      world.setBlock(xco + 19, yco + 12, zco + 63, Blocks.netherrack, 0, 1);
      world.setBlock(xco + 20, yco + 12, zco + 63, Blocks.netherrack, 0, 1);
      world.setBlock(xco + 21, yco + 12, zco + 63, Blocks.stone, 0, 1);
      world.setBlock(xco + 22, yco + 12, zco + 63, Blocks.stone, 0, 1);
      world.setBlock(xco + 23, yco + 12, zco + 63, Blocks.stone, 0, 1);
      world.setBlock(xco + 24, yco + 12, zco + 63, Blocks.stone, 0, 1);
      world.setBlock(xco + 25, yco + 12, zco + 63, Blocks.stone, 0, 1);
      world.setBlock(xco + 26, yco + 12, zco + 63, Blocks.stone, 0, 1);
      world.setBlock(xco + 27, yco + 12, zco + 63, Blocks.stone, 0, 1);
      world.setBlock(xco + 28, yco + 12, zco + 63, Blocks.stone, 0, 1);
      world.setBlock(xco + 32, yco + 12, zco + 63, Blocks.wool, 15, 1);
      world.setBlock(xco + 39, yco + 12, zco + 63, Blocks.wool, 15, 1);
      world.setBlock(xco + 40, yco + 12, zco + 63, Blocks.stone, 0, 1);
      world.setBlock(xco + 47, yco + 12, zco + 63, Blocks.stone, 0, 1);
      world.setBlock(xco + 18, yco + 12, zco + 64, Blocks.stone, 0, 1);
      world.setBlock(xco + 19, yco + 12, zco + 64, Blocks.netherrack, 0, 1);
      world.setBlock(xco + 20, yco + 12, zco + 64, Blocks.netherrack, 0, 1);
      world.setBlock(xco + 21, yco + 12, zco + 64, Blocks.stone, 0, 1);
      world.setBlock(xco + 22, yco + 12, zco + 64, Blocks.stone, 0, 1);
      world.setBlock(xco + 23, yco + 12, zco + 64, Blocks.stone, 0, 1);
      world.setBlock(xco + 24, yco + 12, zco + 64, Blocks.stone, 0, 1);
      world.setBlock(xco + 25, yco + 12, zco + 64, Blocks.stone, 0, 1);
      world.setBlock(xco + 26, yco + 12, zco + 64, Blocks.stone, 0, 1);
      world.setBlock(xco + 27, yco + 12, zco + 64, Blocks.stone, 0, 1);
      world.setBlock(xco + 28, yco + 12, zco + 64, Blocks.stone, 0, 1);
      world.setBlock(xco + 32, yco + 12, zco + 64, Blocks.wool, 15, 1);
      world.setBlock(xco + 39, yco + 12, zco + 64, Blocks.wool, 15, 1);
      world.setBlock(xco + 40, yco + 12, zco + 64, Blocks.stone, 0, 1);
      world.setBlock(xco + 47, yco + 12, zco + 64, Blocks.stone, 0, 1);
      world.setBlock(xco + 18, yco + 12, zco + 65, Blocks.stone, 0, 1);
      world.setBlock(xco + 19, yco + 12, zco + 65, Blocks.stone, 0, 1);
      world.setBlock(xco + 20, yco + 12, zco + 65, Blocks.stone, 0, 1);
      world.setBlock(xco + 21, yco + 12, zco + 65, Blocks.stone, 0, 1);
      world.setBlock(xco + 22, yco + 12, zco + 65, Blocks.stone, 0, 1);
      world.setBlock(xco + 23, yco + 12, zco + 65, Blocks.stone, 0, 1);
      world.setBlock(xco + 24, yco + 12, zco + 65, Blocks.stone, 0, 1);
      world.setBlock(xco + 25, yco + 12, zco + 65, Blocks.stone, 0, 1);
      world.setBlock(xco + 26, yco + 12, zco + 65, Blocks.stone, 0, 1);
      world.setBlock(xco + 27, yco + 12, zco + 65, Blocks.stone, 0, 1);
      world.setBlock(xco + 28, yco + 12, zco + 65, Blocks.stone, 0, 1);
      world.setBlock(xco + 33, yco + 12, zco + 65, Blocks.wool, 15, 1);
      world.setBlock(xco + 38, yco + 12, zco + 65, Blocks.wool, 15, 1);
      world.setBlock(xco + 40, yco + 12, zco + 65, Blocks.stone, 0, 1);
      world.setBlock(xco + 47, yco + 12, zco + 65, Blocks.stone, 0, 1);
      world.setBlock(xco + 18, yco + 12, zco + 66, Blocks.stone, 0, 1);
      world.setBlock(xco + 19, yco + 12, zco + 66, Blocks.stone, 0, 1);
      world.setBlock(xco + 20, yco + 12, zco + 66, Blocks.stone, 0, 1);
      world.setBlock(xco + 21, yco + 12, zco + 66, Blocks.stone, 0, 1);
      world.setBlock(xco + 22, yco + 12, zco + 66, Blocks.stone, 0, 1);
      world.setBlock(xco + 23, yco + 12, zco + 66, Blocks.stone, 0, 1);
      world.setBlock(xco + 24, yco + 12, zco + 66, Blocks.stone, 0, 1);
      world.setBlock(xco + 25, yco + 12, zco + 66, Blocks.stone, 0, 1);
      world.setBlock(xco + 26, yco + 12, zco + 66, Blocks.stone, 0, 1);
      world.setBlock(xco + 27, yco + 12, zco + 66, Blocks.stone, 0, 1);
      world.setBlock(xco + 28, yco + 12, zco + 66, Blocks.stone, 0, 1);
      world.setBlock(xco + 34, yco + 12, zco + 66, Blocks.wool, 15, 1);
      world.setBlock(xco + 35, yco + 12, zco + 66, Blocks.wool, 15, 1);
      world.setBlock(xco + 36, yco + 12, zco + 66, Blocks.wool, 15, 1);
      world.setBlock(xco + 37, yco + 12, zco + 66, Blocks.wool, 15, 1);
      world.setBlock(xco + 41, yco + 12, zco + 66, Blocks.stone, 0, 1);
      world.setBlock(xco + 46, yco + 12, zco + 66, Blocks.stone, 0, 1);
      world.setBlock(xco + 42, yco + 12, zco + 67, Blocks.stone, 0, 1);
      world.setBlock(xco + 43, yco + 12, zco + 67, Blocks.stone, 0, 1);
      world.setBlock(xco + 44, yco + 12, zco + 67, Blocks.stone, 0, 1);
      world.setBlock(xco + 45, yco + 12, zco + 67, Blocks.stone, 0, 1);
      world.setBlock(xco + 24, yco + 13, zco + 36, Blocks.quartz_block, 0, 1);
      world.setBlock(xco + 25, yco + 13, zco + 36, Blocks.stained_hardened_clay, 10, 1);
      world.setBlock(xco + 27, yco + 13, zco + 36, Blocks.stained_hardened_clay, 10, 1);
      world.setBlock(xco + 28, yco + 13, zco + 36, Blocks.quartz_block, 0, 1);
      world.setBlock(xco + 16, yco + 13, zco + 37, Blocks.stained_hardened_clay, 4, 1);
      world.setBlock(xco + 17, yco + 13, zco + 37, Blocks.stained_hardened_clay, 4, 1);
      world.setBlock(xco + 21, yco + 13, zco + 37, Blocks.quartz_block, 0, 1);
      world.setBlock(xco + 22, yco + 13, zco + 37, Blocks.quartz_block, 0, 1);
      world.setBlock(xco + 23, yco + 13, zco + 37, Blocks.stained_hardened_clay, 4, 1);
      world.setBlock(xco + 29, yco + 13, zco + 37, Blocks.stained_hardened_clay, 4, 1);
      world.setBlock(xco + 35, yco + 13, zco + 37, Blocks.stained_hardened_clay, 4, 1);
      world.setBlock(xco + 36, yco + 13, zco + 37, Blocks.stained_hardened_clay, 4, 1);
      world.setBlock(xco + 16, yco + 13, zco + 38, Blocks.stained_hardened_clay, 4, 1);
      world.setBlock(xco + 17, yco + 13, zco + 38, Blocks.stained_hardened_clay, 4, 1);
      world.setBlock(xco + 18, yco + 13, zco + 38, Blocks.stained_hardened_clay, 7, 1);
      world.setBlock(xco + 19, yco + 13, zco + 38, Blocks.stained_hardened_clay, 7, 1);
      world.setBlock(xco + 20, yco + 13, zco + 38, Blocks.stained_hardened_clay, 7, 1);
      world.setBlock(xco + 21, yco + 13, zco + 38, Blocks.quartz_block, 0, 1);
      world.setBlock(xco + 22, yco + 13, zco + 38, Blocks.quartz_block, 0, 1);
      world.setBlock(xco + 30, yco + 13, zco + 38, Blocks.quartz_block, 0, 1);
      world.setBlock(xco + 31, yco + 13, zco + 38, Blocks.quartz_block, 0, 1);
      world.setBlock(xco + 32, yco + 13, zco + 38, Blocks.stained_hardened_clay, 7, 1);
      world.setBlock(xco + 33, yco + 13, zco + 38, Blocks.stained_hardened_clay, 7, 1);
      world.setBlock(xco + 34, yco + 13, zco + 38, Blocks.stained_hardened_clay, 7, 1);
      world.setBlock(xco + 35, yco + 13, zco + 38, Blocks.stained_hardened_clay, 4, 1);
      world.setBlock(xco + 36, yco + 13, zco + 38, Blocks.stained_hardened_clay, 4, 1);
      world.setBlock(xco + 16, yco + 13, zco + 39, Blocks.stained_hardened_clay, 4, 1);
      world.setBlock(xco + 20, yco + 13, zco + 39, Blocks.stained_hardened_clay, 4, 1);
      world.setBlock(xco + 21, yco + 13, zco + 39, Blocks.quartz_block, 0, 1);
      world.setBlock(xco + 22, yco + 13, zco + 39, Blocks.quartz_block, 0, 1);
      world.setBlock(xco + 30, yco + 13, zco + 39, Blocks.quartz_block, 0, 1);
      world.setBlock(xco + 31, yco + 13, zco + 39, Blocks.quartz_block, 0, 1);
      world.setBlock(xco + 32, yco + 13, zco + 39, Blocks.stained_hardened_clay, 4, 1);
      world.setBlock(xco + 36, yco + 13, zco + 39, Blocks.stained_hardened_clay, 4, 1);
      world.setBlock(xco + 5, yco + 13, zco + 40, Blocks.stone, 0, 1);
      world.setBlock(xco + 6, yco + 13, zco + 40, Blocks.stone, 0, 1);
      world.setBlock(xco + 7, yco + 13, zco + 40, Blocks.stone, 0, 1);
      world.setBlock(xco + 16, yco + 13, zco + 40, Blocks.stained_hardened_clay, 4, 1);
      world.setBlock(xco + 20, yco + 13, zco + 40, Blocks.stained_hardened_clay, 4, 1);
      world.setBlock(xco + 21, yco + 13, zco + 40, Blocks.quartz_block, 0, 1);
      world.setBlock(xco + 22, yco + 13, zco + 40, Blocks.quartz_block, 0, 1);
      world.setBlock(xco + 23, yco + 13, zco + 40, Blocks.lava, 10, 1);
      world.setBlock(xco + 29, yco + 13, zco + 40, Blocks.lava, 10, 1);
      world.setBlock(xco + 30, yco + 13, zco + 40, Blocks.quartz_block, 0, 1);
      world.setBlock(xco + 31, yco + 13, zco + 40, Blocks.quartz_block, 0, 1);
      world.setBlock(xco + 32, yco + 13, zco + 40, Blocks.stained_hardened_clay, 4, 1);
      world.setBlock(xco + 35, yco + 13, zco + 40, Blocks.stained_hardened_clay, 4, 1);
      world.setBlock(xco + 36, yco + 13, zco + 40, Blocks.stained_hardened_clay, 4, 1);
      world.setBlock(xco + 4, yco + 13, zco + 41, Blocks.stone, 0, 1);
      world.setBlock(xco + 8, yco + 13, zco + 41, Blocks.stone, 0, 1);
      world.setBlock(xco + 17, yco + 13, zco + 41, Blocks.quartz_block, 0, 1);
      world.setBlock(xco + 20, yco + 13, zco + 41, Blocks.quartz_block, 0, 1);
      world.setBlock(xco + 21, yco + 13, zco + 41, Blocks.quartz_block, 0, 1);
      world.setBlock(xco + 22, yco + 13, zco + 41, Blocks.quartz_block, 0, 1);
      world.setBlock(xco + 23, yco + 13, zco + 41, Blocks.stone, 0, 1);
      world.setBlock(xco + 24, yco + 13, zco + 41, Blocks.stone, 0, 1);
      world.setBlock(xco + 28, yco + 13, zco + 41, Blocks.stone, 0, 1);
      world.setBlock(xco + 29, yco + 13, zco + 41, Blocks.stone, 0, 1);
      world.setBlock(xco + 30, yco + 13, zco + 41, Blocks.quartz_block, 0, 1);
      world.setBlock(xco + 31, yco + 13, zco + 41, Blocks.quartz_block, 0, 1);
      world.setBlock(xco + 32, yco + 13, zco + 41, Blocks.quartz_block, 0, 1);
      world.setBlock(xco + 35, yco + 13, zco + 41, Blocks.quartz_block, 0, 1);
      world.setBlock(xco + 3, yco + 13, zco + 42, Blocks.stone, 0, 1);
      world.setBlock(xco + 9, yco + 13, zco + 42, Blocks.stone, 0, 1);
      world.setBlock(xco + 17, yco + 13, zco + 42, Blocks.quartz_block, 0, 1);
      world.setBlock(xco + 20, yco + 13, zco + 42, Blocks.quartz_block, 0, 1);
      world.setBlock(xco + 21, yco + 13, zco + 42, Blocks.quartz_block, 0, 1);
      world.setBlock(xco + 22, yco + 13, zco + 42, Blocks.quartz_block, 0, 1);
      world.setBlock(xco + 23, yco + 13, zco + 42, Blocks.stone, 0, 1);
      world.setBlock(xco + 24, yco + 13, zco + 42, Blocks.stone, 0, 1);
      world.setBlock(xco + 28, yco + 13, zco + 42, Blocks.stone, 0, 1);
      world.setBlock(xco + 29, yco + 13, zco + 42, Blocks.stone, 0, 1);
      world.setBlock(xco + 30, yco + 13, zco + 42, Blocks.quartz_block, 0, 1);
      world.setBlock(xco + 31, yco + 13, zco + 42, Blocks.quartz_block, 0, 1);
      world.setBlock(xco + 32, yco + 13, zco + 42, Blocks.quartz_block, 0, 1);
      world.setBlock(xco + 35, yco + 13, zco + 42, Blocks.quartz_block, 0, 1);
      world.setBlock(xco + 3, yco + 13, zco + 43, Blocks.stone, 0, 1);
      world.setBlock(xco + 9, yco + 13, zco + 43, Blocks.stone, 0, 1);
      world.setBlock(xco + 16, yco + 13, zco + 43, Blocks.stained_hardened_clay, 4, 1);
      world.setBlock(xco + 20, yco + 13, zco + 43, Blocks.stained_hardened_clay, 4, 1);
      world.setBlock(xco + 21, yco + 13, zco + 43, Blocks.quartz_block, 0, 1);
      world.setBlock(xco + 22, yco + 13, zco + 43, Blocks.quartz_block, 0, 1);
      world.setBlock(xco + 23, yco + 13, zco + 43, Blocks.lava, 10, 1);
      world.setBlock(xco + 29, yco + 13, zco + 43, Blocks.lava, 10, 1);
      world.setBlock(xco + 30, yco + 13, zco + 43, Blocks.quartz_block, 0, 1);
      world.setBlock(xco + 31, yco + 13, zco + 43, Blocks.quartz_block, 0, 1);
      world.setBlock(xco + 32, yco + 13, zco + 43, Blocks.stained_hardened_clay, 4, 1);
      world.setBlock(xco + 36, yco + 13, zco + 43, Blocks.stained_hardened_clay, 4, 1);
      world.setBlock(xco + 3, yco + 13, zco + 44, Blocks.stone, 0, 1);
      world.setBlock(xco + 9, yco + 13, zco + 44, Blocks.stone, 0, 1);
      world.setBlock(xco + 16, yco + 13, zco + 44, Blocks.stained_hardened_clay, 4, 1);
      world.setBlock(xco + 20, yco + 13, zco + 44, Blocks.stained_hardened_clay, 4, 1);
      world.setBlock(xco + 21, yco + 13, zco + 44, Blocks.quartz_block, 0, 1);
      world.setBlock(xco + 22, yco + 13, zco + 44, Blocks.quartz_block, 0, 1);
      world.setBlock(xco + 30, yco + 13, zco + 44, Blocks.quartz_block, 0, 1);
      world.setBlock(xco + 31, yco + 13, zco + 44, Blocks.quartz_block, 0, 1);
      world.setBlock(xco + 32, yco + 13, zco + 44, Blocks.stained_hardened_clay, 4, 1);
      world.setBlock(xco + 36, yco + 13, zco + 44, Blocks.stained_hardened_clay, 4, 1);
      world.setBlock(xco + 4, yco + 13, zco + 45, Blocks.stone, 0, 1);
      world.setBlock(xco + 8, yco + 13, zco + 45, Blocks.stone, 0, 1);
      world.setBlock(xco + 16, yco + 13, zco + 45, Blocks.stained_hardened_clay, 4, 1);
      world.setBlock(xco + 20, yco + 13, zco + 45, Blocks.stained_hardened_clay, 4, 1);
      world.setBlock(xco + 21, yco + 13, zco + 45, Blocks.quartz_block, 0, 1);
      world.setBlock(xco + 22, yco + 13, zco + 45, Blocks.quartz_block, 0, 1);
      world.setBlock(xco + 23, yco + 13, zco + 45, Blocks.lava, 10, 1);
      world.setBlock(xco + 29, yco + 13, zco + 45, Blocks.lava, 10, 1);
      world.setBlock(xco + 30, yco + 13, zco + 45, Blocks.quartz_block, 0, 1);
      world.setBlock(xco + 31, yco + 13, zco + 45, Blocks.quartz_block, 0, 1);
      world.setBlock(xco + 32, yco + 13, zco + 45, Blocks.stained_hardened_clay, 4, 1);
      world.setBlock(xco + 36, yco + 13, zco + 45, Blocks.stained_hardened_clay, 4, 1);
      world.setBlock(xco + 5, yco + 13, zco + 46, Blocks.stone, 0, 1);
      world.setBlock(xco + 6, yco + 13, zco + 46, Blocks.stone, 0, 1);
      world.setBlock(xco + 7, yco + 13, zco + 46, Blocks.stone, 0, 1);
      world.setBlock(xco + 17, yco + 13, zco + 46, Blocks.quartz_block, 0, 1);
      world.setBlock(xco + 18, yco + 13, zco + 46, Blocks.quartz_block, 0, 1);
      world.setBlock(xco + 19, yco + 13, zco + 46, Blocks.quartz_block, 0, 1);
      world.setBlock(xco + 20, yco + 13, zco + 46, Blocks.quartz_block, 0, 1);
      world.setBlock(xco + 21, yco + 13, zco + 46, Blocks.quartz_block, 0, 1);
      world.setBlock(xco + 22, yco + 13, zco + 46, Blocks.quartz_block, 0, 1);
      world.setBlock(xco + 23, yco + 13, zco + 46, Blocks.stone, 0, 1);
      world.setBlock(xco + 24, yco + 13, zco + 46, Blocks.stone, 0, 1);
      world.setBlock(xco + 28, yco + 13, zco + 46, Blocks.stone, 0, 1);
      world.setBlock(xco + 29, yco + 13, zco + 46, Blocks.stone, 0, 1);
      world.setBlock(xco + 30, yco + 13, zco + 46, Blocks.quartz_block, 0, 1);
      world.setBlock(xco + 31, yco + 13, zco + 46, Blocks.quartz_block, 0, 1);
      world.setBlock(xco + 32, yco + 13, zco + 46, Blocks.quartz_block, 0, 1);
      world.setBlock(xco + 35, yco + 13, zco + 46, Blocks.quartz_block, 0, 1);
      world.setBlock(xco + 17, yco + 13, zco + 47, Blocks.quartz_block, 0, 1);
      world.setBlock(xco + 18, yco + 13, zco + 47, Blocks.quartz_block, 0, 1);
      world.setBlock(xco + 19, yco + 13, zco + 47, Blocks.quartz_block, 0, 1);
      world.setBlock(xco + 20, yco + 13, zco + 47, Blocks.quartz_block, 0, 1);
      world.setBlock(xco + 21, yco + 13, zco + 47, Blocks.quartz_block, 0, 1);
      world.setBlock(xco + 22, yco + 13, zco + 47, Blocks.quartz_block, 0, 1);
      world.setBlock(xco + 23, yco + 13, zco + 47, Blocks.stone, 0, 1);
      world.setBlock(xco + 24, yco + 13, zco + 47, Blocks.stone, 0, 1);
      world.setBlock(xco + 28, yco + 13, zco + 47, Blocks.stone, 0, 1);
      world.setBlock(xco + 29, yco + 13, zco + 47, Blocks.stone, 0, 1);
      world.setBlock(xco + 30, yco + 13, zco + 47, Blocks.quartz_block, 0, 1);
      world.setBlock(xco + 31, yco + 13, zco + 47, Blocks.quartz_block, 0, 1);
      world.setBlock(xco + 32, yco + 13, zco + 47, Blocks.quartz_block, 0, 1);
      world.setBlock(xco + 35, yco + 13, zco + 47, Blocks.quartz_block, 0, 1);
      world.setBlock(xco + 16, yco + 13, zco + 48, Blocks.stained_hardened_clay, 4, 1);
      world.setBlock(xco + 20, yco + 13, zco + 48, Blocks.stained_hardened_clay, 4, 1);
      world.setBlock(xco + 21, yco + 13, zco + 48, Blocks.quartz_block, 0, 1);
      world.setBlock(xco + 22, yco + 13, zco + 48, Blocks.quartz_block, 0, 1);
      world.setBlock(xco + 23, yco + 13, zco + 48, Blocks.lava, 10, 1);
      world.setBlock(xco + 29, yco + 13, zco + 48, Blocks.lava, 10, 1);
      world.setBlock(xco + 30, yco + 13, zco + 48, Blocks.quartz_block, 0, 1);
      world.setBlock(xco + 31, yco + 13, zco + 48, Blocks.quartz_block, 0, 1);
      world.setBlock(xco + 32, yco + 13, zco + 48, Blocks.stained_hardened_clay, 4, 1);
      world.setBlock(xco + 36, yco + 13, zco + 48, Blocks.stained_hardened_clay, 4, 1);
      world.setBlock(xco + 16, yco + 13, zco + 49, Blocks.stained_hardened_clay, 4, 1);
      world.setBlock(xco + 20, yco + 13, zco + 49, Blocks.stained_hardened_clay, 4, 1);
      world.setBlock(xco + 21, yco + 13, zco + 49, Blocks.quartz_block, 0, 1);
      world.setBlock(xco + 22, yco + 13, zco + 49, Blocks.quartz_block, 0, 1);
      world.setBlock(xco + 30, yco + 13, zco + 49, Blocks.quartz_block, 0, 1);
      world.setBlock(xco + 31, yco + 13, zco + 49, Blocks.quartz_block, 0, 1);
      world.setBlock(xco + 32, yco + 13, zco + 49, Blocks.stained_hardened_clay, 4, 1);
      world.setBlock(xco + 36, yco + 13, zco + 49, Blocks.stained_hardened_clay, 4, 1);
      world.setBlock(xco + 16, yco + 13, zco + 50, Blocks.stained_hardened_clay, 4, 1);
      world.setBlock(xco + 17, yco + 13, zco + 50, Blocks.stained_hardened_clay, 4, 1);
      world.setBlock(xco + 18, yco + 13, zco + 50, Blocks.stained_hardened_clay, 4, 1);
      world.setBlock(xco + 19, yco + 13, zco + 50, Blocks.stained_hardened_clay, 4, 1);
      world.setBlock(xco + 20, yco + 13, zco + 50, Blocks.stained_hardened_clay, 4, 1);
      world.setBlock(xco + 21, yco + 13, zco + 50, Blocks.quartz_block, 0, 1);
      world.setBlock(xco + 22, yco + 13, zco + 50, Blocks.quartz_block, 0, 1);
      world.setBlock(xco + 30, yco + 13, zco + 50, Blocks.quartz_block, 0, 1);
      world.setBlock(xco + 31, yco + 13, zco + 50, Blocks.quartz_block, 0, 1);
      world.setBlock(xco + 32, yco + 13, zco + 50, Blocks.stained_hardened_clay, 4, 1);
      world.setBlock(xco + 33, yco + 13, zco + 50, Blocks.stained_hardened_clay, 4, 1);
      world.setBlock(xco + 34, yco + 13, zco + 50, Blocks.stained_hardened_clay, 4, 1);
      world.setBlock(xco + 35, yco + 13, zco + 50, Blocks.stained_hardened_clay, 4, 1);
      world.setBlock(xco + 36, yco + 13, zco + 50, Blocks.stained_hardened_clay, 4, 1);
      world.setBlock(xco + 18, yco + 13, zco + 51, Blocks.stained_hardened_clay, 4, 1);
      world.setBlock(xco + 19, yco + 13, zco + 51, Blocks.stained_hardened_clay, 4, 1);
      world.setBlock(xco + 20, yco + 13, zco + 51, Blocks.stained_hardened_clay, 4, 1);
      world.setBlock(xco + 21, yco + 13, zco + 51, Blocks.stained_hardened_clay, 4, 1);
      world.setBlock(xco + 30, yco + 13, zco + 51, Blocks.stained_hardened_clay, 4, 1);
      world.setBlock(xco + 31, yco + 13, zco + 51, Blocks.stained_hardened_clay, 4, 1);
      world.setBlock(xco + 32, yco + 13, zco + 51, Blocks.stained_hardened_clay, 4, 1);
      world.setBlock(xco + 33, yco + 13, zco + 51, Blocks.stained_hardened_clay, 4, 1);
      world.setBlock(xco + 34, yco + 13, zco + 51, Blocks.stained_hardened_clay, 4, 1);
      world.setBlock(xco + 17, yco + 13, zco + 52, Blocks.stained_hardened_clay, 4, 1);
      world.setBlock(xco + 18, yco + 13, zco + 52, Blocks.stained_hardened_clay, 4, 1);
      world.setBlock(xco + 22, yco + 13, zco + 52, Blocks.stained_hardened_clay, 4, 1);
      world.setBlock(xco + 29, yco + 13, zco + 52, Blocks.stained_hardened_clay, 4, 1);
      world.setBlock(xco + 30, yco + 13, zco + 52, Blocks.stained_hardened_clay, 4, 1);
      world.setBlock(xco + 34, yco + 13, zco + 52, Blocks.stained_hardened_clay, 4, 1);
      world.setBlock(xco + 35, yco + 13, zco + 52, Blocks.stained_hardened_clay, 4, 1);
      world.setBlock(xco + 16, yco + 13, zco + 53, Blocks.stained_hardened_clay, 4, 1);
      world.setBlock(xco + 17, yco + 13, zco + 53, Blocks.stained_hardened_clay, 4, 1);
      world.setBlock(xco + 23, yco + 13, zco + 53, Blocks.stained_hardened_clay, 4, 1);
      world.setBlock(xco + 24, yco + 13, zco + 53, Blocks.stained_hardened_clay, 4, 1);
      world.setBlock(xco + 28, yco + 13, zco + 53, Blocks.stained_hardened_clay, 4, 1);
      world.setBlock(xco + 29, yco + 13, zco + 53, Blocks.stained_hardened_clay, 4, 1);
      world.setBlock(xco + 35, yco + 13, zco + 53, Blocks.stained_hardened_clay, 4, 1);
      world.setBlock(xco + 36, yco + 13, zco + 53, Blocks.stained_hardened_clay, 4, 1);
      world.setBlock(xco + 16, yco + 13, zco + 54, Blocks.stained_hardened_clay, 4, 1);
      world.setBlock(xco + 17, yco + 13, zco + 54, Blocks.stained_hardened_clay, 4, 1);
      world.setBlock(xco + 23, yco + 13, zco + 54, Blocks.stained_hardened_clay, 4, 1);
      world.setBlock(xco + 24, yco + 13, zco + 54, Blocks.stained_hardened_clay, 4, 1);
      world.setBlock(xco + 28, yco + 13, zco + 54, Blocks.stained_hardened_clay, 4, 1);
      world.setBlock(xco + 29, yco + 13, zco + 54, Blocks.stained_hardened_clay, 4, 1);
      world.setBlock(xco + 35, yco + 13, zco + 54, Blocks.stained_hardened_clay, 4, 1);
      world.setBlock(xco + 36, yco + 13, zco + 54, Blocks.stained_hardened_clay, 4, 1);
      world.setBlock(xco + 16, yco + 13, zco + 55, Blocks.stained_hardened_clay, 4, 1);
      world.setBlock(xco + 17, yco + 13, zco + 55, Blocks.stained_hardened_clay, 4, 1);
      world.setBlock(xco + 23, yco + 13, zco + 55, Blocks.stained_hardened_clay, 4, 1);
      world.setBlock(xco + 24, yco + 13, zco + 55, Blocks.stained_hardened_clay, 4, 1);
      world.setBlock(xco + 25, yco + 13, zco + 55, Blocks.redstone_torch, 1, 1);
      world.setBlock(xco + 27, yco + 13, zco + 55, Blocks.redstone_torch, 2, 1);
      world.setBlock(xco + 28, yco + 13, zco + 55, Blocks.stained_hardened_clay, 4, 1);
      world.setBlock(xco + 29, yco + 13, zco + 55, Blocks.stained_hardened_clay, 4, 1);
      world.setBlock(xco + 35, yco + 13, zco + 55, Blocks.stained_hardened_clay, 4, 1);
      world.setBlock(xco + 36, yco + 13, zco + 55, Blocks.stained_hardened_clay, 4, 1);
      world.setBlock(xco + 37, yco + 13, zco + 55, Blocks.stained_hardened_clay, 4, 1);
      world.setBlock(xco + 17, yco + 13, zco + 56, Blocks.stained_hardened_clay, 4, 1);
      world.setBlock(xco + 18, yco + 13, zco + 56, Blocks.stained_hardened_clay, 4, 1);
      world.setBlock(xco + 22, yco + 13, zco + 56, Blocks.stained_hardened_clay, 4, 1);
      world.setBlock(xco + 23, yco + 13, zco + 56, Blocks.stained_hardened_clay, 4, 1);
      world.setBlock(xco + 24, yco + 13, zco + 56, Blocks.nether_brick_fence, 0, 1);
      world.setBlock(xco + 28, yco + 13, zco + 56, Blocks.nether_brick_fence, 0, 1);
      world.setBlock(xco + 29, yco + 13, zco + 56, Blocks.stained_hardened_clay, 4, 1);
      world.setBlock(xco + 30, yco + 13, zco + 56, Blocks.stained_hardened_clay, 4, 1);
      world.setBlock(xco + 34, yco + 13, zco + 56, Blocks.stained_hardened_clay, 4, 1);
      world.setBlock(xco + 35, yco + 13, zco + 56, Blocks.stained_hardened_clay, 4, 1);
      world.setBlock(xco + 38, yco + 13, zco + 56, Blocks.stained_hardened_clay, 4, 1);
      world.setBlock(xco + 39, yco + 13, zco + 56, Blocks.wool, 15, 1);
      world.setBlock(xco + 40, yco + 13, zco + 56, Blocks.wool, 15, 1);
      world.setBlock(xco + 18, yco + 13, zco + 57, Blocks.stained_hardened_clay, 4, 1);
      world.setBlock(xco + 19, yco + 13, zco + 57, Blocks.stained_hardened_clay, 4, 1);
      world.setBlock(xco + 20, yco + 13, zco + 57, Blocks.stained_hardened_clay, 4, 1);
      world.setBlock(xco + 21, yco + 13, zco + 57, Blocks.stained_hardened_clay, 4, 1);
      world.setBlock(xco + 22, yco + 13, zco + 57, Blocks.stained_hardened_clay, 4, 1);
      world.setBlock(xco + 23, yco + 13, zco + 57, Blocks.stone, 0, 1);
      world.setBlock(xco + 24, yco + 13, zco + 57, Blocks.nether_brick_fence, 0, 1);
      world.setBlock(xco + 28, yco + 13, zco + 57, Blocks.nether_brick_fence, 0, 1);
      world.setBlock(xco + 29, yco + 13, zco + 57, Blocks.stone, 0, 1);
      world.setBlock(xco + 30, yco + 13, zco + 57, Blocks.stained_hardened_clay, 4, 1);
      world.setBlock(xco + 31, yco + 13, zco + 57, Blocks.stained_hardened_clay, 4, 1);
      world.setBlock(xco + 32, yco + 13, zco + 57, Blocks.stained_hardened_clay, 4, 1);
      world.setBlock(xco + 33, yco + 13, zco + 57, Blocks.stained_hardened_clay, 4, 1);
      world.setBlock(xco + 34, yco + 13, zco + 57, Blocks.stained_hardened_clay, 4, 1);
      world.setBlock(xco + 39, yco + 13, zco + 57, Blocks.stained_hardened_clay, 4, 1);
      world.setBlock(xco + 41, yco + 13, zco + 57, Blocks.wool, 15, 1);
      world.setBlock(xco + 19, yco + 13, zco + 58, Blocks.stained_hardened_clay, 4, 1);
      world.setBlock(xco + 20, yco + 13, zco + 58, Blocks.stained_hardened_clay, 4, 1);
      world.setBlock(xco + 21, yco + 13, zco + 58, Blocks.stained_hardened_clay, 4, 1);
      world.setBlock(xco + 23, yco + 13, zco + 58, Blocks.stone, 0, 1);
      world.setBlock(xco + 29, yco + 13, zco + 58, Blocks.stone, 0, 1);
      world.setBlock(xco + 31, yco + 13, zco + 58, Blocks.stained_hardened_clay, 4, 1);
      world.setBlock(xco + 32, yco + 13, zco + 58, Blocks.stained_hardened_clay, 4, 1);
      world.setBlock(xco + 33, yco + 13, zco + 58, Blocks.stained_hardened_clay, 4, 1);
      world.setBlock(xco + 40, yco + 13, zco + 58, Blocks.stained_hardened_clay, 4, 1);
      world.setBlock(xco + 42, yco + 13, zco + 58, Blocks.wool, 15, 1);
      world.setBlock(xco + 21, yco + 13, zco + 59, Blocks.stone, 0, 1);
      world.setBlock(xco + 22, yco + 13, zco + 59, Blocks.stone, 0, 1);
      world.setBlock(xco + 29, yco + 13, zco + 59, Blocks.stone, 0, 1);
      world.setBlock(xco + 34, yco + 13, zco + 59, Blocks.wool, 15, 1);
      world.setBlock(xco + 35, yco + 13, zco + 59, Blocks.wool, 15, 1);
      world.setBlock(xco + 36, yco + 13, zco + 59, Blocks.wool, 15, 1);
      world.setBlock(xco + 37, yco + 13, zco + 59, Blocks.wool, 15, 1);
      world.setBlock(xco + 41, yco + 13, zco + 59, Blocks.stained_hardened_clay, 4, 1);
      world.setBlock(xco + 42, yco + 13, zco + 59, Blocks.wool, 15, 1);
      world.setBlock(xco + 18, yco + 13, zco + 60, Blocks.stone, 0, 1);
      world.setBlock(xco + 19, yco + 13, zco + 60, Blocks.stone, 0, 1);
      world.setBlock(xco + 20, yco + 13, zco + 60, Blocks.stone, 0, 1);
      world.setBlock(xco + 29, yco + 13, zco + 60, Blocks.stone, 0, 1);
      world.setBlock(xco + 33, yco + 13, zco + 60, Blocks.wool, 15, 1);
      world.setBlock(xco + 38, yco + 13, zco + 60, Blocks.wool, 15, 1);
      world.setBlock(xco + 42, yco + 13, zco + 60, Blocks.stone, 0, 1);
      world.setBlock(xco + 43, yco + 13, zco + 60, Blocks.stone, 0, 1);
      world.setBlock(xco + 44, yco + 13, zco + 60, Blocks.stone, 0, 1);
      world.setBlock(xco + 45, yco + 13, zco + 60, Blocks.stone, 0, 1);
      world.setBlock(xco + 18, yco + 13, zco + 61, Blocks.obsidian, 0, 1);
      world.setBlock(xco + 19, yco + 13, zco + 61, Blocks.fire, 15, 1);
      world.setBlock(xco + 20, yco + 13, zco + 61, Blocks.fire, 15, 1);
      world.setBlock(xco + 21, yco + 13, zco + 61, Blocks.stone, 0, 1);
      world.setBlock(xco + 29, yco + 13, zco + 61, Blocks.stone, 0, 1);
      world.setBlock(xco + 32, yco + 13, zco + 61, Blocks.wool, 15, 1);
      world.setBlock(xco + 39, yco + 13, zco + 61, Blocks.wool, 15, 1);
      world.setBlock(xco + 41, yco + 13, zco + 61, Blocks.stone, 0, 1);
      world.setBlock(xco + 46, yco + 13, zco + 61, Blocks.stone, 0, 1);
      world.setBlock(xco + 18, yco + 13, zco + 62, Blocks.obsidian, 0, 1);
      world.setBlock(xco + 19, yco + 13, zco + 62, Blocks.fire, 15, 1);
      world.setBlock(xco + 20, yco + 13, zco + 62, Blocks.fire, 15, 1);
      world.setBlock(xco + 21, yco + 13, zco + 62, Blocks.iron_bars, 0, 1);
      world.setBlock(xco + 29, yco + 13, zco + 62, Blocks.stone, 0, 1);
      world.setBlock(xco + 32, yco + 13, zco + 62, Blocks.wool, 15, 1);
      world.setBlock(xco + 39, yco + 13, zco + 62, Blocks.wool, 15, 1);
      world.setBlock(xco + 40, yco + 13, zco + 62, Blocks.stone, 0, 1);
      world.setBlock(xco + 47, yco + 13, zco + 62, Blocks.stone, 0, 1);
      world.setBlock(xco + 18, yco + 13, zco + 63, Blocks.obsidian, 0, 1);
      world.setBlock(xco + 19, yco + 13, zco + 63, Blocks.fire, 15, 1);
      world.setBlock(xco + 20, yco + 13, zco + 63, Blocks.fire, 15, 1);
      world.setBlock(xco + 21, yco + 13, zco + 63, Blocks.iron_bars, 0, 1);
      world.setBlock(xco + 23, yco + 13, zco + 63, Blocks.iron_bars, 0, 1);
      world.setBlock(xco + 24, yco + 13, zco + 63, Blocks.iron_bars, 0, 1);
      world.setBlock(xco + 25, yco + 13, zco + 63, Blocks.iron_bars, 0, 1);
      world.setBlock(xco + 26, yco + 13, zco + 63, Blocks.iron_bars, 0, 1);
      world.setBlock(xco + 27, yco + 13, zco + 63, Blocks.iron_bars, 0, 1);
      world.setBlock(xco + 28, yco + 13, zco + 63, Blocks.iron_bars, 0, 1);
      world.setBlock(xco + 29, yco + 13, zco + 63, Blocks.stone, 0, 1);
      world.setBlock(xco + 32, yco + 13, zco + 63, Blocks.wool, 15, 1);
      world.setBlock(xco + 39, yco + 13, zco + 63, Blocks.wool, 15, 1);
      world.setBlock(xco + 40, yco + 13, zco + 63, Blocks.stone, 0, 1);
      world.setBlock(xco + 47, yco + 13, zco + 63, Blocks.stone, 0, 1);
      world.setBlock(xco + 18, yco + 13, zco + 64, Blocks.obsidian, 0, 1);
      world.setBlock(xco + 19, yco + 13, zco + 64, Blocks.fire, 15, 1);
      world.setBlock(xco + 20, yco + 13, zco + 64, Blocks.fire, 15, 1);
      world.setBlock(xco + 21, yco + 13, zco + 64, Blocks.stone, 0, 1);
      world.setBlock(xco + 23, yco + 13, zco + 64, Blocks.iron_bars, 0, 1);
      world.setBlock(xco + 29, yco + 13, zco + 64, Blocks.stone, 0, 1);
      world.setBlock(xco + 32, yco + 13, zco + 64, Blocks.wool, 15, 1);
      world.setBlock(xco + 39, yco + 13, zco + 64, Blocks.wool, 15, 1);
      world.setBlock(xco + 40, yco + 13, zco + 64, Blocks.stone, 0, 1);
      world.setBlock(xco + 47, yco + 13, zco + 64, Blocks.stone, 0, 1);
      world.setBlock(xco + 18, yco + 13, zco + 65, Blocks.obsidian, 0, 1);
      world.setBlock(xco + 19, yco + 13, zco + 65, Blocks.obsidian, 0, 1);
      world.setBlock(xco + 20, yco + 13, zco + 65, Blocks.stone, 0, 1);
      world.setBlock(xco + 21, yco + 13, zco + 65, Blocks.stone, 0, 1);
      world.setBlock(xco + 23, yco + 13, zco + 65, Blocks.iron_bars, 0, 1);
      world.setBlock(xco + 29, yco + 13, zco + 65, Blocks.stone, 0, 1);
      world.setBlock(xco + 33, yco + 13, zco + 65, Blocks.wool, 15, 1);
      world.setBlock(xco + 38, yco + 13, zco + 65, Blocks.wool, 15, 1);
      world.setBlock(xco + 40, yco + 13, zco + 65, Blocks.stone, 0, 1);
      world.setBlock(xco + 47, yco + 13, zco + 65, Blocks.stone, 0, 1);
      world.setBlock(xco + 18, yco + 13, zco + 66, Blocks.stone, 0, 1);
      world.setBlock(xco + 19, yco + 13, zco + 66, Blocks.stone, 0, 1);
      world.setBlock(xco + 20, yco + 13, zco + 66, Blocks.stone, 0, 1);
      world.setBlock(xco + 23, yco + 13, zco + 66, Blocks.iron_bars, 0, 1);
      world.setBlock(xco + 29, yco + 13, zco + 66, Blocks.stone, 0, 1);
      world.setBlock(xco + 34, yco + 13, zco + 66, Blocks.wool, 15, 1);
      world.setBlock(xco + 35, yco + 13, zco + 66, Blocks.wool, 15, 1);
      world.setBlock(xco + 36, yco + 13, zco + 66, Blocks.wool, 15, 1);
      world.setBlock(xco + 37, yco + 13, zco + 66, Blocks.wool, 15, 1);
      world.setBlock(xco + 41, yco + 13, zco + 66, Blocks.stone, 0, 1);
      world.setBlock(xco + 46, yco + 13, zco + 66, Blocks.stone, 0, 1);
      world.setBlock(xco + 20, yco + 13, zco + 67, Blocks.stone, 0, 1);
      world.setBlock(xco + 21, yco + 13, zco + 67, Blocks.stone, 0, 1);
      world.setBlock(xco + 22, yco + 13, zco + 67, Blocks.stone, 0, 1);
      world.setBlock(xco + 23, yco + 13, zco + 67, Blocks.stone, 0, 1);
      world.setBlock(xco + 24, yco + 13, zco + 67, Blocks.stone, 0, 1);
      world.setBlock(xco + 25, yco + 13, zco + 67, Blocks.stone, 0, 1);
      world.setBlock(xco + 26, yco + 13, zco + 67, Blocks.stone, 0, 1);
      world.setBlock(xco + 27, yco + 13, zco + 67, Blocks.stone, 0, 1);
      world.setBlock(xco + 28, yco + 13, zco + 67, Blocks.stone, 0, 1);
      world.setBlock(xco + 42, yco + 13, zco + 67, Blocks.stone, 0, 1);
      world.setBlock(xco + 43, yco + 13, zco + 67, Blocks.stone, 0, 1);
      world.setBlock(xco + 44, yco + 13, zco + 67, Blocks.stone, 0, 1);
      world.setBlock(xco + 45, yco + 13, zco + 67, Blocks.stone, 0, 1);
      world.setBlock(xco + 24, yco + 14, zco + 36, Blocks.quartz_block, 0, 1);
      world.setBlock(xco + 25, yco + 14, zco + 36, Blocks.stained_hardened_clay, 10, 1);
      world.setBlock(xco + 27, yco + 14, zco + 36, Blocks.stained_hardened_clay, 10, 1);
      world.setBlock(xco + 28, yco + 14, zco + 36, Blocks.quartz_block, 0, 1);
      world.setBlock(xco + 16, yco + 14, zco + 37, Blocks.stained_hardened_clay, 4, 1);
      world.setBlock(xco + 17, yco + 14, zco + 37, Blocks.stained_hardened_clay, 4, 1);
      world.setBlock(xco + 21, yco + 14, zco + 37, Blocks.quartz_block, 0, 1);
      world.setBlock(xco + 22, yco + 14, zco + 37, Blocks.quartz_block, 0, 1);
      world.setBlock(xco + 23, yco + 14, zco + 37, Blocks.stained_hardened_clay, 4, 1);
      world.setBlock(xco + 29, yco + 14, zco + 37, Blocks.stained_hardened_clay, 4, 1);
      world.setBlock(xco + 35, yco + 14, zco + 37, Blocks.stained_hardened_clay, 4, 1);
      world.setBlock(xco + 36, yco + 14, zco + 37, Blocks.stained_hardened_clay, 4, 1);
      world.setBlock(xco + 16, yco + 14, zco + 38, Blocks.stained_hardened_clay, 4, 1);
      world.setBlock(xco + 17, yco + 14, zco + 38, Blocks.stained_hardened_clay, 4, 1);
      world.setBlock(xco + 18, yco + 14, zco + 38, Blocks.stained_hardened_clay, 7, 1);
      world.setBlock(xco + 19, yco + 14, zco + 38, Blocks.stained_hardened_clay, 7, 1);
      world.setBlock(xco + 20, yco + 14, zco + 38, Blocks.stained_hardened_clay, 7, 1);
      world.setBlock(xco + 21, yco + 14, zco + 38, Blocks.quartz_block, 0, 1);
      world.setBlock(xco + 22, yco + 14, zco + 38, Blocks.quartz_block, 0, 1);
      world.setBlock(xco + 30, yco + 14, zco + 38, Blocks.quartz_block, 0, 1);
      world.setBlock(xco + 31, yco + 14, zco + 38, Blocks.quartz_block, 0, 1);
      world.setBlock(xco + 32, yco + 14, zco + 38, Blocks.stained_hardened_clay, 7, 1);
      world.setBlock(xco + 33, yco + 14, zco + 38, Blocks.stained_hardened_clay, 7, 1);
      world.setBlock(xco + 34, yco + 14, zco + 38, Blocks.stained_hardened_clay, 7, 1);
      world.setBlock(xco + 35, yco + 14, zco + 38, Blocks.stained_hardened_clay, 4, 1);
      world.setBlock(xco + 36, yco + 14, zco + 38, Blocks.stained_hardened_clay, 4, 1);
      world.setBlock(xco + 4, yco + 14, zco + 39, Blocks.stone, 0, 1);
      world.setBlock(xco + 5, yco + 14, zco + 39, Blocks.stone, 0, 1);
      world.setBlock(xco + 6, yco + 14, zco + 39, Blocks.stone, 0, 1);
      world.setBlock(xco + 7, yco + 14, zco + 39, Blocks.stone, 0, 1);
      world.setBlock(xco + 8, yco + 14, zco + 39, Blocks.stone, 0, 1);
      world.setBlock(xco + 16, yco + 14, zco + 39, Blocks.stained_hardened_clay, 4, 1);
      world.setBlock(xco + 20, yco + 14, zco + 39, Blocks.stained_hardened_clay, 4, 1);
      world.setBlock(xco + 21, yco + 14, zco + 39, Blocks.quartz_block, 0, 1);
      world.setBlock(xco + 22, yco + 14, zco + 39, Blocks.quartz_block, 0, 1);
      world.setBlock(xco + 30, yco + 14, zco + 39, Blocks.quartz_block, 0, 1);
      world.setBlock(xco + 31, yco + 14, zco + 39, Blocks.quartz_block, 0, 1);
      world.setBlock(xco + 32, yco + 14, zco + 39, Blocks.stained_hardened_clay, 4, 1);
      world.setBlock(xco + 36, yco + 14, zco + 39, Blocks.stained_hardened_clay, 4, 1);
      world.setBlock(xco + 3, yco + 14, zco + 40, Blocks.stone, 0, 1);
      world.setBlock(xco + 4, yco + 14, zco + 40, Blocks.stone, 0, 1);
      world.setBlock(xco + 8, yco + 14, zco + 40, Blocks.stone, 0, 1);
      world.setBlock(xco + 9, yco + 14, zco + 40, Blocks.stone, 0, 1);
      world.setBlock(xco + 16, yco + 14, zco + 40, Blocks.stained_hardened_clay, 4, 1);
      world.setBlock(xco + 20, yco + 14, zco + 40, Blocks.stained_hardened_clay, 4, 1);
return true;
  }
}
