package com.slugterra.world.greatForge;
import java.util.Random;

import net.minecraft.block.BlockColored;
import net.minecraft.block.BlockStairs;
import net.minecraft.block.BlockStone;
import net.minecraft.init.Blocks;
import net.minecraft.util.math.BlockPos;
import net.minecraft.world.World;
public class GreatWesternForgeStructure10 {
public boolean generate(World world, Random par2Random, BlockPos pos) {
      world.setBlockState(pos.add(25, 16, 65), Blocks.STONE.getDefaultState());
      world.setBlockState(pos.add(26, 16, 65), Blocks.STONE.getDefaultState());
      world.setBlockState(pos.add(27, 16, 65), Blocks.STONE.getDefaultState());
      world.setBlockState(pos.add(28, 16, 65), Blocks.STONE.getDefaultState());
      world.setBlockState(pos.add(33, 16, 65), Blocks.REDSTONE_BLOCK.getDefaultState());
      world.setBlockState(pos.add(38, 16, 65), Blocks.REDSTONE_BLOCK.getDefaultState());
      world.setBlockState(pos.add(40, 16, 65), Blocks.STONE.getDefaultState());
      world.setBlockState(pos.add(47, 16, 65), Blocks.STONE.getDefaultState());
      world.setBlockState(pos.add(19, 16, 66), Blocks.STONE.getDefaultState());
      world.setBlockState(pos.add(20, 16, 66), Blocks.STONE.getDefaultState());
      world.setBlockState(pos.add(21, 16, 66), Blocks.STONE.getDefaultState());
      world.setBlockState(pos.add(22, 16, 66), Blocks.STONE.getDefaultState());
      world.setBlockState(pos.add(23, 16, 66), Blocks.STONE.getDefaultState());
      world.setBlockState(pos.add(24, 16, 66), Blocks.STONE.getDefaultState());
      world.setBlockState(pos.add(25, 16, 66), Blocks.STONE.getDefaultState());
      world.setBlockState(pos.add(26, 16, 66), Blocks.STONE.getDefaultState());
      world.setBlockState(pos.add(27, 16, 66), Blocks.STONE.getDefaultState());
      world.setBlockState(pos.add(28, 16, 66), Blocks.STONE.getDefaultState());
      world.setBlockState(pos.add(34, 16, 66), Blocks.REDSTONE_BLOCK.getDefaultState());
      world.setBlockState(pos.add(35, 16, 66), Blocks.REDSTONE_BLOCK.getDefaultState());
      world.setBlockState(pos.add(36, 16, 66), Blocks.REDSTONE_BLOCK.getDefaultState());
      world.setBlockState(pos.add(37, 16, 66), Blocks.REDSTONE_BLOCK.getDefaultState());
      world.setBlockState(pos.add(41, 16, 66), Blocks.STONE.getDefaultState());
      world.setBlockState(pos.add(46, 16, 66), Blocks.STONE.getDefaultState());
      world.setBlockState(pos.add(42, 16, 67), Blocks.STONE.getDefaultState());
      world.setBlockState(pos.add(43, 16, 67), Blocks.STONE.getDefaultState());
      world.setBlockState(pos.add(44, 16, 67), Blocks.STONE.getDefaultState());
      world.setBlockState(pos.add(45, 16, 67), Blocks.STONE.getDefaultState());
      world.setBlockState(pos.add(26, 17, 36), Blocks.QUARTZ_BLOCK.getDefaultState());
      world.setBlockState(pos.add(17, 17, 37), ((BlockColored)Blocks.STAINED_HARDENED_CLAY).getStateFromMeta(4));
      world.setBlockState(pos.add(18, 17, 37), ((BlockColored)Blocks.STAINED_HARDENED_CLAY).getStateFromMeta(4));
      world.setBlockState(pos.add(22, 17, 37), Blocks.QUARTZ_STAIRS.getDefaultState());
      world.setBlockState(pos.add(23, 17, 37), ((BlockColored)Blocks.STAINED_HARDENED_CLAY).getStateFromMeta(4));
      world.setBlockState(pos.add(24, 17, 37), ((BlockColored)Blocks.STAINED_HARDENED_CLAY).getStateFromMeta(4));
      world.setBlockState(pos.add(25, 17, 37), Blocks.QUARTZ_BLOCK.getDefaultState());
      world.setBlockState(pos.add(27, 17, 37), Blocks.QUARTZ_BLOCK.getDefaultState());
      world.setBlockState(pos.add(28, 17, 37), ((BlockColored)Blocks.STAINED_HARDENED_CLAY).getStateFromMeta(4));
      world.setBlockState(pos.add(29, 17, 37), ((BlockColored)Blocks.STAINED_HARDENED_CLAY).getStateFromMeta(4));
      world.setBlockState(pos.add(34, 17, 37), ((BlockColored)Blocks.STAINED_HARDENED_CLAY).getStateFromMeta(4));
      world.setBlockState(pos.add(35, 17, 37), ((BlockColored)Blocks.STAINED_HARDENED_CLAY).getStateFromMeta(4));
      world.setBlockState(pos.add(17, 17, 38), ((BlockColored)Blocks.STAINED_HARDENED_CLAY).getStateFromMeta(4));
      world.setBlockState(pos.add(18, 17, 38), ((BlockColored)Blocks.STAINED_HARDENED_CLAY).getStateFromMeta(4));
      world.setBlockState(pos.add(19, 17, 38), ((BlockColored)Blocks.STAINED_HARDENED_CLAY).getStateFromMeta(7));
      world.setBlockState(pos.add(20, 17, 38), ((BlockColored)Blocks.STAINED_HARDENED_CLAY).getStateFromMeta(7));
      world.setBlockState(pos.add(22, 17, 38), Blocks.QUARTZ_STAIRS.getDefaultState());
      world.setBlockState(pos.add(23, 17, 38), ((BlockColored)Blocks.STAINED_HARDENED_CLAY).getStateFromMeta(4));
      world.setBlockState(pos.add(29, 17, 38), ((BlockColored)Blocks.STAINED_HARDENED_CLAY).getStateFromMeta(4));
      world.setBlockState(pos.add(30, 17, 38), ((BlockStairs)Blocks.QUARTZ_STAIRS).getStateFromMeta(1));
      world.setBlockState(pos.add(32, 17, 38), ((BlockColored)Blocks.STAINED_HARDENED_CLAY).getStateFromMeta(7));
      world.setBlockState(pos.add(33, 17, 38), ((BlockColored)Blocks.STAINED_HARDENED_CLAY).getStateFromMeta(7));
      world.setBlockState(pos.add(34, 17, 38), ((BlockColored)Blocks.STAINED_HARDENED_CLAY).getStateFromMeta(4));
      world.setBlockState(pos.add(35, 17, 38), ((BlockColored)Blocks.STAINED_HARDENED_CLAY).getStateFromMeta(4));
      world.setBlockState(pos.add(17, 17, 39), ((BlockColored)Blocks.STAINED_HARDENED_CLAY).getStateFromMeta(4));
      world.setBlockState(pos.add(20, 17, 39), ((BlockColored)Blocks.STAINED_HARDENED_CLAY).getStateFromMeta(4));
      world.setBlockState(pos.add(22, 17, 39), Blocks.QUARTZ_STAIRS.getDefaultState());
      world.setBlockState(pos.add(23, 17, 39), ((BlockColored)Blocks.STAINED_HARDENED_CLAY).getStateFromMeta(4));
      world.setBlockState(pos.add(29, 17, 39), ((BlockColored)Blocks.STAINED_HARDENED_CLAY).getStateFromMeta(4));
      world.setBlockState(pos.add(30, 17, 39), ((BlockStairs)Blocks.QUARTZ_STAIRS).getStateFromMeta(1));
      world.setBlockState(pos.add(32, 17, 39), ((BlockColored)Blocks.STAINED_HARDENED_CLAY).getStateFromMeta(4));
      world.setBlockState(pos.add(35, 17, 39), ((BlockColored)Blocks.STAINED_HARDENED_CLAY).getStateFromMeta(4));
      world.setBlockState(pos.add(4, 17, 40), Blocks.DIAMOND_BLOCK.getDefaultState());
      world.setBlockState(pos.add(5, 17, 40), Blocks.DIAMOND_BLOCK.getDefaultState());
      world.setBlockState(pos.add(6, 17, 40), Blocks.STAINED_GLASS.getStateFromMeta(11));
      world.setBlockState(pos.add(7, 17, 40), Blocks.DIAMOND_BLOCK.getDefaultState());
      world.setBlockState(pos.add(8, 17, 40), Blocks.DIAMOND_BLOCK.getDefaultState());
      world.setBlockState(pos.add(17, 17, 40), ((BlockColored)Blocks.STAINED_HARDENED_CLAY).getStateFromMeta(4));
      world.setBlockState(pos.add(20, 17, 40), ((BlockColored)Blocks.STAINED_HARDENED_CLAY).getStateFromMeta(4));
      world.setBlockState(pos.add(22, 17, 40), Blocks.QUARTZ_STAIRS.getDefaultState());
      world.setBlockState(pos.add(23, 17, 40), ((BlockColored)Blocks.STAINED_HARDENED_CLAY).getStateFromMeta(4));
      world.setBlockState(pos.add(29, 17, 40), ((BlockColored)Blocks.STAINED_HARDENED_CLAY).getStateFromMeta(4));
      world.setBlockState(pos.add(30, 17, 40), ((BlockStairs)Blocks.QUARTZ_STAIRS).getStateFromMeta(1));
      world.setBlockState(pos.add(32, 17, 40), ((BlockColored)Blocks.STAINED_HARDENED_CLAY).getStateFromMeta(4));
      world.setBlockState(pos.add(34, 17, 40), ((BlockColored)Blocks.STAINED_HARDENED_CLAY).getStateFromMeta(4));
      world.setBlockState(pos.add(35, 17, 40), ((BlockColored)Blocks.STAINED_HARDENED_CLAY).getStateFromMeta(4));
      world.setBlockState(pos.add(3, 17, 41), Blocks.DIAMOND_BLOCK.getDefaultState());
      world.setBlockState(pos.add(4, 17, 41), Blocks.DIAMOND_BLOCK.getDefaultState());
      world.setBlockState(pos.add(5, 17, 41), Blocks.STONE.getDefaultState());
      world.setBlockState(pos.add(6, 17, 41), Blocks.GLOWSTONE.getDefaultState());
      world.setBlockState(pos.add(7, 17, 41), Blocks.STONE.getDefaultState());
      world.setBlockState(pos.add(8, 17, 41), Blocks.DIAMOND_BLOCK.getDefaultState());
      world.setBlockState(pos.add(9, 17, 41), Blocks.DIAMOND_BLOCK.getDefaultState());
      world.setBlockState(pos.add(18, 17, 41), Blocks.QUARTZ_BLOCK.getDefaultState());
      world.setBlockState(pos.add(20, 17, 41), Blocks.QUARTZ_BLOCK.getDefaultState());
      world.setBlockState(pos.add(22, 17, 41), Blocks.QUARTZ_STAIRS.getDefaultState());
      world.setBlockState(pos.add(23, 17, 41), ((BlockColored)Blocks.STAINED_HARDENED_CLAY).getStateFromMeta(4));
      world.setBlockState(pos.add(26, 17, 41), Blocks.STONE.getDefaultState());
      world.setBlockState(pos.add(27, 17, 41), Blocks.STONE.getDefaultState());
      world.setBlockState(pos.add(29, 17, 41), ((BlockColored)Blocks.STAINED_HARDENED_CLAY).getStateFromMeta(4));
      world.setBlockState(pos.add(30, 17, 41), ((BlockStairs)Blocks.QUARTZ_STAIRS).getStateFromMeta(1));
      world.setBlockState(pos.add(32, 17, 41), Blocks.QUARTZ_BLOCK.getDefaultState());
      world.setBlockState(pos.add(34, 17, 41), Blocks.QUARTZ_BLOCK.getDefaultState());
      world.setBlockState(pos.add(3, 17, 42), Blocks.DIAMOND_BLOCK.getDefaultState());
      world.setBlockState(pos.add(4, 17, 42), Blocks.STONE.getDefaultState());
      world.setBlockState(pos.add(5, 17, 42), Blocks.STONE.getDefaultState());
      world.setBlockState(pos.add(6, 17, 42), Blocks.STONE.getDefaultState());
      world.setBlockState(pos.add(7, 17, 42), Blocks.STONE.getDefaultState());
      world.setBlockState(pos.add(8, 17, 42), Blocks.STONE.getDefaultState());
      world.setBlockState(pos.add(9, 17, 42), Blocks.DIAMOND_BLOCK.getDefaultState());
      world.setBlockState(pos.add(18, 17, 42), Blocks.QUARTZ_BLOCK.getDefaultState());
      world.setBlockState(pos.add(20, 17, 42), Blocks.QUARTZ_BLOCK.getDefaultState());
      world.setBlockState(pos.add(22, 17, 42), Blocks.QUARTZ_STAIRS.getDefaultState());
      world.setBlockState(pos.add(23, 17, 42), ((BlockColored)Blocks.STAINED_HARDENED_CLAY).getStateFromMeta(4));
      world.setBlockState(pos.add(26, 17, 42), Blocks.STONE.getDefaultState());
      world.setBlockState(pos.add(27, 17, 42), Blocks.STONE.getDefaultState());
      world.setBlockState(pos.add(29, 17, 42), ((BlockColored)Blocks.STAINED_HARDENED_CLAY).getStateFromMeta(4));
      world.setBlockState(pos.add(30, 17, 42), ((BlockStairs)Blocks.QUARTZ_STAIRS).getStateFromMeta(1));
      world.setBlockState(pos.add(32, 17, 42), Blocks.QUARTZ_BLOCK.getDefaultState());
      world.setBlockState(pos.add(34, 17, 42), Blocks.QUARTZ_BLOCK.getDefaultState());
      world.setBlockState(pos.add(3, 17, 43), Blocks.STAINED_GLASS.getStateFromMeta(11));
      world.setBlockState(pos.add(4, 17, 43), Blocks.GLOWSTONE.getDefaultState());
      world.setBlockState(pos.add(5, 17, 43), Blocks.STONE.getDefaultState());
      world.setBlockState(pos.add(6, 17, 43), Blocks.STONE.getDefaultState());
      world.setBlockState(pos.add(7, 17, 43), Blocks.STONE.getDefaultState());
      world.setBlockState(pos.add(8, 17, 43), Blocks.GLOWSTONE.getDefaultState());
      world.setBlockState(pos.add(9, 17, 43), Blocks.STAINED_GLASS.getStateFromMeta(11));
      world.setBlockState(pos.add(17, 17, 43), ((BlockColored)Blocks.STAINED_HARDENED_CLAY).getStateFromMeta(4));
      world.setBlockState(pos.add(20, 17, 43), ((BlockColored)Blocks.STAINED_HARDENED_CLAY).getStateFromMeta(4));
      world.setBlockState(pos.add(22, 17, 43), Blocks.QUARTZ_STAIRS.getDefaultState());
      world.setBlockState(pos.add(23, 17, 43), ((BlockColored)Blocks.STAINED_HARDENED_CLAY).getStateFromMeta(4));
      world.setBlockState(pos.add(29, 17, 43), ((BlockColored)Blocks.STAINED_HARDENED_CLAY).getStateFromMeta(4));
      world.setBlockState(pos.add(30, 17, 43), ((BlockStairs)Blocks.QUARTZ_STAIRS).getStateFromMeta(1));
      world.setBlockState(pos.add(32, 17, 43), ((BlockColored)Blocks.STAINED_HARDENED_CLAY).getStateFromMeta(4));
      world.setBlockState(pos.add(35, 17, 43), ((BlockColored)Blocks.STAINED_HARDENED_CLAY).getStateFromMeta(4));
      world.setBlockState(pos.add(3, 17, 44), Blocks.DIAMOND_BLOCK.getDefaultState());
      world.setBlockState(pos.add(4, 17, 44), Blocks.STONE.getDefaultState());
      world.setBlockState(pos.add(5, 17, 44), Blocks.STONE.getDefaultState());
      world.setBlockState(pos.add(6, 17, 44), Blocks.STONE.getDefaultState());
      world.setBlockState(pos.add(7, 17, 44), Blocks.STONE.getDefaultState());
      world.setBlockState(pos.add(8, 17, 44), Blocks.STONE.getDefaultState());
      world.setBlockState(pos.add(9, 17, 44), Blocks.DIAMOND_BLOCK.getDefaultState());
      world.setBlockState(pos.add(17, 17, 44), ((BlockColored)Blocks.STAINED_HARDENED_CLAY).getStateFromMeta(4));
      world.setBlockState(pos.add(20, 17, 44), ((BlockColored)Blocks.STAINED_HARDENED_CLAY).getStateFromMeta(4));
      world.setBlockState(pos.add(22, 17, 44), Blocks.QUARTZ_STAIRS.getDefaultState());
      world.setBlockState(pos.add(23, 17, 44), ((BlockColored)Blocks.STAINED_HARDENED_CLAY).getStateFromMeta(4));
      world.setBlockState(pos.add(29, 17, 44), ((BlockColored)Blocks.STAINED_HARDENED_CLAY).getStateFromMeta(4));
      world.setBlockState(pos.add(30, 17, 44), ((BlockStairs)Blocks.QUARTZ_STAIRS).getStateFromMeta(1));
      world.setBlockState(pos.add(32, 17, 44), ((BlockColored)Blocks.STAINED_HARDENED_CLAY).getStateFromMeta(4));
      world.setBlockState(pos.add(35, 17, 44), ((BlockColored)Blocks.STAINED_HARDENED_CLAY).getStateFromMeta(4));
      world.setBlockState(pos.add(3, 17, 45), Blocks.DIAMOND_BLOCK.getDefaultState());
      world.setBlockState(pos.add(4, 17, 45), Blocks.DIAMOND_BLOCK.getDefaultState());
      world.setBlockState(pos.add(5, 17, 45), Blocks.STONE.getDefaultState());
      world.setBlockState(pos.add(6, 17, 45), Blocks.GLOWSTONE.getDefaultState());
      world.setBlockState(pos.add(7, 17, 45), Blocks.STONE.getDefaultState());
      world.setBlockState(pos.add(8, 17, 45), Blocks.DIAMOND_BLOCK.getDefaultState());
      world.setBlockState(pos.add(9, 17, 45), Blocks.DIAMOND_BLOCK.getDefaultState());
      world.setBlockState(pos.add(17, 17, 45), ((BlockColored)Blocks.STAINED_HARDENED_CLAY).getStateFromMeta(4));
      world.setBlockState(pos.add(20, 17, 45), ((BlockColored)Blocks.STAINED_HARDENED_CLAY).getStateFromMeta(4));
      world.setBlockState(pos.add(22, 17, 45), Blocks.QUARTZ_STAIRS.getDefaultState());
      world.setBlockState(pos.add(23, 17, 45), ((BlockColored)Blocks.STAINED_HARDENED_CLAY).getStateFromMeta(4));
      world.setBlockState(pos.add(29, 17, 45), ((BlockColored)Blocks.STAINED_HARDENED_CLAY).getStateFromMeta(4));
      world.setBlockState(pos.add(30, 17, 45), ((BlockStairs)Blocks.QUARTZ_STAIRS).getStateFromMeta(1));
      world.setBlockState(pos.add(32, 17, 45), ((BlockColored)Blocks.STAINED_HARDENED_CLAY).getStateFromMeta(4));
      world.setBlockState(pos.add(35, 17, 45), ((BlockColored)Blocks.STAINED_HARDENED_CLAY).getStateFromMeta(4));
      world.setBlockState(pos.add(4, 17, 46), Blocks.DIAMOND_BLOCK.getDefaultState());
      world.setBlockState(pos.add(5, 17, 46), Blocks.DIAMOND_BLOCK.getDefaultState());
      world.setBlockState(pos.add(6, 17, 46), Blocks.STAINED_GLASS.getStateFromMeta(11));
      world.setBlockState(pos.add(7, 17, 46), Blocks.DIAMOND_BLOCK.getDefaultState());
      world.setBlockState(pos.add(8, 17, 46), Blocks.DIAMOND_BLOCK.getDefaultState());
      world.setBlockState(pos.add(18, 17, 46), Blocks.QUARTZ_BLOCK.getDefaultState());
      world.setBlockState(pos.add(19, 17, 46), Blocks.QUARTZ_BLOCK.getDefaultState());
      world.setBlockState(pos.add(20, 17, 46), Blocks.QUARTZ_BLOCK.getDefaultState());
      world.setBlockState(pos.add(22, 17, 46), Blocks.QUARTZ_STAIRS.getDefaultState());
      world.setBlockState(pos.add(23, 17, 46), ((BlockColored)Blocks.STAINED_HARDENED_CLAY).getStateFromMeta(4));
      world.setBlockState(pos.add(25, 17, 46), Blocks.STONE.getDefaultState());
      world.setBlockState(pos.add(26, 17, 46), Blocks.STONE.getDefaultState());
      world.setBlockState(pos.add(29, 17, 46), ((BlockColored)Blocks.STAINED_HARDENED_CLAY).getStateFromMeta(4));
      world.setBlockState(pos.add(30, 17, 46), ((BlockStairs)Blocks.QUARTZ_STAIRS).getStateFromMeta(1));
      world.setBlockState(pos.add(32, 17, 46), Blocks.QUARTZ_BLOCK.getDefaultState());
      world.setBlockState(pos.add(34, 17, 46), Blocks.QUARTZ_BLOCK.getDefaultState());
      world.setBlockState(pos.add(18, 17, 47), Blocks.QUARTZ_BLOCK.getDefaultState());
      world.setBlockState(pos.add(19, 17, 47), Blocks.QUARTZ_BLOCK.getDefaultState());
      world.setBlockState(pos.add(20, 17, 47), Blocks.QUARTZ_BLOCK.getDefaultState());
      world.setBlockState(pos.add(22, 17, 47), Blocks.QUARTZ_STAIRS.getDefaultState());
      world.setBlockState(pos.add(23, 17, 47), ((BlockColored)Blocks.STAINED_HARDENED_CLAY).getStateFromMeta(4));
      world.setBlockState(pos.add(25, 17, 47), Blocks.STONE.getDefaultState());
      world.setBlockState(pos.add(26, 17, 47), Blocks.STONE.getDefaultState());
      world.setBlockState(pos.add(29, 17, 47), ((BlockColored)Blocks.STAINED_HARDENED_CLAY).getStateFromMeta(4));
      world.setBlockState(pos.add(30, 17, 47), ((BlockStairs)Blocks.QUARTZ_STAIRS).getStateFromMeta(1));
      world.setBlockState(pos.add(32, 17, 47), Blocks.QUARTZ_BLOCK.getDefaultState());
      world.setBlockState(pos.add(34, 17, 47), Blocks.QUARTZ_BLOCK.getDefaultState());
      world.setBlockState(pos.add(17, 17, 48), ((BlockColored)Blocks.STAINED_HARDENED_CLAY).getStateFromMeta(4));
      world.setBlockState(pos.add(20, 17, 48), ((BlockColored)Blocks.STAINED_HARDENED_CLAY).getStateFromMeta(4));
      world.setBlockState(pos.add(22, 17, 48), Blocks.QUARTZ_STAIRS.getDefaultState());
      world.setBlockState(pos.add(23, 17, 48), ((BlockColored)Blocks.STAINED_HARDENED_CLAY).getStateFromMeta(4));
      world.setBlockState(pos.add(29, 17, 48), ((BlockColored)Blocks.STAINED_HARDENED_CLAY).getStateFromMeta(4));
      world.setBlockState(pos.add(30, 17, 48), ((BlockStairs)Blocks.QUARTZ_STAIRS).getStateFromMeta(1));
      world.setBlockState(pos.add(32, 17, 48), ((BlockColored)Blocks.STAINED_HARDENED_CLAY).getStateFromMeta(4));
      world.setBlockState(pos.add(35, 17, 48), ((BlockColored)Blocks.STAINED_HARDENED_CLAY).getStateFromMeta(4));
      world.setBlockState(pos.add(17, 17, 49), ((BlockColored)Blocks.STAINED_HARDENED_CLAY).getStateFromMeta(4));
      world.setBlockState(pos.add(20, 17, 49), ((BlockColored)Blocks.STAINED_HARDENED_CLAY).getStateFromMeta(4));
      world.setBlockState(pos.add(22, 17, 49), Blocks.QUARTZ_STAIRS.getDefaultState());
      world.setBlockState(pos.add(23, 17, 49), ((BlockColored)Blocks.STAINED_HARDENED_CLAY).getStateFromMeta(4));
      world.setBlockState(pos.add(29, 17, 49), ((BlockColored)Blocks.STAINED_HARDENED_CLAY).getStateFromMeta(4));
      world.setBlockState(pos.add(30, 17, 49), ((BlockStairs)Blocks.QUARTZ_STAIRS).getStateFromMeta(1));
      world.setBlockState(pos.add(32, 17, 49), ((BlockColored)Blocks.STAINED_HARDENED_CLAY).getStateFromMeta(4));
      world.setBlockState(pos.add(35, 17, 49), ((BlockColored)Blocks.STAINED_HARDENED_CLAY).getStateFromMeta(4));
      world.setBlockState(pos.add(17, 17, 50), ((BlockColored)Blocks.STAINED_HARDENED_CLAY).getStateFromMeta(4));
      world.setBlockState(pos.add(18, 17, 50), ((BlockColored)Blocks.STAINED_HARDENED_CLAY).getStateFromMeta(4));
      world.setBlockState(pos.add(19, 17, 50), ((BlockColored)Blocks.STAINED_HARDENED_CLAY).getStateFromMeta(4));
      world.setBlockState(pos.add(20, 17, 50), ((BlockColored)Blocks.STAINED_HARDENED_CLAY).getStateFromMeta(4));
      world.setBlockState(pos.add(21, 17, 50), ((BlockColored)Blocks.STAINED_HARDENED_CLAY).getStateFromMeta(4));
      world.setBlockState(pos.add(22, 17, 50), Blocks.QUARTZ_STAIRS.getDefaultState());
      world.setBlockState(pos.add(23, 17, 50), ((BlockColored)Blocks.STAINED_HARDENED_CLAY).getStateFromMeta(4));
      world.setBlockState(pos.add(29, 17, 50), ((BlockColored)Blocks.STAINED_HARDENED_CLAY).getStateFromMeta(4));
      world.setBlockState(pos.add(30, 17, 50), ((BlockStairs)Blocks.QUARTZ_STAIRS).getStateFromMeta(1));
      world.setBlockState(pos.add(32, 17, 50), ((BlockColored)Blocks.STAINED_HARDENED_CLAY).getStateFromMeta(4));
      world.setBlockState(pos.add(33, 17, 50), ((BlockColored)Blocks.STAINED_HARDENED_CLAY).getStateFromMeta(4));
      world.setBlockState(pos.add(34, 17, 50), ((BlockColored)Blocks.STAINED_HARDENED_CLAY).getStateFromMeta(4));
      world.setBlockState(pos.add(35, 17, 50), ((BlockColored)Blocks.STAINED_HARDENED_CLAY).getStateFromMeta(4));
      world.setBlockState(pos.add(18, 17, 51), ((BlockColored)Blocks.STAINED_HARDENED_CLAY).getStateFromMeta(4));
      world.setBlockState(pos.add(19, 17, 51), ((BlockColored)Blocks.STAINED_HARDENED_CLAY).getStateFromMeta(4));
      world.setBlockState(pos.add(20, 17, 51), ((BlockColored)Blocks.STAINED_HARDENED_CLAY).getStateFromMeta(4));
      world.setBlockState(pos.add(21, 17, 51), ((BlockColored)Blocks.STAINED_HARDENED_CLAY).getStateFromMeta(4));
      world.setBlockState(pos.add(23, 17, 51), ((BlockColored)Blocks.STAINED_HARDENED_CLAY).getStateFromMeta(4));
      world.setBlockState(pos.add(24, 17, 51), ((BlockColored)Blocks.STAINED_HARDENED_CLAY).getStateFromMeta(4));
      world.setBlockState(pos.add(25, 17, 51), ((BlockColored)Blocks.STAINED_HARDENED_CLAY).getStateFromMeta(4));
      world.setBlockState(pos.add(26, 17, 51), ((BlockColored)Blocks.STAINED_HARDENED_CLAY).getStateFromMeta(4));
      world.setBlockState(pos.add(27, 17, 51), ((BlockColored)Blocks.STAINED_HARDENED_CLAY).getStateFromMeta(4));
      world.setBlockState(pos.add(28, 17, 51), ((BlockColored)Blocks.STAINED_HARDENED_CLAY).getStateFromMeta(4));
      world.setBlockState(pos.add(29, 17, 51), ((BlockColored)Blocks.STAINED_HARDENED_CLAY).getStateFromMeta(4));
      world.setBlockState(pos.add(30, 17, 51), ((BlockColored)Blocks.STAINED_HARDENED_CLAY).getStateFromMeta(4));
      world.setBlockState(pos.add(31, 17, 51), ((BlockColored)Blocks.STAINED_HARDENED_CLAY).getStateFromMeta(4));
      world.setBlockState(pos.add(32, 17, 51), ((BlockColored)Blocks.STAINED_HARDENED_CLAY).getStateFromMeta(4));
      world.setBlockState(pos.add(33, 17, 51), ((BlockColored)Blocks.STAINED_HARDENED_CLAY).getStateFromMeta(4));
      world.setBlockState(pos.add(34, 17, 51), ((BlockColored)Blocks.STAINED_HARDENED_CLAY).getStateFromMeta(4));
      world.setBlockState(pos.add(17, 17, 52), ((BlockColored)Blocks.STAINED_HARDENED_CLAY).getStateFromMeta(4));
      world.setBlockState(pos.add(18, 17, 52), ((BlockColored)Blocks.STAINED_HARDENED_CLAY).getStateFromMeta(4));
      world.setBlockState(pos.add(22, 17, 52), ((BlockColored)Blocks.STAINED_HARDENED_CLAY).getStateFromMeta(4));
      world.setBlockState(pos.add(23, 17, 52), ((BlockStone)Blocks.STONE).getStateFromMeta(4));
      world.setBlockState(pos.add(24, 17, 52), ((BlockStone)Blocks.STONE).getStateFromMeta(4));
      world.setBlockState(pos.add(25, 17, 52), ((BlockStone)Blocks.STONE).getStateFromMeta(4));
      world.setBlockState(pos.add(27, 17, 52), ((BlockStone)Blocks.STONE).getStateFromMeta(4));
      world.setBlockState(pos.add(28, 17, 52), ((BlockStone)Blocks.STONE).getStateFromMeta(4));
      world.setBlockState(pos.add(29, 17, 52), ((BlockColored)Blocks.STAINED_HARDENED_CLAY).getStateFromMeta(4));
      world.setBlockState(pos.add(30, 17, 52), ((BlockColored)Blocks.STAINED_HARDENED_CLAY).getStateFromMeta(4));
      world.setBlockState(pos.add(34, 17, 52), ((BlockColored)Blocks.STAINED_HARDENED_CLAY).getStateFromMeta(4));
      world.setBlockState(pos.add(35, 17, 52), ((BlockColored)Blocks.STAINED_HARDENED_CLAY).getStateFromMeta(4));
      world.setBlockState(pos.add(16, 17, 53), ((BlockColored)Blocks.STAINED_HARDENED_CLAY).getStateFromMeta(4));
      world.setBlockState(pos.add(17, 17, 53), ((BlockColored)Blocks.STAINED_HARDENED_CLAY).getStateFromMeta(4));
      world.setBlockState(pos.add(23, 17, 53), ((BlockColored)Blocks.STAINED_HARDENED_CLAY).getStateFromMeta(4));
      world.setBlockState(pos.add(24, 17, 53), ((BlockColored)Blocks.STAINED_HARDENED_CLAY).getStateFromMeta(4));
      world.setBlockState(pos.add(25, 17, 53), ((BlockStone)Blocks.STONE).getStateFromMeta(4));
      world.setBlockState(pos.add(27, 17, 53), ((BlockStone)Blocks.STONE).getStateFromMeta(4));
      world.setBlockState(pos.add(28, 17, 53), ((BlockColored)Blocks.STAINED_HARDENED_CLAY).getStateFromMeta(4));
      world.setBlockState(pos.add(29, 17, 53), ((BlockColored)Blocks.STAINED_HARDENED_CLAY).getStateFromMeta(4));
      world.setBlockState(pos.add(35, 17, 53), ((BlockColored)Blocks.STAINED_HARDENED_CLAY).getStateFromMeta(4));
      world.setBlockState(pos.add(36, 17, 53), ((BlockColored)Blocks.STAINED_HARDENED_CLAY).getStateFromMeta(4));
      world.setBlockState(pos.add(16, 17, 54), ((BlockColored)Blocks.STAINED_HARDENED_CLAY).getStateFromMeta(4));
      world.setBlockState(pos.add(17, 17, 54), ((BlockColored)Blocks.STAINED_HARDENED_CLAY).getStateFromMeta(4));
      world.setBlockState(pos.add(23, 17, 54), ((BlockColored)Blocks.STAINED_HARDENED_CLAY).getStateFromMeta(4));
      world.setBlockState(pos.add(24, 17, 54), ((BlockColored)Blocks.STAINED_HARDENED_CLAY).getStateFromMeta(4));
      world.setBlockState(pos.add(25, 17, 54), ((BlockStone)Blocks.STONE).getStateFromMeta(4));
      world.setBlockState(pos.add(27, 17, 54), ((BlockStone)Blocks.STONE).getStateFromMeta(4));
      world.setBlockState(pos.add(28, 17, 54), ((BlockColored)Blocks.STAINED_HARDENED_CLAY).getStateFromMeta(4));
      world.setBlockState(pos.add(29, 17, 54), ((BlockColored)Blocks.STAINED_HARDENED_CLAY).getStateFromMeta(4));
      world.setBlockState(pos.add(35, 17, 54), ((BlockColored)Blocks.STAINED_HARDENED_CLAY).getStateFromMeta(4));
      world.setBlockState(pos.add(36, 17, 54), ((BlockColored)Blocks.STAINED_HARDENED_CLAY).getStateFromMeta(4));
      world.setBlockState(pos.add(16, 17, 55), ((BlockColored)Blocks.STAINED_HARDENED_CLAY).getStateFromMeta(4));
      world.setBlockState(pos.add(17, 17, 55), ((BlockColored)Blocks.STAINED_HARDENED_CLAY).getStateFromMeta(4));
      world.setBlockState(pos.add(23, 17, 55), ((BlockColored)Blocks.STAINED_HARDENED_CLAY).getStateFromMeta(4));
      world.setBlockState(pos.add(24, 17, 55), ((BlockColored)Blocks.STAINED_HARDENED_CLAY).getStateFromMeta(4));
      world.setBlockState(pos.add(25, 17, 55), ((BlockStone)Blocks.STONE).getStateFromMeta(4));
      world.setBlockState(pos.add(27, 17, 55), ((BlockStone)Blocks.STONE).getStateFromMeta(4));
      world.setBlockState(pos.add(28, 17, 55), ((BlockColored)Blocks.STAINED_HARDENED_CLAY).getStateFromMeta(4));
      world.setBlockState(pos.add(29, 17, 55), ((BlockColored)Blocks.STAINED_HARDENED_CLAY).getStateFromMeta(4));
      world.setBlockState(pos.add(35, 17, 55), ((BlockColored)Blocks.STAINED_HARDENED_CLAY).getStateFromMeta(4));
      world.setBlockState(pos.add(36, 17, 55), ((BlockColored)Blocks.STAINED_HARDENED_CLAY).getStateFromMeta(4));
      world.setBlockState(pos.add(37, 17, 55), ((BlockColored)Blocks.STAINED_HARDENED_CLAY).getStateFromMeta(4));
      world.setBlockState(pos.add(17, 17, 56), ((BlockColored)Blocks.STAINED_HARDENED_CLAY).getStateFromMeta(4));
      world.setBlockState(pos.add(18, 17, 56), ((BlockColored)Blocks.STAINED_HARDENED_CLAY).getStateFromMeta(4));
      world.setBlockState(pos.add(22, 17, 56), ((BlockColored)Blocks.STAINED_HARDENED_CLAY).getStateFromMeta(4));
      world.setBlockState(pos.add(23, 17, 56), ((BlockColored)Blocks.STAINED_HARDENED_CLAY).getStateFromMeta(4));
      world.setBlockState(pos.add(25, 17, 56), ((BlockStone)Blocks.STONE).getStateFromMeta(4));
      world.setBlockState(pos.add(27, 17, 56), ((BlockStone)Blocks.STONE).getStateFromMeta(4));
      world.setBlockState(pos.add(29, 17, 56), ((BlockColored)Blocks.STAINED_HARDENED_CLAY).getStateFromMeta(4));
      world.setBlockState(pos.add(30, 17, 56), ((BlockColored)Blocks.STAINED_HARDENED_CLAY).getStateFromMeta(4));
      world.setBlockState(pos.add(34, 17, 56), ((BlockColored)Blocks.STAINED_HARDENED_CLAY).getStateFromMeta(4));
      world.setBlockState(pos.add(35, 17, 56), ((BlockColored)Blocks.STAINED_HARDENED_CLAY).getStateFromMeta(4));
      world.setBlockState(pos.add(38, 17, 56), ((BlockColored)Blocks.STAINED_HARDENED_CLAY).getStateFromMeta(4));
      world.setBlockState(pos.add(39, 17, 56), ((BlockColored)Blocks.WOOL).getStateFromMeta(15));
      world.setBlockState(pos.add(40, 17, 56), ((BlockColored)Blocks.WOOL).getStateFromMeta(15));
      world.setBlockState(pos.add(18, 17, 57), ((BlockColored)Blocks.STAINED_HARDENED_CLAY).getStateFromMeta(4));
      world.setBlockState(pos.add(19, 17, 57), ((BlockColored)Blocks.STAINED_HARDENED_CLAY).getStateFromMeta(4));
      world.setBlockState(pos.add(20, 17, 57), ((BlockColored)Blocks.STAINED_HARDENED_CLAY).getStateFromMeta(4));
      world.setBlockState(pos.add(21, 17, 57), ((BlockColored)Blocks.STAINED_HARDENED_CLAY).getStateFromMeta(4));
      world.setBlockState(pos.add(22, 17, 57), ((BlockColored)Blocks.STAINED_HARDENED_CLAY).getStateFromMeta(4));
      world.setBlockState(pos.add(25, 17, 57), Blocks.STONE.getDefaultState());
      world.setBlockState(pos.add(27, 17, 57), Blocks.STONE.getDefaultState());
      world.setBlockState(pos.add(30, 17, 57), ((BlockColored)Blocks.STAINED_HARDENED_CLAY).getStateFromMeta(4));
      world.setBlockState(pos.add(31, 17, 57), ((BlockColored)Blocks.STAINED_HARDENED_CLAY).getStateFromMeta(4));
      world.setBlockState(pos.add(32, 17, 57), ((BlockColored)Blocks.STAINED_HARDENED_CLAY).getStateFromMeta(4));
      world.setBlockState(pos.add(33, 17, 57), ((BlockColored)Blocks.STAINED_HARDENED_CLAY).getStateFromMeta(4));
      world.setBlockState(pos.add(34, 17, 57), ((BlockColored)Blocks.STAINED_HARDENED_CLAY).getStateFromMeta(4));
      world.setBlockState(pos.add(39, 17, 57), ((BlockColored)Blocks.STAINED_HARDENED_CLAY).getStateFromMeta(4));
      world.setBlockState(pos.add(41, 17, 57), ((BlockColored)Blocks.WOOL).getStateFromMeta(15));
      world.setBlockState(pos.add(19, 17, 58), ((BlockColored)Blocks.STAINED_HARDENED_CLAY).getStateFromMeta(4));
      world.setBlockState(pos.add(20, 17, 58), ((BlockColored)Blocks.STAINED_HARDENED_CLAY).getStateFromMeta(4));
      world.setBlockState(pos.add(21, 17, 58), ((BlockColored)Blocks.STAINED_HARDENED_CLAY).getStateFromMeta(4));
      world.setBlockState(pos.add(25, 17, 58), Blocks.STONE.getDefaultState());
      world.setBlockState(pos.add(27, 17, 58), Blocks.STONE.getDefaultState());
      world.setBlockState(pos.add(31, 17, 58), ((BlockColored)Blocks.STAINED_HARDENED_CLAY).getStateFromMeta(4));
      world.setBlockState(pos.add(32, 17, 58), ((BlockColored)Blocks.STAINED_HARDENED_CLAY).getStateFromMeta(4));
      world.setBlockState(pos.add(33, 17, 58), ((BlockColored)Blocks.STAINED_HARDENED_CLAY).getStateFromMeta(4));
      world.setBlockState(pos.add(40, 17, 58), ((BlockColored)Blocks.STAINED_HARDENED_CLAY).getStateFromMeta(4));
      world.setBlockState(pos.add(42, 17, 58), ((BlockColored)Blocks.WOOL).getStateFromMeta(15));
      world.setBlockState(pos.add(25, 17, 59), Blocks.STONE.getDefaultState());
      world.setBlockState(pos.add(27, 17, 59), Blocks.STONE.getDefaultState());
      world.setBlockState(pos.add(34, 17, 59), ((BlockColored)Blocks.WOOL).getStateFromMeta(15));
      world.setBlockState(pos.add(35, 17, 59), ((BlockColored)Blocks.WOOL).getStateFromMeta(15));
      world.setBlockState(pos.add(36, 17, 59), ((BlockColored)Blocks.WOOL).getStateFromMeta(15));
      world.setBlockState(pos.add(37, 17, 59), ((BlockColored)Blocks.WOOL).getStateFromMeta(15));
      world.setBlockState(pos.add(41, 17, 59), ((BlockColored)Blocks.STAINED_HARDENED_CLAY).getStateFromMeta(4));
      world.setBlockState(pos.add(42, 17, 59), ((BlockColored)Blocks.WOOL).getStateFromMeta(15));
      world.setBlockState(pos.add(24, 17, 60), Blocks.STONE.getDefaultState());
      world.setBlockState(pos.add(25, 17, 60), Blocks.STONE.getDefaultState());
      world.setBlockState(pos.add(27, 17, 60), Blocks.STONE.getDefaultState());
      world.setBlockState(pos.add(33, 17, 60), ((BlockColored)Blocks.WOOL).getStateFromMeta(15));
      world.setBlockState(pos.add(38, 17, 60), ((BlockColored)Blocks.WOOL).getStateFromMeta(15));
      world.setBlockState(pos.add(42, 17, 60), Blocks.STONE.getDefaultState());
      world.setBlockState(pos.add(43, 17, 60), Blocks.STONE.getDefaultState());
      world.setBlockState(pos.add(44, 17, 60), Blocks.STONE.getDefaultState());
      world.setBlockState(pos.add(45, 17, 60), Blocks.STONE.getDefaultState());
      world.setBlockState(pos.add(20, 17, 61), Blocks.STONE.getDefaultState());
      world.setBlockState(pos.add(21, 17, 61), Blocks.STONE.getDefaultState());
      world.setBlockState(pos.add(22, 17, 61), Blocks.STONE.getDefaultState());
      world.setBlockState(pos.add(23, 17, 61), Blocks.STONE.getDefaultState());
      world.setBlockState(pos.add(24, 17, 61), Blocks.STONE.getDefaultState());
      world.setBlockState(pos.add(28, 17, 61), Blocks.STONE.getDefaultState());
      world.setBlockState(pos.add(32, 17, 61), ((BlockColored)Blocks.WOOL).getStateFromMeta(15));
      world.setBlockState(pos.add(39, 17, 61), ((BlockColored)Blocks.WOOL).getStateFromMeta(15));
      world.setBlockState(pos.add(41, 17, 61), Blocks.STONE.getDefaultState());
      world.setBlockState(pos.add(46, 17, 61), Blocks.STONE.getDefaultState());
      world.setBlockState(pos.add(18, 17, 62), Blocks.STONE.getDefaultState());
      world.setBlockState(pos.add(19, 17, 62), Blocks.STONE.getDefaultState());
      world.setBlockState(pos.add(28, 17, 62), Blocks.STONE.getDefaultState());
      world.setBlockState(pos.add(32, 17, 62), ((BlockColored)Blocks.WOOL).getStateFromMeta(15));
      world.setBlockState(pos.add(39, 17, 62), ((BlockColored)Blocks.WOOL).getStateFromMeta(15));
      world.setBlockState(pos.add(40, 17, 62), Blocks.STONE.getDefaultState());
      world.setBlockState(pos.add(47, 17, 62), Blocks.STONE.getDefaultState());
      world.setBlockState(pos.add(18, 17, 63), Blocks.STONE.getDefaultState());
      world.setBlockState(pos.add(19, 17, 63), Blocks.STONE.getDefaultState());
      world.setBlockState(pos.add(28, 17, 63), Blocks.STONE.getDefaultState());
      world.setBlockState(pos.add(32, 17, 63), ((BlockColored)Blocks.WOOL).getStateFromMeta(15));
      world.setBlockState(pos.add(39, 17, 63), ((BlockColored)Blocks.WOOL).getStateFromMeta(15));
      world.setBlockState(pos.add(40, 17, 63), Blocks.STONE.getDefaultState());
      world.setBlockState(pos.add(47, 17, 63), Blocks.STONE.getDefaultState());
      world.setBlockState(pos.add(20, 17, 64), Blocks.STONE.getDefaultState());
      world.setBlockState(pos.add(21, 17, 64), Blocks.STONE.getDefaultState());
      world.setBlockState(pos.add(22, 17, 64), Blocks.STONE.getDefaultState());
      world.setBlockState(pos.add(23, 17, 64), Blocks.STONE.getDefaultState());
      world.setBlockState(pos.add(24, 17, 64), Blocks.STONE.getDefaultState());
      world.setBlockState(pos.add(25, 17, 64), Blocks.STONE.getDefaultState());
      world.setBlockState(pos.add(26, 17, 64), Blocks.STONE.getDefaultState());
      world.setBlockState(pos.add(27, 17, 64), Blocks.STONE.getDefaultState());
      world.setBlockState(pos.add(28, 17, 64), Blocks.STONE.getDefaultState());
      world.setBlockState(pos.add(32, 17, 64), ((BlockColored)Blocks.WOOL).getStateFromMeta(15));
      world.setBlockState(pos.add(39, 17, 64), ((BlockColored)Blocks.WOOL).getStateFromMeta(15));
      world.setBlockState(pos.add(40, 17, 64), Blocks.STONE.getDefaultState());
      world.setBlockState(pos.add(47, 17, 64), Blocks.STONE.getDefaultState());
      world.setBlockState(pos.add(33, 17, 65), ((BlockColored)Blocks.WOOL).getStateFromMeta(15));
      world.setBlockState(pos.add(38, 17, 65), ((BlockColored)Blocks.WOOL).getStateFromMeta(15));
      world.setBlockState(pos.add(40, 17, 65), Blocks.STONE.getDefaultState());
      world.setBlockState(pos.add(47, 17, 65), Blocks.STONE.getDefaultState());
      world.setBlockState(pos.add(34, 17, 66), ((BlockColored)Blocks.WOOL).getStateFromMeta(15));
      world.setBlockState(pos.add(35, 17, 66), ((BlockColored)Blocks.WOOL).getStateFromMeta(15));
      world.setBlockState(pos.add(36, 17, 66), ((BlockColored)Blocks.WOOL).getStateFromMeta(15));
      world.setBlockState(pos.add(37, 17, 66), ((BlockColored)Blocks.WOOL).getStateFromMeta(15));
      world.setBlockState(pos.add(41, 17, 66), Blocks.STONE.getDefaultState());
      world.setBlockState(pos.add(46, 17, 66), Blocks.STONE.getDefaultState());
      world.setBlockState(pos.add(42, 17, 67), Blocks.STONE.getDefaultState());
      world.setBlockState(pos.add(43, 17, 67), Blocks.STONE.getDefaultState());
      world.setBlockState(pos.add(44, 17, 67), Blocks.STONE.getDefaultState());
      world.setBlockState(pos.add(45, 17, 67), Blocks.STONE.getDefaultState());
      world.setBlockState(pos.add(17, 18, 37), ((BlockColored)Blocks.STAINED_HARDENED_CLAY).getStateFromMeta(4));
      world.setBlockState(pos.add(18, 18, 37), ((BlockColored)Blocks.STAINED_HARDENED_CLAY).getStateFromMeta(4));
      world.setBlockState(pos.add(23, 18, 37), ((BlockColored)Blocks.STAINED_HARDENED_CLAY).getStateFromMeta(4));
      world.setBlockState(pos.add(24, 18, 37), ((BlockColored)Blocks.STAINED_HARDENED_CLAY).getStateFromMeta(4));
      world.setBlockState(pos.add(25, 18, 37), ((BlockColored)Blocks.STAINED_HARDENED_CLAY).getStateFromMeta(4));
      world.setBlockState(pos.add(26, 18, 37), Blocks.QUARTZ_BLOCK.getDefaultState());
      world.setBlockState(pos.add(27, 18, 37), ((BlockColored)Blocks.STAINED_HARDENED_CLAY).getStateFromMeta(4));
      world.setBlockState(pos.add(28, 18, 37), ((BlockColored)Blocks.STAINED_HARDENED_CLAY).getStateFromMeta(4));
      world.setBlockState(pos.add(29, 18, 37), ((BlockColored)Blocks.STAINED_HARDENED_CLAY).getStateFromMeta(4));
      world.setBlockState(pos.add(34, 18, 37), ((BlockColored)Blocks.STAINED_HARDENED_CLAY).getStateFromMeta(4));
      world.setBlockState(pos.add(35, 18, 37), ((BlockColored)Blocks.STAINED_HARDENED_CLAY).getStateFromMeta(4));
      world.setBlockState(pos.add(17, 18, 38), ((BlockColored)Blocks.STAINED_HARDENED_CLAY).getStateFromMeta(4));
      world.setBlockState(pos.add(18, 18, 38), ((BlockColored)Blocks.STAINED_HARDENED_CLAY).getStateFromMeta(4));
      world.setBlockState(pos.add(19, 18, 38), ((BlockColored)Blocks.STAINED_HARDENED_CLAY).getStateFromMeta(7));
      world.setBlockState(pos.add(20, 18, 38), ((BlockColored)Blocks.STAINED_HARDENED_CLAY).getStateFromMeta(7));
      world.setBlockState(pos.add(23, 18, 38), ((BlockColored)Blocks.STAINED_HARDENED_CLAY).getStateFromMeta(4));
      world.setBlockState(pos.add(29, 18, 38), ((BlockColored)Blocks.STAINED_HARDENED_CLAY).getStateFromMeta(4));
      world.setBlockState(pos.add(32, 18, 38), ((BlockColored)Blocks.STAINED_HARDENED_CLAY).getStateFromMeta(7));
      world.setBlockState(pos.add(33, 18, 38), ((BlockColored)Blocks.STAINED_HARDENED_CLAY).getStateFromMeta(7));
      world.setBlockState(pos.add(34, 18, 38), ((BlockColored)Blocks.STAINED_HARDENED_CLAY).getStateFromMeta(4));
      world.setBlockState(pos.add(35, 18, 38), ((BlockColored)Blocks.STAINED_HARDENED_CLAY).getStateFromMeta(4));
      world.setBlockState(pos.add(17, 18, 39), ((BlockColored)Blocks.STAINED_HARDENED_CLAY).getStateFromMeta(4));
      world.setBlockState(pos.add(20, 18, 39), ((BlockColored)Blocks.STAINED_HARDENED_CLAY).getStateFromMeta(4));
      world.setBlockState(pos.add(23, 18, 39), ((BlockColored)Blocks.STAINED_HARDENED_CLAY).getStateFromMeta(4));
      world.setBlockState(pos.add(29, 18, 39), ((BlockColored)Blocks.STAINED_HARDENED_CLAY).getStateFromMeta(4));
      world.setBlockState(pos.add(32, 18, 39), ((BlockColored)Blocks.STAINED_HARDENED_CLAY).getStateFromMeta(4));
      world.setBlockState(pos.add(35, 18, 39), ((BlockColored)Blocks.STAINED_HARDENED_CLAY).getStateFromMeta(4));
      world.setBlockState(pos.add(17, 18, 40), ((BlockColored)Blocks.STAINED_HARDENED_CLAY).getStateFromMeta(4));
      world.setBlockState(pos.add(20, 18, 40), ((BlockColored)Blocks.STAINED_HARDENED_CLAY).getStateFromMeta(4));
      world.setBlockState(pos.add(23, 18, 40), ((BlockColored)Blocks.STAINED_HARDENED_CLAY).getStateFromMeta(4));
      world.setBlockState(pos.add(29, 18, 40), ((BlockColored)Blocks.STAINED_HARDENED_CLAY).getStateFromMeta(4));
      world.setBlockState(pos.add(32, 18, 40), ((BlockColored)Blocks.STAINED_HARDENED_CLAY).getStateFromMeta(4));
      world.setBlockState(pos.add(34, 18, 40), ((BlockColored)Blocks.STAINED_HARDENED_CLAY).getStateFromMeta(4));
      world.setBlockState(pos.add(35, 18, 40), ((BlockColored)Blocks.STAINED_HARDENED_CLAY).getStateFromMeta(4));
      world.setBlockState(pos.add(5, 18, 41), Blocks.STONE.getDefaultState());
      world.setBlockState(pos.add(6, 18, 41), Blocks.STONE.getDefaultState());
      world.setBlockState(pos.add(7, 18, 41), Blocks.STONE.getDefaultState());
      world.setBlockState(pos.add(18, 18, 41), Blocks.QUARTZ_BLOCK.getDefaultState());
      world.setBlockState(pos.add(20, 18, 41), Blocks.QUARTZ_BLOCK.getDefaultState());
      world.setBlockState(pos.add(23, 18, 41), ((BlockColored)Blocks.STAINED_HARDENED_CLAY).getStateFromMeta(4));
      world.setBlockState(pos.add(26, 18, 41), Blocks.STONE.getDefaultState());
      world.setBlockState(pos.add(27, 18, 41), Blocks.STONE.getDefaultState());
      world.setBlockState(pos.add(29, 18, 41), ((BlockColored)Blocks.STAINED_HARDENED_CLAY).getStateFromMeta(4));
      world.setBlockState(pos.add(32, 18, 41), Blocks.QUARTZ_BLOCK.getDefaultState());
      world.setBlockState(pos.add(34, 18, 41), Blocks.QUARTZ_BLOCK.getDefaultState());
      world.setBlockState(pos.add(4, 18, 42), Blocks.STONE.getDefaultState());
      world.setBlockState(pos.add(5, 18, 42), Blocks.STONE.getDefaultState());
      world.setBlockState(pos.add(6, 18, 42), Blocks.STONE.getDefaultState());
      world.setBlockState(pos.add(7, 18, 42), Blocks.STONE.getDefaultState());
      world.setBlockState(pos.add(8, 18, 42), Blocks.STONE.getDefaultState());
      world.setBlockState(pos.add(18, 18, 42), Blocks.QUARTZ_BLOCK.getDefaultState());
      world.setBlockState(pos.add(20, 18, 42), Blocks.QUARTZ_BLOCK.getDefaultState());
      world.setBlockState(pos.add(23, 18, 42), ((BlockColored)Blocks.STAINED_HARDENED_CLAY).getStateFromMeta(4));
      world.setBlockState(pos.add(26, 18, 42), Blocks.STONE.getDefaultState());
      world.setBlockState(pos.add(27, 18, 42), Blocks.STONE.getDefaultState());
      world.setBlockState(pos.add(29, 18, 42), ((BlockColored)Blocks.STAINED_HARDENED_CLAY).getStateFromMeta(4));
      world.setBlockState(pos.add(32, 18, 42), Blocks.QUARTZ_BLOCK.getDefaultState());
      world.setBlockState(pos.add(34, 18, 42), Blocks.QUARTZ_BLOCK.getDefaultState());
      world.setBlockState(pos.add(4, 18, 43), Blocks.STONE.getDefaultState());
      world.setBlockState(pos.add(5, 18, 43), Blocks.STONE.getDefaultState());
      world.setBlockState(pos.add(6, 18, 43), Blocks.STONE.getDefaultState());
      world.setBlockState(pos.add(7, 18, 43), Blocks.STONE.getDefaultState());
      world.setBlockState(pos.add(8, 18, 43), Blocks.STONE.getDefaultState());
      world.setBlockState(pos.add(17, 18, 43), ((BlockColored)Blocks.STAINED_HARDENED_CLAY).getStateFromMeta(4));
      world.setBlockState(pos.add(20, 18, 43), ((BlockColored)Blocks.STAINED_HARDENED_CLAY).getStateFromMeta(4));
      world.setBlockState(pos.add(23, 18, 43), ((BlockColored)Blocks.STAINED_HARDENED_CLAY).getStateFromMeta(4));
      world.setBlockState(pos.add(29, 18, 43), ((BlockColored)Blocks.STAINED_HARDENED_CLAY).getStateFromMeta(4));
      world.setBlockState(pos.add(32, 18, 43), ((BlockColored)Blocks.STAINED_HARDENED_CLAY).getStateFromMeta(4));
      world.setBlockState(pos.add(35, 18, 43), ((BlockColored)Blocks.STAINED_HARDENED_CLAY).getStateFromMeta(4));
      world.setBlockState(pos.add(4, 18, 44), Blocks.STONE.getDefaultState());
      world.setBlockState(pos.add(5, 18, 44), Blocks.STONE.getDefaultState());
      world.setBlockState(pos.add(6, 18, 44), Blocks.STONE.getDefaultState());
      world.setBlockState(pos.add(7, 18, 44), Blocks.STONE.getDefaultState());
      world.setBlockState(pos.add(8, 18, 44), Blocks.STONE.getDefaultState());
      world.setBlockState(pos.add(17, 18, 44), ((BlockColored)Blocks.STAINED_HARDENED_CLAY).getStateFromMeta(4));
      world.setBlockState(pos.add(20, 18, 44), ((BlockColored)Blocks.STAINED_HARDENED_CLAY).getStateFromMeta(4));
      world.setBlockState(pos.add(23, 18, 44), ((BlockColored)Blocks.STAINED_HARDENED_CLAY).getStateFromMeta(4));
      world.setBlockState(pos.add(29, 18, 44), ((BlockColored)Blocks.STAINED_HARDENED_CLAY).getStateFromMeta(4));
      world.setBlockState(pos.add(32, 18, 44), ((BlockColored)Blocks.STAINED_HARDENED_CLAY).getStateFromMeta(4));
      world.setBlockState(pos.add(35, 18, 44), ((BlockColored)Blocks.STAINED_HARDENED_CLAY).getStateFromMeta(4));
      world.setBlockState(pos.add(5, 18, 45), Blocks.STONE.getDefaultState());
      world.setBlockState(pos.add(6, 18, 45), Blocks.STONE.getDefaultState());
      world.setBlockState(pos.add(7, 18, 45), Blocks.STONE.getDefaultState());
      world.setBlockState(pos.add(17, 18, 45), ((BlockColored)Blocks.STAINED_HARDENED_CLAY).getStateFromMeta(4));
      world.setBlockState(pos.add(20, 18, 45), ((BlockColored)Blocks.STAINED_HARDENED_CLAY).getStateFromMeta(4));
      world.setBlockState(pos.add(23, 18, 45), ((BlockColored)Blocks.STAINED_HARDENED_CLAY).getStateFromMeta(4));
      world.setBlockState(pos.add(29, 18, 45), ((BlockColored)Blocks.STAINED_HARDENED_CLAY).getStateFromMeta(4));
      world.setBlockState(pos.add(32, 18, 45), ((BlockColored)Blocks.STAINED_HARDENED_CLAY).getStateFromMeta(4));
      world.setBlockState(pos.add(35, 18, 45), ((BlockColored)Blocks.STAINED_HARDENED_CLAY).getStateFromMeta(4));
      world.setBlockState(pos.add(18, 18, 46), Blocks.QUARTZ_BLOCK.getDefaultState());
      world.setBlockState(pos.add(19, 18, 46), Blocks.QUARTZ_BLOCK.getDefaultState());
      world.setBlockState(pos.add(20, 18, 46), Blocks.QUARTZ_BLOCK.getDefaultState());
      world.setBlockState(pos.add(23, 18, 46), ((BlockColored)Blocks.STAINED_HARDENED_CLAY).getStateFromMeta(4));
      world.setBlockState(pos.add(25, 18, 46), Blocks.STONE.getDefaultState());
      world.setBlockState(pos.add(26, 18, 46), Blocks.STONE.getDefaultState());
      world.setBlockState(pos.add(29, 18, 46), ((BlockColored)Blocks.STAINED_HARDENED_CLAY).getStateFromMeta(4));
      world.setBlockState(pos.add(32, 18, 46), Blocks.QUARTZ_BLOCK.getDefaultState());
      world.setBlockState(pos.add(34, 18, 46), Blocks.QUARTZ_BLOCK.getDefaultState());
      world.setBlockState(pos.add(18, 18, 47), Blocks.QUARTZ_BLOCK.getDefaultState());
      world.setBlockState(pos.add(19, 18, 47), Blocks.QUARTZ_BLOCK.getDefaultState());
      world.setBlockState(pos.add(20, 18, 47), Blocks.QUARTZ_BLOCK.getDefaultState());
      world.setBlockState(pos.add(23, 18, 47), ((BlockColored)Blocks.STAINED_HARDENED_CLAY).getStateFromMeta(4));
      world.setBlockState(pos.add(25, 18, 47), Blocks.STONE.getDefaultState());
      world.setBlockState(pos.add(26, 18, 47), Blocks.STONE.getDefaultState());
      world.setBlockState(pos.add(29, 18, 47), ((BlockColored)Blocks.STAINED_HARDENED_CLAY).getStateFromMeta(4));
      world.setBlockState(pos.add(32, 18, 47), Blocks.QUARTZ_BLOCK.getDefaultState());
      world.setBlockState(pos.add(34, 18, 47), Blocks.QUARTZ_BLOCK.getDefaultState());
      world.setBlockState(pos.add(17, 18, 48), ((BlockColored)Blocks.STAINED_HARDENED_CLAY).getStateFromMeta(4));
      world.setBlockState(pos.add(20, 18, 48), ((BlockColored)Blocks.STAINED_HARDENED_CLAY).getStateFromMeta(4));
      world.setBlockState(pos.add(23, 18, 48), ((BlockColored)Blocks.STAINED_HARDENED_CLAY).getStateFromMeta(4));
      world.setBlockState(pos.add(29, 18, 48), ((BlockColored)Blocks.STAINED_HARDENED_CLAY).getStateFromMeta(4));
      world.setBlockState(pos.add(32, 18, 48), ((BlockColored)Blocks.STAINED_HARDENED_CLAY).getStateFromMeta(4));
      world.setBlockState(pos.add(35, 18, 48), ((BlockColored)Blocks.STAINED_HARDENED_CLAY).getStateFromMeta(4));
      world.setBlockState(pos.add(17, 18, 49), ((BlockColored)Blocks.STAINED_HARDENED_CLAY).getStateFromMeta(4));
      world.setBlockState(pos.add(20, 18, 49), ((BlockColored)Blocks.STAINED_HARDENED_CLAY).getStateFromMeta(4));
      world.setBlockState(pos.add(23, 18, 49), ((BlockColored)Blocks.STAINED_HARDENED_CLAY).getStateFromMeta(4));
      world.setBlockState(pos.add(29, 18, 49), ((BlockColored)Blocks.STAINED_HARDENED_CLAY).getStateFromMeta(4));
      world.setBlockState(pos.add(32, 18, 49), ((BlockColored)Blocks.STAINED_HARDENED_CLAY).getStateFromMeta(4));
      world.setBlockState(pos.add(35, 18, 49), ((BlockColored)Blocks.STAINED_HARDENED_CLAY).getStateFromMeta(4));
      world.setBlockState(pos.add(17, 18, 50), ((BlockColored)Blocks.STAINED_HARDENED_CLAY).getStateFromMeta(4));
      world.setBlockState(pos.add(18, 18, 50), ((BlockColored)Blocks.STAINED_HARDENED_CLAY).getStateFromMeta(4));
      world.setBlockState(pos.add(19, 18, 50), ((BlockColored)Blocks.STAINED_HARDENED_CLAY).getStateFromMeta(4));
      world.setBlockState(pos.add(20, 18, 50), ((BlockColored)Blocks.STAINED_HARDENED_CLAY).getStateFromMeta(4));
      world.setBlockState(pos.add(21, 18, 50), ((BlockColored)Blocks.STAINED_HARDENED_CLAY).getStateFromMeta(4));
      world.setBlockState(pos.add(23, 18, 50), ((BlockColored)Blocks.STAINED_HARDENED_CLAY).getStateFromMeta(4));
      world.setBlockState(pos.add(29, 18, 50), ((BlockColored)Blocks.STAINED_HARDENED_CLAY).getStateFromMeta(4));
      world.setBlockState(pos.add(31, 18, 50), ((BlockColored)Blocks.STAINED_HARDENED_CLAY).getStateFromMeta(4));
      world.setBlockState(pos.add(32, 18, 50), ((BlockColored)Blocks.STAINED_HARDENED_CLAY).getStateFromMeta(4));
      world.setBlockState(pos.add(33, 18, 50), ((BlockColored)Blocks.STAINED_HARDENED_CLAY).getStateFromMeta(4));
      world.setBlockState(pos.add(34, 18, 50), ((BlockColored)Blocks.STAINED_HARDENED_CLAY).getStateFromMeta(4));
      world.setBlockState(pos.add(35, 18, 50), ((BlockColored)Blocks.STAINED_HARDENED_CLAY).getStateFromMeta(4));
      world.setBlockState(pos.add(18, 18, 51), ((BlockColored)Blocks.STAINED_HARDENED_CLAY).getStateFromMeta(4));
      world.setBlockState(pos.add(19, 18, 51), ((BlockColored)Blocks.STAINED_HARDENED_CLAY).getStateFromMeta(4));
      world.setBlockState(pos.add(20, 18, 51), ((BlockColored)Blocks.STAINED_HARDENED_CLAY).getStateFromMeta(4));
      world.setBlockState(pos.add(21, 18, 51), ((BlockColored)Blocks.STAINED_HARDENED_CLAY).getStateFromMeta(4));
      world.setBlockState(pos.add(22, 18, 51), ((BlockColored)Blocks.STAINED_HARDENED_CLAY).getStateFromMeta(4));
      world.setBlockState(pos.add(23, 18, 51), ((BlockColored)Blocks.STAINED_HARDENED_CLAY).getStateFromMeta(4));
      world.setBlockState(pos.add(24, 18, 51), ((BlockColored)Blocks.STAINED_HARDENED_CLAY).getStateFromMeta(4));
      world.setBlockState(pos.add(25, 18, 51), ((BlockColored)Blocks.STAINED_HARDENED_CLAY).getStateFromMeta(4));
      world.setBlockState(pos.add(26, 18, 51), ((BlockColored)Blocks.STAINED_HARDENED_CLAY).getStateFromMeta(4));
      world.setBlockState(pos.add(27, 18, 51), ((BlockColored)Blocks.STAINED_HARDENED_CLAY).getStateFromMeta(4));
      world.setBlockState(pos.add(28, 18, 51), ((BlockColored)Blocks.STAINED_HARDENED_CLAY).getStateFromMeta(4));
      world.setBlockState(pos.add(29, 18, 51), ((BlockColored)Blocks.STAINED_HARDENED_CLAY).getStateFromMeta(4));
      world.setBlockState(pos.add(30, 18, 51), ((BlockColored)Blocks.STAINED_HARDENED_CLAY).getStateFromMeta(4));
      world.setBlockState(pos.add(31, 18, 51), ((BlockColored)Blocks.STAINED_HARDENED_CLAY).getStateFromMeta(4));
      world.setBlockState(pos.add(32, 18, 51), ((BlockColored)Blocks.STAINED_HARDENED_CLAY).getStateFromMeta(4));
      world.setBlockState(pos.add(33, 18, 51), ((BlockColored)Blocks.STAINED_HARDENED_CLAY).getStateFromMeta(4));
      world.setBlockState(pos.add(34, 18, 51), ((BlockColored)Blocks.STAINED_HARDENED_CLAY).getStateFromMeta(4));
      world.setBlockState(pos.add(17, 18, 52), ((BlockColored)Blocks.STAINED_HARDENED_CLAY).getStateFromMeta(4));
      world.setBlockState(pos.add(18, 18, 52), ((BlockColored)Blocks.STAINED_HARDENED_CLAY).getStateFromMeta(4));
      world.setBlockState(pos.add(22, 18, 52), ((BlockColored)Blocks.STAINED_HARDENED_CLAY).getStateFromMeta(4));
      world.setBlockState(pos.add(23, 18, 52), ((BlockColored)Blocks.STAINED_HARDENED_CLAY).getStateFromMeta(4));
      world.setBlockState(pos.add(26, 18, 52), ((BlockStone)Blocks.STONE).getStateFromMeta(4));
      world.setBlockState(pos.add(29, 18, 52), ((BlockColored)Blocks.STAINED_HARDENED_CLAY).getStateFromMeta(4));
      world.setBlockState(pos.add(30, 18, 52), ((BlockColored)Blocks.STAINED_HARDENED_CLAY).getStateFromMeta(4));
      world.setBlockState(pos.add(34, 18, 52), ((BlockColored)Blocks.STAINED_HARDENED_CLAY).getStateFromMeta(4));
      world.setBlockState(pos.add(35, 18, 52), ((BlockColored)Blocks.STAINED_HARDENED_CLAY).getStateFromMeta(4));
      world.setBlockState(pos.add(16, 18, 53), ((BlockColored)Blocks.STAINED_HARDENED_CLAY).getStateFromMeta(4));
      world.setBlockState(pos.add(17, 18, 53), ((BlockColored)Blocks.STAINED_HARDENED_CLAY).getStateFromMeta(4));
      world.setBlockState(pos.add(23, 18, 53), ((BlockColored)Blocks.STAINED_HARDENED_CLAY).getStateFromMeta(4));
      world.setBlockState(pos.add(24, 18, 53), ((BlockColored)Blocks.STAINED_HARDENED_CLAY).getStateFromMeta(4));
      world.setBlockState(pos.add(26, 18, 53), ((BlockStone)Blocks.STONE).getStateFromMeta(4));
      world.setBlockState(pos.add(28, 18, 53), ((BlockColored)Blocks.STAINED_HARDENED_CLAY).getStateFromMeta(4));
      world.setBlockState(pos.add(29, 18, 53), ((BlockColored)Blocks.STAINED_HARDENED_CLAY).getStateFromMeta(4));
      world.setBlockState(pos.add(35, 18, 53), ((BlockColored)Blocks.STAINED_HARDENED_CLAY).getStateFromMeta(4));
      world.setBlockState(pos.add(36, 18, 53), ((BlockColored)Blocks.STAINED_HARDENED_CLAY).getStateFromMeta(4));
      world.setBlockState(pos.add(16, 18, 54), ((BlockColored)Blocks.STAINED_HARDENED_CLAY).getStateFromMeta(4));
      world.setBlockState(pos.add(17, 18, 54), ((BlockColored)Blocks.STAINED_HARDENED_CLAY).getStateFromMeta(4));
      world.setBlockState(pos.add(23, 18, 54), ((BlockColored)Blocks.STAINED_HARDENED_CLAY).getStateFromMeta(4));
      world.setBlockState(pos.add(24, 18, 54), ((BlockColored)Blocks.STAINED_HARDENED_CLAY).getStateFromMeta(4));
      world.setBlockState(pos.add(26, 18, 54), ((BlockStone)Blocks.STONE).getStateFromMeta(4));
      world.setBlockState(pos.add(28, 18, 54), ((BlockColored)Blocks.STAINED_HARDENED_CLAY).getStateFromMeta(4));
      world.setBlockState(pos.add(29, 18, 54), ((BlockColored)Blocks.STAINED_HARDENED_CLAY).getStateFromMeta(4));
      world.setBlockState(pos.add(35, 18, 54), ((BlockColored)Blocks.STAINED_HARDENED_CLAY).getStateFromMeta(4));
      world.setBlockState(pos.add(36, 18, 54), ((BlockColored)Blocks.STAINED_HARDENED_CLAY).getStateFromMeta(4));
      world.setBlockState(pos.add(16, 18, 55), ((BlockColored)Blocks.STAINED_HARDENED_CLAY).getStateFromMeta(4));
      world.setBlockState(pos.add(17, 18, 55), ((BlockColored)Blocks.STAINED_HARDENED_CLAY).getStateFromMeta(4));
      world.setBlockState(pos.add(23, 18, 55), ((BlockColored)Blocks.STAINED_HARDENED_CLAY).getStateFromMeta(4));
      world.setBlockState(pos.add(24, 18, 55), ((BlockColored)Blocks.STAINED_HARDENED_CLAY).getStateFromMeta(4));
      world.setBlockState(pos.add(26, 18, 55), ((BlockStone)Blocks.STONE).getStateFromMeta(4));
      world.setBlockState(pos.add(28, 18, 55), ((BlockColored)Blocks.STAINED_HARDENED_CLAY).getStateFromMeta(4));
      world.setBlockState(pos.add(29, 18, 55), ((BlockColored)Blocks.STAINED_HARDENED_CLAY).getStateFromMeta(4));
      world.setBlockState(pos.add(35, 18, 55), ((BlockColored)Blocks.STAINED_HARDENED_CLAY).getStateFromMeta(4));
      world.setBlockState(pos.add(36, 18, 55), ((BlockColored)Blocks.STAINED_HARDENED_CLAY).getStateFromMeta(4));
      world.setBlockState(pos.add(37, 18, 55), ((BlockColored)Blocks.STAINED_HARDENED_CLAY).getStateFromMeta(4));
      world.setBlockState(pos.add(17, 18, 56), ((BlockColored)Blocks.STAINED_HARDENED_CLAY).getStateFromMeta(4));
      world.setBlockState(pos.add(18, 18, 56), ((BlockColored)Blocks.STAINED_HARDENED_CLAY).getStateFromMeta(4));
      world.setBlockState(pos.add(22, 18, 56), ((BlockColored)Blocks.STAINED_HARDENED_CLAY).getStateFromMeta(4));
      world.setBlockState(pos.add(23, 18, 56), ((BlockColored)Blocks.STAINED_HARDENED_CLAY).getStateFromMeta(4));
      world.setBlockState(pos.add(26, 18, 56), ((BlockStone)Blocks.STONE).getStateFromMeta(4));
      world.setBlockState(pos.add(29, 18, 56), ((BlockColored)Blocks.STAINED_HARDENED_CLAY).getStateFromMeta(4));
      world.setBlockState(pos.add(30, 18, 56), ((BlockColored)Blocks.STAINED_HARDENED_CLAY).getStateFromMeta(4));
      world.setBlockState(pos.add(34, 18, 56), ((BlockColored)Blocks.STAINED_HARDENED_CLAY).getStateFromMeta(4));
      world.setBlockState(pos.add(35, 18, 56), ((BlockColored)Blocks.STAINED_HARDENED_CLAY).getStateFromMeta(4));
      world.setBlockState(pos.add(38, 18, 56), ((BlockColored)Blocks.STAINED_HARDENED_CLAY).getStateFromMeta(4));
      world.setBlockState(pos.add(39, 18, 56), ((BlockColored)Blocks.WOOL).getStateFromMeta(15));
      world.setBlockState(pos.add(40, 18, 56), ((BlockColored)Blocks.WOOL).getStateFromMeta(15));
      world.setBlockState(pos.add(18, 18, 57), ((BlockColored)Blocks.STAINED_HARDENED_CLAY).getStateFromMeta(4));
      world.setBlockState(pos.add(19, 18, 57), ((BlockColored)Blocks.STAINED_HARDENED_CLAY).getStateFromMeta(4));
      world.setBlockState(pos.add(20, 18, 57), ((BlockColored)Blocks.STAINED_HARDENED_CLAY).getStateFromMeta(4));
      world.setBlockState(pos.add(21, 18, 57), ((BlockColored)Blocks.STAINED_HARDENED_CLAY).getStateFromMeta(4));
      world.setBlockState(pos.add(22, 18, 57), ((BlockColored)Blocks.STAINED_HARDENED_CLAY).getStateFromMeta(4));
      world.setBlockState(pos.add(26, 18, 57), Blocks.STONE.getDefaultState());
      world.setBlockState(pos.add(30, 18, 57), ((BlockColored)Blocks.STAINED_HARDENED_CLAY).getStateFromMeta(4));
      world.setBlockState(pos.add(31, 18, 57), ((BlockColored)Blocks.STAINED_HARDENED_CLAY).getStateFromMeta(4));
      world.setBlockState(pos.add(32, 18, 57), ((BlockColored)Blocks.STAINED_HARDENED_CLAY).getStateFromMeta(4));
      world.setBlockState(pos.add(33, 18, 57), ((BlockColored)Blocks.STAINED_HARDENED_CLAY).getStateFromMeta(4));
      world.setBlockState(pos.add(34, 18, 57), ((BlockColored)Blocks.STAINED_HARDENED_CLAY).getStateFromMeta(4));
      world.setBlockState(pos.add(39, 18, 57), ((BlockColored)Blocks.STAINED_HARDENED_CLAY).getStateFromMeta(4));
      world.setBlockState(pos.add(41, 18, 57), ((BlockColored)Blocks.WOOL).getStateFromMeta(15));
      world.setBlockState(pos.add(19, 18, 58), ((BlockColored)Blocks.STAINED_HARDENED_CLAY).getStateFromMeta(4));
      world.setBlockState(pos.add(20, 18, 58), ((BlockColored)Blocks.STAINED_HARDENED_CLAY).getStateFromMeta(4));
      world.setBlockState(pos.add(21, 18, 58), ((BlockColored)Blocks.STAINED_HARDENED_CLAY).getStateFromMeta(4));
      world.setBlockState(pos.add(26, 18, 58), Blocks.STONE.getDefaultState());
      world.setBlockState(pos.add(31, 18, 58), ((BlockColored)Blocks.STAINED_HARDENED_CLAY).getStateFromMeta(4));
      world.setBlockState(pos.add(32, 18, 58), ((BlockColored)Blocks.STAINED_HARDENED_CLAY).getStateFromMeta(4));
      world.setBlockState(pos.add(33, 18, 58), ((BlockColored)Blocks.STAINED_HARDENED_CLAY).getStateFromMeta(4));
      world.setBlockState(pos.add(40, 18, 58), ((BlockColored)Blocks.STAINED_HARDENED_CLAY).getStateFromMeta(4));
      world.setBlockState(pos.add(42, 18, 58), ((BlockColored)Blocks.WOOL).getStateFromMeta(15));
      world.setBlockState(pos.add(26, 18, 59), Blocks.STONE.getDefaultState());
      world.setBlockState(pos.add(34, 18, 59), Blocks.REDSTONE_BLOCK.getDefaultState());
      world.setBlockState(pos.add(35, 18, 59), Blocks.REDSTONE_BLOCK.getDefaultState());
      world.setBlockState(pos.add(36, 18, 59), Blocks.REDSTONE_BLOCK.getDefaultState());
      world.setBlockState(pos.add(37, 18, 59), Blocks.REDSTONE_BLOCK.getDefaultState());
      world.setBlockState(pos.add(41, 18, 59), ((BlockColored)Blocks.STAINED_HARDENED_CLAY).getStateFromMeta(4));
      world.setBlockState(pos.add(42, 18, 59), ((BlockColored)Blocks.WOOL).getStateFromMeta(15));
      world.setBlockState(pos.add(26, 18, 60), Blocks.STONE.getDefaultState());
      world.setBlockState(pos.add(33, 18, 60), Blocks.REDSTONE_BLOCK.getDefaultState());
      world.setBlockState(pos.add(38, 18, 60), Blocks.REDSTONE_BLOCK.getDefaultState());
      world.setBlockState(pos.add(42, 18, 60), Blocks.STONE.getDefaultState());
      world.setBlockState(pos.add(43, 18, 60), Blocks.STONE.getDefaultState());
      world.setBlockState(pos.add(44, 18, 60), Blocks.STONE.getDefaultState());
      world.setBlockState(pos.add(45, 18, 60), Blocks.STONE.getDefaultState());
      world.setBlockState(pos.add(25, 18, 61), Blocks.STONE.getDefaultState());
      world.setBlockState(pos.add(26, 18, 61), Blocks.STONE.getDefaultState());
      world.setBlockState(pos.add(27, 18, 61), Blocks.STONE.getDefaultState());
      world.setBlockState(pos.add(32, 18, 61), Blocks.REDSTONE_BLOCK.getDefaultState());
      world.setBlockState(pos.add(39, 18, 61), Blocks.REDSTONE_BLOCK.getDefaultState());
      world.setBlockState(pos.add(41, 18, 61), Blocks.STONE.getDefaultState());
      world.setBlockState(pos.add(46, 18, 61), Blocks.STONE.getDefaultState());
      world.setBlockState(pos.add(20, 18, 62), Blocks.STONE.getDefaultState());
      world.setBlockState(pos.add(21, 18, 62), Blocks.STONE.getDefaultState());
      world.setBlockState(pos.add(22, 18, 62), Blocks.STONE.getDefaultState());
      world.setBlockState(pos.add(23, 18, 62), Blocks.STONE.getDefaultState());
      world.setBlockState(pos.add(24, 18, 62), Blocks.STONE.getDefaultState());
      world.setBlockState(pos.add(25, 18, 62), Blocks.STONE.getDefaultState());
      world.setBlockState(pos.add(26, 18, 62), Blocks.STONE.getDefaultState());
      world.setBlockState(pos.add(27, 18, 62), Blocks.STONE.getDefaultState());
      world.setBlockState(pos.add(32, 18, 62), Blocks.REDSTONE_BLOCK.getDefaultState());
      world.setBlockState(pos.add(39, 18, 62), Blocks.REDSTONE_BLOCK.getDefaultState());
      world.setBlockState(pos.add(40, 18, 62), Blocks.STONE.getDefaultState());
      world.setBlockState(pos.add(47, 18, 62), Blocks.STONE.getDefaultState());
      world.setBlockState(pos.add(20, 18, 63), Blocks.STONE.getDefaultState());
      world.setBlockState(pos.add(21, 18, 63), Blocks.STONE.getDefaultState());
      world.setBlockState(pos.add(22, 18, 63), Blocks.STONE.getDefaultState());
      world.setBlockState(pos.add(23, 18, 63), Blocks.STONE.getDefaultState());
      world.setBlockState(pos.add(24, 18, 63), Blocks.STONE.getDefaultState());
      world.setBlockState(pos.add(25, 18, 63), Blocks.STONE.getDefaultState());
      world.setBlockState(pos.add(26, 18, 63), Blocks.STONE.getDefaultState());
      world.setBlockState(pos.add(27, 18, 63), Blocks.STONE.getDefaultState());
      world.setBlockState(pos.add(32, 18, 63), Blocks.REDSTONE_BLOCK.getDefaultState());
      world.setBlockState(pos.add(39, 18, 63), Blocks.REDSTONE_BLOCK.getDefaultState());
      world.setBlockState(pos.add(40, 18, 63), Blocks.STONE.getDefaultState());
      world.setBlockState(pos.add(47, 18, 63), Blocks.STONE.getDefaultState());
      world.setBlockState(pos.add(32, 18, 64), Blocks.REDSTONE_BLOCK.getDefaultState());
      world.setBlockState(pos.add(39, 18, 64), Blocks.REDSTONE_BLOCK.getDefaultState());
      world.setBlockState(pos.add(40, 18, 64), Blocks.STONE.getDefaultState());
      world.setBlockState(pos.add(47, 18, 64), Blocks.STONE.getDefaultState());
      world.setBlockState(pos.add(33, 18, 65), Blocks.REDSTONE_BLOCK.getDefaultState());
      world.setBlockState(pos.add(38, 18, 65), Blocks.REDSTONE_BLOCK.getDefaultState());
      world.setBlockState(pos.add(40, 18, 65), Blocks.STONE.getDefaultState());
      world.setBlockState(pos.add(47, 18, 65), Blocks.STONE.getDefaultState());
      world.setBlockState(pos.add(34, 18, 66), Blocks.REDSTONE_BLOCK.getDefaultState());
      world.setBlockState(pos.add(35, 18, 66), Blocks.REDSTONE_BLOCK.getDefaultState());
      world.setBlockState(pos.add(36, 18, 66), Blocks.REDSTONE_BLOCK.getDefaultState());
      world.setBlockState(pos.add(37, 18, 66), Blocks.REDSTONE_BLOCK.getDefaultState());
      world.setBlockState(pos.add(41, 18, 66), Blocks.STONE.getDefaultState());
      world.setBlockState(pos.add(46, 18, 66), Blocks.STONE.getDefaultState());
      world.setBlockState(pos.add(42, 18, 67), Blocks.STONE.getDefaultState());
      world.setBlockState(pos.add(43, 18, 67), Blocks.STONE.getDefaultState());
      world.setBlockState(pos.add(44, 18, 67), Blocks.STONE.getDefaultState());
      world.setBlockState(pos.add(45, 18, 67), Blocks.STONE.getDefaultState());
      world.setBlockState(pos.add(26, 19, 36), Blocks.NETHER_BRICK_FENCE.getDefaultState());
      world.setBlockState(pos.add(17, 19, 37), ((BlockColored)Blocks.STAINED_HARDENED_CLAY).getStateFromMeta(4));
      world.setBlockState(pos.add(18, 19, 37), ((BlockColored)Blocks.STAINED_HARDENED_CLAY).getStateFromMeta(4));
      world.setBlockState(pos.add(19, 19, 37), ((BlockColored)Blocks.STAINED_HARDENED_CLAY).getStateFromMeta(4));
      world.setBlockState(pos.add(20, 19, 37), ((BlockColored)Blocks.STAINED_HARDENED_CLAY).getStateFromMeta(4));
      world.setBlockState(pos.add(23, 19, 37), ((BlockColored)Blocks.STAINED_HARDENED_CLAY).getStateFromMeta(4));
      world.setBlockState(pos.add(24, 19, 37), ((BlockColored)Blocks.STAINED_HARDENED_CLAY).getStateFromMeta(4));
      world.setBlockState(pos.add(25, 19, 37), ((BlockColored)Blocks.STAINED_HARDENED_CLAY).getStateFromMeta(4));
      world.setBlockState(pos.add(26, 19, 37), ((BlockColored)Blocks.STAINED_HARDENED_CLAY).getStateFromMeta(4));
      world.setBlockState(pos.add(27, 19, 37), ((BlockColored)Blocks.STAINED_HARDENED_CLAY).getStateFromMeta(4));
      world.setBlockState(pos.add(28, 19, 37), ((BlockColored)Blocks.STAINED_HARDENED_CLAY).getStateFromMeta(4));
      world.setBlockState(pos.add(29, 19, 37), ((BlockColored)Blocks.STAINED_HARDENED_CLAY).getStateFromMeta(4));
      world.setBlockState(pos.add(32, 19, 37), ((BlockColored)Blocks.STAINED_HARDENED_CLAY).getStateFromMeta(4));
      world.setBlockState(pos.add(33, 19, 37), ((BlockColored)Blocks.STAINED_HARDENED_CLAY).getStateFromMeta(4));
      world.setBlockState(pos.add(34, 19, 37), ((BlockColored)Blocks.STAINED_HARDENED_CLAY).getStateFromMeta(4));
      world.setBlockState(pos.add(35, 19, 37), ((BlockColored)Blocks.STAINED_HARDENED_CLAY).getStateFromMeta(4));
      world.setBlockState(pos.add(17, 19, 38), ((BlockColored)Blocks.STAINED_HARDENED_CLAY).getStateFromMeta(4));
      world.setBlockState(pos.add(18, 19, 38), ((BlockColored)Blocks.STAINED_HARDENED_CLAY).getStateFromMeta(4));
      world.setBlockState(pos.add(19, 19, 38), ((BlockColored)Blocks.STAINED_HARDENED_CLAY).getStateFromMeta(4));
      world.setBlockState(pos.add(20, 19, 38), ((BlockColored)Blocks.STAINED_HARDENED_CLAY).getStateFromMeta(4));
      world.setBlockState(pos.add(23, 19, 38), ((BlockColored)Blocks.STAINED_HARDENED_CLAY).getStateFromMeta(4));
      world.setBlockState(pos.add(29, 19, 38), ((BlockColored)Blocks.STAINED_HARDENED_CLAY).getStateFromMeta(4));
      world.setBlockState(pos.add(32, 19, 38), ((BlockColored)Blocks.STAINED_HARDENED_CLAY).getStateFromMeta(4));
      world.setBlockState(pos.add(33, 19, 38), ((BlockColored)Blocks.STAINED_HARDENED_CLAY).getStateFromMeta(4));
      world.setBlockState(pos.add(34, 19, 38), ((BlockColored)Blocks.STAINED_HARDENED_CLAY).getStateFromMeta(4));
      world.setBlockState(pos.add(35, 19, 38), ((BlockColored)Blocks.STAINED_HARDENED_CLAY).getStateFromMeta(4));
      world.setBlockState(pos.add(17, 19, 39), ((BlockColored)Blocks.STAINED_HARDENED_CLAY).getStateFromMeta(4));
      world.setBlockState(pos.add(20, 19, 39), ((BlockColored)Blocks.STAINED_HARDENED_CLAY).getStateFromMeta(4));
      world.setBlockState(pos.add(23, 19, 39), ((BlockColored)Blocks.STAINED_HARDENED_CLAY).getStateFromMeta(4));
      world.setBlockState(pos.add(29, 19, 39), ((BlockColored)Blocks.STAINED_HARDENED_CLAY).getStateFromMeta(4));
      world.setBlockState(pos.add(32, 19, 39), ((BlockColored)Blocks.STAINED_HARDENED_CLAY).getStateFromMeta(4));
      world.setBlockState(pos.add(34, 19, 39), ((BlockColored)Blocks.STAINED_HARDENED_CLAY).getStateFromMeta(4));
      world.setBlockState(pos.add(35, 19, 39), ((BlockColored)Blocks.STAINED_HARDENED_CLAY).getStateFromMeta(4));
      world.setBlockState(pos.add(17, 19, 40), ((BlockColored)Blocks.STAINED_HARDENED_CLAY).getStateFromMeta(4));
      world.setBlockState(pos.add(20, 19, 40), ((BlockColored)Blocks.STAINED_HARDENED_CLAY).getStateFromMeta(4));
      world.setBlockState(pos.add(23, 19, 40), ((BlockColored)Blocks.STAINED_HARDENED_CLAY).getStateFromMeta(4));
      world.setBlockState(pos.add(29, 19, 40), ((BlockColored)Blocks.STAINED_HARDENED_CLAY).getStateFromMeta(4));
      world.setBlockState(pos.add(32, 19, 40), ((BlockColored)Blocks.STAINED_HARDENED_CLAY).getStateFromMeta(4));
      world.setBlockState(pos.add(34, 19, 40), ((BlockColored)Blocks.STAINED_HARDENED_CLAY).getStateFromMeta(4));
      world.setBlockState(pos.add(35, 19, 40), ((BlockColored)Blocks.STAINED_HARDENED_CLAY).getStateFromMeta(4));
      world.setBlockState(pos.add(18, 19, 41), Blocks.QUARTZ_BLOCK.getDefaultState());
      world.setBlockState(pos.add(20, 19, 41), Blocks.QUARTZ_BLOCK.getDefaultState());
      world.setBlockState(pos.add(23, 19, 41), ((BlockColored)Blocks.STAINED_HARDENED_CLAY).getStateFromMeta(4));
      world.setBlockState(pos.add(26, 19, 41), Blocks.STONE.getDefaultState());
      world.setBlockState(pos.add(27, 19, 41), Blocks.STONE.getDefaultState());
      world.setBlockState(pos.add(29, 19, 41), ((BlockColored)Blocks.STAINED_HARDENED_CLAY).getStateFromMeta(4));
      world.setBlockState(pos.add(32, 19, 41), Blocks.QUARTZ_BLOCK.getDefaultState());
      world.setBlockState(pos.add(34, 19, 41), Blocks.QUARTZ_BLOCK.getDefaultState());
      world.setBlockState(pos.add(18, 19, 42), Blocks.QUARTZ_BLOCK.getDefaultState());
      world.setBlockState(pos.add(20, 19, 42), Blocks.QUARTZ_BLOCK.getDefaultState());
      world.setBlockState(pos.add(23, 19, 42), ((BlockColored)Blocks.STAINED_HARDENED_CLAY).getStateFromMeta(4));
      world.setBlockState(pos.add(26, 19, 42), Blocks.STONE.getDefaultState());
      world.setBlockState(pos.add(27, 19, 42), Blocks.STONE.getDefaultState());
      world.setBlockState(pos.add(29, 19, 42), ((BlockColored)Blocks.STAINED_HARDENED_CLAY).getStateFromMeta(4));
      world.setBlockState(pos.add(32, 19, 42), Blocks.QUARTZ_BLOCK.getDefaultState());
      world.setBlockState(pos.add(34, 19, 42), Blocks.QUARTZ_BLOCK.getDefaultState());
      world.setBlockState(pos.add(17, 19, 43), ((BlockColored)Blocks.STAINED_HARDENED_CLAY).getStateFromMeta(4));
      world.setBlockState(pos.add(20, 19, 43), ((BlockColored)Blocks.STAINED_HARDENED_CLAY).getStateFromMeta(4));
      world.setBlockState(pos.add(23, 19, 43), ((BlockColored)Blocks.STAINED_HARDENED_CLAY).getStateFromMeta(4));
      world.setBlockState(pos.add(29, 19, 43), ((BlockColored)Blocks.STAINED_HARDENED_CLAY).getStateFromMeta(4));
      world.setBlockState(pos.add(32, 19, 43), ((BlockColored)Blocks.STAINED_HARDENED_CLAY).getStateFromMeta(4));
      world.setBlockState(pos.add(35, 19, 43), ((BlockColored)Blocks.STAINED_HARDENED_CLAY).getStateFromMeta(4));
      world.setBlockState(pos.add(17, 19, 44), ((BlockColored)Blocks.STAINED_HARDENED_CLAY).getStateFromMeta(4));
      world.setBlockState(pos.add(20, 19, 44), ((BlockColored)Blocks.STAINED_HARDENED_CLAY).getStateFromMeta(4));
      world.setBlockState(pos.add(23, 19, 44), ((BlockColored)Blocks.STAINED_HARDENED_CLAY).getStateFromMeta(4));
      world.setBlockState(pos.add(29, 19, 44), ((BlockColored)Blocks.STAINED_HARDENED_CLAY).getStateFromMeta(4));
      world.setBlockState(pos.add(32, 19, 44), ((BlockColored)Blocks.STAINED_HARDENED_CLAY).getStateFromMeta(4));
      world.setBlockState(pos.add(35, 19, 44), ((BlockColored)Blocks.STAINED_HARDENED_CLAY).getStateFromMeta(4));
      world.setBlockState(pos.add(17, 19, 45), ((BlockColored)Blocks.STAINED_HARDENED_CLAY).getStateFromMeta(4));
      world.setBlockState(pos.add(20, 19, 45), ((BlockColored)Blocks.STAINED_HARDENED_CLAY).getStateFromMeta(4));
      world.setBlockState(pos.add(23, 19, 45), ((BlockColored)Blocks.STAINED_HARDENED_CLAY).getStateFromMeta(4));
      world.setBlockState(pos.add(29, 19, 45), ((BlockColored)Blocks.STAINED_HARDENED_CLAY).getStateFromMeta(4));
      world.setBlockState(pos.add(32, 19, 45), ((BlockColored)Blocks.STAINED_HARDENED_CLAY).getStateFromMeta(4));
      world.setBlockState(pos.add(35, 19, 45), ((BlockColored)Blocks.STAINED_HARDENED_CLAY).getStateFromMeta(4));
      world.setBlockState(pos.add(18, 19, 46), Blocks.QUARTZ_BLOCK.getDefaultState());
      world.setBlockState(pos.add(19, 19, 46), Blocks.QUARTZ_BLOCK.getDefaultState());
      world.setBlockState(pos.add(20, 19, 46), Blocks.QUARTZ_BLOCK.getDefaultState());
      world.setBlockState(pos.add(23, 19, 46), ((BlockColored)Blocks.STAINED_HARDENED_CLAY).getStateFromMeta(4));
      world.setBlockState(pos.add(25, 19, 46), Blocks.STONE.getDefaultState());
      world.setBlockState(pos.add(26, 19, 46), Blocks.STONE.getDefaultState());
      world.setBlockState(pos.add(29, 19, 46), ((BlockColored)Blocks.STAINED_HARDENED_CLAY).getStateFromMeta(4));
      world.setBlockState(pos.add(32, 19, 46), Blocks.QUARTZ_BLOCK.getDefaultState());
      world.setBlockState(pos.add(34, 19, 46), Blocks.QUARTZ_BLOCK.getDefaultState());
      world.setBlockState(pos.add(18, 19, 47), Blocks.QUARTZ_BLOCK.getDefaultState());
      world.setBlockState(pos.add(19, 19, 47), Blocks.QUARTZ_BLOCK.getDefaultState());
      world.setBlockState(pos.add(20, 19, 47), Blocks.QUARTZ_BLOCK.getDefaultState());
      world.setBlockState(pos.add(23, 19, 47), ((BlockColored)Blocks.STAINED_HARDENED_CLAY).getStateFromMeta(4));
      world.setBlockState(pos.add(25, 19, 47), Blocks.STONE.getDefaultState());
      world.setBlockState(pos.add(26, 19, 47), Blocks.STONE.getDefaultState());
      world.setBlockState(pos.add(29, 19, 47), ((BlockColored)Blocks.STAINED_HARDENED_CLAY).getStateFromMeta(4));
      world.setBlockState(pos.add(32, 19, 47), Blocks.QUARTZ_BLOCK.getDefaultState());
      world.setBlockState(pos.add(34, 19, 47), Blocks.QUARTZ_BLOCK.getDefaultState());
      world.setBlockState(pos.add(17, 19, 48), ((BlockColored)Blocks.STAINED_HARDENED_CLAY).getStateFromMeta(4));
      world.setBlockState(pos.add(20, 19, 48), ((BlockColored)Blocks.STAINED_HARDENED_CLAY).getStateFromMeta(4));
      world.setBlockState(pos.add(23, 19, 48), ((BlockColored)Blocks.STAINED_HARDENED_CLAY).getStateFromMeta(4));
      world.setBlockState(pos.add(29, 19, 48), ((BlockColored)Blocks.STAINED_HARDENED_CLAY).getStateFromMeta(4));
      world.setBlockState(pos.add(32, 19, 48), ((BlockColored)Blocks.STAINED_HARDENED_CLAY).getStateFromMeta(4));
      world.setBlockState(pos.add(35, 19, 48), ((BlockColored)Blocks.STAINED_HARDENED_CLAY).getStateFromMeta(4));
      world.setBlockState(pos.add(17, 19, 49), ((BlockColored)Blocks.STAINED_HARDENED_CLAY).getStateFromMeta(4));
      world.setBlockState(pos.add(20, 19, 49), ((BlockColored)Blocks.STAINED_HARDENED_CLAY).getStateFromMeta(4));
      world.setBlockState(pos.add(23, 19, 49), ((BlockColored)Blocks.STAINED_HARDENED_CLAY).getStateFromMeta(4));
      world.setBlockState(pos.add(29, 19, 49), ((BlockColored)Blocks.STAINED_HARDENED_CLAY).getStateFromMeta(4));
      world.setBlockState(pos.add(32, 19, 49), ((BlockColored)Blocks.STAINED_HARDENED_CLAY).getStateFromMeta(4));
      world.setBlockState(pos.add(35, 19, 49), ((BlockColored)Blocks.STAINED_HARDENED_CLAY).getStateFromMeta(4));
      world.setBlockState(pos.add(17, 19, 50), ((BlockColored)Blocks.STAINED_HARDENED_CLAY).getStateFromMeta(4));
      world.setBlockState(pos.add(18, 19, 50), ((BlockColored)Blocks.STAINED_HARDENED_CLAY).getStateFromMeta(4));
      world.setBlockState(pos.add(19, 19, 50), ((BlockColored)Blocks.STAINED_HARDENED_CLAY).getStateFromMeta(4));
      world.setBlockState(pos.add(20, 19, 50), ((BlockColored)Blocks.STAINED_HARDENED_CLAY).getStateFromMeta(4));
      world.setBlockState(pos.add(21, 19, 50), ((BlockColored)Blocks.STAINED_HARDENED_CLAY).getStateFromMeta(4));
      world.setBlockState(pos.add(23, 19, 50), ((BlockColored)Blocks.STAINED_HARDENED_CLAY).getStateFromMeta(4));
      world.setBlockState(pos.add(29, 19, 50), ((BlockColored)Blocks.STAINED_HARDENED_CLAY).getStateFromMeta(4));
      world.setBlockState(pos.add(31, 19, 50), ((BlockColored)Blocks.STAINED_HARDENED_CLAY).getStateFromMeta(4));
      world.setBlockState(pos.add(32, 19, 50), ((BlockColored)Blocks.STAINED_HARDENED_CLAY).getStateFromMeta(4));
      world.setBlockState(pos.add(33, 19, 50), ((BlockColored)Blocks.STAINED_HARDENED_CLAY).getStateFromMeta(4));
      world.setBlockState(pos.add(34, 19, 50), ((BlockColored)Blocks.STAINED_HARDENED_CLAY).getStateFromMeta(4));
      world.setBlockState(pos.add(35, 19, 50), ((BlockColored)Blocks.STAINED_HARDENED_CLAY).getStateFromMeta(4));
      world.setBlockState(pos.add(18, 19, 51), ((BlockColored)Blocks.STAINED_HARDENED_CLAY).getStateFromMeta(4));
      world.setBlockState(pos.add(19, 19, 51), ((BlockColored)Blocks.STAINED_HARDENED_CLAY).getStateFromMeta(4));
      world.setBlockState(pos.add(20, 19, 51), ((BlockColored)Blocks.STAINED_HARDENED_CLAY).getStateFromMeta(4));
      world.setBlockState(pos.add(21, 19, 51), ((BlockColored)Blocks.STAINED_HARDENED_CLAY).getStateFromMeta(4));
      world.setBlockState(pos.add(22, 19, 51), ((BlockColored)Blocks.STAINED_HARDENED_CLAY).getStateFromMeta(4));
      world.setBlockState(pos.add(23, 19, 51), ((BlockColored)Blocks.STAINED_HARDENED_CLAY).getStateFromMeta(4));
      world.setBlockState(pos.add(24, 19, 51), ((BlockColored)Blocks.STAINED_HARDENED_CLAY).getStateFromMeta(4));
      world.setBlockState(pos.add(25, 19, 51), ((BlockColored)Blocks.STAINED_HARDENED_CLAY).getStateFromMeta(4));
      world.setBlockState(pos.add(26, 19, 51), ((BlockColored)Blocks.STAINED_HARDENED_CLAY).getStateFromMeta(4));
      world.setBlockState(pos.add(27, 19, 51), ((BlockColored)Blocks.STAINED_HARDENED_CLAY).getStateFromMeta(4));
      world.setBlockState(pos.add(28, 19, 51), ((BlockColored)Blocks.STAINED_HARDENED_CLAY).getStateFromMeta(4));
      world.setBlockState(pos.add(29, 19, 51), ((BlockColored)Blocks.STAINED_HARDENED_CLAY).getStateFromMeta(4));
      world.setBlockState(pos.add(30, 19, 51), ((BlockColored)Blocks.STAINED_HARDENED_CLAY).getStateFromMeta(4));
      world.setBlockState(pos.add(31, 19, 51), ((BlockColored)Blocks.STAINED_HARDENED_CLAY).getStateFromMeta(4));
      world.setBlockState(pos.add(32, 19, 51), ((BlockColored)Blocks.STAINED_HARDENED_CLAY).getStateFromMeta(4));
      world.setBlockState(pos.add(33, 19, 51), ((BlockColored)Blocks.STAINED_HARDENED_CLAY).getStateFromMeta(4));
      world.setBlockState(pos.add(34, 19, 51), ((BlockColored)Blocks.STAINED_HARDENED_CLAY).getStateFromMeta(4));
      world.setBlockState(pos.add(17, 19, 52), ((BlockColored)Blocks.STAINED_HARDENED_CLAY).getStateFromMeta(4));
      world.setBlockState(pos.add(18, 19, 52), ((BlockColored)Blocks.STAINED_HARDENED_CLAY).getStateFromMeta(4));
      world.setBlockState(pos.add(22, 19, 52), ((BlockColored)Blocks.STAINED_HARDENED_CLAY).getStateFromMeta(4));
      world.setBlockState(pos.add(23, 19, 52), ((BlockColored)Blocks.STAINED_HARDENED_CLAY).getStateFromMeta(4));
      world.setBlockState(pos.add(29, 19, 52), ((BlockColored)Blocks.STAINED_HARDENED_CLAY).getStateFromMeta(4));
      world.setBlockState(pos.add(30, 19, 52), ((BlockColored)Blocks.STAINED_HARDENED_CLAY).getStateFromMeta(4));
      world.setBlockState(pos.add(34, 19, 52), ((BlockColored)Blocks.STAINED_HARDENED_CLAY).getStateFromMeta(4));
      world.setBlockState(pos.add(35, 19, 52), ((BlockColored)Blocks.STAINED_HARDENED_CLAY).getStateFromMeta(4));
      world.setBlockState(pos.add(16, 19, 53), ((BlockColored)Blocks.STAINED_HARDENED_CLAY).getStateFromMeta(4));
      world.setBlockState(pos.add(17, 19, 53), ((BlockColored)Blocks.STAINED_HARDENED_CLAY).getStateFromMeta(4));
      world.setBlockState(pos.add(23, 19, 53), ((BlockColored)Blocks.STAINED_HARDENED_CLAY).getStateFromMeta(4));
      world.setBlockState(pos.add(24, 19, 53), ((BlockColored)Blocks.STAINED_HARDENED_CLAY).getStateFromMeta(4));
      world.setBlockState(pos.add(28, 19, 53), ((BlockColored)Blocks.STAINED_HARDENED_CLAY).getStateFromMeta(4));
      world.setBlockState(pos.add(29, 19, 53), ((BlockColored)Blocks.STAINED_HARDENED_CLAY).getStateFromMeta(4));
      world.setBlockState(pos.add(35, 19, 53), ((BlockColored)Blocks.STAINED_HARDENED_CLAY).getStateFromMeta(4));
      world.setBlockState(pos.add(36, 19, 53), ((BlockColored)Blocks.STAINED_HARDENED_CLAY).getStateFromMeta(4));
      world.setBlockState(pos.add(16, 19, 54), ((BlockColored)Blocks.STAINED_HARDENED_CLAY).getStateFromMeta(4));
      world.setBlockState(pos.add(17, 19, 54), ((BlockColored)Blocks.STAINED_HARDENED_CLAY).getStateFromMeta(4));
      world.setBlockState(pos.add(23, 19, 54), ((BlockColored)Blocks.STAINED_HARDENED_CLAY).getStateFromMeta(4));
      world.setBlockState(pos.add(24, 19, 54), ((BlockColored)Blocks.STAINED_HARDENED_CLAY).getStateFromMeta(4));
      world.setBlockState(pos.add(28, 19, 54), ((BlockColored)Blocks.STAINED_HARDENED_CLAY).getStateFromMeta(4));
      world.setBlockState(pos.add(29, 19, 54), ((BlockColored)Blocks.STAINED_HARDENED_CLAY).getStateFromMeta(4));
      world.setBlockState(pos.add(35, 19, 54), ((BlockColored)Blocks.STAINED_HARDENED_CLAY).getStateFromMeta(4));
      world.setBlockState(pos.add(36, 19, 54), ((BlockColored)Blocks.STAINED_HARDENED_CLAY).getStateFromMeta(4));
      world.setBlockState(pos.add(16, 19, 55), ((BlockColored)Blocks.STAINED_HARDENED_CLAY).getStateFromMeta(4));
      world.setBlockState(pos.add(17, 19, 55), ((BlockColored)Blocks.STAINED_HARDENED_CLAY).getStateFromMeta(4));
      world.setBlockState(pos.add(23, 19, 55), ((BlockColored)Blocks.STAINED_HARDENED_CLAY).getStateFromMeta(4));
      world.setBlockState(pos.add(24, 19, 55), ((BlockColored)Blocks.STAINED_HARDENED_CLAY).getStateFromMeta(4));
      world.setBlockState(pos.add(28, 19, 55), ((BlockColored)Blocks.STAINED_HARDENED_CLAY).getStateFromMeta(4));
      world.setBlockState(pos.add(29, 19, 55), ((BlockColored)Blocks.STAINED_HARDENED_CLAY).getStateFromMeta(4));
      world.setBlockState(pos.add(35, 19, 55), ((BlockColored)Blocks.STAINED_HARDENED_CLAY).getStateFromMeta(4));
      world.setBlockState(pos.add(36, 19, 55), ((BlockColored)Blocks.STAINED_HARDENED_CLAY).getStateFromMeta(4));
      world.setBlockState(pos.add(37, 19, 55), ((BlockColored)Blocks.STAINED_HARDENED_CLAY).getStateFromMeta(4));
      world.setBlockState(pos.add(17, 19, 56), ((BlockColored)Blocks.STAINED_HARDENED_CLAY).getStateFromMeta(4));
      world.setBlockState(pos.add(18, 19, 56), ((BlockColored)Blocks.STAINED_HARDENED_CLAY).getStateFromMeta(4));
      world.setBlockState(pos.add(22, 19, 56), ((BlockColored)Blocks.STAINED_HARDENED_CLAY).getStateFromMeta(4));
      world.setBlockState(pos.add(23, 19, 56), ((BlockColored)Blocks.STAINED_HARDENED_CLAY).getStateFromMeta(4));
      world.setBlockState(pos.add(29, 19, 56), ((BlockColored)Blocks.STAINED_HARDENED_CLAY).getStateFromMeta(4));
      world.setBlockState(pos.add(30, 19, 56), ((BlockColored)Blocks.STAINED_HARDENED_CLAY).getStateFromMeta(4));
      world.setBlockState(pos.add(34, 19, 56), ((BlockColored)Blocks.STAINED_HARDENED_CLAY).getStateFromMeta(4));
      world.setBlockState(pos.add(35, 19, 56), ((BlockColored)Blocks.STAINED_HARDENED_CLAY).getStateFromMeta(4));
      world.setBlockState(pos.add(38, 19, 56), ((BlockColored)Blocks.STAINED_HARDENED_CLAY).getStateFromMeta(4));
      world.setBlockState(pos.add(39, 19, 56), ((BlockColored)Blocks.WOOL).getStateFromMeta(15));
      world.setBlockState(pos.add(40, 19, 56), ((BlockColored)Blocks.WOOL).getStateFromMeta(15));
      world.setBlockState(pos.add(18, 19, 57), ((BlockColored)Blocks.STAINED_HARDENED_CLAY).getStateFromMeta(4));
      world.setBlockState(pos.add(19, 19, 57), ((BlockColored)Blocks.STAINED_HARDENED_CLAY).getStateFromMeta(4));
      world.setBlockState(pos.add(20, 19, 57), ((BlockColored)Blocks.STAINED_HARDENED_CLAY).getStateFromMeta(4));
      world.setBlockState(pos.add(21, 19, 57), ((BlockColored)Blocks.STAINED_HARDENED_CLAY).getStateFromMeta(4));
      world.setBlockState(pos.add(22, 19, 57), ((BlockColored)Blocks.STAINED_HARDENED_CLAY).getStateFromMeta(4));
      world.setBlockState(pos.add(30, 19, 57), ((BlockColored)Blocks.STAINED_HARDENED_CLAY).getStateFromMeta(4));
      world.setBlockState(pos.add(31, 19, 57), ((BlockColored)Blocks.STAINED_HARDENED_CLAY).getStateFromMeta(4));
      world.setBlockState(pos.add(32, 19, 57), ((BlockColored)Blocks.STAINED_HARDENED_CLAY).getStateFromMeta(4));
      world.setBlockState(pos.add(33, 19, 57), ((BlockColored)Blocks.STAINED_HARDENED_CLAY).getStateFromMeta(4));
      world.setBlockState(pos.add(34, 19, 57), ((BlockColored)Blocks.STAINED_HARDENED_CLAY).getStateFromMeta(4));
      world.setBlockState(pos.add(39, 19, 57), ((BlockColored)Blocks.STAINED_HARDENED_CLAY).getStateFromMeta(4));
      world.setBlockState(pos.add(41, 19, 57), ((BlockColored)Blocks.WOOL).getStateFromMeta(15));
      world.setBlockState(pos.add(19, 19, 58), ((BlockColored)Blocks.STAINED_HARDENED_CLAY).getStateFromMeta(4));
      world.setBlockState(pos.add(20, 19, 58), ((BlockColored)Blocks.STAINED_HARDENED_CLAY).getStateFromMeta(4));
      world.setBlockState(pos.add(21, 19, 58), ((BlockColored)Blocks.STAINED_HARDENED_CLAY).getStateFromMeta(4));
      world.setBlockState(pos.add(31, 19, 58), ((BlockColored)Blocks.STAINED_HARDENED_CLAY).getStateFromMeta(4));
      world.setBlockState(pos.add(32, 19, 58), ((BlockColored)Blocks.STAINED_HARDENED_CLAY).getStateFromMeta(4));
      world.setBlockState(pos.add(33, 19, 58), ((BlockColored)Blocks.STAINED_HARDENED_CLAY).getStateFromMeta(4));
      world.setBlockState(pos.add(40, 19, 58), ((BlockColored)Blocks.STAINED_HARDENED_CLAY).getStateFromMeta(4));
      world.setBlockState(pos.add(42, 19, 58), ((BlockColored)Blocks.WOOL).getStateFromMeta(15));
      world.setBlockState(pos.add(34, 19, 59), ((BlockColored)Blocks.WOOL).getStateFromMeta(15));
      world.setBlockState(pos.add(35, 19, 59), ((BlockColored)Blocks.WOOL).getStateFromMeta(15));
      world.setBlockState(pos.add(36, 19, 59), ((BlockColored)Blocks.WOOL).getStateFromMeta(15));
      world.setBlockState(pos.add(37, 19, 59), ((BlockColored)Blocks.WOOL).getStateFromMeta(15));
      world.setBlockState(pos.add(41, 19, 59), ((BlockColored)Blocks.STAINED_HARDENED_CLAY).getStateFromMeta(4));
      world.setBlockState(pos.add(42, 19, 59), ((BlockColored)Blocks.WOOL).getStateFromMeta(15));
      world.setBlockState(pos.add(33, 19, 60), ((BlockColored)Blocks.WOOL).getStateFromMeta(15));
      world.setBlockState(pos.add(38, 19, 60), ((BlockColored)Blocks.WOOL).getStateFromMeta(15));
      world.setBlockState(pos.add(42, 19, 60), Blocks.STONE.getDefaultState());
      world.setBlockState(pos.add(43, 19, 60), Blocks.STONE.getDefaultState());
      world.setBlockState(pos.add(44, 19, 60), Blocks.STONE.getDefaultState());
      world.setBlockState(pos.add(45, 19, 60), Blocks.STONE.getDefaultState());
      world.setBlockState(pos.add(32, 19, 61), ((BlockColored)Blocks.WOOL).getStateFromMeta(15));
      world.setBlockState(pos.add(39, 19, 61), ((BlockColored)Blocks.WOOL).getStateFromMeta(15));
      world.setBlockState(pos.add(41, 19, 61), Blocks.STONE.getDefaultState());
      world.setBlockState(pos.add(46, 19, 61), Blocks.STONE.getDefaultState());
      world.setBlockState(pos.add(32, 19, 62), ((BlockColored)Blocks.WOOL).getStateFromMeta(15));
      world.setBlockState(pos.add(39, 19, 62), ((BlockColored)Blocks.WOOL).getStateFromMeta(15));
      world.setBlockState(pos.add(40, 19, 62), Blocks.STONE.getDefaultState());
      world.setBlockState(pos.add(47, 19, 62), Blocks.STONE.getDefaultState());
      world.setBlockState(pos.add(32, 19, 63), ((BlockColored)Blocks.WOOL).getStateFromMeta(15));
      world.setBlockState(pos.add(39, 19, 63), ((BlockColored)Blocks.WOOL).getStateFromMeta(15));
      world.setBlockState(pos.add(40, 19, 63), Blocks.STONE.getDefaultState());
      world.setBlockState(pos.add(47, 19, 63), Blocks.STONE.getDefaultState());
      world.setBlockState(pos.add(32, 19, 64), ((BlockColored)Blocks.WOOL).getStateFromMeta(15));
      world.setBlockState(pos.add(39, 19, 64), ((BlockColored)Blocks.WOOL).getStateFromMeta(15));
      world.setBlockState(pos.add(40, 19, 64), Blocks.STONE.getDefaultState());
      world.setBlockState(pos.add(47, 19, 64), Blocks.STONE.getDefaultState());
      world.setBlockState(pos.add(33, 19, 65), ((BlockColored)Blocks.WOOL).getStateFromMeta(15));
      world.setBlockState(pos.add(38, 19, 65), ((BlockColored)Blocks.WOOL).getStateFromMeta(15));
      world.setBlockState(pos.add(40, 19, 65), Blocks.STONE.getDefaultState());
      world.setBlockState(pos.add(47, 19, 65), Blocks.STONE.getDefaultState());
      world.setBlockState(pos.add(34, 19, 66), ((BlockColored)Blocks.WOOL).getStateFromMeta(15));
      world.setBlockState(pos.add(35, 19, 66), ((BlockColored)Blocks.WOOL).getStateFromMeta(15));
      world.setBlockState(pos.add(36, 19, 66), ((BlockColored)Blocks.WOOL).getStateFromMeta(15));
      world.setBlockState(pos.add(37, 19, 66), ((BlockColored)Blocks.WOOL).getStateFromMeta(15));
      world.setBlockState(pos.add(41, 19, 66), Blocks.STONE.getDefaultState());
      world.setBlockState(pos.add(46, 19, 66), Blocks.STONE.getDefaultState());
      world.setBlockState(pos.add(42, 19, 67), Blocks.STONE.getDefaultState());
      world.setBlockState(pos.add(43, 19, 67), Blocks.STONE.getDefaultState());
      world.setBlockState(pos.add(44, 19, 67), Blocks.STONE.getDefaultState());
      world.setBlockState(pos.add(45, 19, 67), Blocks.STONE.getDefaultState());
      world.setBlockState(pos.add(26, 20, 36), Blocks.NETHER_BRICK_FENCE.getDefaultState());
      world.setBlockState(pos.add(17, 20, 37), ((BlockColored)Blocks.STAINED_HARDENED_CLAY).getStateFromMeta(4));
      world.setBlockState(pos.add(18, 20, 37), ((BlockColored)Blocks.STAINED_HARDENED_CLAY).getStateFromMeta(4));
      world.setBlockState(pos.add(19, 20, 37), ((BlockColored)Blocks.STAINED_HARDENED_CLAY).getStateFromMeta(4));
      world.setBlockState(pos.add(20, 20, 37), ((BlockColored)Blocks.STAINED_HARDENED_CLAY).getStateFromMeta(4));
      world.setBlockState(pos.add(23, 20, 37), ((BlockColored)Blocks.STAINED_HARDENED_CLAY).getStateFromMeta(4));
      world.setBlockState(pos.add(24, 20, 37), ((BlockColored)Blocks.STAINED_HARDENED_CLAY).getStateFromMeta(4));
      world.setBlockState(pos.add(25, 20, 37), ((BlockColored)Blocks.STAINED_HARDENED_CLAY).getStateFromMeta(4));
      world.setBlockState(pos.add(26, 20, 37), Blocks.DIAMOND_BLOCK.getDefaultState());
      world.setBlockState(pos.add(27, 20, 37), ((BlockColored)Blocks.STAINED_HARDENED_CLAY).getStateFromMeta(4));
      world.setBlockState(pos.add(28, 20, 37), ((BlockColored)Blocks.STAINED_HARDENED_CLAY).getStateFromMeta(4));
      world.setBlockState(pos.add(29, 20, 37), ((BlockColored)Blocks.STAINED_HARDENED_CLAY).getStateFromMeta(4));
      world.setBlockState(pos.add(32, 20, 37), ((BlockColored)Blocks.STAINED_HARDENED_CLAY).getStateFromMeta(4));
      world.setBlockState(pos.add(33, 20, 37), ((BlockColored)Blocks.STAINED_HARDENED_CLAY).getStateFromMeta(4));
      world.setBlockState(pos.add(34, 20, 37), ((BlockColored)Blocks.STAINED_HARDENED_CLAY).getStateFromMeta(4));
      world.setBlockState(pos.add(35, 20, 37), ((BlockColored)Blocks.STAINED_HARDENED_CLAY).getStateFromMeta(4));
      world.setBlockState(pos.add(17, 20, 38), ((BlockColored)Blocks.STAINED_HARDENED_CLAY).getStateFromMeta(4));
      world.setBlockState(pos.add(18, 20, 38), ((BlockColored)Blocks.STAINED_HARDENED_CLAY).getStateFromMeta(4));
      world.setBlockState(pos.add(19, 20, 38), ((BlockColored)Blocks.STAINED_HARDENED_CLAY).getStateFromMeta(4));
      world.setBlockState(pos.add(20, 20, 38), ((BlockColored)Blocks.STAINED_HARDENED_CLAY).getStateFromMeta(4));
      world.setBlockState(pos.add(23, 20, 38), Blocks.DIAMOND_BLOCK.getDefaultState());
      world.setBlockState(pos.add(29, 20, 38), Blocks.DIAMOND_BLOCK.getDefaultState());
      world.setBlockState(pos.add(32, 20, 38), ((BlockColored)Blocks.STAINED_HARDENED_CLAY).getStateFromMeta(4));
      world.setBlockState(pos.add(33, 20, 38), ((BlockColored)Blocks.STAINED_HARDENED_CLAY).getStateFromMeta(4));
      world.setBlockState(pos.add(34, 20, 38), ((BlockColored)Blocks.STAINED_HARDENED_CLAY).getStateFromMeta(4));
      world.setBlockState(pos.add(35, 20, 38), ((BlockColored)Blocks.STAINED_HARDENED_CLAY).getStateFromMeta(4));
      world.setBlockState(pos.add(17, 20, 39), ((BlockColored)Blocks.STAINED_HARDENED_CLAY).getStateFromMeta(4));
      world.setBlockState(pos.add(20, 20, 39), ((BlockColored)Blocks.STAINED_HARDENED_CLAY).getStateFromMeta(4));
      world.setBlockState(pos.add(23, 20, 39), Blocks.DIAMOND_BLOCK.getDefaultState());
      world.setBlockState(pos.add(29, 20, 39), Blocks.DIAMOND_BLOCK.getDefaultState());
      world.setBlockState(pos.add(32, 20, 39), ((BlockColored)Blocks.STAINED_HARDENED_CLAY).getStateFromMeta(4));
      world.setBlockState(pos.add(35, 20, 39), ((BlockColored)Blocks.STAINED_HARDENED_CLAY).getStateFromMeta(4));
      world.setBlockState(pos.add(17, 20, 40), ((BlockColored)Blocks.STAINED_HARDENED_CLAY).getStateFromMeta(4));
      world.setBlockState(pos.add(20, 20, 40), ((BlockColored)Blocks.STAINED_HARDENED_CLAY).getStateFromMeta(4));
      world.setBlockState(pos.add(23, 20, 40), Blocks.DIAMOND_BLOCK.getDefaultState());
      world.setBlockState(pos.add(29, 20, 40), Blocks.DIAMOND_BLOCK.getDefaultState());
      world.setBlockState(pos.add(32, 20, 40), ((BlockColored)Blocks.STAINED_HARDENED_CLAY).getStateFromMeta(4));
      world.setBlockState(pos.add(34, 20, 40), ((BlockColored)Blocks.STAINED_HARDENED_CLAY).getStateFromMeta(4));
      world.setBlockState(pos.add(35, 20, 40), ((BlockColored)Blocks.STAINED_HARDENED_CLAY).getStateFromMeta(4));
      world.setBlockState(pos.add(18, 20, 41), Blocks.QUARTZ_BLOCK.getDefaultState());
      world.setBlockState(pos.add(20, 20, 41), Blocks.QUARTZ_BLOCK.getDefaultState());
      world.setBlockState(pos.add(23, 20, 41), ((BlockColored)Blocks.STAINED_HARDENED_CLAY).getStateFromMeta(4));
      world.setBlockState(pos.add(26, 20, 41), Blocks.STONE.getDefaultState());
      world.setBlockState(pos.add(27, 20, 41), Blocks.STONE.getDefaultState());
      world.setBlockState(pos.add(29, 20, 41), ((BlockColored)Blocks.STAINED_HARDENED_CLAY).getStateFromMeta(4));
      world.setBlockState(pos.add(32, 20, 41), Blocks.QUARTZ_BLOCK.getDefaultState());
      world.setBlockState(pos.add(34, 20, 41), Blocks.QUARTZ_BLOCK.getDefaultState());
      world.setBlockState(pos.add(18, 20, 42), Blocks.QUARTZ_BLOCK.getDefaultState());
      world.setBlockState(pos.add(20, 20, 42), Blocks.QUARTZ_BLOCK.getDefaultState());
      world.setBlockState(pos.add(23, 20, 42), ((BlockColored)Blocks.STAINED_HARDENED_CLAY).getStateFromMeta(4));
      world.setBlockState(pos.add(26, 20, 42), Blocks.STONE.getDefaultState());
      world.setBlockState(pos.add(27, 20, 42), Blocks.STONE.getDefaultState());
      world.setBlockState(pos.add(29, 20, 42), ((BlockColored)Blocks.STAINED_HARDENED_CLAY).getStateFromMeta(4));
      world.setBlockState(pos.add(32, 20, 42), Blocks.QUARTZ_BLOCK.getDefaultState());
      world.setBlockState(pos.add(34, 20, 42), Blocks.QUARTZ_BLOCK.getDefaultState());
      world.setBlockState(pos.add(17, 20, 43), ((BlockColored)Blocks.STAINED_HARDENED_CLAY).getStateFromMeta(4));
      world.setBlockState(pos.add(20, 20, 43), ((BlockColored)Blocks.STAINED_HARDENED_CLAY).getStateFromMeta(4));
      world.setBlockState(pos.add(23, 20, 43), Blocks.DIAMOND_BLOCK.getDefaultState());
      world.setBlockState(pos.add(29, 20, 43), Blocks.DIAMOND_BLOCK.getDefaultState());
      world.setBlockState(pos.add(32, 20, 43), ((BlockColored)Blocks.STAINED_HARDENED_CLAY).getStateFromMeta(4));
      world.setBlockState(pos.add(35, 20, 43), ((BlockColored)Blocks.STAINED_HARDENED_CLAY).getStateFromMeta(4));
      world.setBlockState(pos.add(17, 20, 44), ((BlockColored)Blocks.STAINED_HARDENED_CLAY).getStateFromMeta(4));
      world.setBlockState(pos.add(20, 20, 44), ((BlockColored)Blocks.STAINED_HARDENED_CLAY).getStateFromMeta(4));
      world.setBlockState(pos.add(23, 20, 44), Blocks.DIAMOND_BLOCK.getDefaultState());
      world.setBlockState(pos.add(29, 20, 44), Blocks.DIAMOND_BLOCK.getDefaultState());
      world.setBlockState(pos.add(32, 20, 44), ((BlockColored)Blocks.STAINED_HARDENED_CLAY).getStateFromMeta(4));
      world.setBlockState(pos.add(35, 20, 44), ((BlockColored)Blocks.STAINED_HARDENED_CLAY).getStateFromMeta(4));
      world.setBlockState(pos.add(17, 20, 45), ((BlockColored)Blocks.STAINED_HARDENED_CLAY).getStateFromMeta(4));
      world.setBlockState(pos.add(20, 20, 45), ((BlockColored)Blocks.STAINED_HARDENED_CLAY).getStateFromMeta(4));
      world.setBlockState(pos.add(23, 20, 45), Blocks.DIAMOND_BLOCK.getDefaultState());
      world.setBlockState(pos.add(29, 20, 45), Blocks.DIAMOND_BLOCK.getDefaultState());
      world.setBlockState(pos.add(32, 20, 45), ((BlockColored)Blocks.STAINED_HARDENED_CLAY).getStateFromMeta(4));
      world.setBlockState(pos.add(35, 20, 45), ((BlockColored)Blocks.STAINED_HARDENED_CLAY).getStateFromMeta(4));
      world.setBlockState(pos.add(18, 20, 46), Blocks.QUARTZ_BLOCK.getDefaultState());
      world.setBlockState(pos.add(19, 20, 46), Blocks.QUARTZ_BLOCK.getDefaultState());
      world.setBlockState(pos.add(20, 20, 46), Blocks.QUARTZ_BLOCK.getDefaultState());
      world.setBlockState(pos.add(23, 20, 46), ((BlockColored)Blocks.STAINED_HARDENED_CLAY).getStateFromMeta(4));
      world.setBlockState(pos.add(25, 20, 46), Blocks.STONE.getDefaultState());
